File: archive/undergrad/433/Tensile Test/Specimen_RawData_12.csv
Time,Extension,Load,Strain Gage18
(s),(mm),(N),(mm/mm)
"0.00000","0.00000","204.02856","0.00017"
"0.10000","0.00322","225.29865","0.00019"
"0.20000","0.01355","294.91443","0.00027"
"0.30000","0.02413","364.23495","0.00034"
"0.40000","0.03427","429.44705","0.00041"
"0.50000","0.04429","492.48138","0.00047"
"0.60000","0.05436","554.92365","0.00052"
"0.70000","0.06426","615.31476","0.00059"
"0.80000","0.07420","675.61542","0.00065"
"0.90000","0.08414","734.94928","0.00069"
"1.00000","0.09419","794.06061","0.00076"
"1.10000","0.10425","853.05835","0.00082"
"1.20000","0.11435","911.45959","0.00089"
"1.30000","0.12434","969.18939","0.00093"
"1.40000","0.13425","1026.07605","0.00099"
"1.50000","0.14418","1083.15198","0.00105"
"1.60000","0.15406","1139.69543","0.00111"
"1.70000","0.16419","1197.48999","0.00118"
"1.80000","0.17427","1254.96643","0.00125"
"1.90000","0.18437","1312.21960","0.00131"
"2.00000","0.19429","1368.43921","0.00136"
"2.10000","0.20427","1424.63916","0.00142"
"2.20000","0.21416","1480.49231","0.00147"
"2.30000","0.22415","1536.77295","0.00153"
"2.40000","0.23425","1593.23584","0.00159"
"2.50000","0.24427","1649.17651","0.00165"
"2.60000","0.25425","1704.68738","0.00169"
"2.70000","0.26423","1760.09924","0.00176"
"2.80000","0.27424","1815.15552","0.00181"
"2.90000","0.28427","1869.74683","0.00186"
"3.00000","0.29432","1924.07617","0.00193"
"3.10000","0.30427","1977.37292","0.00200"
"3.20000","0.31422","2030.03027","0.00205"
"3.30000","0.32417","2082.22266","0.00210"
"3.40000","0.33418","2133.83325","0.00217"
"3.50000","0.34426","2185.31250","0.00223"
"3.60000","0.35433","2235.39795","0.00229"
"3.70000","0.36436","2283.41699","0.00235"
"3.80000","0.37426","2328.93457","0.00242"
"3.90000","0.38420","2371.83057","0.00248"
"4.00000","0.39406","2410.85938","0.00255"
"4.10000","0.40417","2446.89868","0.00261"
"4.20000","0.41432","2478.05396","0.00269"
"4.30000","0.42439","2503.94873","0.00277"
"4.40000","0.43432","2524.04077","0.00286"
"4.50000","0.44427","2540.16528","0.00295"
"4.60000","0.45417","2552.02490","0.00304"
"4.70000","0.46418","2560.91260","0.00313"
"4.80000","0.47426","2568.13647","0.00323"
"4.90000","0.48428","2573.35498","0.00330"
"5.00000","0.49436","2578.78076","0.00338"
"5.10000","0.50432","2584.40698","0.00345"
"5.20000","0.51421","2574.59375","0.00349"
"5.30000","0.52423","2579.79956","0.00355"
"5.40000","0.53424","2593.27319","0.00359"
"5.50000","0.54422","2590.30981","0.00362"
"5.60000","0.55424","2599.68335","0.00369"
"5.70000","0.56421","2607.07495","0.00375"
"5.80000","0.57422","2605.30347","0.00381"
"5.90000","0.58426","2606.71069","0.00386"
"6.00000","0.59431","2610.88916","0.00393"
"6.10000","0.60432","2612.93481","0.00399"
"6.20000","0.61429","2615.33960","0.00407"
"6.30000","0.62421","2614.03833","0.00414"
"6.40000","0.63409","2606.12012","0.00419"
"6.50000","0.64421","2608.62695","0.00428"
"6.60000","0.65437","2610.01489","0.00524"
"6.70000","0.66439","2610.01245","0.00746"
"6.80000","0.67430","2609.49146","0.00814"
"6.90000","0.68421","2610.38867","0.00734"
"7.00000","0.69414","2610.71167","0.00730"
"7.10000","0.70415","2610.50342","0.00725"
"7.20000","0.71429","2611.14331","0.00721"
"7.30000","0.72431","2612.12109","0.00715"
"7.40000","0.73437","2613.79541","0.00709"
"7.50000","0.74430","2616.05054","0.00705"
"7.60000","0.75417","2616.34399","0.00698"
"7.70000","0.76421","2615.97974","0.00692"
"7.80000","0.77424","2617.05249","0.00687"
"7.90000","0.78429","2616.89478","0.00682"
"8.00000","0.79430","2617.94995","0.00678"
"8.10000","0.80423","2617.13501","0.00673"
"8.20000","0.81423","2616.57471","0.00669"
"8.30000","0.82424","2616.00391","0.00664"
"8.40000","0.83429","2620.28833","0.00660"
"8.50000","0.84433","2633.95728","0.00658"
"8.60000","0.85427","2635.37476","0.00654"
"8.70000","0.86419","2632.78589","0.00649"
"8.80000","0.87415","2629.81421","0.00644"
"8.90000","0.88426","2634.94897","0.00640"
"9.00000","0.89437","2641.65112","0.00636"
"9.10000","0.90439","2630.25854","0.00630"
"9.20000","0.91429","2640.86841","0.00624"
"9.30000","0.92419","2653.60742","0.00620"
"9.40000","0.93410","2663.63940","0.00615"
"9.50000","0.94416","2673.39209","0.00609"
"9.60000","0.95424","2665.75098","0.00602"
"9.70000","0.96442","2673.78613","0.00595"
"9.80000","0.97438","2686.11084","0.00589"
"9.90000","0.98428","2701.90991","0.00584"
"10.00000","0.99411","2709.72729","0.00578"
"10.10000","1.00417","2710.58276","0.00572"
"10.20000","1.01423","2724.91284","0.00565"
"10.30000","1.02433","2706.34814","0.00556"
"10.40000","1.03431","2723.51587","0.00549"
"10.50000","1.04426","2739.32861","0.00543"
"10.60000","1.05427","2740.52124","0.00537"
"10.70000","1.06422","2736.84473","0.00531"
"10.80000","1.07421","2732.05884","0.00525"
"10.90000","1.08435","2716.79639","0.00519"
"11.00000","1.09429","2719.50366","0.00512"
"11.10000","1.10421","2722.91455","0.00507"
"11.20000","1.11417","2728.02588","0.00501"
"11.30000","1.12428","2733.05518","0.00496"
"11.40000","1.13432","2734.25439","0.00490"
"11.50000","1.14438","2734.60645","0.00483"
"11.60000","1.15428","2729.32959","0.00476"
"11.70000","1.16417","2724.54785","0.00469"
"11.80000","1.17409","2718.91772","0.00456"
"11.90000","1.18423","2719.54321","0.00284"
"12.00000","1.19429","2721.89819","0.00204"
"12.10000","1.20444","2723.79248","0.00159"
"12.20000","1.21439","2732.15723","0.00150"
"12.30000","1.22423","2735.89038","0.00146"
"12.40000","1.23415","2737.26782","0.00141"
"12.50000","1.24415","2740.58105","0.00140"
"12.60000","1.25419","2736.33154","0.00138"
"12.70000","1.26433","2739.63574","0.00138"
"12.80000","1.27438","2738.33936","0.00137"
"12.90000","1.28427","2738.28711","0.00137"
"13.00000","1.29421","2742.07544","0.00134"
"13.10000","1.30421","2739.71338","0.00129"
"13.20000","1.31419","2742.45874","0.00133"
"13.30000","1.32433","2740.25317","0.00133"
"13.40000","1.33431","2740.98511","0.00129"
"13.50000","1.34424","2743.40137","0.00128"
"13.60000","1.35419","2740.30859","0.00126"
"13.70000","1.36429","2741.50049","0.00122"
"13.80000","1.37429","2741.28638","0.00130"
"13.90000","1.38434","2740.62842","0.00128"
"14.00000","1.39428","2743.28442","0.00048"
"14.10000","1.40415","2742.14478","0.00123"
"14.20000","1.41413","2742.35034","0.00101"
"14.30000","1.42427","2743.23999","0.00078"
"14.40000","1.43433","2743.32007","0.00039"
"14.50000","1.44439","2737.35010","0.00017"
"14.60000","1.45441","2742.55664","0.00000"
"14.70000","1.46420","2769.63184","-0.00005"
"14.80000","1.47413","2769.97900","0.00018"
"14.90000","1.48419","2771.26831","0.00037"
"15.00000","1.49422","2799.51172","0.00067"
"15.10000","1.50443","2792.60083","0.00087"
"15.20000","1.51442","2812.25342","0.00131"
"15.30000","1.52423","2773.56274","0.00145"
"15.40000","1.53417","2795.33423","0.00109"
"15.50000","1.54420","2804.80786","0.00095"
"15.60000","1.55418","2805.11987","0.00086"
"15.70000","1.56432","2810.30347","-0.01695"
"15.80000","1.57434","2822.75317","0.00105"
"15.90000","1.58423","2832.33740","0.00090"
"16.00000","1.59425","2829.91846","0.00092"
"16.10000","1.60422","2827.69922","0.00092"
"16.20000","1.61420","2817.80591","0.00075"
"16.30000","1.62430","2854.83252","0.00049"
"16.40000","1.63432","2843.75439","0.00046"
"16.50000","1.64417","2845.89404","0.07623"
"16.60000","1.65416","2850.88794","0.07354"
"16.70000","1.66429","2829.20068","0.07361"
"16.80000","1.67434","2849.57446","0.07361"
"16.90000","1.68436","2876.94531","0.07361"
"17.00000","1.69435","2883.39575","0.07361"
"17.10000","1.70422","2856.57690","0.07361"
"17.20000","1.71411","2878.45386","0.07361"
"17.30000","1.72424","2870.14062","0.07361"
"17.40000","1.73426","2862.90454","0.07361"
"17.50000","1.74444","2905.03198","0.07361"
"17.60000","1.75438","2890.98413","0.07361"
"17.70000","1.76422","2900.24561","0.07361"
"17.80000","1.77418","2903.31421","0.07361"
"17.90000","1.78421","2887.26489","0.07361"
"18.00000","1.79419","2907.31006","0.07361"
"18.10000","1.80429","2919.84644","0.07361"
"18.20000","1.81441","2887.82227","0.07361"
"18.30000","1.82430","2874.21338","0.07361"
"18.40000","1.83422","2867.54370","0.07361"
"18.50000","1.84420","2869.87573","0.07361"
"18.60000","1.85426","2873.93701","0.07361"
"18.70000","1.86429","2877.74976","0.07361"
"18.80000","1.87432","2876.37866","0.07361"
"18.90000","1.88417","2876.94922","0.07361"
"19.00000","1.89422","2877.56641","0.07361"
"19.10000","1.90432","2880.95532","0.07361"
"19.20000","1.91432","2876.96777","0.07361"
"19.30000","1.92435","2879.33008","0.07361"
"19.40000","1.93429","2880.16968","0.07361"
"19.50000","1.94423","2882.22656","0.07361"
"19.60000","1.95414","2881.74707","0.07361"
"19.70000","1.96424","2879.35742","0.07361"
"19.80000","1.97430","2876.85132","0.07361"
"19.90000","1.98439","2877.86304","0.07361"
"20.00000","1.99439","2878.80371","0.07361"
"20.10000","2.00418","2877.29028","0.07361"
"20.20000","2.01418","2881.10278","0.07361"
"20.30000","2.02416","2880.82935","0.07361"
"20.40000","2.03426","2880.80493","0.07361"
"20.50000","2.04431","2877.25073","0.07361"
"20.60000","2.05444","2881.93311","0.07361"
"20.70000","2.06430","2879.25244","0.07361"
"20.80000","2.07420","2874.82495","0.07361"
"20.90000","2.08418","2865.07446","0.07361"
"21.00000","2.09424","2862.37622","0.07361"
"21.10000","2.10429","2870.09692","0.07361"
"21.20000","2.11435","2874.23730","0.07361"
"21.30000","2.12426","2863.42847","0.07361"
"21.40000","2.13426","2866.87085","0.07361"
"21.50000","2.14426","2871.91821","0.07361"
"21.60000","2.15421","2878.86548","0.07361"
"21.70000","2.16428","2880.48584","0.07361"
"21.80000","2.17428","2887.33936","0.07361"
"21.90000","2.18424","2888.89771","0.07361"
"22.00000","2.19419","2883.09375","0.07361"
"22.10000","2.20425","2878.06421","0.07361"
"22.20000","2.21432","2871.33105","0.07361"
"22.30000","2.22438","2860.50610","0.07361"
"22.40000","2.23435","2875.80225","0.07361"
"22.50000","2.24420","2905.29199","0.07361"
"22.60000","2.25416","2918.45483","0.07361"
"22.70000","2.26420","2925.11011","0.07361"
"22.80000","2.27427","2932.51172","0.07361"
"22.90000","2.28433","2937.70459","0.07361"
"23.00000","2.29437","2944.02075","0.07361"
"23.10000","2.30431","2951.85083","0.07361"
"23.20000","2.31419","2951.42358","0.07361"
"23.30000","2.32413","2948.93457","0.07361"
"23.40000","2.33420","2967.29517","0.07361"
"23.50000","2.34425","2975.68115","0.07361"
"23.60000","2.35438","2966.22095","0.07361"
"23.70000","2.36431","2966.15405","0.07361"
"23.80000","2.37428","2990.11792","0.07361"
"23.90000","2.38420","2952.07715","0.07361"
"24.00000","2.39422","3005.17651","0.07361"
"24.10000","2.40428","2971.50684","0.07361"
"24.20000","2.41424","3006.69922","0.07361"
"24.30000","2.42425","2998.32568","0.07361"
"24.40000","2.43427","3003.91357","0.07361"
"24.50000","2.44426","3014.24731","0.07361"
"24.60000","2.45432","3005.24756","0.07361"
"24.70000","2.46433","2972.51465","0.07361"
"24.80000","2.47426","3011.90161","0.07361"
"24.90000","2.48426","3023.28540","0.07361"
"25.00000","2.49418","3022.64941","0.07361"
"25.10000","2.50422","2968.33691","0.07361"
"25.20000","2.51423","3020.95020","0.07361"
"25.30000","2.52436","3002.01392","0.07361"
"25.40000","2.53438","2965.15967","0.07361"
"25.50000","2.54427","3009.27441","0.07361"
"25.60000","2.55418","3019.86694","0.07361"
"25.70000","2.56406","3041.54346","0.07361"
"25.80000","2.57421","3031.07861","0.07361"
"25.90000","2.58431","3008.94971","0.07361"
"26.00000","2.59440","2996.57666","0.07361"
"26.10000","2.60431","2999.76001","0.07361"
"26.20000","2.61425","3051.38403","0.07361"
"26.30000","2.62417","3051.46484","0.07361"
"26.40000","2.63419","3075.07300","0.07361"
"26.50000","2.64428","3058.68506","0.07361"
"26.60000","2.65428","3046.29541","0.07361"
"26.70000","2.66431","3051.75342","0.07361"
"26.80000","2.67431","3071.92700","0.07361"
"26.90000","2.68423","3066.22266","0.07361"
"27.00000","2.69425","3055.18555","0.07361"
"27.10000","2.70430","3049.15845","0.07361"
"27.20000","2.71428","3056.33350","0.07361"
"27.30000","2.72426","3063.48169","0.07361"
"27.40000","2.73419","3056.67432","0.07361"
"27.50000","2.74423","3046.85376","0.07361"
"27.60000","2.75427","3038.91528","0.07361"
"27.70000","2.76432","3037.38428","0.07361"
"27.80000","2.77435","3044.50171","0.07361"
"27.90000","2.78428","3049.02563","0.07361"
"28.00000","2.79422","3042.81519","0.07361"
"28.10000","2.80409","3032.56763","0.07361"
"28.20000","2.81421","3023.55347","0.07361"
"28.30000","2.82434","3019.13257","0.07361"
"28.40000","2.83440","3022.48901","0.07361"
"28.50000","2.84431","3031.96411","0.07361"
"28.60000","2.85422","3031.94312","0.07361"
"28.70000","2.86412","3020.89575","0.07361"
"28.80000","2.87415","3008.17383","0.07361"
"28.90000","2.88428","3000.57593","0.07361"
"29.00000","2.89430","2997.37061","0.07361"
"29.10000","2.90437","3004.99976","0.07361"
"29.20000","2.91431","3020.54126","0.07361"
"29.30000","2.92420","3019.47290","0.07361"
"29.40000","2.93422","3009.75049","0.07361"
"29.50000","2.94426","3002.15991","0.07361"
"29.60000","2.95429","3000.48950","0.07361"
"29.70000","2.96424","3009.38916","0.07361"
"29.80000","2.97425","3023.50854","0.07361"
"29.90000","2.98425","3024.71997","0.07361"
"30.00000","2.99425","3016.82617","0.07361"
"30.10000","3.00427","3009.07275","0.07361"
"30.20000","3.01431","3007.92578","0.07361"
"30.30000","3.02430","3021.08496","0.07361"
"30.40000","3.03419","3028.67456","0.07361"
"30.50000","3.04412","3019.91284","0.07361"
"30.60000","3.05421","3010.21997","0.07361"
"30.70000","3.06441","3007.16040","0.07361"
"30.80000","3.07439","3019.32324","0.07361"
"30.90000","3.08431","3033.11792","0.07361"
"31.00000","3.09418","3024.13550","0.07361"
"31.10000","3.10414","3012.74390","0.07361"
"31.20000","3.11420","3007.19849","0.07361"
"31.30000","3.12427","3015.66406","0.07361"
"31.40000","3.13437","3029.81372","0.07361"
"31.50000","3.14437","3022.82129","0.07361"
"31.60000","3.15427","3023.02197","0.07361"
"31.70000","3.16414","3029.50806","0.07361"
"31.80000","3.17421","3015.55420","0.07361"
"31.90000","3.18420","3008.59985","0.07361"
"32.00000","3.19432","3010.47681","0.07361"
"32.10000","3.20431","3024.67798","0.07361"
"32.20000","3.21421","3032.20068","0.07361"
"32.30000","3.22418","3023.93091","0.07361"
"32.40000","3.23423","3014.76685","0.07361"
"32.50000","3.24427","3009.61499","0.07361"
"32.60000","3.25433","3016.93848","0.07361"
"32.70000","3.26429","3037.64844","0.07361"
"32.80000","3.27417","3035.91162","0.07361"
"32.90000","3.28418","3025.74707","0.07361"
"33.00000","3.29427","3025.53223","0.07361"
"33.10000","3.30432","3053.07056","0.07361"
"33.20000","3.31439","3053.66675","0.07361"
"33.30000","3.32430","3044.18237","0.07361"
"33.40000","3.33420","3060.62500","0.07361"
"33.50000","3.34411","3075.70093","0.07361"
"33.60000","3.35420","3066.30029","0.07361"
"33.70000","3.36426","3072.02686","0.07361"
"33.80000","3.37443","3090.20190","0.07361"
"33.90000","3.38441","3075.31592","0.07361"
"34.00000","3.39424","3089.68408","0.07361"
"34.10000","3.40414","3104.48755","0.07361"
"34.20000","3.41419","3094.75439","0.07361"
"34.30000","3.42421","3090.93066","0.07361"
"34.40000","3.43433","3099.93018","0.07361"
"34.50000","3.44433","3121.95459","0.07361"
"34.60000","3.45425","3118.22607","0.07361"
"34.70000","3.46428","3123.08276","0.07361"
"34.80000","3.47419","3127.95776","0.07361"
"34.90000","3.48422","3129.62354","0.07361"
"35.00000","3.49430","3121.43921","0.07361"
"35.10000","3.50429","3135.43408","0.07361"
"35.20000","3.51422","3115.03003","0.07361"
"35.30000","3.52421","3152.54102","0.07361"
"35.40000","3.53429","3137.81616","0.07361"
"35.50000","3.54429","3115.65405","0.07361"
"35.60000","3.55436","3154.47412","0.07361"
"35.70000","3.56430","3139.42480","0.07361"
"35.80000","3.57416","3116.78418","0.07361"
"35.90000","3.58411","3156.38403","0.07361"
"36.00000","3.59424","3140.76660","0.07361"
"36.10000","3.60430","3120.38354","0.07361"
"36.20000","3.61442","3159.56763","0.07361"
"36.30000","3.62440","3147.68994","0.07361"
"36.40000","3.63419","3126.68750","0.07361"
"36.50000","3.64413","3155.80566","0.07361"
"36.60000","3.65419","3123.00073","0.07361"
"36.70000","3.66420","3135.97803","0.07361"
"36.80000","3.67440","3133.32129","0.07361"
"36.90000","3.68442","3145.43628","0.07361"
"37.00000","3.69424","3126.06030","0.07361"
"37.10000","3.70417","3121.21118","0.07361"
"37.20000","3.71421","3147.90356","0.07361"
"37.30000","3.72422","3126.90503","0.07361"
"37.40000","3.73432","3116.90698","0.07361"
"37.50000","3.74431","3153.89526","0.07361"
"37.60000","3.75421","3131.15259","0.07361"
"37.70000","3.76422","3117.66968","0.07361"
"37.80000","3.77427","3157.53418","0.07361"
"37.90000","3.78427","3136.19067","0.07361"
"38.00000","3.79434","3116.51489","0.07361"
"38.10000","3.80429","3153.50659","0.07361"
"38.20000","3.81414","3138.56226","0.07361"
"38.30000","3.82415","3113.27173","0.07361"
"38.40000","3.83429","3140.86670","0.07361"
"38.50000","3.84433","3141.32983","0.07361"
"38.60000","3.85440","3116.89258","0.07361"
"38.70000","3.86438","3121.07227","0.07361"
"38.80000","3.87420","3145.55835","0.07361"
"38.90000","3.88413","3118.41968","0.07361"
"39.00000","3.89418","3127.83008","0.07361"
"39.10000","3.90422","3148.45068","0.07361"
"39.20000","3.91444","3123.78442","0.07361"
"39.30000","3.92438","3126.06128","0.07361"
"39.40000","3.93422","3149.24609","0.07361"
"39.50000","3.94418","3118.99756","0.07361"
"39.60000","3.95420","3154.35913","0.07361"
"39.70000","3.96419","3140.01318","0.07361"
"39.80000","3.97428","3117.51562","0.07361"
"39.90000","3.98438","3163.87329","0.07361"
"40.00000","3.99429","3141.87158","0.07361"
"40.10000","4.00424","3120.96362","0.07361"
"40.20000","4.01423","3166.67847","0.07361"
"40.30000","4.02426","3141.98145","0.07361"
"40.40000","4.03431","3122.12402","0.07361"
"40.50000","4.04433","3166.28003","0.07361"
"40.60000","4.05418","3138.51489","0.07361"
"40.70000","4.06421","3120.97803","0.07361"
"40.80000","4.07429","3164.33057","0.07361"
"40.90000","4.08432","3142.06104","0.07361"
"41.00000","4.09434","3135.69531","0.07361"
"41.10000","4.10435","3175.34570","0.07361"
"41.20000","4.11420","3145.00024","0.07361"
"41.30000","4.12410","3191.17188","0.07361"
"41.40000","4.13425","3113.29395","0.07361"
"41.50000","4.14428","3137.03052","0.07361"
"41.60000","4.15439","3148.18701","0.07361"
"41.70000","4.16438","3140.93481","0.07361"
"41.80000","4.17419","3190.91162","0.07361"
"41.90000","4.18413","3159.30542","0.07361"
"42.00000","4.19415","3205.58203","0.07361"
"42.10000","4.20424","3173.25854","0.07361"
"42.20000","4.21432","3173.50439","0.07361"
"42.30000","4.22444","3199.55151","0.07361"
"42.40000","4.23425","3169.89795","0.07361"
"42.50000","4.24417","3217.91089","0.07361"
"42.60000","4.25417","3183.46436","0.07361"
"42.70000","4.26428","3200.37891","0.07361"
"42.80000","4.27432","3167.04688","0.07361"
"42.90000","4.28435","3201.88770","0.07361"
"43.00000","4.29425","3169.71387","0.07361"
"43.10000","4.30422","3210.23242","0.07361"
"43.20000","4.31432","3184.58740","0.07361"
"43.30000","4.32426","3178.56104","0.07361"
"43.40000","4.33430","3202.14136","0.07361"
"43.50000","4.34431","3174.48633","0.07361"
"43.60000","4.35426","3136.30737","0.07361"
"43.70000","4.36415","3179.10352","0.07361"
"43.80000","4.37426","3153.17212","0.07361"
"43.90000","4.38429","3198.46460","0.07361"
"44.00000","4.39439","3215.46533","0.07361"
"44.10000","4.40438","3163.33252","0.07361"
"44.20000","4.41420","3213.84668","0.07361"
"44.30000","4.42417","3178.64941","0.07361"
"44.40000","4.43419","3211.28491","0.07361"
"44.50000","4.44424","3163.58472","0.07361"
"44.60000","4.45428","3162.12549","0.07361"
"44.70000","4.46436","3144.20361","0.07361"
"44.80000","4.47433","3125.46606","0.07361"
"44.90000","4.48424","3140.91357","0.07361"
"45.00000","4.49416","3159.44629","0.07361"
"45.10000","4.50415","3165.49121","0.07361"
"45.20000","4.51424","3209.41797","0.07361"
"45.30000","4.52433","3165.53833","0.07361"
"45.40000","4.53430","3220.02466","0.07361"
"45.50000","4.54432","3193.40332","0.07361"
"45.60000","4.55426","3212.73999","0.07361"
"45.70000","4.56426","3187.96826","0.07361"
"45.80000","4.57429","3230.84082","0.07361"
"45.90000","4.58428","3199.09595","0.07361"
"46.00000","4.59422","3231.81567","0.07361"
"46.10000","4.60424","3212.60889","0.07361"
"46.20000","4.61421","3210.43652","0.07361"
"46.30000","4.62434","3225.61011","0.07361"
"46.40000","4.63433","3194.75073","0.07361"
"46.50000","4.64433","3236.83398","0.07361"
"46.60000","4.65422","3195.06079","0.07361"
"46.70000","4.66417","3245.86963","0.07361"
"46.80000","4.67421","3211.06787","0.07361"
"46.90000","4.68426","3234.98584","0.07361"
"47.00000","4.69436","3198.65649","0.07361"
"47.10000","4.70436","3250.77173","0.07361"
"47.20000","4.71432","3206.45337","0.07361"
"47.30000","4.72417","3259.32349","0.07361"
"47.40000","4.73413","3218.01855","0.07361"
"47.50000","4.74422","3229.80811","0.07361"
"47.60000","4.75429","3233.54639","0.07361"
"47.70000","4.76436","3198.04614","0.07361"
"47.80000","4.77427","3246.90039","0.07361"
"47.90000","4.78425","3202.01172","0.07361"
"48.00000","4.79420","3256.44653","0.07361"
"48.10000","4.80425","3214.53223","0.07361"
"48.20000","4.81425","3239.83569","0.07361"
"48.30000","4.82423","3225.50903","0.07361"
"48.40000","4.83427","3163.57690","0.07361"
"48.50000","4.84428","3193.06592","0.07361"
"48.60000","4.85425","3185.84546","0.07361"
"48.70000","4.86428","3218.52759","0.07361"
"48.80000","4.87434","3188.54297","0.07361"
"48.90000","4.88427","3228.90063","0.07361"
"49.00000","4.89428","3187.29956","0.07361"
"49.10000","4.90416","3237.71680","0.07361"
"49.20000","4.91424","3211.43188","0.07361"
"49.30000","4.92425","3247.40234","0.07361"
"49.40000","4.93436","3237.21582","0.07361"
"49.50000","4.94435","3220.22510","0.07361"
"49.60000","4.95428","3256.89062","0.07361"
"49.70000","4.96424","3199.80127","0.07361"
"49.80000","4.97399","3252.21094","0.07361"
"49.90000","4.98421","3221.09790","0.07361"
"50.00000","4.99430","3237.53052","0.07361"
"50.10000","5.00443","3237.71021","0.07361"
"50.20000","5.01434","3239.69800","0.07361"
"50.30000","5.02425","3237.27246","0.07361"
"50.40000","5.03416","3214.47559","0.07361"
"50.50000","5.04411","3227.76440","0.07361"
"50.60000","5.05426","3203.93408","0.07361"
"50.70000","5.06430","3240.74243","0.07361"
"50.80000","5.07438","3205.01562","0.07361"
"50.90000","5.08427","3252.95435","0.07361"
"51.00000","5.09421","3221.66650","0.07361"
"51.10000","5.10423","3210.74512","0.07361"
"51.20000","5.11426","3239.65698","0.07361"
"51.30000","5.12430","3200.99292","0.07361"
"51.40000","5.13427","3253.66113","0.07361"
"51.50000","5.14422","3218.06494","0.07361"
"51.60000","5.15422","3211.07178","0.07361"
"51.70000","5.16427","3237.50757","0.07361"
"51.80000","5.17432","3201.31885","0.07361"
"51.90000","5.18432","3253.71021","0.07361"
"52.00000","5.19428","3221.44702","0.07361"
"52.10000","5.20420","3232.84351","0.07361"
"52.20000","5.21407","3236.40381","0.07361"
"52.30000","5.22422","3203.00610","0.07361"
"52.40000","5.23433","3252.44824","0.07361"
"52.50000","5.24441","3223.20093","0.07361"
"52.60000","5.25431","3220.62451","0.07361"
"52.70000","5.26421","3234.90381","0.07361"
"52.80000","5.27414","3204.44995","0.07361"
"52.90000","5.28414","3258.20142","0.07361"
"53.00000","5.29429","3226.84570","0.07361"
"53.10000","5.30435","3251.58716","0.07361"
"53.20000","5.31442","3215.05811","0.07361"
"53.30000","5.32431","3215.86987","0.07361"
"53.40000","5.33416","3232.92505","0.07361"
"53.50000","5.34418","3196.95435","0.07361"
"53.60000","5.35419","3247.96362","0.07361"
"53.70000","5.36428","3202.93604","0.07361"
"53.80000","5.37428","3257.15942","0.07361"
"53.90000","5.38425","3217.33838","0.07361"
"54.00000","5.39424","3238.51880","0.07361"
"54.10000","5.40425","3231.97681","0.07361"
"54.20000","5.41425","3211.77271","0.07361"
"54.30000","5.42431","3244.51514","0.07361"
"54.40000","5.43431","3202.39746","0.07361"
"54.50000","5.44417","3256.86792","0.07361"
"54.60000","5.45416","3212.17505","0.07361"
"54.70000","5.46425","3267.70874","0.07361"
"54.80000","5.47439","3229.89624","0.07361"
"54.90000","5.48436","3237.51489","0.07361"
"55.00000","5.49429","3243.64014","0.07361"
"55.10000","5.50416","3214.44727","0.07361"
"55.20000","5.51410","3254.54517","0.07361"
"55.30000","5.52419","3210.51294","0.07361"
"55.40000","5.53427","3266.82080","0.07361"
"55.50000","5.54442","3221.88916","0.07361"
"55.60000","5.55439","3271.63379","0.07361"
"55.70000","5.56427","3231.46313","0.07361"
"55.80000","5.57413","3229.91040","0.07361"
"55.90000","5.58417","3247.40308","0.07361"
"56.00000","5.59420","3225.32544","0.07361"
"56.10000","5.60434","3276.04419","0.07361"
"56.20000","5.61436","3261.69702","0.07361"
"56.30000","5.62426","3217.04150","0.07361"
"56.40000","5.63422","3262.22705","0.07361"
"56.50000","5.64422","3217.60840","0.07361"
"56.60000","5.65424","3272.00024","0.07361"
"56.70000","5.66433","3222.27881","0.07361"
"56.80000","5.67428","3277.15527","0.07361"
"56.90000","5.68421","3229.20483","0.07361"
"57.00000","5.69421","3282.76538","0.07361"
"57.10000","5.70430","3240.21802","0.07361"
"57.20000","5.71430","3289.89990","0.07361"
"57.30000","5.72436","3250.12695","0.07361"
"57.40000","5.73427","3289.48730","0.07361"
"57.50000","5.74417","3256.17896","0.07361"
"57.60000","5.75410","3290.37793","0.07361"
"57.70000","5.76421","3259.86938","0.07361"
"57.80000","5.77427","3297.16504","0.07361"
"57.90000","5.78446","3261.99121","0.07361"
"58.00000","5.79438","3273.98706","0.07361"
"58.10000","5.80423","3249.60693","0.07361"
"58.20000","5.81411","3289.54614","0.07361"
"58.30000","5.82417","3257.18823","0.07361"
"58.40000","5.83419","3282.15356","0.07361"
"58.50000","5.84437","3273.92847","0.07361"
"58.60000","5.85439","3270.01587","0.07361"
"58.70000","5.86424","3288.03223","0.07361"
"58.80000","5.87424","3263.94482","0.07361"
"58.90000","5.88419","3302.98511","0.07361"
"59.00000","5.89424","3218.68701","0.07361"
"59.10000","5.90430","3275.08350","0.07361"
"59.20000","5.91429","3275.79980","0.07361"
"59.30000","5.92426","3278.44775","0.07361"
"59.40000","5.93422","3264.90503","0.07361"
"59.50000","5.94427","3298.17188","0.07361"
"59.60000","5.95427","3284.90918","0.07361"
"59.70000","5.96435","3330.90210","0.07361"
"59.80000","5.97429","3291.79102","0.07361"
"59.90000","5.98416","3285.61133","0.07361"
"60.00000","5.99412","3283.14746","0.07361"
"60.10000","6.00427","3304.45312","0.07361"
"60.20000","6.01431","3315.08936","0.07361"
"60.30000","6.02442","3259.63525","0.07361"
"60.40000","6.03436","3304.44653","0.07361"
"60.50000","6.04422","3265.76562","0.07361"
"60.60000","6.05412","3316.59399","0.07361"
"60.70000","6.06418","3263.91748","0.07361"
"60.80000","6.07423","3317.82617","0.07361"
"60.90000","6.08442","3271.35693","0.07361"
"61.00000","6.09440","3321.79468","0.07361"
"61.10000","6.10424","3275.19287","0.07361"
"61.20000","6.11416","3324.70117","0.07361"
"61.30000","6.12421","3277.25708","0.07361"
"61.40000","6.13420","3326.55688","0.07361"
"61.50000","6.14433","3279.39355","0.07361"
"61.60000","6.15435","3304.09302","0.07361"
"61.70000","6.16430","3284.60645","0.07361"
"61.80000","6.17420","3296.81714","0.07361"
"61.90000","6.18425","3287.51807","0.07361"
"62.00000","6.19424","3298.00684","0.07361"
"62.10000","6.20430","3288.52686","0.07361"
"62.20000","6.21431","3294.08081","0.07361"
"62.30000","6.22417","3286.40747","0.07361"
"62.40000","6.23418","3306.04346","0.07361"
"62.50000","6.24430","3279.70605","0.07361"
"62.60000","6.25433","3289.60303","0.07361"
"62.70000","6.26434","3279.33179","0.07361"
"62.80000","6.27438","3240.67017","0.07361"
"62.90000","6.28417","3292.65698","0.07361"
"63.00000","6.29414","3310.47485","0.07361"
"63.10000","6.30420","3292.09717","0.07361"
"63.20000","6.31427","3324.60034","0.07361"
"63.30000","6.32449","3259.98169","0.07361"
"63.40000","6.33441","3298.71021","0.07361"
"63.50000","6.34423","3263.70215","0.07361"
"63.60000","6.35415","3290.61450","0.07361"
"63.70000","6.36419","3270.58472","0.07361"
"63.80000","6.37415","3271.99316","0.07361"
"63.90000","6.38432","3279.72778","0.07361"
"64.00000","6.39440","3239.33472","0.07361"
"64.10000","6.40429","3285.12817","0.07361"
"64.20000","6.41424","3241.97412","0.07361"
"64.30000","6.42417","3297.66016","0.07361"
"64.40000","6.43420","3243.33789","0.07361"
"64.50000","6.44426","3298.92334","0.07361"
"64.60000","6.45436","3255.17017","0.07361"
"64.70000","6.46423","3300.88892","0.07361"
"64.80000","6.47422","3264.54297","0.07361"
"64.90000","6.48431","3301.61938","0.07361"
"65.00000","6.49429","3264.74707","0.07361"
"65.10000","6.50432","3250.61499","0.07361"
"65.20000","6.51430","3274.93555","0.07361"
"65.30000","6.52423","3260.42212","0.07361"
"65.40000","6.53413","3281.28857","0.07361"
"65.50000","6.54425","3297.01343","0.07361"
"65.60000","6.55431","3245.65356","0.07361"
"65.70000","6.56442","3273.68945","0.07361"
"65.80000","6.57436","3260.37451","0.07361"
"65.90000","6.58419","3306.99463","0.07361"
"66.00000","6.59419","3265.96606","0.07361"
"66.10000","6.60417","3319.76221","0.07361"
"66.20000","6.61424","3292.46851","0.07361"
"66.30000","6.62433","3247.72363","0.07361"
"66.40000","6.63442","3292.36914","0.07361"
"66.50000","6.64429","3268.95337","0.07361"
"66.60000","6.65419","3286.45850","0.07361"
"66.70000","6.66413","3298.44287","0.07361"
"66.80000","6.67425","3282.46387","0.07361"
"66.90000","6.68427","3313.25342","0.07361"
"67.00000","6.69435","3280.96118","0.07361"
"67.10000","6.70424","3326.15405","0.07361"
"67.20000","6.71428","3275.26709","0.07361"
"67.30000","6.72424","3315.67749","0.07361"
"67.40000","6.73428","3256.13916","0.07361"
"67.50000","6.74428","3309.78418","0.07361"
"67.60000","6.75427","3251.71362","0.07361"
"67.70000","6.76423","3307.34448","0.07361"
"67.80000","6.77423","3249.92139","0.07361"
"67.90000","6.78423","3303.29810","0.07361"
"68.00000","6.79432","3255.54272","0.07361"
"68.10000","6.80431","3301.68579","0.07361"
"68.20000","6.81433","3276.27148","0.07361"
"68.30000","6.82420","3294.39966","0.07361"
"68.40000","6.83416","3322.37939","0.07361"
"68.50000","6.84419","3284.79346","0.07361"
"68.60000","6.85426","3334.66821","0.07361"
"68.70000","6.86436","3297.13745","0.07361"
"68.80000","6.87442","3263.67505","0.07361"
"68.90000","6.88428","3314.94653","0.07361"
"69.00000","6.89420","3255.66968","0.07361"
"69.10000","6.90411","3311.50513","0.07361"
"69.20000","6.91422","3256.13257","0.07361"
"69.30000","6.92429","3306.55103","0.07361"
"69.40000","6.93438","3265.06128","0.07361"
"69.50000","6.94431","3298.96387","0.07361"
"69.60000","6.95426","3302.53345","0.07361"
"69.70000","6.96418","3288.84790","0.07361"
"69.80000","6.97416","3334.85034","0.07361"
"69.90000","6.98428","3280.00928","0.07361"
"70.00000","6.99425","3332.23828","0.07361"
"70.10000","7.00430","3274.14429","0.07361"
"70.20000","7.01425","3328.58521","0.07361"
"70.30000","7.02424","3247.05664","0.07361"
"70.40000","7.03428","3276.29224","0.07361"
"70.50000","7.04431","3242.83643","0.07361"
"70.60000","7.05431","3290.46094","0.07361"
"70.70000","7.06422","3309.53223","0.07361"
"70.80000","7.07419","3277.83862","0.07361"
"70.90000","7.08421","3329.28711","0.07361"
"71.00000","7.09429","3267.68237","0.07361"
"71.10000","7.10432","3322.79468","0.07361"
"71.20000","7.11434","3303.92798","0.07361"
"71.30000","7.12431","3256.12720","0.07361"
"71.40000","7.13420","3297.93359","0.07361"
"71.50000","7.14408","3286.86646","0.07361"
"71.60000","7.15417","3290.55200","0.07361"
"71.70000","7.16429","3310.04736","0.07361"
"71.80000","7.17442","3286.36865","0.07361"
"71.90000","7.18432","3329.79639","0.07361"
"72.00000","7.19426","3279.04004","0.07361"
"72.10000","7.20413","3331.31104","0.07361"
"72.20000","7.21422","3266.30396","0.07361"
"72.30000","7.22426","3322.31934","0.07361"
"72.40000","7.23429","3274.70483","0.07361"
"72.50000","7.24434","3291.43433","0.07361"
"72.60000","7.25429","3290.98950","0.07361"
"72.70000","7.26424","3307.24902","0.07361"
"72.80000","7.27423","3330.63867","0.07361"
"72.90000","7.28427","3312.51685","0.07361"
"73.00000","7.29428","3306.67871","0.07361"
"73.10000","7.30428","3318.26733","0.07361"
"73.20000","7.31420","3309.90527","0.07361"
"73.30000","7.32422","3339.74805","0.07361"
"73.40000","7.33425","3303.85083","0.07361"
"73.50000","7.34431","3352.78442","0.07361"
"73.60000","7.35436","3288.75928","0.07361"
"73.70000","7.36428","3341.29346","0.07361"
"73.80000","7.37419","3245.98706","0.07361"
"73.90000","7.38405","3300.21631","0.07361"
"74.00000","7.39421","3308.48926","0.07361"
"74.10000","7.40435","3290.23682","0.07361"
"74.20000","7.41440","3331.43945","0.07361"
"74.30000","7.42430","3282.79688","0.07361"
"74.40000","7.43421","3334.54907","0.07361"
"74.50000","7.44416","3271.50757","0.07361"
"74.60000","7.45415","3326.89795","0.07361"
"74.70000","7.46427","3262.03882","0.07361"
"74.80000","7.47429","3318.80835","0.07361"
"74.90000","7.48443","3253.38159","0.07361"
"75.00000","7.49429","3306.59326","0.07361"
"75.10000","7.50417","3260.47729","0.07361"
"75.20000","7.51418","3307.64160","0.07361"
"75.30000","7.52424","3292.80127","0.07361"
"75.40000","7.53433","3293.41699","0.07361"
"75.50000","7.54427","3311.48999","0.07361"
"75.60000","7.55422","3291.86816","0.07361"
"75.70000","7.56422","3341.27173","0.07361"
"75.80000","7.57428","3270.52661","0.07361"
"75.90000","7.58426","3322.17114","0.07361"
"76.00000","7.59435","3261.56323","0.07361"
"76.10000","7.60424","3315.07593","0.07361"
"76.20000","7.61423","3276.44238","0.07361"
"76.30000","7.62413","3305.12646","0.07361"
"76.40000","7.63424","3335.37500","0.07361"
"76.50000","7.64436","3293.85400","0.07361"
"76.60000","7.65440","3344.45874","0.07361"
"76.70000","7.66432","3277.45605","0.07361"
"76.80000","7.67416","3331.27490","0.07361"
"76.90000","7.68412","3311.23999","0.07361"
"77.00000","7.69414","3302.35962","0.07361"
"77.10000","7.70428","3314.43359","0.07361"
"77.20000","7.71438","3300.34058","0.07361"
"77.30000","7.72440","3292.35229","0.07361"
"77.40000","7.73427","3321.59473","0.07361"
"77.50000","7.74416","3289.05664","0.07361"
"77.60000","7.75418","3314.62036","0.07361"
"77.70000","7.76421","3295.90918","0.07361"
"77.80000","7.77435","3261.59595","0.07361"
"77.90000","7.78430","3298.09497","0.07361"
"78.00000","7.79426","3303.25244","0.07361"
"78.10000","7.80425","3278.52563","0.07361"
"78.20000","7.81420","3324.98657","0.07361"
"78.30000","7.82426","3251.29932","0.07361"
"78.40000","7.83431","3301.80591","0.07361"
"78.50000","7.84430","3273.47192","0.07361"
"78.60000","7.85419","3300.14111","0.07361"
"78.70000","7.86420","3247.45923","0.07361"
"78.80000","7.87423","3290.33740","0.07361"
"78.90000","7.88435","3317.55542","0.07361"
"79.00000","7.89439","3258.55103","0.07361"
"79.10000","7.90429","3309.30640","0.07361"
"79.20000","7.91419","3225.31274","0.07361"
"79.30000","7.92411","3278.53638","0.07361"
"79.40000","7.93422","3236.27002","0.07361"
"79.50000","7.94430","3257.83301","0.07361"
"79.60000","7.95441","3237.92578","0.07361"
"79.70000","7.96438","3235.49146","0.07361"
"79.80000","7.97420","3231.71387","0.07361"
"79.90000","7.98411","3217.85840","0.07361"
"80.00000","7.99416","3190.62427","0.07361"
"80.10000","8.00417","3202.87427","0.07361"
"80.20000","8.01439","3147.92065","0.07361"
"80.30000","8.02436","3192.63013","0.07361"
"80.40000","8.03424","3133.22290","0.07361"
"80.50000","8.04418","3141.45117","0.07361"
"80.60000","8.05419","3130.83154","0.07361"
"80.70000","8.06427","3081.87891","0.07361"
"80.80000","8.07431","3078.84131","0.07361"
"80.90000","8.08430","3080.57153","0.07361"
"81.00000","8.09425","3038.05005","0.07361"
"81.10000","8.10423","3003.33667","0.07361"
"81.20000","8.11429","2991.65405","0.07361"
"81.30000","8.12428","2984.62891","0.07361"
"81.40000","8.13439","2956.16650","0.07361"
"81.50000","8.14431","2921.05127","0.07361"
"81.60000","8.15421","2885.93726","0.07361"
"81.70000","8.16411","2851.74707","0.07361"
"81.80000","8.17431","2816.78662","0.07361"
"81.90000","8.18430","2780.92944","0.07361"
"82.00000","8.19445","2742.12769","0.07361"
"82.10000","8.20439","2699.26611","0.07361"
"82.20000","8.21423","2653.28052","0.07361"
"82.30000","8.22415","2600.74512","0.07361"
"82.40000","8.23419","2538.32275","0.07361"
"82.50000","8.24424","2463.10278","0.07361"
"82.59900","8.25436","1476.12073","0.07361"