File: archive/undergrad/433/Tensile Test/Specimen_RawData_9.csv
Time,Extension,Load,Strain Gage18
(s),(mm),(N),(mm/mm)
"0.00000","0.00000","284.37564","-0.00076"
"0.10000","0.00331","307.53830","-0.00077"
"0.20000","0.01351","381.59344","-0.00079"
"0.30000","0.02408","452.03284","-0.00082"
"0.40000","0.03420","500.40604","-0.00084"
"0.50000","0.04439","562.18707","-0.00086"
"0.60000","0.05440","621.79193","-0.00088"
"0.70000","0.06429","681.73859","-0.00090"
"0.80000","0.07420","741.80975","-0.00092"
"0.90000","0.08419","801.79181","-0.00095"
"1.00000","0.09426","861.40771","-0.00097"
"1.10000","0.10431","920.54193","-0.00099"
"1.20000","0.11433","978.84863","-0.00101"
"1.30000","0.12421","1036.01709","-0.00103"
"1.40000","0.13425","1094.03406","-0.00105"
"1.50000","0.14431","1152.48352","-0.00108"
"1.60000","0.15428","1209.91211","-0.00110"
"1.70000","0.16434","1268.12012","-0.00112"
"1.80000","0.17431","1325.12817","-0.00114"
"1.90000","0.18419","1381.95813","-0.00116"
"2.00000","0.19416","1439.04675","-0.00118"
"2.10000","0.20427","1496.99915","-0.00120"
"2.20000","0.21434","1554.34558","-0.00122"
"2.30000","0.22446","1611.88599","-0.00124"
"2.40000","0.23438","1668.03137","-0.00127"
"2.50000","0.24419","1723.21106","-0.00129"
"2.60000","0.25416","1779.10852","-0.00131"
"2.70000","0.26420","1835.26282","-0.00133"
"2.80000","0.27427","1891.25146","-0.00135"
"2.90000","0.28443","1947.51318","-0.00137"
"3.00000","0.29445","2002.16467","-0.00139"
"3.10000","0.30423","2054.68896","-0.00141"
"3.20000","0.31423","2107.87891","-0.00143"
"3.30000","0.32421","2160.04102","-0.00146"
"3.40000","0.33425","2211.34497","-0.00148"
"3.50000","0.34435","2261.41577","-0.00150"
"3.60000","0.35438","2309.04688","-0.00152"
"3.70000","0.36432","2353.87280","-0.00155"
"3.80000","0.37427","2395.63965","-0.00157"
"3.90000","0.38430","2434.19263","-0.00160"
"4.00000","0.39426","2467.28125","-0.00163"
"4.10000","0.40433","2496.37695","-0.00166"
"4.20000","0.41435","2519.79736","-0.00170"
"4.30000","0.42420","2538.40308","-0.00173"
"4.40000","0.43424","2553.68433","-0.00176"
"4.50000","0.44431","2565.36572","-0.00180"
"4.60000","0.45438","2574.90649","-0.00183"
"4.70000","0.46439","2581.67139","-0.00186"
"4.80000","0.47438","2587.38062","-0.00189"
"4.90000","0.48424","2592.57764","-0.00192"
"5.00000","0.49418","2598.21704","-0.00195"
"5.10000","0.50425","2603.35400","-0.00200"
"5.20000","0.51431","2607.33887","-0.00207"
"5.30000","0.52447","2611.49512","-0.00217"
"5.40000","0.53445","2613.37134","-0.00228"
"5.50000","0.54421","2616.12524","-0.00236"
"5.60000","0.55421","2618.43237","-0.00242"
"5.70000","0.56423","2620.90015","-0.00245"
"5.80000","0.57425","2619.54346","-0.00247"
"5.90000","0.58436","2622.81738","-0.00249"
"6.00000","0.59442","2622.40796","-0.00250"
"6.10000","0.60435","2623.02173","-0.00251"
"6.20000","0.61427","2625.86060","-0.00252"
"6.30000","0.62423","2628.55811","-0.00253"
"6.40000","0.63427","2630.93066","-0.00254"
"6.50000","0.64432","2633.46362","-0.00255"
"6.60000","0.65437","2635.02271","-0.00256"
"6.70000","0.66425","2637.39893","-0.00256"
"6.80000","0.67431","2645.07275","-0.00257"
"6.90000","0.68431","2658.35791","-0.00259"
"7.00000","0.69431","2613.09766","-0.00257"
"7.10000","0.70437","2621.92725","-0.00258"
"7.20000","0.71441","2629.84546","-0.00259"
"7.30000","0.72423","2638.38330","-0.00259"
"7.40000","0.73417","2637.16284","-0.00259"
"7.50000","0.74424","2640.29663","-0.00260"
"7.60000","0.75437","2639.75342","-0.00260"
"7.70000","0.76443","2643.11890","-0.00260"
"7.80000","0.77444","2647.44922","-0.00260"
"7.90000","0.78425","2652.47949","-0.00261"
"8.00000","0.79420","2654.90381","-0.00262"
"8.10000","0.80422","2642.30737","-0.00263"
"8.20000","0.81427","2643.40454","-0.00263"
"8.30000","0.82436","2643.11597","-0.00263"
"8.40000","0.83447","2651.10645","-0.00263"
"8.50000","0.84431","2659.60181","-0.00264"
"8.60000","0.85426","2665.85059","-0.00264"
"8.70000","0.86418","2666.96167","-0.00264"
"8.80000","0.87427","2651.83081","-0.00312"
"8.90000","0.88430","2647.07739","-0.00389"
"9.00000","0.89440","2671.20776","-0.00298"
"9.10000","0.90432","2661.23706","-0.00187"
"9.20000","0.91433","2656.08350","-0.00184"
"9.30000","0.92431","2664.79468","-0.00183"
"9.40000","0.93429","2671.22876","-0.00182"
"9.50000","0.94431","2686.53027","-0.00182"
"9.60000","0.95432","2694.85889","-0.00182"
"9.70000","0.96425","2702.87573","-0.00182"
"9.80000","0.97419","2722.22119","-0.00182"
"9.90000","0.98424","2706.53857","-0.00181"
"10.00000","0.99434","2728.11768","-0.00181"
"10.10000","1.00435","2730.55688","-0.00181"
"10.20000","1.01435","2720.12476","-0.00181"
"10.30000","1.02423","2736.51074","-0.00181"
"10.40000","1.03422","2745.36719","-0.00181"
"10.50000","1.04423","2708.80054","-0.00180"
"10.60000","1.05427","2717.22217","-0.00181"
"10.70000","1.06437","2720.69556","-0.00180"
"10.80000","1.07447","2730.78003","-0.00181"
"10.90000","1.08434","2732.63379","-0.00181"
"11.00000","1.09426","2736.52246","-0.00181"
"11.10000","1.10417","2735.79541","-0.00181"
"11.20000","1.11425","2736.65283","-0.00180"
"11.30000","1.12433","2738.83765","-0.00181"
"11.40000","1.13443","2740.41064","-0.00180"
"11.50000","1.14434","2740.61255","-0.00180"
"11.60000","1.15430","2743.93921","-0.00180"
"11.70000","1.16428","2743.73657","-0.00180"
"11.80000","1.17425","2746.64062","-0.00180"
"11.90000","1.18431","2746.90771","-0.00180"
"12.00000","1.19430","2747.57861","-0.00180"
"12.10000","1.20431","2751.28516","-0.00181"
"12.20000","1.21429","2747.45728","-0.00180"
"12.30000","1.22431","2765.03687","-0.00180"
"12.40000","1.23434","2750.48755","-0.00177"
"12.50000","1.24433","2777.24292","-0.00155"
"12.60000","1.25435","2765.53247","-0.00124"
"12.70000","1.26424","2770.06372","-0.00100"
"12.80000","1.27421","2780.88379","-0.00085"
"12.90000","1.28422","2782.43384","-0.00079"
"13.00000","1.29432","2786.81885","-0.00077"
"13.10000","1.30439","2778.05078","-0.00076"
"13.20000","1.31443","2753.84082","-0.00075"
"13.30000","1.32430","2762.45801","-0.00075"
"13.40000","1.33424","2773.31982","-0.00075"
"13.50000","1.34416","2770.94458","-0.00074"
"13.60000","1.35424","2775.87988","-0.00074"
"13.70000","1.36436","2783.07642","-0.00074"
"13.80000","1.37444","2789.60938","-0.00074"
"13.90000","1.38436","2792.99170","-0.00074"
"14.00000","1.39430","2773.07007","-0.00074"
"14.10000","1.40419","2818.02881","-0.00074"
"14.20000","1.41423","2762.03003","-0.00073"
"14.30000","1.42428","2768.62915","-0.00072"
"14.40000","1.43433","2771.81714","-0.00072"
"14.50000","1.44437","2776.78735","-0.00072"
"14.60000","1.45434","2784.21240","-0.00071"
"14.70000","1.46423","2790.66138","-0.00071"
"14.80000","1.47432","2792.92456","-0.00071"
"14.90000","1.48433","2801.22583","-0.00070"
"15.00000","1.49434","2805.02734","-0.00070"
"15.10000","1.50427","2812.85083","-0.00069"
"15.20000","1.51425","2802.44434","-0.00069"
"15.30000","1.52426","2803.12549","-0.00069"
"15.40000","1.53431","2808.06006","-0.00068"
"15.50000","1.54435","2814.21411","-0.00068"
"15.60000","1.55435","2818.29126","-0.00067"
"15.70000","1.56434","2809.06372","-0.00067"
"15.80000","1.57423","2836.65991","-0.00070"
"15.90000","1.58412","2853.40796","-0.00066"
"16.00000","1.59423","2837.11646","-0.00067"
"16.10000","1.60435","2855.97656","-0.00067"
"16.20000","1.61443","2869.32886","-0.00059"
"16.30000","1.62434","2876.59009","-0.00062"
"16.40000","1.63427","2847.70581","-0.00118"
"16.50000","1.64417","2879.91772","-0.00169"
"16.60000","1.65425","2862.73706","-0.00173"
"16.70000","1.66429","2856.78296","-0.00194"
"16.80000","1.67436","2861.36816","-0.00185"
"16.90000","1.68439","2860.25342","-0.00185"
"17.00000","1.69433","2874.46729","-0.00196"
"17.10000","1.70424","2879.60718","-0.00136"
"17.20000","1.71424","2870.37134","-0.00126"
"17.30000","1.72428","2887.93335","-0.00162"
"17.40000","1.73436","2892.95386","-0.00150"
"17.50000","1.74430","2894.04541","-0.00178"
"17.60000","1.75428","2906.49731","-0.00181"
"17.70000","1.76427","2890.01416","-0.00205"
"17.80000","1.77428","2899.43823","-0.00239"
"17.90000","1.78434","2889.32910","-0.00258"
"18.00000","1.79437","2900.90161","-0.00231"
"18.10000","1.80431","2904.77222","-0.00192"
"18.20000","1.81426","2916.11279","-0.00166"
"18.30000","1.82410","2913.12402","-0.00078"
"18.40000","1.83429","2912.85669","-0.00061"
"18.50000","1.84440","2917.66797","-0.00055"
"18.60000","1.85442","2916.49146","-0.00049"
"18.70000","1.86432","2862.38940","-0.00015"
"18.80000","1.87425","2860.18335","-0.00058"
"18.90000","1.88417","2870.20947","-0.00061"
"19.00000","1.89418","2878.54688","-0.00062"
"19.10000","1.90430","2879.19727","-0.00063"
"19.20000","1.91438","2877.26562","-0.00063"
"19.30000","1.92446","2875.71948","-0.00062"
"19.40000","1.93430","2877.78369","-0.00064"
"19.50000","1.94423","2878.12524","-0.00063"
"19.60000","1.95422","2879.49097","-0.00052"
"19.70000","1.96426","2881.63403","-0.00052"
"19.80000","1.97436","2883.96240","-0.00052"
"19.90000","1.98435","2881.60596","-0.00051"
"20.00000","1.99430","2884.95337","-0.00050"
"20.10000","2.00427","2887.78833","-0.00051"
"20.20000","2.01425","2886.98730","-0.00050"
"20.30000","2.02430","2887.57544","-0.00050"
"20.40000","2.03436","2891.26050","-0.00050"
"20.50000","2.04431","2890.03589","-0.00051"
"20.60000","2.05425","2887.78516","-0.00051"
"20.70000","2.06419","2874.98486","-0.00051"
"20.80000","2.07430","2906.10181","-0.00051"
"20.90000","2.08438","2901.52686","-0.00050"
"21.00000","2.09439","2923.04614","-0.00050"
"21.10000","2.10435","2931.42993","-0.00050"
"21.20000","2.11421","2911.25659","-0.00051"
"21.30000","2.12415","2927.20972","-0.00051"
"21.40000","2.13420","2966.94580","-0.00052"
"21.50000","2.14435","2959.00244","-0.00052"
"21.60000","2.15446","2931.47461","-0.00052"
"21.70000","2.16445","2934.36841","-0.00052"
"21.80000","2.17428","2951.01636","-0.00051"
"21.90000","2.18417","2962.25928","-0.00052"
"22.00000","2.19424","2959.41797","-0.00051"
"22.10000","2.20424","2952.09668","-0.00053"
"22.20000","2.21441","2946.36133","-0.00050"
"22.30000","2.22439","2945.87939","-0.00051"
"22.40000","2.23430","2997.73804","-0.00050"
"22.50000","2.24427","2906.61890","-0.00050"
"22.60000","2.25424","2912.62988","-0.00050"
"22.70000","2.26427","2918.97437","-0.00050"
"22.80000","2.27436","2919.66211","-0.00050"
"22.90000","2.28436","2907.45581","-0.00049"
"23.00000","2.29424","2942.61157","-0.00049"
"23.10000","2.30422","2972.04785","-0.00049"
"23.20000","2.31432","2977.94092","-0.00050"
"23.30000","2.32437","2929.87817","-0.00049"
"23.40000","2.33437","2928.17603","-0.00049"
"23.50000","2.34434","2909.90308","-0.00049"
"23.60000","2.35416","2956.82788","-0.00049"
"23.70000","2.36415","2976.55151","-0.00049"
"23.80000","2.37428","3002.28223","-0.00049"
"23.90000","2.38440","2992.35938","-0.00049"
"24.00000","2.39447","3016.33496","-0.00049"
"24.10000","2.40443","2982.69019","-0.00050"
"24.20000","2.41425","3030.53394","-0.00049"
"24.30000","2.42419","2975.07056","-0.00050"
"24.40000","2.43421","3004.38330","-0.00049"
"24.50000","2.44424","3013.77417","-0.00050"
"24.60000","2.45441","3001.39233","-0.00050"
"24.70000","2.46444","3038.49878","-0.00050"
"24.80000","2.47429","3027.76270","-0.00050"
"24.90000","2.48423","3021.42676","-0.00050"
"25.00000","2.49423","3010.91211","-0.00050"
"25.10000","2.50427","2985.33618","-0.00050"
"25.20000","2.51433","3035.02051","-0.00050"
"25.30000","2.52441","2975.31201","-0.00050"
"25.40000","2.53428","3021.89526","-0.00051"
"25.50000","2.54427","3026.88501","-0.00050"
"25.60000","2.55433","3015.70264","-0.00051"
"25.70000","2.56428","3021.19727","-0.00050"
"25.80000","2.57435","3026.45459","-0.00051"
"25.90000","2.58434","3023.36353","-0.00050"
"26.00000","2.59416","3026.00806","-0.00051"
"26.10000","2.60418","3024.28442","-0.00051"
"26.20000","2.61429","3022.93555","-0.00051"
"26.30000","2.62436","3020.47412","-0.00051"
"26.40000","2.63443","3019.61328","-0.00050"
"26.50000","2.64440","3028.37427","-0.00051"
"26.60000","2.65424","3025.40552","-0.00051"
"26.70000","2.66418","3019.45361","-0.00051"
"26.80000","2.67421","3013.94751","-0.00051"
"26.90000","2.68431","3009.52417","-0.00051"
"27.00000","2.69446","3010.07544","-0.00051"
"27.10000","2.70446","3014.81299","-0.00051"
"27.20000","2.71425","3027.59399","-0.00051"
"27.30000","2.72424","3018.14941","-0.00051"
"27.40000","2.73425","3008.64233","-0.00051"
"27.50000","2.74426","3006.81250","-0.00051"
"27.60000","2.75434","3003.55396","-0.00051"
"27.70000","2.76440","3007.47705","-0.00051"
"27.80000","2.77433","3004.44897","-0.00051"
"27.90000","2.78428","3027.29736","-0.00051"
"28.00000","2.79427","3031.41821","-0.00051"
"28.10000","2.80426","3002.37524","-0.00051"
"28.20000","2.81434","3025.86694","-0.00051"
"28.30000","2.82437","3010.86548","-0.00052"
"28.40000","2.83424","3001.70728","-0.00051"
"28.50000","2.84425","3003.73462","-0.00052"
"28.60000","2.85431","3017.03027","-0.00051"
"28.70000","2.86436","3004.75049","-0.00052"
"28.80000","2.87436","3014.09009","-0.00051"
"28.90000","2.88438","3029.34229","-0.00052"
"29.00000","2.89423","3060.90967","-0.00051"
"29.10000","2.90418","3082.28296","-0.00052"
"29.20000","2.91425","3041.35205","-0.00052"
"29.30000","2.92435","3038.57056","-0.00052"
"29.40000","2.93445","3043.03296","-0.00052"
"29.50000","2.94443","3050.58911","-0.00051"
"29.60000","2.95424","3048.85107","-0.00052"
"29.70000","2.96423","3047.67651","-0.00052"
"29.80000","2.97425","3047.53271","-0.00052"
"29.90000","2.98424","3058.08179","-0.00052"
"30.00000","2.99436","3058.70117","-0.00052"
"30.10000","3.00444","3041.95508","-0.00052"
"30.20000","3.01434","3049.26953","-0.00052"
"30.30000","3.02424","3077.70532","-0.00052"
"30.40000","3.03420","3094.14111","-0.00052"
"30.50000","3.04426","3074.61133","-0.00052"
"30.60000","3.05430","3067.04517","-0.00052"
"30.70000","3.06439","3073.41235","-0.00052"
"30.80000","3.07425","3096.50757","-0.00052"
"30.90000","3.08432","3091.57837","-0.00052"
"31.00000","3.09433","3101.12451","-0.00052"
"31.10000","3.10432","3079.85083","-0.00052"
"31.20000","3.11434","3084.84448","-0.00052"
"31.30000","3.12436","3097.80225","-0.00052"
"31.40000","3.13426","3083.98242","-0.00052"
"31.50000","3.14422","3085.88794","-0.00052"
"31.60000","3.15427","3096.77881","-0.00052"
"31.70000","3.16436","3091.61597","-0.00052"
"31.80000","3.17441","3087.17798","-0.00052"
"31.90000","3.18435","3103.27075","-0.00052"
"32.00000","3.19423","3106.35791","-0.00052"
"32.10000","3.20422","3091.07544","-0.00052"
"32.20000","3.21423","3090.42822","-0.00052"
"32.30000","3.22427","3114.69019","-0.00052"
"32.40000","3.23436","3107.22363","-0.00052"
"32.50000","3.24447","3094.34058","-0.00052"
"32.60000","3.25433","3060.15674","-0.00052"
"32.70000","3.26424","3087.30518","-0.00052"
"32.80000","3.27415","3085.26953","-0.00052"
"32.90000","3.28426","3079.64355","-0.00052"
"33.00000","3.29432","3077.82202","-0.00052"
"33.10000","3.30440","3123.20264","-0.00052"
"33.20000","3.31431","3125.59375","-0.00052"
"33.30000","3.32432","3098.15479","-0.00052"
"33.40000","3.33425","3120.62866","-0.00052"
"33.50000","3.34429","3048.48047","-0.00052"
"33.60000","3.35432","3037.94897","-0.00052"
"33.70000","3.36431","3055.97021","-0.00052"
"33.80000","3.37428","3066.68506","-0.00052"
"33.90000","3.38428","3052.58716","-0.00052"
"34.00000","3.39430","3061.46777","-0.00052"
"34.10000","3.40434","3079.02344","-0.00052"
"34.20000","3.41437","3107.32153","-0.00052"
"34.30000","3.42436","3108.29688","-0.00052"
"34.40000","3.43423","3109.20386","-0.00052"
"34.50000","3.44424","3137.69653","-0.00052"
"34.60000","3.45421","3135.65479","-0.00052"
"34.70000","3.46431","3114.26831","-0.00052"
"34.80000","3.47438","3098.87305","-0.00052"
"34.90000","3.48443","3138.32788","-0.00053"
"35.00000","3.49434","3141.31909","-0.00052"
"35.10000","3.50425","3125.80054","-0.00053"
"35.20000","3.51412","3130.52271","-0.00052"
"35.30000","3.52423","3106.12061","-0.00052"
"35.40000","3.53436","3140.07690","-0.00052"
"35.50000","3.54442","3138.23291","-0.00052"
"35.60000","3.55438","3122.67236","-0.00053"
"35.70000","3.56428","3142.83594","-0.00052"
"35.80000","3.57424","3151.27271","-0.00053"
"35.90000","3.58425","3131.13306","-0.00052"
"36.00000","3.59429","3139.41528","-0.00053"
"36.10000","3.60432","3088.99072","-0.00052"
"36.20000","3.61432","3136.94434","-0.00053"
"36.30000","3.62433","3142.72754","-0.00052"
"36.40000","3.63428","3130.53979","-0.00053"
"36.50000","3.64430","3166.28931","-0.00053"
"36.60000","3.65433","3178.90894","-0.00053"
"36.70000","3.66436","3169.19312","-0.00053"
"36.80000","3.67427","3137.36914","-0.00052"
"36.90000","3.68421","3141.88965","-0.00053"
"37.00000","3.69423","3173.23096","-0.00052"
"37.10000","3.70432","3162.92603","-0.00053"
"37.20000","3.71441","3165.10498","-0.00052"
"37.30000","3.72439","3139.19043","-0.00053"
"37.40000","3.73432","3174.88696","-0.00053"
"37.50000","3.74423","3157.24585","-0.00053"
"37.60000","3.75413","3140.91553","-0.00053"
"37.70000","3.76422","3164.96167","-0.00053"
"37.80000","3.77438","3169.51880","-0.00053"
"37.90000","3.78445","3148.27295","-0.00053"
"38.00000","3.79437","3153.76440","-0.00053"
"38.10000","3.80426","3172.91016","-0.00053"
"38.20000","3.81420","3149.40991","-0.00053"
"38.30000","3.82420","3149.20850","-0.00053"
"38.40000","3.83425","3171.75659","-0.00053"
"38.50000","3.84437","3165.49121","-0.00053"
"38.60000","3.85439","3149.39331","-0.00053"
"38.70000","3.86437","3153.84497","-0.00053"
"38.80000","3.87426","3166.53027","-0.00053"
"38.90000","3.88427","3145.70215","-0.00053"
"39.00000","3.89430","3155.20996","-0.00052"
"39.10000","3.90430","3154.51074","-0.00053"
"39.20000","3.91429","3194.54346","-0.00052"
"39.30000","3.92427","3162.42529","-0.00053"
"39.40000","3.93428","3203.02539","-0.00052"
"39.50000","3.94430","3187.02466","-0.00053"
"39.60000","3.95435","3118.35132","-0.00053"
"39.70000","3.96433","3147.61523","-0.00053"
"39.80000","3.97433","3152.31641","-0.00053"
"39.90000","3.98424","3128.62622","-0.00052"
"40.00000","3.99415","3121.58789","-0.00053"
"40.10000","4.00425","3155.60669","-0.00052"
"40.20000","4.01438","3141.01538","-0.00053"
"40.30000","4.02447","3130.30298","-0.00052"
"40.40000","4.03433","3186.35693","-0.00053"
"40.50000","4.04425","3172.97241","-0.00052"
"40.60000","4.05417","3222.60938","-0.00053"
"40.70000","4.06419","3187.72461","-0.00053"
"40.80000","4.07430","3179.84082","-0.00053"
"40.90000","4.08439","3167.00610","-0.00053"
"41.00000","4.09443","3188.61279","-0.00052"
"41.10000","4.10431","3163.14185","-0.00053"
"41.20000","4.11424","3201.99536","-0.00052"
"41.30000","4.12423","3190.75146","-0.00053"
"41.40000","4.13431","3137.60083","-0.00052"
"41.50000","4.14432","3193.90625","-0.00053"
"41.60000","4.15434","3154.70435","-0.00053"
"41.70000","4.16430","3192.78052","-0.00053"
"41.80000","4.17428","3178.79810","-0.00053"
"41.90000","4.18428","3162.90137","-0.00053"
"42.00000","4.19425","3173.65308","-0.00053"
"42.10000","4.20435","3189.89160","-0.00053"
"42.20000","4.21430","3164.60425","-0.00053"
"42.30000","4.22415","3220.11475","-0.00053"
"42.40000","4.23417","3195.95605","-0.00053"
"42.50000","4.24433","3140.53735","-0.00053"
"42.60000","4.25438","3181.91211","-0.00053"
"42.70000","4.26442","3154.52710","-0.00053"
"42.80000","4.27432","3159.31445","-0.00053"
"42.90000","4.28420","3187.64551","-0.00053"
"43.00000","4.29415","3202.02563","-0.00053"
"43.10000","4.30422","3220.89966","-0.00053"
"43.20000","4.31437","3167.89966","-0.00053"
"43.30000","4.32443","3224.37354","-0.00053"
"43.40000","4.33448","3194.18237","-0.00053"
"43.50000","4.34428","3211.66992","-0.00053"
"43.60000","4.35418","3216.92529","-0.00053"
"43.70000","4.36421","3166.50537","-0.00053"
"43.80000","4.37425","3177.56543","-0.00053"
"43.90000","4.38438","3187.40942","-0.00053"
"44.00000","4.39439","3180.52246","-0.00053"
"44.10000","4.40430","3160.13062","-0.00053"
"44.20000","4.41424","3208.57812","-0.00053"
"44.30000","4.42426","3194.44019","-0.00053"
"44.40000","4.43427","3240.64380","-0.00053"
"44.50000","4.44438","3168.72290","-0.00053"
"44.60000","4.45432","3224.51636","-0.00053"
"44.70000","4.46428","3184.92871","-0.00053"
"44.80000","4.47421","3204.26904","-0.00053"
"44.90000","4.48433","3204.51587","-0.00053"
"45.00000","4.49437","3171.86157","-0.00053"
"45.10000","4.50438","3205.96167","-0.00053"
"45.20000","4.51435","3172.52612","-0.00053"
"45.30000","4.52418","3223.74243","-0.00053"
"45.40000","4.53417","3177.18164","-0.00053"
"45.50000","4.54424","3187.07788","-0.00053"
"45.60000","4.55436","3211.03369","-0.00053"
"45.70000","4.56447","3183.10181","-0.00053"
"45.80000","4.57443","3230.92188","-0.00053"
"45.90000","4.58428","3203.08765","-0.00053"
"46.00000","4.59413","3247.27979","-0.00053"
"46.10000","4.60423","3187.56616","-0.00053"
"46.20000","4.61424","3234.88257","-0.00053"
"46.30000","4.62442","3204.65234","-0.00053"
"46.40000","4.63443","3195.04224","-0.00053"
"46.50000","4.64430","3222.00439","-0.00053"
"46.60000","4.65425","3184.43115","-0.00053"
"46.70000","4.66422","3233.65820","-0.00053"
"46.80000","4.67427","3201.33716","-0.00053"
"46.90000","4.68434","3188.58276","-0.00053"
"47.00000","4.69437","3222.55005","-0.00053"
"47.10000","4.70427","3197.04858","-0.00053"
"47.20000","4.71424","3167.85547","-0.00053"
"47.30000","4.72429","3200.84839","-0.00053"
"47.40000","4.73434","3196.74097","-0.00052"
"47.50000","4.74442","3241.04834","-0.00053"
"47.60000","4.75437","3177.02417","-0.00052"
"47.70000","4.76417","3232.40869","-0.00053"
"47.80000","4.77417","3238.16772","-0.00052"
"47.90000","4.78432","3222.18726","-0.00053"
"48.00000","4.79435","3238.74609","-0.00053"
"48.10000","4.80445","3213.42529","-0.00053"
"48.20000","4.81438","3251.30444","-0.00053"
"48.30000","4.82427","3213.97217","-0.00053"
"48.40000","4.83413","3264.44019","-0.00053"
"48.50000","4.84422","3228.55371","-0.00053"
"48.60000","4.85426","3257.47314","-0.00053"
"48.70000","4.86445","3247.38354","-0.00053"
"48.80000","4.87447","3236.77808","-0.00053"
"48.90000","4.88426","3198.67236","-0.00053"
"49.00000","4.89421","3214.71924","-0.00053"
"49.10000","4.90425","3213.48730","-0.00053"
"49.20000","4.91428","3187.61011","-0.00053"
"49.30000","4.92431","3233.50537","-0.00053"
"49.40000","4.93442","3207.89551","-0.00053"
"49.50000","4.94430","3238.21240","-0.00053"
"49.60000","4.95427","3235.56836","-0.00053"
"49.70000","4.96428","3258.02271","-0.00053"
"49.80000","4.97427","3216.71216","-0.00053"
"49.90000","4.98430","3259.00098","-0.00053"
"50.00000","4.99435","3242.79102","-0.00053"
"50.10000","5.00424","3263.52686","-0.00053"
"50.20000","5.01425","3223.72656","-0.00053"
"50.30000","5.02435","3270.27246","-0.00053"
"50.40000","5.03438","3237.17383","-0.00053"
"50.50000","5.04439","3265.80640","-0.00053"
"50.60000","5.05439","3237.66846","-0.00053"
"50.70000","5.06422","3261.30762","-0.00053"
"50.80000","5.07419","3233.79517","-0.00053"
"50.90000","5.08420","3266.33936","-0.00053"
"51.00000","5.09436","3228.73218","-0.00053"
"51.10000","5.10441","3277.42773","-0.00053"
"51.20000","5.11447","3236.08960","-0.00053"
"51.30000","5.12422","3285.56421","-0.00053"
"51.40000","5.13423","3241.04028","-0.00053"
"51.50000","5.14422","3289.39038","-0.00053"
"51.60000","5.15426","3267.98413","-0.00053"
"51.70000","5.16437","3260.36694","-0.00053"
"51.80000","5.17441","3264.70508","-0.00053"
"51.90000","5.18434","3271.76270","-0.00053"
"52.00000","5.19427","3246.31885","-0.00053"
"52.10000","5.20426","3287.39111","-0.00053"
"52.20000","5.21427","3251.14941","-0.00053"
"52.30000","5.22429","3277.39038","-0.00053"
"52.40000","5.23435","3264.01001","-0.00053"
"52.50000","5.24424","3262.26343","-0.00053"
"52.60000","5.25429","3273.94897","-0.00053"
"52.70000","5.26432","3243.16626","-0.00053"
"52.80000","5.27436","3279.31006","-0.00053"
"52.90000","5.28434","3235.31519","-0.00053"
"53.00000","5.29433","3287.14429","-0.00053"
"53.10000","5.30427","3238.94653","-0.00053"
"53.20000","5.31420","3292.80981","-0.00053"
"53.30000","5.32431","3244.16113","-0.00053"
"53.40000","5.33435","3290.28247","-0.00053"
"53.50000","5.34446","3249.59424","-0.00053"
"53.60000","5.35438","3245.48291","-0.00053"
"53.70000","5.36425","3268.02173","-0.00053"
"53.80000","5.37422","3233.85400","-0.00053"
"53.90000","5.38422","3286.30322","-0.00053"
"54.00000","5.39428","3241.65698","-0.00053"
"54.10000","5.40437","3296.39355","-0.00053"
"54.20000","5.41447","3247.58545","-0.00053"
"54.30000","5.42432","3298.80688","-0.00053"
"54.40000","5.43425","3248.16699","-0.00053"
"54.50000","5.44414","3299.81958","-0.00053"
"54.60000","5.45427","3252.03735","-0.00053"
"54.70000","5.46432","3302.87183","-0.00053"
"54.80000","5.47439","3259.21729","-0.00053"
"54.90000","5.48432","3306.28491","-0.00053"
"55.00000","5.49432","3262.99780","-0.00053"
"55.10000","5.50425","3295.67676","-0.00053"
"55.20000","5.51427","3265.64160","-0.00053"
"55.30000","5.52431","3272.87842","-0.00053"
"55.40000","5.53437","3269.27686","-0.00053"
"55.50000","5.54429","3241.39258","-0.00053"
"55.60000","5.55422","3276.31763","-0.00053"
"55.70000","5.56428","3261.66016","-0.00053"
"55.80000","5.57436","3238.75317","-0.00053"
"55.90000","5.58440","3281.41309","-0.00053"
"56.00000","5.59438","3251.19507","-0.00052"
"56.10000","5.60424","3274.15234","-0.00053"
"56.20000","5.61421","3268.45532","-0.00052"
"56.30000","5.62421","3244.42505","-0.00053"
"56.40000","5.63429","3282.74902","-0.00053"
"56.50000","5.64440","3243.58521","-0.00053"
"56.60000","5.65443","3294.38721","-0.00053"
"56.70000","5.66433","3256.45850","-0.00053"
"56.80000","5.67425","3299.15649","-0.00053"
"56.90000","5.68412","3268.72656","-0.00052"
"57.00000","5.69422","3267.79077","-0.00053"
"57.10000","5.70432","3280.00293","-0.00052"
"57.20000","5.71445","3241.80908","-0.00053"
"57.30000","5.72435","3291.99097","-0.00052"
"57.40000","5.73435","3247.27563","-0.00053"
"57.50000","5.74423","3300.13892","-0.00053"
"57.60000","5.75426","3257.22388","-0.00053"
"57.70000","5.76431","3289.44727","-0.00053"
"57.80000","5.77433","3240.58447","-0.00053"
"57.90000","5.78431","3287.74976","-0.00053"
"58.00000","5.79433","3243.11230","-0.00052"
"58.10000","5.80424","3293.97534","-0.00053"
"58.20000","5.81431","3246.55518","-0.00052"
"58.30000","5.82431","3296.82666","-0.00053"
"58.40000","5.83431","3252.06470","-0.00053"
"58.50000","5.84424","3294.81030","-0.00053"
"58.60000","5.85425","3256.92285","-0.00053"
"58.70000","5.86424","3268.54736","-0.00053"
"58.80000","5.87430","3264.80908","-0.00053"
"58.90000","5.88437","3243.09692","-0.00053"
"59.00000","5.89441","3271.45312","-0.00053"
"59.10000","5.90433","3236.60474","-0.00052"
"59.20000","5.91426","3273.25952","-0.00053"
"59.30000","5.92415","3231.10522","-0.00052"
"59.40000","5.93423","3283.46387","-0.00053"
"59.50000","5.94439","3236.77539","-0.00052"
"59.60000","5.95442","3292.03076","-0.00053"
"59.70000","5.96438","3245.62524","-0.00053"
"59.80000","5.97427","3295.82422","-0.00053"
"59.90000","5.98423","3254.32007","-0.00053"
"60.00000","5.99419","3273.70312","-0.00052"
"60.10000","6.00431","3264.01147","-0.00053"
"60.20000","6.01432","3245.22778","-0.00052"
"60.30000","6.02437","3274.98389","-0.00053"
"60.40000","6.03436","3235.33130","-0.00052"
"60.50000","6.04425","3282.69458","-0.00053"
"60.60000","6.05427","3236.68726","-0.00053"
"60.70000","6.06430","3290.82275","-0.00053"
"60.80000","6.07436","3244.34521","-0.00053"
"60.90000","6.08426","3296.44116","-0.00053"
"61.00000","6.09427","3245.05762","-0.00053"
"61.10000","6.10424","3270.68188","-0.00052"
"61.20000","6.11432","3260.22290","-0.00053"
"61.30000","6.12436","3213.51660","-0.00052"
"61.40000","6.13437","3254.29224","-0.00053"
"61.50000","6.14432","3215.82666","-0.00052"
"61.60000","6.15423","3264.37695","-0.00053"
"61.70000","6.16417","3223.84644","-0.00053"
"61.80000","6.17424","3274.74805","-0.00053"
"61.90000","6.18441","3246.94263","-0.00053"
"62.00000","6.19440","3296.11646","-0.00053"
"62.10000","6.20438","3258.20557","-0.00053"
"62.20000","6.21425","3248.74902","-0.00052"
"62.30000","6.22417","3273.85962","-0.00053"
"62.40000","6.23419","3266.15088","-0.00052"
"62.50000","6.24427","3288.52271","-0.00053"
"62.60000","6.25439","3310.50195","-0.00052"
"62.70000","6.26441","3294.31323","-0.00053"
"62.80000","6.27432","3300.26904","-0.00052"
"62.90000","6.28421","3257.62329","-0.00052"
"63.00000","6.29423","3305.23804","-0.00052"
"63.10000","6.30430","3264.65674","-0.00052"
"63.20000","6.31434","3299.37402","-0.00052"
"63.30000","6.32433","3248.45801","-0.00052"
"63.40000","6.33428","3298.08154","-0.00052"
"63.50000","6.34430","3257.66211","-0.00052"
"63.60000","6.35427","3299.59692","-0.00052"
"63.70000","6.36430","3279.45605","-0.00052"
"63.80000","6.37437","3280.83813","-0.00052"
"63.90000","6.38433","3263.28125","-0.00052"
"64.00000","6.39423","3272.56274","-0.00052"
"64.10000","6.40415","3283.03491","-0.00052"
"64.20000","6.41429","3277.08301","-0.00052"
"64.30000","6.42438","3289.01440","-0.00052"
"64.40000","6.43443","3269.55884","-0.00052"
"64.50000","6.44431","3300.01562","-0.00052"
"64.60000","6.45423","3273.75342","-0.00052"
"64.70000","6.46412","3314.12622","-0.00052"
"64.80000","6.47423","3284.97437","-0.00052"
"64.90000","6.48430","3321.75342","-0.00052"
"65.00000","6.49445","3301.93115","-0.00052"
"65.10000","6.50443","3286.87573","-0.00052"
"65.20000","6.51430","3277.54321","-0.00052"
"65.30000","6.52419","3326.69849","-0.00052"
"65.40000","6.53422","3274.27173","-0.00052"
"65.50000","6.54424","3323.61719","-0.00052"
"65.60000","6.55435","3287.89648","-0.00052"
"65.70000","6.56437","3333.47461","-0.00052"
"65.80000","6.57431","3300.58862","-0.00052"
"65.90000","6.58426","3346.93604","-0.00052"
"66.00000","6.59426","3307.55151","-0.00052"
"66.10000","6.60429","3296.92285","-0.00052"
"66.20000","6.61437","3316.39502","-0.00052"
"66.30000","6.62434","3274.17505","-0.00052"
"66.40000","6.63425","3320.94702","-0.00052"
"66.50000","6.64419","3306.40625","-0.00052"
"66.60000","6.65434","3299.34399","-0.00052"
"66.70000","6.66437","3310.02100","-0.00052"
"66.80000","6.67440","3308.40942","-0.00052"
"66.90000","6.68432","3305.39526","-0.00052"
"67.00000","6.69420","3286.07788","-0.00052"
"67.10000","6.70416","3276.93408","-0.00052"
"67.20000","6.71423","3278.92725","-0.00052"
"67.30000","6.72435","3278.53516","-0.00052"
"67.40000","6.73443","3252.37109","-0.00052"
"67.50000","6.74446","3304.11279","-0.00052"
"67.60000","6.75423","3318.10376","-0.00052"
"67.70000","6.76421","3302.85352","-0.00052"
"67.80000","6.77421","3352.00122","-0.00052"
"67.90000","6.78429","3234.29956","-0.00052"
"68.00000","6.79442","3294.73730","-0.00052"
"68.10000","6.80443","3259.15747","-0.00052"
"68.20000","6.81430","3311.80249","-0.00052"
"68.30000","6.82421","3292.48535","-0.00052"
"68.40000","6.83424","3312.00000","-0.00052"
"68.50000","6.84426","3298.76270","-0.00052"
"68.60000","6.85435","3311.67773","-0.00052"
"68.70000","6.86435","3290.12085","-0.00052"
"68.80000","6.87426","3314.49365","-0.00052"
"68.90000","6.88426","3300.76318","-0.00052"
"69.00000","6.89432","3316.86621","-0.00052"
"69.10000","6.90431","3318.63281","-0.00052"
"69.20000","6.91437","3313.97656","-0.00052"
"69.30000","6.92434","3326.40454","-0.00052"
"69.40000","6.93422","3310.37524","-0.00052"
"69.50000","6.94415","3324.84692","-0.00052"
"69.60000","6.95429","3304.62280","-0.00052"
"69.70000","6.96439","3287.36182","-0.00052"
"69.80000","6.97445","3310.19238","-0.00052"
"69.90000","6.98441","3301.67822","-0.00052"
"70.00000","6.99425","3307.87036","-0.00052"
"70.10000","7.00414","3341.18042","-0.00052"
"70.20000","7.01424","3301.71851","-0.00052"
"70.30000","7.02425","3350.24927","-0.00052"
"70.40000","7.03447","3296.87329","-0.00052"
"70.50000","7.04442","3347.86743","-0.00052"
"70.60000","7.05431","3286.36328","-0.00052"
"70.70000","7.06423","3333.61963","-0.00053"
"70.80000","7.07424","3330.76270","-0.00052"
"70.90000","7.08427","3278.92090","-0.00053"
"71.00000","7.09433","3325.27490","-0.00052"
"71.10000","7.10440","3269.41504","-0.00053"
"71.20000","7.11430","3316.56934","-0.00052"
"71.30000","7.12425","3302.29004","-0.00052"
"71.40000","7.13430","3306.10791","-0.00052"
"71.50000","7.14432","3352.35718","-0.00052"
"71.60000","7.15435","3292.16528","-0.00053"
"71.70000","7.16432","3344.30664","-0.00052"
"71.80000","7.17418","3299.94189","-0.00053"
"71.90000","7.18421","3323.52930","-0.00052"
"72.00000","7.19435","3286.82104","-0.00053"
"72.10000","7.20438","3332.80054","-0.00052"
"72.20000","7.21446","3273.19287","-0.00053"
"72.30000","7.22435","3324.57275","-0.00052"
"72.40000","7.23426","3271.61914","-0.00052"
"72.50000","7.24416","3315.37695","-0.00052"
"72.60000","7.25422","3282.45581","-0.00052"
"72.70000","7.26429","3301.44995","-0.00053"
"72.80000","7.27443","3286.06787","-0.00052"
"72.90000","7.28446","3301.49976","-0.00053"
"73.00000","7.29423","3319.36182","-0.00052"
"73.10000","7.30424","3293.27368","-0.00053"
"73.20000","7.31419","3340.21118","-0.00052"
"73.30000","7.32430","3286.45142","-0.00052"
"73.40000","7.33432","3337.56958","-0.00052"
"73.50000","7.34446","3278.49512","-0.00052"
"73.60000","7.35432","3331.27417","-0.00052"
"73.70000","7.36430","3269.21167","-0.00052"
"73.80000","7.37424","3322.46387","-0.00052"
"73.90000","7.38428","3273.76611","-0.00052"
"74.00000","7.39431","3314.05518","-0.00052"
"74.10000","7.40436","3292.45581","-0.00052"
"74.20000","7.41420","3306.27124","-0.00052"
"74.30000","7.42425","3324.68408","-0.00052"
"74.40000","7.43432","3300.99243","-0.00052"
"74.50000","7.44430","3347.35547","-0.00052"
"74.60000","7.45439","3293.92065","-0.00052"
"74.70000","7.46437","3345.50513","-0.00053"
"74.80000","7.47425","3284.76343","-0.00052"
"74.90000","7.48418","3338.86865","-0.00053"
"75.00000","7.49426","3277.05933","-0.00052"
"75.10000","7.50436","3330.60742","-0.00053"
"75.20000","7.51447","3307.25488","-0.00052"
"75.30000","7.52441","3317.99829","-0.00053"
"75.40000","7.53423","3331.30469","-0.00052"
"75.50000","7.54423","3341.42529","-0.00053"
"75.60000","7.55425","3330.55566","-0.00053"
"75.70000","7.56426","3354.36572","-0.00052"
"75.80000","7.57434","3313.24048","-0.00052"
"75.90000","7.58443","3359.93457","-0.00052"
"76.00000","7.59438","3311.37671","-0.00052"
"76.10000","7.60424","3360.85791","-0.00052"
"76.20000","7.61423","3312.37720","-0.00052"
"76.30000","7.62422","3364.42627","-0.00052"
"76.40000","7.63433","3312.20557","-0.00052"
"76.50000","7.64438","3365.84082","-0.00052"
"76.60000","7.65431","3310.92065","-0.00052"
"76.70000","7.66430","3361.69678","-0.00052"
"76.80000","7.67430","3319.25684","-0.00052"
"76.90000","7.68432","3347.68896","-0.00052"
"77.00000","7.69431","3342.26147","-0.00052"
"77.10000","7.70434","3356.27710","-0.00052"
"77.20000","7.71423","3374.16089","-0.00052"
"77.30000","7.72427","3330.21143","-0.00052"
"77.40000","7.73428","3370.83179","-0.00052"
"77.50000","7.74437","3364.47705","-0.00052"
"77.60000","7.75441","3353.67700","-0.00052"
"77.70000","7.76434","3386.85693","-0.00052"
"77.80000","7.77426","3363.12427","-0.00052"
"77.90000","7.78422","3397.21924","-0.00052"
"78.00000","7.79426","3285.37012","-0.00052"
"78.10000","7.80426","3340.71411","-0.00052"
"78.20000","7.81441","3274.00415","-0.00052"
"78.30000","7.82444","3330.40918","-0.00052"
"78.40000","7.83435","3266.36841","-0.00052"
"78.50000","7.84422","3320.65112","-0.00052"
"78.60000","7.85413","3273.18530","-0.00052"
"78.70000","7.86425","3310.65430","-0.00052"
"78.80000","7.87430","3303.78418","-0.00052"
"78.90000","7.88441","3300.33301","-0.00052"
"79.00000","7.89431","3348.26147","-0.00052"
"79.10000","7.90438","3284.24048","-0.00052"
"79.20000","7.91425","3336.58008","-0.00052"
"79.30000","7.92430","3266.42578","-0.00052"
"79.40000","7.93428","3320.70630","-0.00052"
"79.50000","7.94431","3282.61938","-0.00052"
"79.60000","7.95431","3301.76123","-0.00052"
"79.70000","7.96429","3344.91016","-0.00052"
"79.80000","7.97430","3270.01172","-0.00052"
"79.90000","7.98432","3323.20605","-0.00052"
"80.00000","7.99437","3272.49438","-0.00052"
"80.10000","8.00434","3304.93701","-0.00052"
"80.20000","8.01423","3343.33325","-0.00052"
"80.30000","8.02423","3276.42383","-0.00052"
"80.40000","8.03422","3322.98389","-0.00052"
"80.50000","8.04432","3266.20312","-0.00052"
"80.60000","8.05437","3318.62427","-0.00052"
"80.70000","8.06442","3247.98145","-0.00052"
"80.80000","8.07430","3292.65527","-0.00052"
"80.90000","8.08426","3317.39893","-0.00052"
"81.00000","8.09413","3264.15967","-0.00052"
"81.10000","8.10421","3313.27271","-0.00052"
"81.20000","8.11437","3243.29175","-0.00052"
"81.30000","8.12441","3294.25195","-0.00053"
"81.40000","8.13439","3228.46802","-0.00052"
"81.50000","8.14429","3278.97632","-0.00053"
"81.60000","8.15423","3213.05615","-0.00052"
"81.70000","8.16418","3256.71948","-0.00053"
"81.80000","8.17432","3202.96094","-0.00053"
"81.90000","8.18429","3190.55664","-0.00053"
"82.00000","8.19438","3196.93164","-0.00053"
"82.10000","8.20435","3146.91333","-0.00053"
"82.20000","8.21426","3180.90845","-0.00053"
"82.30000","8.22430","3143.56714","-0.00053"
"82.40000","8.23434","3104.76050","-0.00053"
"82.50000","8.24434","3114.45532","-0.00053"
"82.60000","8.25425","3098.74390","-0.00053"
"82.70000","8.26428","3060.87427","-0.00053"
"82.80000","8.27424","3036.12085","-0.00053"
"82.90000","8.28430","3030.76758","-0.00053"
"83.00000","8.29437","3016.67798","-0.00053"
"83.10000","8.30438","2987.27637","-0.00053"
"83.20000","8.31433","2956.62500","-0.00053"
"83.30000","8.32424","2926.78223","-0.00053"
"83.40000","8.33412","2897.43091","-0.00053"
"83.50000","8.34424","2866.73022","-0.00053"
"83.60000","8.35442","2834.90771","-0.00053"
"83.70000","8.36445","2801.00952","-0.00053"
"83.80000","8.37439","2765.44775","-0.00053"
"83.90000","8.38425","2726.63623","-0.00053"
"84.00000","8.39421","2683.70166","-0.00053"
"84.10000","8.40422","2635.37451","-0.00053"
"84.20000","8.41431","2579.97021","-0.00053"
"84.30000","8.42438","2515.66016","-0.00053"
"84.40000","8.43441","2438.08960","-0.00053"
"84.44900","8.43919","1474.22742","-0.00052"