File: archive/undergrad/433/Tensile Test/Specimen_RawData_8.csv
Time,Extension,Load,Strain Gage18
(s),(mm),(N),(mm/mm)
"0.00000","0.59264","265.66132","0.00022"
"0.10000","0.59588","287.35132","0.00024"
"0.20000","0.60591","358.52219","0.00032"
"0.30000","0.61654","430.93640","0.00039"
"0.40000","0.62664","495.57532","0.00046"
"0.50000","0.63671","557.34058","0.00052"
"0.60000","0.64667","617.53778","0.00059"
"0.70000","0.65678","678.90015","0.00065"
"0.80000","0.66673","738.75757","0.00071"
"0.90000","0.67661","797.71692","0.00077"
"1.00000","0.68663","856.45874","0.00083"
"1.10000","0.69679","915.61407","0.00089"
"1.20000","0.70683","974.37549","0.00095"
"1.30000","0.71684","1032.15674","0.00101"
"1.40000","0.72683","1089.90881","0.00107"
"1.50000","0.73665","1146.50085","0.00113"
"1.60000","0.74661","1204.11426","0.00119"
"1.70000","0.75662","1261.78223","0.00125"
"1.80000","0.76673","1320.05396","0.00131"
"1.90000","0.77687","1378.30786","0.00137"
"2.00000","0.78688","1435.52283","0.00143"
"2.10000","0.79669","1491.45984","0.00149"
"2.20000","0.80664","1547.98096","0.00155"
"2.30000","0.81665","1604.73828","0.00161"
"2.40000","0.82668","1661.18884","0.00166"
"2.50000","0.83676","1717.78503","0.00172"
"2.60000","0.84685","1774.42395","0.00178"
"2.70000","0.85676","1829.57178","0.00184"
"2.80000","0.86668","1884.38562","0.00190"
"2.90000","0.87668","1939.48584","0.00196"
"3.00000","0.88672","1994.33679","0.00202"
"3.10000","0.89673","2048.58789","0.00208"
"3.20000","0.90678","2102.58105","0.00214"
"3.30000","0.91665","2154.70557","0.00220"
"3.40000","0.92670","2207.29761","0.00226"
"3.50000","0.93675","2258.75879","0.00232"
"3.60000","0.94679","2308.18481","0.00238"
"3.70000","0.95675","2355.20874","0.00245"
"3.80000","0.96681","2400.03735","0.00252"
"3.90000","0.97667","2439.90479","0.00259"
"4.00000","0.98663","2476.55005","0.00266"
"4.10000","0.99669","2508.27686","0.00274"
"4.20000","1.00677","2534.49097","0.00283"
"4.30000","1.01691","2555.37769","0.00292"
"4.40000","1.02684","2570.73755","0.00301"
"4.50000","1.03668","2582.16284","0.00310"
"4.60000","1.04665","2591.23218","0.00319"
"4.70000","1.05666","2598.68091","0.00328"
"4.80000","1.06669","2604.40527","0.00336"
"4.90000","1.07679","2609.59814","0.00343"
"5.00000","1.08689","2614.20093","0.00350"
"5.10000","1.09678","2618.39209","0.00357"
"5.20000","1.10672","2622.49194","0.00363"
"5.30000","1.11663","2626.31543","0.00370"
"5.40000","1.12669","2629.69824","0.00377"
"5.50000","1.13673","2632.75122","0.00384"
"5.60000","1.14683","2636.33813","0.00392"
"5.70000","1.15675","2639.08667","0.00401"
"5.80000","1.16674","2640.69946","0.00412"
"5.90000","1.17676","2637.25195","0.00421"
"6.00000","1.18674","2634.25586","0.00427"
"6.10000","1.19677","2649.42163","0.00434"
"6.20000","1.20678","2638.86255","0.00441"
"6.30000","1.21669","2641.10864","0.00445"
"6.40000","1.22665","2641.61987","0.00449"
"6.50000","1.23674","2641.19849","0.00452"
"6.60000","1.24680","2641.68530","0.00454"
"6.70000","1.25687","2642.16870","0.00457"
"6.80000","1.26677","2644.16309","0.00459"
"6.90000","1.27665","2646.66333","0.00462"
"7.00000","1.28667","2648.91504","0.00464"
"7.10000","1.29667","2650.59058","0.00466"
"7.20000","1.30673","2651.76953","0.00468"
"7.30000","1.31680","2661.44678","0.00472"
"7.40000","1.32691","2664.43164","0.00483"
"7.50000","1.33678","2647.69067","0.00505"
"7.60000","1.34666","2665.05981","0.00532"
"7.70000","1.35660","2666.13379","0.00568"
"7.80000","1.36671","2667.73145","0.00775"
"7.90000","1.37674","2663.47705","0.00831"
"8.00000","1.38683","2662.36914","0.00831"
"8.10000","1.39676","2662.53076","0.00776"
"8.20000","1.40676","2664.14331","0.00721"
"8.30000","1.41670","2665.56543","0.00699"
"8.40000","1.42671","2670.39795","0.00669"
"8.50000","1.43676","2666.89648","0.00631"
"8.60000","1.44674","2668.78955","0.00575"
"8.70000","1.45672","2669.48193","0.00512"
"8.80000","1.46673","2670.93750","0.00492"
"8.90000","1.47674","2671.16138","0.00373"
"9.00000","1.48679","2675.42603","0.00321"
"9.10000","1.49678","2680.36865","0.00293"
"9.20000","1.50679","2688.55103","0.00277"
"9.30000","1.51668","2677.50049","0.00263"
"9.40000","1.52666","2668.24976","0.00250"
"9.50000","1.53665","2668.63013","0.00240"
"9.60000","1.54676","2669.30762","0.00226"
"9.70000","1.55684","2671.76343","0.00218"
"9.80000","1.56687","2675.41821","0.00213"
"9.90000","1.57676","2683.31006","0.00207"
"10.00000","1.58667","2700.06274","0.00202"
"10.10000","1.59657","2715.08789","0.00197"
"10.20000","1.60667","2701.74756","0.00193"
"10.30000","1.61676","2695.99658","0.00188"
"10.40000","1.62687","2701.78296","0.00185"
"10.50000","1.63676","2719.73218","0.00182"
"10.60000","1.64673","2724.48608","0.00179"
"10.70000","1.65661","2740.16699","0.00176"
"10.80000","1.66663","2723.44507","0.00173"
"10.90000","1.67670","2757.44141","0.00170"
"11.00000","1.68674","2766.19556","0.00169"
"11.10000","1.69679","2767.56445","0.00168"
"11.20000","1.70678","2764.95776","0.00166"
"11.30000","1.71671","2764.78638","0.00165"
"11.40000","1.72674","2762.60083","0.00165"
"11.50000","1.73678","2763.61157","0.00164"
"11.60000","1.74679","2763.41675","0.00163"
"11.70000","1.75672","2760.65479","0.00163"
"11.80000","1.76666","2762.13013","0.00162"
"11.90000","1.77671","2760.47705","0.00161"
"12.00000","1.78675","2760.92773","0.00161"
"12.10000","1.79681","2763.78027","0.00160"
"12.20000","1.80680","2759.18628","0.00160"
"12.30000","1.81676","2760.48584","0.00159"
"12.40000","1.82668","2761.51074","0.00159"
"12.50000","1.83656","2755.29712","0.00159"
"12.60000","1.84668","2751.77832","0.00158"
"12.70000","1.85679","2792.54468","0.00159"
"12.80000","1.86685","2810.90454","0.00159"
"12.90000","1.87681","2775.24341","0.00158"
"13.00000","1.88671","2785.06323","0.00158"
"13.10000","1.89661","2774.83960","0.00160"
"13.20000","1.90664","2780.50977","0.00164"
"13.30000","1.91672","2784.22266","0.00165"
"13.40000","1.92677","2787.39795","0.00165"
"13.50000","1.93684","2793.11816","0.00160"
"13.60000","1.94677","2793.48633","0.00156"
"13.70000","1.95670","2795.45923","0.00154"
"13.80000","1.96669","2794.75220","0.00153"
"13.90000","1.97673","2797.95410","0.00152"
"14.00000","1.98676","2801.51587","0.00152"
"14.10000","1.99675","2800.51660","0.00151"
"14.20000","2.00672","2803.08203","0.00150"
"14.30000","2.01672","2800.50854","0.00150"
"14.40000","2.02673","2798.94409","0.00149"
"14.50000","2.03676","2802.87891","0.00149"
"14.60000","2.04681","2803.05981","0.00149"
"14.70000","2.05674","2804.73511","0.00148"
"14.80000","2.06669","2806.77246","0.00148"
"14.90000","2.07655","2808.45850","0.00148"
"15.00000","2.08671","2810.91504","0.00148"
"15.10000","2.09684","2817.05396","0.00148"
"15.20000","2.10689","2820.71729","0.00147"
"15.30000","2.11677","2803.21143","0.00147"
"15.40000","2.12667","2790.02905","0.00146"
"15.50000","2.13661","2797.59863","0.00146"
"15.60000","2.14662","2803.81274","0.00146"
"15.70000","2.15672","2806.76025","0.00146"
"15.80000","2.16684","2808.95044","0.00146"
"15.90000","2.17690","2807.38965","0.00146"
"16.00000","2.18678","2818.05469","0.00146"
"16.10000","2.19662","2824.75928","0.00146"
"16.20000","2.20664","2830.10986","0.00147"
"16.30000","2.21670","2805.20923","0.00146"
"16.40000","2.22678","2811.08032","0.00146"
"16.50000","2.23676","2830.43750","0.00146"
"16.60000","2.24675","2852.17041","0.00146"
"16.70000","2.25671","2836.41211","0.00146"
"16.80000","2.26672","2833.39258","0.00145"
"16.90000","2.27670","2847.23755","0.00145"
"17.00000","2.28680","2862.78101","0.00146"
"17.10000","2.29676","2868.75244","0.00146"
"17.20000","2.30670","2857.22754","0.00146"
"17.30000","2.31661","2890.07153","0.00147"
"17.40000","2.32674","2880.11230","0.00146"
"17.50000","2.33683","2907.26318","0.00147"
"17.60000","2.34686","2868.96118","0.00146"
"17.70000","2.35675","2881.67676","0.00147"
"17.80000","2.36664","2902.05322","0.00147"
"17.90000","2.37658","2901.72412","0.00147"
"18.00000","2.38661","2903.68164","0.00146"
"18.10000","2.39676","2903.89551","0.00146"
"18.20000","2.40688","2904.51245","0.00147"
"18.30000","2.41689","2902.04761","0.00146"
"18.40000","2.42672","2905.81274","0.00141"
"18.50000","2.43663","2907.54761","0.00130"
"18.60000","2.44666","2904.90308","-0.13988"
"18.70000","2.45668","2906.18604","-0.13600"
"18.80000","2.46684","2905.76831","-0.00214"
"18.90000","2.47680","2904.04907","0.00028"
"19.00000","2.48676","2904.45581","-0.00024"
"19.10000","2.49670","2907.20679","0.00060"
"19.20000","2.50666","2906.00171","0.00145"
"19.30000","2.51669","2905.40112","-0.14188"
"19.40000","2.52681","2904.71069","-0.13594"
"19.50000","2.53678","2905.26489","-0.13601"
"19.60000","2.54670","2904.64722","-0.13601"
"19.70000","2.55668","2900.45337","-0.13601"
"19.80000","2.56673","2912.57959","-0.12301"
"19.90000","2.57680","2934.22534","-0.12078"
"20.00000","2.58681","2941.23950","0.00219"
"20.10000","2.59678","2945.79224","0.00123"
"20.20000","2.60664","2965.37305","0.00122"
"20.30000","2.61658","2954.28418","0.00121"
"20.40000","2.62670","2952.92822","0.00122"
"20.50000","2.63680","2953.82886","0.00121"
"20.60000","2.64692","2957.86353","0.00121"
"20.70000","2.65684","2958.95776","-0.11793"
"20.80000","2.66669","2960.10815","0.00498"
"20.90000","2.67661","2959.32056","0.00120"
"21.00000","2.68665","2955.07935","0.00122"
"21.10000","2.69670","2950.97412","0.00124"
"21.20000","2.70687","2945.58545","0.00124"
"21.30000","2.71689","2939.53394","0.00124"
"21.40000","2.72672","2931.30933","-0.05974"
"21.50000","2.73667","2950.52954","0.00140"
"21.60000","2.74666","2946.35107","0.00124"
"21.70000","2.75672","2958.92896","0.00124"
"21.80000","2.76676","2959.44116","0.00125"
"21.90000","2.77678","2954.13403","0.00126"
"22.00000","2.78674","2950.08350","0.00128"
"22.10000","2.79671","2948.63403","0.00131"
"22.20000","2.80674","2948.82495","0.00132"
"22.30000","2.81672","2948.38403","0.00132"
"22.40000","2.82679","2947.87036","0.00132"
"22.50000","2.83678","2944.87354","0.00132"
"22.60000","2.84666","2944.43921","0.00131"
"22.70000","2.85660","2943.06714","0.00131"
"22.80000","2.86678","2938.92139","0.00131"
"22.90000","2.87679","2941.88550","0.00131"
"23.00000","2.88689","2942.55347","0.00131"
"23.10000","2.89683","2946.45483","0.00131"
"23.20000","2.90669","2942.38184","0.00130"
"23.30000","2.91662","2940.36157","0.00130"
"23.40000","2.92664","2938.60156","0.00130"
"23.50000","2.93674","2939.98755","0.00130"
"23.60000","2.94690","2938.47412","0.00130"
"23.70000","2.95687","2935.43506","0.00129"
"23.80000","2.96669","2934.76685","0.00129"
"23.90000","2.97670","2932.20947","0.00129"
"24.00000","2.98667","2925.74072","0.00129"
"24.10000","2.99668","2920.80786","0.00129"
"24.20000","3.00674","2921.96045","0.00142"
"24.30000","3.01684","2919.50317","0.00138"
"24.40000","3.02676","2920.44653","0.00132"
"24.50000","3.03672","2932.05493","0.00137"
"24.60000","3.04672","2950.86401","0.00127"
"24.70000","3.05669","2972.25659","0.00137"
"24.80000","3.06678","2963.74585","0.00136"
"24.90000","3.07681","2996.39038","0.00136"
"25.00000","3.08667","2984.73657","0.00135"
"25.10000","3.09666","2995.10327","0.00135"
"25.20000","3.10677","2999.75879","0.00134"
"25.30000","3.11681","3003.84229","0.00134"
"25.40000","3.12682","3004.58545","0.00133"
"25.50000","3.13681","3008.20728","0.00133"
"25.60000","3.14665","3000.82129","0.00133"
"25.70000","3.15666","3016.58862","0.00133"
"25.80000","3.16666","3029.41504","0.00132"
"25.90000","3.17679","3022.70044","0.00132"
"26.00000","3.18690","3028.65625","0.00132"
"26.10000","3.19686","3044.25293","0.00131"
"26.20000","3.20668","3042.77197","0.00131"
"26.30000","3.21663","3076.30322","0.00131"
"26.40000","3.22664","3062.70166","0.00131"
"26.50000","3.23669","3033.71753","0.00130"
"26.60000","3.24674","3075.66479","0.00130"
"26.70000","3.25687","3060.63647","0.00130"
"26.80000","3.26674","3046.48657","0.00130"
"26.90000","3.27668","3040.27637","0.00130"
"27.00000","3.28665","3043.71729","0.00130"
"27.10000","3.29671","3058.12427","0.00129"
"27.20000","3.30673","3057.62158","0.00129"
"27.30000","3.31683","3046.43408","0.00129"
"27.40000","3.32669","3041.85352","0.00129"
"27.50000","3.33674","3041.17358","0.00129"
"27.60000","3.34678","3046.27002","0.00128"
"27.70000","3.35677","3055.06421","0.00129"
"27.80000","3.36678","3056.60059","0.00128"
"27.90000","3.37681","3048.49536","0.00128"
"28.00000","3.38670","3041.00000","0.00128"
"28.10000","3.39666","3039.07080","0.00128"
"28.20000","3.40670","3044.88867","0.00128"
"28.30000","3.41679","3053.17041","0.00128"
"28.40000","3.42688","3057.62549","0.00128"
"28.50000","3.43682","3052.09229","0.00128"
"28.60000","3.44668","3043.63940","0.00128"
"28.70000","3.45663","3039.11914","0.00127"
"28.80000","3.46665","3042.15356","0.00128"
"28.90000","3.47673","3048.22876","0.00127"
"29.00000","3.48680","3040.34644","0.00127"
"29.10000","3.49689","3080.98096","0.00127"
"29.20000","3.50676","3084.36328","0.00127"
"29.30000","3.51669","3100.89307","0.00127"
"29.40000","3.52660","3097.43481","0.00127"
"29.50000","3.53668","3095.72559","0.00127"
"29.60000","3.54674","3092.20728","0.00127"
"29.70000","3.55683","3088.94873","0.00127"
"29.80000","3.56678","3088.26392","0.00127"
"29.90000","3.57675","3097.17383","0.00127"
"30.00000","3.58671","3099.41284","0.00127"
"30.10000","3.59670","3089.72241","0.00127"
"30.20000","3.60678","3082.86938","0.00127"
"30.30000","3.61675","3078.02051","0.00127"
"30.40000","3.62674","3072.91919","0.00127"
"30.50000","3.63667","3082.00635","0.00126"
"30.60000","3.64674","3080.64136","0.00127"
"30.70000","3.65681","3080.03760","0.00126"
"30.80000","3.66681","3087.22412","0.00127"
"30.90000","3.67679","3080.41064","0.00126"
"31.00000","3.68667","3079.35669","0.00126"
"31.10000","3.69665","3092.25659","0.00126"
"31.20000","3.70662","3103.42212","0.00126"
"31.30000","3.71676","3093.98242","0.00126"
"31.40000","3.72682","3086.21387","0.00126"
"31.50000","3.73691","3083.27319","0.00126"
"31.60000","3.74674","3079.42065","0.00126"
"31.70000","3.75665","3091.53540","0.00126"
"31.80000","3.76655","3090.18604","0.00126"
"31.90000","3.77669","3079.43384","0.00126"
"32.00000","3.78680","3070.90747","0.00126"
"32.10000","3.79687","3072.43457","0.00126"
"32.20000","3.80678","3088.01392","0.00126"
"32.30000","3.81673","3087.20337","0.00126"
"32.40000","3.82669","3082.02002","0.00126"
"32.50000","3.83668","3071.86646","0.00126"
"32.60000","3.84671","3068.97607","0.00126"
"32.70000","3.85673","3083.48315","0.00126"
"32.80000","3.86678","3084.10645","0.00126"
"32.90000","3.87678","3077.88770","0.00126"
"33.00000","3.88671","3071.84692","0.00126"
"33.10000","3.89675","3070.29419","0.00126"
"33.20000","3.90678","3072.95166","0.00126"
"33.30000","3.91680","3078.10620","0.00126"
"33.40000","3.92670","3077.62158","0.00126"
"33.50000","3.93665","3068.06226","0.00126"
"33.60000","3.94669","3066.01807","0.00126"
"33.70000","3.95676","3071.12573","0.00126"
"33.80000","3.96678","3072.52539","0.00126"
"33.90000","3.97682","3073.32104","0.00126"
"34.00000","3.98678","3064.87036","0.00126"
"34.10000","3.99667","3056.38843","0.00126"
"34.20000","4.00655","3051.88647","0.00126"
"34.30000","4.01664","3057.36987","0.00126"
"34.40000","4.02678","3059.26514","0.00126"
"34.50000","4.03687","3070.27295","0.00126"
"34.60000","4.04683","3073.63525","0.00126"
"34.70000","4.05676","3078.11499","0.00126"
"34.80000","4.06663","3089.03467","0.00126"
"34.90000","4.07666","3107.91089","0.00126"
"35.00000","4.08672","3101.58960","0.00127"
"35.10000","4.09678","3137.61646","0.00126"
"35.20000","4.10683","3128.67993","0.00126"
"35.30000","4.11678","3106.19409","0.00126"
"35.40000","4.12668","3141.65552","0.00126"
"35.50000","4.13671","3122.63696","0.00126"
"35.60000","4.14675","3115.43311","0.00126"
"35.70000","4.15675","3152.66626","0.00126"
"35.80000","4.16673","3139.16211","0.00126"
"35.90000","4.17667","3123.09595","0.00127"
"36.00000","4.18673","3144.36328","0.00126"
"36.10000","4.19673","3145.02002","0.00127"
"36.20000","4.20680","3137.78564","0.00126"
"36.30000","4.21681","3125.95264","0.00126"
"36.40000","4.22674","3174.08154","0.00126"
"36.50000","4.23668","3154.77246","0.00126"
"36.60000","4.24657","3176.82104","0.00126"
"36.70000","4.25671","3176.35620","0.00126"
"36.80000","4.26681","3197.38721","0.00126"
"36.90000","4.27687","3196.37891","0.00126"
"37.00000","4.28678","3172.81494","0.00126"
"37.10000","4.29671","3154.28125","0.00126"
"37.20000","4.30660","3190.80908","0.00126"
"37.30000","4.31665","3193.87402","0.00126"
"37.40000","4.32672","3180.15112","0.00126"
"37.50000","4.33680","3202.38843","0.00126"
"37.60000","4.34687","3196.14478","0.00126"
"37.70000","4.35677","3175.34570","0.00126"
"37.80000","4.36669","3165.28540","0.00126"
"37.90000","4.37666","3194.81226","0.00126"
"38.00000","4.38672","3182.10449","0.00126"
"38.10000","4.39677","3161.43604","0.00126"
"38.20000","4.40677","3187.22803","0.00126"
"38.30000","4.41671","3187.93579","0.00126"
"38.40000","4.42673","3168.67505","0.00126"
"38.50000","4.43670","3163.45288","0.00126"
"38.60000","4.44675","3189.79102","0.00126"
"38.70000","4.45682","3181.32275","0.00126"
"38.80000","4.46676","3162.06177","0.00126"
"38.90000","4.47667","3174.70459","0.00126"
"39.00000","4.48656","3189.76294","0.00126"
"39.10000","4.49675","3164.30176","0.00126"
"39.20000","4.50682","3172.50049","0.00126"
"39.30000","4.51688","3191.53882","0.00126"
"39.40000","4.52678","3163.96021","0.00126"
"39.50000","4.53666","3173.14795","0.00126"
"39.60000","4.54658","3188.55200","0.00126"
"39.70000","4.55664","3159.83228","0.00125"
"39.80000","4.56673","3175.97510","0.00125"
"39.90000","4.57691","3187.13599","0.00125"
"40.00000","4.58692","3162.87427","0.00125"
"40.10000","4.59670","3165.20508","0.00125"
"40.20000","4.60662","3188.50171","0.00125"
"40.30000","4.61664","3166.80591","0.00125"
"40.40000","4.62668","3157.01318","0.00125"
"40.50000","4.63680","3178.31885","0.00125"
"40.60000","4.64683","3189.06836","0.00125"
"40.70000","4.65673","3201.17188","0.00125"
"40.80000","4.66670","3213.38892","0.00125"
"40.90000","4.67669","3217.97461","0.00125"
"41.00000","4.68672","3223.10962","0.00125"
"41.10000","4.69680","3219.15869","0.00125"
"41.20000","4.70676","3217.14429","0.00125"
"41.30000","4.71669","3212.91382","0.00124"
"41.40000","4.72666","3206.13159","0.00125"
"41.50000","4.73676","3201.52832","0.00124"
"41.60000","4.74678","3214.51562","0.00124"
"41.70000","4.75683","3207.18896","0.00124"
"41.80000","4.76680","3188.43457","0.00124"
"41.90000","4.77662","3196.90039","0.00124"
"42.00000","4.78660","3210.56616","0.00124"
"42.10000","4.79668","3186.88965","0.00124"
"42.20000","4.80679","3186.06934","0.00124"
"42.30000","4.81689","3214.67773","0.00124"
"42.40000","4.82690","3191.85864","0.00124"
"42.50000","4.83667","3174.77295","0.00124"
"42.60000","4.84659","3208.96777","0.00124"
"42.70000","4.85663","3199.62988","0.00124"
"42.80000","4.86666","3179.07080","0.00124"
"42.90000","4.87680","3215.31006","0.00124"
"43.00000","4.88685","3208.45703","0.00124"
"43.10000","4.89676","3185.01001","0.00123"
"43.20000","4.90669","3230.78418","0.00124"
"43.30000","4.91669","3199.58691","0.00123"
"43.40000","4.92669","3187.83374","0.00124"
"43.50000","4.93678","3221.69849","0.00123"
"43.60000","4.94680","3192.74414","0.00124"
"43.70000","4.95672","3188.01855","0.00123"
"43.80000","4.96673","3216.12354","0.00123"
"43.90000","4.97678","3189.15869","0.00123"
"44.00000","4.98677","3186.90210","0.00123"
"44.10000","4.99679","3215.20264","0.00123"
"44.20000","5.00679","3192.19385","0.00123"
"44.30000","5.01663","3180.17407","0.00123"
"44.40000","5.02661","3215.71948","0.00123"
"44.50000","5.03676","3191.32056","0.00123"
"44.60000","5.04680","3178.90601","0.00123"
"44.70000","5.05687","3213.86279","0.00123"
"44.80000","5.06685","3182.68750","0.00123"
"44.90000","5.07668","3183.05200","0.00123"
"45.00000","5.08659","3206.91650","0.00123"
"45.10000","5.09667","3178.68262","0.00123"
"45.20000","5.10669","3194.46362","0.00123"
"45.30000","5.11688","3205.64648","0.00123"
"45.40000","5.12690","3180.18506","0.00123"
"45.50000","5.13669","3183.59814","0.00123"
"45.60000","5.14666","3205.31470","0.00123"
"45.70000","5.15668","3179.03345","0.00123"
"45.80000","5.16671","3178.40063","0.00123"
"45.90000","5.17675","3205.77222","0.00123"
"46.00000","5.18683","3180.18872","0.00123"
"46.10000","5.19673","3178.30713","0.00123"
"46.20000","5.20672","3205.03369","0.00123"
"46.30000","5.21675","3175.04492","0.00123"
"46.40000","5.22673","3196.35498","0.00123"
"46.50000","5.23678","3168.45654","0.00123"
"46.60000","5.24677","3193.18066","0.00123"
"46.70000","5.25667","3190.42456","0.00123"
"46.80000","5.26666","3162.44702","0.00123"
"46.90000","5.27676","3198.07568","0.00123"
"47.00000","5.28680","3187.89136","0.00123"
"47.10000","5.29685","3162.33569","0.00123"
"47.20000","5.30681","3190.68774","0.00123"
"47.30000","5.31667","3186.27612","0.00123"
"47.40000","5.32662","3160.68799","0.00123"
"47.50000","5.33664","3200.28223","0.00123"
"47.60000","5.34680","3186.56909","0.00123"
"47.70000","5.35687","3163.25537","0.00123"
"47.80000","5.36687","3210.23877","0.00123"
"47.90000","5.37668","3186.66895","0.00123"
"48.00000","5.38668","3200.10376","0.00124"
"48.10000","5.39667","3206.83569","0.00123"
"48.20000","5.40671","3195.76221","0.00124"
"48.30000","5.41675","3233.30762","0.00124"
"48.40000","5.42685","3239.03149","0.00124"
"48.50000","5.43678","3238.82593","0.00124"
"48.60000","5.44669","3244.00659","0.00124"
"48.70000","5.45667","3241.13379","0.00124"
"48.80000","5.46669","3239.87036","0.00124"
"48.90000","5.47678","3217.94629","0.00124"
"49.00000","5.48677","3257.39526","0.00124"
"49.10000","5.49669","3221.19897","0.00124"
"49.20000","5.50668","3272.27295","0.00124"
"49.30000","5.51679","3241.01221","0.00124"
"49.40000","5.52679","3244.87207","0.00124"
"49.50000","5.53677","3256.27881","0.00124"
"49.60000","5.54678","3225.62524","0.00125"
"49.70000","5.55669","3275.48657","0.00124"
"49.80000","5.56668","3238.80127","0.00125"
"49.90000","5.57665","3254.11719","0.00124"
"50.00000","5.58680","3263.19263","0.00125"
"50.10000","5.59687","3227.24390","0.00125"
"50.20000","5.60683","3276.36304","0.00125"
"50.30000","5.61670","3243.98438","0.00125"
"50.40000","5.62663","3296.03101","0.00125"
"50.50000","5.63667","3262.31055","0.00125"
"50.60000","5.64670","3272.14551","0.00125"
"50.70000","5.65681","3294.12085","0.00125"
"50.80000","5.66688","3292.43164","0.00125"
"50.90000","5.67679","3244.06396","0.00125"
"51.00000","5.68667","3287.52588","0.00125"
"51.10000","5.69663","3260.03101","0.00125"
"51.20000","5.70669","3290.62012","0.00125"
"51.30000","5.71673","3256.80005","0.00125"
"51.40000","5.72682","3304.40991","0.00125"
"51.50000","5.73673","3267.45361","0.00125"
"51.60000","5.74675","3281.95068","0.00125"
"51.70000","5.75672","3281.78491","0.00125"
"51.80000","5.76677","3256.32397","0.00125"
"51.90000","5.77673","3295.24756","0.00125"
"52.00000","5.78677","3254.25903","0.00125"
"52.10000","5.79671","3305.50854","0.00125"
"52.20000","5.80669","3260.79321","0.00125"
"52.30000","5.81672","3315.01587","0.00125"
"52.40000","5.82679","3269.62988","0.00125"
"52.50000","5.83684","3320.71997","0.00125"
"52.60000","5.84683","3276.82495","0.00125"
"52.70000","5.85669","3312.15527","0.00125"
"52.80000","5.86666","3279.51099","0.00125"
"52.90000","5.87662","3287.08813","0.00126"
"53.00000","5.88673","3285.43921","0.00125"
"53.10000","5.89681","3259.59058","0.00125"
"53.20000","5.90688","3294.11914","0.00125"
"53.30000","5.91677","3251.47144","0.00125"
"53.40000","5.92670","3300.37500","0.00125"
"53.50000","5.93658","3254.05151","0.00125"
"53.60000","5.94665","3307.80591","0.00125"
"53.70000","5.95676","3263.15063","0.00125"
"53.80000","5.96684","3310.20508","0.00126"
"53.90000","5.97682","3271.30371","0.00125"
"54.00000","5.98673","3296.76758","0.00126"
"54.10000","5.99672","3273.11670","0.00125"
"54.20000","6.00667","3271.03394","0.00126"
"54.30000","6.01675","3253.87378","0.00125"
"54.40000","6.02671","3291.19336","0.00126"
"54.50000","6.03679","3255.16846","0.00126"
"54.60000","6.04671","3303.71606","0.00126"
"54.70000","6.05676","3263.51587","0.00126"
"54.80000","6.06676","3265.44116","0.00126"
"54.90000","6.07678","3278.16797","0.00126"
"55.00000","6.08678","3247.69067","0.00126"
"55.10000","6.09666","3289.71484","0.00126"
"55.20000","6.10670","3246.30737","0.00126"
"55.30000","6.11666","3298.69238","0.00126"
"55.40000","6.12676","3251.98315","0.00126"
"55.50000","6.13681","3303.57617","0.00126"
"55.60000","6.14687","3272.53687","0.00126"
"55.70000","6.15677","3259.31079","0.00126"
"55.80000","6.16666","3273.10498","0.00126"
"55.90000","6.17655","3272.58521","0.00126"
"56.00000","6.18667","3247.00952","0.00126"
"56.10000","6.19681","3285.75928","0.00126"
"56.20000","6.20685","3242.00830","0.00126"
"56.30000","6.21680","3291.96313","0.00126"
"56.40000","6.22671","3245.80225","0.00126"
"56.50000","6.23664","3297.10913","0.00126"
"56.60000","6.24669","3252.88550","0.00126"
"56.70000","6.25673","3302.47437","0.00126"
"56.80000","6.26675","3261.51636","0.00126"
"56.90000","6.27677","3274.40234","0.00126"
"57.00000","6.28680","3271.95264","0.00126"
"57.10000","6.29670","3249.43896","0.00126"
"57.20000","6.30671","3283.80640","0.00126"
"57.30000","6.31673","3243.09180","0.00126"
"57.40000","6.32677","3292.98926","0.00126"
"57.50000","6.33671","3245.71924","0.00126"
"57.60000","6.34667","3300.01270","0.00126"
"57.70000","6.35672","3252.06665","0.00126"
"57.80000","6.36673","3302.92065","0.00126"
"57.90000","6.37682","3260.61816","0.00126"
"58.00000","6.38683","3263.78687","0.00126"
"58.10000","6.39676","3274.15771","0.00126"
"58.20000","6.40667","3245.66821","0.00126"
"58.30000","6.41656","3285.25610","0.00126"
"58.40000","6.42671","3242.69019","0.00126"
"58.50000","6.43680","3296.55420","0.00126"
"58.60000","6.44687","3251.66772","0.00126"
"58.70000","6.45674","3304.11353","0.00126"
"58.80000","6.46668","3261.45020","0.00126"
"58.90000","6.47655","3303.35205","0.00126"
"59.00000","6.48660","3270.87964","0.00126"
"59.10000","6.49673","3286.18481","0.00126"
"59.20000","6.50682","3283.64478","0.00126"
"59.30000","6.51685","3292.70801","0.00126"
"59.40000","6.52679","3306.20679","0.00126"
"59.50000","6.53665","3261.05493","0.00126"
"59.60000","6.54666","3312.13110","0.00126"
"59.70000","6.55676","3246.70410","0.00126"
"59.80000","6.56678","3295.93115","0.00126"
"59.90000","6.57678","3255.74902","0.00126"
"60.00000","6.58669","3269.91260","0.00126"
"60.10000","6.59675","3272.45776","0.00126"
"60.20000","6.60673","3245.25391","0.00126"
"60.30000","6.61673","3287.13257","0.00126"
"60.40000","6.62680","3248.10156","0.00126"
"60.50000","6.63675","3299.98462","0.00126"
"60.60000","6.64670","3260.29395","0.00126"
"60.70000","6.65658","3300.15015","0.00126"
"60.80000","6.66673","3272.30957","0.00126"
"60.90000","6.67680","3266.54639","0.00126"
"61.00000","6.68689","3283.87280","0.00125"
"61.10000","6.69678","3248.87817","0.00126"
"61.20000","6.70665","3292.52100","0.00125"
"61.30000","6.71660","3249.47729","0.00126"
"61.40000","6.72663","3302.19653","0.00125"
"61.50000","6.73676","3262.33130","0.00126"
"61.60000","6.74687","3294.68506","0.00125"
"61.70000","6.75687","3279.12915","0.00126"
"61.80000","6.76674","3257.85010","0.00125"
"61.90000","6.77665","3290.45996","0.00125"
"62.00000","6.78666","3249.25220","0.00125"
"62.10000","6.79668","3300.98560","0.00125"
"62.20000","6.80679","3257.36035","0.00126"
"62.30000","6.81681","3309.34448","0.00125"
"62.40000","6.82676","3268.28955","0.00126"
"62.50000","6.83671","3292.89062","0.00125"
"62.60000","6.84669","3278.52954","0.00125"
"62.70000","6.85670","3267.66602","0.00125"
"62.80000","6.86682","3287.93188","0.00125"
"62.90000","6.87677","3254.36621","0.00125"
"63.00000","6.88666","3291.96265","0.00125"
"63.10000","6.89663","3253.87988","0.00125"
"63.20000","6.90676","3294.48950","0.00125"
"63.30000","6.91681","3254.31567","0.00125"
"63.40000","6.92684","3303.90698","0.00125"
"63.50000","6.93677","3262.23071","0.00125"
"63.60000","6.94664","3305.38184","0.00125"
"63.70000","6.95661","3268.38574","0.00125"
"63.80000","6.96665","3314.34302","0.00125"
"63.90000","6.97681","3282.00342","0.00125"
"64.00000","6.98687","3326.92090","0.00125"
"64.10000","6.99691","3295.56641","0.00125"
"64.20000","7.00671","3318.79517","0.00125"
"64.30000","7.01660","3311.64966","0.00124"
"64.40000","7.02661","3317.87915","0.00125"
"64.50000","7.03666","3317.91968","0.00124"
"64.60000","7.04685","3311.52612","0.00125"
"64.70000","7.05685","3315.20288","0.00124"
"64.80000","7.06675","3303.97900","0.00125"
"64.90000","7.07667","3325.12329","0.00125"
"65.00000","7.08670","3295.18994","0.00125"
"65.10000","7.09666","3330.58569","0.00125"
"65.20000","7.10679","3320.05835","0.00125"
"65.30000","7.11675","3326.92554","0.00125"
"65.40000","7.12673","3308.22388","0.00124"
"65.50000","7.13670","3286.83521","0.00125"
"65.60000","7.14677","3320.18140","0.00124"
"65.70000","7.15678","3279.97461","0.00125"
"65.80000","7.16680","3327.67432","0.00124"
"65.90000","7.17679","3278.49170","0.00125"
"66.00000","7.18660","3326.87354","0.00124"
"66.10000","7.19661","3277.06738","0.00124"
"66.20000","7.20670","3327.37354","0.00124"
"66.30000","7.21680","3278.60449","0.00124"
"66.40000","7.22690","3328.02417","0.00124"
"66.50000","7.23686","3284.55005","0.00124"
"66.60000","7.24668","3321.52319","0.00124"
"66.70000","7.25659","3296.40088","0.00124"
"66.80000","7.26665","3317.56592","0.00124"
"66.90000","7.27668","3301.47437","0.00124"
"67.00000","7.28687","3318.39648","0.00124"
"67.10000","7.29685","3313.57129","0.00124"
"67.20000","7.30674","3315.66406","0.00124"
"67.30000","7.31666","3337.84546","0.00124"
"67.40000","7.32668","3311.23022","0.00124"
"67.50000","7.33667","3349.14429","0.00124"
"67.60000","7.34677","3307.77124","0.00124"
"67.70000","7.35682","3350.79272","0.00124"
"67.80000","7.36676","3304.77612","0.00124"
"67.90000","7.37670","3351.34082","0.00124"
"68.00000","7.38671","3299.38672","0.00124"
"68.10000","7.39674","3347.71265","0.00124"
"68.20000","7.40680","3294.33496","0.00124"
"68.30000","7.41679","3345.24243","0.00124"
"68.40000","7.42665","3288.58130","0.00124"
"68.50000","7.43661","3340.96069","0.00124"
"68.60000","7.44682","3285.12451","0.00124"
"68.70000","7.45680","3337.94702","0.00123"
"68.80000","7.46686","3290.10400","0.00124"
"68.90000","7.47680","3320.53223","0.00123"
"69.00000","7.48668","3278.77319","0.00124"
"69.10000","7.49659","3327.81567","0.00124"
"69.20000","7.50670","3275.11987","0.00124"
"69.30000","7.51673","3325.03052","0.00124"
"69.40000","7.52689","3284.06177","0.00124"
"69.50000","7.53691","3320.06934","0.00124"
"69.60000","7.54666","3303.19482","0.00124"
"69.70000","7.55666","3314.17725","0.00124"
"69.80000","7.56662","3335.87378","0.00124"
"69.90000","7.57671","3307.75146","0.00124"
"70.00000","7.58678","3355.38501","0.00124"
"70.10000","7.59685","3300.43140","0.00124"
"70.20000","7.60678","3351.78638","0.00124"
"70.30000","7.61672","3285.98511","0.00124"
"70.40000","7.62669","3337.22339","0.00124"
"70.50000","7.63673","3280.66943","0.00124"
"70.60000","7.64676","3331.04199","0.00124"
"70.70000","7.65678","3301.24316","0.00124"
"70.80000","7.66668","3314.66870","0.00124"
"70.90000","7.67667","3317.11768","0.00123"
"71.00000","7.68679","3338.17798","0.00124"
"71.10000","7.69680","3281.01416","0.00123"
"71.20000","7.70679","3326.13892","0.00124"
"71.30000","7.71682","3282.97656","0.00123"
"71.40000","7.72670","3315.83887","0.00124"
"71.50000","7.73663","3337.88086","0.00123"
"71.60000","7.74668","3302.30225","0.00123"
"71.70000","7.75680","3350.59424","0.00123"
"71.80000","7.76687","3294.91431","0.00123"
"71.90000","7.77682","3346.07617","0.00123"
"72.00000","7.78668","3287.41821","0.00123"
"72.10000","7.79666","3341.30127","0.00123"
"72.20000","7.80669","3279.87598","0.00123"
"72.30000","7.81668","3334.46216","0.00123"
"72.40000","7.82679","3281.89355","0.00123"
"72.50000","7.83686","3327.25952","0.00123"
"72.60000","7.84677","3319.43970","0.00123"
"72.70000","7.85670","3315.38647","0.00123"
"72.80000","7.86666","3348.94775","0.00123"
"72.90000","7.87669","3325.79126","0.00123"
"73.00000","7.88674","3336.43530","0.00123"
"73.10000","7.89683","3312.63550","0.00123"
"73.20000","7.90672","3316.81006","0.00123"
"73.30000","7.91675","3327.23047","0.00123"
"73.40000","7.92673","3311.99878","0.00123"
"73.50000","7.93675","3350.65845","0.00123"
"73.60000","7.94677","3297.94849","0.00123"
"73.70000","7.95677","3345.44849","0.00123"
"73.80000","7.96669","3310.02441","0.00123"
"73.90000","7.97670","3295.11987","0.00123"
"74.00000","7.98671","3311.97461","0.00123"
"74.10000","7.99683","3296.59644","0.00123"
"74.20000","8.00684","3322.69360","0.00123"
"74.30000","8.01681","3290.25244","0.00123"
"74.40000","8.02667","3336.65918","0.00123"
"74.50000","8.03666","3277.18262","0.00123"
"74.60000","8.04665","3329.76538","0.00123"
"74.70000","8.05670","3296.48022","0.00123"
"74.80000","8.06675","3316.82739","0.00123"
"74.90000","8.07685","3352.35522","0.00123"
"75.00000","8.08674","3302.97339","0.00123"
"75.10000","8.09663","3351.94800","0.00123"
"75.20000","8.10660","3286.77417","0.00123"
"75.30000","8.11668","3340.71484","0.00123"
"75.40000","8.12676","3287.13428","0.00123"
"75.50000","8.13685","3329.05396","0.00123"
"75.60000","8.14674","3368.42090","0.00123"
"75.70000","8.15681","3296.00024","0.00123"
"75.80000","8.16669","3343.29077","0.00123"
"75.90000","8.17674","3287.87036","0.00123"
"76.00000","8.18675","3324.44897","0.00123"
"76.10000","8.19674","3319.77612","0.00123"
"76.20000","8.20675","3321.47632","0.00123"
"76.30000","8.21671","3361.91992","0.00123"
"76.40000","8.22675","3291.11768","0.00123"
"76.50000","8.23675","3341.70679","0.00123"
"76.60000","8.24681","3296.16406","0.00123"
"76.70000","8.25677","3325.74609","0.00123"
"76.80000","8.26669","3354.02344","0.00123"
"76.90000","8.27668","3260.26611","0.00123"
"77.00000","8.28664","3311.70923","0.00123"
"77.10000","8.29676","3248.41919","0.00123"
"77.20000","8.30680","3298.77954","0.00123"
"77.30000","8.31688","3260.57300","0.00123"
"77.40000","8.32674","3286.69946","0.00123"
"77.50000","8.33669","3311.66382","0.00123"
"77.60000","8.34657","3276.61011","0.00123"
"77.70000","8.35665","3326.50317","0.00123"
"77.80000","8.36678","3264.80371","0.00123"
"77.90000","8.37684","3318.16821","0.00123"
"78.00000","8.38683","3256.04688","0.00123"
"78.10000","8.39674","3309.09351","0.00124"
"78.20000","8.40667","3261.18652","0.00123"
"78.30000","8.41667","3301.89014","0.00124"
"78.40000","8.42676","3290.66479","0.00123"
"78.50000","8.43675","3295.51538","0.00124"
"78.60000","8.44679","3338.49487","0.00123"
"78.70000","8.45678","3285.22656","0.00124"
"78.80000","8.46670","3335.48999","0.00124"
"78.90000","8.47675","3269.98682","0.00123"
"79.00000","8.48676","3322.76489","0.00124"
"79.10000","8.49675","3273.25171","0.00123"
"79.20000","8.50670","3306.02368","0.00124"
"79.30000","8.51667","3311.87183","0.00123"
"79.40000","8.52668","3291.59131","0.00124"
"79.50000","8.53676","3338.63989","0.00123"
"79.60000","8.54679","3273.09668","0.00124"
"79.70000","8.55684","3324.45459","0.00124"
"79.80000","8.56679","3249.40234","0.00124"
"79.90000","8.57668","3301.50244","0.00124"
"80.00000","8.58655","3240.41211","0.00124"
"80.10000","8.59668","3285.84131","0.00124"
"80.20000","8.60683","3247.08179","0.00124"
"80.30000","8.61689","3265.63428","0.00124"
"80.40000","8.62677","3250.38086","0.00124"
"80.50000","8.63668","3246.53003","0.00124"
"80.60000","8.64661","3234.37524","0.00124"
"80.70000","8.65664","3233.45850","0.00124"
"80.80000","8.66671","3191.27930","0.00124"
"80.90000","8.67677","3223.08716","0.00124"
"81.00000","8.68685","3168.30615","0.00124"
"81.10000","8.69680","3211.62646","0.00124"
"81.20000","8.70669","3162.44214","0.00124"
"81.30000","8.71669","3139.94434","0.00124"
"81.40000","8.72674","3158.19263","0.00124"
"81.50000","8.73682","3113.06567","0.00124"
"81.60000","8.74672","3093.64600","0.00124"
"81.70000","8.75670","3107.13257","0.00124"
"81.80000","8.76674","3072.61499","0.00124"
"81.90000","8.77672","3039.00977","0.00124"
"82.00000","8.78677","3022.18970","0.00124"
"82.10000","8.79678","3014.02148","0.00124"
"82.20000","8.80676","2991.47852","0.00124"
"82.30000","8.81667","2960.44897","0.00124"
"82.40000","8.82659","2929.46021","0.00124"
"82.50000","8.83673","2899.70215","0.00124"
"82.60000","8.84684","2871.50073","0.00124"
"82.70000","8.85689","2841.38770","0.00124"
"82.80000","8.86678","2809.42407","0.00124"
"82.90000","8.87670","2774.01709","0.00124"
"83.00000","8.88662","2734.06445","0.00124"
"83.10000","8.89667","2687.93701","0.00124"
"83.20000","8.90674","2636.27002","0.00124"
"83.30000","8.91686","2572.23560","0.00124"
"83.35000","8.92184","1560.42847","0.00124"