File: archive/undergrad/433/Tensile Test/Specimen_RawData_2.csv
Time,Extension,Load,Strain Gage18
(s),(mm),(N),(mm/mm)
"0.00000","0.00000","260.33627","-0.00007"
"0.10000","0.00307","281.11908","-0.00008"
"0.20000","0.01351","355.64404","-0.00011"
"0.30000","0.02409","427.75455","-0.00014"
"0.40000","0.03410","494.46838","-0.00016"
"0.50000","0.04410","560.13165","-0.00018"
"0.60000","0.05412","625.22699","-0.00021"
"0.70000","0.06409","688.82440","-0.00023"
"0.80000","0.07416","751.79138","-0.00025"
"0.90000","0.08415","813.22632","-0.00028"
"1.00000","0.09408","873.61920","-0.00030"
"1.10000","0.10404","933.36969","-0.00032"
"1.20000","0.11409","993.31427","-0.00034"
"1.30000","0.12418","1052.72510","-0.00036"
"1.40000","0.13427","1112.21948","-0.00039"
"1.50000","0.14419","1169.74939","-0.00041"
"1.60000","0.15409","1227.29297","-0.00043"
"1.70000","0.16402","1284.70215","-0.00045"
"1.80000","0.17404","1342.75049","-0.00047"
"1.90000","0.18411","1400.91235","-0.00049"
"2.00000","0.19420","1458.80579","-0.00051"
"2.10000","0.20424","1516.22034","-0.00053"
"2.20000","0.21419","1572.87122","-0.00055"
"2.30000","0.22406","1629.02271","-0.00057"
"2.40000","0.23400","1685.22766","-0.00059"
"2.50000","0.24406","1741.65857","-0.00062"
"2.60000","0.25411","1797.98999","-0.00064"
"2.70000","0.26422","1854.10156","-0.00066"
"2.80000","0.27417","1908.49280","-0.00068"
"2.90000","0.28415","1962.58203","-0.00070"
"3.00000","0.29407","2015.80469","-0.00072"
"3.10000","0.30411","2069.15015","-0.00075"
"3.20000","0.31414","2121.77197","-0.00077"
"3.30000","0.32413","2172.31934","-0.00079"
"3.40000","0.33409","2221.60303","-0.00082"
"3.50000","0.34411","2269.43701","-0.00084"
"3.60000","0.35412","2314.47070","-0.00087"
"3.70000","0.36418","2356.97339","-0.00090"
"3.80000","0.37421","2395.15967","-0.00093"
"3.90000","0.38416","2428.47363","-0.00096"
"4.00000","0.39409","2457.79004","-0.00100"
"4.10000","0.40406","2482.95850","-0.00103"
"4.20000","0.41409","2503.90332","-0.00107"
"4.30000","0.42412","2521.44214","-0.00110"
"4.40000","0.43423","2536.04468","-0.00114"
"4.50000","0.44426","2547.60620","-0.00117"
"4.60000","0.45418","2557.00732","-0.00120"
"4.70000","0.46406","2565.33325","-0.00123"
"4.80000","0.47394","2572.20654","-0.00126"
"4.90000","0.48407","2578.29053","-0.00129"
"5.00000","0.49416","2583.84058","-0.00131"
"5.10000","0.50428","2588.85474","-0.00134"
"5.20000","0.51418","2594.14771","-0.00136"
"5.30000","0.52417","2596.75024","-0.00138"
"5.40000","0.53407","2597.56396","-0.00140"
"5.50000","0.54409","2605.40039","-0.00143"
"5.60000","0.55415","2597.48413","-0.00144"
"5.70000","0.56415","2597.75073","-0.00145"
"5.80000","0.57414","2614.47217","-0.00147"
"5.90000","0.58417","2606.61304","-0.00147"
"6.00000","0.59412","2622.45752","-0.00149"
"6.10000","0.60414","2620.12842","-0.00150"
"6.20000","0.61419","2625.70093","-0.00151"
"6.30000","0.62415","2615.38745","-0.00151"
"6.40000","0.63411","2618.19214","-0.00180"
"6.50000","0.64405","2620.51685","-0.00294"
"6.60000","0.65410","2620.20093","-0.00318"
"6.70000","0.66414","2620.08398","-0.00320"
"6.80000","0.67421","2622.12915","-0.00321"
"6.90000","0.68425","2623.72632","-0.00322"
"7.00000","0.69415","2625.12500","-0.00322"
"7.10000","0.70408","2650.85229","-0.00323"
"7.20000","0.71397","2613.56201","-0.00322"
"7.30000","0.72407","2620.38379","-0.00322"
"7.40000","0.73420","2624.52393","-0.00322"
"7.50000","0.74428","2626.36328","-0.00323"
"7.60000","0.75415","2628.74731","-0.00323"
"7.70000","0.76412","2629.82959","-0.00323"
"7.80000","0.77402","2629.26562","-0.00323"
"7.90000","0.78403","2629.03979","-0.00323"
"8.00000","0.79414","2628.61523","-0.00323"
"8.10000","0.80415","2627.45264","-0.00323"
"8.20000","0.81420","2630.04517","-0.00324"
"8.30000","0.82420","2641.04565","-0.00324"
"8.40000","0.83410","2658.40918","-0.00325"
"8.50000","0.84411","2676.35474","-0.00326"
"8.60000","0.85416","2637.95898","-0.00324"
"8.70000","0.86419","2633.09863","-0.00324"
"8.80000","0.87411","2631.86426","-0.00324"
"8.90000","0.88409","2632.08960","-0.00324"
"9.00000","0.89413","2634.77637","-0.00324"
"9.10000","0.90413","2640.36279","-0.00324"
"9.20000","0.91418","2644.92798","-0.00325"
"9.30000","0.92421","2645.05640","-0.00325"
"9.40000","0.93414","2654.40527","-0.00325"
"9.50000","0.94406","2664.75781","-0.00325"
"9.60000","0.95397","2666.37573","-0.00325"
"9.70000","0.96406","2675.36987","-0.00326"
"9.80000","0.97425","2682.66235","-0.00326"
"9.90000","0.98428","2681.08105","-0.00326"
"10.00000","0.99418","2718.00830","-0.00328"
"10.10000","1.00408","2707.16577","-0.00327"
"10.20000","1.01403","2678.55029","-0.00326"
"10.30000","1.02402","2684.52490","-0.00326"
"10.40000","1.03414","2709.91016","-0.00327"
"10.50000","1.04423","2707.97412","-0.00327"
"10.60000","1.05424","2714.37378","-0.00327"
"10.70000","1.06420","2734.90747","-0.00328"
"10.80000","1.07405","2737.77417","-0.00328"
"10.90000","1.08407","2735.27612","-0.00327"
"11.00000","1.09409","2749.00952","-0.00328"
"11.10000","1.10420","2736.93750","-0.00323"
"11.20000","1.11416","2727.57007","-0.00277"
"11.30000","1.12411","2724.06567","-0.00231"
"11.40000","1.13411","2731.40967","-0.00297"
"11.50000","1.14411","2734.98926","-0.00296"
"11.60000","1.15416","2739.68335","-0.00100"
"11.70000","1.16421","2745.47217","-0.00100"
"11.80000","1.17415","2753.03271","-0.00098"
"11.90000","1.18404","2752.79980","-0.00098"
"12.00000","1.19402","2750.54883","-0.00097"
"12.10000","1.20412","2737.52539","-0.00097"
"12.20000","1.21421","2756.52100","-0.00097"
"12.30000","1.22427","2765.27905","-0.00097"
"12.40000","1.23418","2767.07959","-0.00096"
"12.50000","1.24408","2754.14087","-0.00096"
"12.60000","1.25398","2750.83911","-0.00096"
"12.70000","1.26406","2749.44189","-0.00096"
"12.80000","1.27414","2747.82520","-0.00096"
"12.90000","1.28431","2751.08472","-0.00096"
"13.00000","1.29430","2751.19775","-0.00096"
"13.10000","1.30417","2751.48877","-0.00096"
"13.20000","1.31403","2757.74438","-0.00096"
"13.30000","1.32405","2758.00977","-0.00096"
"13.40000","1.33410","2761.61670","-0.00096"
"13.50000","1.34418","2759.46753","-0.00096"
"13.60000","1.35421","2753.08276","-0.00095"
"13.70000","1.36414","2748.75635","-0.00095"
"13.80000","1.37413","2748.74341","-0.00095"
"13.90000","1.38403","2750.03687","-0.00095"
"14.00000","1.39407","2751.80127","-0.00095"
"14.10000","1.40419","2780.77856","-0.00095"
"14.20000","1.41416","2741.57349","-0.00094"
"14.30000","1.42406","2786.26782","-0.00095"
"14.40000","1.43407","2805.35693","-0.00095"
"14.50000","1.44417","2811.15894","-0.00095"
"14.60000","1.45417","2838.49121","-0.00095"
"14.70000","1.46427","2796.76904","-0.00094"
"14.80000","1.47415","2819.46973","-0.00095"
"14.90000","1.48406","2801.20850","-0.00094"
"15.00000","1.49403","2766.84253","-0.00094"
"15.10000","1.50408","2758.77661","-0.00094"
"15.20000","1.51416","2756.44824","-0.00094"
"15.30000","1.52431","2759.23413","-0.00094"
"15.40000","1.53427","2759.97095","-0.00093"
"15.50000","1.54407","2767.42798","-0.00093"
"15.60000","1.55402","2770.80713","-0.00093"
"15.70000","1.56405","2775.96216","-0.00093"
"15.80000","1.57407","2780.53516","-0.00093"
"15.90000","1.58425","2780.20288","-0.00093"
"16.00000","1.59426","2781.61865","-0.00093"
"16.10000","1.60412","2792.65552","-0.00093"
"16.20000","1.61404","2792.02319","-0.00093"
"16.30000","1.62407","2816.88354","-0.00094"
"16.40000","1.63407","2823.71484","-0.00094"
"16.50000","1.64422","2820.14844","-0.00093"
"16.60000","1.65416","2831.42212","-0.00094"
"16.70000","1.66406","2837.76343","-0.00094"
"16.80000","1.67407","2863.18823","-0.00094"
"16.90000","1.68418","2860.65479","-0.00094"
"17.00000","1.69417","2839.88330","-0.00093"
"17.10000","1.70420","2868.28662","-0.00093"
"17.20000","1.71416","2876.95117","-0.00093"
"17.30000","1.72402","2881.41260","-0.00093"
"17.40000","1.73403","2837.93311","-0.00093"
"17.50000","1.74415","2861.84619","-0.00093"
"17.60000","1.75420","2904.97754","-0.00093"
"17.70000","1.76431","2889.68750","-0.00093"
"17.80000","1.77427","2900.50513","-0.00093"
"17.90000","1.78407","2867.73779","-0.00093"
"18.00000","1.79400","2880.65088","-0.00093"
"18.10000","1.80404","2897.73315","-0.00094"
"18.20000","1.81410","2876.20190","-0.00093"
"18.30000","1.82430","2858.32446","-0.00093"
"18.40000","1.83429","2856.03247","-0.00094"
"18.50000","1.84410","2852.96753","-0.00093"
"18.60000","1.85405","2856.44995","-0.00091"
"18.70000","1.86407","2871.09253","-0.00089"
"18.80000","1.87408","2879.02222","-0.00089"
"18.90000","1.88419","2879.38940","-0.00088"
"19.00000","1.89423","2880.72388","-0.00088"
"19.10000","1.90415","2893.22949","-0.00088"
"19.20000","1.91410","2898.34424","-0.00087"
"19.30000","1.92414","2874.11914","-0.00087"
"19.40000","1.93413","2874.62036","-0.00087"
"19.50000","1.94417","2892.48608","-0.00087"
"19.60000","1.95418","2926.62378","-0.00087"
"19.70000","1.96404","2920.34448","-0.00087"
"19.80000","1.97405","2928.63965","-0.00086"
"19.90000","1.98419","2873.03638","-0.00086"
"20.00000","1.99419","2923.29590","-0.00086"
"20.10000","2.00424","2951.59790","-0.00086"
"20.20000","2.01424","2948.61450","-0.00086"
"20.30000","2.02409","2880.76221","-0.00086"
"20.40000","2.03398","2888.98315","-0.00086"
"20.50000","2.04407","2905.86938","-0.00086"
"20.60000","2.05414","2891.81836","-0.00086"
"20.70000","2.06430","2889.52466","-0.00086"
"20.80000","2.07426","2904.56567","-0.00086"
"20.90000","2.08409","2897.87378","-0.00086"
"21.00000","2.09404","2913.37915","-0.00086"
"21.10000","2.10407","2911.71289","-0.00086"
"21.20000","2.11410","2900.28467","-0.00086"
"21.30000","2.12415","2888.24170","-0.00085"
"21.40000","2.13427","2887.49341","-0.00085"
"21.50000","2.14414","2890.71826","-0.00085"
"21.60000","2.15411","2920.98242","-0.00086"
"21.70000","2.16410","2909.87671","-0.00085"
"21.80000","2.17411","2892.23511","-0.00085"
"21.90000","2.18416","2884.55664","-0.00085"
"22.00000","2.19421","2889.04785","-0.00085"
"22.10000","2.20406","2907.49561","-0.00085"
"22.20000","2.21409","2915.05200","-0.00085"
"22.30000","2.22418","2940.56006","-0.00085"
"22.40000","2.23415","2962.48706","-0.00085"
"22.50000","2.24421","2946.61304","-0.00085"
"22.60000","2.25416","2981.29028","-0.00086"
"22.70000","2.26411","2991.93262","-0.00086"
"22.80000","2.27401","2970.80029","-0.00085"
"22.90000","2.28410","2951.95312","-0.00085"
"23.00000","2.29419","2937.99683","-0.00085"
"23.10000","2.30427","2957.95483","-0.00085"
"23.20000","2.31428","2907.86523","-0.00085"
"23.30000","2.32407","2893.72925","-0.00085"
"23.40000","2.33402","2915.10840","-0.00085"
"23.50000","2.34406","2922.67651","-0.00085"
"23.60000","2.35413","2912.52051","-0.00085"
"23.70000","2.36419","2901.68481","-0.00085"
"23.80000","2.37429","2902.66479","-0.00085"
"23.90000","2.38416","2897.50903","-0.00085"
"24.00000","2.39405","2907.41650","-0.00085"
"24.10000","2.40405","2932.90161","-0.00085"
"24.20000","2.41409","2929.88354","-0.00085"
"24.30000","2.42415","2916.59399","-0.00085"
"24.40000","2.43423","2911.66528","-0.00085"
"24.50000","2.44414","2912.45581","-0.00085"
"24.60000","2.45414","2939.00000","-0.00085"
"24.70000","2.46417","2950.81787","-0.00085"
"24.80000","2.47414","2953.96582","-0.00085"
"24.90000","2.48414","2946.21265","-0.00085"
"25.00000","2.49417","2969.77344","-0.00085"
"25.10000","2.50408","2974.50684","-0.00085"
"25.20000","2.51408","2969.00220","-0.00085"
"25.30000","2.52411","2958.31567","-0.00085"
"25.40000","2.53421","2996.16943","-0.00085"
"25.50000","2.54422","2993.87988","-0.00085"
"25.60000","2.55421","3001.15308","-0.00085"
"25.70000","2.56408","3014.48071","-0.00085"
"25.80000","2.57405","3006.83276","-0.00085"
"25.90000","2.58408","2989.09741","-0.00084"
"26.00000","2.59411","3000.35815","-0.00084"
"26.10000","2.60424","3028.89600","-0.00085"
"26.20000","2.61426","2994.46875","-0.00084"
"26.30000","2.62420","3051.98535","-0.00085"
"26.40000","2.63409","3012.25659","-0.00084"
"26.50000","2.64400","3000.51074","-0.00084"
"26.60000","2.65408","3043.22925","-0.00085"
"26.70000","2.66415","3020.46069","-0.00085"
"26.80000","2.67424","3008.11475","-0.00085"
"26.90000","2.68420","3018.16797","-0.00085"
"27.00000","2.69414","3009.71851","-0.00084"
"27.10000","2.70410","2995.03320","-0.00076"
"27.20000","2.71411","2997.93359","-0.00077"
"27.30000","2.72414","3031.49097","-0.00077"
"27.40000","2.73413","3012.39380","-0.00077"
"27.50000","2.74412","2997.35254","-0.00077"
"27.60000","2.75413","3025.19067","-0.00077"
"27.70000","2.76415","3032.67700","-0.00077"
"27.80000","2.77418","3021.88501","-0.00077"
"27.90000","2.78421","3008.76489","-0.00077"
"28.00000","2.79416","3035.90723","-0.00076"
"28.10000","2.80413","2966.08105","-0.00076"
"28.20000","2.81402","3025.05591","-0.00076"
"28.30000","2.82409","3025.09082","-0.00077"
"28.40000","2.83413","3065.72607","-0.00077"
"28.50000","2.84425","3042.21167","-0.00077"
"28.60000","2.85421","3057.84375","-0.00077"
"28.70000","2.86418","3042.19360","-0.00077"
"28.80000","2.87411","2989.10010","-0.00077"
"28.90000","2.88393","3037.08960","-0.00077"
"29.00000","2.89409","3054.00562","-0.00077"
"29.10000","2.90417","3072.31128","-0.00077"
"29.20000","2.91428","3032.09741","-0.00077"
"29.30000","2.92421","3089.21216","-0.00077"
"29.40000","2.93417","3025.45679","-0.00077"
"29.50000","2.94404","3081.59106","-0.00077"
"29.60000","2.95403","3063.62427","-0.00077"
"29.70000","2.96412","3052.97583","-0.00077"
"29.80000","2.97414","3088.11035","-0.00077"
"29.90000","2.98418","3071.98022","-0.00077"
"30.00000","2.99416","3036.74609","-0.00077"
"30.10000","3.00410","3055.53320","-0.00077"
"30.20000","3.01412","3038.22217","-0.00077"
"30.30000","3.02417","3023.67285","-0.00077"
"30.40000","3.03416","3065.14185","-0.00077"
"30.50000","3.04414","3040.94946","-0.00077"
"30.60000","3.05407","3029.62646","-0.00077"
"30.70000","3.06408","3039.99609","-0.00077"
"30.80000","3.07415","3030.59644","-0.00077"
"30.90000","3.08420","3059.63623","-0.00077"
"31.00000","3.09423","3049.97607","-0.00077"
"31.10000","3.10415","3022.96924","-0.00077"
"31.20000","3.11408","3073.50928","-0.00077"
"31.30000","3.12396","3037.86670","-0.00077"
"31.40000","3.13406","3030.34644","-0.00077"
"31.50000","3.14420","3060.83105","-0.00077"
"31.60000","3.15428","3043.73364","-0.00077"
"31.70000","3.16422","3017.73950","-0.00077"
"31.80000","3.17411","3067.35938","-0.00077"
"31.90000","3.18403","3039.01807","-0.00077"
"32.00000","3.19401","3025.49048","-0.00077"
"32.10000","3.20414","3024.14429","-0.00077"
"32.20000","3.21418","3067.70532","-0.00077"
"32.30000","3.22426","3028.90332","-0.00077"
"32.40000","3.23418","3085.80713","-0.00077"
"32.50000","3.24409","3048.21851","-0.00077"
"32.60000","3.25408","3102.80688","-0.00077"
"32.70000","3.26410","3085.18408","-0.00077"
"32.80000","3.27409","3122.19849","-0.00077"
"32.90000","3.28416","3077.93457","-0.00077"
"33.00000","3.29410","3134.17944","-0.00077"
"33.10000","3.30414","3105.72046","-0.00077"
"33.20000","3.31412","3141.89429","-0.00077"
"33.30000","3.32416","3137.42798","-0.00077"
"33.40000","3.33419","3136.04858","-0.00077"
"33.50000","3.34413","3133.14941","-0.00077"
"33.60000","3.35410","3150.04785","-0.00077"
"33.70000","3.36401","3092.32349","-0.00077"
"33.80000","3.37411","3149.67188","-0.00077"
"33.90000","3.38428","3054.46533","-0.00077"
"34.00000","3.39427","3043.80029","-0.00077"
"34.10000","3.40416","3033.42163","-0.00077"
"34.20000","3.41406","3048.55298","-0.00077"
"34.30000","3.42400","3063.63599","-0.00077"
"34.40000","3.43403","3037.98511","-0.00077"
"34.50000","3.44415","3030.07031","-0.00077"
"34.60000","3.45423","3075.21362","-0.00077"
"34.70000","3.46428","3060.36255","-0.00077"
"34.80000","3.47418","3039.26587","-0.00077"
"34.90000","3.48401","3085.56348","-0.00077"
"35.00000","3.49409","3067.67017","-0.00077"
"35.10000","3.50408","3045.51953","-0.00077"
"35.20000","3.51416","3058.60205","-0.00077"
"35.30000","3.52421","3079.56299","-0.00077"
"35.40000","3.53415","3064.29297","-0.00077"
"35.50000","3.54413","3055.15967","-0.00077"
"35.60000","3.55408","3100.63818","-0.00077"
"35.70000","3.56413","3079.46680","-0.00077"
"35.80000","3.57419","3063.56104","-0.00077"
"35.90000","3.58414","3106.67676","-0.00077"
"36.00000","3.59405","3102.38159","-0.00077"
"36.10000","3.60407","3085.91992","-0.00077"
"36.20000","3.61416","3111.88940","-0.00077"
"36.30000","3.62423","3112.08276","-0.00077"
"36.40000","3.63423","3124.58374","-0.00077"
"36.50000","3.64415","3093.18579","-0.00077"
"36.60000","3.65407","3086.18701","-0.00077"
"36.70000","3.66397","3118.70776","-0.00077"
"36.80000","3.67406","3086.44946","-0.00077"
"36.90000","3.68413","3120.26587","-0.00077"
"37.00000","3.69433","3118.04590","-0.00077"
"37.10000","3.70428","3083.51416","-0.00077"
"37.20000","3.71412","3133.02417","-0.00077"
"37.30000","3.72400","3122.00781","-0.00077"
"37.40000","3.73402","3152.46875","-0.00077"
"37.50000","3.74409","3128.74756","-0.00077"
"37.60000","3.75420","3123.52808","-0.00077"
"37.70000","3.76424","3148.60864","-0.00077"
"37.80000","3.77417","3116.50513","-0.00077"
"37.90000","3.78412","3167.79907","-0.00077"
"38.00000","3.79408","3153.61035","-0.00077"
"38.10000","3.80406","3193.37817","-0.00077"
"38.20000","3.81418","3191.38403","-0.00077"
"38.30000","3.82417","3142.69092","-0.00077"
"38.40000","3.83410","3114.36499","-0.00077"
"38.50000","3.84408","3164.49072","-0.00077"
"38.60000","3.85418","3129.27002","-0.00076"
"38.70000","3.86415","3131.95947","-0.00076"
"38.80000","3.87424","3151.44800","-0.00076"
"38.90000","3.88416","3117.34741","-0.00076"
"39.00000","3.89404","3128.43994","-0.00076"
"39.10000","3.90397","3144.83057","-0.00075"
"39.20000","3.91414","3114.22778","-0.00076"
"39.30000","3.92419","3153.12744","-0.00076"
"39.40000","3.93432","3147.27197","-0.00076"
"39.50000","3.94426","3118.46680","-0.00077"
"39.60000","3.95407","3169.38867","-0.00077"
"39.70000","3.96403","3131.40942","-0.00077"
"39.80000","3.97402","3131.92896","-0.00078"
"39.90000","3.98408","3158.25073","-0.00078"
"40.00000","3.99425","3122.86548","-0.00078"
"40.10000","4.00427","3176.43945","-0.00078"
"40.20000","4.01413","3142.03760","-0.00078"
"40.30000","4.02407","3126.77026","-0.00078"
"40.40000","4.03407","3184.47583","-0.00078"
"40.50000","4.04406","3158.75708","-0.00078"
"40.60000","4.05420","3159.39453","-0.00078"
"40.70000","4.06422","3117.53198","-0.00078"
"40.80000","4.07414","3161.39722","-0.00078"
"40.90000","4.08410","3161.03223","-0.00078"
"41.00000","4.09413","3213.98828","-0.00078"
"41.10000","4.10415","3174.06836","-0.00078"
"41.20000","4.11418","3183.81372","-0.00078"
"41.30000","4.12418","3182.22412","-0.00078"
"41.40000","4.13402","3217.94312","-0.00078"
"41.50000","4.14407","3177.62280","-0.00078"
"41.60000","4.15416","3157.25464","-0.00078"
"41.70000","4.16421","3190.30518","-0.00078"
"41.80000","4.17424","3150.62622","-0.00078"
"41.90000","4.18424","3205.30786","-0.00078"
"42.00000","4.19407","3169.40991","-0.00078"
"42.10000","4.20399","3188.11694","-0.00078"
"42.20000","4.21408","3182.74976","-0.00078"
"42.30000","4.22413","3147.30566","-0.00078"
"42.40000","4.23432","3177.79932","-0.00078"
"42.50000","4.24430","3175.55664","-0.00078"
"42.60000","4.25410","3145.14795","-0.00078"
"42.70000","4.26402","3197.34668","-0.00078"
"42.80000","4.27408","3158.09546","-0.00078"
"42.90000","4.28405","3176.45557","-0.00078"
"43.00000","4.29419","3174.58740","-0.00078"
"43.10000","4.30427","3143.43799","-0.00078"
"43.20000","4.31415","3184.39868","-0.00078"
"43.30000","4.32415","3168.16040","-0.00079"
"43.40000","4.33408","3149.69409","-0.00079"
"43.50000","4.34408","3185.25220","-0.00079"
"43.60000","4.35415","3166.69824","-0.00079"
"43.70000","4.36421","3204.27783","-0.00079"
"43.80000","4.37407","3190.96704","-0.00079"
"43.90000","4.38409","3158.79126","-0.00079"
"44.00000","4.39419","3148.77490","-0.00079"
"44.10000","4.40418","3172.73218","-0.00079"
"44.20000","4.41423","3140.83765","-0.00079"
"44.30000","4.42418","3191.78516","-0.00079"
"44.40000","4.43410","3160.25977","-0.00079"
"44.50000","4.44397","3155.70532","-0.00079"
"44.60000","4.45411","3183.11597","-0.00079"
"44.70000","4.46416","3147.55933","-0.00079"
"44.80000","4.47431","3191.26221","-0.00079"
"44.90000","4.48423","3172.90088","-0.00079"
"45.00000","4.49407","3185.86523","-0.00079"
"45.10000","4.50407","3200.43604","-0.00079"
"45.20000","4.51407","3220.26831","-0.00079"
"45.30000","4.52412","3148.21484","-0.00079"
"45.40000","4.53416","3199.11987","-0.00079"
"45.50000","4.54430","3147.37524","-0.00079"
"45.60000","4.55418","3199.40698","-0.00079"
"45.70000","4.56406","3173.74536","-0.00079"
"45.80000","4.57405","3211.79468","-0.00079"
"45.90000","4.58411","3172.99927","-0.00078"
"46.00000","4.59411","3224.33569","-0.00078"
"46.10000","4.60419","3164.76001","-0.00078"
"46.20000","4.61409","3215.81152","-0.00078"
"46.30000","4.62413","3179.02832","-0.00078"
"46.40000","4.63417","3219.31836","-0.00078"
"46.50000","4.64418","3178.02588","-0.00078"
"46.60000","4.65417","3230.82495","-0.00078"
"46.70000","4.66418","3183.96875","-0.00078"
"46.80000","4.67407","3238.45752","-0.00078"
"46.90000","4.68410","3189.28931","-0.00078"
"47.00000","4.69411","3242.56836","-0.00078"
"47.10000","4.70423","3190.98755","-0.00078"
"47.20000","4.71421","3242.03882","-0.00078"
"47.30000","4.72425","3197.26270","-0.00078"
"47.40000","4.73405","3250.62012","-0.00078"
"47.50000","4.74407","3201.44141","-0.00078"
"47.60000","4.75400","3256.93945","-0.00078"
"47.70000","4.76415","3152.40015","-0.00078"
"47.80000","4.77421","3176.19263","-0.00078"
"47.90000","4.78430","3180.30566","-0.00078"
"48.00000","4.79418","3136.84790","-0.00078"
"48.10000","4.80406","3190.48755","-0.00078"
"48.20000","4.81403","3155.79932","-0.00078"
"48.30000","4.82404","3156.27856","-0.00078"
"48.40000","4.83414","3174.02295","-0.00078"
"48.50000","4.84424","3135.13208","-0.00078"
"48.60000","4.85418","3186.07690","-0.00078"
"48.70000","4.86417","3157.50122","-0.00078"
"48.80000","4.87407","3146.97070","-0.00078"
"48.90000","4.88407","3179.47314","-0.00078"
"49.00000","4.89415","3144.99780","-0.00078"
"49.10000","4.90416","3197.24390","-0.00078"
"49.20000","4.91412","3174.94385","-0.00078"
"49.30000","4.92412","3218.79688","-0.00078"
"49.40000","4.93412","3176.11987","-0.00078"
"49.50000","4.94418","3214.07178","-0.00078"
"49.60000","4.95423","3191.68945","-0.00078"
"49.70000","4.96419","3223.78125","-0.00078"
"49.80000","4.97409","3206.58423","-0.00078"
"49.90000","4.98405","3226.44922","-0.00078"
"50.00000","4.99410","3184.01465","-0.00078"
"50.10000","5.00413","3237.98926","-0.00078"
"50.20000","5.01422","3219.43311","-0.00078"
"50.30000","5.02424","3243.46680","-0.00078"
"50.40000","5.03417","3250.62939","-0.00077"
"50.50000","5.04410","3203.30493","-0.00077"
"50.60000","5.05396","3257.75098","-0.00077"
"50.70000","5.06406","3204.96362","-0.00077"
"50.80000","5.07415","3254.06079","-0.00077"
"50.90000","5.08429","3213.18945","-0.00077"
"51.00000","5.09422","3256.75122","-0.00077"
"51.10000","5.10416","3209.09277","-0.00077"
"51.20000","5.11403","3257.06665","-0.00077"
"51.30000","5.12411","3201.69189","-0.00077"
"51.40000","5.13412","3255.51953","-0.00076"
"51.50000","5.14418","3198.77368","-0.00077"
"51.60000","5.15414","3256.27930","-0.00077"
"51.70000","5.16419","3205.97876","-0.00077"
"51.80000","5.17411","3261.26367","-0.00077"
"51.90000","5.18416","3184.26562","-0.00077"
"52.00000","5.19416","3236.08154","-0.00077"
"52.10000","5.20413","3221.66797","-0.00077"
"52.20000","5.21413","3262.27051","-0.00077"
"52.30000","5.22409","3243.18262","-0.00077"
"52.40000","5.23413","3204.37256","-0.00077"
"52.50000","5.24412","3248.67065","-0.00077"
"52.60000","5.25422","3202.86963","-0.00077"
"52.70000","5.26422","3261.08228","-0.00077"
"52.80000","5.27417","3211.55566","-0.00078"
"52.90000","5.28407","3265.57349","-0.00077"
"53.00000","5.29393","3208.33691","-0.00078"
"53.10000","5.30409","3266.73315","-0.00078"
"53.20000","5.31422","3221.97754","-0.00077"
"53.30000","5.32426","3277.98804","-0.00077"
"53.40000","5.33419","3227.83521","-0.00077"
"53.50000","5.34413","3261.14331","-0.00077"
"53.60000","5.35405","3230.78638","-0.00077"
"53.70000","5.36403","3224.55396","-0.00077"
"53.80000","5.37412","3239.64648","-0.00077"
"53.90000","5.38415","3205.76660","-0.00077"
"54.00000","5.39425","3245.98706","-0.00077"
"54.10000","5.40419","3244.20996","-0.00077"
"54.20000","5.41408","3222.47070","-0.00077"
"54.30000","5.42407","3191.82959","-0.00077"
"54.40000","5.43414","3236.08813","-0.00077"
"54.50000","5.44415","3223.31201","-0.00077"
"54.60000","5.45412","3221.05518","-0.00077"
"54.70000","5.46409","3273.96289","-0.00077"
"54.80000","5.47412","3214.86548","-0.00077"
"54.90000","5.48413","3270.17798","-0.00077"
"55.00000","5.49417","3216.87305","-0.00077"
"55.10000","5.50419","3269.10718","-0.00077"
"55.20000","5.51416","3231.86670","-0.00077"
"55.30000","5.52408","3236.80347","-0.00077"
"55.40000","5.53397","3259.90942","-0.00077"
"55.50000","5.54410","3252.51416","-0.00077"
"55.60000","5.55422","3280.45557","-0.00077"
"55.70000","5.56430","3234.88940","-0.00077"
"55.80000","5.57416","3288.42700","-0.00077"
"55.90000","5.58409","3253.31470","-0.00077"
"56.00000","5.59398","3268.62598","-0.00077"
"56.10000","5.60401","3264.80151","-0.00078"
"56.20000","5.61413","3230.96631","-0.00078"
"56.30000","5.62424","3281.43042","-0.00078"
"56.40000","5.63428","3242.01245","-0.00078"
"56.50000","5.64417","3297.27295","-0.00078"
"56.60000","5.65406","3215.55615","-0.00078"
"56.70000","5.66406","3276.80322","-0.00078"
"56.80000","5.67408","3241.19897","-0.00078"
"56.90000","5.68418","3268.35327","-0.00078"
"57.00000","5.69416","3226.08838","-0.00078"
"57.10000","5.70413","3272.54224","-0.00078"
"57.20000","5.71414","3225.49048","-0.00078"
"57.30000","5.72407","3280.45068","-0.00078"
"57.40000","5.73410","3231.17896","-0.00078"
"57.50000","5.74416","3289.05908","-0.00078"
"57.60000","5.75422","3235.82739","-0.00078"
"57.70000","5.76404","3293.33838","-0.00078"
"57.80000","5.77404","3234.52686","-0.00078"
"57.90000","5.78408","3293.47510","-0.00078"
"58.00000","5.79424","3235.19702","-0.00078"
"58.10000","5.80425","3293.58350","-0.00078"
"58.20000","5.81423","3231.43628","-0.00078"
"58.30000","5.82405","3269.14941","-0.00078"
"58.40000","5.83399","3241.39185","-0.00078"
"58.50000","5.84405","3294.64160","-0.00078"
"58.60000","5.85417","3262.56836","-0.00078"
"58.70000","5.86430","3238.67529","-0.00078"
"58.80000","5.87426","3262.61255","-0.00078"
"58.90000","5.88412","3295.45215","-0.00078"
"59.00000","5.89405","3246.70557","-0.00079"
"59.10000","5.90403","3300.25513","-0.00078"
"59.20000","5.91409","3238.97900","-0.00079"
"59.30000","5.92421","3296.12427","-0.00078"
"59.40000","5.93427","3239.08862","-0.00078"
"59.50000","5.94410","3294.78687","-0.00078"
"59.60000","5.95411","3240.03931","-0.00078"
"59.70000","5.96405","3296.49487","-0.00078"
"59.80000","5.97412","3237.62793","-0.00078"
"59.90000","5.98419","3295.35938","-0.00078"
"60.00000","5.99418","3231.73804","-0.00078"
"60.10000","6.00406","3267.58203","-0.00078"
"60.20000","6.01411","3239.27734","-0.00078"
"60.30000","6.02414","3290.15430","-0.00078"
"60.40000","6.03420","3243.83569","-0.00078"
"60.50000","6.04425","3290.30859","-0.00078"
"60.60000","6.05415","3246.02173","-0.00078"
"60.70000","6.06405","3284.64624","-0.00078"
"60.80000","6.07399","3249.26221","-0.00078"
"60.90000","6.08413","3289.76855","-0.00078"
"61.00000","6.09416","3253.30493","-0.00078"
"61.10000","6.10432","3281.81226","-0.00078"
"61.20000","6.11430","3255.64307","-0.00078"
"61.30000","6.12409","3289.34302","-0.00078"
"61.40000","6.13402","3239.28101","-0.00078"
"61.50000","6.14405","3263.75562","-0.00078"
"61.60000","6.15408","3251.23657","-0.00078"
"61.70000","6.16424","3264.99243","-0.00078"
"61.80000","6.17426","3249.13013","-0.00078"
"61.90000","6.18413","3264.73462","-0.00078"
"62.00000","6.19408","3279.43970","-0.00078"
"62.10000","6.20404","3267.74341","-0.00078"
"62.20000","6.21404","3275.33081","-0.00078"
"62.30000","6.22417","3258.93921","-0.00078"
"62.40000","6.23417","3274.40942","-0.00078"
"62.50000","6.24413","3267.38281","-0.00078"
"62.60000","6.25409","3311.27051","-0.00078"
"62.70000","6.26422","3266.41528","-0.00078"
"62.80000","6.27412","3313.36401","-0.00078"
"62.90000","6.28421","3256.94751","-0.00078"
"63.00000","6.29417","3304.35815","-0.00078"
"63.10000","6.30403","3270.29370","-0.00078"
"63.20000","6.31404","3275.28149","-0.00078"
"63.30000","6.32413","3265.76318","-0.00078"
"63.40000","6.33420","3310.01685","-0.00078"
"63.50000","6.34430","3253.08301","-0.00078"
"63.60000","6.35425","3305.60815","-0.00078"
"63.70000","6.36404","3239.96875","-0.00078"
"63.80000","6.37398","3297.13330","-0.00078"
"63.90000","6.38404","3238.43848","-0.00078"
"64.00000","6.39411","3288.62769","-0.00078"
"64.10000","6.40427","3246.79419","-0.00078"
"64.20000","6.41427","3275.90918","-0.00078"
"64.30000","6.42410","3277.81250","-0.00078"
"64.40000","6.43403","3267.01636","-0.00078"
"64.50000","6.44406","3311.31177","-0.00078"
"64.60000","6.45410","3269.31519","-0.00078"
"64.70000","6.46417","3301.68970","-0.00078"
"64.80000","6.47424","3256.77393","-0.00078"
"64.90000","6.48411","3304.67383","-0.00078"
"65.00000","6.49413","3257.77930","-0.00078"
"65.10000","6.50411","3305.43066","-0.00078"
"65.20000","6.51412","3264.57983","-0.00078"
"65.30000","6.52417","3283.96973","-0.00078"
"65.40000","6.53420","3325.48462","-0.00078"
"65.50000","6.54404","3264.20923","-0.00078"
"65.60000","6.55407","3317.01636","-0.00078"
"65.70000","6.56420","3255.87280","-0.00078"
"65.80000","6.57420","3297.07349","-0.00078"
"65.90000","6.58423","3329.04761","-0.00078"
"66.00000","6.59423","3277.58276","-0.00078"
"66.10000","6.60406","3328.42627","-0.00078"
"66.20000","6.61404","3255.99902","-0.00078"
"66.30000","6.62405","3313.61768","-0.00078"
"66.40000","6.63416","3262.68896","-0.00078"
"66.50000","6.64431","3298.34814","-0.00078"
"66.60000","6.65424","3320.40259","-0.00078"
"66.70000","6.66408","3280.58423","-0.00078"
"66.80000","6.67402","3331.95972","-0.00078"
"66.90000","6.68409","3263.45410","-0.00079"
"67.00000","6.69408","3319.49927","-0.00078"
"67.10000","6.70420","3295.00879","-0.00078"
"67.20000","6.71429","3267.28271","-0.00079"
"67.30000","6.72417","3285.28174","-0.00079"
"67.40000","6.73410","3306.65552","-0.00079"
"67.50000","6.74408","3270.82642","-0.00079"
"67.60000","6.75410","3318.68799","-0.00079"
"67.70000","6.76415","3259.23120","-0.00079"
"67.80000","6.77422","3312.21777","-0.00079"
"67.90000","6.78411","3250.17871","-0.00079"
"68.00000","6.79411","3303.96045","-0.00079"
"68.10000","6.80420","3256.97803","-0.00079"
"68.20000","6.81412","3312.95386","-0.00079"
"68.30000","6.82422","3245.75781","-0.00079"
"68.40000","6.83418","3297.98828","-0.00079"
"68.50000","6.84408","3309.38647","-0.00079"
"68.60000","6.85404","3260.28833","-0.00079"
"68.70000","6.86411","3310.08691","-0.00079"
"68.80000","6.87422","3247.04077","-0.00080"
"68.90000","6.88427","3303.72705","-0.00080"
"69.00000","6.89421","3298.75244","-0.00080"
"69.10000","6.90407","3300.19775","-0.00080"
"69.20000","6.91406","3253.65430","-0.00080"
"69.30000","6.92405","3301.98901","-0.00080"
"69.40000","6.93412","3220.61328","-0.00080"
"69.50000","6.94416","3275.14478","-0.00080"
"69.60000","6.95432","3295.91040","-0.00080"
"69.70000","6.96419","3273.20874","-0.00080"
"69.80000","6.97408","3325.33057","-0.00080"
"69.90000","6.98401","3267.51685","-0.00080"
"70.00000","6.99409","3287.46167","-0.00080"
"70.10000","7.00415","3269.02490","-0.00080"
"70.20000","7.01423","3309.77954","-0.00080"
"70.30000","7.02417","3256.61450","-0.00080"
"70.40000","7.03412","3310.04590","-0.00080"
"70.50000","7.04418","3254.97900","-0.00080"
"70.60000","7.05410","3290.63525","-0.00080"
"70.70000","7.06414","3333.86475","-0.00080"
"70.80000","7.07416","3273.14551","-0.00080"
"70.90000","7.08412","3306.80786","-0.00080"
"71.00000","7.09411","3239.49756","-0.00080"
"71.10000","7.10412","3281.70850","-0.00080"
"71.20000","7.11419","3295.95776","-0.00080"
"71.30000","7.12424","3275.14624","-0.00080"
"71.40000","7.13419","3318.96606","-0.00080"
"71.50000","7.14410","3260.32642","-0.00079"
"71.60000","7.15402","3313.78271","-0.00080"
"71.70000","7.16408","3248.24146","-0.00079"
"71.80000","7.17412","3302.43970","-0.00079"
"71.90000","7.18423","3255.12964","-0.00079"
"72.00000","7.19426","3293.53027","-0.00079"
"72.10000","7.20415","3297.23608","-0.00079"
"72.20000","7.21406","3282.91064","-0.00079"
"72.30000","7.22397","3332.37012","-0.00079"
"72.40000","7.23408","3239.16699","-0.00079"
"72.50000","7.24415","3286.26440","-0.00079"
"72.60000","7.25427","3244.67041","-0.00079"
"72.70000","7.26420","3295.75952","-0.00079"
"72.80000","7.27417","3242.79956","-0.00079"
"72.90000","7.28407","3285.30078","-0.00079"
"73.00000","7.29410","3244.46826","-0.00079"
"73.10000","7.30410","3289.21973","-0.00079"
"73.20000","7.31414","3244.21680","-0.00079"
"73.30000","7.32415","3292.24878","-0.00079"
"73.40000","7.33415","3243.12524","-0.00079"
"73.50000","7.34411","3281.38916","-0.00079"
"73.60000","7.35418","3243.02026","-0.00079"
"73.70000","7.36418","3272.06665","-0.00079"
"73.80000","7.37417","3245.83838","-0.00079"
"73.90000","7.38409","3289.58301","-0.00079"
"74.00000","7.39405","3245.51050","-0.00079"
"74.10000","7.40410","3297.33447","-0.00079"
"74.20000","7.41416","3245.67188","-0.00079"
"74.30000","7.42422","3300.22168","-0.00079"
"74.40000","7.43423","3244.87793","-0.00079"
"74.50000","7.44417","3300.17090","-0.00079"
"74.60000","7.45411","3242.47192","-0.00079"
"74.70000","7.46393","3298.23267","-0.00079"
"74.80000","7.47409","3237.91235","-0.00079"
"74.90000","7.48415","3291.44849","-0.00079"
"75.00000","7.49428","3252.64868","-0.00078"
"75.10000","7.50420","3280.32422","-0.00078"
"75.20000","7.51411","3322.54590","-0.00078"
"75.30000","7.52403","3264.41455","-0.00078"
"75.40000","7.53406","3312.85010","-0.00078"
"75.50000","7.54414","3252.70996","-0.00078"
"75.60000","7.55412","3307.17480","-0.00078"
"75.70000","7.56423","3248.51880","-0.00078"
"75.80000","7.57418","3306.01416","-0.00078"
"75.90000","7.58412","3300.25220","-0.00078"
"76.00000","7.59412","3274.85718","-0.00078"
"76.10000","7.60414","3318.45288","-0.00078"
"76.20000","7.61414","3267.81226","-0.00078"
"76.30000","7.62413","3303.41504","-0.00078"
"76.40000","7.63412","3250.36865","-0.00078"
"76.50000","7.64411","3304.64282","-0.00078"
"76.60000","7.65413","3244.19409","-0.00078"
"76.70000","7.66420","3286.42432","-0.00078"
"76.80000","7.67419","3322.81299","-0.00078"
"76.90000","7.68418","3271.38501","-0.00078"
"77.00000","7.69406","3322.60083","-0.00078"
"77.10000","7.70396","3295.58618","-0.00078"
"77.20000","7.71413","3279.88721","-0.00077"
"77.30000","7.72422","3321.28589","-0.00078"
"77.40000","7.73429","3303.15869","-0.00078"
"77.50000","7.74418","3310.42749","-0.00077"
"77.60000","7.75410","3266.18579","-0.00077"
"77.70000","7.76401","3277.94507","-0.00077"
"77.80000","7.77401","3319.75806","-0.00077"
"77.90000","7.78414","3258.22632","-0.00077"
"78.00000","7.79421","3311.57080","-0.00077"
"78.10000","7.80430","3256.05225","-0.00077"
"78.20000","7.81413","3288.65601","-0.00077"
"78.30000","7.82404","3331.50952","-0.00077"
"78.40000","7.83406","3257.80762","-0.00077"
"78.50000","7.84408","3311.67920","-0.00077"
"78.60000","7.85420","3233.83887","-0.00077"
"78.70000","7.86418","3288.07056","-0.00077"
"78.80000","7.87411","3281.14380","-0.00077"
"78.90000","7.88412","3257.52686","-0.00077"
"79.00000","7.89412","3306.09668","-0.00077"
"79.10000","7.90418","3230.40234","-0.00077"
"79.20000","7.91421","3283.92993","-0.00077"
"79.30000","7.92417","3205.88696","-0.00077"
"79.40000","7.93406","3261.55347","-0.00076"
"79.50000","7.94402","3182.21289","-0.00076"
"79.60000","7.95413","3238.61157","-0.00076"
"79.70000","7.96423","3167.15210","-0.00076"
"79.80000","7.97422","3220.78418","-0.00076"
"79.90000","7.98420","3154.09863","-0.00076"
"80.00000","7.99407","3179.48486","-0.00076"
"80.10000","8.00401","3144.45874","-0.00076"
"80.20000","8.01403","3098.89014","-0.00076"
"80.30000","8.02414","3137.08008","-0.00076"
"80.40000","8.03430","3083.95654","-0.00076"
"80.50000","8.04427","3053.23926","-0.00076"
"80.60000","8.05416","3079.82397","-0.00076"
"80.70000","8.06403","3033.74756","-0.00076"
"80.80000","8.07408","2991.99878","-0.00075"
"80.90000","8.08405","2977.12500","-0.00075"
"81.00000","8.09416","2968.87354","-0.00075"
"81.10000","8.10420","2945.36304","-0.00075"
"81.20000","8.11417","2912.47852","-0.00075"
"81.30000","8.12415","2877.74756","-0.00075"
"81.40000","8.13409","2843.11597","-0.00075"
"81.50000","8.14412","2808.75513","-0.00075"
"81.60000","8.15419","2771.92212","-0.00074"
"81.70000","8.16417","2728.74316","-0.00074"
"81.80000","8.17409","2681.08594","-0.00074"
"81.90000","8.18409","2626.27661","-0.00074"
"82.00000","8.19416","2562.19971","-0.00074"
"82.08100","8.20230","1520.46130","-0.00068"