File: archive/undergrad/433/Tensile Test/Specimen_RawData_1.csv
Time,Extension,Load,Strain Gage18
(s),(mm),(N),(mm/mm)
"0.00000","-0.03125","72.86613","-0.00001"
"0.10000","-0.02804","93.89183","0.00002"
"0.20000","-0.01711","168.87163","0.00013"
"0.30000","-0.00677","238.31993","0.00022"
"0.40000","0.00328","304.98862","0.00031"
"0.50000","0.01335","370.96722","0.00039"
"0.60000","0.02343","435.46817","0.00047"
"0.70000","0.03339","497.45581","0.00055"
"0.80000","0.04339","558.74854","0.00062"
"0.90000","0.05332","618.09619","0.00069"
"1.00000","0.06332","676.50238","0.00076"
"1.10000","0.07338","734.21002","0.00084"
"1.20000","0.08337","790.36768","0.00090"
"1.30000","0.09332","845.93054","0.00097"
"1.40000","0.10332","901.15930","0.00103"
"1.50000","0.11334","956.27820","0.00110"
"1.60000","0.12345","1011.56140","0.00116"
"1.70000","0.13348","1066.06458","0.00123"
"1.80000","0.14342","1119.68164","0.00129"
"1.90000","0.15332","1172.80042","0.00136"
"2.00000","0.16326","1226.08911","0.00142"
"2.10000","0.17330","1279.49902","0.00148"
"2.20000","0.18338","1333.20630","0.00155"
"2.30000","0.19346","1386.06982","0.00161"
"2.40000","0.20351","1438.74036","0.00167"
"2.50000","0.21340","1489.92151","0.00173"
"2.60000","0.22332","1541.17700","0.00180"
"2.70000","0.23321","1591.64075","0.00186"
"2.80000","0.24330","1642.68408","0.00192"
"2.90000","0.25339","1693.20801","0.00198"
"3.00000","0.26350","1743.47217","0.00205"
"3.10000","0.27344","1792.02539","0.00211"
"3.20000","0.28342","1840.14539","0.00217"
"3.30000","0.29330","1887.21851","0.00223"
"3.40000","0.30334","1934.58252","0.00230"
"3.50000","0.31336","1980.95312","0.00236"
"3.60000","0.32339","2026.66992","0.00242"
"3.70000","0.33337","2070.92334","0.00249"
"3.80000","0.34340","2114.50757","0.00255"
"3.90000","0.35338","2155.62720","0.00262"
"4.00000","0.36342","2194.56079","0.00269"
"4.10000","0.37345","2230.14575","0.00276"
"4.20000","0.38338","2261.36475","0.00283"
"4.30000","0.39337","2288.50781","0.00291"
"4.40000","0.40332","2312.00562","0.00299"
"4.50000","0.41332","2331.06714","0.00308"
"4.60000","0.42340","2347.11572","0.00318"
"4.70000","0.43348","2359.99365","0.00328"
"4.80000","0.44349","2369.81055","0.00338"
"4.90000","0.45341","2377.85278","0.00348"
"5.00000","0.46335","2384.83423","0.00357"
"5.10000","0.47318","2390.41309","0.00367"
"5.20000","0.48332","2395.54297","0.00376"
"5.30000","0.49344","2400.75586","0.00385"
"5.40000","0.50354","2405.63306","0.00394"
"5.50000","0.51342","2410.48755","0.00403"
"5.60000","0.52342","2415.28174","0.00414"
"5.70000","0.53328","2417.85010","0.00427"
"5.80000","0.54331","2420.10645","0.00440"
"5.90000","0.55339","2420.70850","0.00454"
"6.00000","0.56341","2417.29419","0.00462"
"6.10000","0.57347","2421.95776","0.00470"
"6.20000","0.58342","2425.41455","0.00475"
"6.30000","0.59334","2424.86816","0.00479"
"6.40000","0.60336","2426.05591","0.00482"
"6.50000","0.61342","2427.91772","0.00484"
"6.60000","0.62339","2428.84644","0.00487"
"6.70000","0.63335","2429.22437","0.00489"
"6.80000","0.64334","2425.48560","0.00490"
"6.90000","0.65333","2434.86401","0.00492"
"7.00000","0.66343","2452.54077","0.00497"
"7.10000","0.67343","2463.65454","0.00503"
"7.20000","0.68348","2440.48560","0.00502"
"7.30000","0.69339","2436.98291","0.00503"
"7.40000","0.70336","2436.19873","0.00504"
"7.50000","0.71318","2436.47852","0.00505"
"7.60000","0.72334","2438.09351","0.00507"
"7.70000","0.73347","2439.50757","0.00508"
"7.80000","0.74353","2440.77588","0.00509"
"7.90000","0.75343","2442.88110","0.00510"
"8.00000","0.76335","2444.44873","0.00511"
"8.10000","0.77324","2445.78467","0.00513"
"8.20000","0.78326","2449.23950","0.00514"
"8.30000","0.79336","2452.15820","0.00515"
"8.40000","0.80344","2452.82178","0.00516"
"8.50000","0.81352","2449.30151","0.00517"
"8.60000","0.82344","2447.84253","0.00517"
"8.70000","0.83333","2451.59521","0.00518"
"8.80000","0.84336","2451.60938","0.00519"
"8.90000","0.85336","2444.52905","0.00371"
"9.00000","0.86343","2443.45215","0.00107"
"9.10000","0.87336","2439.46997","0.00011"
"9.20000","0.88341","2449.77563","-0.00006"
"9.30000","0.89336","2451.62671","-0.00015"
"9.40000","0.90336","2453.86987","-0.00016"
"9.50000","0.91338","2454.95337","-0.00017"
"9.60000","0.92345","2455.82007","-0.00017"
"9.70000","0.93340","2456.80273","-0.00018"
"9.80000","0.94334","2456.19751","-0.00018"
"9.90000","0.95323","2461.34448","-0.00018"
"10.00000","0.96334","2479.24438","-0.00019"
"10.10000","0.97351","2481.72070","-0.00019"
"10.20000","0.98351","2500.44141","-0.00019"
"10.30000","0.99344","2513.90869","-0.00019"
"10.40000","1.00331","2509.04858","-0.00020"
"10.50000","1.01325","2513.14331","-0.00020"
"10.60000","1.02328","2533.79492","-0.00020"
"10.70000","1.03341","2533.74854","-0.00020"
"10.80000","1.04351","2530.66724","-0.00020"
"10.90000","1.05353","2534.62378","-0.00020"
"11.00000","1.06341","2539.75684","-0.00020"
"11.10000","1.07329","2536.77637","-0.00020"
"11.20000","1.08331","2539.06299","-0.00021"
"11.30000","1.09332","2543.45386","-0.00020"
"11.40000","1.10344","2540.14771","-0.00021"
"11.50000","1.11344","2540.90576","-0.00021"
"11.60000","1.12341","2536.51221","-0.00021"
"11.70000","1.13335","2541.95410","-0.00021"
"11.80000","1.14332","2538.87817","-0.00021"
"11.90000","1.15338","2576.70630","-0.00020"
"12.00000","1.16347","2549.35425","-0.00022"
"12.10000","1.17340","2543.09717","-0.00022"
"12.20000","1.18332","2539.28247","-0.00022"
"12.30000","1.19331","2543.67065","-0.00022"
"12.40000","1.20339","2546.89868","-0.00022"
"12.50000","1.21346","2551.54175","-0.00021"
"12.60000","1.22350","2555.54224","-0.00021"
"12.70000","1.23339","2556.36548","-0.00021"
"12.80000","1.24331","2560.61060","-0.00021"
"12.90000","1.25324","2560.75439","-0.00021"
"13.00000","1.26333","2560.87939","-0.00021"
"13.10000","1.27340","2563.80273","-0.00021"
"13.20000","1.28359","2559.98389","-0.00022"
"13.30000","1.29356","2563.58936","-0.00022"
"13.40000","1.30337","2566.32764","-0.00022"
"13.50000","1.31328","2569.64893","-0.00022"
"13.60000","1.32330","2573.88818","-0.00022"
"13.70000","1.33332","2570.00391","-0.00022"
"13.80000","1.34347","2572.13989","-0.00022"
"13.90000","1.35349","2565.42993","-0.00022"
"14.00000","1.36340","2566.96094","-0.00022"
"14.10000","1.37338","2573.40308","-0.00022"
"14.20000","1.38323","2572.86572","-0.00022"
"14.30000","1.39331","2570.25464","-0.00022"
"14.40000","1.40341","2566.79956","-0.00021"
"14.50000","1.41344","2566.62476","-0.00020"
"14.60000","1.42334","2566.87354","-0.00019"
"14.70000","1.43336","2564.56787","-0.00020"
"14.80000","1.44341","2568.53394","-0.00019"
"14.90000","1.45341","2568.80029","-0.00020"
"15.00000","1.46349","2569.27563","-0.00021"
"15.10000","1.47341","2572.37817","-0.00022"
"15.20000","1.48330","2575.87158","-0.00022"
"15.30000","1.49330","2576.23730","-0.00022"
"15.40000","1.50334","2578.06543","-0.00022"
"15.50000","1.51345","2580.14331","-0.00023"
"15.60000","1.52354","2580.28003","-0.00023"
"15.70000","1.53350","2582.99365","-0.00023"
"15.80000","1.54329","2595.38306","-0.00023"
"15.90000","1.55327","2590.50708","-0.00023"
"16.00000","1.56328","2608.84912","-0.00023"
"16.10000","1.57335","2611.63232","-0.00023"
"16.20000","1.58351","2604.89380","-0.00024"
"16.30000","1.59352","2615.03564","-0.00024"
"16.40000","1.60336","2619.05908","-0.00025"
"16.50000","1.61332","2626.49268","-0.00024"
"16.60000","1.62332","2618.86548","-0.00025"
"16.70000","1.63331","2666.90039","-0.00023"
"16.80000","1.64346","2634.95996","-0.00026"
"16.90000","1.65345","2660.40259","-0.00024"
"17.00000","1.66334","2660.79614","-0.00024"
"17.10000","1.67335","2667.38403","-0.00024"
"17.20000","1.68341","2669.70850","-0.00024"
"17.30000","1.69339","2668.63818","-0.00024"
"17.40000","1.70343","2677.03076","-0.00024"
"17.50000","1.71342","2666.74561","-0.00025"
"17.60000","1.72327","2663.15723","-0.00025"
"17.70000","1.73330","2660.66333","-0.00025"
"17.80000","1.74341","2668.04346","-0.00025"
"17.90000","1.75346","2668.23096","-0.00025"
"18.00000","1.76351","2670.95630","-0.00025"
"18.10000","1.77350","2672.61426","-0.00025"
"18.20000","1.78332","2671.55127","-0.00025"
"18.30000","1.79325","2667.57227","-0.00025"
"18.40000","1.80330","2677.57471","-0.00025"
"18.50000","1.81339","2685.54639","-0.00024"
"18.60000","1.82357","2664.68311","-0.00025"
"18.70000","1.83353","2705.86816","-0.00024"
"18.80000","1.84334","2723.75415","-0.00025"
"18.90000","1.85331","2686.87012","-0.00024"
"19.00000","1.86332","2696.68726","-0.00024"
"19.10000","1.87334","2702.64111","-0.00023"
"19.20000","1.88345","2685.25464","-0.00021"
"19.30000","1.89350","2689.64624","-0.00020"
"19.40000","1.90341","2689.97803","-0.00020"
"19.50000","1.91338","2691.41504","-0.00020"
"19.60000","1.92333","2700.47046","-0.00021"
"19.70000","1.93336","2709.31421","-0.00021"
"19.80000","1.94342","2708.41162","-0.00021"
"19.90000","1.95345","2705.11963","-0.00022"
"20.00000","1.96331","2701.47363","-0.00023"
"20.10000","1.97336","2696.22778","-0.00023"
"20.20000","1.98342","2690.96094","-0.00024"
"20.30000","1.99343","2693.82812","-0.00024"
"20.40000","2.00346","2695.38330","-0.00024"
"20.50000","2.01346","2695.37793","-0.00024"
"20.60000","2.02332","2702.68311","-0.00024"
"20.70000","2.03324","2707.56567","-0.00024"
"20.80000","2.04335","2707.93091","-0.00024"
"20.90000","2.05342","2703.96777","-0.00024"
"21.00000","2.06356","2695.64990","-0.00024"
"21.10000","2.07351","2697.40601","-0.00024"
"21.20000","2.08333","2697.62280","-0.00024"
"21.30000","2.09328","2696.90967","-0.00024"
"21.40000","2.10333","2692.59375","-0.00024"
"21.50000","2.11333","2690.24292","-0.00025"
"21.60000","2.12343","2689.23047","-0.00024"
"21.70000","2.13354","2689.46289","-0.00025"
"21.80000","2.14343","2689.07251","-0.00024"
"21.90000","2.15336","2691.35083","-0.00025"
"22.00000","2.16330","2696.13184","-0.00024"
"22.10000","2.17335","2696.94116","-0.00024"
"22.20000","2.18339","2687.14160","-0.00025"
"22.30000","2.19348","2681.59888","-0.00025"
"22.40000","2.20336","2694.42944","-0.00025"
"22.50000","2.21338","2696.92310","-0.00025"
"22.60000","2.22341","2711.95703","-0.00025"
"22.70000","2.23337","2737.66162","-0.00024"
"22.80000","2.24341","2746.68481","-0.00025"
"22.90000","2.25342","2703.81226","-0.00025"
"23.00000","2.26337","2699.60840","-0.00026"
"23.10000","2.27329","2699.08618","-0.00026"
"23.20000","2.28335","2698.74658","-0.00026"
"23.30000","2.29347","2700.12109","-0.00026"
"23.40000","2.30349","2713.87793","-0.00025"
"23.50000","2.31348","2718.50293","-0.00025"
"23.60000","2.32331","2739.58765","-0.00025"
"23.70000","2.33329","2748.54834","-0.00025"
"23.80000","2.34332","2708.89136","-0.00026"
"23.90000","2.35339","2713.21704","-0.00026"
"24.00000","2.36343","2749.30835","-0.00025"
"24.10000","2.37352","2766.35449","-0.00025"
"24.20000","2.38342","2761.50732","-0.00025"
"24.30000","2.39332","2784.79395","-0.00025"
"24.40000","2.40327","2769.78735","-0.00025"
"24.50000","2.41331","2760.92188","-0.00026"
"24.60000","2.42340","2764.75977","-0.00026"
"24.70000","2.43347","2801.64404","-0.00024"
"24.80000","2.44346","2775.64697","-0.00026"
"24.90000","2.45338","2797.47144","-0.00025"
"25.00000","2.46336","2811.74634","-0.00025"
"25.10000","2.47338","2770.59229","-0.00027"
"25.20000","2.48339","2790.71655","-0.00026"
"25.30000","2.49341","2801.24170","-0.00025"
"25.40000","2.50337","2792.45947","-0.00026"
"25.50000","2.51338","2784.67993","-0.00026"
"25.60000","2.52334","2784.74463","-0.00026"
"25.70000","2.53346","2799.65430","-0.00026"
"25.80000","2.54344","2818.86133","-0.00025"
"25.90000","2.55345","2795.33252","-0.00026"
"26.00000","2.56332","2791.17090","-0.00026"
"26.10000","2.57331","2826.17432","-0.00025"
"26.20000","2.58332","2809.21387","-0.00026"
"26.30000","2.59340","2789.69189","-0.00027"
"26.40000","2.60349","2801.05859","-0.00026"
"26.50000","2.61349","2823.28345","-0.00025"
"26.60000","2.62345","2800.46948","-0.00026"
"26.70000","2.63334","2787.74170","-0.00027"
"26.80000","2.64322","2809.05249","-0.00026"
"26.90000","2.65332","2814.02588","-0.00026"
"27.00000","2.66343","2803.20093","-0.00026"
"27.10000","2.67351","2792.42285","-0.00027"
"27.20000","2.68346","2818.55420","-0.00026"
"27.30000","2.69340","2805.09766","-0.00026"
"27.40000","2.70327","2803.01221","-0.00027"
"27.50000","2.71335","2828.48877","-0.00026"
"27.60000","2.72336","2813.55347","-0.00025"
"27.70000","2.73337","2808.98511","-0.00020"
"27.80000","2.74343","2797.06299","-0.00016"
"27.90000","2.75341","2832.60059","-0.00016"
"28.00000","2.76338","2828.96533","-0.00016"
"28.10000","2.77340","2807.33862","-0.00016"
"28.20000","2.78343","2805.64844","-0.00018"
"28.30000","2.79337","2836.93994","-0.00018"
"28.40000","2.80338","2849.47314","-0.00018"
"28.50000","2.81332","2804.30884","-0.00017"
"28.60000","2.82332","2848.61499","-0.00017"
"28.70000","2.83341","2834.93311","-0.00017"
"28.80000","2.84349","2812.84814","-0.00017"
"28.90000","2.85346","2828.95776","-0.00018"
"29.00000","2.86343","2846.14282","-0.00017"
"29.10000","2.87332","2825.83130","-0.00018"
"29.20000","2.88318","2816.02466","-0.00020"
"29.30000","2.89335","2848.80835","-0.00018"
"29.40000","2.90347","2838.22583","-0.00019"
"29.50000","2.91353","2824.84424","-0.00019"
"29.60000","2.92346","2824.37207","-0.00020"
"29.70000","2.93338","2839.58496","-0.00019"
"29.80000","2.94327","2843.08203","-0.00019"
"29.90000","2.95329","2840.73340","-0.00019"
"30.00000","2.96336","2826.06738","-0.00020"
"30.10000","2.97345","2816.44580","-0.00021"
"30.20000","2.98347","2856.65552","-0.00019"
"30.30000","2.99340","2832.85376","-0.00020"
"30.40000","3.00332","2812.67773","-0.00021"
"30.50000","3.01335","2819.64038","-0.00021"
"30.60000","3.02338","2844.26025","-0.00019"
"30.70000","3.03343","2833.10815","-0.00020"
"30.80000","3.04338","2812.92651","-0.00021"
"30.90000","3.05336","2820.85400","-0.00021"
"31.00000","3.06334","2841.03735","-0.00020"
"31.10000","3.07340","2832.54761","-0.00020"
"31.20000","3.08344","2823.31592","-0.00020"
"31.30000","3.09346","2811.76929","-0.00021"
"31.40000","3.10340","2813.36133","-0.00021"
"31.50000","3.11333","2842.19214","-0.00019"
"31.60000","3.12321","2829.65796","-0.00020"
"31.70000","3.13336","2809.91187","-0.00021"
"31.80000","3.14345","2825.00342","-0.00021"
"31.90000","3.15351","2842.88379","-0.00020"
"32.00000","3.16345","2823.04688","-0.00020"
"32.10000","3.17333","2821.41895","-0.00020"
"32.20000","3.18325","2817.35938","-0.00020"
"32.30000","3.19324","2818.43726","-0.00021"
"32.40000","3.20339","2837.26440","-0.00020"
"32.50000","3.21349","2847.61426","-0.00020"
"32.60000","3.22356","2830.71802","-0.00021"
"32.70000","3.23344","2819.74854","-0.00021"
"32.80000","3.24328","2837.29199","-0.00021"
"32.90000","3.25332","2845.78540","-0.00020"
"33.00000","3.26333","2827.96875","-0.00021"
"33.10000","3.27337","2828.29004","-0.00021"
"33.20000","3.28341","2854.69092","-0.00020"
"33.30000","3.29340","2843.46875","-0.00020"
"33.40000","3.30339","2837.72998","-0.00021"
"33.50000","3.31334","2878.54004","-0.00019"
"33.60000","3.32337","2881.66821","-0.00020"
"33.70000","3.33345","2847.48486","-0.00021"
"33.80000","3.34340","2890.06177","-0.00020"
"33.90000","3.35330","2878.97095","-0.00020"
"34.00000","3.36329","2892.26392","-0.00020"
"34.10000","3.37340","2860.89990","-0.00021"
"34.20000","3.38348","2901.16919","-0.00020"
"34.30000","3.39350","2888.50244","-0.00021"
"34.40000","3.40341","2913.84131","-0.00020"
"34.50000","3.41329","2893.51929","-0.00021"
"34.60000","3.42324","2916.60547","-0.00020"
"34.70000","3.43331","2913.06641","-0.00021"
"34.80000","3.44340","2924.61133","-0.00020"
"34.90000","3.45356","2888.46094","-0.00022"
"35.00000","3.46353","2882.29541","-0.00022"
"35.10000","3.47337","2917.68604","-0.00020"
"35.20000","3.48325","2923.86426","-0.00021"
"35.30000","3.49331","2953.42603","-0.00020"
"35.40000","3.50333","2921.55249","-0.00021"
"35.50000","3.51347","2934.94653","-0.00021"
"35.60000","3.52348","2944.61426","-0.00020"
"35.70000","3.53343","2918.16260","-0.00021"
"35.80000","3.54333","2969.28394","-0.00020"
"35.90000","3.55334","2903.06348","-0.00021"
"36.00000","3.56336","2957.32349","-0.00020"
"36.10000","3.57344","2922.52295","-0.00021"
"36.20000","3.58340","2908.97314","-0.00021"
"36.30000","3.59331","2943.22900","-0.00020"
"36.40000","3.60336","2918.69653","-0.00018"
"36.50000","3.61340","2926.46606","-0.00015"
"36.60000","3.62344","2946.13696","-0.00015"
"36.70000","3.63350","2915.04102","-0.00013"
"36.80000","3.64337","2960.97949","-0.00014"
"36.90000","3.65330","2929.11841","-0.00013"
"37.00000","3.66325","2920.66187","-0.00012"
"37.10000","3.67334","2968.47046","-0.00014"
"37.20000","3.68344","2943.97266","-0.00013"
"37.30000","3.69356","2929.27661","-0.00013"
"37.40000","3.70352","2965.13574","-0.00014"
"37.50000","3.71336","2924.87134","-0.00014"
"37.60000","3.72322","2973.55103","-0.00015"
"37.70000","3.73329","2936.09375","-0.00015"
"37.80000","3.74332","2962.42456","-0.00016"
"37.90000","3.75350","2953.89453","-0.00016"
"38.00000","3.76354","2928.48535","-0.00017"
"38.10000","3.77337","2967.65991","-0.00016"
"38.20000","3.78335","2951.42651","-0.00016"
"38.30000","3.79333","2924.91235","-0.00017"
"38.40000","3.80335","2894.63013","-0.00018"
"38.50000","3.81340","2940.33374","-0.00017"
"38.60000","3.82343","2912.90869","-0.00018"
"38.70000","3.83338","2946.22656","-0.00017"
"38.80000","3.84337","2915.41504","-0.00018"
"38.90000","3.85339","2936.92676","-0.00018"
"39.00000","3.86338","2936.15869","-0.00017"
"39.10000","3.87349","2914.49097","-0.00018"
"39.20000","3.88340","2923.09839","-0.00018"
"39.30000","3.89327","2953.25342","-0.00017"
"39.40000","3.90327","2926.11279","-0.00018"
"39.50000","3.91341","2924.57397","-0.00019"
"39.60000","3.92346","2947.11646","-0.00018"
"39.70000","3.93353","2910.30566","-0.00019"
"39.80000","3.94349","2956.00562","-0.00018"
"39.90000","3.95333","2914.90918","-0.00019"
"40.00000","3.96326","2955.33496","-0.00018"
"40.10000","3.97329","2933.15137","-0.00018"
"40.20000","3.98336","2909.73242","-0.00019"
"40.30000","3.99352","2934.66577","-0.00019"
"40.40000","4.00354","2930.07397","-0.00019"
"40.50000","4.01336","2907.96118","-0.00019"
"40.60000","4.02329","2905.27344","-0.00019"
"40.70000","4.03332","2923.64722","-0.00019"
"40.80000","4.04331","2928.14404","-0.00018"
"40.90000","4.05345","2905.67236","-0.00019"
"41.00000","4.06349","2899.25610","-0.00019"
"41.10000","4.07342","2935.80176","-0.00018"
"41.20000","4.08336","2926.46143","-0.00019"
"41.30000","4.09335","2951.85254","-0.00018"
"41.40000","4.10338","2954.40771","-0.00018"
"41.50000","4.11340","2964.96362","-0.00019"
"41.60000","4.12346","2936.78003","-0.00019"
"41.70000","4.13328","2949.26343","-0.00019"
"41.80000","4.14336","2957.56299","-0.00018"
"41.90000","4.15342","2970.28735","-0.00018"
"42.00000","4.16347","2945.75171","-0.00018"
"42.10000","4.17343","2952.70459","-0.00019"
"42.20000","4.18348","2965.22168","-0.00018"
"42.30000","4.19331","2930.94946","-0.00019"
"42.40000","4.20325","2984.11743","-0.00018"
"42.50000","4.21335","2946.10864","-0.00019"
"42.60000","4.22340","2943.32666","-0.00019"
"42.70000","4.23358","2983.94189","-0.00018"
"42.80000","4.24353","2947.95361","-0.00019"
"42.90000","4.25336","2959.83691","-0.00018"
"43.00000","4.26329","2926.15967","-0.00019"
"43.10000","4.27330","2960.11035","-0.00018"
"43.20000","4.28334","2951.82642","-0.00018"
"43.30000","4.29345","2925.59399","-0.00019"
"43.40000","4.30353","2975.88867","-0.00018"
"43.50000","4.31342","2948.61450","-0.00018"
"43.60000","4.32336","2933.88770","-0.00019"
"43.70000","4.33330","2965.95068","-0.00018"
"43.80000","4.34335","2932.82495","-0.00019"
"43.90000","4.35336","2971.03247","-0.00018"
"44.00000","4.36347","2953.57935","-0.00018"
"44.10000","4.37339","2923.86597","-0.00019"
"44.20000","4.38336","2974.07300","-0.00018"
"44.30000","4.39344","2946.47241","-0.00018"
"44.40000","4.40339","2931.55469","-0.00019"
"44.50000","4.41343","2972.15942","-0.00018"
"44.60000","4.42343","2947.23389","-0.00019"
"44.70000","4.43335","2932.19653","-0.00019"
"44.80000","4.44325","2965.57886","-0.00018"
"44.90000","4.45341","2933.62476","-0.00019"
"45.00000","4.46341","2943.24561","-0.00019"
"45.10000","4.47355","2959.55957","-0.00018"
"45.20000","4.48346","2927.42505","-0.00019"
"45.30000","4.49332","2975.24268","-0.00018"
"45.40000","4.50334","2948.68604","-0.00019"
"45.50000","4.51331","2929.98413","-0.00020"
"45.60000","4.52336","2971.33447","-0.00018"
"45.70000","4.53345","2946.49634","-0.00019"
"45.80000","4.54357","2934.40747","-0.00020"
"45.90000","4.55343","2974.18677","-0.00018"
"46.00000","4.56332","2946.75537","-0.00019"
"46.10000","4.57325","2944.90430","-0.00019"
"46.20000","4.58333","2965.94360","-0.00019"
"46.30000","4.59336","2933.51245","-0.00020"
"46.40000","4.60344","2929.06274","-0.00020"
"46.50000","4.61339","2959.69165","-0.00019"
"46.60000","4.62341","2954.98047","-0.00019"
"46.70000","4.63337","3000.67505","-0.00018"
"46.80000","4.64337","3006.14526","-0.00019"
"46.90000","4.65342","2989.24268","-0.00019"
"47.00000","4.66338","3015.20630","-0.00019"
"47.10000","4.67337","3013.73730","-0.00019"
"47.20000","4.68339","2972.81787","-0.00020"
"47.30000","4.69338","3022.01929","-0.00018"
"47.40000","4.70347","2979.71777","-0.00020"
"47.50000","4.71343","3027.80566","-0.00018"
"47.60000","4.72345","2993.28540","-0.00019"
"47.70000","4.73331","3031.07886","-0.00019"
"47.80000","4.74330","3009.02271","-0.00019"
"47.90000","4.75328","3001.90527","-0.00020"
"48.00000","4.76339","3025.76123","-0.00019"
"48.10000","4.77350","2991.00708","-0.00020"
"48.20000","4.78352","3039.51685","-0.00018"
"48.30000","4.79342","3001.51660","-0.00020"
"48.40000","4.80330","3051.00635","-0.00018"
"48.50000","4.81325","3014.20630","-0.00019"
"48.60000","4.82331","3036.08423","-0.00019"
"48.70000","4.83342","3028.52979","-0.00019"
"48.80000","4.84350","3002.76758","-0.00020"
"48.90000","4.85345","3040.44922","-0.00019"
"49.00000","4.86342","2999.35693","-0.00020"
"49.10000","4.87329","3050.70337","-0.00018"
"49.20000","4.88329","3009.71924","-0.00020"
"49.30000","4.89337","3056.50684","-0.00018"
"49.40000","4.90342","3023.76367","-0.00019"
"49.50000","4.91341","3025.44263","-0.00019"
"49.60000","4.92340","3036.61865","-0.00019"
"49.70000","4.93337","3004.31567","-0.00020"
"49.80000","4.94339","3046.60327","-0.00018"
"49.90000","4.95347","3004.40649","-0.00020"
"50.00000","4.96340","3056.36157","-0.00018"
"50.10000","4.97340","3012.79688","-0.00020"
"50.20000","4.98329","3064.04272","-0.00018"
"50.30000","4.99338","3021.09302","-0.00019"
"50.40000","5.00339","3062.67896","-0.00018"
"50.50000","5.01348","3025.77783","-0.00019"
"50.60000","5.02345","3059.86548","-0.00018"
"50.70000","5.03343","3023.23291","-0.00019"
"50.80000","5.04333","3056.01733","-0.00018"
"50.90000","5.05323","3030.41699","-0.00019"
"51.00000","5.06329","3026.05493","-0.00019"
"51.10000","5.07345","3016.96191","-0.00020"
"51.20000","5.08355","3048.31616","-0.00018"
"51.30000","5.09347","3009.82642","-0.00020"
"51.40000","5.10338","3060.37061","-0.00018"
"51.50000","5.11328","2985.30835","-0.00020"
"51.60000","5.12330","3036.48706","-0.00018"
"51.70000","5.13340","3006.97607","-0.00019"
"51.80000","5.14343","3020.58130","-0.00019"
"51.90000","5.15345","3036.66919","-0.00018"
"52.00000","5.16345","3017.77661","-0.00019"
"52.10000","5.17336","3064.03467","-0.00018"
"52.20000","5.18336","3039.08545","-0.00019"
"52.30000","5.19338","3044.79443","-0.00019"
"52.40000","5.20338","3065.96265","-0.00018"
"52.50000","5.21340","3054.37036","-0.00019"
"52.60000","5.22335","3011.70239","-0.00020"
"52.70000","5.23337","3030.39673","-0.00019"
"52.80000","5.24337","3011.80078","-0.00020"
"52.90000","5.25343","3036.59448","-0.00018"
"53.00000","5.26348","2998.61011","-0.00020"
"53.10000","5.27339","3044.60864","-0.00018"
"53.20000","5.28332","3002.36353","-0.00020"
"53.30000","5.29318","3051.55103","-0.00018"
"53.40000","5.30339","3005.11841","-0.00019"
"53.50000","5.31348","3059.88867","-0.00018"
"53.60000","5.32355","3012.67139","-0.00019"
"53.70000","5.33339","3065.78418","-0.00017"
"53.80000","5.34335","3019.99048","-0.00018"
"53.90000","5.35328","3070.14307","-0.00017"
"54.00000","5.36328","3026.59863","-0.00018"
"54.10000","5.37336","3054.21484","-0.00018"
"54.20000","5.38346","3035.36816","-0.00017"
"54.30000","5.39353","3023.13037","-0.00017"
"54.40000","5.40343","3042.08154","-0.00016"
"54.50000","5.41330","3011.26196","-0.00015"
"54.60000","5.42330","3045.69824","-0.00015"
"54.70000","5.43335","3005.48193","-0.00014"
"54.80000","5.44343","3047.16724","-0.00014"
"54.90000","5.45342","2999.64331","-0.00013"
"55.00000","5.46338","3052.19116","-0.00014"
"55.10000","5.47336","3003.03003","-0.00013"
"55.20000","5.48337","3057.53394","-0.00014"
"55.30000","5.49341","3008.24023","-0.00012"
"55.40000","5.50343","3062.80786","-0.00013"
"55.50000","5.51342","3015.62354","-0.00012"
"55.60000","5.52332","3064.43506","-0.00013"
"55.70000","5.53327","3023.02539","-0.00012"
"55.80000","5.54338","3044.17261","-0.00012"
"55.90000","5.55349","3033.13672","-0.00012"
"56.00000","5.56350","3025.09521","-0.00011"
"56.10000","5.57342","3039.40601","-0.00012"
"56.20000","5.58328","3035.30737","-0.00012"
"56.30000","5.59325","3029.87256","-0.00012"
"56.40000","5.60329","2984.76099","-0.00013"
"56.50000","5.61338","3039.95947","-0.00013"
"56.60000","5.62353","3007.53906","-0.00014"
"56.70000","5.63353","3041.51831","-0.00013"
"56.80000","5.64339","3009.62549","-0.00014"
"56.90000","5.65327","3046.06689","-0.00013"
"57.00000","5.66330","3001.91504","-0.00013"
"57.10000","5.67331","3052.39185","-0.00013"
"57.20000","5.68348","3006.68921","-0.00011"
"57.30000","5.69340","3060.83081","-0.00011"
"57.40000","5.70344","3010.80298","-0.00010"
"57.50000","5.71337","3064.31714","-0.00011"
"57.60000","5.72333","3012.93335","-0.00009"
"57.70000","5.73331","3064.88965","-0.00010"
"57.80000","5.74344","3022.78809","-0.00009"
"57.90000","5.75344","3059.66113","-0.00010"
"58.00000","5.76334","3014.58521","-0.00009"
"58.10000","5.77331","3061.56396","-0.00010"
"58.20000","5.78337","3025.85571","-0.00008"
"58.30000","5.79347","3060.10352","-0.00010"
"58.40000","5.80347","3062.56738","-0.00009"
"58.50000","5.81344","3052.05444","-0.00009"
"58.60000","5.82328","3011.09839","-0.00010"
"58.70000","5.83326","3054.64087","-0.00010"
"58.80000","5.84336","3005.74951","-0.00011"
"58.90000","5.85341","3055.41187","-0.00011"
"59.00000","5.86358","3026.53320","-0.00011"
"59.10000","5.87349","3039.63647","-0.00011"
"59.20000","5.88335","3035.05957","-0.00011"
"59.30000","5.89327","3005.34644","-0.00012"
"59.40000","5.90330","3047.27954","-0.00012"
"59.50000","5.91333","3004.51611","-0.00012"
"59.60000","5.92350","3059.25610","-0.00012"
"59.70000","5.93353","3013.82373","-0.00012"
"59.80000","5.94336","3066.14478","-0.00012"
"59.90000","5.95335","3019.82788","-0.00012"
"60.00000","5.96329","3060.99829","-0.00012"
"60.10000","5.97337","3031.02222","-0.00012"
"60.20000","5.98345","3027.80493","-0.00012"
"60.30000","5.99341","3043.24365","-0.00012"
"60.40000","6.00336","3009.47681","-0.00013"
"60.50000","6.01336","3052.95068","-0.00012"
"60.60000","6.02342","3009.79956","-0.00013"
"60.70000","6.03340","3049.94238","-0.00013"
"60.80000","6.04349","3005.47778","-0.00013"
"60.90000","6.05338","3052.10010","-0.00013"
"61.00000","6.06331","3006.33252","-0.00013"
"61.10000","6.07324","3059.86230","-0.00013"
"61.20000","6.08344","3015.02686","-0.00013"
"61.30000","6.09341","3066.59497","-0.00013"
"61.40000","6.10359","3019.10107","-0.00013"
"61.50000","6.11349","3019.44604","-0.00013"
"61.60000","6.12333","3029.25586","-0.00013"
"61.70000","6.13328","2996.37109","-0.00013"
"61.80000","6.14328","3034.87354","-0.00013"
"61.90000","6.15338","2990.20361","-0.00013"
"62.00000","6.16351","3045.14307","-0.00013"
"62.10000","6.17353","2999.95752","-0.00013"
"62.20000","6.18335","3052.35620","-0.00013"
"62.30000","6.19335","3007.83936","-0.00013"
"62.40000","6.20325","3041.09497","-0.00013"
"62.50000","6.21331","3018.39087","-0.00013"
"62.60000","6.22339","3026.12183","-0.00013"
"62.70000","6.23346","3025.45410","-0.00013"
"62.80000","6.24340","3039.52930","-0.00013"
"62.90000","6.25340","3017.48828","-0.00014"
"63.00000","6.26340","3062.43408","-0.00013"
"63.10000","6.27337","3047.74829","-0.00013"
"63.20000","6.28345","3010.96094","-0.00014"
"63.30000","6.29341","3060.65259","-0.00013"
"63.40000","6.30332","3013.60059","-0.00014"
"63.50000","6.31332","3065.75513","-0.00013"
"63.60000","6.32343","3029.42090","-0.00014"
"63.70000","6.33342","3057.11841","-0.00013"
"63.80000","6.34349","3025.95288","-0.00013"
"63.90000","6.35348","3071.71948","-0.00013"
"64.00000","6.36329","3027.92725","-0.00013"
"64.10000","6.37324","3077.72217","-0.00013"
"64.20000","6.38329","3011.25317","-0.00013"
"64.30000","6.39341","3024.13135","-0.00013"
"64.40000","6.40351","3044.24805","-0.00012"
"64.50000","6.41350","3091.97778","-0.00012"
"64.60000","6.42336","3058.10083","-0.00013"
"64.70000","6.43327","3061.38672","-0.00013"
"64.80000","6.44334","3077.68408","-0.00012"
"64.90000","6.45335","3006.19556","-0.00013"
"65.00000","6.46344","3055.44971","-0.00012"
"65.10000","6.47350","3047.83984","-0.00012"
"65.20000","6.48340","3048.90161","-0.00012"
"65.30000","6.49333","3072.79517","-0.00012"
"65.40000","6.50334","3045.60254","-0.00012"
"65.50000","6.51334","3084.90015","-0.00012"
"65.60000","6.52343","3043.79346","-0.00012"
"65.70000","6.53343","3090.97876","-0.00011"
"65.80000","6.54333","3040.97656","-0.00012"
"65.90000","6.55337","3092.00317","-0.00011"
"66.00000","6.56344","3040.88599","-0.00011"
"66.10000","6.57342","3094.00903","-0.00011"
"66.20000","6.58346","3036.94141","-0.00011"
"66.30000","6.59344","3088.36206","-0.00011"
"66.40000","6.60331","3128.84937","-0.00011"
"66.50000","6.61330","3062.72510","-0.00011"
"66.60000","6.62334","3112.88232","-0.00010"
"66.70000","6.63345","3045.45020","-0.00011"
"66.80000","6.64354","3099.18896","-0.00010"
"66.90000","6.65348","3055.90454","-0.00010"
"67.00000","6.66333","3086.81592","-0.00010"
"67.10000","6.67326","3116.67969","-0.00010"
"67.20000","6.68333","3073.23096","-0.00010"
"67.30000","6.69334","3122.35791","-0.00010"
"67.40000","6.70348","3054.78540","-0.00010"
"67.50000","6.71354","3108.37671","-0.00010"
"67.60000","6.72343","3107.88916","-0.00010"
"67.70000","6.73336","3095.76953","-0.00010"
"67.80000","6.74329","3039.55518","-0.00010"
"67.90000","6.75333","3089.05078","-0.00009"
"68.00000","6.76340","3026.61060","-0.00010"
"68.10000","6.77347","3080.76953","-0.00009"
"68.20000","6.78339","3028.74683","-0.00010"
"68.30000","6.79341","3073.21094","-0.00009"
"68.40000","6.80338","3056.20288","-0.00010"
"68.50000","6.81336","3065.75366","-0.00009"
"68.60000","6.82341","3096.59229","-0.00009"
"68.70000","6.83342","3058.10107","-0.00009"
"68.80000","6.84336","3107.26538","-0.00009"
"68.90000","6.85332","3049.91650","-0.00009"
"69.00000","6.86338","3102.54663","-0.00009"
"69.10000","6.87347","3042.92676","-0.00009"
"69.20000","6.88349","3097.43481","-0.00009"
"69.30000","6.89346","3037.97510","-0.00009"
"69.40000","6.90330","3091.06665","-0.00009"
"69.50000","6.91331","3038.36865","-0.00009"
"69.60000","6.92330","3083.77222","-0.00009"
"69.70000","6.93336","3083.44849","-0.00009"
"69.80000","6.94344","3058.74243","-0.00010"
"69.90000","6.95357","3069.39087","-0.00009"
"70.00000","6.96340","3081.86206","-0.00010"
"70.10000","6.97335","3061.93335","-0.00009"
"70.20000","6.98322","3108.31104","-0.00009"
"70.30000","6.99333","3051.17603","-0.00009"
"70.40000","7.00341","3102.89502","-0.00010"
"70.50000","7.01351","3040.57959","-0.00010"
"70.60000","7.02343","3087.27222","-0.00010"
"70.70000","7.03339","3080.73755","-0.00010"
"70.80000","7.04337","3091.28809","-0.00010"
"70.90000","7.05333","3090.40674","-0.00010"
"71.00000","7.06339","3059.40552","-0.00010"
"71.10000","7.07338","3106.10889","-0.00010"
"71.20000","7.08342","3048.63745","-0.00010"
"71.30000","7.09338","3100.61572","-0.00010"
"71.40000","7.10339","3039.69824","-0.00010"
"71.50000","7.11343","3092.97510","-0.00010"
"71.60000","7.12342","3044.56177","-0.00010"
"71.70000","7.13343","3084.06104","-0.00010"
"71.80000","7.14333","3061.59229","-0.00010"
"71.90000","7.15330","3076.64062","-0.00010"
"72.00000","7.16331","3085.33276","-0.00010"
"72.10000","7.17340","3071.43896","-0.00010"
"72.20000","7.18348","3114.62085","-0.00010"
"72.30000","7.19352","3065.61938","-0.00010"
"72.40000","7.20340","3115.25415","-0.00010"
"72.50000","7.21332","3055.72949","-0.00010"
"72.60000","7.22318","3108.26636","-0.00010"
"72.70000","7.23333","3046.58862","-0.00010"
"72.80000","7.24343","3101.81177","-0.00010"
"72.90000","7.25354","3049.16919","-0.00010"
"73.00000","7.26348","3093.29248","-0.00010"
"73.10000","7.27338","3081.24414","-0.00010"
"73.20000","7.28330","3080.17578","-0.00010"
"73.30000","7.29332","3083.97314","-0.00010"
"73.40000","7.30335","3057.10889","-0.00010"
"73.50000","7.31342","3064.89697","-0.00010"
"73.60000","7.32344","3044.02905","-0.00010"
"73.70000","7.33343","3069.99707","-0.00009"
"73.80000","7.34334","3097.18188","-0.00009"
"73.90000","7.35339","3093.62793","-0.00010"
"74.00000","7.36340","3080.25000","-0.00009"
"74.10000","7.37342","3030.41772","-0.00009"
"74.20000","7.38335","3069.31860","-0.00009"
"74.30000","7.39331","3041.78296","-0.00009"
"74.40000","7.40337","3054.24414","-0.00009"
"74.50000","7.41337","3100.03955","-0.00009"
"74.60000","7.42350","3027.13599","-0.00009"
"74.70000","7.43344","3077.01953","-0.00009"
"74.80000","7.44344","3019.29248","-0.00009"
"74.90000","7.45333","3060.27075","-0.00009"
"75.00000","7.46319","3102.52148","-0.00009"
"75.10000","7.47335","3030.90430","-0.00009"
"75.20000","7.48345","3081.93945","-0.00008"
"75.30000","7.49356","3008.81226","-0.00009"
"75.40000","7.50345","3061.56177","-0.00008"
"75.50000","7.51334","3017.83423","-0.00009"
"75.60000","7.52324","3030.05908","-0.00008"
"75.70000","7.53330","3058.98682","-0.00008"
"75.80000","7.54338","3009.16479","-0.00008"
"75.90000","7.55341","3054.70386","-0.00008"
"76.00000","7.56352","2988.15015","-0.00008"
"76.10000","7.57342","3030.88623","-0.00008"
"76.20000","7.58334","2973.08911","-0.00008"
"76.30000","7.59333","2986.74658","-0.00008"
"76.40000","7.60339","2959.71680","-0.00008"
"76.50000","7.61340","2920.82812","-0.00007"
"76.60000","7.62341","2952.21387","-0.00007"
"76.70000","7.63336","2896.72998","-0.00007"
"76.80000","7.64337","2912.67578","-0.00007"
"76.90000","7.65337","2896.09399","-0.00007"
"77.00000","7.66342","2848.96899","-0.00007"
"77.10000","7.67347","2843.49341","-0.00007"
"77.20000","7.68339","2848.97266","-0.00007"
"77.30000","7.69334","2807.52295","-0.00007"
"77.40000","7.70323","2770.18848","-0.00007"
"77.50000","7.71341","2752.52783","-0.00007"
"77.60000","7.72350","2743.43115","-0.00007"
"77.70000","7.73355","2723.69507","-0.00007"
"77.80000","7.74343","2693.96118","-0.00007"
"77.90000","7.75333","2660.73145","-0.00007"
"78.00000","7.76326","2625.32617","-0.00006"
"78.10000","7.77329","2585.78589","-0.00006"
"78.20000","7.78338","2542.80518","-0.00006"
"78.30000","7.79353","2492.99512","-0.00006"
"78.40000","7.80358","2438.82446","-0.00006"
"78.49300","7.81267","1422.22668","-0.00007"