File: archive/undergrad/433/Tensile Test/Specimen_RawData_10.csv
Time,Extension,Load,Strain Gage18
(s),(mm),(N),(mm/mm)
"0.00000","0.00000","242.33884","0.00028"
"0.10000","0.00318","264.02509","0.00030"
"0.20000","0.01386","339.16229","0.00038"
"0.30000","0.02424","409.25098","0.00045"
"0.40000","0.03430","475.28772","0.00052"
"0.50000","0.04434","538.44385","0.00059"
"0.60000","0.05441","601.48846","0.00065"
"0.70000","0.06436","663.13879","0.00072"
"0.80000","0.07435","724.07935","0.00078"
"0.90000","0.08432","782.80328","0.00084"
"1.00000","0.09436","840.24927","0.00090"
"1.10000","0.10439","897.79364","0.00096"
"1.20000","0.11443","954.73688","0.00102"
"1.30000","0.12438","1011.07361","0.00108"
"1.40000","0.13428","1066.73584","0.00113"
"1.50000","0.14424","1122.43835","0.00119"
"1.60000","0.15437","1179.22375","0.00125"
"1.70000","0.16448","1235.54138","0.00131"
"1.80000","0.17449","1290.90857","0.00137"
"1.90000","0.18439","1345.59741","0.00142"
"2.00000","0.19431","1400.53381","0.00148"
"2.10000","0.20422","1455.21606","0.00154"
"2.20000","0.21425","1510.26807","0.00159"
"2.30000","0.22436","1565.79504","0.00165"
"2.40000","0.23452","1621.15784","0.00171"
"2.50000","0.24449","1675.57971","0.00177"
"2.60000","0.25437","1729.05103","0.00182"
"2.70000","0.26425","1782.30884","0.00188"
"2.80000","0.27428","1836.02051","0.00194"
"2.90000","0.28435","1889.83105","0.00199"
"3.00000","0.29444","1943.07678","0.00205"
"3.10000","0.30445","1995.64124","0.00211"
"3.20000","0.31437","2047.17896","0.00217"
"3.30000","0.32437","2098.65820","0.00222"
"3.40000","0.33434","2149.23633","0.00228"
"3.50000","0.34433","2198.98682","0.00234"
"3.60000","0.35445","2248.42700","0.00240"
"3.70000","0.36441","2295.27466","0.00246"
"3.80000","0.37431","2340.15625","0.00252"
"3.90000","0.38430","2383.00415","0.00258"
"4.00000","0.39440","2423.08496","0.00265"
"4.10000","0.40443","2458.98560","0.00271"
"4.20000","0.41451","2490.06128","0.00279"
"4.30000","0.42438","2515.54614","0.00286"
"4.40000","0.43428","2536.73730","0.00294"
"4.50000","0.44423","2553.60205","0.00302"
"4.60000","0.45435","2567.22095","0.00311"
"4.70000","0.46442","2578.33228","0.00321"
"4.80000","0.47456","2587.57666","0.00330"
"4.90000","0.48451","2594.48877","0.00339"
"5.00000","0.49433","2600.07764","0.00348"
"5.10000","0.50428","2604.95361","0.00357"
"5.20000","0.51429","2609.32153","0.00366"
"5.30000","0.52431","2613.10498","0.00374"
"5.40000","0.53449","2617.29297","0.00382"
"5.50000","0.54452","2620.79639","0.00390"
"5.60000","0.55439","2624.69336","0.00398"
"5.70000","0.56433","2629.98779","0.00406"
"5.80000","0.57433","2630.19678","0.00415"
"5.90000","0.58432","2625.41089","0.00422"
"6.00000","0.59445","2629.67993","0.00428"
"6.10000","0.60442","2630.47412","0.00433"
"6.20000","0.61436","2632.64282","0.00437"
"6.30000","0.62433","2630.65649","0.00440"
"6.40000","0.63442","2631.79541","0.00443"
"6.50000","0.64443","2633.81079","0.00446"
"6.60000","0.65446","2635.22485","0.00448"
"6.70000","0.66441","2635.08911","0.00450"
"6.80000","0.67429","2642.19604","0.00453"
"6.90000","0.68424","2650.75781","0.00458"
"7.00000","0.69438","2663.11304","0.00468"
"7.10000","0.70446","2645.47144","0.00473"
"7.20000","0.71454","2657.05933","0.00479"
"7.30000","0.72455","2626.87793","0.00480"
"7.40000","0.73432","2638.24072","0.00483"
"7.50000","0.74427","2639.52148","0.00485"
"7.60000","0.75431","2641.27637","0.00487"
"7.70000","0.76434","2642.16113","0.00489"
"7.80000","0.77456","2643.64453","0.00490"
"7.90000","0.78454","2644.59302","0.00492"
"8.00000","0.79437","2645.04810","0.00493"
"8.10000","0.80428","2647.50806","0.00494"
"8.20000","0.81430","2652.04224","0.00496"
"8.30000","0.82426","2654.24927","0.00497"
"8.40000","0.83445","2658.25244","0.00499"
"8.50000","0.84445","2662.44824","0.00501"
"8.60000","0.85439","2659.33545","0.00502"
"8.70000","0.86437","2658.41138","0.00504"
"8.80000","0.87437","2655.64038","0.00504"
"8.90000","0.88438","2654.67700","0.00505"
"9.00000","0.89442","2657.82935","0.00508"
"9.10000","0.90444","2667.09277","0.00568"
"9.20000","0.91431","2672.79028","0.00768"
"9.30000","0.92426","2672.79175","0.00922"
"9.40000","0.93443","2685.12012","0.00940"
"9.50000","0.94445","2694.44800","0.00963"
"9.60000","0.95451","2707.06665","0.00981"
"9.70000","0.96449","2714.33545","0.00985"
"9.80000","0.97434","2724.91992","0.00985"
"9.90000","0.98422","2710.62866","0.00978"
"10.00000","0.99435","2704.58154","0.00973"
"10.10000","1.00438","2677.57764","0.00966"
"10.20000","1.01457","2687.12646","0.00964"
"10.30000","1.02452","2685.98413","0.00961"
"10.40000","1.03433","2705.19922","0.00960"
"10.50000","1.04430","2722.19189","0.00959"
"10.60000","1.05433","2725.58569","0.00943"
"10.70000","1.06435","2732.11597","0.00845"
"10.80000","1.07442","2726.59692","0.00742"
"10.90000","1.08454","2732.52808","0.00699"
"11.00000","1.09441","2742.29175","0.00656"
"11.10000","1.10434","2745.40405","0.00623"
"11.20000","1.11434","2751.57837","0.00591"
"11.30000","1.12440","2752.44165","0.00564"
"11.40000","1.13440","2753.27441","0.00538"
"11.50000","1.14445","2753.46069","0.00515"
"11.60000","1.15428","2753.89038","0.00493"
"11.70000","1.16435","2755.36694","0.00470"
"11.80000","1.17443","2753.74243","0.00453"
"11.90000","1.18446","2745.22852","0.00440"
"12.00000","1.19444","2765.24658","0.00432"
"12.10000","1.20442","2763.88989","0.00422"
"12.20000","1.21434","2771.29907","0.00414"
"12.30000","1.22431","2776.44946","0.00406"
"12.40000","1.23436","2768.83765","0.00399"
"12.50000","1.24442","2788.42627","0.00394"
"12.60000","1.25452","2795.98169","0.00390"
"12.70000","1.26450","2812.35132","0.00387"
"12.80000","1.27431","2809.95264","0.00380"
"12.90000","1.28430","2744.03833","0.00370"
"13.00000","1.29428","2761.05225","0.00368"
"13.10000","1.30437","2764.91724","0.00366"
"13.20000","1.31446","2763.02661","0.00363"
"13.30000","1.32456","2765.77954","0.00361"
"13.40000","1.33443","2764.56396","0.00358"
"13.50000","1.34433","2766.18945","0.00356"
"13.60000","1.35429","2769.74585","0.00355"
"13.70000","1.36435","2769.50244","0.00353"
"13.80000","1.37440","2771.33203","0.00351"
"13.90000","1.38449","2773.12988","0.00349"
"14.00000","1.39439","2774.48682","0.00348"
"14.10000","1.40436","2779.14819","0.00347"
"14.20000","1.41438","2783.19775","0.00346"
"14.30000","1.42434","2787.60547","0.00344"
"14.40000","1.43440","2784.25708","0.00343"
"14.50000","1.44440","2790.41650","0.00341"
"14.60000","1.45437","2791.91748","0.00340"
"14.70000","1.46431","2791.49951","0.00339"
"14.80000","1.47436","2792.58447","0.00340"
"14.90000","1.48447","2791.25610","0.00343"
"15.00000","1.49452","2787.15430","0.00355"
"15.10000","1.50447","2785.04614","0.00369"
"15.20000","1.51434","2791.17529","0.00380"
"15.30000","1.52429","2794.52612","0.00394"
"15.40000","1.53432","2792.92383","0.00412"
"15.50000","1.54438","2808.78516","0.00366"
"15.60000","1.55448","2827.30371","0.00346"
"15.70000","1.56451","2837.82178","0.00338"
"15.80000","1.57442","2848.45728","0.00331"
"15.90000","1.58432","2843.75928","0.00323"
"16.00000","1.59425","2842.49023","0.00319"
"16.10000","1.60431","2886.24072","0.00317"
"16.20000","1.61438","2849.84058","0.00286"
"16.30000","1.62451","2871.55737","0.00281"
"16.40000","1.63445","2855.63989","0.00275"
"16.50000","1.64439","2844.16870","0.00272"
"16.60000","1.65434","2822.07690","0.00268"
"16.70000","1.66437","2829.49146","0.00268"
"16.80000","1.67438","2828.18335","0.00268"
"16.90000","1.68438","2831.63403","0.00268"
"17.00000","1.69439","2845.25708","0.00268"
"17.10000","1.70439","2856.08740","0.00268"
"17.20000","1.71440","2859.63428","0.00267"
"17.30000","1.72442","2869.63013","0.00267"
"17.40000","1.73445","2875.88062","0.00267"
"17.50000","1.74442","2872.49976","0.00266"
"17.60000","1.75437","2876.76562","0.00266"
"17.70000","1.76430","2882.66455","0.00266"
"17.80000","1.77432","2884.98730","0.00265"
"17.90000","1.78437","2885.96362","0.00265"
"18.00000","1.79450","2877.44702","0.00264"
"18.10000","1.80449","2899.00195","0.00264"
"18.20000","1.81439","2910.61963","0.00264"
"18.30000","1.82432","2880.46265","0.00262"
"18.40000","1.83418","2893.06787","0.00263"
"18.50000","1.84433","2895.53369","0.00263"
"18.60000","1.85444","2865.14209","0.00261"
"18.70000","1.86453","2888.47485","0.00263"
"18.80000","1.87442","2892.25952","0.00263"
"18.90000","1.88439","2899.77759","0.00263"
"19.00000","1.89430","2860.07715","0.00260"
"19.10000","1.90430","2898.47900","0.00263"
"19.20000","1.91441","2898.99536","0.00267"
"19.30000","1.92441","2894.05884","0.00273"
"19.40000","1.93446","2934.44556","0.00277"
"19.50000","1.94443","2913.41626","0.00263"
"19.60000","1.95435","2917.55664","0.00211"
"19.70000","1.96435","2937.87354","0.00210"
"19.80000","1.97442","2936.00293","0.00209"
"19.90000","1.98442","2927.59473","0.00209"
"20.00000","1.99437","2921.63110","0.00212"
"20.10000","2.00433","2920.13965","0.00217"
"20.20000","2.01434","2921.48169","0.00222"
"20.30000","2.02440","2923.45435","0.00224"
"20.40000","2.03445","2923.44849","0.00227"
"20.50000","2.04447","2921.65625","0.00230"
"20.60000","2.05437","2925.76440","0.00230"
"20.70000","2.06432","2927.03613","0.00230"
"20.80000","2.07419","2927.81934","0.00229"
"20.90000","2.08435","2927.19629","0.00226"
"21.00000","2.09451","2924.30615","0.00223"
"21.10000","2.10453","2921.05103","0.00220"
"21.20000","2.11444","2922.50830","0.00218"
"21.30000","2.12432","2924.85718","0.00217"
"21.40000","2.13425","2926.75098","0.00216"
"21.50000","2.14428","2926.93115","0.00216"
"21.60000","2.15441","2924.77686","0.00215"
"21.70000","2.16443","2920.50049","0.00215"
"21.80000","2.17450","2917.66943","0.00214"
"21.90000","2.18442","2916.47510","0.00214"
"22.00000","2.19433","2915.40723","0.00213"
"22.10000","2.20435","2915.14648","0.00213"
"22.20000","2.21437","2915.94165","0.00213"
"22.30000","2.22444","2915.53345","0.00212"
"22.40000","2.23436","2915.20850","0.00212"
"22.50000","2.24437","2915.76758","0.00212"
"22.60000","2.25436","2917.36719","0.00212"
"22.70000","2.26435","2920.45630","0.00211"
"22.80000","2.27440","2919.13354","0.00211"
"22.90000","2.28446","2919.33228","0.00211"
"23.00000","2.29441","2925.10132","0.00211"
"23.10000","2.30432","2930.09106","0.00211"
"23.20000","2.31425","2934.39941","0.00211"
"23.30000","2.32435","2936.34937","0.00211"
"23.40000","2.33451","2940.72803","0.00210"
"23.50000","2.34454","2948.85938","0.00211"
"23.60000","2.35442","2946.28662","0.00210"
"23.70000","2.36430","2954.96240","0.00210"
"23.80000","2.37426","2950.67773","0.00210"
"23.90000","2.38429","2964.20703","0.00210"
"24.00000","2.39440","2982.96753","0.00210"
"24.10000","2.40451","2964.39111","0.00210"
"24.20000","2.41449","2986.52808","0.00210"
"24.30000","2.42436","2994.72363","0.00210"
"24.40000","2.43425","2984.72559","0.00210"
"24.50000","2.44431","2969.76660","0.00208"
"24.60000","2.45432","2974.03638","0.00209"
"24.70000","2.46445","2965.34448","0.00208"
"24.80000","2.47445","2969.10498","0.00208"
"24.90000","2.48437","2966.93066","0.00208"
"25.00000","2.49435","2971.84961","0.00208"
"25.10000","2.50433","2988.02637","0.00209"
"25.20000","2.51440","3003.01807","0.00209"
"25.30000","2.52446","3004.69946","0.00209"
"25.40000","2.53442","2997.99219","0.00208"
"25.50000","2.54430","3007.78906","0.00209"
"25.60000","2.55429","3018.83472","0.00209"
"25.70000","2.56439","3012.70288","0.00209"
"25.80000","2.57446","3010.80103","0.00208"
"25.90000","2.58451","3015.69946","0.00208"
"26.00000","2.59440","3023.50684","0.00209"
"26.10000","2.60433","3018.52661","0.00208"
"26.20000","2.61424","3000.52417","0.00208"
"26.30000","2.62432","3026.04761","0.00208"
"26.40000","2.63439","3034.49585","0.00208"
"26.50000","2.64456","3033.54150","0.00208"
"26.60000","2.65451","3033.78174","0.00208"
"26.70000","2.66435","3038.10181","0.00208"
"26.80000","2.67428","3023.49243","0.00208"
"26.90000","2.68433","3018.31177","0.00207"
"27.00000","2.69435","3026.47388","0.00207"
"27.10000","2.70445","3041.37646","0.00208"
"27.20000","2.71448","3023.19629","0.00207"
"27.30000","2.72439","3017.25757","0.00207"
"27.40000","2.73437","3028.13135","0.00207"
"27.50000","2.74432","3036.98975","0.00207"
"27.60000","2.75434","3055.68628","0.00208"
"27.70000","2.76445","3036.34937","0.00207"
"27.80000","2.77442","3012.46094","0.00205"
"27.90000","2.78432","3049.25635","0.00207"
"28.00000","2.79435","3034.28613","0.00206"
"28.10000","2.80442","3060.58740","0.00207"
"28.20000","2.81439","3055.95117","0.00206"
"28.30000","2.82449","3089.62744","0.00207"
"28.40000","2.83442","3048.98706","0.00206"
"28.50000","2.84428","3069.15039","0.00206"
"28.60000","2.85425","3052.24658","0.00205"
"28.70000","2.86436","3048.72241","0.00204"
"28.80000","2.87443","3070.44580","0.00205"
"28.90000","2.88454","3067.17505","0.00205"
"29.00000","2.89451","3061.27832","0.00214"
"29.10000","2.90431","3052.27441","0.00225"
"29.20000","2.91427","3051.16968","0.00233"
"29.30000","2.92431","3063.50879","0.00238"
"29.40000","2.93436","3070.10303","0.00242"
"29.50000","2.94452","3067.24927","0.00246"
"29.60000","2.95453","3061.56982","0.00251"
"29.70000","2.96438","3055.04175","0.00255"
"29.80000","2.97433","3053.92456","0.00256"
"29.90000","2.98431","3063.13794","0.00255"
"30.00000","2.99433","3071.79736","0.00253"
"30.10000","3.00447","3065.05908","0.00251"
"30.20000","3.01443","3057.02563","0.00233"
"30.30000","3.02433","3050.60522","0.00230"
"30.40000","3.03432","3046.96826","0.00228"
"30.50000","3.04442","3055.74243","0.00227"
"30.60000","3.05437","3072.41528","0.00227"
"30.70000","3.06445","3061.18530","0.00226"
"30.80000","3.07444","3047.85840","0.00225"
"30.90000","3.08427","3059.91260","0.00226"
"31.00000","3.09427","3069.67505","0.00231"
"31.10000","3.10443","3062.50708","0.00235"
"31.20000","3.11446","3057.10132","0.00234"
"31.30000","3.12454","3052.39526","0.00219"
"31.40000","3.13452","3047.69824","0.00219"
"31.50000","3.14432","3054.16260","0.00224"
"31.60000","3.15424","3066.48975","0.00235"
"31.70000","3.16429","3060.01929","0.00230"
"31.80000","3.17438","3050.38257","0.00213"
"31.90000","3.18455","3045.72803","0.00218"
"32.00000","3.19452","3046.18701","0.00218"
"32.10000","3.20433","3064.98120","0.00218"
"32.20000","3.21427","3067.07129","0.00217"
"32.30000","3.22433","3055.16382","0.00216"
"32.40000","3.23434","3049.04980","0.00215"
"32.50000","3.24444","3056.05151","0.00212"
"32.60000","3.25449","3068.34082","0.00191"
"32.70000","3.26440","3068.00928","0.00119"
"32.80000","3.27438","3062.74829","0.00208"
"32.90000","3.28435","3059.56470","0.00167"
"33.00000","3.29437","3074.73633","0.00127"
"33.10000","3.30442","3082.87061","0.00190"
"33.20000","3.31449","3070.45288","0.00028"
"33.30000","3.32433","3082.10767","0.00192"
"33.40000","3.33431","3087.68994","0.00195"
"33.50000","3.34442","3089.63794","-0.00027"
"33.60000","3.35442","3090.12207","0.00123"
"33.70000","3.36446","3092.48218","0.00071"
"33.80000","3.37449","3095.58569","0.00148"
"33.90000","3.38434","3110.86890","-0.00340"
"34.00000","3.39424","3108.08447","0.00201"
"34.10000","3.40434","3122.62964","0.00123"
"34.20000","3.41441","3140.98218","0.11688"
"34.30000","3.42452","3159.76025","0.10112"
"34.40000","3.43452","3087.90869","0.10256"
"34.50000","3.44432","3140.83667","0.08234"
"34.60000","3.45429","3104.18896","0.11354"
"34.70000","3.46433","3091.15625","0.11405"
"34.80000","3.47433","3104.46606","0.11408"
"34.90000","3.48442","3115.39868","0.07600"
"35.00000","3.49458","3095.23193","0.10909"
"35.10000","3.50441","3083.80664","0.11399"
"35.20000","3.51433","3101.11401","0.11408"
"35.30000","3.52429","3116.49731","0.11408"
"35.40000","3.53435","3101.54077","0.11408"
"35.50000","3.54443","3101.66675","0.11408"
"35.60000","3.55448","3138.64209","0.11408"
"35.70000","3.56439","3120.54443","0.11280"
"35.80000","3.57436","3123.30151","0.11407"
"35.90000","3.58441","3151.49268","0.11408"
"36.00000","3.59440","3133.86475","0.11408"
"36.10000","3.60441","3121.89087","0.11408"
"36.20000","3.61444","3157.55688","0.11137"
"36.30000","3.62440","3143.70728","0.11409"
"36.40000","3.63428","3121.34668","0.11408"
"36.50000","3.64434","3154.20117","0.10662"
"36.60000","3.65444","3152.30151","0.11416"
"36.70000","3.66451","3133.06860","0.11430"
"36.80000","3.67450","3143.78149","0.11406"
"36.90000","3.68432","3157.89233","0.11415"
"37.00000","3.69430","3138.04639","0.09530"
"37.10000","3.70430","3141.78516","0.10638"
"37.20000","3.71439","3172.86475","0.11014"
"37.30000","3.72445","3145.15723","0.10322"
"37.40000","3.73452","3161.54443","0.11096"
"37.50000","3.74443","3153.20898","0.10423"
"37.60000","3.75432","3139.71338","0.11399"
"37.70000","3.76429","3156.50513","0.11404"
"37.80000","3.77431","3164.88623","0.11408"
"37.90000","3.78439","3143.53442","0.11408"
"38.00000","3.79445","3173.14941","0.11408"
"38.10000","3.80444","3160.21973","0.11408"
"38.20000","3.81442","3135.63086","0.11408"
"38.30000","3.82439","3117.46265","0.11408"
"38.40000","3.83436","3172.87451","0.11408"
"38.50000","3.84441","3165.08643","0.11408"
"38.60000","3.85441","3171.09961","0.11408"
"38.70000","3.86438","3173.58667","0.11408"
"38.80000","3.87436","3171.12622","0.11408"
"38.90000","3.88435","3196.63281","0.11408"
"39.00000","3.89445","3167.68579","0.11408"
"39.10000","3.90446","3138.30444","0.11408"
"39.20000","3.91444","3195.47095","0.11408"
"39.30000","3.92435","3181.63867","0.11408"
"39.40000","3.93430","3196.15454","0.11408"
"39.50000","3.94435","3159.03418","0.11408"
"39.60000","3.95436","3183.15771","0.11408"
"39.70000","3.96450","3176.53540","0.11408"
"39.80000","3.97450","3142.09839","0.11408"
"39.90000","3.98444","3173.65234","0.11408"
"40.00000","3.99432","3176.85376","0.11408"
"40.10000","4.00423","3142.48730","0.11408"
"40.20000","4.01433","3182.02588","0.11408"
"40.30000","4.02442","3166.12061","0.11408"
"40.40000","4.03445","3145.36865","0.11408"
"40.50000","4.04439","3189.56738","0.11408"
"40.60000","4.05437","3163.75537","0.11408"
"40.70000","4.06429","3142.51416","0.11408"
"40.80000","4.07435","3185.05054","0.11408"
"40.90000","4.08440","3162.26929","0.11408"
"41.00000","4.09439","3143.11792","0.11408"
"41.10000","4.10441","3187.50488","0.11408"
"41.20000","4.11441","3167.01416","0.11408"
"41.30000","4.12439","3149.61035","0.11408"
"41.40000","4.13438","3193.18140","0.11408"
"41.50000","4.14448","3167.47949","0.11408"
"41.60000","4.15440","3155.70581","0.11408"
"41.70000","4.16438","3190.26416","0.11408"
"41.80000","4.17429","3155.28174","0.11408"
"41.90000","4.18432","3197.98999","0.11408"
"42.00000","4.19440","3169.68677","0.11408"
"42.10000","4.20449","3164.57349","0.11408"
"42.20000","4.21445","3192.89722","0.11408"
"42.30000","4.22442","3162.65332","0.11408"
"42.40000","4.23430","3187.82251","0.11408"
"42.50000","4.24417","3188.12695","0.11408"
"42.60000","4.25433","3161.71265","0.11408"
"42.70000","4.26443","3195.66162","0.11408"
"42.80000","4.27455","3189.50366","0.11408"
"42.90000","4.28446","3161.29663","0.11408"
"43.00000","4.29436","3191.34448","0.11408"
"43.10000","4.30426","3186.22510","0.11408"
"43.20000","4.31426","3159.78687","0.11408"
"43.30000","4.32440","3193.34912","0.11408"
"43.40000","4.33444","3187.43774","0.11408"
"43.50000","4.34451","3159.55688","0.11408"
"43.60000","4.35440","3208.11230","0.11408"
"43.70000","4.36433","3181.44263","0.11408"
"43.80000","4.37433","3163.07666","0.11408"
"43.90000","4.38440","3204.31079","0.11408"
"44.00000","4.39444","3177.42090","0.11408"
"44.10000","4.40440","3163.14819","0.11408"
"44.20000","4.41432","3202.89282","0.11408"
"44.30000","4.42435","3178.20605","0.11408"
"44.40000","4.43439","3171.96997","0.11408"
"44.50000","4.44442","3205.30420","0.11408"
"44.60000","4.45447","3177.84058","0.11408"
"44.70000","4.46439","3183.50415","0.11408"
"44.80000","4.47433","3200.71851","0.11408"
"44.90000","4.48421","3167.12866","0.11408"
"45.00000","4.49434","3195.94482","0.11408"
"45.10000","4.50447","3193.89136","0.11408"
"45.20000","4.51453","3168.47998","0.11408"
"45.30000","4.52443","3212.09546","0.11408"
"45.40000","4.53432","3184.98047","0.11408"
"45.50000","4.54425","3182.76929","0.11408"
"45.60000","4.55427","3208.78589","0.11408"
"45.70000","4.56444","3185.08936","0.11408"
"45.80000","4.57446","3226.18408","0.11408"
"45.90000","4.58454","3209.05176","0.11408"
"46.00000","4.59442","3213.93604","0.11408"
"46.10000","4.60429","3210.19775","0.11408"
"46.20000","4.61433","3204.49170","0.11408"
"46.30000","4.62433","3230.47412","0.11408"
"46.40000","4.63441","3219.45850","0.11408"
"46.50000","4.64442","3205.61890","0.11408"
"46.60000","4.65437","3246.53320","0.11408"
"46.70000","4.66436","3231.82129","0.11408"
"46.80000","4.67435","3255.53491","0.11408"
"46.90000","4.68440","3198.18604","0.11408"
"47.00000","4.69443","3247.93384","0.11408"
"47.10000","4.70441","3217.09888","0.11408"
"47.20000","4.71432","3255.75439","0.11408"
"47.30000","4.72430","3242.91479","0.11408"
"47.40000","4.73439","3218.32300","0.11408"
"47.50000","4.74449","3265.87939","0.11408"
"47.60000","4.75450","3256.27808","0.11408"
"47.70000","4.76442","3235.26050","0.11408"
"47.80000","4.77429","3253.98120","0.11408"
"47.90000","4.78426","3237.83765","0.11408"
"48.00000","4.79430","3247.89893","0.11408"
"48.10000","4.80441","3247.89819","0.11408"
"48.20000","4.81453","3225.28369","0.11408"
"48.30000","4.82451","3268.33350","0.11408"
"48.40000","4.83437","3228.68628","0.11408"
"48.50000","4.84425","3278.55054","0.11408"
"48.60000","4.85432","3240.27466","0.11408"
"48.70000","4.86432","3251.89355","0.11408"
"48.80000","4.87449","3255.45825","0.11408"
"48.90000","4.88447","3222.59253","0.11408"
"49.00000","4.89437","3268.03589","0.11408"
"49.10000","4.90436","3225.07910","0.11408"
"49.20000","4.91432","3279.19580","0.11408"
"49.30000","4.92441","3237.43921","0.11408"
"49.40000","4.93443","3285.50122","0.11408"
"49.50000","4.94442","3248.94971","0.11408"
"49.60000","4.95433","3272.52295","0.11408"
"49.70000","4.96434","3255.32324","0.11408"
"49.80000","4.97440","3259.17383","0.11408"
"49.90000","4.98444","3260.42261","0.11408"
"50.00000","4.99449","3232.80200","0.11408"
"50.10000","5.00440","3267.84131","0.11408"
"50.20000","5.01431","3228.30713","0.11408"
"50.30000","5.02421","3277.72461","0.11408"
"50.40000","5.03435","3233.50098","0.11408"
"50.50000","5.04440","3287.83057","0.11408"
"50.60000","5.05456","3243.24512","0.11408"
"50.70000","5.06452","3295.66113","0.11408"
"50.80000","5.07434","3252.62500","0.11408"
"50.90000","5.08425","3256.09082","0.11408"
"51.00000","5.09430","3278.45654","0.11408"
"51.10000","5.10433","3221.60083","0.11408"
"51.20000","5.11450","3208.71436","0.11408"
"51.30000","5.12451","3226.78760","0.11408"
"51.40000","5.13441","3200.59277","0.11408"
"51.50000","5.14435","3237.24365","0.11408"
"51.60000","5.15435","3199.00659","0.11408"
"51.70000","5.16433","3236.10596","0.11408"
"51.80000","5.17445","3218.01978","0.11408"
"51.90000","5.18443","3187.75171","0.11408"
"52.00000","5.19437","3235.66748","0.11408"
"52.10000","5.20436","3200.63745","0.11408"
"52.20000","5.21439","3241.46338","0.11408"
"52.30000","5.22440","3222.01221","0.11408"
"52.40000","5.23447","3206.26758","0.11408"
"52.50000","5.24439","3241.28906","0.11408"
"52.60000","5.25430","3204.61792","0.11408"
"52.70000","5.26424","3258.66528","0.11408"
"52.80000","5.27441","3222.46973","0.11408"
"52.90000","5.28446","3270.46265","0.11408"
"53.00000","5.29453","3241.73975","0.11408"
"53.10000","5.30448","3236.51221","0.11408"
"53.20000","5.31432","3255.86572","0.11408"
"53.30000","5.32427","3221.16455","0.11408"
"53.40000","5.33429","3266.54175","0.11408"
"53.50000","5.34436","3269.58374","0.11408"
"53.60000","5.35454","3245.56226","0.11408"
"53.70000","5.36453","3241.34009","0.11408"
"53.80000","5.37438","3258.29883","0.11408"
"53.90000","5.38429","3225.16187","0.11408"
"54.00000","5.39433","3270.74683","0.11408"
"54.10000","5.40434","3229.18359","0.11408"
"54.20000","5.41444","3283.58032","0.11408"
"54.30000","5.42449","3246.66846","0.11408"
"54.40000","5.43442","3258.40894","0.11408"
"54.50000","5.44433","3259.72412","0.11408"
"54.60000","5.45435","3228.92480","0.11408"
"54.70000","5.46437","3275.82471","0.11408"
"54.80000","5.47444","3249.83716","0.11408"
"54.90000","5.48443","3260.32983","0.11408"
"55.00000","5.49430","3263.31958","0.11408"
"55.10000","5.50434","3235.39453","0.11408"
"55.20000","5.51441","3272.89746","0.11408"
"55.30000","5.52448","3232.39185","0.11408"
"55.40000","5.53446","3286.65454","0.11408"
"55.50000","5.54452","3244.86646","0.11408"
"55.60000","5.55434","3291.84839","0.11408"
"55.70000","5.56424","3255.19043","0.11408"
"55.80000","5.57436","3264.84058","0.11408"
"55.90000","5.58440","3269.10327","0.11408"
"56.00000","5.59458","3226.21533","0.11408"
"56.10000","5.60452","3269.58569","0.11408"
"56.20000","5.61437","3235.22388","0.11408"
"56.30000","5.62426","3244.78003","0.11408"
"56.40000","5.63429","3254.65771","0.11408"
"56.50000","5.64428","3223.86035","0.11408"
"56.60000","5.65442","3268.42188","0.11408"
"56.70000","5.66453","3233.42017","0.11408"
"56.80000","5.67441","3263.40649","0.11408"
"56.90000","5.68436","3279.03442","0.11408"
"57.00000","5.69431","3271.76416","0.11408"
"57.10000","5.70435","3252.12476","0.11408"
"57.20000","5.71440","3264.65918","0.11408"
"57.30000","5.72448","3225.07520","0.11408"
"57.40000","5.73437","3266.84717","0.11408"
"57.50000","5.74436","3224.39868","0.11408"
"57.60000","5.75442","3260.56372","0.11408"
"57.70000","5.76441","3236.52954","0.11408"
"57.80000","5.77443","3290.58911","0.11408"
"57.90000","5.78446","3266.46558","0.11408"
"58.00000","5.79435","3295.73315","0.11408"
"58.10000","5.80425","3289.42993","0.11408"
"58.20000","5.81439","3293.77734","0.11408"
"58.30000","5.82443","3308.13721","0.11408"
"58.40000","5.83453","3294.84204","0.11408"
"58.50000","5.84447","3298.92896","0.11408"
"58.60000","5.85433","3290.15747","0.11408"
"58.70000","5.86430","3306.27930","0.11408"
"58.80000","5.87432","3296.81958","0.11408"
"58.90000","5.88438","3232.48853","0.11408"
"59.00000","5.89443","3288.39209","0.11408"
"59.10000","5.90457","3266.35010","0.11408"
"59.20000","5.91441","3312.95361","0.11408"
"59.30000","5.92430","3296.44580","0.11408"
"59.40000","5.93427","3299.12817","0.11408"
"59.50000","5.94438","3291.15308","0.11408"
"59.60000","5.95441","3285.32983","0.11408"
"59.70000","5.96447","3274.21680","0.11408"
"59.80000","5.97438","3315.44800","0.11408"
"59.90000","5.98440","3265.33496","0.11408"
"60.00000","5.99436","3313.14502","0.11408"
"60.10000","6.00439","3266.72266","0.11408"
"60.20000","6.01442","3314.08789","0.11408"
"60.30000","6.02441","3270.82471","0.11408"
"60.40000","6.03435","3316.81519","0.11408"
"60.50000","6.04435","3273.74341","0.11408"
"60.60000","6.05438","3318.98926","0.11408"
"60.70000","6.06444","3278.06812","0.11408"
"60.80000","6.07444","3323.80273","0.11408"
"60.90000","6.08446","3278.46143","0.11408"
"61.00000","6.09432","3326.34229","0.11408"
"61.10000","6.10430","3260.70776","0.11408"
"61.20000","6.11428","3315.37012","0.11408"
"61.30000","6.12442","3257.38086","0.11408"
"61.40000","6.13446","3312.59009","0.11408"
"61.50000","6.14457","3255.27905","0.11408"
"61.60000","6.15442","3260.49292","0.11408"
"61.70000","6.16431","3265.10547","0.11408"
"61.80000","6.17424","3272.21558","0.11408"
"61.90000","6.18433","3272.01978","0.11408"
"62.00000","6.19442","3251.05029","0.11408"
"62.10000","6.20450","3282.82593","0.11408"
"62.20000","6.21443","3248.70044","0.11408"
"62.30000","6.22438","3285.89941","0.11408"
"62.40000","6.23429","3267.13110","0.11408"
"62.50000","6.24429","3293.27832","0.11408"
"62.60000","6.25437","3329.32837","0.11408"
"62.70000","6.26442","3289.36133","0.11408"
"62.80000","6.27440","3339.67773","0.11408"
"62.90000","6.28439","3268.37231","0.11408"
"63.00000","6.29434","3320.96216","0.11408"
"63.10000","6.30442","3275.49976","0.11408"
"63.20000","6.31443","3312.26001","0.11408"
"63.30000","6.32443","3293.02612","0.11408"
"63.40000","6.33435","3304.89575","0.11408"
"63.50000","6.34431","3332.25024","0.11408"
"63.60000","6.35433","3298.00024","0.11408"
"63.70000","6.36441","3348.48608","0.11408"
"63.80000","6.37448","3290.43018","0.11408"
"63.90000","6.38445","3342.38306","0.11408"
"64.00000","6.39447","3276.32788","0.11408"
"64.10000","6.40430","3310.55029","0.11408"
"64.20000","6.41424","3232.99048","0.11408"
"64.30000","6.42431","3278.16016","0.11408"
"64.40000","6.43442","3244.79517","0.11408"
"64.50000","6.44453","3287.56982","0.11408"
"64.60000","6.45445","3246.73291","0.11408"
"64.70000","6.46435","3295.10840","0.11408"
"64.80000","6.47429","3248.86621","0.11408"
"64.90000","6.48431","3302.62036","0.11408"
"65.00000","6.49441","3255.74316","0.11408"
"65.10000","6.50439","3309.66968","0.11408"
"65.20000","6.51448","3264.44312","0.11408"
"65.30000","6.52441","3309.49829","0.11408"
"65.40000","6.53438","3273.51196","0.11408"
"65.50000","6.54436","3293.77197","0.11408"
"65.60000","6.55440","3281.71729","0.11408"
"65.70000","6.56440","3275.83105","0.11408"
"65.80000","6.57442","3288.81665","0.11408"
"65.90000","6.58433","3262.57080","0.11408"
"66.00000","6.59435","3296.58838","0.11408"
"66.10000","6.60439","3256.16968","0.11408"
"66.20000","6.61442","3305.65088","0.11408"
"66.30000","6.62449","3257.58838","0.11408"
"66.40000","6.63440","3311.71191","0.11408"
"66.50000","6.64432","3261.56128","0.11408"
"66.60000","6.65415","3315.14600","0.11408"
"66.70000","6.66437","3267.35718","0.11408"
"66.80000","6.67446","3318.17090","0.11408"
"66.90000","6.68455","3277.71167","0.11408"
"67.00000","6.69438","3301.28564","0.11408"
"67.10000","6.70435","3284.46851","0.11408"
"67.20000","6.71426","3290.48828","0.11408"
"67.30000","6.72430","3292.12109","0.11408"
"67.40000","6.73439","3301.72998","0.11408"
"67.50000","6.74447","3260.56299","0.11408"
"67.60000","6.75451","3309.48950","0.11408"
"67.70000","6.76443","3262.69824","0.11408"
"67.80000","6.77429","3314.86499","0.11408"
"67.90000","6.78432","3284.65771","0.11408"
"68.00000","6.79438","3276.96826","0.11408"
"68.10000","6.80444","3283.73169","0.11408"
"68.20000","6.81440","3278.67798","0.11408"
"68.30000","6.82435","3310.66699","0.11408"
"68.40000","6.83435","3282.75293","0.11408"
"68.50000","6.84437","3332.21826","0.11408"
"68.60000","6.85441","3300.83252","0.11408"
"68.70000","6.86446","3310.49121","0.11408"
"68.80000","6.87440","3304.44995","0.11408"
"68.90000","6.88435","3312.16040","0.11408"
"69.00000","6.89425","3310.08350","0.11408"
"69.10000","6.90438","3284.85400","0.11408"
"69.20000","6.91448","3326.11694","0.11408"
"69.30000","6.92452","3304.72144","0.11408"
"69.40000","6.93441","3327.46851","0.11408"
"69.50000","6.94430","3320.35303","0.11408"
"69.60000","6.95424","3331.28052","0.11408"
"69.70000","6.96430","3275.35010","0.11408"
"69.80000","6.97438","3328.28271","0.11408"
"69.90000","6.98452","3271.11548","0.11408"
"70.00000","6.99453","3324.68970","0.11408"
"70.10000","7.00442","3272.92969","0.11408"
"70.20000","7.01425","3325.38599","0.11408"
"70.30000","7.02432","3276.91650","0.11408"
"70.40000","7.03432","3324.77881","0.11408"
"70.50000","7.04449","3284.40967","0.11408"
"70.60000","7.05441","3322.08569","0.11408"
"70.70000","7.06440","3304.10815","0.11408"
"70.80000","7.07435","3316.53906","0.11408"
"70.90000","7.08431","3328.53345","0.11408"
"71.00000","7.09437","3312.06445","0.11408"
"71.10000","7.10444","3353.01489","0.11408"
"71.20000","7.11446","3307.22363","0.11408"
"71.30000","7.12431","3352.36646","0.11408"
"71.40000","7.13432","3302.35840","0.11408"
"71.50000","7.14436","3353.30322","0.11408"
"71.60000","7.15451","3304.53809","0.11408"
"71.70000","7.16448","3357.65210","0.11408"
"71.80000","7.17445","3296.41772","0.11408"
"71.90000","7.18428","3351.12256","0.11408"
"72.00000","7.19427","3287.61670","0.11408"
"72.10000","7.20432","3343.07031","0.11408"
"72.20000","7.21442","3288.11377","0.11408"
"72.30000","7.22455","3338.57153","0.11408"
"72.40000","7.23451","3301.65771","0.11408"
"72.50000","7.24428","3326.71509","0.11408"
"72.60000","7.25416","3334.43140","0.11408"
"72.70000","7.26431","3309.35132","0.11408"
"72.80000","7.27433","3301.88013","0.11408"
"72.90000","7.28451","3313.65210","0.11408"
"73.00000","7.29453","3276.74146","0.11408"
"73.10000","7.30435","3322.66528","0.11408"
"73.20000","7.31435","3272.71851","0.11408"
"73.30000","7.32430","3321.37305","0.11408"
"73.40000","7.33437","3270.94727","0.11408"
"73.50000","7.34444","3322.93433","0.11408"
"73.60000","7.35446","3270.23340","0.11408"
"73.70000","7.36436","3321.02026","0.11408"
"73.80000","7.37435","3275.48608","0.11408"
"73.90000","7.38440","3318.81934","0.11408"
"74.00000","7.39441","3286.49438","0.11408"
"74.10000","7.40448","3316.38867","0.11408"
"74.20000","7.41441","3303.23901","0.11408"
"74.30000","7.42431","3312.77075","0.11408"
"74.40000","7.43422","3329.83179","0.11408"
"74.50000","7.44443","3310.33569","0.11408"
"74.60000","7.45441","3347.29443","0.11408"
"74.70000","7.46457","3308.52490","0.11408"
"74.80000","7.47450","3358.83911","0.11408"
"74.90000","7.48436","3302.65430","0.11408"
"75.00000","7.49424","3356.00000","0.11408"
"75.10000","7.50433","3295.27148","0.11408"
"75.20000","7.51435","3351.92749","0.11408"
"75.30000","7.52452","3295.68164","0.11408"
"75.40000","7.53453","3347.26025","0.11408"
"75.50000","7.54436","3330.62720","0.11408"
"75.60000","7.55434","3339.40674","0.11408"
"75.70000","7.56431","3384.02173","0.11408"
"75.80000","7.57435","3325.17822","0.11408"
"75.90000","7.58442","3273.96777","0.11408"
"76.00000","7.59447","3299.73877","0.11408"
"76.10000","7.60439","3343.80444","0.11408"
"76.20000","7.61438","3288.53589","0.11408"
"76.30000","7.62440","3340.46826","0.11408"
"76.40000","7.63439","3278.03467","0.11408"
"76.50000","7.64445","3332.70947","0.11408"
"76.60000","7.65448","3271.68774","0.11408"
"76.70000","7.66427","3325.45190","0.11408"
"76.80000","7.67430","3274.98584","0.11408"
"76.90000","7.68439","3320.91553","0.11408"
"77.00000","7.69443","3297.94580","0.11408"
"77.10000","7.70449","3316.99634","0.11408"
"77.20000","7.71449","3333.24268","0.11408"
"77.30000","7.72430","3311.82935","0.11408"
"77.40000","7.73426","3361.72729","0.11408"
"77.50000","7.74434","3301.21899","0.11408"
"77.60000","7.75440","3354.87720","0.11408"
"77.70000","7.76455","3286.96680","0.11408"
"77.80000","7.77453","3337.80786","0.11408"
"77.90000","7.78434","3306.39673","0.11408"
"78.00000","7.79425","3322.23071","0.11408"
"78.10000","7.80432","3358.68262","0.11408"
"78.20000","7.81437","3305.73999","0.11408"
"78.30000","7.82438","3356.36914","0.11408"
"78.40000","7.83451","3277.17114","0.11408"
"78.50000","7.84440","3329.28198","0.11408"
"78.60000","7.85434","3279.41333","0.11408"
"78.70000","7.86434","3315.04468","0.11408"
"78.80000","7.87436","3329.54126","0.11408"
"78.90000","7.88443","3281.99390","0.11408"
"79.00000","7.89446","3331.44507","0.11408"
"79.10000","7.90434","3260.41089","0.11408"
"79.20000","7.91433","3312.79224","0.11408"
"79.30000","7.92445","3241.21265","0.11408"
"79.40000","7.93444","3293.21436","0.11408"
"79.50000","7.94447","3228.82910","0.11408"
"79.60000","7.95446","3278.44629","0.11408"
"79.70000","7.96436","3214.80444","0.11408"
"79.80000","7.97425","3248.49438","0.11408"
"79.90000","7.98437","3207.27637","0.11408"
"80.00000","7.99441","3171.78955","0.11408"
"80.10000","8.00454","3200.91431","0.11408"
"80.20000","8.01452","3150.73169","0.11408"
"80.30000","8.02432","3139.57739","0.11408"
"80.40000","8.03428","3147.16260","0.11408"
"80.50000","8.04431","3104.70923","0.11408"
"80.60000","8.05437","3076.13940","0.11408"
"80.70000","8.06444","3078.46509","0.11408"
"80.80000","8.07456","3061.45239","0.11408"
"80.90000","8.08442","3028.47412","0.11408"
"81.00000","8.09435","2997.09448","0.11408"
"81.10000","8.10427","2972.24292","0.11408"
"81.20000","8.11437","2948.59595","0.11408"
"81.30000","8.12442","2921.13770","0.11408"
"81.40000","8.13450","2890.42676","0.11408"
"81.50000","8.14439","2857.21313","0.11408"
"81.60000","8.15440","2821.32275","0.11408"
"81.70000","8.16441","2784.12231","0.11408"
"81.80000","8.17438","2744.08667","0.11408"
"81.90000","8.18445","2698.47510","0.11408"
"82.00000","8.19445","2648.78711","0.11408"
"82.10000","8.20439","2590.69116","0.11408"
"82.20000","8.21429","2523.76953","0.11408"
"82.30000","8.22439","2441.53247","0.11408"
"82.36500","8.23089","1443.77319","0.11408"