File: archive/undergrad/433/Tensile Test/Specimen_RawData_7.csv
Time,Extension,Load,Strain Gage18
(s),(mm),(N),(mm/mm)
"0.00000","0.00000","170.86316","-0.00074"
"0.10000","0.00313","191.89963","-0.00075"
"0.20000","0.01330","262.72574","-0.00078"
"0.30000","0.02378","332.41971","-0.00081"
"0.40000","0.03385","396.89484","-0.00083"
"0.50000","0.04392","459.40918","-0.00086"
"0.60000","0.05409","520.60907","-0.00088"
"0.70000","0.06410","577.85779","-0.00090"
"0.80000","0.07396","631.92090","-0.00092"
"0.90000","0.08391","684.83698","-0.00094"
"1.00000","0.09393","740.55560","-0.00096"
"1.10000","0.10395","795.84521","-0.00099"
"1.20000","0.11401","850.89191","-0.00101"
"1.30000","0.12409","906.21149","-0.00103"
"1.40000","0.13401","960.43695","-0.00105"
"1.50000","0.14399","1015.00891","-0.00107"
"1.60000","0.15396","1069.38220","-0.00109"
"1.70000","0.16397","1123.69849","-0.00111"
"1.80000","0.17403","1178.30237","-0.00114"
"1.90000","0.18405","1232.21472","-0.00116"
"2.00000","0.19388","1284.78149","-0.00118"
"2.10000","0.20394","1338.89221","-0.00120"
"2.20000","0.21405","1393.13818","-0.00122"
"2.30000","0.22402","1446.28345","-0.00124"
"2.40000","0.23407","1499.43860","-0.00126"
"2.50000","0.24406","1552.14282","-0.00128"
"2.60000","0.25393","1603.70361","-0.00130"
"2.70000","0.26387","1655.59351","-0.00132"
"2.80000","0.27393","1707.70300","-0.00134"
"2.90000","0.28401","1758.95520","-0.00136"
"3.00000","0.29414","1810.04871","-0.00138"
"3.10000","0.30416","1859.82568","-0.00141"
"3.20000","0.31392","1907.87756","-0.00143"
"3.30000","0.32390","1956.31384","-0.00145"
"3.40000","0.33392","2004.64355","-0.00147"
"3.50000","0.34395","2052.49146","-0.00149"
"3.60000","0.35405","2100.26611","-0.00152"
"3.70000","0.36415","2147.03687","-0.00154"
"3.80000","0.37404","2191.64648","-0.00156"
"3.90000","0.38397","2234.80249","-0.00158"
"4.00000","0.39392","2275.42920","-0.00161"
"4.10000","0.40398","2313.12988","-0.00164"
"4.20000","0.41401","2345.80640","-0.00167"
"4.30000","0.42405","2373.76514","-0.00170"
"4.40000","0.43398","2395.77173","-0.00174"
"4.50000","0.44400","2413.41772","-0.00178"
"4.60000","0.45405","2426.89697","-0.00182"
"4.70000","0.46400","2436.45630","-0.00186"
"4.80000","0.47405","2444.19116","-0.00190"
"4.90000","0.48407","2450.00952","-0.00194"
"5.00000","0.49396","2454.85962","-0.00197"
"5.10000","0.50389","2459.47217","-0.00200"
"5.20000","0.51394","2464.63843","-0.00203"
"5.30000","0.52410","2468.69312","-0.00206"
"5.40000","0.53417","2472.63892","-0.00210"
"5.50000","0.54410","2475.89868","-0.00214"
"5.60000","0.55391","2478.40698","-0.00218"
"5.70000","0.56392","2481.06812","-0.00223"
"5.80000","0.57394","2482.88477","-0.00229"
"5.90000","0.58400","2485.74829","-0.00233"
"6.00000","0.59407","2487.67847","-0.00238"
"6.10000","0.60416","2488.32227","-0.00241"
"6.20000","0.61407","2489.99854","-0.00243"
"6.30000","0.62396","2493.46655","-0.00245"
"6.40000","0.63386","2493.66333","-0.00247"
"6.50000","0.64396","2491.38721","-0.00248"
"6.60000","0.65404","2492.96851","-0.00249"
"6.70000","0.66408","2495.51196","-0.00250"
"6.80000","0.67403","2493.82275","-0.00251"
"6.90000","0.68403","2494.51660","-0.00252"
"7.00000","0.69397","2494.35913","-0.00252"
"7.10000","0.70401","2496.44336","-0.00253"
"7.20000","0.71402","2509.42627","-0.00254"
"7.30000","0.72401","2519.00562","-0.00255"
"7.40000","0.73399","2509.91943","-0.00256"
"7.50000","0.74397","2515.56323","-0.00257"
"7.60000","0.75398","2517.08887","-0.00258"
"7.70000","0.76407","2517.95532","-0.00259"
"7.80000","0.77408","2510.64868","-0.00260"
"7.90000","0.78406","2519.32910","-0.00261"
"8.00000","0.79398","2524.39429","-0.00262"
"8.10000","0.80391","2527.22437","-0.00263"
"8.20000","0.81391","2529.49536","-0.00264"
"8.30000","0.82401","2529.67749","-0.00265"
"8.40000","0.83411","2528.06812","-0.00266"
"8.50000","0.84414","2529.63403","-0.00267"
"8.60000","0.85404","2527.22876","-0.00268"
"8.70000","0.86395","2526.78174","-0.00269"
"8.80000","0.87383","2526.50220","-0.00270"
"8.90000","0.88397","2523.16772","-0.00270"
"9.00000","0.89405","2518.22778","-0.00271"
"9.10000","0.90411","2518.96875","-0.00271"
"9.20000","0.91405","2517.29370","-0.00272"
"9.30000","0.92405","2516.75635","-0.00273"
"9.40000","0.93393","2517.94360","-0.00277"
"9.50000","0.94396","2521.25415","-0.00340"
"9.60000","0.95397","2522.25391","-0.00448"
"9.70000","0.96401","2519.67773","-0.00340"
"9.80000","0.97405","2523.47998","-0.00318"
"9.90000","0.98402","2524.82446","-0.00313"
"10.00000","0.99401","2525.86548","-0.00309"
"10.10000","1.00401","2528.60425","-0.00305"
"10.20000","1.01407","2535.82251","-0.00302"
"10.30000","1.02403","2548.66260","-0.00300"
"10.40000","1.03400","2540.73682","-0.00298"
"10.50000","1.04392","2558.22046","-0.00297"
"10.60000","1.05394","2558.13550","-0.00296"
"10.70000","1.06403","2568.44897","-0.00295"
"10.80000","1.07410","2577.90747","-0.00288"
"10.90000","1.08409","2582.47339","-0.00276"
"11.00000","1.09403","2595.59937","-0.00273"
"11.10000","1.10396","2598.14893","-0.00263"
"11.20000","1.11381","2603.59888","-0.00259"
"11.30000","1.12391","2603.70117","-0.00257"
"11.40000","1.13407","2608.84473","-0.00256"
"11.50000","1.14414","2609.84961","-0.00254"
"11.60000","1.15411","2609.69775","-0.00253"
"11.70000","1.16400","2611.41724","-0.00252"
"11.80000","1.17391","2609.81348","-0.00250"
"11.90000","1.18391","2613.18604","-0.00249"
"12.00000","1.19401","2608.92456","-0.00248"
"12.10000","1.20403","2612.27905","-0.00246"
"12.20000","1.21410","2603.65845","-0.00245"
"12.30000","1.22404","2641.02734","-0.00244"
"12.40000","1.23397","2634.50171","-0.00243"
"12.50000","1.24399","2652.32544","-0.00239"
"12.60000","1.25403","2612.67334","-0.00238"
"12.70000","1.26403","2635.16187","-0.00237"
"12.80000","1.27397","2629.66968","-0.00236"
"12.90000","1.28398","2629.51880","-0.00235"
"13.00000","1.29398","2627.80957","-0.00234"
"13.10000","1.30402","2630.34570","-0.00233"
"13.20000","1.31405","2639.94165","-0.00233"
"13.30000","1.32408","2645.63110","-0.00232"
"13.40000","1.33404","2645.78320","-0.00231"
"13.50000","1.34391","2650.27441","-0.00230"
"13.60000","1.35384","2653.71606","-0.00230"
"13.70000","1.36396","2652.91992","-0.00229"
"13.80000","1.37413","2657.81641","-0.00228"
"13.90000","1.38414","2656.96069","-0.00228"
"14.00000","1.39404","2659.15674","-0.00227"
"14.10000","1.40396","2659.13770","-0.00226"
"14.20000","1.41387","2660.34741","-0.00226"
"14.30000","1.42392","2658.47241","-0.00225"
"14.40000","1.43402","2656.96582","-0.00225"
"14.50000","1.44409","2653.32959","-0.00224"
"14.60000","1.45410","2651.91968","-0.00224"
"14.70000","1.46407","2653.03467","-0.00223"
"14.80000","1.47392","2651.91626","-0.00222"
"14.90000","1.48396","2648.31494","-0.00222"
"15.00000","1.49397","2651.53882","-0.00221"
"15.10000","1.50405","2647.34863","-0.00221"
"15.20000","1.51400","2645.85645","-0.00220"
"15.30000","1.52401","2647.52197","-0.00220"
"15.40000","1.53400","2639.03857","-0.00219"
"15.50000","1.54398","2634.26050","-0.00217"
"15.60000","1.55405","2639.76123","-0.00212"
"15.70000","1.56408","2642.14111","-0.00180"
"15.80000","1.57404","2649.42773","-0.00174"
"15.90000","1.58393","2652.92383","-0.00170"
"16.00000","1.59387","2654.04175","-0.00164"
"16.10000","1.60402","2647.29395","-0.00161"
"16.20000","1.61406","2664.12622","-0.00158"
"16.30000","1.62414","2654.82690","-0.00155"
"16.40000","1.63401","2658.76318","-0.00153"
"16.50000","1.64390","2664.33374","-0.00151"
"16.60000","1.65384","2688.37988","-0.00150"
"16.70000","1.66387","2686.01538","-0.00148"
"16.80000","1.67401","2694.78149","-0.00147"
"16.90000","1.68414","2701.20361","-0.00145"
"17.00000","1.69416","2710.13745","-0.00144"
"17.10000","1.70403","2685.15430","-0.00146"
"17.20000","1.71390","2699.26978","-0.00148"
"17.30000","1.72392","2716.56372","-0.00156"
"17.40000","1.73396","2728.97412","-0.00162"
"17.50000","1.74409","2733.78125","-0.00165"
"17.60000","1.75411","2714.39600","-0.00119"
"17.70000","1.76400","2752.96313","-0.00120"
"17.80000","1.77401","2738.98218","-0.00095"
"17.90000","1.78396","2737.99243","-0.00107"
"18.00000","1.79397","2745.70020","-0.00110"
"18.10000","1.80406","2749.83691","-0.00114"
"18.20000","1.81402","2752.03442","-0.00120"
"18.30000","1.82397","2745.29297","-0.00124"
"18.40000","1.83394","2745.84692","-0.00119"
"18.50000","1.84403","2757.62476","-0.00119"
"18.60000","1.85406","2756.26880","-0.00122"
"18.70000","1.86411","2754.88916","-0.00124"
"18.80000","1.87403","2747.64648","-0.00122"
"18.90000","1.88392","2750.25635","-0.00110"
"19.00000","1.89384","2751.10791","-0.00103"
"19.10000","1.90396","2748.38599","-0.00097"
"19.20000","1.91404","2771.77661","-0.00093"
"19.30000","1.92417","2754.75049","-0.00091"
"19.40000","1.93417","2792.13574","-0.00091"
"19.50000","1.94397","2754.09595","-0.00088"
"19.60000","1.95390","2760.56470","-0.00087"
"19.70000","1.96392","2763.72607","-0.00105"
"19.80000","1.97394","2765.21265","-0.00091"
"19.90000","1.98411","2767.15454","-0.00082"
"20.00000","1.99417","2766.46631","-0.00078"
"20.10000","2.00400","2766.91211","-0.00078"
"20.20000","2.01397","2768.45239","-0.00080"
"20.30000","2.02396","2769.60571","-0.00083"
"20.40000","2.03394","2771.65894","-0.00093"
"20.50000","2.04407","2770.56543","-0.00087"
"20.60000","2.05405","2771.39160","-0.00067"
"20.70000","2.06398","2773.73682","-0.00034"
"20.80000","2.07395","2775.32666","-0.00008"
"20.90000","2.08402","2776.28101","0.00005"
"21.00000","2.09399","2778.83081","0.00030"
"21.10000","2.10410","2777.67920","0.00005"
"21.20000","2.11404","2778.56934","-0.00005"
"21.30000","2.12389","2779.84131","-0.00064"
"21.40000","2.13387","2780.15039","-0.00062"
"21.50000","2.14402","2780.08447","-0.00063"
"21.60000","2.15409","2780.53369","-0.00070"
"21.70000","2.16415","2782.52441","-0.00033"
"21.80000","2.17414","2783.33032","-0.00044"
"21.90000","2.18397","2786.58081","-0.00042"
"22.00000","2.19386","2788.38965","-0.00049"
"22.10000","2.20396","2789.98267","-0.00075"
"22.20000","2.21393","2792.40332","-0.00068"
"22.30000","2.22417","2793.22217","-0.00070"
"22.40000","2.23416","2801.18042","-0.00071"
"22.50000","2.24400","2790.54639","-0.00072"
"22.60000","2.25392","2792.01880","-0.00070"
"22.70000","2.26398","2761.19287","-0.00069"
"22.80000","2.27392","2764.69141","-0.00069"
"22.90000","2.28404","2775.02002","-0.00070"
"23.00000","2.29410","2768.18921","-0.00071"
"23.10000","2.30401","2778.93213","-0.00072"
"23.20000","2.31400","2779.06128","-0.00072"
"23.30000","2.32398","2786.37744","-0.00071"
"23.40000","2.33400","2795.53784","-0.00074"
"23.50000","2.34406","2799.38086","-0.00075"
"23.60000","2.35406","2804.14380","-0.00075"
"23.70000","2.36388","2773.87012","-0.00076"
"23.80000","2.37393","2819.12134","-0.00076"
"23.90000","2.38400","2808.50928","-0.00076"
"24.00000","2.39407","2808.60791","-0.00076"
"24.10000","2.40413","2801.89648","-0.00076"
"24.20000","2.41408","2816.63110","-0.00076"
"24.30000","2.42394","2821.15039","-0.00076"
"24.40000","2.43388","2826.77197","-0.00077"
"24.50000","2.44394","2838.01807","-0.00077"
"24.60000","2.45401","2847.42725","-0.00077"
"24.70000","2.46417","2841.10742","-0.00077"
"24.80000","2.47415","2813.04688","-0.00077"
"24.90000","2.48396","2819.23413","-0.00077"
"25.00000","2.49392","2827.09277","-0.00077"
"25.10000","2.50394","2830.32690","-0.00078"
"25.20000","2.51395","2844.20459","-0.00078"
"25.30000","2.52401","2857.78491","-0.00078"
"25.40000","2.53415","2864.49561","-0.00078"
"25.50000","2.54404","2864.13477","-0.00078"
"25.60000","2.55400","2859.95117","-0.00078"
"25.70000","2.56392","2857.17163","-0.00078"
"25.80000","2.57400","2883.74243","-0.00078"
"25.90000","2.58403","2897.86914","-0.00078"
"26.00000","2.59407","2883.24243","-0.00078"
"26.10000","2.60398","2869.23730","-0.00078"
"26.20000","2.61394","2880.87085","-0.00078"
"26.30000","2.62406","2895.67896","-0.00078"
"26.40000","2.63403","2889.22534","-0.00078"
"26.50000","2.64408","2877.49365","-0.00078"
"26.60000","2.65405","2879.60034","-0.00078"
"26.70000","2.66396","2878.53638","-0.00078"
"26.80000","2.67390","2885.35791","-0.00078"
"26.90000","2.68398","2890.54199","-0.00078"
"27.00000","2.69404","2884.93237","-0.00079"
"27.10000","2.70413","2883.82227","-0.00078"
"27.20000","2.71414","2889.84253","-0.00079"
"27.30000","2.72395","2867.08618","-0.00078"
"27.40000","2.73388","2895.35791","-0.00079"
"27.50000","2.74393","2910.94824","-0.00079"
"27.60000","2.75399","2853.24536","-0.00078"
"27.70000","2.76407","2889.50879","-0.00079"
"27.80000","2.77416","2903.81616","-0.00079"
"27.90000","2.78407","2931.09106","-0.00079"
"28.00000","2.79395","2892.94971","-0.00078"
"28.10000","2.80390","2889.39478","-0.00079"
"28.20000","2.81395","2912.22046","-0.00079"
"28.30000","2.82402","2903.26636","-0.00079"
"28.40000","2.83407","2895.09424","-0.00078"
"28.50000","2.84404","2892.71777","-0.00078"
"28.60000","2.85398","2909.87744","-0.00078"
"28.70000","2.86402","2910.95850","-0.00078"
"28.80000","2.87399","2908.01050","-0.00078"
"28.90000","2.88402","2902.51733","-0.00078"
"29.00000","2.89406","2896.76758","-0.00078"
"29.10000","2.90397","2897.36475","-0.00078"
"29.20000","2.91395","2905.58716","-0.00079"
"29.30000","2.92400","2908.90796","-0.00082"
"29.40000","2.93410","2910.67261","-0.00085"
"29.50000","2.94410","2910.50171","-0.00087"
"29.60000","2.95403","2907.24951","-0.00086"
"29.70000","2.96396","2905.07812","-0.00084"
"29.80000","2.97393","2907.31250","-0.00083"
"29.90000","2.98393","2898.32690","-0.00082"
"30.00000","2.99398","2906.51929","-0.00082"
"30.10000","3.00406","2939.82397","-0.00082"
"30.20000","3.01416","2892.18408","-0.00081"
"30.30000","3.02404","2920.00854","-0.00081"
"30.40000","3.03396","2923.61670","-0.00081"
"30.50000","3.04388","2911.85840","-0.00081"
"30.60000","3.05394","2904.24854","-0.00081"
"30.70000","3.06401","2905.54321","-0.00081"
"30.80000","3.07412","2922.84155","-0.00081"
"30.90000","3.08406","2927.02808","-0.00081"
"31.00000","3.09403","2918.64478","-0.00081"
"31.10000","3.10395","2914.03735","-0.00081"
"31.20000","3.11399","2915.95410","-0.00081"
"31.30000","3.12400","2918.39966","-0.00080"
"31.40000","3.13401","2922.15430","-0.00081"
"31.50000","3.14399","2925.06470","-0.00081"
"31.60000","3.15404","2922.47754","-0.00080"
"31.70000","3.16400","2921.76782","-0.00080"
"31.80000","3.17406","2930.78979","-0.00080"
"31.90000","3.18407","2929.79468","-0.00080"
"32.00000","3.19404","2931.91699","-0.00080"
"32.10000","3.20400","2925.58716","-0.00080"
"32.20000","3.21390","2931.51099","-0.00080"
"32.30000","3.22391","2925.28442","-0.00080"
"32.40000","3.23401","2908.88794","-0.00080"
"32.50000","3.24405","2940.24365","-0.00080"
"32.60000","3.25409","2945.68750","-0.00080"
"32.70000","3.26400","2938.14062","-0.00080"
"32.80000","3.27390","2941.89648","-0.00081"
"32.90000","3.28381","2941.97900","-0.00081"
"33.00000","3.29395","2939.85669","-0.00081"
"33.10000","3.30404","2950.50562","-0.00081"
"33.20000","3.31414","2958.34253","-0.00081"
"33.30000","3.32408","2948.93506","-0.00081"
"33.40000","3.33400","2945.66382","-0.00081"
"33.50000","3.34394","2941.41748","-0.00081"
"33.60000","3.35396","2932.26270","-0.00081"
"33.70000","3.36402","2923.52490","-0.00081"
"33.80000","3.37404","2911.61914","-0.00081"
"33.90000","3.38409","2905.81348","-0.00081"
"34.00000","3.39404","2905.67212","-0.00081"
"34.10000","3.40396","2935.32300","-0.00081"
"34.20000","3.41399","2919.91187","-0.00081"
"34.30000","3.42404","2943.23706","-0.00081"
"34.40000","3.43403","2977.11011","-0.00081"
"34.50000","3.44400","2941.19482","-0.00081"
"34.60000","3.45392","2993.67505","-0.00081"
"34.70000","3.46396","2995.20776","-0.00081"
"34.80000","3.47403","3008.46997","-0.00081"
"34.90000","3.48407","3004.29175","-0.00081"
"35.00000","3.49411","2926.45068","-0.00081"
"35.10000","3.50401","2974.31445","-0.00081"
"35.20000","3.51398","2955.25781","-0.00081"
"35.30000","3.52381","2947.33472","-0.00081"
"35.40000","3.53394","2979.01904","-0.00081"
"35.50000","3.54409","2980.49316","-0.00081"
"35.60000","3.55416","2968.61987","-0.00081"
"35.70000","3.56404","2991.58716","-0.00081"
"35.80000","3.57394","2997.29565","-0.00081"
"35.90000","3.58390","2978.45923","-0.00081"
"36.00000","3.59391","2978.20654","-0.00081"
"36.10000","3.60405","3013.84180","-0.00081"
"36.20000","3.61406","3009.69189","-0.00081"
"36.30000","3.62412","2991.92480","-0.00081"
"36.40000","3.63404","3013.62646","-0.00081"
"36.50000","3.64395","3022.85522","-0.00082"
"36.60000","3.65398","3010.11719","-0.00081"
"36.70000","3.66399","2991.69824","-0.00081"
"36.80000","3.67403","3012.69897","-0.00081"
"36.90000","3.68401","3012.63232","-0.00081"
"37.00000","3.69400","2995.16235","-0.00081"
"37.10000","3.70397","2997.49170","-0.00081"
"37.20000","3.71399","3010.97363","-0.00081"
"37.30000","3.72402","2985.03638","-0.00081"
"37.40000","3.73408","3026.77930","-0.00082"
"37.50000","3.74400","3005.77515","-0.00081"
"37.60000","3.75391","2993.03223","-0.00081"
"37.70000","3.76384","3023.50659","-0.00081"
"37.80000","3.77403","3005.18530","-0.00081"
"37.90000","3.78414","2976.60449","-0.00081"
"38.00000","3.79414","3030.96411","-0.00082"
"38.10000","3.80403","2996.88403","-0.00081"
"38.20000","3.81393","3038.84863","-0.00082"
"38.30000","3.82389","3036.75244","-0.00082"
"38.40000","3.83391","3005.99780","-0.00081"
"38.50000","3.84399","2994.48828","-0.00081"
"38.60000","3.85413","3013.07788","-0.00081"
"38.70000","3.86415","3016.11255","-0.00081"
"38.80000","3.87402","3051.44312","-0.00082"
"38.90000","3.88389","3062.61328","-0.00082"
"39.00000","3.89394","3000.71069","-0.00081"
"39.10000","3.90395","3039.35474","-0.00082"
"39.20000","3.91407","3046.37207","-0.00082"
"39.30000","3.92405","3086.51050","-0.00082"
"39.40000","3.93404","2987.82910","-0.00081"
"39.50000","3.94399","3033.18140","-0.00081"
"39.60000","3.95399","2999.32568","-0.00081"
"39.70000","3.96397","3017.99951","-0.00081"
"39.80000","3.97408","3028.49707","-0.00081"
"39.90000","3.98403","3007.17310","-0.00081"
"40.00000","3.99392","3008.60938","-0.00081"
"40.10000","4.00388","3036.62866","-0.00081"
"40.20000","4.01402","3017.74316","-0.00081"
"40.30000","4.02404","3003.80762","-0.00081"
"40.40000","4.03412","3036.10107","-0.00081"
"40.50000","4.04409","3025.32764","-0.00081"
"40.60000","4.05394","3003.69287","-0.00081"
"40.70000","4.06386","3033.73926","-0.00081"
"40.80000","4.07398","3029.53027","-0.00081"
"40.90000","4.08402","3005.58179","-0.00081"
"41.00000","4.09420","3024.41187","-0.00081"
"41.10000","4.10415","3034.13452","-0.00081"
"41.20000","4.11399","3010.42407","-0.00085"
"41.30000","4.12387","3015.65649","-0.00084"
"41.40000","4.13393","3038.06567","-0.00078"
"41.50000","4.14395","3014.50464","-0.00079"
"41.60000","4.15408","3013.79907","-0.00079"
"41.70000","4.16413","3041.79980","-0.00079"
"41.80000","4.17397","3012.80054","-0.00078"
"41.90000","4.18400","3026.32886","-0.00077"
"42.00000","4.19393","3050.57544","-0.00077"
"42.10000","4.20399","3022.91772","-0.00077"
"42.20000","4.21406","3023.44946","-0.00077"
"42.30000","4.22403","3049.46313","-0.00077"
"42.40000","4.23399","3026.74268","-0.00077"
"42.50000","4.24396","3019.06006","-0.00076"
"42.60000","4.25405","3053.46875","-0.00076"
"42.70000","4.26403","3026.73218","-0.00076"
"42.80000","4.27406","3031.48804","-0.00076"
"42.90000","4.28402","3049.80347","-0.00077"
"43.00000","4.29394","3021.31177","-0.00076"
"43.10000","4.30387","3045.22632","-0.00077"
"43.20000","4.31400","3045.92456","-0.00076"
"43.30000","4.32408","3021.65405","-0.00076"
"43.40000","4.33415","3043.95923","-0.00076"
"43.50000","4.34415","3046.49390","-0.00077"
"43.60000","4.35394","3021.93774","-0.00076"
"43.70000","4.36389","3047.96948","-0.00076"
"43.80000","4.37393","3046.74609","-0.00077"
"43.90000","4.38395","3024.06982","-0.00076"
"44.00000","4.39414","3060.84814","-0.00077"
"44.10000","4.40418","3047.78369","-0.00076"
"44.20000","4.41399","3033.58667","-0.00076"
"44.30000","4.42393","3057.00830","-0.00076"
"44.40000","4.43394","3041.91895","-0.00076"
"44.50000","4.44394","3033.83911","-0.00076"
"44.60000","4.45405","3067.88379","-0.00076"
"44.70000","4.46406","3045.48901","-0.00076"
"44.80000","4.47400","3070.21289","-0.00076"
"44.90000","4.48395","3066.56201","-0.00077"
"45.00000","4.49402","3053.99365","-0.00076"
"45.10000","4.50403","3085.69727","-0.00077"
"45.20000","4.51411","3027.89111","-0.00076"
"45.30000","4.52405","3075.76221","-0.00076"
"45.40000","4.53390","3068.83008","-0.00076"
"45.50000","4.54389","3088.96606","-0.00076"
"45.60000","4.55404","3078.87134","-0.00076"
"45.70000","4.56407","3057.81421","-0.00076"
"45.80000","4.57414","3058.67261","-0.00076"
"45.90000","4.58415","3093.26025","-0.00076"
"46.00000","4.59393","3074.93066","-0.00076"
"46.10000","4.60385","3107.48267","-0.00076"
"46.20000","4.61394","3054.50146","-0.00076"
"46.30000","4.62399","3059.73340","-0.00076"
"46.40000","4.63417","3074.97070","-0.00076"
"46.50000","4.64418","3072.51489","-0.00076"
"46.60000","4.65395","3111.14966","-0.00076"
"46.70000","4.66393","3040.98022","-0.00076"
"46.80000","4.67397","3024.15308","-0.00076"
"46.90000","4.68396","3059.71875","-0.00076"
"47.00000","4.69405","3037.51489","-0.00076"
"47.10000","4.70413","3018.33521","-0.00076"
"47.20000","4.71402","3060.39697","-0.00076"
"47.30000","4.72400","3041.75049","-0.00076"
"47.40000","4.73396","3028.57764","-0.00076"
"47.50000","4.74397","3066.57251","-0.00076"
"47.60000","4.75401","3047.81934","-0.00076"
"47.70000","4.76411","3039.19019","-0.00076"
"47.80000","4.77392","3072.26880","-0.00076"
"47.90000","4.78398","3040.84595","-0.00076"
"48.00000","4.79405","3075.08618","-0.00076"
"48.10000","4.80405","3067.92383","-0.00076"
"48.20000","4.81408","3092.10913","-0.00077"
"48.30000","4.82408","3085.58911","-0.00076"
"48.40000","4.83393","3095.12329","-0.00077"
"48.50000","4.84388","3095.17847","-0.00077"
"48.60000","4.85393","3081.27100","-0.00076"
"48.70000","4.86403","3107.14331","-0.00077"
"48.80000","4.87412","3114.12866","-0.00077"
"48.90000","4.88412","3108.67700","-0.00077"
"49.00000","4.89394","3142.99683","-0.00077"
"49.10000","4.90393","3117.33984","-0.00077"
"49.20000","4.91393","3141.09595","-0.00077"
"49.30000","4.92397","3115.79761","-0.00077"
"49.40000","4.93405","3131.44653","-0.00077"
"49.50000","4.94418","3123.15747","-0.00077"
"49.60000","4.95406","3130.69971","-0.00077"
"49.70000","4.96402","3041.55005","-0.00076"
"49.80000","4.97392","3096.27100","-0.00077"
"49.90000","4.98400","3062.25562","-0.00077"
"50.00000","4.99400","3071.61108","-0.00077"
"50.10000","5.00409","3088.80908","-0.00077"
"50.20000","5.01398","3060.92773","-0.00077"
"50.30000","5.02398","3109.89209","-0.00077"
"50.40000","5.03406","3079.32910","-0.00077"
"50.50000","5.04401","3092.39600","-0.00077"
"50.60000","5.05403","3100.74609","-0.00077"
"50.70000","5.06405","3068.80029","-0.00077"
"50.80000","5.07396","3118.23364","-0.00077"
"50.90000","5.08394","3092.31738","-0.00077"
"51.00000","5.09398","3112.76685","-0.00077"
"51.10000","5.10408","3115.45752","-0.00077"
"51.20000","5.11413","3080.94800","-0.00077"
"51.30000","5.12410","3129.50610","-0.00077"
"51.40000","5.13394","3096.29785","-0.00077"
"51.50000","5.14392","3133.23950","-0.00077"
"51.60000","5.15392","3111.61841","-0.00077"
"51.70000","5.16402","3090.27686","-0.00077"
"51.80000","5.17406","3127.84863","-0.00077"
"51.90000","5.18417","3092.97656","-0.00077"
"52.00000","5.19404","3123.54297","-0.00077"
"52.10000","5.20395","3102.28638","-0.00077"
"52.20000","5.21387","3111.32959","-0.00077"
"52.30000","5.22396","3128.96362","-0.00077"
"52.40000","5.23401","3086.22339","-0.00077"
"52.50000","5.24408","3117.88574","-0.00077"
"52.60000","5.25409","3092.69409","-0.00077"
"52.70000","5.26402","3135.03320","-0.00077"
"52.80000","5.27399","3093.07495","-0.00077"
"52.90000","5.28395","3135.00586","-0.00077"
"53.00000","5.29402","3102.37598","-0.00077"
"53.10000","5.30404","3123.61206","-0.00077"
"53.20000","5.31398","3110.48584","-0.00077"
"53.30000","5.32400","3112.10425","-0.00077"
"53.40000","5.33397","3101.06567","-0.00076"
"53.50000","5.34408","3117.78760","-0.00077"
"53.60000","5.35408","3112.85327","-0.00076"
"53.70000","5.36405","3098.64233","-0.00077"
"53.80000","5.37394","3132.10010","-0.00077"
"53.90000","5.38397","3103.70557","-0.00077"
"54.00000","5.39391","3152.30859","-0.00077"
"54.10000","5.40403","3120.05396","-0.00077"
"54.20000","5.41408","3165.25000","-0.00077"
"54.30000","5.42411","3139.98169","-0.00077"
"54.40000","5.43407","3084.17407","-0.00077"
"54.50000","5.44394","3119.21387","-0.00077"
"54.60000","5.45383","3090.43628","-0.00077"
"54.70000","5.46393","3142.87573","-0.00077"
"54.80000","5.47405","3115.11621","-0.00077"
"54.90000","5.48411","3162.25854","-0.00077"
"55.00000","5.49409","3081.48608","-0.00077"
"55.10000","5.50400","3117.10498","-0.00077"
"55.20000","5.51392","3081.66382","-0.00077"
"55.30000","5.52396","3129.08398","-0.00077"
"55.40000","5.53400","3093.43726","-0.00076"
"55.50000","5.54401","3132.27661","-0.00077"
"55.60000","5.55405","3110.76343","-0.00076"
"55.70000","5.56407","3102.64014","-0.00077"
"55.80000","5.57396","3123.44775","-0.00076"
"55.90000","5.58402","3089.72559","-0.00077"
"56.00000","5.59403","3136.87256","-0.00077"
"56.10000","5.60403","3098.32910","-0.00077"
"56.20000","5.61399","3145.77026","-0.00077"
"56.30000","5.62395","3113.43555","-0.00077"
"56.40000","5.63396","3110.65112","-0.00077"
"56.50000","5.64402","3128.42212","-0.00077"
"56.60000","5.65410","3092.43286","-0.00078"
"56.70000","5.66408","3140.83179","-0.00078"
"56.80000","5.67404","3100.25659","-0.00079"
"56.90000","5.68395","3150.90723","-0.00078"
"57.00000","5.69381","3111.58472","-0.00079"
"57.10000","5.70396","3130.51611","-0.00080"
"57.20000","5.71409","3125.94287","-0.00080"
"57.30000","5.72413","3093.49341","-0.00080"
"57.40000","5.73406","3137.05273","-0.00079"
"57.50000","5.74400","3098.88647","-0.00079"
"57.60000","5.75388","3149.08179","-0.00079"
"57.70000","5.76394","3111.34839","-0.00079"
"57.80000","5.77399","3154.03442","-0.00079"
"57.90000","5.78403","3103.60327","-0.00079"
"58.00000","5.79412","3143.69287","-0.00079"
"58.10000","5.80407","3107.18945","-0.00079"
"58.20000","5.81395","3155.78101","-0.00079"
"58.30000","5.82394","3117.14233","-0.00079"
"58.40000","5.83401","3143.32178","-0.00079"
"58.50000","5.84405","3127.09351","-0.00079"
"58.60000","5.85403","3111.38672","-0.00079"
"58.70000","5.86397","3138.39307","-0.00079"
"58.80000","5.87398","3102.49023","-0.00079"
"58.90000","5.88402","3149.15479","-0.00079"
"59.00000","5.89408","3107.54858","-0.00079"
"59.10000","5.90405","3157.08521","-0.00079"
"59.20000","5.91404","3117.12500","-0.00079"
"59.30000","5.92395","3150.52905","-0.00079"
"59.40000","5.93383","3130.24976","-0.00079"
"59.50000","5.94397","3124.23828","-0.00079"
"59.60000","5.95411","3127.60840","-0.00078"
"59.70000","5.96413","3119.30786","-0.00078"
"59.80000","5.97407","3135.01318","-0.00078"
"59.90000","5.98393","3121.49365","-0.00078"
"60.00000","5.99389","3138.83472","-0.00078"
"60.10000","6.00388","3133.09814","-0.00078"
"60.20000","6.01404","3130.85474","-0.00078"
"60.30000","6.02410","3127.63867","-0.00078"
"60.40000","6.03415","3149.01538","-0.00078"
"60.50000","6.04405","3117.38184","-0.00078"
"60.60000","6.05391","3144.12427","-0.00078"
"60.70000","6.06398","3120.11597","-0.00078"
"60.80000","6.07395","3165.12964","-0.00078"
"60.90000","6.08410","3124.26294","-0.00078"
"61.00000","6.09399","3173.07983","-0.00078"
"61.10000","6.10404","3111.44263","-0.00078"
"61.20000","6.11397","3160.43384","-0.00078"
"61.30000","6.12398","3124.50610","-0.00078"
"61.40000","6.13399","3175.41650","-0.00078"
"61.50000","6.14410","3130.69971","-0.00078"
"61.60000","6.15402","3181.53125","-0.00078"
"61.70000","6.16395","3134.91772","-0.00078"
"61.80000","6.17386","3180.65552","-0.00078"
"61.90000","6.18403","3138.45605","-0.00078"
"62.00000","6.19411","3164.53052","-0.00078"
"62.10000","6.20411","3162.92944","-0.00079"
"62.20000","6.21402","3167.76196","-0.00078"
"62.30000","6.22389","3166.16919","-0.00078"
"62.40000","6.23387","3167.26465","-0.00078"
"62.50000","6.24393","3185.90967","-0.00079"
"62.60000","6.25406","3167.30029","-0.00079"
"62.70000","6.26416","3195.82935","-0.00079"
"62.80000","6.27415","3132.03003","-0.00078"
"62.90000","6.28401","3167.47900","-0.00078"
"63.00000","6.29387","3188.81763","-0.00079"
"63.10000","6.30394","3153.98413","-0.00078"
"63.20000","6.31392","3194.80811","-0.00079"
"63.30000","6.32410","3174.16528","-0.00079"
"63.40000","6.33410","3177.52222","-0.00079"
"63.50000","6.34402","3156.64673","-0.00079"
"63.60000","6.35396","3173.55664","-0.00079"
"63.70000","6.36393","3156.15527","-0.00079"
"63.80000","6.37399","3183.78125","-0.00079"
"63.90000","6.38406","3209.15552","-0.00079"
"64.00000","6.39407","3164.48706","-0.00079"
"64.10000","6.40392","3203.90308","-0.00079"
"64.20000","6.41397","3153.77930","-0.00079"
"64.30000","6.42403","3196.17725","-0.00079"
"64.40000","6.43406","3143.94336","-0.00079"
"64.50000","6.44409","3168.11865","-0.00079"
"64.60000","6.45400","3208.94458","-0.00079"
"64.70000","6.46389","3149.48071","-0.00079"
"64.80000","6.47385","3192.84131","-0.00079"
"64.90000","6.48394","3148.33569","-0.00079"
"65.00000","6.49402","3177.02026","-0.00079"
"65.10000","6.50421","3160.16333","-0.00079"
"65.20000","6.51415","3169.40967","-0.00079"
"65.30000","6.52397","3160.24170","-0.00079"
"65.40000","6.53386","3153.84985","-0.00079"
"65.50000","6.54391","3170.05469","-0.00079"
"65.60000","6.55398","3148.75391","-0.00079"
"65.70000","6.56411","3170.36816","-0.00079"
"65.80000","6.57418","3166.48291","-0.00079"
"65.90000","6.58398","3166.69458","-0.00079"
"66.00000","6.59398","3131.41040","-0.00079"
"66.10000","6.60395","3176.18799","-0.00079"
"66.20000","6.61396","3131.77661","-0.00079"
"66.30000","6.62403","3136.59546","-0.00079"
"66.40000","6.63406","3145.92188","-0.00079"
"66.50000","6.64402","3111.38306","-0.00079"
"66.60000","6.65397","3157.40991","-0.00079"
"66.70000","6.66405","3118.31348","-0.00079"
"66.80000","6.67397","3167.52905","-0.00079"
"66.90000","6.68411","3130.42773","-0.00079"
"67.00000","6.69402","3164.11157","-0.00079"
"67.10000","6.70392","3139.88257","-0.00079"
"67.20000","6.71389","3148.15186","-0.00079"
"67.30000","6.72403","3149.09448","-0.00079"
"67.40000","6.73408","3133.40576","-0.00079"
"67.50000","6.74415","3157.53784","-0.00079"
"67.60000","6.75412","3127.82642","-0.00079"
"67.70000","6.76393","3160.56934","-0.00079"
"67.80000","6.77390","3117.23413","-0.00079"
"67.90000","6.78392","3166.35107","-0.00079"
"68.00000","6.79399","3152.58911","-0.00079"
"68.10000","6.80414","3163.06836","-0.00079"
"68.20000","6.81417","3163.48560","-0.00079"
"68.30000","6.82396","3164.61816","-0.00079"
"68.40000","6.83394","3163.96094","-0.00079"
"68.50000","6.84396","3149.24902","-0.00079"
"68.60000","6.85393","3156.72412","-0.00079"
"68.70000","6.86407","3152.76050","-0.00079"
"68.80000","6.87410","3162.07446","-0.00079"
"68.90000","6.88405","3162.01758","-0.00079"
"69.00000","6.89395","3145.68140","-0.00079"
"69.10000","6.90398","3171.32544","-0.00079"
"69.20000","6.91401","3136.19067","-0.00079"
"69.30000","6.92403","3173.67285","-0.00079"
"69.40000","6.93407","3134.79297","-0.00079"
"69.50000","6.94389","3174.61230","-0.00079"
"69.60000","6.95398","3134.41528","-0.00079"
"69.70000","6.96403","3177.16089","-0.00079"
"69.80000","6.97407","3139.77124","-0.00079"
"69.90000","6.98409","3178.00708","-0.00079"
"70.00000","6.99411","3141.42139","-0.00079"
"70.10000","7.00396","3177.90723","-0.00079"
"70.20000","7.01388","3142.83472","-0.00079"
"70.30000","7.02393","3179.94312","-0.00079"
"70.40000","7.03402","3142.92920","-0.00079"
"70.50000","7.04417","3182.12354","-0.00079"
"70.60000","7.05414","3143.99683","-0.00079"
"70.70000","7.06394","3183.24561","-0.00079"
"70.80000","7.07390","3149.10742","-0.00079"
"70.90000","7.08396","3185.61597","-0.00079"
"71.00000","7.09396","3182.37085","-0.00079"
"71.10000","7.10404","3178.68359","-0.00079"
"71.20000","7.11414","3170.67847","-0.00079"
"71.30000","7.12403","3197.51025","-0.00079"
"71.40000","7.13401","3169.79932","-0.00079"
"71.50000","7.14392","3216.17822","-0.00080"
"71.60000","7.15399","3167.33789","-0.00080"
"71.70000","7.16400","3218.32495","-0.00080"
"71.80000","7.17409","3172.34839","-0.00080"
"71.90000","7.18396","3211.40210","-0.00080"
"72.00000","7.19400","3197.52954","-0.00080"
"72.10000","7.20402","3209.03516","-0.00080"
"72.20000","7.21401","3192.49487","-0.00080"
"72.30000","7.22407","3186.90771","-0.00080"
"72.40000","7.23408","3141.46021","-0.00079"
"72.50000","7.24394","3183.56055","-0.00080"
"72.60000","7.25392","3158.87109","-0.00079"
"72.70000","7.26399","3191.96021","-0.00080"
"72.80000","7.27408","3156.09570","-0.00079"
"72.90000","7.28413","3202.63916","-0.00080"
"73.00000","7.29409","3155.29590","-0.00079"
"73.10000","7.30393","3204.46191","-0.00080"
"73.20000","7.31394","3150.17139","-0.00079"
"73.30000","7.32391","3202.73901","-0.00079"
"73.40000","7.33400","3147.13037","-0.00079"
"73.50000","7.34403","3200.80078","-0.00080"
"73.60000","7.35419","3145.47192","-0.00079"
"73.70000","7.36404","3198.62524","-0.00080"
"73.80000","7.37399","3142.88135","-0.00079"
"73.90000","7.38386","3194.34473","-0.00079"
"74.00000","7.39398","3143.33301","-0.00079"
"74.10000","7.40399","3192.52417","-0.00079"
"74.20000","7.41411","3146.03296","-0.00079"
"74.30000","7.42404","3187.21094","-0.00079"
"74.40000","7.43399","3191.19531","-0.00079"
"74.50000","7.44402","3168.79980","-0.00079"
"74.60000","7.45399","3172.44751","-0.00079"
"74.70000","7.46402","3201.42700","-0.00079"
"74.80000","7.47406","3130.19946","-0.00079"
"74.90000","7.48397","3176.31299","-0.00079"
"75.00000","7.49399","3125.50244","-0.00079"
"75.10000","7.50399","3167.97974","-0.00079"
"75.20000","7.51406","3182.68994","-0.00079"
"75.30000","7.52410","3151.47754","-0.00079"
"75.40000","7.53409","3196.47705","-0.00079"
"75.50000","7.54395","3145.13623","-0.00079"
"75.60000","7.55390","3195.55615","-0.00079"
"75.70000","7.56393","3134.49683","-0.00079"
"75.80000","7.57401","3186.01587","-0.00079"
"75.90000","7.58410","3170.69751","-0.00079"
"76.00000","7.59414","3169.25244","-0.00079"
"76.10000","7.60405","3213.52637","-0.00079"
"76.20000","7.61394","3148.48535","-0.00079"
"76.30000","7.62385","3198.59912","-0.00079"
"76.40000","7.63396","3136.37842","-0.00079"
"76.50000","7.64405","3185.12891","-0.00079"
"76.60000","7.65412","3152.64087","-0.00079"
"76.70000","7.66408","3163.39844","-0.00079"
"76.80000","7.67399","3203.17041","-0.00079"
"76.90000","7.68397","3143.80566","-0.00079"
"77.00000","7.69396","3191.17114","-0.00079"
"77.10000","7.70401","3123.53760","-0.00079"
"77.20000","7.71404","3174.49097","-0.00079"
"77.30000","7.72405","3106.15039","-0.00078"
"77.40000","7.73405","3156.89478","-0.00079"
"77.50000","7.74399","3092.33472","-0.00078"
"77.60000","7.75402","3138.87817","-0.00079"
"77.70000","7.76406","3079.15747","-0.00078"
"77.80000","7.77398","3124.97168","-0.00079"
"77.90000","7.78399","3064.97095","-0.00078"
"78.00000","7.79392","3111.43481","-0.00078"
"78.10000","7.80398","3058.00366","-0.00078"
"78.20000","7.81401","3051.30029","-0.00078"
"78.30000","7.82409","3054.80688","-0.00078"
"78.40000","7.83410","3008.25879","-0.00078"
"78.50000","7.84403","3019.43701","-0.00078"
"78.60000","7.85398","3006.18701","-0.00078"
"78.70000","7.86385","2966.19946","-0.00078"
"78.80000","7.87395","2949.77417","-0.00078"
"78.90000","7.88404","2952.01123","-0.00078"
"79.00000","7.89417","2928.60986","-0.00078"
"79.10000","7.90409","2898.66382","-0.00078"
"79.20000","7.91401","2871.79004","-0.00078"
"79.30000","7.92391","2850.80347","-0.00078"
"79.40000","7.93394","2829.16113","-0.00078"
"79.50000","7.94398","2802.85254","-0.00078"
"79.60000","7.95403","2772.22852","-0.00078"
"79.70000","7.96410","2740.71069","-0.00078"
"79.80000","7.97406","2708.68823","-0.00078"
"79.90000","7.98399","2674.81421","-0.00078"
"80.00000","7.99399","2637.75464","-0.00078"
"80.10000","8.00405","2596.90405","-0.00077"
"80.20000","8.01403","2550.44873","-0.00077"
"80.30000","8.02403","2498.31152","-0.00077"
"80.40000","8.03397","2438.27173","-0.00077"
"80.50000","8.04398","2364.44873","-0.00077"
"80.56300","8.05030","1413.51562","-0.00076"