File: archive/undergrad/433/Concentration/Specimen_RawData_4.csv
Time,Extension,Load,Strain Gage18
(s),(mm),(N),(mm/mm)
"0.00000","0.00000","983.31226","0.00036"
"0.30000","0.02385","1349.74780","0.00048"
"0.60000","0.05405","1746.65393","0.00061"
"0.90000","0.08399","2118.42065","0.00073"
"1.20000","0.11395","2481.45435","0.00085"
"1.50000","0.14408","2838.73315","0.00096"
"1.80000","0.17394","3184.82935","0.00108"
"2.10000","0.20406","3529.57056","0.00119"
"2.40000","0.23399","3867.23877","0.00130"
"2.70000","0.26402","4200.89014","0.00141"
"3.00000","0.29402","4530.80811","0.00152"
"3.30000","0.32399","4855.68506","0.00163"
"3.60000","0.35403","5177.58643","0.00173"
"3.90000","0.38401","5496.98193","0.00184"
"4.20000","0.41393","5810.55859","0.00194"
"4.50000","0.44411","6121.93457","0.00205"
"4.80000","0.47396","6424.40820","0.00215"
"5.10000","0.50407","6725.69775","0.00225"
"5.40000","0.53400","7021.68066","0.00235"
"5.70000","0.56397","7313.17529","0.00245"
"6.00000","0.59409","7598.29932","0.00254"
"6.30000","0.62401","7861.79883","0.00263"
"6.60000","0.65395","8109.57910","0.00272"
"6.90000","0.68412","8360.59961","0.00281"
"7.20000","0.71396","8605.94238","0.00290"
"7.50000","0.74409","8854.50879","0.00299"
"7.80000","0.77399","9099.09570","0.00308"
"8.10000","0.80399","9342.80664","0.00317"
"8.40000","0.83403","9584.33496","0.00326"
"8.70000","0.86399","9821.36328","0.00336"
"9.00000","0.89403","10053.91602","0.00345"
"9.30000","0.92405","10279.64648","0.00354"
"9.60000","0.95403","10496.14551","0.00364"
"9.90000","0.98410","10709.83594","0.00374"
"10.20000","1.01397","10912.52148","0.00384"
"10.50000","1.04404","11111.11719","0.00395"
"10.80000","1.07407","11298.71680","0.00407"
"11.10000","1.10404","11476.63379","0.00418"
"11.40000","1.13409","11643.19727","0.00431"
"11.70000","1.16403","11798.95996","0.00444"
"12.00000","1.19403","11944.44238","0.00457"
"12.30000","1.22413","12080.34570","0.00470"
"12.60000","1.25398","12195.42676","0.00484"
"12.90000","1.28407","12299.68848","0.00498"
"13.20000","1.31408","12392.60645","0.00515"
"13.50000","1.34397","12491.03027","0.00533"
"13.80000","1.37413","12583.06250","0.00550"
"14.10000","1.40396","12670.58691","0.00567"
"14.40000","1.43408","12753.54883","0.00585"
"14.70000","1.46409","12835.90234","0.00602"
"15.00000","1.49403","12909.79785","0.00619"
"15.30000","1.52404","12986.42480","0.00637"
"15.60000","1.55410","13057.06055","0.00654"
"15.90000","1.58398","13125.80957","0.00672"
"16.20000","1.61411","13193.00977","0.00689"
"16.50000","1.64397","13255.76270","0.00706"
"16.80000","1.67415","13317.90234","0.00723"
"17.10000","1.70403","13377.14941","0.00081"
"17.40000","1.73410","13432.37500","0.00077"
"17.70000","1.76401","13488.35645","0.00076"
"18.00000","1.79408","13540.53906","0.00075"
"18.30000","1.82405","13591.92383","0.00075"
"18.60000","1.85409","13640.19336","0.00075"
"18.90000","1.88394","13687.26758","0.00075"
"19.20000","1.91420","13734.33789","0.00075"
"19.50000","1.94401","13778.36328","0.00076"
"19.80000","1.97410","13820.09961","0.00077"
"20.10000","2.00402","13862.29199","0.00077"
"20.40000","2.03408","13901.73633","0.00078"
"20.70000","2.06408","13942.89453","0.00079"
"21.00000","2.09409","13978.90625","0.00080"
"21.30000","2.12395","14015.43652","0.00081"
"21.60000","2.15422","14053.59473","0.00081"
"21.90000","2.18397","14087.05664","0.00082"
"22.20000","2.21412","14121.47168","0.00083"
"22.50000","2.24399","14154.93066","0.00084"
"22.80000","2.27408","14187.06348","0.00085"
"23.10000","2.30406","14220.74609","0.00085"
"23.40000","2.33412","14250.91797","0.00086"
"23.70000","2.36404","14281.35449","0.00088"
"24.00000","2.39420","14312.40430","0.00087"
"24.30000","2.42399","14340.73926","0.00088"
"24.60000","2.45418","14370.84375","0.00089"
"24.90000","2.48399","14397.97852","0.00089"
"25.20000","2.51409","14425.40332","0.00090"
"25.50000","2.54411","14455.22949","0.00091"
"25.80000","2.57411","14479.64941","0.00092"
"26.10000","2.60413","14508.14160","0.00093"
"26.40000","2.63419","14534.34863","0.00093"
"26.70000","2.66401","14558.32129","0.00094"
"27.00000","2.69421","14585.74121","0.00095"
"27.30000","2.72401","14609.30371","0.00094"
"27.60000","2.75415","14633.30957","0.00094"
"27.90000","2.78414","14659.84766","0.00094"
"28.20000","2.81412","14681.88281","0.00094"
"28.50000","2.84413","14706.90820","0.00094"
"28.80000","2.87416","14730.22363","0.00094"
"29.10000","2.90398","14752.21973","0.00095"
"29.40000","2.93421","14776.21094","0.00095"
"29.70000","2.96403","14797.82422","0.00095"
"30.00000","2.99417","14821.37402","0.00096"
"30.30000","3.02406","14843.57129","0.00096"
"30.60000","3.05413","14864.54297","0.00096"
"30.90000","3.08412","14888.36719","0.00097"
"31.20000","3.11415","14907.75391","0.00097"
"31.50000","3.14406","14929.12500","0.00098"
"31.80000","3.17414","14950.14844","0.00098"
"32.10000","3.20400","14969.87793","0.00099"
"32.40000","3.23421","14992.58691","0.00099"
"32.70000","3.26396","15011.96777","0.00099"
"33.00000","3.29418","15032.34766","0.00099"
"33.30000","3.32412","15053.83301","0.00099"
"33.60000","3.35408","15071.79297","0.00100"
"33.90000","3.38408","15092.80664","0.00099"
"34.20000","3.41412","15111.57910","0.00100"
"34.50000","3.44400","15130.55859","0.00100"
"34.80000","3.47423","15151.26074","0.00100"
"35.10000","3.50389","15167.63086","0.00100"
"35.40000","3.53421","15189.73730","0.00100"
"35.70000","3.56407","15208.08789","0.00100"
"36.00000","3.59403","15224.65625","0.00099"
"36.30000","3.62406","15245.54688","0.00098"
"36.60000","3.65410","15262.50098","0.00097"
"36.90000","3.68403","15280.97559","0.00096"
"37.20000","3.71417","15300.48242","0.00093"
"37.50000","3.74384","15314.63672","0.00092"
"37.80000","3.77423","15336.77832","0.00092"
"38.10000","3.80396","15353.01758","0.00090"
"38.40000","3.83405","15369.47070","0.00090"
"38.70000","3.86400","15388.02637","0.00089"
"39.00000","3.89408","15405.41211","0.00089"
"39.30000","3.92406","15423.36621","0.00090"
"39.60000","3.95417","15440.99023","0.00091"
"39.90000","3.98386","15455.40723","0.00091"
"40.20000","4.01422","15475.87988","0.00090"
"40.50000","4.04385","15489.63184","0.00088"
"40.80000","4.07410","15508.78418","0.00087"
"41.10000","4.10394","15524.04883","0.00086"
"41.40000","4.13405","15540.57031","0.00084"
"41.70000","4.16407","15559.13574","0.00083"
"42.00000","4.19413","15575.48633","0.00082"
"42.30000","4.22385","15588.75000","0.00082"
"42.60000","4.25425","15609.56055","0.00082"
"42.90000","4.28385","15621.09473","0.00081"
"43.20000","4.31422","15640.90430","0.00081"
"43.50000","4.34389","15653.56738","0.00080"
"43.80000","4.37407","15670.70215","0.00079"
"44.10000","4.40401","15686.67480","0.00079"
"44.40000","4.43414","15703.89844","0.00079"
"44.70000","4.46390","15717.01270","0.00078"
"45.00000","4.49418","15735.45312","0.00078"
"45.30000","4.52383","15746.69141","0.00077"
"45.60000","4.55422","15766.90625","0.00077"
"45.90000","4.58387","15777.59863","0.00077"
"46.20000","4.61413","15796.29492","0.00076"
"46.50000","4.64401","15810.90820","0.00076"
"46.80000","4.67406","15825.28809","0.00075"
"47.10000","4.70400","15840.05176","0.00075"
"47.40000","4.73413","15856.90723","0.00074"
"47.70000","4.76396","15869.50879","0.00074"
"48.00000","4.79423","15887.21582","0.00073"
"48.30000","4.82383","15897.34082","0.00073"
"48.60000","4.85420","15915.80762","0.00073"
"48.90000","4.88399","15928.65137","0.00072"
"49.20000","4.91405","15943.63770","0.00072"
"49.50000","4.94404","15957.51074","0.00072"
"49.80000","4.97416","15974.01758","0.00072"
"50.10000","5.00389","15984.47852","0.00072"
"50.40000","5.03419","16002.53906","0.00071"
"50.70000","5.06388","16012.36328","0.00071"
"51.00000","5.09418","16030.77832","0.00071"
"51.30000","5.12400","16042.26367","0.00071"
"51.60000","5.15409","16057.26465","0.00071"
"51.90000","5.18400","16070.82910","0.00071"
"52.20000","5.21410","16085.73926","0.00070"
"52.50000","5.24400","16098.22363","0.00070"
"52.80000","5.27413","16113.54980","0.00070"
"53.10000","5.30396","16123.99805","0.00070"
"53.40000","5.33421","16141.49023","0.00070"
"53.70000","5.36395","16152.24219","0.00069"
"54.00000","5.39411","16167.33105","0.00069"
"54.30000","5.42403","16179.44434","0.00069"
"54.60000","5.45405","16193.79492","0.00069"
"54.90000","5.48405","16206.74023","0.00069"
"55.20000","5.51412","16221.15234","0.00069"
"55.50000","5.54403","16232.78809","0.00068"
"55.80000","5.57420","16248.35449","0.00068"
"56.10000","5.60397","16258.33203","0.00068"
"56.40000","5.63414","16274.03906","0.00068"
"56.70000","5.66397","16284.70898","0.00068"
"57.00000","5.69406","16298.47852","0.00069"
"57.30000","5.72408","16311.92676","0.00070"
"57.60000","5.75407","16324.39941","0.00070"
"57.90000","5.78408","16336.68066","0.00070"
"58.20000","5.81413","16350.99609","0.00070"
"58.50000","5.84395","16360.94336","0.00070"
"58.80000","5.87415","16376.17188","0.00070"
"59.10000","5.90395","16386.64648","0.00070"
"59.40000","5.93409","16400.33789","0.00070"
"59.70000","5.96410","16413.34961","0.00070"
"60.00000","5.99411","16426.06836","0.00070"
"60.30000","6.02412","16437.91406","0.00070"
"60.60000","6.05409","16450.69922","0.00069"
"60.90000","6.08397","16461.11523","0.00069"
"61.20000","6.11413","16475.56836","0.00069"
"61.50000","6.14401","16485.42383","0.00069"
"61.80000","6.17417","16500.01172","0.00068"
"62.10000","6.20404","16510.46680","0.00068"
"62.40000","6.23407","16523.14258","0.00068"
"62.70000","6.26413","16535.74023","0.00068"
"63.00000","6.29402","16546.87109","0.00068"
"63.30000","6.32396","16556.96094","0.00068"
"63.60000","6.35406","16570.38867","0.00067"
"63.90000","6.38403","16581.83398","0.00067"
"64.20000","6.41413","16594.99219","0.00067"
"64.50000","6.44402","16605.31641","0.00067"
"64.80000","6.47403","16617.31445","0.00066"
"65.10000","6.50410","16628.60156","0.00066"
"65.40000","6.53403","16639.78320","0.00066"
"65.70000","6.56404","16651.84766","0.00066"
"66.00000","6.59407","16663.62500","0.00065"
"66.30000","6.62399","16673.40039","0.00065"
"66.60000","6.65411","16687.15430","0.00065"
"66.90000","6.68398","16696.18750","0.00065"
"67.20000","6.71411","16709.57617","0.00064"
"67.50000","6.74406","16720.04102","0.00064"
"67.80000","6.77402","16730.41211","0.00064"
"68.10000","6.80405","16742.15234","0.00064"
"68.40000","6.83402","16753.97852","0.00063"
"68.70000","6.86404","16763.63867","0.00063"
"69.00000","6.89411","16776.46875","0.00063"
"69.30000","6.92393","16785.33789","0.00062"
"69.60000","6.95414","16799.16602","0.00062"
"69.90000","6.98405","16808.43945","0.00062"
"70.20000","7.01403","16819.89648","0.00062"
"70.50000","7.04406","16829.63477","0.00062"
"70.80000","7.07404","16841.50195","0.00062"
"71.10000","7.10404","16851.40039","0.00062"
"71.40000","7.13411","16863.73828","0.00061"
"71.70000","7.16398","16871.90039","0.00061"
"72.00000","7.19416","16885.22656","0.00061"
"72.30000","7.22400","16893.23047","0.00061"
"72.60000","7.25403","16904.87500","0.00061"
"72.90000","7.28400","16914.77344","0.00060"
"73.20000","7.31402","16925.52930","0.00060"
"73.50000","7.34408","16935.40430","0.00060"
"73.80000","7.37402","16946.56250","0.00060"
"74.10000","7.40399","16955.32617","0.00060"
"74.40000","7.43413","16968.46484","0.00059"
"74.70000","7.46400","16976.41602","0.00059"
"75.00000","7.49413","16988.26758","0.00059"
"75.30000","7.52401","16996.41406","0.00054"
"75.60000","7.55401","17007.73047","0.00053"
"75.90000","7.58411","17017.40039","0.00053"
"76.20000","7.61401","17026.98633","0.00053"
"76.50000","7.64399","17036.29883","0.00053"
"76.80000","7.67410","17048.96484","0.00053"
"77.10000","7.70397","17056.01562","0.00053"
"77.40000","7.73418","17069.41797","0.00053"
"77.70000","7.76400","17075.76758","0.00053"
"78.00000","7.79404","17086.81250","0.00053"
"78.30000","7.82411","17097.40820","0.00053"
"78.60000","7.85397","17105.33594","0.00053"
"78.90000","7.88405","17115.18164","0.00054"
"79.20000","7.91405","17125.90820","0.00054"
"79.50000","7.94404","17134.75977","0.00054"
"79.80000","7.97413","17146.68945","0.00054"
"80.10000","8.00404","17154.21484","0.00054"
"80.40000","8.03401","17163.92578","0.00054"
"80.70000","8.06411","17173.19531","0.00054"
"81.00000","8.09398","17181.84570","0.00054"
"81.30000","8.12411","17192.47070","0.00054"
"81.60000","8.15394","17200.81641","0.00054"
"81.90000","8.18416","17211.75391","0.00054"
"82.20000","8.21408","17221.91016","0.00054"
"82.50000","8.24404","17229.35938","0.00054"
"82.80000","8.27405","17240.22070","0.00054"
"83.10000","8.30409","17248.85352","0.00054"
"83.40000","8.33401","17256.81641","0.00054"
"83.70000","8.36413","17267.20703","0.00054"
"84.00000","8.39386","17274.45117","0.00054"
"84.30000","8.42414","17285.57031","0.00053"
"84.60000","8.45409","17295.49414","0.00053"
"84.90000","8.48409","17303.27539","0.00053"
"85.20000","8.51405","17312.64648","0.00053"
"85.50000","8.54413","17321.61328","0.00053"
"85.80000","8.57400","17329.55859","0.00053"
"86.10000","8.60413","17339.06836","0.00053"
"86.40000","8.63396","17346.93555","0.00053"
"86.70000","8.66419","17357.69336","0.00053"
"87.00000","8.69401","17365.16992","0.00053"
"87.30000","8.72406","17373.26367","0.00053"
"87.60000","8.75402","17383.13867","0.00053"
"87.90000","8.78415","17391.40039","0.00053"
"88.20000","8.81412","17400.22266","0.00053"
"88.50000","8.84411","17408.63867","0.00053"
"88.80000","8.87394","17415.55859","0.00053"
"89.10000","8.90424","17427.33203","0.00053"
"89.40000","8.93400","17433.70117","0.00053"
"89.70000","8.96417","17442.26758","0.00053"
"90.00000","8.99401","17450.17383","0.00053"
"90.30000","9.02408","17460.11719","0.00053"
"90.60000","9.05412","17469.02344","0.00053"
"90.90000","9.08415","17476.95508","0.00053"
"91.20000","9.11401","17484.62109","0.00053"
"91.50000","9.14427","17495.35742","0.00053"
"91.80000","9.17394","17500.64258","0.00053"
"92.10000","9.20424","17511.91797","0.00053"
"92.40000","9.23398","17517.74219","0.00053"
"92.70000","9.26409","17526.16797","0.00053"
"93.00000","9.29406","17535.98828","0.00053"
"93.30000","9.32411","17543.42383","0.00053"
"93.60000","9.35410","17551.44922","0.00053"
"93.90000","9.38423","17561.07031","0.00053"
"94.20000","9.41402","17566.93555","0.00053"
"94.50000","9.44420","17576.40234","0.00053"
"94.80000","9.47402","17583.27930","0.00053"
"95.10000","9.50414","17591.47656","0.00053"
"95.40000","9.53411","17599.93750","0.00053"
"95.70000","9.56416","17607.25586","0.00053"
"96.00000","9.59415","17615.36523","0.00053"
"96.30000","9.62418","17623.59375","0.00053"
"96.60000","9.65402","17630.31836","0.00053"
"96.90000","9.68418","17638.78711","0.00053"
"97.20000","9.71401","17645.10156","0.00054"
"97.50000","9.74421","17654.54492","0.00054"
"97.80000","9.77403","17661.27344","0.00054"
"98.10000","9.80413","17668.66211","0.00054"
"98.40000","9.83419","17677.85156","0.00054"
"98.70000","9.86408","17683.67969","0.00054"
"99.00000","9.89405","17691.36719","0.00053"
"99.30000","9.92419","17699.95898","0.00053"
"99.60000","9.95400","17705.33984","0.00053"
"99.90000","9.98420","17714.19922","0.00053"
"100.20000","10.01398","17720.49609","0.00053"
"100.50000","10.04414","17728.67383","0.00053"
"100.80000","10.07414","17736.21680","0.00053"
"101.10000","10.10407","17743.16211","0.00053"
"101.40000","10.13407","17751.43945","0.00053"
"101.70000","10.16413","17758.09961","0.00053"
"102.00000","10.19402","17765.13281","0.00053"
"102.30000","10.22416","17773.63672","0.00053"
"102.60000","10.25389","17778.05859","0.00053"
"102.90000","10.28421","17788.54492","0.00053"
"103.20000","10.31404","17794.75586","0.00053"
"103.50000","10.34404","17801.12109","0.00053"
"103.80000","10.37409","17809.52539","0.00053"
"104.10000","10.40410","17816.23438","0.00053"
"104.40000","10.43402","17822.38281","0.00053"
"104.70000","10.46416","17831.05078","0.00053"
"105.00000","10.49382","17835.69727","0.00053"
"105.30000","10.52422","17845.99414","0.00053"
"105.60000","10.55401","17851.51367","0.00053"
"105.90000","10.58405","17858.42773","0.00053"
"106.20000","10.61402","17865.44922","0.00053"
"106.50000","10.64410","17873.16016","0.00053"
"106.80000","10.67403","17879.86523","0.00053"
"107.10000","10.70416","17887.66797","0.00053"
"107.40000","10.73386","17891.95117","0.00053"
"107.70000","10.76420","17902.25977","0.00053"
"108.00000","10.79382","17904.89062","0.00054"
"108.30000","10.82417","17915.52930","0.00054"
"108.60000","10.85394","17920.74219","0.00054"
"108.90000","10.88408","17927.99609","0.00054"
"109.20000","10.91404","17935.09766","0.00054"
"109.50000","10.94412","17942.58984","0.00054"
"109.80000","10.97388","17945.95508","0.00054"
"110.10000","11.00423","17955.92383","0.00054"
"110.40000","11.03385","17959.42578","0.00054"
"110.70000","11.06417","17969.30469","0.00054"
"111.00000","11.09391","17973.25391","0.00054"
"111.30000","11.12414","17982.04688","0.00055"
"111.60000","11.15402","17986.91602","0.00055"
"111.90000","11.18411","17994.20898","0.00055"
"112.20000","11.21397","17999.46289","0.00055"
"112.50000","11.24415","18007.18359","0.00055"
"112.80000","11.27385","18009.78906","0.00055"
"113.10000","11.30421","18021.17969","0.00055"
"113.40000","11.33385","18023.14844","0.00055"
"113.70000","11.36415","18032.72461","0.00055"
"114.00000","11.39404","18038.23047","0.00055"
"114.30000","11.42410","18044.27148","0.00055"
"114.60000","11.45396","18049.10547","0.00055"
"114.90000","11.48416","18058.57031","0.00055"
"115.20000","11.51385","18060.49414","0.00055"
"115.50000","11.54424","18071.00977","0.00055"
"115.80000","11.57385","18072.98438","0.00055"
"116.10000","11.60420","18082.82227","0.00055"
"116.40000","11.63397","18086.39844","0.00055"
"116.70000","11.66413","18094.02344","0.00055"
"117.00000","11.69399","18098.46484","0.00055"
"117.30000","11.72412","18105.79883","0.00055"
"117.60000","11.75394","18109.88086","0.00055"
"117.90000","11.78417","18119.22070","0.00055"
"118.20000","11.81389","18121.11523","0.00055"
"118.50000","11.84426","18131.46680","0.00056"
"118.80000","11.87397","18133.98242","0.00056"
"119.10000","11.90408","18140.87305","0.00056"
"119.40000","11.93405","18146.88672","0.00056"
"119.70000","11.96407","18153.31055","0.00056"
"120.00000","11.99400","18157.62109","0.00056"
"120.30000","12.02417","18165.90430","0.00056"
"120.60000","12.05392","18168.42383","0.00055"
"120.90000","12.08417","18177.32812","0.00056"
"121.20000","12.11399","18181.46094","0.00055"
"121.50000","12.14410","18188.22852","0.00055"
"121.80000","12.17402","18192.34570","0.00055"
"122.10000","12.20407","18199.40625","0.00055"
"122.40000","12.23403","18204.83008","0.00055"
"122.70000","12.26407","18211.61523","0.00055"
"123.00000","12.29402","18216.02930","0.00055"
"123.30000","12.32417","18223.57617","0.00055"
"123.60000","12.35400","18226.59570","0.00056"
"123.90000","12.38412","18233.90820","0.00055"
"124.20000","12.41399","18238.00000","0.00056"
"124.50000","12.44404","18243.38672","0.00056"
"124.80000","12.47409","18249.87109","0.00056"
"125.10000","12.50406","18255.65625","0.00056"
"125.40000","12.53407","18260.07227","0.00056"
"125.70000","12.56416","18266.82227","0.00056"
"126.00000","12.59397","18270.13281","0.00056"
"126.30000","12.62416","18277.06250","0.00056"
"126.60000","12.65397","18279.91211","0.00056"
"126.90000","12.68406","18287.10352","0.00056"
"127.20000","12.71408","18292.05273","0.00056"
"127.50000","12.74406","18297.40625","0.00056"
"127.80000","12.77413","18303.41016","0.00056"
"128.10001","12.80406","18307.70312","0.00055"
"128.39999","12.83401","18312.29297","0.00055"
"128.70000","12.86414","18319.79688","0.00055"
"129.00000","12.89398","18321.98828","0.00055"
"129.30000","12.92411","18328.55859","0.00056"
"129.60001","12.95405","18333.47852","0.00055"
"129.89999","12.98406","18338.82422","0.00055"
"130.20000","13.01414","18344.79102","0.00055"
"130.50000","13.04404","18349.84180","0.00055"
"130.80000","13.07399","18353.41797","0.00055"
"131.10001","13.10408","18359.73633","0.00055"
"131.39999","13.13397","18363.34570","0.00055"
"131.70000","13.16415","18369.98633","0.00056"
"132.00000","13.19401","18373.11914","0.00055"
"132.30000","13.22409","18379.80078","0.00056"
"132.60001","13.25412","18384.31836","0.00056"
"132.89999","13.28403","18389.10938","0.00056"
"133.20000","13.31405","18394.20898","0.00056"
"133.50000","13.34406","18399.16016","0.00056"
"133.80000","13.37397","18402.51562","0.00056"
"134.10001","13.40415","18410.64258","0.00056"
"134.39999","13.43395","18413.35352","0.00056"
"134.70000","13.46410","18419.88477","0.00056"
"135.00000","13.49408","18424.35352","0.00056"
"135.30000","13.52394","18427.58984","0.00056"
"135.60001","13.55407","18433.74805","0.00056"
"135.89999","13.58402","18438.88477","0.00056"
"136.20000","13.61401","18442.99609","0.00056"
"136.50000","13.64414","18449.15430","0.00056"
"136.80000","13.67395","18452.98633","0.00056"
"137.10001","13.70413","18459.92578","0.00056"
"137.39999","13.73405","18463.08789","0.00056"
"137.70000","13.76402","18467.90430","0.00056"
"138.00000","13.79402","18472.24023","0.00056"
"138.30000","13.82402","18477.02344","0.00056"
"138.60001","13.85409","18482.87500","0.00056"
"138.89999","13.88404","18487.60547","0.00057"
"139.20000","13.91394","18490.19336","0.00057"
"139.50000","13.94418","18498.62500","0.00057"
"139.80000","13.97396","18500.21094","0.00057"
"140.10001","14.00408","18506.12695","0.00057"
"140.39999","14.03403","18510.18359","0.00057"
"140.70000","14.06399","18514.60352","0.00058"
"141.00000","14.09409","18519.09570","0.00058"
"141.30000","14.12407","18524.28516","0.00058"
"141.60001","14.15396","18527.30859","0.00058"
"141.89999","14.18417","18534.19336","0.00058"
"142.20000","14.21400","18536.12305","0.00058"
"142.50000","14.24410","18542.27148","0.00058"
"142.80000","14.27401","18545.16797","0.00058"
"143.10001","14.30404","18550.32617","0.00058"
"143.39999","14.33410","18554.32031","0.00058"
"143.70000","14.36403","18557.65820","0.00058"
"144.00000","14.39402","18561.58984","0.00058"
"144.30000","14.42410","18567.36328","0.00058"
"144.60001","14.45400","18569.70117","0.00058"
"144.89999","14.48414","18576.35742","0.00058"
"145.20000","14.51396","18577.71484","0.00058"
"145.50000","14.54404","18582.83984","0.00058"
"145.80000","14.57416","18587.62891","0.00058"
"146.10001","14.60399","18590.94336","0.00058"
"146.39999","14.63407","18594.93945","0.00058"
"146.70000","14.66405","18599.63477","0.00059"
"147.00000","14.69403","18602.65625","0.00059"
"147.30000","14.72416","18608.43359","0.00059"
"147.60001","14.75400","18609.58398","0.00060"
"147.89999","14.78405","18615.59570","0.00060"
"148.20000","14.81413","18619.42188","0.00060"
"148.50000","14.84400","18622.49219","0.00060"
"148.80000","14.87411","18627.38086","0.00060"
"149.10001","14.90402","18630.72266","0.00060"
"149.39999","14.93410","18634.60156","0.00060"
"149.70000","14.96410","18639.93555","0.00060"
"150.00000","14.99404","18641.87891","0.00060"
"150.30000","15.02404","18646.65234","0.00060"
"150.60001","15.05411","18650.85156","0.00060"
"150.89999","15.08400","18652.78906","0.00060"
"151.20000","15.11413","18658.39258","0.00060"
"151.50000","15.14395","18661.39844","0.00060"
"151.80000","15.17417","18666.93945","0.00060"
"152.10001","15.20407","18670.77344","0.00060"
"152.39999","15.23407","18673.66016","0.00060"
"152.70000","15.26400","18677.75781","0.00060"
"153.00000","15.29406","18681.31641","0.00060"
"153.30000","15.32404","18685.74414","0.00060"
"153.60001","15.35413","18689.51172","0.00060"
"153.89999","15.38393","18691.50781","0.00059"
"154.20000","15.41419","18698.10742","0.00059"
"154.50000","15.44400","18700.44531","0.00059"
"154.80000","15.47408","18704.28711","0.00059"
"155.10001","15.50398","18708.28516","0.00059"
"155.39999","15.53404","18711.54883","0.00059"
"155.70000","15.56409","18716.25391","0.00060"
"156.00000","15.59413","18721.30078","0.00059"
"156.30000","15.62396","18723.08398","0.00059"
"156.60001","15.65423","18728.73828","0.00059"
"156.89999","15.68398","18730.85547","0.00059"
"157.20000","15.71412","18735.24023","0.00059"
"157.50000","15.74400","18738.38867","0.00059"
"157.80000","15.77411","18742.81836","0.00059"
"158.10001","15.80415","18746.62891","0.00059"
"158.39999","15.83412","18749.08594","0.00059"
"158.70000","15.86400","18752.70312","0.00059"
"159.00000","15.89423","18758.52344","0.00059"
"159.30000","15.92397","18759.53320","0.00059"
"159.60001","15.95423","18765.14453","0.00059"
"159.89999","15.98396","18766.57422","0.00059"
"160.20000","16.01414","18770.84961","0.00059"
"160.50000","16.04413","18775.65039","0.00059"
"160.80000","16.07413","18779.31836","0.00059"
"161.10001","16.10409","18782.10547","0.00059"
"161.39999","16.13424","18787.10352","0.00060"
"161.70000","16.16398","18787.78711","0.00060"
"162.00000","16.19425","18793.34375","0.00060"
"162.30000","16.22402","18795.41797","0.00060"
"162.60001","16.25413","18798.82227","0.00060"
"162.89999","16.28411","18802.49023","0.00060"
"163.20000","16.31413","18806.61719","0.00060"
"163.50000","16.34414","18810.47266","0.00060"
"163.80000","16.37419","18813.89844","0.00060"
"164.10001","16.40402","18815.45508","0.00060"
"164.39999","16.43423","18820.45898","0.00060"
"164.70000","16.46405","18821.87891","0.00060"
"165.00000","16.49419","18826.35938","0.00060"
"165.30000","16.52407","18829.27344","0.00060"
"165.60001","16.55416","18831.99414","0.00060"
"165.89999","16.58416","18836.39453","0.00060"
"166.20000","16.61411","18839.63477","0.00060"
"166.50000","16.64404","18841.94531","0.00060"
"166.80000","16.67420","18846.01172","0.00060"
"167.10001","16.70404","18848.16602","0.00060"
"167.39999","16.73423","18852.63867","0.00060"
"167.70000","16.76396","18853.56055","0.00060"
"168.00000","16.79417","18858.08203","0.00061"
"168.30000","16.82414","18861.42188","0.00061"
"168.60001","16.85406","18863.14844","0.00061"
"168.89999","16.88408","18867.14648","0.00061"
"169.20000","16.91412","18870.53516","0.00061"
"169.50000","16.94404","18872.92578","0.00061"
"169.80000","16.97418","18877.00781","0.00061"
"170.10001","17.00390","18877.09570","0.00061"
"170.39999","17.03418","18881.89062","0.00061"
"170.70000","17.06406","18885.06250","0.00062"
"171.00000","17.09403","18886.93359","0.00062"
"171.30000","17.12403","18890.01172","0.00062"
"171.60001","17.15410","18893.40039","0.00062"
"171.89999","17.18402","18895.24805","0.00062"
"172.20000","17.21420","18899.37305","0.00062"
"172.50000","17.24386","18899.14648","0.00062"
"172.80000","17.27419","18904.01172","0.00062"
"173.10001","17.30394","18904.70898","0.00062"
"173.39999","17.33405","18908.50000","0.00062"
"173.70000","17.36399","18910.69336","0.00062"
"174.00000","17.39406","18913.02148","0.00062"
"174.30000","17.42409","18916.23242","0.00062"
"174.60001","17.45415","18919.29297","0.00062"
"174.89999","17.48383","18918.21875","0.00062"
"175.20000","17.51426","18925.47656","0.00062"
"175.50000","17.54387","18924.56250","0.00062"
"175.80000","17.57409","18928.25000","0.00062"
"176.10001","17.60396","18929.58594","0.00062"
"176.39999","17.63400","18931.75000","0.00062"
"176.70000","17.66407","18934.75391","0.00062"
"177.00000","17.69415","18938.18750","0.00062"
"177.30000","17.72383","18937.21289","0.00062"
"177.60001","17.75425","18943.20703","0.00061"
"177.89999","17.78386","18941.72070","0.00062"
"178.20000","17.81416","18946.81836","0.00061"
"178.50000","17.84389","18945.66406","0.00061"
"178.80000","17.87411","18950.00391","0.00061"
"179.10001","17.90396","18950.95703","0.00061"
"179.39999","17.93407","18953.71484","0.00061"
"179.70000","17.96395","18955.09375","0.00061"
"180.00000","17.99420","18960.49023","0.00061"
"180.30000","18.02383","18958.49023","0.00061"
"180.60001","18.05425","18965.74805","0.00061"
"180.89999","18.08382","18964.62891","0.00061"
"181.20000","18.11420","18971.11719","0.00062"
"181.50000","18.14404","18973.51953","0.00062"
"181.80000","18.17408","18977.97070","0.00061"
"182.10001","18.20397","18979.57422","0.00062"
"182.39999","18.23416","18985.50000","0.00061"
"182.70000","18.26388","18985.35547","0.00061"
"183.00000","18.29424","18991.19727","0.00061"
"183.30000","18.32387","18990.40430","0.00061"
"183.60001","18.35419","18996.20312","0.00061"
"183.89999","18.38404","18997.00977","0.00061"
"184.20000","18.41412","19000.24219","0.00061"
"184.50000","18.44403","19001.37891","0.00062"
"184.80000","18.47398","19003.22656","0.00062"
"185.10001","18.50392","19005.16016","0.00062"
"185.39999","18.53414","19010.62695","0.00062"
"185.70000","18.56391","19009.60938","0.00062"
"186.00000","18.59426","19015.79102","0.00062"
"186.30000","18.62399","19015.96094","0.00062"
"186.60001","18.65408","19019.06250","0.00062"
"186.89999","18.68404","19021.61914","0.00062"
"187.20000","18.71407","19024.86914","0.00062"
"187.50000","18.74401","19025.38477","0.00062"
"187.80000","18.77417","19029.31641","0.00062"
"188.10001","18.80392","19026.75977","0.00062"
"188.39999","18.83421","19029.00195","0.00062"
"188.70000","18.86396","19025.63672","0.00062"
"189.00000","18.89411","19026.45703","0.00062"
"189.30000","18.92397","19023.65234","0.00062"
"189.60001","18.95403","19023.60547","0.00062"
"189.89999","18.98404","19023.67188","0.00062"
"190.20000","19.01408","19025.87305","0.00062"
"190.50000","19.04403","19028.78320","0.00062"
"190.80000","19.07418","19036.20312","0.00062"
"191.10001","19.10391","19035.31836","0.00062"
"191.39999","19.13412","19036.19922","0.00062"
"191.70000","19.16403","19030.19727","0.00062"
"192.00000","19.19402","19023.42773","0.00061"
"192.30000","19.22409","19019.07812","0.00061"
"192.60001","19.25406","19016.41797","0.00062"
"192.89999","19.28407","19013.34180","0.00062"
"193.20000","19.31415","19015.11914","0.00062"
"193.50000","19.34398","19014.99414","0.00062"
"193.80000","19.37413","19018.28320","0.00062"
"194.10001","19.40399","19012.59766","0.00062"
"194.39999","19.43408","19012.20898","0.00062"
"194.70000","19.46404","19013.32227","0.00062"
"195.00000","19.49408","19010.62109","0.00062"
"195.30000","19.52415","19010.82031","0.00062"
"195.60001","19.55409","19015.10938","0.00062"
"195.89999","19.58398","19009.68359","0.00062"
"196.20000","19.61414","19011.94531","0.00064"
"196.50000","19.64397","19013.11328","0.00056"
"196.80000","19.67409","19012.49609","0.00054"
"197.10001","19.70406","19010.34180","0.00058"
"197.39999","19.73406","19017.14258","0.00049"
"197.70000","19.76416","19013.57227","0.00056"
"198.00000","19.79408","19010.61914","0.00056"
"198.30000","19.82401","19013.60547","0.00056"
"198.60001","19.85411","19013.09570","0.00056"
"198.89999","19.88402","19008.75195","0.00056"
"199.20000","19.91412","19018.33203","0.00055"
"199.50000","19.94399","19008.45508","0.00055"
"199.80000","19.97408","19018.09570","0.00055"
"200.10001","20.00412","19020.83398","0.00055"
"200.39999","20.03405","19017.12500","0.00055"
"200.70000","20.06407","19028.38281","0.00055"
"201.00000","20.09407","19027.49609","0.00055"
"201.30000","20.12398","19017.71484","0.00055"
"201.60001","20.15416","19039.28516","0.00055"
"201.89999","20.18398","19024.18945","0.00055"
"202.20000","20.21416","19028.93945","0.00055"
"202.50000","20.24408","19041.96094","0.00054"
"202.80000","20.27398","19022.58008","0.00054"
"203.10001","20.30407","19034.30469","0.00054"
"203.39999","20.33408","19047.09766","0.00054"
"203.70000","20.36403","19018.33203","0.00054"
"204.00000","20.39413","19047.64648","0.00054"
"204.30000","20.42391","19028.99414","0.00054"
"204.60001","20.45416","19029.71094","0.00054"
"204.89999","20.48402","19053.52539","0.00054"
"205.20000","20.51403","19019.44727","0.00054"
"205.50000","20.54402","19038.64648","0.00054"
"205.80000","20.57403","19051.35742","0.00054"
"206.10001","20.60406","19015.31445","0.00054"
"206.39999","20.63408","19062.70312","0.00053"
"206.70000","20.66393","19035.81641","0.00053"
"207.00000","20.69414","19041.80859","0.00053"
"207.30000","20.72400","19072.12109","0.00053"
"207.60001","20.75406","19033.93945","0.00053"
"207.89999","20.78403","19062.16211","0.00053"
"208.20000","20.81402","19072.77148","0.00053"
"208.50000","20.84408","19037.02734","0.00053"
"208.80000","20.87406","19079.91406","0.00053"
"209.10001","20.90394","19048.99023","0.00053"
"209.39999","20.93414","19058.02734","0.00053"
"209.70000","20.96399","19083.23828","0.00053"
"210.00000","20.99411","19030.54102","0.00053"
"210.30000","21.02397","19075.18359","0.00053"
"210.60001","21.05400","19064.49414","0.00052"
"210.89999","21.08411","19041.24414","0.00052"
"211.20000","21.11400","19092.48828","0.00052"
"211.50000","21.14403","19018.39062","0.00052"
"211.80000","21.17411","19075.91016","0.00052"
"212.10001","21.20400","19074.62500","0.00052"
"212.39999","21.23414","19041.70703","0.00052"
"212.70000","21.26400","19099.83203","0.00052"
"213.00000","21.29399","19023.66211","0.00052"
"213.30000","21.32413","19079.82422","0.00051"
"213.60001","21.35399","19090.42969","0.00052"
"213.89999","21.38405","19039.49609","0.00051"
"214.20000","21.41401","19112.71094","0.00052"
"214.50000","21.44407","19020.30469","0.00051"
"214.80000","21.47412","19087.31641","0.00051"
"215.10001","21.50403","19103.34570","0.00051"
"215.39999","21.53403","19047.27539","0.00051"
"215.70000","21.56406","19125.55664","0.00051"
"216.00000","21.59401","19022.19727","0.00052"
"216.30000","21.62412","19098.04688","0.00052"
"216.60001","21.65400","19108.33203","0.00052"
"216.89999","21.68410","19044.28906","0.00052"
"217.20000","21.71409","19139.19922","0.00052"
"217.50000","21.74401","19006.84180","0.00052"
"217.80000","21.77402","19105.48438","0.00052"
"218.10001","21.80416","19115.93164","0.00052"
"218.39999","21.83397","19051.80078","0.00052"
"218.70000","21.86413","19151.21875","0.00052"
"219.00000","21.89397","18993.07422","0.00052"
"219.30000","21.92416","19113.14648","0.00052"
"219.60001","21.95406","19137.07227","0.00052"
"219.89999","21.98405","19035.73633","0.00052"
"220.20000","22.01399","19153.14844","0.00052"
"220.50000","22.04412","18959.42773","0.00052"
"220.80000","22.07407","19099.66992","0.00052"
"221.10001","22.10415","19162.79102","0.00052"
"221.39999","22.13392","19009.96289","0.00053"
"221.70000","22.16420","19153.28125","0.00053"
"222.00000","22.19405","18949.42969","0.00053"
"222.30000","22.22411","19082.24609","0.00053"
"222.60001","22.25403","19176.47656","0.00053"
"222.89999","22.28407","18979.59766","0.00053"
"223.20000","22.31410","19140.31250","0.00053"
"223.50000","22.34418","18936.48438","0.00053"
"223.80000","22.37395","19042.04883","0.00053"
"224.10001","22.40421","19176.96875","0.00053"
"224.39999","22.43398","18920.61133","0.00053"
"224.70000","22.46416","19112.14648","0.00053"
"225.00000","22.49397","19121.54883","0.00054"
"225.30000","22.52408","18998.28906","0.00054"
"225.60001","22.55412","19168.45703","0.00054"
"225.89999","22.58420","18871.98438","0.00054"
"226.20000","22.61396","19070.84961","0.00054"
"226.50000","22.64425","19197.95508","0.00054"
"226.80000","22.67394","18944.03320","0.00054"
"227.10001","22.70418","19139.11523","0.00054"
"227.39999","22.73409","18874.91992","0.00054"
"227.70000","22.76407","19019.08398","0.00054"
"228.00000","22.79413","19184.74609","0.00054"
"228.30000","22.82419","18882.82031","0.00054"
"228.60001","22.85406","19090.59180","0.00054"
"228.89999","22.88425","19197.67969","0.00054"
"229.20000","22.91399","18957.79883","0.00054"
"229.50000","22.94420","19153.78320","0.00054"
"229.80000","22.97415","18825.87109","0.00054"
"230.10001","23.00415","19034.73828","0.00054"
"230.39999","23.03410","19192.89453","0.00054"
"230.70000","23.06414","18884.90820","0.00054"
"231.00000","23.09417","19100.39062","0.00055"
"231.30000","23.12411","19191.42188","0.00055"
"231.60001","23.15401","18960.76758","0.00055"
"231.89999","23.18426","19158.11328","0.00055"
"232.20000","23.21412","18826.31836","0.00055"
"232.50000","23.24419","19040.59180","0.00055"
"232.80000","23.27407","19195.22266","0.00055"
"233.10001","23.30413","18900.93945","0.00055"
"233.39999","23.33413","19109.43945","0.00055"
"233.70000","23.36411","19182.57617","0.00055"
"234.00000","23.39404","18975.72070","0.00055"
"234.30000","23.42418","19165.37500","0.00055"
"234.60001","23.45416","18851.21875","0.00055"
"234.89999","23.48417","19056.65625","0.00055"
"235.20000","23.51392","19199.39648","0.00055"
"235.50000","23.54415","18921.99219","0.00055"
"235.80000","23.57415","19121.96875","0.00055"
"236.10001","23.60412","19158.72070","0.00055"
"236.39999","23.63408","18999.51367","0.00055"
"236.70000","23.66413","19175.01758","0.00055"
"237.00000","23.69411","18882.47656","0.00054"
"237.30000","23.72422","19081.34180","0.00054"
"237.60001","23.75387","19201.35156","0.00054"
"237.89999","23.78421","18964.18359","0.00054"
"238.20000","23.81406","19147.30469","0.00054"
"238.50000","23.84411","18943.59961","0.00054"
"238.80000","23.87400","19040.30078","0.00054"
"239.10001","23.90406","19191.93359","0.00054"
"239.39999","23.93403","18939.58984","0.00054"
"239.70000","23.96418","19126.92969","0.00054"
"240.00000","23.99389","19159.95703","0.00054"
"240.30000","24.02420","19034.76172","0.00054"
"240.60001","24.05397","19188.82812","0.00054"
"240.89999","24.08408","18937.04297","0.00054"
"241.20000","24.11396","19114.23438","0.00054"
"241.50000","24.14408","19215.80078","0.00054"
"241.80000","24.17401","19009.43164","0.00054"
"242.10001","24.20415","19174.04883","0.00054"
"242.39999","24.23393","18935.98047","0.00054"
"242.70000","24.26421","19074.11914","0.00054"
"243.00000","24.29391","19188.68555","0.00054"
"243.30000","24.32406","18951.22070","0.00055"
"243.60001","24.35391","19115.28320","0.00055"
"243.89999","24.38416","18839.28320","0.00055"
"244.20000","24.41404","19021.94531","0.00055"
"244.50000","24.44426","18728.89258","0.00055"
"244.80000","24.47383","18909.50977","0.00055"
"245.10001","24.50431","18636.09375","0.00055"
"245.39999","24.53384","18780.06055","0.00055"
"245.70000","24.56421","18595.64453","0.00055"
"246.00000","24.59389","18609.50000","0.00055"
"246.30000","24.62408","18636.92188","0.00055"
"246.60001","24.65405","18719.15625","0.00055"
"246.89999","24.68410","18800.73047","0.00055"
"247.20000","24.71391","18875.26953","0.00055"
"247.50000","24.74418","18955.63672","0.00055"
"247.80000","24.77380","19015.70508","0.00055"
"248.10001","24.80420","19066.21094","0.00055"
"248.39999","24.83390","19099.89844","0.00055"
"248.70000","24.86418","19129.61133","0.00055"
"249.00000","24.89402","19147.32227","0.00055"
"249.30000","24.92409","19161.02148","0.00055"
"249.60001","24.95395","19181.15430","0.00055"
"249.89999","24.98416","19205.18164","0.00055"
"250.20000","25.01383","19221.31445","0.00055"
"250.50000","25.04421","19241.70508","0.00055"
"250.80000","25.07385","19246.57617","0.00055"
"251.10001","25.10423","19265.30078","0.00055"
"251.39999","25.13397","19270.36133","0.00055"
"251.70000","25.16409","19277.33008","0.00055"
"252.00000","25.19403","19281.28516","0.00055"
"252.30000","25.22410","19282.39258","0.00055"
"252.60001","25.25394","19280.08984","0.00055"
"252.89999","25.28421","19283.61914","0.00055"
"253.20000","25.31385","19282.07617","0.00055"
"253.50000","25.34419","19295.17773","0.00055"
"253.80000","25.37400","19305.00000","0.00054"
"254.10001","25.40402","19315.13672","0.00055"
"254.39999","25.43404","19324.28516","0.00054"
"254.70000","25.46409","19333.45898","0.00054"
"255.00000","25.49397","19340.05078","0.00054"
"255.30000","25.52415","19350.26758","0.00054"
"255.60001","25.55394","19354.67773","0.00054"
"255.89999","25.58419","19363.75586","0.00054"
"256.20001","25.61399","19364.44141","0.00054"
"256.50000","25.64410","19366.17969","0.00054"
"256.79999","25.67399","19357.50195","0.00054"
"257.10001","25.70404","19337.90039","0.00053"
"257.39999","25.73405","19323.29492","0.00053"
"257.70001","25.76407","19334.54492","0.00053"
"258.00000","25.79401","19335.29688","0.00053"
"258.29999","25.82420","19309.49414","0.00053"
"258.60001","25.85396","19309.27539","0.00053"
"258.89999","25.88412","19328.98633","0.00053"
"259.20001","25.91400","19282.58789","0.00053"
"259.50000","25.94403","19308.35352","0.00053"
"259.79999","25.97410","19339.14453","0.00053"
"260.10001","26.00406","19265.73828","0.00053"
"260.39999","26.03408","19314.00977","0.00053"
"260.70001","26.06414","19348.83203","0.00053"
"261.00000","26.09396","19240.68164","0.00053"
"261.29999","26.12414","19340.01758","0.00053"
"261.60001","26.15399","19302.15820","0.00053"
"261.89999","26.18407","19263.26367","0.00053"
"262.20001","26.21408","19376.87695","0.00053"
"262.50000","26.24412","19114.70117","0.00053"
"262.79999","26.27415","19259.21094","0.00053"
"263.10001","26.30407","19390.57812","0.00053"
"263.39999","26.33403","19028.70703","0.00053"
"263.70001","26.36412","19232.14844","0.00053"
"264.00000","26.39401","19382.45508","0.00053"
"264.29999","26.42425","18942.97070","0.00053"
"264.60001","26.45404","19168.48828","0.00053"
"264.89999","26.48407","19348.52734","0.00053"
"265.20001","26.51412","19234.66797","0.00053"
"265.50000","26.54399","19097.94141","0.00053"
"265.79999","26.57397","19296.81641","0.00053"
"266.10001","26.60411","19398.03906","0.00053"
"266.39999","26.63397","19015.76367","0.00053"
"266.70001","26.66413","19234.15430","0.00053"
"267.00000","26.69398","19372.56055","0.00052"
"267.29999","26.72409","18936.76758","0.00053"
"267.60001","26.75416","19157.98828","0.00053"
"267.89999","26.78402","19328.38086","0.00052"
"268.20001","26.81408","19090.23047","0.00052"
"268.50000","26.84407","19094.91797","0.00052"
"268.79999","26.87397","19280.58594","0.00052"
"269.10001","26.90415","19371.35156","0.00052"
"269.39999","26.93398","19005.67188","0.00052"
"269.70001","26.96408","19207.20312","0.00052"
"270.00000","26.99407","19341.12109","0.00052"
"270.29999","27.02417","18924.48438","0.00052"
"270.60001","27.05400","19117.25781","0.00053"
"270.89999","27.08404","19286.36523","0.00052"
"271.20001","27.11405","19343.43359","0.00052"
"271.50000","27.14411","19039.27148","0.00053"
"271.79999","27.17391","19221.66602","0.00052"
"272.10001","27.20416","19336.36914","0.00052"
"272.39999","27.23410","18962.75781","0.00052"
"272.70001","27.26403","19148.21484","0.00052"
"273.00000","27.29403","19298.41406","0.00052"
"273.29999","27.32398","19314.06641","0.00052"
"273.60001","27.35407","19056.53125","0.00052"
"273.89999","27.38409","19230.42383","0.00053"
"274.20001","27.41392","19322.86133","0.00052"
"274.50000","27.44424","19016.49219","0.00052"
"274.79999","27.47400","19139.62891","0.00053"
"275.10001","27.50404","19268.38672","0.00053"
"275.39999","27.53402","19252.70117","0.00053"
"275.70001","27.56399","19075.01758","0.00053"
"276.00000","27.59407","19205.20898","0.00053"
"276.20200","27.61459","11378.45996","0.00056"