File: archive/undergrad/433/Concentration/Specimen_RawData_8.csv
Time,Extension,Load,Strain Gage18
(s),(mm),(N),(mm/mm)
"0.00000","0.00000","125.92448","-0.00018"
"0.10000","0.00326","161.47305","-0.00016"
"0.20000","0.01411","283.22876","-0.00010"
"0.30000","0.02435","396.42789","-0.00005"
"0.40000","0.03457","507.34518","0.00001"
"0.50000","0.04464","616.34399","0.00007"
"0.60000","0.05474","727.00275","0.00013"
"0.70000","0.06473","837.27014","0.00019"
"0.80000","0.07452","945.07159","0.00025"
"0.90000","0.08441","1055.17944","0.00031"
"1.00000","0.09452","1166.35498","0.00036"
"1.10000","0.10451","1274.88916","0.00042"
"1.20000","0.11471","1383.68555","0.00048"
"1.30000","0.12469","1488.80603","0.00053"
"1.40000","0.13458","1592.53186","0.00059"
"1.50000","0.14450","1696.25073","0.00064"
"1.60000","0.15452","1800.39587","0.00070"
"1.70000","0.16451","1903.11523","0.00075"
"1.80000","0.17460","2006.59729","0.00081"
"1.90000","0.18465","2108.75220","0.00086"
"2.00000","0.19456","2209.23682","0.00091"
"2.10000","0.20456","2309.72168","0.00096"
"2.20000","0.21460","2410.38989","0.00102"
"2.30000","0.22458","2509.64209","0.00107"
"2.40000","0.23464","2609.38525","0.00112"
"2.50000","0.24463","2707.91284","0.00117"
"2.60000","0.25446","2804.15405","0.00122"
"2.70000","0.26445","2901.95703","0.00128"
"2.80000","0.27463","3001.83350","0.00133"
"2.90000","0.28464","3099.56177","0.00138"
"3.00000","0.29474","3197.52661","0.00143"
"3.10000","0.30466","3293.13721","0.00148"
"3.20000","0.31455","3387.91577","0.00153"
"3.30000","0.32442","3482.80078","0.00158"
"3.40000","0.33452","3579.63599","0.00163"
"3.50000","0.34458","3675.46118","0.00168"
"3.60000","0.35477","3772.89233","0.00173"
"3.70000","0.36476","3867.50000","0.00178"
"3.80000","0.37454","3959.60425","0.00183"
"3.90000","0.38452","4053.37988","0.00188"
"4.00000","0.39453","4147.51855","0.00194"
"4.10000","0.40457","4241.05273","0.00199"
"4.20000","0.41462","4335.04102","0.00204"
"4.30000","0.42471","4429.06787","0.00209"
"4.40000","0.43460","4520.45410","0.00214"
"4.50000","0.44457","4612.70068","0.00219"
"4.60000","0.45460","4705.33057","0.00224"
"4.70000","0.46455","4796.46338","0.00230"
"4.80000","0.47462","4888.59033","0.00235"
"4.90000","0.48465","4979.96484","0.00240"
"5.00000","0.49453","5069.28516","0.00245"
"5.10000","0.50451","5159.74854","0.00251"
"5.20000","0.51466","5251.85449","0.00256"
"5.30000","0.52463","5341.09033","0.00262"
"5.40000","0.53469","5431.28564","0.00267"
"5.50000","0.54468","5520.27393","0.00273"
"5.60000","0.55452","5607.44775","0.00279"
"5.70000","0.56446","5695.56299","0.00285"
"5.80000","0.57453","5784.85840","0.00291"
"5.90000","0.58464","5873.64746","0.00297"
"6.00000","0.59474","5961.99561","0.00303"
"6.10000","0.60473","6048.62207","0.00309"
"6.20000","0.61453","6132.90430","0.00316"
"6.30000","0.62454","6219.16650","0.00322"
"6.40000","0.63454","6304.67383","0.00329"
"6.50000","0.64454","6389.93018","0.00336"
"6.60000","0.65464","6475.28467","0.00343"
"6.70000","0.66472","6560.38281","0.00350"
"6.80000","0.67467","6644.12402","0.00358"
"6.90000","0.68458","6727.28662","0.00366"
"7.00000","0.69455","6810.45898","0.00374"
"7.10000","0.70455","6893.04541","0.00382"
"7.20000","0.71462","6975.95850","0.00391"
"7.30000","0.72467","7058.46045","0.00400"
"7.40000","0.73457","7138.78516","0.00410"
"7.50000","0.74457","7219.31836","0.00420"
"7.60000","0.75464","7300.17041","0.00430"
"7.70000","0.76464","7378.56836","0.00440"
"7.80000","0.77460","7456.01709","0.00451"
"7.90000","0.78463","7532.71729","0.00463"
"8.00000","0.79455","7605.00488","0.00474"
"8.10000","0.80451","7675.93213","0.00486"
"8.20000","0.81459","7747.85596","0.00498"
"8.30000","0.82465","7818.60596","0.00511"
"8.40000","0.83475","7889.40625","0.00525"
"8.50000","0.84466","7957.46094","0.00538"
"8.60000","0.85454","8025.37744","0.00553"
"8.70000","0.86451","8094.54346","0.00569"
"8.80000","0.87454","8163.40527","0.00585"
"8.90000","0.88456","8231.47363","0.00603"
"9.00000","0.89471","8300.35059","0.00620"
"9.10000","0.90471","8367.49609","0.00639"
"9.20000","0.91462","8434.02344","0.00659"
"9.30000","0.92449","8499.05176","0.00679"
"9.40000","0.93445","8564.79004","0.00699"
"9.50000","0.94456","8630.27539","0.00722"
"9.60000","0.95459","8694.04199","0.00744"
"9.70000","0.96472","8758.22559","0.00768"
"9.80000","0.97462","8819.69434","0.00792"
"9.90000","0.98464","8881.18359","0.00818"
"10.00000","0.99459","8940.94434","0.00844"
"10.10000","1.00452","8998.50293","0.00869"
"10.20000","1.01464","9056.06348","0.00897"
"10.30000","1.02468","9111.50195","0.00927"
"10.40000","1.03460","9164.84668","0.00951"
"10.50000","1.04458","9218.72070","0.00974"
"10.60000","1.05459","9266.43359","0.11448"
"10.70000","1.06466","9316.00977","0.11186"
"10.80000","1.07468","9366.17676","0.11187"
"10.90000","1.08467","9414.30762","0.11187"
"11.00000","1.09457","9459.88574","0.11187"
"11.10000","1.10450","9505.74121","0.11187"
"11.20000","1.11454","9550.05371","0.11187"
"11.30000","1.12456","9592.81250","0.11187"
"11.40000","1.13463","9636.13770","0.11187"
"11.50000","1.14473","9677.80859","0.11187"
"11.60000","1.15463","9716.69336","0.11187"
"11.70000","1.16456","9755.80566","0.11187"
"11.80000","1.17443","9793.76562","0.11187"
"11.90000","1.18451","9831.58105","0.11187"
"12.00000","1.19465","9868.84277","0.11187"
"12.10000","1.20475","9904.82910","0.11187"
"12.20000","1.21466","9939.55469","0.11187"
"12.30000","1.22468","9975.12793","0.11187"
"12.40000","1.23455","10008.41992","0.11187"
"12.50000","1.24455","10041.00000","0.11187"
"12.60000","1.25464","10073.37012","0.11187"
"12.70000","1.26460","10104.37402","0.11187"
"12.80000","1.27466","10135.89941","0.11187"
"12.90000","1.28464","10167.35547","0.11187"
"13.00000","1.29460","10198.07520","0.11187"
"13.10000","1.30462","10227.91113","0.11187"
"13.20000","1.31466","10257.31348","0.11187"
"13.30000","1.32461","10284.61328","0.11187"
"13.40000","1.33459","10312.34668","0.11187"
"13.50000","1.34453","10341.08008","0.11187"
"13.60000","1.35455","10369.50098","0.11187"
"13.70000","1.36461","10397.62012","0.11187"
"13.80000","1.37469","10425.04492","0.11187"
"13.90000","1.38470","10450.63672","0.11187"
"14.00000","1.39465","10476.33691","0.11187"
"14.10000","1.40454","10501.59277","0.11187"
"14.20000","1.41444","10526.92090","0.11187"
"14.30000","1.42453","10552.55469","0.11187"
"14.40000","1.43469","10578.35840","0.11187"
"14.50000","1.44477","10603.41602","0.11187"
"14.60000","1.45465","10626.30078","0.11187"
"14.70000","1.46459","10648.61816","0.11187"
"14.80000","1.47449","10672.04883","0.11187"
"14.90000","1.48451","10696.10449","0.11187"
"15.00000","1.49461","10721.10449","0.11187"
"15.10000","1.50463","10743.83691","0.11187"
"15.20000","1.51471","10767.49707","0.11187"
"15.30000","1.52466","10791.12500","0.11187"
"15.40000","1.53456","10813.72656","0.11187"
"15.50000","1.54457","10836.24805","0.11187"
"15.60000","1.55464","10859.00000","0.11187"
"15.70000","1.56465","10879.41406","0.11187"
"15.80000","1.57458","10899.52148","0.11187"
"15.90000","1.58455","10921.88965","0.11187"
"16.00000","1.59458","10944.13867","0.11187"
"16.10000","1.60461","10965.93652","0.11187"
"16.20000","1.61464","10987.55469","0.11187"
"16.30000","1.62470","11008.32715","0.11187"
"16.40000","1.63465","11027.61914","0.11187"
"16.50000","1.64454","11047.45508","0.11187"
"16.60000","1.65448","11067.29297","0.11187"
"16.70000","1.66455","11088.20898","0.11187"
"16.80000","1.67466","11109.51562","0.11187"
"16.90000","1.68479","11129.82910","0.11187"
"17.00000","1.69465","11147.35645","0.11187"
"17.10000","1.70457","11167.28418","0.11187"
"17.20000","1.71444","11186.55957","0.11187"
"17.30000","1.72454","11206.82910","0.11187"
"17.40000","1.73458","11225.88477","0.11187"
"17.50000","1.74469","11244.76758","0.11187"
"17.60000","1.75473","11263.78516","0.11187"
"17.70000","1.76464","11281.91211","0.11187"
"17.80000","1.77453","11299.70312","0.11187"
"17.90000","1.78459","11318.81738","0.11187"
"18.00000","1.79458","11336.68164","0.11187"
"18.10000","1.80464","11354.45312","0.11187"
"18.20000","1.81465","11371.79102","0.11187"
"18.30000","1.82462","11389.75000","0.11187"
"18.40000","1.83457","11407.25098","0.11187"
"18.50000","1.84458","11425.38672","0.11187"
"18.60000","1.85462","11443.15918","0.11187"
"18.70000","1.86468","11460.16406","0.11187"
"18.80000","1.87465","11476.44922","0.11187"
"18.90000","1.88454","11492.59375","0.11187"
"19.00000","1.89447","11509.60449","0.11187"
"19.10000","1.90461","11528.08203","0.11187"
"19.20000","1.91468","11545.50586","0.11187"
"19.30000","1.92476","11562.01367","0.11187"
"19.40000","1.93463","11576.34668","0.11187"
"19.50000","1.94455","11592.48730","0.11187"
"19.60000","1.95443","11607.84473","0.11187"
"19.70000","1.96454","11624.73535","0.11187"
"19.80000","1.97462","11641.37402","0.11187"
"19.90000","1.98472","11657.54004","0.11187"
"20.00000","1.99475","11673.03516","0.11187"
"20.10000","2.00465","11687.32324","0.11187"
"20.20000","2.01448","11701.34277","0.11187"
"20.30000","2.02453","11718.02246","0.11187"
"20.40000","2.03456","11732.53027","0.11187"
"20.50000","2.04467","11747.56543","0.11187"
"20.60000","2.05468","11761.90332","0.11187"
"20.70000","2.06457","11776.12891","0.11187"
"20.80000","2.07458","11791.39062","0.11187"
"20.90000","2.08458","11805.71973","0.11187"
"21.00000","2.09459","11819.76172","0.11187"
"21.10000","2.10467","11834.01465","0.11187"
"21.20000","2.11465","11847.33887","0.11187"
"21.30000","2.12456","11860.09961","0.11187"
"21.40000","2.13450","11874.08301","0.11187"
"21.50000","2.14466","11890.44238","0.11187"
"21.60000","2.15466","11904.08887","0.11187"
"21.70000","2.16474","11917.89160","0.11187"
"21.80000","2.17464","11928.79590","0.11187"
"21.90000","2.18453","11941.73145","0.11187"
"22.00000","2.19442","11954.17285","0.11187"
"22.10000","2.20456","11969.35742","0.11187"
"22.20000","2.21466","11983.16504","0.11187"
"22.30000","2.22474","11995.96191","0.11187"
"22.40000","2.23480","12008.70996","0.11187"
"22.50000","2.24458","12018.98633","0.11187"
"22.60000","2.25448","12030.93652","0.11187"
"22.70000","2.26455","12044.24414","0.11187"
"22.80000","2.27458","12056.34961","0.11187"
"22.90000","2.28471","12068.94727","0.11187"
"23.00000","2.29473","12079.83398","0.11187"
"23.10000","2.30460","12089.98438","0.11187"
"23.20000","2.31456","12101.40820","0.11187"
"23.30000","2.32457","12113.27051","0.11187"
"23.40000","2.33455","12124.29688","0.11187"
"23.50000","2.34468","12136.35059","0.11187"
"23.60000","2.35467","12145.87988","0.11187"
"23.70000","2.36459","12155.39160","0.11187"
"23.80000","2.37455","12166.78125","0.11187"
"23.90000","2.38462","12178.98828","0.11187"
"24.00000","2.39464","12188.75977","0.11187"
"24.10000","2.40470","12198.05566","0.11187"
"24.20000","2.41468","12205.52051","0.11187"
"24.30000","2.42449","12213.26660","0.11187"
"24.40000","2.43439","12222.08594","0.11187"
"24.50000","2.44465","12233.90332","0.11187"
"24.60000","2.45471","12241.41602","0.11187"
"24.70000","2.46475","11232.63770","0.11187"
"24.71200","2.46611","7344.18945","0.11187"