File: archive/undergrad/433/Concentration/Specimen_RawData_3.csv
Time,Extension,Load,Strain Gage18
(s),(mm),(N),(mm/mm)
"0.00000","0.00000","417.00244","0.11676"
"0.30000","0.02405","768.28607","0.11676"
"0.60000","0.05420","1134.37878","0.11676"
"0.90000","0.08414","1449.82092","0.11676"
"1.20000","0.11415","1748.13623","0.11676"
"1.50000","0.14422","2034.01538","0.11676"
"1.80000","0.17409","2305.16895","0.11676"
"2.10000","0.20421","2568.95044","0.11676"
"2.40000","0.23414","2820.97583","0.11676"
"2.70000","0.26419","3060.91772","0.11676"
"3.00000","0.29419","3290.26514","0.11676"
"3.30000","0.32414","3495.41821","0.11676"
"3.60000","0.35422","3698.10425","0.11676"
"3.90000","0.38418","3901.96582","0.11676"
"4.20000","0.41409","4105.85205","0.11676"
"4.50000","0.44428","4314.80225","0.11676"
"4.80000","0.47413","4521.51758","0.11676"
"5.10000","0.50421","4731.39844","0.11676"
"5.40000","0.53417","4941.85059","0.11676"
"5.70000","0.56416","5153.37061","0.11676"
"6.00000","0.59425","5366.61426","0.11676"
"6.30000","0.62418","5578.27881","0.11676"
"6.60000","0.65410","5789.51953","0.11676"
"6.90000","0.68428","6000.33057","0.11676"
"7.20000","0.71412","6202.43750","0.11676"
"7.50000","0.74424","6409.74951","0.11676"
"7.80000","0.77415","6616.55127","0.11676"
"8.10000","0.80415","6825.50830","0.11676"
"8.40000","0.83421","7037.50049","0.11676"
"8.70000","0.86414","7249.84033","0.11676"
"9.00000","0.89419","7464.32471","0.11676"
"9.30000","0.92421","7681.32715","0.11676"
"9.60000","0.95417","7897.80176","0.11676"
"9.90000","0.98424","8118.19043","0.11676"
"10.20000","1.01414","8337.41406","0.11676"
"10.50000","1.04418","8558.84082","0.11676"
"10.80000","1.07425","8780.84863","0.11676"
"11.10000","1.10418","9002.31250","0.11676"
"11.40000","1.13421","9225.20703","0.11676"
"11.70000","1.16416","9447.60156","0.11676"
"12.00000","1.19416","9669.58203","0.11676"
"12.30000","1.22427","9894.35938","0.11676"
"12.60000","1.25414","10114.76367","0.11676"
"12.90000","1.28419","10337.27344","0.11676"
"13.20000","1.31425","10558.31055","0.11676"
"13.50000","1.34412","10777.06055","0.11676"
"13.80000","1.37428","10995.93848","0.11676"
"14.10000","1.40411","11209.94043","0.11676"
"14.40000","1.43421","11421.52832","0.11676"
"14.70000","1.46424","11630.53125","0.11676"
"15.00000","1.49420","11831.10449","0.11676"
"15.30000","1.52420","12027.29297","0.11676"
"15.60000","1.55426","12213.97363","0.11676"
"15.90000","1.58412","12389.38477","0.11676"
"16.20000","1.61423","12556.03125","0.11676"
"16.50000","1.64412","12707.84180","0.11676"
"16.80000","1.67429","12847.47852","0.11676"
"17.10000","1.70420","12972.93555","0.11676"
"17.40000","1.73426","13081.86621","0.11676"
"17.70000","1.76417","13179.16797","0.11676"
"18.00000","1.79426","13264.01953","0.11676"
"18.30000","1.82419","13339.87988","0.11676"
"18.60000","1.85425","13407.41406","0.11676"
"18.90000","1.88411","13470.09375","0.11676"
"19.20000","1.91435","13529.21875","0.11676"
"19.50000","1.94417","13583.66602","0.11676"
"19.80000","1.97426","13633.93945","0.11676"
"20.10000","2.00418","13683.37695","0.11676"
"20.40000","2.03425","13728.40820","0.11676"
"20.70000","2.06422","13773.89258","0.11676"
"21.00000","2.09426","13813.81934","0.11676"
"21.30000","2.12412","13853.33691","0.11676"
"21.60000","2.15439","13894.08594","0.11676"
"21.90000","2.18415","13929.02734","0.11676"
"22.20000","2.21428","13964.37305","0.11676"
"22.50000","2.24416","13998.57227","0.11676"
"22.80000","2.27424","14030.94727","0.11676"
"23.10000","2.30425","14064.76953","0.11676"
"23.40000","2.33428","14094.21094","0.11676"
"23.70000","2.36420","14124.01465","0.11676"
"24.00000","2.39439","14154.58203","0.11676"
"24.30000","2.42415","14181.75000","0.11676"
"24.60000","2.45432","14209.80664","0.11676"
"24.90000","2.48413","14236.10254","0.11676"
"25.20000","2.51430","14262.78516","0.11676"
"25.50000","2.54425","14290.23145","0.11676"
"25.80000","2.57425","14313.35059","0.11676"
"26.10000","2.60426","14340.13574","0.11676"
"26.40000","2.63436","14364.81738","0.11676"
"26.70000","2.66417","14386.63770","0.11676"
"27.00000","2.69436","14410.52734","0.11676"
"27.30000","2.72415","14432.04688","0.11676"
"27.60000","2.75432","14455.87891","0.11676"
"27.90000","2.78429","14480.77246","0.11676"
"28.20000","2.81427","14501.53125","0.11676"
"28.50000","2.84426","14524.54297","0.11676"
"28.80000","2.87433","14546.82617","0.11676"
"29.10000","2.90414","14566.32617","0.11676"
"29.40000","2.93439","14589.13672","0.11676"
"29.70000","2.96419","14609.01367","0.11676"
"30.00000","2.99430","14630.10449","0.11676"
"30.30000","3.02421","14651.28223","0.11676"
"30.60000","3.05434","14671.12109","0.11676"
"30.90000","3.08427","14692.93359","0.11676"
"31.20000","3.11431","14711.53223","0.11676"
"31.50000","3.14421","14731.44336","0.11676"
"31.80000","3.17432","14751.70215","0.11676"
"32.10000","3.20417","14769.80762","0.11676"
"32.40000","3.23437","14791.09961","0.11676"
"32.70000","3.26413","14808.98145","0.11676"
"33.00000","3.29435","14829.03320","0.11676"
"33.30000","3.32428","14848.73438","0.11676"
"33.60000","3.35425","14865.74512","0.11676"
"33.90000","3.38422","14884.64160","0.11676"
"34.20000","3.41426","14903.07324","0.11676"
"34.50000","3.44416","14921.10449","0.11676"
"34.80000","3.47440","14941.11426","0.11676"
"35.10000","3.50404","14955.99316","0.11676"
"35.40000","3.53437","14976.92188","0.11676"
"35.70000","3.56421","14994.44727","0.11676"
"36.00000","3.59419","15010.76855","0.11676"
"36.30000","3.62419","15030.00684","0.11676"
"36.60000","3.65428","15046.74707","0.11676"
"36.90000","3.68416","15064.16211","0.11676"
"37.20000","3.71434","15083.25488","0.11676"
"37.50000","3.74402","15097.22070","0.11676"
"37.80000","3.77438","15117.79297","0.11676"
"38.10000","3.80414","15133.46094","0.11676"
"38.40000","3.83419","15149.34277","0.11676"
"38.70000","3.86416","15167.80078","0.11676"
"39.00000","3.89423","15184.12402","0.11676"
"39.30000","3.92420","15200.96777","0.11676"
"39.60000","3.95432","15218.52637","0.11676"
"39.90000","3.98400","15231.97168","0.11676"
"40.20000","4.01438","15252.52441","0.11676"
"40.50000","4.04402","15265.71777","0.11676"
"40.80000","4.07424","15284.01855","0.11676"
"41.10000","4.10413","15299.17285","0.11676"
"41.40000","4.13424","15315.87500","0.11676"
"41.70000","4.16420","15332.63672","0.11676"
"42.00000","4.19431","15349.82031","0.11676"
"42.30000","4.22402","15362.31445","0.11676"
"42.60000","4.25440","15382.64453","0.11676"
"42.90000","4.28400","15393.63379","0.11676"
"43.20000","4.31436","15412.83691","0.11676"
"43.50000","4.34408","15426.29004","0.11676"
"43.80000","4.37425","15443.22559","0.11676"
"44.10000","4.40417","15458.02930","0.11676"
"44.40000","4.43428","15474.89941","0.11676"
"44.70000","4.46402","15487.70117","0.11676"
"45.00000","4.49436","15507.07227","0.11676"
"45.30000","4.52404","15518.06348","0.11676"
"45.60000","4.55440","15537.95605","0.11676"
"45.90000","4.58406","15548.25000","0.11676"
"46.20000","4.61430","15566.55176","0.11676"
"46.50000","4.64417","15580.67969","0.11676"
"46.80000","4.67425","15595.81445","0.11676"
"47.10000","4.70418","15610.06934","0.11676"
"47.40000","4.73429","15626.12695","0.11676"
"47.70000","4.76404","15637.39453","0.11676"
"48.00000","4.79438","15656.71094","0.11676"
"48.30000","4.82398","15666.58301","0.11676"
"48.60000","4.85432","15684.55957","0.11676"
"48.90000","4.88418","15698.17676","0.11676"
"49.20000","4.91422","15713.11035","0.11676"
"49.50000","4.94421","15727.16699","0.11676"
"49.80000","4.97428","15742.50781","0.11676"
"50.10000","5.00409","15754.46875","0.11676"
"50.40000","5.03437","15772.04297","0.11676"
"50.70000","5.06404","15781.84961","0.11676"
"51.00000","5.09435","15799.99609","0.11676"
"51.30000","5.12416","15811.59375","0.11676"
"51.60000","5.15424","15826.51758","0.11676"
"51.90000","5.18417","15840.04492","0.11676"
"52.20000","5.21428","15854.95605","0.11676"
"52.50000","5.24417","15867.36914","0.11676"
"52.80000","5.27429","15883.07617","0.11676"
"53.10000","5.30411","15893.17871","0.11676"
"53.40000","5.33437","15910.97266","0.11676"
"53.70000","5.36413","15922.25684","0.11676"
"54.00000","5.39425","15936.66406","0.11676"
"54.30000","5.42416","15948.49121","0.11676"
"54.60000","5.45422","15963.66895","0.11676"
"54.90000","5.48422","15976.75488","0.11676"
"55.20000","5.51425","15990.90137","0.11676"
"55.50000","5.54418","16002.67578","0.11676"
"55.80000","5.57437","16018.45508","0.11676"
"56.10000","5.60415","16028.29980","0.11676"
"56.40000","5.63430","16044.11719","0.11676"
"56.70000","5.66412","16054.45117","0.11676"
"57.00000","5.69422","16068.82617","0.11676"
"57.30000","5.72421","16081.70410","0.11676"
"57.60000","5.75423","16094.27441","0.11676"
"57.90000","5.78426","16106.67871","0.11676"
"58.20000","5.81429","16120.94922","0.11676"
"58.50000","5.84412","16131.05859","0.11676"
"58.80000","5.87434","16145.93457","0.11676"
"59.10000","5.90415","16156.95801","0.11676"
"59.40000","5.93423","16170.47070","0.11676"
"59.70000","5.96427","16183.13184","0.11676"
"60.00000","5.99423","16195.88770","0.11676"
"60.30000","6.02426","16208.07324","0.11676"
"60.60000","6.05427","16221.82324","0.11676"
"60.90000","6.08413","16232.73047","0.11676"
"61.20000","6.11428","16246.95703","0.11676"
"61.50000","6.14416","16256.67188","0.11676"
"61.80000","6.17432","16272.21387","0.11676"
"62.10000","6.20420","16282.34668","0.11676"
"62.40000","6.23425","16295.24805","0.11676"
"62.70000","6.26433","16308.06934","0.11676"
"63.00000","6.29422","16319.47168","0.11676"
"63.30000","6.32422","16330.58789","0.11676"
"63.60000","6.35423","16343.69922","0.11676"
"63.90000","6.38415","16354.42871","0.11676"
"64.20000","6.41430","16367.71387","0.11676"
"64.50000","6.44423","16379.45312","0.11676"
"64.80000","6.47421","16391.23047","0.11676"
"65.10000","6.50428","16402.61523","0.11676"
"65.40000","6.53420","16414.42578","0.11676"
"65.70000","6.56419","16425.48047","0.11676"
"66.00000","6.59422","16437.74414","0.11676"
"66.30000","6.62418","16448.38086","0.11676"
"66.60000","6.65425","16461.65039","0.11676"
"66.90000","6.68414","16471.13086","0.11676"
"67.20000","6.71427","16484.66797","0.11676"
"67.50000","6.74421","16494.86523","0.11676"
"67.80000","6.77417","16506.00977","0.11676"
"68.10000","6.80421","16517.97070","0.11676"
"68.40000","6.83417","16529.17383","0.11676"
"68.70000","6.86419","16539.17969","0.11676"
"69.00000","6.89430","16552.81055","0.11676"
"69.30000","6.92413","16561.59375","0.11676"
"69.60000","6.95429","16574.93555","0.11676"
"69.90000","6.98421","16584.66016","0.11676"
"70.20000","7.01416","16595.54297","0.11676"
"70.50000","7.04421","16606.26953","0.11676"
"70.80000","7.07418","16617.77539","0.11676"
"71.10000","7.10421","16628.38672","0.11676"
"71.40000","7.13427","16640.26562","0.11676"
"71.70000","7.16413","16648.81445","0.11676"
"72.00000","7.19429","16662.55664","0.11676"
"72.30000","7.22412","16669.92383","0.11676"
"72.60000","7.25417","16681.80469","0.11676"
"72.90000","7.28416","16692.33984","0.11676"
"73.20000","7.31420","16703.32031","0.11676"
"73.50000","7.34426","16713.96094","0.11676"
"73.80000","7.37420","16724.86719","0.11676"
"74.10000","7.40413","16733.50391","0.11676"
"74.40000","7.43428","16747.08984","0.11676"
"74.70000","7.46417","16755.24023","0.11676"
"75.00000","7.49427","16767.25977","0.11676"
"75.30000","7.52416","16775.56250","0.11676"
"75.60000","7.55419","16787.06641","0.11676"
"75.90000","7.58428","16797.06055","0.11676"
"76.20000","7.61418","16806.80273","0.11676"
"76.50000","7.64417","16816.49023","0.11676"
"76.80000","7.67426","16828.73828","0.11676"
"77.10000","7.70417","16836.53516","0.11676"
"77.40000","7.73432","16849.29883","0.11676"
"77.70000","7.76417","16856.12500","0.11676"
"78.00000","7.79420","16867.00000","0.11676"
"78.30000","7.82425","16877.34961","0.11676"
"78.60000","7.85414","16886.13281","0.11676"
"78.90000","7.88420","16896.32422","0.11676"
"79.20000","7.91424","16907.38867","0.11676"
"79.50000","7.94419","16915.11133","0.11676"
"79.80000","7.97429","16927.46094","0.11676"
"80.10000","8.00419","16934.82812","0.11676"
"80.40000","8.03421","16945.53125","0.11676"
"80.70000","8.06429","16955.13086","0.11676"
"81.00000","8.09417","16963.88672","0.11676"
"81.30000","8.12426","16973.83008","0.11676"
"81.60000","8.15415","16983.12109","0.11676"
"81.90000","8.18425","16992.60547","0.11676"
"82.20000","8.21426","17003.54297","0.11676"
"82.50000","8.24419","17010.63672","0.11676"
"82.80000","8.27423","17021.86523","0.11676"
"83.10000","8.30428","17030.94336","0.11676"
"83.40000","8.33417","17038.83008","0.11676"
"83.70000","8.36430","17049.38672","0.11676"
"84.00000","8.39409","17057.65039","0.11676"
"84.30000","8.42430","17068.17773","0.11676"
"84.60000","8.45424","17077.84766","0.11676"
"84.90000","8.48421","17085.84570","0.11676"
"85.20000","8.51420","17095.16797","0.11676"
"85.50000","8.54427","17104.50781","0.11676"
"85.80000","8.57418","17113.50195","0.11676"
"86.10000","8.60430","17123.00391","0.11676"
"86.40000","8.63413","17131.07422","0.11676"
"86.70000","8.66434","17141.91992","0.11676"
"87.00000","8.69418","17149.66211","0.11676"
"87.30000","8.72430","17158.92578","0.11676"
"87.60000","8.75417","17167.16797","0.11676"
"87.90000","8.78429","17175.97656","0.11676"
"88.20000","8.81425","17185.06641","0.11676"
"88.50000","8.84425","17193.20312","0.11676"
"88.80000","8.87411","17201.22266","0.11676"
"89.10000","8.90440","17212.17969","0.11676"
"89.40000","8.93415","17219.15234","0.11676"
"89.70000","8.96436","17228.14258","0.11676"
"90.00000","8.99417","17235.56836","0.11676"
"90.30000","9.02422","17244.43359","0.11676"
"90.60000","9.05428","17253.61328","0.11676"
"90.90000","9.08428","17261.24805","0.11676"
"91.20000","9.11416","17269.33398","0.11676"
"91.50000","9.14440","17279.75391","0.11676"
"91.80000","9.17414","17286.66211","0.11676"
"92.10000","9.20438","17296.43555","0.11676"
"92.40000","9.23414","17302.86719","0.11676"
"92.70000","9.26428","17311.92773","0.11676"
"93.00000","9.29429","17321.54102","0.11676"
"93.30000","9.32427","17328.03516","0.11676"
"93.60000","9.35426","17336.65820","0.11676"
"93.90000","9.38440","17345.64258","0.11676"
"94.20000","9.41415","17351.63672","0.11676"
"94.50000","9.44435","17361.30859","0.11676"
"94.80000","9.47412","17367.71094","0.11676"
"95.10000","9.50430","17376.90625","0.11676"
"95.40000","9.53427","17385.24219","0.11676"
"95.70000","9.56431","17392.67773","0.11676"
"96.00000","9.59429","17401.15234","0.11676"
"96.30000","9.62436","17409.15234","0.11676"
"96.60000","9.65417","17416.10156","0.11676"
"96.90000","9.68436","17424.64844","0.11676"
"97.20000","9.71419","17431.12891","0.11676"
"97.50000","9.74435","17440.43164","0.11676"
"97.80000","9.77418","17447.18164","0.11676"
"98.10000","9.80431","17455.11523","0.11676"
"98.40000","9.83431","17463.56055","0.11676"
"98.70000","9.86424","17470.36523","0.11676"
"99.00000","9.89420","17477.58594","0.11676"
"99.30000","9.92434","17486.37109","0.11676"
"99.60000","9.95417","17491.95703","0.11676"
"99.90000","9.98435","17500.85938","0.11676"
"100.20000","10.01413","17507.26953","0.11676"
"100.50000","10.04430","17515.38086","0.11676"
"100.80000","10.07428","17523.15430","0.11676"
"101.10000","10.10424","17530.22070","0.11676"
"101.40000","10.13420","17537.36523","0.11676"
"101.70000","10.16430","17545.05273","0.11676"
"102.00000","10.19420","17552.13477","0.11676"
"102.30000","10.22433","17560.60938","0.11676"
"102.60000","10.25406","17565.32031","0.11676"
"102.90000","10.28436","17575.39062","0.11676"
"103.20000","10.31422","17582.30273","0.11676"
"103.50000","10.34420","17588.53125","0.11676"
"103.80000","10.37425","17596.41992","0.11676"
"104.10000","10.40424","17603.24609","0.11676"
"104.40000","10.43419","17609.54492","0.11676"
"104.70000","10.46432","17618.66406","0.11676"
"105.00000","10.49398","17622.89258","0.11676"
"105.30000","10.52439","17632.96484","0.11676"
"105.60000","10.55412","17637.27734","0.11676"
"105.90000","10.58421","17645.47461","0.11676"
"106.20000","10.61419","17652.21680","0.11676"
"106.50000","10.64425","17659.53516","0.11676"
"106.80000","10.67419","17666.39258","0.11676"
"107.10000","10.70433","17674.08594","0.11676"
"107.40000","10.73400","17677.97461","0.11676"
"107.70000","10.76437","17688.64258","0.11676"
"108.00000","10.79408","17692.52734","0.11676"
"108.30000","10.82425","17700.89648","0.11676"
"108.60000","10.85411","17706.46094","0.11676"
"108.90000","10.88424","17713.88672","0.11676"
"109.20000","10.91419","17720.16211","0.11676"
"109.50000","10.94430","17728.39453","0.11676"
"109.80000","10.97403","17731.41797","0.11676"
"110.10000","11.00440","17742.16406","0.11676"
"110.40000","11.03403","17745.80469","0.11676"
"110.70000","11.06431","17754.70898","0.11676"
"111.00000","11.09405","17758.57031","0.11676"
"111.30000","11.12428","17767.55078","0.11676"
"111.60000","11.15421","17773.47852","0.11676"
"111.90000","11.18427","17779.99219","0.11676"
"112.20000","11.21411","17785.49609","0.11676"
"112.50000","11.24436","17794.16406","0.11676"
"112.80000","11.27400","17796.76172","0.11676"
"113.10000","11.30439","17807.77344","0.11676"
"113.40000","11.33402","17809.93164","0.11676"
"113.70000","11.36426","17818.06445","0.11676"
"114.00000","11.39419","17824.58984","0.11676"
"114.30000","11.42426","17831.10742","0.11676"
"114.60000","11.45412","17835.28125","0.11676"
"114.90000","11.48436","17844.93555","0.11676"
"115.20000","11.51402","17846.92188","0.11676"
"115.50000","11.54440","17857.12695","0.11676"
"115.80000","11.57406","17859.51758","0.11676"
"116.10000","11.60434","17867.82617","0.11676"
"116.40000","11.63417","17872.43555","0.11676"
"116.70000","11.66426","17879.54492","0.11676"
"117.00000","11.69417","17884.85352","0.11676"
"117.30000","11.72430","17891.81250","0.11676"
"117.60000","11.75407","17895.34961","0.11676"
"117.90000","11.78435","17904.91992","0.11676"
"118.20000","11.81406","17906.70117","0.11676"
"118.50000","11.84440","17916.45312","0.11676"
"118.80000","11.87415","17919.67773","0.11676"
"119.10000","11.90421","17925.86523","0.11676"
"119.40000","11.93422","17931.97852","0.11676"
"119.70000","11.96423","17939.20703","0.11676"
"120.00000","11.99416","17942.65820","0.11676"
"120.30000","12.02434","17951.09570","0.11676"
"120.60000","12.05409","17953.99219","0.11676"
"120.90000","12.08433","17962.06445","0.11676"
"121.20000","12.11413","17966.07422","0.11676"
"121.50000","12.14425","17972.71875","0.11676"
"121.80000","12.17417","17976.85352","0.11676"
"122.10000","12.20424","17984.23242","0.11676"
"122.40000","12.23416","17989.01953","0.11676"
"122.70000","12.26426","17995.99023","0.11676"
"123.00000","12.29418","18000.23828","0.11676"
"123.30000","12.32433","18008.01562","0.11676"
"123.60000","12.35416","18010.83203","0.11676"
"123.90000","12.38427","18018.48438","0.11676"
"124.20000","12.41416","18022.98633","0.11676"
"124.50000","12.44421","18028.18164","0.11676"
"124.80000","12.47427","18034.45312","0.11676"
"125.10000","12.50418","18040.18359","0.11676"
"125.40000","12.53427","18045.55664","0.11676"
"125.70000","12.56434","18051.87500","0.11676"
"126.00000","12.59414","18055.37109","0.11676"
"126.30000","12.62430","18062.12695","0.11676"
"126.60000","12.65414","18065.98828","0.11676"
"126.90000","12.68417","18071.73438","0.11676"
"127.20000","12.71426","18077.92773","0.11676"
"127.50000","12.74423","18083.16016","0.11676"
"127.80000","12.77430","18088.71680","0.11676"
"128.10001","12.80427","18093.43750","0.11676"
"128.39999","12.83413","18097.42578","0.11676"
"128.70000","12.86430","18104.95312","0.11676"
"129.00000","12.89414","18107.91992","0.11676"
"129.30000","12.92427","18114.96875","0.11676"
"129.60001","12.95422","18119.97070","0.11676"
"129.89999","12.98425","18125.43164","0.11676"
"130.20000","13.01427","18130.12891","0.11676"
"130.50000","13.04424","18136.23828","0.11676"
"130.80000","13.07417","18138.96094","0.11676"
"131.10001","13.10425","18145.03711","0.11676"
"131.39999","13.13416","18148.94922","0.11676"
"131.70000","13.16424","18154.67188","0.11676"
"132.00000","13.19421","18159.41602","0.11676"
"132.30000","13.22423","18165.04297","0.11676"
"132.60001","13.25428","18169.78711","0.11676"
"132.89999","13.28421","18174.30859","0.11676"
"133.20000","13.31417","18178.42773","0.11676"
"133.50000","13.34422","18184.05078","0.11676"
"133.80000","13.37414","18186.45703","0.11676"
"134.10001","13.40430","18194.19141","0.11676"
"134.39999","13.43415","18197.01758","0.11676"
"134.70000","13.46425","18203.09570","0.11676"
"135.00000","13.49424","18207.79492","0.11676"
"135.30000","13.52417","18212.44141","0.11676"
"135.60001","13.55418","18216.40430","0.11676"
"135.89999","13.58422","18221.55469","0.11676"
"136.20000","13.61419","18225.40625","0.11676"
"136.50000","13.64425","18230.20117","0.11676"
"136.80000","13.67410","18234.29688","0.11676"
"137.10001","13.70426","18240.81445","0.11676"
"137.39999","13.73422","18244.25195","0.11676"
"137.70000","13.76419","18249.18750","0.11676"
"138.00000","13.79418","18253.00195","0.11676"
"138.30000","13.82419","18257.91797","0.11676"
"138.60001","13.85425","18262.55664","0.11676"
"138.89999","13.88422","18266.75781","0.11676"
"139.20000","13.91408","18268.71094","0.11676"
"139.50000","13.94431","18277.00586","0.11676"
"139.80000","13.97414","18278.99805","0.11676"
"140.10001","14.00425","18284.45703","0.11676"
"140.39999","14.03419","18287.78125","0.11676"
"140.70000","14.06414","18292.00000","0.11676"
"141.00000","14.09424","18295.89844","0.11676"
"141.30000","14.12422","18301.43750","0.11676"
"141.60001","14.15408","18303.38086","0.11676"
"141.89999","14.18434","18310.20117","0.11676"
"142.20000","14.21416","18311.71484","0.11676"
"142.50000","14.24427","18318.31641","0.11676"
"142.80000","14.27417","18320.68945","0.11676"
"143.10001","14.30417","18325.31641","0.11676"
"143.39999","14.33428","18329.87891","0.11676"
"143.70000","14.36421","18332.95703","0.11676"
"144.00000","14.39417","18336.69336","0.11676"
"144.30000","14.42423","18341.76172","0.11676"
"144.60001","14.45412","18343.69531","0.11676"
"144.89999","14.48431","18350.94531","0.11676"
"145.20000","14.51415","18353.58984","0.11676"
"145.50000","14.54422","18357.99609","0.11676"
"145.80000","14.57429","18362.09180","0.11676"
"146.10001","14.60416","18366.44531","0.11676"
"146.39999","14.63424","18370.57812","0.11676"
"146.70000","14.66419","18374.33398","0.11676"
"147.00000","14.69417","18377.72070","0.11676"
"147.30000","14.72432","18383.75586","0.11676"
"147.60001","14.75415","18386.12500","0.11676"
"147.89999","14.78423","18392.00781","0.11676"
"148.20000","14.81429","18396.07422","0.11676"
"148.50000","14.84415","18398.91406","0.11676"
"148.80000","14.87428","18404.54492","0.11676"
"149.10001","14.90418","18407.96680","0.11676"
"149.39999","14.93424","18411.65039","0.11676"
"149.70000","14.96428","18417.16211","0.11676"
"150.00000","14.99418","18419.08789","0.11676"
"150.30000","15.02421","18424.33203","0.11676"
"150.60001","15.05429","18429.30664","0.11676"
"150.89999","15.08413","18430.88281","0.11676"
"151.20000","15.11429","18436.71289","0.11676"
"151.50000","15.14411","18439.63281","0.11676"
"151.80000","15.17433","18444.46289","0.11676"
"152.10001","15.20424","18448.06445","0.11676"
"152.39999","15.23424","18450.96094","0.11676"
"152.70000","15.26416","18454.47656","0.11676"
"153.00000","15.29420","18458.27344","0.11676"
"153.30000","15.32413","18461.88867","0.11676"
"153.60001","15.35427","18466.73047","0.11676"
"153.89999","15.38418","18469.80078","0.11676"
"154.20000","15.41438","18474.65039","0.11676"
"154.50000","15.44419","18477.07422","0.11676"
"154.80000","15.47425","18480.68164","0.11676"
"155.10001","15.50417","18483.77734","0.11676"
"155.39999","15.53425","18487.38477","0.11676"
"155.70000","15.56425","18491.53320","0.11676"
"156.00000","15.59428","18495.43555","0.11676"
"156.30000","15.62409","18497.09375","0.11676"
"156.60001","15.65438","18502.82031","0.11676"
"156.89999","15.68417","18504.91406","0.11676"
"157.20000","15.71432","18509.51367","0.11676"
"157.50000","15.74416","18511.74609","0.11676"
"157.80000","15.77426","18515.78711","0.11676"
"158.10001","15.80429","18519.23828","0.11676"
"158.39999","15.83424","18521.71289","0.11676"
"158.70000","15.86411","18525.24609","0.11676"
"159.00000","15.89440","18531.46289","0.11676"
"159.30000","15.92414","18533.06836","0.11676"
"159.60001","15.95441","18538.56055","0.11676"
"159.89999","15.98416","18540.17969","0.11676"
"160.20000","16.01429","18543.71289","0.11676"
"160.50000","16.04429","18548.06250","0.11676"
"160.80000","16.07429","18551.23438","0.11676"
"161.10001","16.10425","18554.79492","0.11676"
"161.39999","16.13440","18559.61328","0.11676"
"161.70000","16.16414","18560.42578","0.11676"
"162.00000","16.19441","18566.09961","0.11676"
"162.30000","16.22420","18567.56836","0.11676"
"162.60001","16.25430","18570.35938","0.11676"
"162.89999","16.28427","18573.63281","0.11676"
"163.20000","16.31430","18576.57031","0.11676"
"163.50000","16.34428","18579.33984","0.11676"
"163.80000","16.37434","18582.28906","0.11676"
"164.10001","16.40417","18584.18945","0.11676"
"164.39999","16.43437","18588.57031","0.11676"
"164.70000","16.46422","18589.82227","0.11676"
"165.00000","16.49435","18593.59570","0.11676"
"165.30000","16.52422","18595.76953","0.11676"
"165.60001","16.55433","18598.45312","0.11676"
"165.89999","16.58431","18601.89844","0.11676"
"166.20000","16.61428","18604.36328","0.11676"
"166.50000","16.64421","18606.22266","0.11676"
"166.80000","16.67433","18609.66016","0.11676"
"167.10001","16.70419","18612.30664","0.11676"
"167.39999","16.73438","18616.51172","0.11676"
"167.70000","16.76415","18617.68164","0.11676"
"168.00000","16.79434","18621.95117","0.11676"
"168.30000","16.82431","18624.88477","0.11676"
"168.60001","16.85420","18626.36523","0.11676"
"168.89999","16.88425","18631.00781","0.11676"
"169.20000","16.91426","18633.26953","0.11676"
"169.50000","16.94415","18635.40625","0.11676"
"169.80000","16.97435","18640.72266","0.11676"
"170.10001","17.00406","18640.10156","0.11676"
"170.39999","17.03436","18646.42188","0.11676"
"170.70000","17.06421","18648.69727","0.11676"
"171.00000","17.09419","18650.99219","0.11676"
"171.30000","17.12421","18654.33203","0.11676"
"171.60001","17.15425","18657.43750","0.11676"
"171.89999","17.18415","18658.89258","0.11676"
"172.20000","17.21434","18663.34180","0.11676"
"172.50000","17.24405","18664.10352","0.11676"
"172.80000","17.27433","18668.60938","0.11676"
"173.10001","17.30413","18670.48047","0.11676"
"173.39999","17.33421","18674.11133","0.11676"
"173.70000","17.36416","18676.40234","0.11676"
"174.00000","17.39422","18678.32812","0.11676"
"174.30000","17.42423","18681.34570","0.11676"
"174.60001","17.45428","18683.79883","0.11676"
"174.89999","17.48399","18684.00195","0.11676"
"175.20000","17.51441","18690.85352","0.11676"
"175.50000","17.54406","18690.32227","0.11676"
"175.80000","17.57424","18694.70898","0.11676"
"176.10001","17.60414","18696.99414","0.11676"
"176.39999","17.63422","18700.52930","0.11676"
"176.70000","17.66421","18702.86133","0.11676"
"177.00000","17.69430","18707.68945","0.11676"
"177.30000","17.72402","18708.78320","0.11676"
"177.60001","17.75438","18715.19336","0.11676"
"177.89999","17.78403","18716.52734","0.11676"
"178.20000","17.81432","18723.78711","0.11676"
"178.50000","17.84406","18724.97461","0.11676"
"178.80000","17.87426","18731.40430","0.11676"
"179.10001","17.90419","18735.37695","0.11676"
"179.39999","17.93426","18739.61328","0.11676"
"179.70000","17.96409","18741.61914","0.11676"
"180.00000","17.99434","18748.81641","0.11676"
"180.30000","18.02398","18748.46289","0.11676"
"180.60001","18.05439","18756.62695","0.11676"
"180.89999","18.08401","18755.75391","0.11676"
"181.20000","18.11431","18760.68945","0.11676"
"181.50000","18.14421","18762.25781","0.11676"
"181.80000","18.17423","18764.52734","0.11676"
"182.10001","18.20413","18764.47852","0.11676"
"182.39999","18.23433","18767.64844","0.11676"
"182.70000","18.26400","18764.29688","0.11676"
"183.00000","18.29438","18768.09180","0.11676"
"183.30000","18.32404","18764.79297","0.11676"
"183.60001","18.35433","18766.14258","0.11676"
"183.89999","18.38420","18762.71289","0.11676"
"184.20000","18.41423","18760.54492","0.11676"
"184.50000","18.44418","18758.50977","0.11676"
"184.80000","18.47427","18756.76172","0.11676"
"185.10001","18.50403","18751.27539","0.11676"
"185.39999","18.53432","18753.29688","0.11676"
"185.70000","18.56407","18747.47070","0.11676"
"186.00000","18.59440","18750.76367","0.11676"
"186.30000","18.62415","18748.51367","0.11676"
"186.60001","18.65422","18750.48047","0.11676"
"186.89999","18.68418","18752.87500","0.11676"
"187.20000","18.71427","18756.15820","0.11676"
"187.50000","18.74417","18756.65430","0.11676"
"187.80000","18.77433","18762.15430","0.11676"
"188.10001","18.80408","18762.52344","0.11676"
"188.39999","18.83436","18768.23242","0.11676"
"188.70000","18.86411","18768.25000","0.11676"
"189.00000","18.89426","18773.02734","0.11676"
"189.30000","18.92416","18774.25586","0.11676"
"189.60001","18.95419","18778.28906","0.11676"
"189.89999","18.98422","18780.26172","0.11676"
"190.20000","19.01425","18782.84961","0.11676"
"190.50000","19.04419","18782.54688","0.11676"
"190.80000","19.07435","18787.40820","0.11676"
"191.10001","19.10409","18786.61133","0.11676"
"191.39999","19.13427","18791.12500","0.11676"
"191.70000","19.16419","18794.40625","0.11676"
"192.00000","19.19423","18799.58203","0.11676"
"192.30000","19.22425","18804.31641","0.11676"
"192.60001","19.25423","18809.09570","0.11676"
"192.89999","19.28423","18809.09961","0.11676"
"193.20000","19.31433","18809.37305","0.11676"
"193.50000","19.34413","18799.19336","0.11676"
"193.80000","19.37430","18790.84375","0.11676"
"194.10001","19.40414","18778.59766","0.11676"
"194.39999","19.43424","18778.24805","0.11676"
"194.70000","19.46424","18786.41992","0.11676"
"195.00000","19.49422","18796.32812","0.11676"
"195.30000","19.52433","18800.53906","0.11676"
"195.60001","19.55424","18793.87305","0.11676"
"195.89999","19.58417","18779.59180","0.11676"
"196.20000","19.61432","18780.16602","0.11676"
"196.50000","19.64412","18784.42383","0.11676"
"196.80000","19.67426","18787.38672","0.11676"
"197.10001","19.70424","18771.53320","0.11676"
"197.39999","19.73421","18771.88477","0.11676"
"197.70000","19.76432","18781.48438","0.11676"
"198.00000","19.79425","18773.45508","0.11676"
"198.30000","19.82416","18758.40820","0.11676"
"198.60001","19.85426","18771.94531","0.11676"
"198.89999","19.88418","18769.41602","0.11676"
"199.20000","19.91425","18751.52734","0.11676"
"199.50000","19.94419","18762.84375","0.11676"
"199.80000","19.97421","18770.12695","0.11676"
"200.10001","20.00429","18743.43750","0.11676"
"200.39999","20.03423","18756.95117","0.11676"
"200.70000","20.06423","18768.08594","0.11676"
"201.00000","20.09424","18743.69727","0.11676"
"201.30000","20.12415","18752.29102","0.11676"
"201.60001","20.15428","18769.84570","0.11676"
"201.89999","20.18414","18735.65234","0.11676"
"202.20000","20.21430","18756.47461","0.11676"
"202.50000","20.24427","18764.54297","0.11676"
"202.80000","20.27416","18734.08203","0.11676"
"203.10001","20.30422","18764.59961","0.11676"
"203.39999","20.33422","18758.26172","0.11676"
"203.70000","20.36418","18733.77930","0.11676"
"204.00000","20.39431","18776.42578","0.11676"
"204.30000","20.42411","18728.37500","0.11676"
"204.60001","20.45432","18751.86133","0.11676"
"204.89999","20.48420","18777.96289","0.11676"
"205.20000","20.51422","18715.33398","0.11676"
"205.50000","20.54420","18766.67383","0.11676"
"205.80000","20.57419","18739.51172","0.11676"
"206.10001","20.60423","18733.12500","0.11676"
"206.39999","20.63423","18786.63477","0.11676"
"206.70000","20.66414","18688.82812","0.11676"
"207.00000","20.69430","18776.22852","0.11676"
"207.30000","20.72417","18740.23047","0.11676"
"207.60001","20.75422","18739.23438","0.11676"
"207.89999","20.78419","18817.82422","0.11676"
"208.20000","20.81418","18687.82422","0.11676"
"208.50000","20.84422","18798.17969","0.11676"
"208.80000","20.87421","18798.80859","0.11676"
"209.10001","20.90408","18727.83203","0.11676"
"209.39999","20.93431","18846.78516","0.11676"
"209.70000","20.96420","18644.94922","0.11676"
"210.00000","20.99428","18781.24414","0.11676"
"210.30000","21.02414","18879.78320","0.11676"
"210.60001","21.05418","18658.54688","0.11676"
"210.89999","21.08427","18817.78906","0.11676"
"211.20000","21.11413","18894.02930","0.11676"
"211.50000","21.14412","18674.07227","0.11676"
"211.80000","21.17426","18840.23242","0.11676"
"212.10001","21.20414","18898.25781","0.11676"
"212.39999","21.23429","18698.70898","0.11676"
"212.70000","21.26416","18855.67969","0.11676"
"213.00000","21.29416","18907.06641","0.11676"
"213.30000","21.32426","18718.46875","0.11676"
"213.60001","21.35415","18870.18164","0.11676"
"213.89999","21.38420","18916.04297","0.11676"
"214.20000","21.41421","18733.76367","0.11676"
"214.50000","21.44416","18879.67969","0.11676"
"214.80000","21.47427","18935.65430","0.11676"
"215.10001","21.50418","18739.76367","0.11676"
"215.39999","21.53423","18881.34570","0.11676"
"215.70000","21.56424","18949.25977","0.11676"
"216.00000","21.59418","18745.96094","0.11676"
"216.30000","21.62431","18874.48828","0.11676"
"216.60001","21.65414","18952.37305","0.11676"
"216.89999","21.68426","18755.44336","0.11676"
"217.20000","21.71428","18865.03711","0.11676"
"217.50000","21.74413","18951.69531","0.11676"
"217.80000","21.77423","18838.21094","0.11676"
"218.10001","21.80428","18846.11914","0.11676"
"218.39999","21.83411","18943.10742","0.11676"
"218.70000","21.86432","18939.45898","0.11676"
"219.00000","21.89411","18830.50977","0.11676"
"219.30000","21.92429","18931.31055","0.11676"
"219.60001","21.95425","18969.83008","0.11676"
"219.89999","21.98422","18814.54297","0.11676"
"220.20000","22.01418","18912.08203","0.11676"
"220.50000","22.04424","18978.84375","0.11676"
"220.80000","22.07425","18840.84570","0.11676"
"221.10001","22.10425","18883.41602","0.11676"
"221.39999","22.13408","18968.99219","0.11676"
"221.70000","22.16437","18937.34180","0.11676"
"222.00000","22.19419","18856.49219","0.11676"
"222.30000","22.22426","18957.69336","0.11676"
"222.60001","22.25418","18990.72461","0.11676"
"222.89999","22.28425","18817.24805","0.11676"
"223.20000","22.31419","18928.98047","0.11676"
"223.50000","22.34424","19000.61523","0.11676"
"223.80000","22.37415","18807.30469","0.11676"
"224.10001","22.40432","18889.70508","0.11676"
"224.39999","22.43419","18987.71484","0.11676"
"224.70000","22.46435","18945.05859","0.11676"
"225.00000","22.49414","18835.03516","0.11676"
"225.30000","22.52425","18962.95898","0.11676"
"225.60001","22.55428","19005.75977","0.11676"
"225.89999","22.58424","18765.05078","0.11676"
"226.20000","22.61416","18926.23828","0.11676"
"226.50000","22.64439","19015.50391","0.11676"
"226.80000","22.67410","18682.83984","0.11676"
"227.10001","22.70436","18880.06836","0.11676"
"227.39999","22.73417","19005.00977","0.11676"
"227.70000","22.76436","18603.27344","0.11676"
"228.00000","22.79429","18817.32617","0.11676"
"228.30000","22.82428","18975.67773","0.11676"
"228.60001","22.85424","18664.24609","0.11676"
"228.89999","22.88436","18746.38672","0.11676"
"229.20000","22.91416","18933.56836","0.11676"
"229.50000","22.94436","19019.30859","0.11676"
"229.80000","22.97417","18684.12305","0.11676"
"230.10001","23.00433","18893.76367","0.11676"
"230.39999","23.03424","19009.58203","0.11676"
"230.70000","23.06429","18639.61914","0.11676"
"231.00000","23.09431","18860.56836","0.11676"
"231.30000","23.12431","18999.19531","0.11676"
"231.60001","23.15416","18604.69922","0.11676"
"231.89999","23.18439","18832.09375","0.11676"
"232.20000","23.21416","18982.06250","0.11676"
"232.50000","23.24442","18574.95508","0.11676"
"232.80000","23.27423","18798.56445","0.11676"
"233.10001","23.30429","18962.13672","0.11676"
"233.39999","23.33439","18541.44336","0.11676"
"233.70000","23.36432","18767.84766","0.11676"
"234.00000","23.39417","18931.24023","0.11676"
"234.30000","23.42440","18504.64258","0.11676"
"234.60001","23.45418","18724.82812","0.11676"
"234.89999","23.48437","18571.77930","0.11676"
"235.20000","23.51414","18547.33594","0.11676"
"235.50000","23.54441","18424.04688","0.11676"
"235.80000","23.57428","18382.64844","0.11676"
"236.10001","23.60427","18398.77930","0.11676"
"236.39999","23.63421","18480.36523","0.11676"
"236.70000","23.66426","18573.85547","0.11676"
"237.00000","23.69414","18666.02539","0.11676"
"237.30000","23.72435","18740.52344","0.11676"
"237.60001","23.75398","18787.68750","0.11676"
"237.89999","23.78440","18831.34375","0.11676"
"238.20000","23.81426","18864.57422","0.11676"
"238.50000","23.84422","18889.59766","0.11676"
"238.80000","23.87419","18909.43945","0.11676"
"239.10001","23.90426","18927.75391","0.11676"
"239.39999","23.93417","18940.61328","0.11676"
"239.70000","23.96434","18956.85742","0.11676"
"240.00000","23.99403","18966.86914","0.11676"
"240.30000","24.02439","18980.97461","0.11676"
"240.60001","24.05416","18987.18164","0.11676"
"240.89999","24.08419","18994.18555","0.11676"
"241.20000","24.11413","19001.71484","0.11676"
"241.50000","24.14422","19009.57617","0.11676"
"241.80000","24.17423","19018.11328","0.11676"
"242.10001","24.20431","19024.70508","0.11676"
"242.39999","24.23402","19022.75391","0.11676"
"242.70000","24.26440","19024.94336","0.11676"
"243.00000","24.29408","19019.50195","0.11676"
"243.30000","24.32425","19018.57617","0.11676"
"243.60001","24.35411","19013.97070","0.11676"
"243.89999","24.38424","19008.04102","0.11676"
"244.20000","24.41422","18999.22266","0.11676"
"244.50000","24.44432","18999.99023","0.11676"
"244.80000","24.47403","18993.38867","0.11676"
"245.10001","24.50440","18979.13086","0.11676"
"245.39999","24.53403","18974.82227","0.11676"
"245.70000","24.56432","18995.29297","0.11676"
"246.00000","24.59407","18967.21484","0.11676"
"246.30000","24.62424","18965.96484","0.11676"
"246.60001","24.65421","18999.42383","0.11676"
"246.89999","24.68426","18951.11719","0.11676"
"247.20000","24.71408","18947.83008","0.11676"
"247.50000","24.74436","19012.68164","0.11676"
"247.80000","24.77401","18856.62109","0.11676"
"248.10001","24.80435","18963.01562","0.11676"
"248.39999","24.83405","19038.35156","0.11676"
"248.70000","24.86431","18751.48047","0.11676"
"249.00000","24.89418","18942.44336","0.11676"
"249.30000","24.92426","19066.31055","0.11676"
"249.38100","24.93270","10936.48633","0.11676"