File: archive/undergrad/433/RESIDUAL/Specimen_RawData_2.csv
Time,Extension,Load,Strain Gage18
(s),(mm),(N),(mm/mm)
"0.00000","0.00000","0.02834","0.00000"
"0.50000","0.08954","-0.01208","0.00000"
"1.00000","0.18944","0.02901","0.00000"
"1.50000","0.28963","-0.13847","0.00000"
"2.00000","0.38961","0.00379","0.00000"
"2.50000","0.48943","0.04057","0.00000"
"3.00000","0.58968","0.09048","0.00000"
"3.50000","0.68951","0.09588","0.00000"
"4.00000","0.78948","0.21269","0.00000"
"4.50000","0.88973","0.19444","0.00000"
"5.00000","0.98951","0.24705","0.00000"
"5.50000","1.08950","0.36962","0.00000"
"6.00000","1.18969","0.35017","-0.00001"
"6.50000","1.28950","0.45904","-0.00001"
"7.00000","1.38950","0.43931","-0.00001"
"7.50000","1.48973","0.42947","-0.00001"
"8.00000","1.58948","0.46836","-0.00001"
"8.50000","1.68948","0.58883","-0.00001"
"9.00000","1.78971","0.55880","-0.00001"
"9.50000","1.88949","0.64912","-0.00001"
"10.00000","1.98952","0.58787","-0.00001"
"10.50000","2.08971","0.73695","-0.00001"
"11.00000","2.18949","0.84028","-0.00001"
"11.50000","2.28953","0.68402","-0.00001"
"12.00000","2.38968","0.79391","-0.00001"
"12.50000","2.48947","0.88626","-0.00002"
"13.00000","2.58952","0.90212","-0.00002"
"13.50000","2.68965","1.02665","-0.00002"
"14.00000","2.78947","1.11860","-0.00002"
"14.50000","2.88960","1.05930","-0.00002"
"15.00000","2.98965","1.19717","-0.00002"
"15.50000","3.08947","1.02487","-0.00002"
"16.00000","3.18957","1.20091","-0.00002"
"16.50000","3.28969","1.12474","-0.00002"
"17.00000","3.38946","1.31868","-0.00002"
"17.50000","3.48960","1.43197","-0.00002"
"18.00000","3.58964","1.40484","-0.00002"
"18.50000","3.68945","1.30678","-0.00002"
"19.00000","3.78961","1.29823","-0.00002"
"19.50000","3.88959","1.48021","-0.00002"
"20.00000","3.98947","1.51499","-0.00003"
"20.50000","4.08962","1.57860","-0.00003"
"21.00000","4.18958","1.56821","-0.00003"
"21.50000","4.28946","1.55959","-0.00003"
"22.00000","4.38964","1.74712","-0.00003"
"22.50000","4.48959","1.68957","-0.00003"
"23.00000","4.58945","1.84676","-0.00003"
"23.50000","4.68964","1.80090","-0.00003"
"24.00000","4.78958","1.81715","-0.00003"
"24.50000","4.88946","1.84714","-0.00003"
"25.00000","4.98972","1.97956","-0.00003"
"25.50000","5.08953","1.89941","-0.00003"
"26.00000","5.18948","2.13211","-0.00003"
"26.50000","5.28969","2.14657","-0.00004"
"27.00000","5.38952","2.17948","-0.00004"
"27.50000","5.48946","2.20050","-0.00004"
"28.00000","5.58970","2.32301","-0.00004"
"28.50000","5.68947","2.30343","-0.00004"
"29.00000","5.78947","2.44134","-0.00004"
"29.50000","5.88973","2.42184","-0.00004"
"30.00000","5.98949","2.34332","-0.00004"
"30.50000","6.08948","2.54586","-0.00004"
"31.00000","6.18973","2.61896","-0.00004"
"31.50000","6.28949","2.58787","-0.00004"
"32.00000","6.38951","2.67092","-0.00004"
"32.50000","6.48968","2.72822","-0.00005"
"33.00000","6.58950","2.69573","-0.00004"
"33.50000","6.68952","2.80811","-0.00005"
"34.00000","6.78968","2.80840","-0.00005"
"34.50000","6.88949","2.92488","-0.00005"
"35.00000","6.98953","2.91498","-0.00005"
"35.50000","7.08966","3.04744","-0.00005"
"36.00000","7.18947","3.02898","-0.00005"
"36.50000","7.28956","3.14843","-0.00005"
"37.00000","7.38973","3.15344","-0.00005"
"37.50000","7.48949","3.12582","-0.00005"
"38.00000","7.58959","3.28691","-0.00005"
"38.50000","7.68966","3.22711","-0.00005"
"39.00000","7.78948","3.29944","-0.00005"
"39.50000","7.88956","3.33869","-0.00005"
"40.00000","7.98964","3.43609","-0.00006"
"40.50000","8.08947","3.37584","-0.00006"
"41.00000","8.18962","3.43554","-0.00006"
"41.50000","8.28959","3.57084","-0.00006"
"42.00000","8.38949","3.55697","-0.00006"
"42.50000","8.48957","3.62478","-0.00006"
"43.00000","8.58959","3.61711","-0.00006"
"43.50000","8.68947","3.56655","-0.00006"
"44.00000","8.78968","3.66917","-0.00006"
"44.50000","8.88956","3.78847","-0.00006"
"45.00000","8.98949","3.74955","-0.00006"
"45.50000","9.08965","3.81037","-0.00006"
"46.00000","9.18958","3.82962","-0.00007"
"46.50000","9.28947","3.91864","-0.00007"
"47.00000","9.38969","3.86655","-0.00007"
"47.50000","9.48952","3.92109","-0.00007"
"48.00000","9.58947","4.02837","-0.00007"
"48.50000","9.68968","3.94889","-0.00007"
"49.00000","9.78958","4.18100","-0.00007"
"49.50000","9.88939","4.17379","-0.00007"
"50.00000","9.98970","4.18104","-0.00007"
"50.50000","10.08952","4.30921","-0.00007"
"51.00000","10.18948","4.28566","-0.00007"
"51.50000","10.28974","4.41140","-0.00007"
"52.00000","10.38952","4.44829","-0.00007"
"52.50000","10.48951","4.46490","-0.00007"
"53.00000","10.58969","4.55349","-0.00007"
"53.50000","10.68948","4.58007","-0.00008"
"54.00000","10.78953","4.75075","-0.00008"
"54.50000","10.88970","4.70599","-0.00008"
"55.00000","10.98948","4.77384","-0.00008"
"55.50000","11.08955","4.74504","-0.00008"
"56.00000","11.18972","4.74705","-0.00008"
"56.50000","11.28946","4.83616","-0.00008"
"57.00000","11.38951","4.94246","-0.00008"
"57.50000","11.48972","5.00398","-0.00008"
"58.00000","11.58950","4.97215","-0.00008"
"58.50000","11.68956","5.00436","-0.00008"
"59.00000","11.78967","4.95379","-0.00008"
"59.50000","11.88949","5.19502","-0.00008"
"60.00000","11.98955","5.15917","-0.00009"
"60.50000","12.08968","5.25565","-0.00009"
"61.00000","12.18946","5.27151","-0.00009"
"61.50000","12.28961","5.37835","-0.00009"
"62.00000","12.38962","5.31653","-0.00009"
"62.50000","12.48948","5.38578","-0.00009"
"63.00000","12.58959","5.29530","-0.00009"
"63.50000","12.68964","5.48866","-0.00009"
"64.00000","12.78948","5.50879","-0.00009"
"64.50000","12.88965","5.55994","-0.00009"
"65.00000","12.98957","5.57013","-0.00009"
"65.50000","13.08947","5.69871","-0.00009"
"66.00000","13.18963","5.66164","-0.00010"
"66.50000","13.28960","5.74241","-0.00010"
"67.00000","13.38946","5.69539","-0.00010"
"67.50000","13.48967","5.75030","-0.00010"
"68.00000","13.58956","5.83321","-0.00010"
"68.50000","13.68948","5.76582","-0.00010"
"69.00000","13.78964","5.89009","-0.00010"
"69.50000","13.88958","5.93921","-0.00010"
"70.00000","13.98945","6.06776","-0.00010"
"70.50000","14.08965","6.04788","-0.00010"
"71.00000","14.18954","6.06900","-0.00010"
"71.50000","14.28947","6.18136","-0.00010"
"72.00000","14.38972","6.17330","-0.00010"
"72.50000","14.48947","6.27869","-0.00010"
"73.00000","14.58950","6.22684","-0.00010"
"73.50000","14.68970","6.33836","-0.00011"
"74.00000","14.78949","6.43915","-0.00011"
"74.50000","14.88950","6.44496","-0.00011"
"75.00000","14.98972","6.47832","-0.00011"
"75.50000","15.08950","6.61285","-0.00011"
"76.00000","15.18948","6.57861","-0.00011"
"76.50000","15.28972","6.58144","-0.00011"
"77.00000","15.38946","6.61682","-0.00011"
"77.50000","15.48950","6.76651","-0.00011"
"78.00000","15.58975","6.71466","-0.00011"
"78.50000","15.68948","6.92161","-0.00011"
"79.00000","15.78954","6.90226","-0.00011"
"79.50000","15.88967","6.86354","-0.00011"
"80.00000","15.98951","6.90951","-0.00012"
"80.50000","16.08948","6.85568","-0.00012"
"81.00000","16.18969","7.02485","-0.00012"
"81.50000","16.28948","7.18064","-0.00012"
"82.00000","16.38957","7.16730","-0.00012"
"82.50000","16.48969","7.16141","-0.00012"
"83.00000","16.58951","7.27396","-0.00012"
"83.50000","16.68958","7.26016","-0.00012"
"84.00000","16.78968","7.39618","-0.00012"
"84.50000","16.88947","7.32422","-0.00012"
"85.00000","16.98956","7.51726","-0.00012"
"85.50000","17.08963","7.52103","-0.00012"
"86.00000","17.18947","7.45470","-0.00012"
"86.50000","17.28958","7.46037","-0.00013"
"87.00000","17.38962","7.59809","-0.00013"
"87.50000","17.48946","7.62335","-0.00013"
"88.00000","17.58967","7.59536","-0.00013"
"88.50000","17.68952","7.69134","-0.00013"
"89.00000","17.78950","7.78834","-0.00013"
"89.50000","17.88963","7.83862","-0.00013"
"90.00000","17.98959","7.81665","-0.00013"
"90.50000","18.08947","7.90110","-0.00013"
"91.00000","18.18965","7.87623","-0.00013"
"91.50000","18.28953","8.07672","-0.00013"
"92.00000","18.38948","7.98467","-0.00013"
"92.50000","18.48967","8.10016","-0.00013"
"93.00000","18.58952","8.10469","-0.00013"
"93.50000","18.68945","8.07167","-0.00014"
"94.00000","18.78971","8.10170","-0.00014"
"94.50000","18.88946","8.26373","-0.00014"
"95.00000","18.98954","8.28703","-0.00014"
"95.50000","19.08967","8.36513","-0.00014"
"96.00000","19.18956","8.46143","-0.00014"
"96.50000","19.28943","8.41720","-0.00014"
"97.00000","19.38972","8.39116","-0.00014"
"97.50000","19.48948","8.50035","-0.00014"
"98.00000","19.58953","8.45988","-0.00014"
"98.50000","19.68969","8.59904","-0.00014"
"99.00000","19.78950","8.62720","-0.00014"
"99.50000","19.88951","8.65063","-0.00014"
"100.00000","19.98970","8.63991","-0.00015"
"100.50000","20.08947","8.82756","-0.00015"
"101.00000","20.18956","8.89661","-0.00015"
"101.50000","20.28969","8.88550","-0.00015"
"102.00000","20.38950","8.95521","-0.00015"
"102.50000","20.48953","8.97122","-0.00015"
"103.00000","20.58971","9.01192","-0.00015"
"103.50000","20.68948","9.04521","-0.00015"
"104.00000","20.78955","9.12562","-0.00015"
"104.50000","20.88972","9.15594","-0.00015"
"105.00000","20.98946","9.28713","-0.00015"
"105.50000","21.08958","9.22069","-0.00015"
"106.00000","21.18965","9.35470","-0.00015"
"106.50000","21.28949","9.28531","-0.00015"
"107.00000","21.38954","9.43404","-0.00016"
"107.50000","21.48966","9.37676","-0.00016"
"108.00000","21.58948","9.40322","-0.00016"
"108.50000","21.68961","9.54970","-0.00016"
"109.00000","21.78966","9.51759","-0.00016"
"109.50000","21.88951","9.58388","-0.00016"
"110.00000","21.98956","9.61338","-0.00016"
"110.50000","22.08961","9.74868","-0.00016"
"111.00000","22.18947","9.71220","-0.00016"
"111.50000","22.28965","9.71465","-0.00016"
"112.00000","22.38955","9.83728","-0.00016"
"112.50000","22.48946","9.84694","-0.00016"
"113.00000","22.58965","9.84367","-0.00016"
"113.50000","22.68956","9.95090","-0.00017"
"114.00000","22.78947","9.96661","-0.00017"
"114.50000","22.88970","10.04089","-0.00017"
"115.00000","22.98952","10.07050","-0.00017"
"115.50000","23.08946","10.03263","-0.00017"
"116.00000","23.18969","10.14289","-0.00017"
"116.50000","23.28955","10.12699","-0.00017"
"117.00000","23.38946","10.21801","-0.00017"
"117.50000","23.48967","10.27534","-0.00017"
"118.00000","23.58951","10.27195","-0.00017"
"118.50000","23.68947","10.41711","-0.00017"
"119.00000","23.78973","10.50465","-0.00017"
"119.50000","23.88949","10.51865","-0.00017"
"120.00000","23.98953","10.46980","-0.00018"
"120.50000","24.08969","10.52117","-0.00018"
"121.00000","24.18948","10.53292","-0.00018"
"121.50000","24.28951","10.61908","-0.00018"
"122.00000","24.38972","10.76945","-0.00018"
"122.50000","24.48948","10.71613","-0.00018"
"123.00000","24.58948","10.80658","-0.00018"
"123.50000","24.68973","10.86443","-0.00018"
"124.00000","24.78948","10.87612","-0.00018"
"124.50000","24.88952","10.99517","-0.00018"
"125.00000","24.98972","10.83616","-0.00018"
"125.50000","25.08948","11.08337","-0.00018"
"126.00000","25.18954","11.04303","-0.00018"
"126.50000","25.28966","11.11456","-0.00018"
"127.00000","25.38950","11.11825","-0.00019"
"127.50000","25.48953","11.23836","-0.00019"
"128.00000","25.58966","11.25182","-0.00019"
"128.50000","25.68947","11.21739","-0.00019"
"129.00000","25.78961","11.26778","-0.00019"
"129.50000","25.88965","11.30261","-0.00019"
"130.00000","25.98950","11.35476","-0.00019"
"130.50000","26.08960","11.45992","-0.00019"
"131.00000","26.18961","11.51643","-0.00019"
"131.50000","26.28951","11.56027","-0.00019"
"132.00000","26.38959","11.56578","-0.00019"
"132.50000","26.48958","11.57289","-0.00019"
"133.00000","26.58942","11.58494","-0.00020"
"133.50000","26.68963","11.67583","-0.00020"
"134.00000","26.78957","11.67582","-0.00020"
"134.50000","26.88947","11.69684","-0.00020"
"135.00000","26.98966","11.80726","-0.00020"
"135.50000","27.08954","11.70774","-0.00020"
"136.00000","27.18946","11.85627","-0.00020"
"136.50000","27.28968","11.82254","-0.00020"
"137.00000","27.38956","11.85777","-0.00020"
"137.50000","27.48946","11.95856","-0.00020"
"138.00000","27.58968","12.08070","-0.00020"
"138.50000","27.68952","11.97102","-0.00020"
"139.00000","27.78945","12.05122","-0.00020"
"139.50000","27.88972","12.10992","-0.00021"
"140.00000","27.98949","12.09786","-0.00021"
"140.50000","28.08950","12.23261","-0.00021"
"141.00000","28.18966","12.21071","-0.00021"
"141.50000","28.28951","12.24986","-0.00021"
"142.00000","28.38951","12.33409","-0.00021"
"142.50000","28.48970","12.26112","-0.00021"
"143.00000","28.58948","12.12177","-0.00021"
"143.50000","28.68948","12.24137","-0.00021"
"144.00000","28.78971","12.25442","-0.00021"
"144.50000","28.88950","12.33972","-0.00021"
"145.00000","28.98950","12.33223","-0.00021"
"145.50000","29.08975","12.39050","-0.00022"
"146.00000","29.18947","12.55010","-0.00022"
"146.50000","29.28951","12.55909","-0.00022"
"147.00000","29.38967","12.70215","-0.00022"
"147.50000","29.48948","12.79622","-0.00022"
"148.00000","29.58952","12.79069","-0.00022"
"148.50000","29.68967","12.77462","-0.00022"
"149.00000","29.78948","12.80756","-0.00022"
"149.50000","29.88961","12.97862","-0.00022"
"150.00000","29.98966","12.99772","-0.00022"
"150.50000","30.08948","12.98881","-0.00022"
"151.00000","30.18957","13.01744","-0.00022"
"151.27000","30.24367","13.08039","-0.00022"