File: archive/undergrad/433/RESIDUAL/Specimen_RawData_15.csv
Time,Extension,Load,Strain Gage18
(s),(mm),(N),(mm/mm)
"0.00000","0.00000","0.09750","0.00000"
"0.50000","0.09011","0.05708","0.00000"
"1.00000","0.18987","-0.07847","0.00000"
"1.50000","0.28991","0.01952","0.00000"
"2.00000","0.39008","0.06328","0.00000"
"2.50000","0.48989","0.24046","-0.00001"
"3.00000","0.58990","0.15425","-0.00001"
"3.50000","0.69008","0.19929","-0.00001"
"4.00000","0.78987","0.27580","-0.00001"
"4.50000","0.89000","0.31366","-0.00002"
"5.00000","0.99009","0.27637","-0.00002"
"5.50000","1.08987","0.37024","-0.00002"
"6.00000","1.18997","0.46119","-0.00003"
"6.50000","1.29009","0.48517","-0.00003"
"7.00000","1.38986","0.43311","-0.00003"
"7.50000","1.49000","0.49282","-0.00004"
"8.00000","1.59005","0.57248","-0.00004"
"8.50000","1.68988","0.65557","-0.00004"
"9.00000","1.78996","0.70692","-0.00004"
"9.50000","1.89002","0.67359","-0.00005"
"10.00000","1.98988","0.80467","-0.00005"
"10.50000","2.09003","0.81258","-0.00005"
"11.00000","2.19002","0.85723","-0.00006"
"11.50000","2.28990","0.83385","-0.00006"
"12.00000","2.39002","0.96235","-0.00006"
"12.50000","2.49002","0.92529","-0.00006"
"13.00000","2.58980","1.10124","-0.00007"
"13.50000","2.69006","1.07009","-0.00007"
"14.00000","2.78995","1.18980","-0.00007"
"14.50000","2.88990","1.16646","-0.00007"
"15.00000","2.99008","1.18473","-0.00008"
"15.50000","3.08993","1.13139","-0.00008"
"16.00000","3.18985","1.27738","-0.00008"
"16.50000","3.29011","1.21802","-0.00009"
"17.00000","3.38990","1.37671","-0.00009"
"17.50000","3.48992","1.29359","-0.00009"
"18.00000","3.59009","1.43375","-0.00009"
"18.50000","3.68988","1.44373","-0.00010"
"19.00000","3.78987","1.48465","-0.00010"
"19.50000","3.89015","1.57119","-0.00010"
"20.00000","3.98990","1.57798","-0.00011"
"20.50000","4.08988","1.63813","-0.00011"
"21.00000","4.19012","1.67202","-0.00011"
"21.50000","4.28992","1.75218","-0.00011"
"22.00000","4.38991","1.66800","-0.00012"
"22.50000","4.49008","1.82971","-0.00012"
"23.00000","4.58989","1.90334","-0.00012"
"23.50000","4.68994","1.87180","-0.00013"
"24.00000","4.79012","2.08109","-0.00013"
"24.50000","4.88988","2.14522","-0.00013"
"25.00000","4.98994","1.93577","-0.00013"
"25.50000","5.09010","2.13611","-0.00014"
"26.00000","5.18987","2.12731","-0.00014"
"26.50000","5.28992","2.21457","-0.00014"
"27.00000","5.39011","2.31336","-0.00015"
"27.50000","5.48988","2.11691","-0.00015"
"28.00000","5.58999","2.41095","-0.00015"
"28.50000","5.69006","2.27267","-0.00015"
"29.00000","5.78989","2.58132","-0.00016"
"29.50000","5.88996","2.36630","-0.00016"
"30.00000","5.99003","2.74330","-0.00016"
"30.50000","6.08990","2.42467","-0.00017"
"31.00000","6.19000","2.61449","-0.00017"
"31.50000","6.29002","2.61943","-0.00017"
"32.00000","6.38990","2.49563","-0.00017"
"32.50000","6.48999","2.91444","-0.00018"
"33.00000","6.59004","2.68416","-0.00018"
"33.50000","6.68988","2.95031","-0.00018"
"34.00000","6.79005","2.90922","-0.00019"
"34.50000","6.88997","3.01570","-0.00019"
"35.00000","6.98989","3.07427","-0.00019"
"35.50000","7.09006","3.09629","-0.00019"
"36.00000","7.18991","3.22081","-0.00020"
"36.50000","7.28987","3.20221","-0.00020"
"37.00000","7.39009","3.24955","-0.00020"
"37.50000","7.48995","3.29189","-0.00021"
"38.00000","7.58986","3.35453","-0.00021"
"38.50000","7.69009","3.38519","-0.00021"
"39.00000","7.78994","3.36606","-0.00021"
"39.50000","7.88986","3.41774","-0.00022"
"40.00000","7.99007","3.49523","-0.00022"
"40.50000","8.08992","3.53595","-0.00022"
"41.00000","8.18985","3.55629","-0.00023"
"41.50000","8.29014","3.61197","-0.00023"
"42.00000","8.38990","3.64395","-0.00023"
"42.50000","8.48993","3.67505","-0.00024"
"43.00000","8.59010","3.66018","-0.00024"
"43.50000","8.68991","3.72542","-0.00024"
"44.00000","8.78982","3.69024","-0.00024"
"44.50000","8.89012","3.84822","-0.00025"
"45.00000","8.98989","3.83398","-0.00025"
"45.50000","9.08989","3.94573","-0.00025"
"46.00000","9.19009","3.87505","-0.00026"
"46.50000","9.28990","3.96616","-0.00026"
"47.00000","9.38989","3.96919","-0.00026"
"47.50000","9.49014","4.01438","-0.00026"
"48.00000","9.58988","4.13963","-0.00027"
"48.50000","9.68994","4.27073","-0.00027"
"49.00000","9.79006","4.18539","-0.00027"
"49.50000","9.88989","4.23375","-0.00028"
"50.00000","9.98997","4.32717","-0.00028"
"50.50000","10.09008","4.20025","-0.00028"
"51.00000","10.18989","4.34675","-0.00028"
"51.50000","10.29002","4.51529","-0.00029"
"52.00000","10.38998","4.19355","-0.00029"
"52.50000","10.48990","4.55306","-0.00029"
"53.00000","10.58999","4.39222","-0.00030"
"53.50000","10.69006","4.46890","-0.00030"
"54.00000","10.78986","4.70953","-0.00030"
"54.50000","10.89004","4.28427","-0.00030"
"55.00000","10.98999","4.77109","-0.00031"
"55.50000","11.08986","4.65563","-0.00031"
"56.00000","11.19002","4.61433","-0.00031"
"56.50000","11.29000","4.96382","-0.00032"
"57.00000","11.38985","4.56415","-0.00032"
"57.50000","11.49006","4.97539","-0.00032"
"58.00000","11.58999","4.89200","-0.00032"
"58.50000","11.68989","4.87485","-0.00033"
"59.00000","11.79006","5.25814","-0.00033"
"59.50000","11.88998","4.80164","-0.00033"
"60.00000","11.98982","5.17916","-0.00034"
"60.50000","12.09009","5.09361","-0.00034"
"61.00000","12.18993","5.06123","-0.00034"
"61.50000","12.28988","5.23396","-0.00034"
"62.00000","12.39005","5.22252","-0.00035"
"62.50000","12.48994","5.46037","-0.00035"
"63.00000","12.58987","5.38367","-0.00035"
"63.50000","12.69011","5.40326","-0.00036"
"64.00000","12.78988","5.44058","-0.00036"
"64.50000","12.88989","5.63468","-0.00036"
"65.00000","12.99009","5.49157","-0.00036"
"65.50000","13.08990","5.85299","-0.00037"
"66.00000","13.18986","5.39387","-0.00037"
"66.50000","13.29012","5.82930","-0.00037"
"67.00000","13.38988","5.52371","-0.00038"
"67.50000","13.48993","5.78065","-0.00038"
"68.00000","13.59010","5.77825","-0.00038"
"68.50000","13.68993","5.58993","-0.00038"
"69.00000","13.78993","6.08146","-0.00039"
"69.50000","13.89009","5.65601","-0.00039"
"70.00000","13.98985","6.20843","-0.00039"
"70.50000","14.08996","5.81224","-0.00040"
"71.00000","14.19008","6.03334","-0.00040"
"71.50000","14.28988","6.27212","-0.00040"
"72.00000","14.38999","5.93819","-0.00040"
"72.50000","14.49005","6.42641","-0.00041"
"73.00000","14.58988","6.31393","-0.00041"
"73.50000","14.68995","6.51337","-0.00041"
"74.00000","14.79010","6.54111","-0.00041"
"74.50000","14.88987","6.63931","-0.00042"
"75.00000","14.99001","6.70667","-0.00042"
"75.50000","15.09003","6.75979","-0.00042"
"76.00000","15.18987","6.73296","-0.00043"
"76.50000","15.29003","6.73315","-0.00043"
"77.00000","15.39005","6.86098","-0.00043"
"77.50000","15.48985","6.93380","-0.00044"
"78.00000","15.59001","6.91560","-0.00044"
"78.50000","15.69002","7.03598","-0.00044"
"79.00000","15.78991","6.97278","-0.00044"
"79.50000","15.88998","7.05878","-0.00045"
"80.00000","15.99001","7.08390","-0.00045"
"80.50000","16.08983","7.24200","-0.00045"
"81.00000","16.19007","7.29804","-0.00046"
"81.50000","16.28994","7.22028","-0.00046"
"82.00000","16.38988","7.44429","-0.00046"
"82.50000","16.49007","7.46694","-0.00046"
"83.00000","16.58995","7.50840","-0.00047"
"83.50000","16.68988","7.55795","-0.00047"
"84.00000","16.79011","7.43250","-0.00047"
"84.50000","16.88994","7.71107","-0.00048"
"85.00000","16.98987","7.57022","-0.00048"
"85.50000","17.09008","7.57296","-0.00048"
"86.00000","17.18994","7.94064","-0.00048"
"86.50000","17.28988","7.65309","-0.00049"
"87.00000","17.39011","7.87008","-0.00049"
"87.50000","17.48990","8.07098","-0.00049"
"88.00000","17.58988","7.96739","-0.00050"
"88.50000","17.69011","8.04645","-0.00050"
"89.00000","17.78989","8.19918","-0.00050"
"89.50000","17.88995","7.99309","-0.00050"
"90.00000","17.99007","8.24697","-0.00051"
"90.50000","18.08986","8.30837","-0.00051"
"91.00000","18.18995","8.12959","-0.00051"
"91.50000","18.29010","8.48380","-0.00051"
"92.00000","18.38986","8.09206","-0.00052"
"92.50000","18.48991","8.47341","-0.00052"
"93.00000","18.59009","8.01749","-0.00052"
"93.50000","18.68987","8.53958","-0.00053"
"94.00000","18.78992","8.35929","-0.00053"
"94.50000","18.89013","8.42340","-0.00053"
"95.00000","18.98987","8.62990","-0.00053"
"95.50000","19.08998","8.45839","-0.00054"
"96.00000","19.19007","8.85642","-0.00054"
"96.50000","19.28984","8.43038","-0.00055"
"97.00000","19.38999","8.96107","-0.00055"
"97.50000","19.49005","8.44237","-0.00055"
"98.00000","19.58987","9.02236","-0.00055"
"98.50000","19.68997","8.67995","-0.00056"
"99.00000","19.79005","8.97392","-0.00056"
"99.50000","19.88987","8.91295","-0.00056"
"100.00000","19.99001","9.00319","-0.00056"
"100.50000","20.08998","9.18538","-0.00057"
"101.00000","20.18987","8.98764","-0.00057"
"101.50000","20.29002","9.33885","-0.00057"
"102.00000","20.38998","8.98518","-0.00058"
"102.50000","20.48988","9.55300","-0.00058"
"103.00000","20.59005","9.08255","-0.00058"
"103.50000","20.68994","9.67004","-0.00058"
"104.00000","20.78985","9.10128","-0.00059"
"104.50000","20.89008","9.78479","-0.00059"
"105.00000","20.98999","9.21682","-0.00059"
"105.50000","21.08986","9.76109","-0.00059"
"106.00000","21.19006","9.50968","-0.00060"
"106.50000","21.28995","9.89021","-0.00060"
"107.00000","21.38988","9.67656","-0.00060"
"107.50000","21.49004","9.89138","-0.00061"
"108.00000","21.58991","9.77514","-0.00061"
"108.50000","21.68984","9.90305","-0.00061"
"109.00000","21.79013","9.71324","-0.00062"
"109.50000","21.88989","10.19777","-0.00062"
"110.00000","21.98992","9.94698","-0.00062"
"110.50000","22.09009","10.18067","-0.00062"
"111.00000","22.18987","9.92932","-0.00063"
"111.50000","22.28992","10.39012","-0.00063"
"112.00000","22.39010","10.23942","-0.00063"
"112.50000","22.48989","10.38480","-0.00063"
"113.00000","22.58991","10.12544","-0.00064"
"113.50000","22.69013","10.21806","-0.00064"
"114.00000","22.78987","10.24334","-0.00064"
"114.50000","22.88994","10.45754","-0.00065"
"115.00000","22.99011","10.28465","-0.00065"
"115.50000","23.08987","10.55134","-0.00065"
"116.00000","23.18996","10.05831","-0.00066"
"116.50000","23.29004","10.41243","-0.00066"
"117.00000","23.38990","10.30183","-0.00066"
"117.50000","23.48994","10.57594","-0.00066"
"118.00000","23.59007","10.62086","-0.00067"
"118.50000","23.68988","10.72716","-0.00067"
"119.00000","23.78999","10.65895","-0.00067"
"119.50000","23.89005","10.65081","-0.00068"
"120.00000","23.98988","10.98935","-0.00068"
"120.50000","24.09000","10.87685","-0.00068"
"121.00000","24.19004","11.06348","-0.00068"
"121.50000","24.28986","10.90268","-0.00069"
"122.00000","24.39001","10.97234","-0.00069"
"122.50000","24.49001","11.04703","-0.00069"
"123.00000","24.58984","11.05270","-0.00070"
"123.50000","24.69002","11.14143","-0.00070"
"124.00000","24.79001","11.29225","-0.00070"
"124.50000","24.88985","11.23777","-0.00070"
"125.00000","24.99009","11.39639","-0.00071"
"125.50000","25.08995","11.41449","-0.00071"
"126.00000","25.18990","11.60721","-0.00071"
"126.50000","25.29003","11.58399","-0.00071"
"127.00000","25.38999","11.54670","-0.00072"
"127.50000","25.48986","11.64929","-0.00072"
"128.00000","25.59005","11.70599","-0.00072"
"128.50000","25.68993","11.76514","-0.00073"
"129.00000","25.78988","11.78854","-0.00073"
"129.50000","25.89006","11.83790","-0.00073"
"130.00000","25.98994","11.82979","-0.00073"
"130.50000","26.08989","11.81827","-0.00074"
"131.00000","26.19011","12.00092","-0.00074"
"131.50000","26.28989","11.90337","-0.00074"
"132.00000","26.38992","11.88350","-0.00075"
"132.50000","26.49012","12.10578","-0.00075"
"133.00000","26.58990","12.20076","-0.00075"
"133.50000","26.68987","12.19758","-0.00075"
"134.00000","26.79010","12.09562","-0.00076"
"134.50000","26.88989","12.24781","-0.00076"
"135.00000","26.98991","12.30030","-0.00076"
"135.50000","27.09014","12.19002","-0.00077"
"136.00000","27.18987","12.48970","-0.00077"
"136.50000","27.28993","12.31038","-0.00077"
"137.00000","27.39009","12.37052","-0.00077"
"137.50000","27.48989","12.48761","-0.00078"
"138.00000","27.58995","12.33557","-0.00078"
"138.50000","27.69009","12.49730","-0.00078"
"139.00000","27.78987","12.44067","-0.00079"
"139.50000","27.88998","12.51572","-0.00079"
"140.00000","27.99009","12.47475","-0.00079"
"140.50000","28.08990","12.63014","-0.00080"
"141.00000","28.18995","12.58922","-0.00080"
"141.50000","28.29010","12.70687","-0.00080"
"142.00000","28.38984","12.47607","-0.00080"
"142.50000","28.49000","12.54587","-0.00081"
"143.00000","28.59007","12.68015","-0.00081"
"143.50000","28.68986","12.68215","-0.00081"
"144.00000","28.79002","12.68276","-0.00082"
"144.50000","28.89006","12.72744","-0.00082"
"145.00000","28.98982","12.66166","-0.00082"
"145.50000","29.09001","12.89382","-0.00082"
"146.00000","29.19000","12.70373","-0.00083"
"146.50000","29.28992","12.90436","-0.00083"
"147.00000","29.39002","12.76999","-0.00083"
"147.50000","29.49002","12.86323","-0.00084"
"148.00000","29.58990","12.79121","-0.00084"
"148.50000","29.69002","12.90761","-0.00084"
"149.00000","29.78995","12.91316","-0.00085"
"149.50000","29.88986","12.90065","-0.00085"
"150.00000","29.99009","12.91461","-0.00085"
"150.50000","30.08992","12.90693","-0.00086"
"151.00000","30.18989","13.10750","-0.00086"
"151.50000","30.29008","13.23383","-0.00086"
"151.88200","30.36629","13.25674","-0.00086"