File: archive/undergrad/433/RESIDUAL/Specimen_RawData_9.csv
Time,Extension,Load,Strain Gage18
(s),(mm),(N),(mm/mm)
"0.00000","0.00000","-0.08727","0.00000"
"0.50000","0.08959","-0.03230","0.00000"
"1.00000","0.18953","-0.04381","0.00000"
"1.50000","0.28970","0.02463","0.00000"
"2.00000","0.38966","0.05902","0.00000"
"2.50000","0.48949","0.06235","0.00000"
"3.00000","0.58975","0.05746","-0.00001"
"3.50000","0.68959","0.12146","-0.00001"
"4.00000","0.78953","0.22839","-0.00001"
"4.50000","0.88977","0.13910","-0.00002"
"5.00000","0.98956","0.22998","-0.00002"
"5.50000","1.08956","0.26567","-0.00002"
"6.00000","1.18974","0.25423","-0.00003"
"6.50000","1.28956","0.30924","-0.00003"
"7.00000","1.38955","0.48666","-0.00003"
"7.50000","1.48978","0.57290","-0.00004"
"8.00000","1.58954","0.45238","-0.00004"
"8.50000","1.68954","0.52972","-0.00004"
"9.00000","1.78978","0.53460","-0.00005"
"9.50000","1.88956","0.59174","-0.00005"
"10.00000","1.98957","0.77278","-0.00005"
"10.50000","2.08978","0.78176","-0.00006"
"11.00000","2.18956","0.77831","-0.00006"
"11.50000","2.28959","0.82693","-0.00006"
"12.00000","2.38973","0.87090","-0.00007"
"12.50000","2.48954","0.82725","-0.00007"
"13.00000","2.58958","0.98536","-0.00007"
"13.50000","2.68971","0.93284","-0.00008"
"14.00000","2.78953","0.85967","-0.00008"
"14.50000","2.88966","0.93277","-0.00008"
"15.00000","2.98971","0.94907","-0.00009"
"15.50000","3.08954","1.06073","-0.00009"
"16.00000","3.18963","1.12078","-0.00009"
"16.50000","3.28975","1.21712","-0.00010"
"17.00000","3.38954","1.22918","-0.00010"
"17.50000","3.48967","1.21375","-0.00010"
"18.00000","3.58968","1.22269","-0.00011"
"18.50000","3.68951","1.27794","-0.00011"
"19.00000","3.78969","1.39020","-0.00011"
"19.50000","3.88966","1.28078","-0.00012"
"20.00000","3.98953","1.45084","-0.00012"
"20.50000","4.08966","1.53027","-0.00012"
"21.00000","4.18965","1.58264","-0.00013"
"21.50000","4.28952","1.61012","-0.00013"
"22.00000","4.38969","1.56854","-0.00013"
"22.50000","4.48966","1.56963","-0.00014"
"23.00000","4.58952","1.64752","-0.00014"
"23.50000","4.68968","1.75498","-0.00014"
"24.00000","4.78961","1.69690","-0.00015"
"24.50000","4.88952","1.86403","-0.00015"
"25.00000","4.98975","1.79266","-0.00015"
"25.50000","5.08959","1.98244","-0.00016"
"26.00000","5.18952","1.95364","-0.00016"
"26.50000","5.28976","1.97961","-0.00016"
"27.00000","5.38958","2.11886","-0.00017"
"27.50000","5.48950","2.08413","-0.00017"
"28.00000","5.58979","2.15900","-0.00017"
"28.50000","5.68954","2.24811","-0.00018"
"29.00000","5.78953","2.35141","-0.00018"
"29.50000","5.88978","2.38495","-0.00018"
"30.00000","5.98956","2.61134","-0.00019"
"30.50000","6.08955","2.38414","-0.00019"
"31.00000","6.18978","2.55623","-0.00019"
"31.50000","6.28956","2.47139","-0.00020"
"32.00000","6.38958","2.59740","-0.00020"
"32.50000","6.48975","2.55643","-0.00020"
"33.00000","6.58955","2.80242","-0.00021"
"33.50000","6.68959","2.72182","-0.00021"
"34.00000","6.78973","2.77997","-0.00022"
"34.50000","6.88954","2.76686","-0.00022"
"35.00000","6.98960","2.82133","-0.00022"
"35.50000","7.08973","2.98482","-0.00022"
"36.00000","7.18954","2.96001","-0.00023"
"36.50000","7.28960","3.03902","-0.00023"
"37.00000","7.38977","3.12988","-0.00023"
"37.50000","7.48953","3.15621","-0.00024"
"38.00000","7.58964","3.14744","-0.00024"
"38.50000","7.68972","3.18816","-0.00024"
"39.00000","7.78954","3.36821","-0.00025"
"39.50000","7.88963","3.25251","-0.00025"
"40.00000","7.98970","3.32913","-0.00026"
"40.50000","8.08954","3.34521","-0.00026"
"41.00000","8.18968","3.39672","-0.00026"
"41.50000","8.28965","3.44940","-0.00027"
"42.00000","8.38955","3.52200","-0.00027"
"42.50000","8.48964","3.52234","-0.00027"
"43.00000","8.58966","3.55248","-0.00027"
"43.50000","8.68955","3.62713","-0.00028"
"44.00000","8.78976","3.70277","-0.00028"
"44.50000","8.88962","3.68835","-0.00028"
"45.00000","8.98953","3.65865","-0.00029"
"45.50000","9.08970","3.78363","-0.00029"
"46.00000","9.18963","3.72459","-0.00030"
"46.50000","9.28951","3.82482","-0.00030"
"47.00000","9.38975","3.80506","-0.00030"
"47.50000","9.48958","3.96904","-0.00031"
"48.00000","9.58953","3.96665","-0.00031"
"48.50000","9.68973","4.07887","-0.00031"
"49.00000","9.78963","4.06751","-0.00031"
"49.50000","9.88947","4.13997","-0.00032"
"50.00000","9.98976","4.14603","-0.00032"
"50.50000","10.08959","4.27085","-0.00032"
"51.00000","10.18955","4.31294","-0.00033"
"51.50000","10.28979","4.29210","-0.00033"
"52.00000","10.38958","4.36987","-0.00034"
"52.50000","10.48959","4.47447","-0.00034"
"53.00000","10.58974","4.47453","-0.00034"
"53.50000","10.68954","4.51657","-0.00035"
"54.00000","10.78959","4.64477","-0.00035"
"54.50000","10.88978","4.68722","-0.00035"
"55.00000","10.98954","4.76362","-0.00035"
"55.50000","11.08961","4.74133","-0.00036"
"56.00000","11.18977","4.75746","-0.00036"
"56.50000","11.28950","4.71748","-0.00036"
"57.00000","11.38958","4.94331","-0.00037"
"57.50000","11.48978","4.90229","-0.00037"
"58.00000","11.58955","4.95023","-0.00038"
"58.50000","11.68962","5.02206","-0.00038"
"59.00000","11.78972","4.96175","-0.00038"
"59.50000","11.88954","5.16821","-0.00039"
"60.00000","11.98962","5.10899","-0.00039"
"60.50000","12.08973","5.22580","-0.00039"
"61.00000","12.18952","5.23895","-0.00039"
"61.50000","12.28966","5.25471","-0.00040"
"62.00000","12.38969","5.20858","-0.00040"
"62.50000","12.48954","5.35383","-0.00040"
"63.00000","12.58965","5.49448","-0.00041"
"63.50000","12.68970","5.35850","-0.00041"
"64.00000","12.78953","5.47586","-0.00041"
"64.50000","12.88969","5.54542","-0.00042"
"65.00000","12.98964","5.58144","-0.00042"
"65.50000","13.08952","5.72904","-0.00042"
"66.00000","13.18968","5.57634","-0.00043"
"66.50000","13.28964","5.75027","-0.00043"
"67.00000","13.38952","5.77253","-0.00043"
"67.50000","13.48973","5.60394","-0.00044"
"68.00000","13.58962","5.70777","-0.00044"
"68.50000","13.68953","5.83887","-0.00044"
"69.00000","13.78969","5.87265","-0.00045"
"69.50000","13.88964","5.93360","-0.00045"
"70.00000","13.98951","5.97649","-0.00045"
"70.50000","14.08972","6.02798","-0.00046"
"71.00000","14.18961","6.06538","-0.00046"
"71.50000","14.28952","6.12318","-0.00046"
"72.00000","14.38977","5.96376","-0.00047"
"72.50000","14.48954","6.07755","-0.00047"
"73.00000","14.58955","6.19864","-0.00047"
"73.50000","14.68976","6.29099","-0.00048"
"74.00000","14.78954","6.21368","-0.00048"
"74.50000","14.88958","6.30794","-0.00048"
"75.00000","14.98978","6.32703","-0.00049"
"75.50000","15.08957","6.43561","-0.00049"
"76.00000","15.18957","6.39603","-0.00049"
"76.50000","15.28975","6.58774","-0.00050"
"77.00000","15.38953","6.68542","-0.00050"
"77.50000","15.48956","6.73716","-0.00050"
"78.00000","15.58981","6.65240","-0.00051"
"78.50000","15.68953","6.64613","-0.00051"
"79.00000","15.78960","6.78973","-0.00051"
"79.50000","15.88974","6.83398","-0.00052"
"80.00000","15.98956","6.92509","-0.00052"
"80.50000","16.08956","6.97565","-0.00052"
"81.00000","16.18972","7.06391","-0.00052"
"81.50000","16.28954","7.07915","-0.00053"
"82.00000","16.38963","7.02793","-0.00053"
"82.50000","16.48975","7.13297","-0.00053"
"83.00000","16.58956","7.15736","-0.00054"
"83.50000","16.68963","7.19382","-0.00054"
"84.00000","16.78973","7.25314","-0.00054"
"84.50000","16.88953","7.33819","-0.00055"
"85.00000","16.98961","7.37822","-0.00055"
"85.50000","17.08969","7.35797","-0.00055"
"86.00000","17.18954","7.42849","-0.00056"
"86.50000","17.28963","7.45528","-0.00056"
"87.00000","17.38967","7.41760","-0.00056"
"87.50000","17.48951","7.61034","-0.00057"
"88.00000","17.58971","7.68050","-0.00057"
"88.50000","17.68960","7.66176","-0.00057"
"89.00000","17.78955","7.66367","-0.00058"
"89.50000","17.88968","7.81802","-0.00058"
"90.00000","17.98965","7.70151","-0.00058"
"90.50000","18.08952","7.97425","-0.00059"
"91.00000","18.18972","7.81243","-0.00059"
"91.50000","18.28959","8.01042","-0.00059"
"92.00000","18.38954","8.01501","-0.00060"
"92.50000","18.48972","8.01884","-0.00060"
"93.00000","18.58958","8.14426","-0.00060"
"93.50000","18.68953","8.09069","-0.00061"
"94.00000","18.78978","8.10716","-0.00061"
"94.50000","18.88952","8.21910","-0.00061"
"95.00000","18.98959","8.17185","-0.00062"
"95.50000","19.08974","8.34462","-0.00062"
"96.00000","19.18963","8.35648","-0.00062"
"96.50000","19.28951","8.43432","-0.00063"
"97.00000","19.38978","8.42627","-0.00063"
"97.50000","19.48956","8.49025","-0.00063"
"98.00000","19.58955","8.46221","-0.00063"
"98.50000","19.68977","8.54898","-0.00064"
"99.00000","19.78955","8.59039","-0.00064"
"99.50000","19.88958","8.77324","-0.00064"
"100.00000","19.98976","8.69085","-0.00065"
"100.50000","20.08951","8.71046","-0.00065"
"101.00000","20.18962","8.77038","-0.00065"
"101.50000","20.28976","8.88109","-0.00066"
"102.00000","20.38954","8.90777","-0.00066"
"102.50000","20.48957","8.82475","-0.00066"
"103.00000","20.58977","8.96349","-0.00067"
"103.50000","20.68955","9.11116","-0.00067"
"104.00000","20.78961","9.14096","-0.00067"
"104.50000","20.88977","9.10242","-0.00068"
"105.00000","20.98953","9.26314","-0.00068"
"105.50000","21.08965","9.33075","-0.00068"
"106.00000","21.18972","9.42559","-0.00069"
"106.50000","21.28954","9.44019","-0.00069"
"107.00000","21.38961","9.57299","-0.00069"
"107.50000","21.48970","9.53959","-0.00070"
"108.00000","21.58953","9.37440","-0.00070"
"108.50000","21.68967","9.68915","-0.00070"
"109.00000","21.78971","9.58575","-0.00070"
"109.50000","21.88956","9.70762","-0.00071"
"110.00000","21.98964","9.82200","-0.00071"
"110.50000","22.08968","9.84125","-0.00071"
"111.00000","22.18954","9.96745","-0.00072"
"111.50000","22.28970","9.95374","-0.00072"
"112.00000","22.38959","10.03710","-0.00072"
"112.50000","22.48952","10.06080","-0.00073"
"113.00000","22.58971","10.22691","-0.00073"
"113.50000","22.68963","10.17694","-0.00073"
"114.00000","22.78952","10.21013","-0.00074"
"114.50000","22.88976","10.25381","-0.00074"
"115.00000","22.98958","10.40320","-0.00074"
"115.50000","23.08955","10.40281","-0.00075"
"116.00000","23.18974","10.26976","-0.00075"
"116.50000","23.28960","10.46400","-0.00075"
"117.00000","23.38953","10.58389","-0.00076"
"117.50000","23.48976","10.46477","-0.00076"
"118.00000","23.58957","10.47694","-0.00076"
"118.50000","23.68953","10.60157","-0.00076"
"119.00000","23.78980","10.63343","-0.00077"
"119.50000","23.88956","10.67765","-0.00077"
"120.00000","23.98958","10.82805","-0.00077"
"120.50000","24.08975","10.86707","-0.00078"
"121.00000","24.18954","10.79643","-0.00078"
"121.50000","24.28957","10.89493","-0.00078"
"122.00000","24.38980","10.87787","-0.00079"
"122.50000","24.48953","10.93338","-0.00079"
"123.00000","24.58956","11.00313","-0.00079"
"123.50000","24.68979","10.93225","-0.00080"
"124.00000","24.78956","11.06938","-0.00080"
"124.50000","24.88957","11.09852","-0.00080"
"125.00000","24.98976","11.12300","-0.00081"
"125.50000","25.08953","11.24276","-0.00081"
"126.00000","25.18960","11.23465","-0.00081"
"126.50000","25.28974","11.23502","-0.00081"
"127.00000","25.38956","11.28241","-0.00082"
"127.50000","25.48960","11.46218","-0.00082"
"128.00000","25.58973","11.35775","-0.00082"
"128.50000","25.68954","11.52727","-0.00083"
"129.00000","25.78966","11.48007","-0.00083"
"129.50000","25.88970","11.51044","-0.00083"
"130.00000","25.98954","11.69329","-0.00084"
"130.50000","26.08965","11.74878","-0.00084"
"131.00000","26.18968","11.66274","-0.00084"
"131.50000","26.28956","11.74631","-0.00085"
"132.00000","26.38966","11.82834","-0.00085"
"132.50000","26.48966","11.76782","-0.00085"
"133.00000","26.58948","11.95271","-0.00085"
"133.50000","26.68969","11.90503","-0.00086"
"134.00000","26.78964","11.90719","-0.00086"
"134.50000","26.88953","11.98678","-0.00086"
"135.00000","26.98973","11.97366","-0.00087"
"135.50000","27.08961","12.09291","-0.00087"
"136.00000","27.18953","12.23747","-0.00087"
"136.50000","27.28975","12.12748","-0.00088"
"137.00000","27.38963","12.24229","-0.00088"
"137.50000","27.48951","12.15548","-0.00088"
"138.00000","27.58973","12.28691","-0.00089"
"138.50000","27.68959","12.29370","-0.00089"
"139.00000","27.78952","12.30398","-0.00089"
"139.50000","27.88978","12.27228","-0.00090"
"140.00000","27.98954","12.37779","-0.00090"
"140.50000","28.08957","12.42041","-0.00090"
"141.00000","28.18971","12.37261","-0.00090"
"141.50000","28.28956","12.47759","-0.00091"
"142.00000","28.38957","12.54137","-0.00091"
"142.50000","28.48977","12.42542","-0.00091"
"143.00000","28.58955","12.54198","-0.00092"
"143.50000","28.68955","12.68460","-0.00092"
"144.00000","28.78978","12.76581","-0.00092"
"144.50000","28.88954","12.66422","-0.00093"
"145.00000","28.98955","12.88329","-0.00093"
"145.50000","29.08981","12.86359","-0.00093"
"146.00000","29.18954","12.97909","-0.00094"
"146.50000","29.28958","13.01457","-0.00094"
"147.00000","29.38975","13.01161","-0.00094"
"147.50000","29.48954","13.12545","-0.00095"
"148.00000","29.58958","12.97930","-0.00095"
"148.50000","29.68974","13.26954","-0.00095"
"149.00000","29.78954","13.24256","-0.00095"
"149.50000","29.88968","13.20065","-0.00096"
"150.00000","29.98973","13.26392","-0.00096"
"150.50000","30.08954","13.34881","-0.00096"
"151.00000","30.18964","13.50257","-0.00097"
"151.21001","30.23174","13.51950","-0.00097"