File: archive/undergrad/433/RESIDUAL/Specimen_RawData_6.csv
Time,Extension,Load,Strain Gage18
(s),(mm),(N),(mm/mm)
"0.00000","0.00000","-0.10342","0.00000"
"0.50000","0.08953","0.06860","0.00000"
"1.00000","0.18944","-0.04502","0.00000"
"1.50000","0.28961","-0.00175","0.00000"
"2.00000","0.38958","-0.03327","0.00000"
"2.50000","0.48943","0.16100","0.00000"
"3.00000","0.58969","0.12529","0.00000"
"3.50000","0.68952","0.07371","0.00000"
"4.00000","0.78945","0.14442","-0.00001"
"4.50000","0.88971","0.13920","-0.00001"
"5.00000","0.98949","0.17966","-0.00001"
"5.50000","1.08949","0.28350","-0.00001"
"6.00000","1.18968","0.24456","-0.00002"
"6.50000","1.28949","0.39644","-0.00002"
"7.00000","1.38947","0.41624","-0.00002"
"7.50000","1.48972","0.40287","-0.00002"
"8.00000","1.58948","0.45922","-0.00003"
"8.50000","1.68946","0.44391","-0.00003"
"9.00000","1.78970","0.66687","-0.00003"
"9.50000","1.88950","0.61309","-0.00003"
"10.00000","1.98950","0.65279","-0.00003"
"10.50000","2.08971","0.79551","-0.00004"
"11.00000","2.18947","0.79329","-0.00004"
"11.50000","2.28952","0.79082","-0.00004"
"12.00000","2.38964","0.85358","-0.00004"
"12.50000","2.48946","0.82406","-0.00005"
"13.00000","2.58951","0.93704","-0.00005"
"13.50000","2.68965","1.01641","-0.00005"
"14.00000","2.78947","1.08835","-0.00005"
"14.50000","2.88959","0.96114","-0.00006"
"15.00000","2.98964","1.22060","-0.00006"
"15.50000","3.08949","1.11672","-0.00006"
"16.00000","3.18957","1.10539","-0.00006"
"16.50000","3.28966","1.25574","-0.00007"
"17.00000","3.38948","1.25263","-0.00007"
"17.50000","3.48959","1.27865","-0.00007"
"18.00000","3.58961","1.23178","-0.00007"
"18.50000","3.68944","1.19118","-0.00008"
"19.00000","3.78962","1.46585","-0.00008"
"19.50000","3.88956","1.42330","-0.00008"
"20.00000","3.98947","1.35557","-0.00008"
"20.50000","4.08959","1.43866","-0.00009"
"21.00000","4.18957","1.52653","-0.00009"
"21.50000","4.28945","1.62659","-0.00009"
"22.00000","4.38962","1.60580","-0.00009"
"22.50000","4.48958","1.66689","-0.00009"
"23.00000","4.58944","1.71491","-0.00010"
"23.50000","4.68961","1.70605","-0.00010"
"24.00000","4.78953","1.75664","-0.00010"
"24.50000","4.88944","1.89185","-0.00010"
"25.00000","4.98970","1.90086","-0.00011"
"25.50000","5.08951","1.95279","-0.00011"
"26.00000","5.18946","1.96993","-0.00011"
"26.50000","5.28967","2.09583","-0.00011"
"27.00000","5.38952","2.13434","-0.00012"
"27.50000","5.48944","2.13350","-0.00012"
"28.00000","5.58970","2.16960","-0.00012"
"28.50000","5.68946","2.35587","-0.00012"
"29.00000","5.78947","2.27462","-0.00012"
"29.50000","5.88973","2.37956","-0.00013"
"30.00000","5.98950","2.50380","-0.00013"
"30.50000","6.08947","2.45544","-0.00013"
"31.00000","6.18971","2.52140","-0.00013"
"31.50000","6.28949","2.45767","-0.00014"
"32.00000","6.38950","2.58949","-0.00014"
"32.50000","6.48968","2.78797","-0.00014"
"33.00000","6.58947","2.61068","-0.00014"
"33.50000","6.68952","2.72583","-0.00014"
"34.00000","6.78967","2.73704","-0.00015"
"34.50000","6.88948","2.79635","-0.00015"
"35.00000","6.98953","2.88287","-0.00015"
"35.50000","7.08964","2.90669","-0.00015"
"36.00000","7.18946","2.94397","-0.00016"
"36.50000","7.28953","3.09004","-0.00016"
"37.00000","7.38971","3.13370","-0.00016"
"37.50000","7.48945","3.15716","-0.00016"
"38.00000","7.58958","3.09850","-0.00017"
"38.50000","7.68966","3.23147","-0.00017"
"39.00000","7.78948","3.24719","-0.00017"
"39.50000","7.88955","3.19991","-0.00017"
"40.00000","7.98963","3.36955","-0.00018"
"40.50000","8.08946","3.44010","-0.00018"
"41.00000","8.18959","3.37408","-0.00018"
"41.50000","8.28957","3.37239","-0.00018"
"42.00000","8.38947","3.32939","-0.00019"
"42.50000","8.48956","3.48600","-0.00019"
"43.00000","8.58961","3.51087","-0.00019"
"43.50000","8.68948","3.47491","-0.00019"
"44.00000","8.78966","3.55314","-0.00019"
"44.50000","8.88955","3.64562","-0.00020"
"45.00000","8.98947","3.66362","-0.00020"
"45.50000","9.08963","3.65129","-0.00020"
"46.00000","9.18956","3.81023","-0.00020"
"46.50000","9.28945","3.82149","-0.00021"
"47.00000","9.38967","3.80793","-0.00021"
"47.50000","9.48950","3.92885","-0.00021"
"48.00000","9.58946","3.91779","-0.00021"
"48.50000","9.68965","4.04495","-0.00022"
"49.00000","9.78955","4.09400","-0.00022"
"49.50000","9.88939","4.07639","-0.00022"
"50.00000","9.98969","4.08354","-0.00022"
"50.50000","10.08951","4.14901","-0.00023"
"51.00000","10.18947","4.30034","-0.00023"
"51.50000","10.28971","4.25175","-0.00023"
"52.00000","10.38950","4.37514","-0.00023"
"52.50000","10.48955","4.37949","-0.00024"
"53.00000","10.58966","4.42976","-0.00024"
"53.50000","10.68948","4.50466","-0.00024"
"54.00000","10.78953","4.56711","-0.00024"
"54.50000","10.88966","4.64998","-0.00024"
"55.00000","10.98948","4.62651","-0.00025"
"55.50000","11.08953","4.64711","-0.00025"
"56.00000","11.18970","4.74103","-0.00025"
"56.50000","11.28947","4.76749","-0.00025"
"57.00000","11.38951","4.75212","-0.00026"
"57.50000","11.48971","4.96423","-0.00026"
"58.00000","11.58951","4.98293","-0.00026"
"58.50000","11.68953","4.97330","-0.00026"
"59.00000","11.78964","5.03156","-0.00027"
"59.50000","11.88949","5.08001","-0.00027"
"60.00000","11.98953","5.14691","-0.00027"
"60.50000","12.08967","5.17255","-0.00027"
"61.00000","12.18944","5.24129","-0.00027"
"61.50000","12.28959","5.10077","-0.00028"
"62.00000","12.38962","5.24282","-0.00028"
"62.50000","12.48946","5.34096","-0.00028"
"63.00000","12.58960","5.37757","-0.00028"
"63.50000","12.68963","5.32781","-0.00029"
"64.00000","12.78945","5.40465","-0.00029"
"64.50000","12.88962","5.51489","-0.00029"
"65.00000","12.98958","5.48131","-0.00029"
"65.50000","13.08945","5.66419","-0.00030"
"66.00000","13.18963","5.54500","-0.00030"
"66.50000","13.28958","5.55658","-0.00030"
"67.00000","13.38945","5.56978","-0.00030"
"67.50000","13.48966","5.76343","-0.00031"
"68.00000","13.58955","5.71539","-0.00031"
"68.50000","13.68947","5.79730","-0.00031"
"69.00000","13.78964","5.83262","-0.00031"
"69.50000","13.88958","5.91739","-0.00031"
"70.00000","13.98943","5.97243","-0.00032"
"70.50000","14.08964","5.99648","-0.00032"
"71.00000","14.18953","6.02569","-0.00032"
"71.50000","14.28944","6.01915","-0.00032"
"72.00000","14.38972","6.06910","-0.00033"
"72.50000","14.48947","6.11723","-0.00033"
"73.00000","14.58948","6.28003","-0.00033"
"73.50000","14.68967","6.21300","-0.00033"
"74.00000","14.78949","6.25229","-0.00034"
"74.50000","14.88949","6.33551","-0.00034"
"75.00000","14.98969","6.34243","-0.00034"
"75.50000","15.08949","6.53230","-0.00034"
"76.00000","15.18948","6.62266","-0.00035"
"76.50000","15.28970","6.57701","-0.00035"
"77.00000","15.38946","6.65940","-0.00035"
"77.50000","15.48950","6.71912","-0.00035"
"78.00000","15.58972","6.66602","-0.00035"
"78.50000","15.68948","6.72308","-0.00036"
"79.00000","15.78953","6.78546","-0.00036"
"79.50000","15.88965","6.87332","-0.00036"
"80.00000","15.98949","6.86318","-0.00036"
"80.50000","16.08949","6.94196","-0.00037"
"81.00000","16.18969","6.92974","-0.00037"
"81.50000","16.28948","7.13257","-0.00037"
"82.00000","16.38956","6.99921","-0.00037"
"82.50000","16.48967","7.15175","-0.00038"
"83.00000","16.58950","7.13533","-0.00038"
"83.50000","16.68956","7.24362","-0.00038"
"84.00000","16.78967","7.29645","-0.00038"
"84.50000","16.88945","7.34403","-0.00039"
"85.00000","16.98955","7.43988","-0.00039"
"85.50000","17.08962","7.48255","-0.00039"
"86.00000","17.18947","7.43098","-0.00039"
"86.50000","17.28957","7.44475","-0.00039"
"87.00000","17.38961","7.57005","-0.00040"
"87.50000","17.48943","7.63434","-0.00040"
"88.00000","17.58965","7.71559","-0.00040"
"88.50000","17.68951","7.72670","-0.00040"
"89.00000","17.78948","7.74844","-0.00041"
"89.50000","17.88960","7.83757","-0.00041"
"90.00000","17.98959","7.74682","-0.00041"
"90.50000","18.08947","7.82065","-0.00041"
"91.00000","18.18965","7.91770","-0.00042"
"91.50000","18.28953","7.91123","-0.00042"
"92.00000","18.38947","8.10577","-0.00042"
"92.50000","18.48965","7.98025","-0.00042"
"93.00000","18.58949","8.02778","-0.00042"
"93.50000","18.68945","8.10537","-0.00043"
"94.00000","18.78968","8.15321","-0.00043"
"94.50000","18.88944","8.27877","-0.00043"
"95.00000","18.98951","8.31604","-0.00043"
"95.50000","19.08968","8.29137","-0.00044"
"96.00000","19.18955","8.34060","-0.00044"
"96.50000","19.28943","8.39686","-0.00044"
"97.00000","19.38971","8.38510","-0.00044"
"97.50000","19.48948","8.47698","-0.00044"
"98.00000","19.58949","8.54888","-0.00045"
"98.50000","19.68970","8.48071","-0.00045"
"99.00000","19.78950","8.59609","-0.00045"
"99.50000","19.88950","8.54288","-0.00045"
"100.00000","19.98969","8.77976","-0.00046"
"100.50000","20.08945","8.70249","-0.00046"
"101.00000","20.18956","8.70348","-0.00046"
"101.50000","20.28968","8.89749","-0.00046"
"102.00000","20.38947","8.87814","-0.00047"
"102.50000","20.48950","8.87632","-0.00047"
"103.00000","20.58971","8.96330","-0.00047"
"103.50000","20.68948","9.03707","-0.00047"
"104.00000","20.78955","9.18297","-0.00047"
"104.50000","20.88970","9.14315","-0.00048"
"105.00000","20.98944","9.23332","-0.00048"
"105.50000","21.08957","9.27888","-0.00048"
"106.00000","21.18965","9.27981","-0.00048"
"106.50000","21.28946","9.42114","-0.00049"
"107.00000","21.38954","9.34904","-0.00049"
"107.50000","21.48964","9.39441","-0.00049"
"108.00000","21.58946","9.38966","-0.00049"
"108.50000","21.68961","9.48874","-0.00050"
"109.00000","21.78964","9.56549","-0.00050"
"109.50000","21.88949","9.50730","-0.00050"
"110.00000","21.98958","9.60315","-0.00050"
"110.50000","22.08961","9.56887","-0.00051"
"111.00000","22.18947","9.74601","-0.00051"
"111.50000","22.28964","9.66721","-0.00051"
"112.00000","22.38954","9.78358","-0.00051"
"112.50000","22.48944","9.76735","-0.00051"
"113.00000","22.58965","9.87688","-0.00052"
"113.50000","22.68954","9.94565","-0.00052"
"114.00000","22.78944","9.92385","-0.00052"
"114.50000","22.88970","10.06375","-0.00052"
"115.00000","22.98950","9.97312","-0.00053"
"115.50000","23.08948","10.05735","-0.00053"
"116.00000","23.18967","9.98199","-0.00053"
"116.50000","23.28953","10.17516","-0.00053"
"117.00000","23.38946","10.09752","-0.00054"
"117.50000","23.48969","10.25521","-0.00054"
"118.00000","23.58949","10.22261","-0.00054"
"118.50000","23.68945","10.25150","-0.00054"
"119.00000","23.78973","10.29728","-0.00054"
"119.50000","23.88949","10.37064","-0.00055"
"120.00000","23.98950","10.47091","-0.00055"
"120.50000","24.08968","10.46871","-0.00055"
"121.00000","24.18947","10.42214","-0.00055"
"121.50000","24.28950","10.71190","-0.00055"
"122.00000","24.38972","10.66058","-0.00056"
"122.50000","24.48947","10.59082","-0.00056"
"123.00000","24.58949","10.67550","-0.00056"
"123.50000","24.68971","10.92843","-0.00056"
"124.00000","24.78947","10.83008","-0.00057"
"124.50000","24.88952","10.86123","-0.00057"
"125.00000","24.98969","11.00450","-0.00057"
"125.50000","25.08947","11.06304","-0.00057"
"126.00000","25.18953","11.03902","-0.00058"
"126.50000","25.28965","11.12494","-0.00058"
"127.00000","25.38949","11.13047","-0.00058"
"127.50000","25.48953","11.10142","-0.00058"
"128.00000","25.58965","11.25330","-0.00058"
"128.50000","25.68947","11.21167","-0.00059"
"129.00000","25.78958","11.26998","-0.00059"
"129.50000","25.88963","11.38636","-0.00059"
"130.00000","25.98947","11.48764","-0.00059"
"130.50000","26.08958","11.44686","-0.00060"
"131.00000","26.18960","11.67047","-0.00060"
"131.50000","26.28949","11.63791","-0.00060"
"132.00000","26.38959","11.56435","-0.00060"
"132.50000","26.48957","11.70940","-0.00061"
"133.00000","26.58941","11.68001","-0.00061"
"133.50000","26.68962","11.71654","-0.00061"
"134.00000","26.78957","11.82704","-0.00061"
"134.50000","26.88945","11.92926","-0.00061"
"135.00000","26.98965","11.84518","-0.00062"
"135.50000","27.08954","11.86011","-0.00062"
"136.00000","27.18945","12.06192","-0.00062"
"136.50000","27.28967","11.96014","-0.00062"
"137.00000","27.38956","12.02155","-0.00063"
"137.50000","27.48944","12.06102","-0.00063"
"138.00000","27.58966","12.05732","-0.00063"
"138.50000","27.68951","12.16071","-0.00063"
"139.00000","27.78944","12.23482","-0.00063"
"139.50000","27.88971","12.33202","-0.00064"
"140.00000","27.98948","12.23505","-0.00064"
"140.50000","28.08949","12.23349","-0.00064"
"141.00000","28.18965","12.36180","-0.00064"
"141.50000","28.28950","12.35073","-0.00065"
"142.00000","28.38951","12.43210","-0.00065"
"142.50000","28.48969","12.43545","-0.00065"
"143.00000","28.58948","12.49238","-0.00065"
"143.50000","28.68947","12.54870","-0.00065"
"144.00000","28.78971","12.65409","-0.00066"
"144.50000","28.88947","12.64666","-0.00066"
"145.00000","28.98949","12.59114","-0.00066"
"145.50000","29.08975","12.73867","-0.00066"
"146.00000","29.18947","12.88940","-0.00067"
"146.50000","29.28951","12.83290","-0.00067"
"147.00000","29.38967","12.90135","-0.00067"
"147.50000","29.48948","12.88651","-0.00067"
"148.00000","29.58949","12.95162","-0.00068"
"148.50000","29.68964","12.94763","-0.00068"
"149.00000","29.78946","13.04601","-0.00068"
"149.50000","29.88960","13.12369","-0.00068"
"150.00000","29.98965","13.04891","-0.00069"
"150.50000","30.08946","13.13203","-0.00069"
"151.00000","30.18957","13.25123","-0.00069"
"151.21001","30.23168","13.13316","-0.00069"