File: archive/undergrad/433/Pressure Vessel/Specimen_RawData_2.csv
Time,Extension,Load,Strain Gage18
(s),(mm),(N),(mm/mm)
"0.00000","0.00000","-0.02182","0.00000"
"0.01800","0.00000","-0.00673","0.00000"
"0.03600","0.00010","-0.02784","0.00000"
"0.05400","0.00044","0.00466","0.00000"
"0.07200","0.00127","0.05055","0.00000"
"0.09000","0.00257","0.00189","0.00000"
"0.10800","0.00358","0.04745","0.00000"
"0.12600","0.00429","0.07101","0.00000"
"0.14400","0.00539","0.05660","0.00000"
"0.16200","0.00724","0.05111","0.00001"
"0.18000","0.00964","0.09780","0.00001"
"0.19800","0.01219","0.11036","0.00000"
"0.21600","0.01461","0.03798","0.00000"
"0.23400","0.01681","-0.00575","0.00000"
"0.25200","0.01883","0.02302","0.00000"
"0.27000","0.02065","0.05912","0.00000"
"0.28800","0.02239","0.05408","0.00000"
"0.30600","0.02418","0.07712","0.00000"
"0.32400","0.02603","0.07544","0.00000"
"0.34200","0.02790","0.06917","0.00000"
"0.36000","0.02975","0.05412","0.00001"
"0.37800","0.03153","0.04196","0.00001"
"0.39600","0.03329","0.03166","0.00001"
"0.41400","0.03510","0.01477","0.00001"
"0.43200","0.03693","0.01104","0.00000"
"0.45000","0.03879","-0.04614","0.00000"
"0.46800","0.04068","0.04885","0.00000"
"0.48600","0.04250","0.09102","0.00000"
"0.50400","0.04422","0.04432","0.00000"
"0.52200","0.04595","0.02210","0.00000"
"0.54000","0.04777","0.02166","0.00000"
"0.55800","0.04961","0.03543","0.00000"
"0.57600","0.05144","0.04463","0.00001"
"0.59400","0.05325","0.05075","0.00001"
"0.61200","0.05499","0.01355","0.00001"
"0.63000","0.05670","0.05291","0.00001"
"0.64800","0.05846","0.02781","0.00001"
"0.66600","0.06026","0.01822","0.00000"
"0.68400","0.06211","-0.01996","0.00000"
"0.70200","0.06399","-0.00153","0.00000"
"0.72000","0.06577","0.08585","0.00000"
"0.73800","0.06747","0.12443","0.00000"
"0.75600","0.06919","0.10800","0.00000"
"0.77400","0.07098","0.12456","0.00000"
"0.79200","0.07280","0.13054","0.00001"
"0.81000","0.07465","0.08123","0.00001"
"0.82800","0.07648","0.00312","0.00001"
"0.84600","0.07826","0.06571","0.00001"
"0.86400","0.08003","0.05690","0.00001"
"0.88200","0.08185","0.02015","0.00000"
"0.90000","0.08368","0.02376","0.00000"
"0.91800","0.08555","0.02303","0.00000"
"0.93600","0.08742","0.05321","0.00000"
"0.95400","0.08919","0.05153","0.00000"
"0.97200","0.09091","0.07181","0.00000"
"0.99000","0.09269","0.00279","0.00000"
"1.00800","0.09453","-0.05839","0.00001"
"1.02600","0.09636","0.03413","0.00001"
"1.04400","0.09822","0.07949","0.00001"
"1.06200","0.10007","0.08848","0.00001"
"1.08000","0.10184","0.09413","0.00001"
"1.09800","0.10360","0.07129","0.00000"
"1.11600","0.10539","0.09287","0.00000"
"1.13400","0.10721","0.04267","0.00000"
"1.15200","0.10906","0.03421","0.00000"
"1.17000","0.11087","0.02653","0.00000"
"1.18800","0.11260","0.03050","0.00000"
"1.20600","0.11431","-0.01073","0.00000"
"1.22400","0.11608","0.02403","0.00000"
"1.24200","0.11787","0.05631","0.00001"
"1.26000","0.11968","0.04760","0.00001"
"1.27800","0.12154","0.01908","0.00001"
"1.29600","0.12334","-0.00883","0.00000"
"1.31400","0.12509","-0.03892","0.00000"
"1.33200","0.12686","-0.04472","0.00000"
"1.35000","0.12866","0.02236","0.00000"
"1.36800","0.13048","0.01823","0.00000"
"1.38600","0.13232","0.00429","0.00000"
"1.40400","0.13414","0.02877","0.00000"
"1.42200","0.13589","0.08172","0.00000"
"1.44000","0.13765","0.05797","0.00000"
"1.45800","0.13946","0.00544","0.00000"
"1.47600","0.14126","-0.00543","0.00000"
"1.49400","0.14308","0.07519","0.00000"
"1.51200","0.14493","0.06373","0.00000"
"1.53000","0.14675","0.01875","0.00000"
"1.54800","0.14851","0.01288","0.00000"
"1.56600","0.15027","0.05078","0.00000"
"1.58400","0.15206","-0.00373","0.00000"
"1.60200","0.15389","0.07136","0.00000"
"1.62000","0.15577","0.06592","0.00000"
"1.63800","0.15759","0.06480","0.00000"
"1.65600","0.15937","0.07894","0.00000"
"1.67400","0.16118","0.02858","0.00000"
"1.69200","0.16299","0.02135","0.00000"
"1.71000","0.16477","-0.01828","0.00000"
"1.72800","0.16660","-0.00326","0.00000"
"1.74600","0.16844","0.08466","0.00000"
"1.76400","0.17020","0.11471","0.00000"
"1.78200","0.17194","0.07241","0.00000"
"1.80000","0.17373","-0.01153","0.00000"
"1.81800","0.17555","-0.04338","0.00000"
"1.83600","0.17737","-0.03068","0.00000"
"1.85400","0.17919","-0.01926","0.00000"
"1.87200","0.18095","0.02800","0.00000"
"1.89000","0.18268","0.08800","0.00000"
"1.90800","0.18446","0.06333","0.00000"
"1.92600","0.18627","-0.07080","0.00000"
"1.94400","0.18806","-0.06543","0.00000"
"1.96200","0.18989","-0.04184","0.00000"
"1.98000","0.19168","-0.00447","0.00000"
"1.99800","0.19340","0.05998","0.00000"
"2.01600","0.19513","0.06976","0.00000"
"2.03400","0.19696","0.08443","0.00000"
"2.05200","0.19883","0.06702","0.00000"
"2.07000","0.20071","0.04015","0.00000"
"2.08800","0.20255","0.08561","0.00000"
"2.10600","0.20431","0.09657","0.00000"
"2.12400","0.20606","0.04610","0.00000"
"2.14200","0.20787","0.05031","0.00000"
"2.16000","0.20968","0.05035","0.00000"
"2.17800","0.21149","0.02997","0.00000"
"2.19600","0.21335","0.09227","0.00000"
"2.21400","0.21519","0.05701","0.00000"
"2.23200","0.21696","0.02091","0.00000"
"2.25000","0.21875","0.07462","0.00000"
"2.26800","0.22060","0.07683","0.00000"
"2.28600","0.22245","0.00119","0.00000"
"2.30400","0.22430","-0.10570","0.00000"
"2.32200","0.22609","-0.06965","0.00000"
"2.34000","0.22783","0.02921","0.00000"
"2.35800","0.22958","0.04583","0.00000"
"2.37600","0.23135","-0.01192","0.00000"
"2.39400","0.23314","0.02142","0.00000"
"2.41200","0.23496","0.08225","0.00000"
"2.43000","0.23679","0.00127","0.00000"
"2.44800","0.23854","-0.09128","0.00000"
"2.46600","0.24024","-0.04372","0.00000"
"2.48400","0.24202","0.08099","0.00000"
"2.50200","0.24385","0.10582","0.00000"
"2.52000","0.24569","0.08158","0.00000"
"2.53800","0.24753","0.07141","0.00000"
"2.55600","0.24930","0.13864","0.00000"
"2.57400","0.25102","0.03684","0.00000"
"2.59200","0.25277","-0.05545","0.00000"
"2.61000","0.25458","-0.06334","0.00000"
"2.62800","0.25641","-0.06959","0.00000"
"2.64600","0.25829","-0.00084","0.00000"
"2.66400","0.26014","0.07538","0.00000"
"2.68200","0.26191","0.04954","0.00000"
"2.70000","0.26365","0.08490","0.00000"
"2.71800","0.26546","0.12240","0.00000"
"2.73600","0.26732","0.11089","0.00000"
"2.75400","0.26918","0.13215","0.00000"
"2.77200","0.27101","0.10950","0.00000"
"2.79000","0.27277","0.07775","0.00000"
"2.80800","0.27452","0.03447","0.00000"
"2.82600","0.27631","-0.03070","0.00000"
"2.84400","0.27813","-0.03307","0.00000"
"2.86200","0.27999","0.01422","0.00000"
"2.88000","0.28188","-0.01375","0.00000"
"2.89800","0.28369","-0.03718","0.00000"
"2.91600","0.28539","-0.04403","0.00000"
"2.93400","0.28713","-0.03532","0.00000"
"2.95200","0.28895","0.03873","0.00000"
"2.97000","0.29079","0.07695","0.00000"
"2.98800","0.29264","0.02838","0.00000"
"3.00600","0.29445","-0.02906","0.00000"
"3.02400","0.29619","-0.00761","0.00000"
"3.04200","0.29790","0.01438","0.00000"
"3.06000","0.29965","0.00968","0.00000"
"3.07800","0.30145","0.04510","0.00000"
"3.09600","0.30330","-0.05230","0.00000"
"3.11400","0.30516","-0.03984","0.00000"
"3.13200","0.30695","0.04547","0.00000"
"3.15000","0.30866","0.04474","0.00000"
"3.16800","0.31040","-0.02102","0.00000"
"3.18600","0.31221","-0.05107","0.00000"
"3.20400","0.31404","-0.02807","0.00000"
"3.22200","0.31588","-0.01143","0.00000"
"3.24000","0.31770","0.03535","0.00000"
"3.25800","0.31947","0.06247","0.00000"
"3.27600","0.32122","0.06410","0.00000"
"3.29400","0.32302","0.05960","0.00000"
"3.31200","0.32484","0.07876","0.00000"
"3.33000","0.32672","0.08658","0.00000"
"3.34800","0.32860","0.09375","0.00000"
"3.36600","0.33037","0.02631","0.00000"
"3.38400","0.33209","-0.01265","0.00000"
"3.40200","0.33388","-0.01936","0.00000"
"3.42000","0.33573","0.01658","0.00000"
"3.43800","0.33758","0.09537","0.00000"
"3.45600","0.33945","0.08612","0.00000"
"3.47400","0.34126","0.10293","0.00000"
"3.49200","0.34300","0.07638","0.00000"
"3.51000","0.34474","-0.02351","0.00000"
"3.52800","0.34652","-0.09408","0.00000"
"3.54600","0.34836","-0.07270","0.00000"
"3.56400","0.35024","-0.04710","0.00000"
"3.58200","0.35207","-0.03082","0.00000"
"3.60000","0.35381","0.02945","0.00000"
"3.61800","0.35554","0.05021","0.00000"
"3.63600","0.35732","0.02224","0.00000"
"3.65400","0.35911","0.03683","0.00000"
"3.67200","0.36092","0.01572","0.00000"
"3.69000","0.36276","0.01042","0.00000"
"3.70800","0.36454","0.03574","0.00000"
"3.72600","0.36627","0.02092","0.00000"
"3.74400","0.36803","0.03986","0.00000"
"3.76200","0.36982","0.04500","0.00000"
"3.78000","0.37164","0.06089","0.00000"
"3.79800","0.37349","0.01501","0.00000"
"3.81600","0.37531","0.00610","0.00000"
"3.83400","0.37706","0.00222","0.00000"
"3.85200","0.37883","0.01736","0.00000"
"3.87000","0.38065","0.00194","0.00000"
"3.88800","0.38246","0.00516","0.00000"
"3.90600","0.38429","0.07158","0.00000"
"3.92400","0.38614","0.04464","0.00000"
"3.94200","0.38794","-0.00525","0.00000"
"3.96000","0.38969","-0.03720","0.00000"
"3.97800","0.39146","-0.01488","0.00000"
"3.99600","0.39327","-0.03294","0.00000"
"4.01400","0.39512","0.03699","0.00000"
"4.03200","0.39700","0.04076","0.00000"
"4.05000","0.39881","0.03815","0.00000"
"4.06800","0.40058","0.04844","0.00000"
"4.08600","0.40240","0.07736","0.00000"
"4.10400","0.40421","0.13338","0.00000"
"4.12200","0.40600","0.12766","0.00000"
"4.14000","0.40784","0.03505","0.00000"
"4.15800","0.40967","-0.04643","0.00000"
"4.17600","0.41142","0.01214","0.00000"
"4.19400","0.41315","0.03566","0.00000"
"4.21200","0.41493","0.04933","0.00000"
"4.23000","0.41674","0.07580","0.00000"
"4.24800","0.41855","0.07275","0.00000"
"4.26600","0.42037","0.01147","0.00000"
"4.28400","0.42214","-0.03716","0.00000"
"4.30200","0.42389","-0.04628","0.00000"
"4.32000","0.42569","0.01002","0.00000"
"4.33800","0.42748","0.03848","0.00000"
"4.35600","0.42927","0.06811","0.00000"
"4.37400","0.43108","0.03093","0.00000"
"4.39200","0.43285","-0.00259","0.00000"
"4.41000","0.43456","0.02580","0.00000"
"4.42800","0.43630","0.06228","0.00000"
"4.44600","0.43814","0.00515","0.00000"
"4.46400","0.44003","-0.01431","-0.00001"
"4.48200","0.44192","-0.03073","-0.00001"
"4.50000","0.44376","-0.04554","0.00000"
"4.51800","0.44551","0.02450","0.00000"
"4.53600","0.44726","0.12407","0.00000"
"4.55400","0.44907","0.08848","0.00000"
"4.57200","0.45089","0.07768","0.00000"
"4.59000","0.45273","0.03950","0.00000"
"4.60800","0.45460","0.05083","0.00000"
"4.62600","0.45641","0.04111","0.00000"
"4.64400","0.45815","0.02960","0.00000"
"4.66200","0.45992","0.03709","0.00000"
"4.68000","0.46176","-0.01067","-0.00001"
"4.69800","0.46361","-0.00564","-0.00001"
"4.71600","0.46546","-0.00541","-0.00001"
"4.73400","0.46727","0.04871","0.00000"
"4.75200","0.46903","0.11538","0.00000"
"4.77000","0.47079","0.13791","0.00000"
"4.78800","0.47256","0.11610","0.00000"
"4.80600","0.47434","0.04535","0.00000"
"4.82400","0.47616","-0.05663","0.00000"
"4.84200","0.47797","-0.02965","0.00000"
"4.86000","0.47971","-0.03858","0.00000"
"4.87800","0.48142","-0.03736","0.00000"
"4.89600","0.48320","0.00385","-0.00001"
"4.91400","0.48505","0.01329","-0.00001"
"4.93200","0.48690","0.06445","-0.00001"
"4.95000","0.48875","0.11670","0.00000"
"4.96800","0.49051","0.09930","0.00000"
"4.98600","0.49223","0.13379","0.00000"
"5.00400","0.49399","0.04428","0.00000"
"5.02200","0.49579","0.00570","0.00000"
"5.04000","0.49763","0.01776","0.00000"
"5.05800","0.49951","0.05234","0.00000"
"5.07600","0.50137","0.05655","0.00000"
"5.09400","0.50314","0.03532","0.00000"
"5.11200","0.50488","-0.01862","-0.00001"
"5.13000","0.50667","-0.04672","-0.00001"
"5.14800","0.50852","-0.05969","-0.00001"
"5.16600","0.51037","-0.07107","0.00000"
"5.18400","0.51220","-0.04955","0.00000"
"5.20200","0.51397","0.06854","0.00000"
"5.22000","0.51571","0.08109","0.00000"
"5.23800","0.51750","0.03453","0.00000"
"5.25600","0.51932","0.07978","0.00000"
"5.27400","0.52118","0.06360","0.00000"
"5.29200","0.52305","0.05190","0.00000"
"5.31000","0.52484","0.07455","0.00000"
"5.32800","0.52654","0.05216","-0.00001"
"5.34600","0.52830","-0.09027","-0.00001"
"5.36400","0.53016","-0.02771","-0.00001"
"5.38200","0.53203","0.02862","-0.00001"
"5.40000","0.53388","-0.00296","0.00000"
"5.41800","0.53569","0.03654","0.00000"
"5.43600","0.53742","0.08052","0.00000"
"5.45400","0.53912","0.08889","0.00000"
"5.47200","0.54087","-0.02843","0.00000"
"5.49000","0.54266","-0.04505","0.00000"
"5.50800","0.54450","-0.03198","0.00000"
"5.52600","0.54636","-0.01038","-0.00001"
"5.54400","0.54814","-0.01039","-0.00001"
"5.56200","0.54984","0.01386","-0.00001"
"5.58000","0.55158","0.06713","-0.00001"
"5.59800","0.55340","0.05641","-0.00001"
"5.61600","0.55524","0.03194","-0.00001"
"5.63400","0.55711","-0.01813","0.00000"
"5.65200","0.55894","-0.01904","0.00000"
"5.67000","0.56070","0.01926","0.00000"
"5.68800","0.56245","0.05596","0.00000"
"5.70600","0.56424","-0.00482","0.00000"
"5.72400","0.56606","-0.08147","0.00000"
"5.74200","0.56792","0.12704","0.00000"
"5.76000","0.56978","0.26081","-0.00001"
"5.77800","0.57154","0.17329","-0.00001"
"5.79600","0.57325","0.08494","-0.00001"
"5.81400","0.57506","-0.02848","-0.00001"
"5.83200","0.57691","-0.03679","-0.00001"
"5.85000","0.57878","-0.02131","0.00000"
"5.86800","0.58066","-0.03274","0.00000"
"5.88600","0.58249","0.01612","0.00000"
"5.90400","0.58424","0.05373","0.00000"
"5.92200","0.58597","-0.00189","0.00000"
"5.94000","0.58775","0.05616","0.00000"
"5.95800","0.58957","0.11597","0.00000"
"5.97600","0.59142","0.15744","-0.00001"
"5.99400","0.59324","0.10719","-0.00001"
"6.01200","0.59496","0.08892","-0.00001"
"6.03000","0.59669","0.06565","-0.00001"
"6.04800","0.59847","0.00028","-0.00001"
"6.06600","0.60026","0.04121","0.00000"
"6.08400","0.60208","0.07958","0.00000"
"6.10200","0.60393","0.06371","0.00000"
"6.12000","0.60572","-0.02930","0.00000"
"6.13800","0.60747","-0.05882","0.00000"
"6.15600","0.60924","0.08184","0.00000"
"6.17400","0.61103","0.03684","0.00000"
"6.19200","0.61283","0.03607","-0.00001"
"6.21000","0.61467","0.04916","-0.00001"
"6.22800","0.61647","0.04505","-0.00001"
"6.24600","0.61822","0.04522","-0.00001"
"6.26400","0.62000","0.06094","-0.00001"
"6.28200","0.62182","0.06900","-0.00001"
"6.30000","0.62364","-0.00293","0.00000"
"6.31800","0.62549","-0.05785","0.00000"
"6.33600","0.62735","-0.06595","0.00000"
"6.35400","0.62914","-0.08947","0.00000"
"6.37200","0.63088","-0.05814","0.00000"
"6.39000","0.63265","0.00572","-0.00001"
"6.40800","0.63447","0.01286","-0.00001"
"6.42600","0.63634","0.04113","-0.00001"
"6.44400","0.63822","-0.04957","-0.00001"
"6.46200","0.64001","0.00208","-0.00001"
"6.48000","0.64177","0.06997","-0.00001"
"6.49800","0.64358","0.06109","-0.00001"
"6.51600","0.64539","0.01469","-0.00001"
"6.53400","0.64719","-0.03691","0.00000"
"6.55200","0.64903","0.01537","0.00000"
"6.57000","0.65086","0.05368","0.00000"
"6.58800","0.65260","0.08020","0.00000"
"6.60600","0.65433","0.08206","0.00000"
"6.62400","0.65612","-0.00716","-0.00001"
"6.64200","0.65792","-0.06848","-0.00001"
"6.66000","0.65973","-0.00866","-0.00001"
"6.67800","0.66155","0.01620","-0.00001"
"6.69600","0.66331","0.08906","-0.00001"
"6.71400","0.66507","0.11122","-0.00001"
"6.73200","0.66687","-0.01657","0.00000"
"6.75000","0.66868","-0.04817","0.00000"
"6.76800","0.67048","-0.05238","0.00000"
"6.78600","0.67231","0.02241","0.00000"
"6.80400","0.67408","0.01148","0.00000"
"6.82200","0.67578","0.02902","0.00000"
"6.84000","0.67752","0.00502","0.00000"
"6.85800","0.67935","0.01842","-0.00001"
"6.87600","0.68122","0.08643","-0.00001"
"6.89400","0.68311","0.06757","-0.00001"
"6.91200","0.68494","0.05114","-0.00001"
"6.93000","0.68669","0.02610","-0.00001"
"6.94800","0.68846","-0.02061","-0.00001"
"6.96600","0.69028","-0.05745","0.00000"
"6.98400","0.69210","-0.05377","0.00000"
"7.00200","0.69392","-0.05917","0.00000"
"7.02000","0.69577","-0.07545","0.00000"
"7.03800","0.69757","-0.10023","0.00000"
"7.05600","0.69933","-0.01488","0.00000"
"7.07400","0.70112","0.04727","-0.00001"
"7.09200","0.70297","-0.00779","-0.00001"
"7.11000","0.70481","-0.03869","-0.00001"
"7.12800","0.70666","-0.13526","-0.00001"
"7.14600","0.70846","-0.03522","-0.00001"
"7.16400","0.71023","0.03085","-0.00001"
"7.18200","0.71200","0.08323","0.00000"
"7.20000","0.71378","0.04939","0.00000"
"7.21800","0.71556","0.03389","0.00000"
"7.23600","0.71739","0.04573","0.00000"
"7.25400","0.71920","0.06556","0.00000"
"7.27200","0.72093","0.03099","0.00000"
"7.29000","0.72263","0.05245","-0.00001"
"7.30800","0.72442","0.01533","-0.00001"
"7.32600","0.72626","0.11305","-0.00001"
"7.34400","0.72811","0.06726","-0.00001"
"7.36200","0.72995","-0.03194","-0.00001"
"7.38000","0.73169","-0.04017","-0.00001"
"7.39800","0.73340","-0.03227","-0.00001"
"7.41600","0.73517","-0.03165","0.00000"
"7.43400","0.73699","-0.00726","0.00000"
"7.45200","0.73885","0.05181","0.00000"
"7.47000","0.74075","0.07195","0.00000"
"7.48800","0.74259","0.06524","-0.00001"
"7.50600","0.74432","0.08189","-0.00001"
"7.52400","0.74603","0.03848","-0.00001"
"7.54200","0.74782","-0.03374","-0.00001"
"7.56000","0.74966","-0.05425","-0.00001"
"7.57800","0.75154","0.03268","-0.00001"
"7.59600","0.75339","0.03501","-0.00001"
"7.61400","0.75518","0.04667","-0.00001"
"7.63200","0.75693","0.01555","0.00000"
"7.65000","0.75872","0.00264","0.00000"
"7.66800","0.76054","0.08410","0.00000"
"7.68600","0.76240","0.10256","0.00000"
"7.70400","0.76428","0.07869","0.00000"
"7.72200","0.76605","0.07315","-0.00001"
"7.74000","0.76775","0.08256","-0.00001"
"7.75800","0.76950","0.05585","-0.00001"
"7.77600","0.77135","0.06629","-0.00001"
"7.79400","0.77320","0.07281","-0.00001"
"7.81200","0.77504","0.07005","-0.00001"
"7.83000","0.77684","0.10612","-0.00001"
"7.84800","0.77858","0.11532","-0.00001"
"7.86600","0.78031","-0.03715","0.00000"
"7.88400","0.78207","0.01690","0.00000"
"7.90200","0.78386","0.08254","0.00000"
"7.92000","0.78570","0.07185","-0.00001"
"7.93800","0.78755","0.03639","-0.00001"
"7.95600","0.78931","0.05621","-0.00001"
"7.97400","0.79100","0.10425","-0.00001"
"7.99200","0.79274","0.07349","-0.00001"
"8.01000","0.79456","0.02804","-0.00001"
"8.02800","0.79641","0.07610","-0.00001"
"8.04600","0.79829","0.00740","-0.00001"
"8.06400","0.80012","-0.03492","-0.00001"
"8.08200","0.80189","0.04903","-0.00001"
"8.10000","0.80366","0.11853","0.00000"
"8.11800","0.80546","0.07601","0.00000"
"8.13600","0.80728","0.04402","0.00000"
"8.15400","0.80914","0.09950","-0.00001"
"8.17200","0.81099","0.02065","-0.00001"
"8.19000","0.81274","0.01808","-0.00001"
"8.20800","0.81447","0.04243","-0.00001"
"8.22600","0.81628","0.06392","-0.00001"
"8.24400","0.81813","0.04095","-0.00001"
"8.26200","0.81999","0.02530","-0.00001"
"8.28000","0.82186","-0.01714","-0.00001"
"8.29800","0.82369","-0.03345","-0.00001"
"8.31600","0.82543","0.03080","0.00000"
"8.33400","0.82718","0.04895","0.00000"
"8.35200","0.82896","0.00562","-0.00001"
"8.37000","0.83078","-0.02143","-0.00001"
"8.38800","0.83263","0.00709","-0.00001"
"8.40600","0.83443","0.05380","-0.00001"
"8.42400","0.83614","0.04627","-0.00001"
"8.44200","0.83786","0.05102","-0.00001"
"8.46000","0.83965","0.00018","-0.00001"
"8.47800","0.84146","-0.00481","-0.00001"
"8.49600","0.84330","0.02382","-0.00001"
"8.51400","0.84514","0.08905","-0.00001"
"8.53200","0.84693","0.00655","0.00000"
"8.55000","0.84867","0.03031","0.00000"
"8.56800","0.85045","0.05096","0.00000"
"8.58600","0.85225","0.00094","0.00000"
"8.60400","0.85406","0.02662","-0.00001"
"8.62200","0.85590","0.03023","-0.00001"
"8.64000","0.85770","0.01983","-0.00001"
"8.65800","0.85945","0.00552","-0.00001"
"8.67600","0.86123","-0.01915","-0.00001"
"8.69400","0.86305","-0.06726","-0.00001"
"8.71200","0.86486","-0.05940","-0.00001"
"8.73000","0.86669","-0.10913","-0.00001"
"8.74800","0.86854","-0.06978","0.00000"
"8.76600","0.87033","0.02040","0.00000"
"8.78400","0.87208","0.07595","0.00000"
"8.80200","0.87386","0.06941","0.00000"
"8.82000","0.87568","0.09525","-0.00001"
"8.83800","0.87753","-0.03643","-0.00001"
"8.85600","0.87940","-0.06653","-0.00001"
"8.87400","0.88119","-0.03676","-0.00001"
"8.89200","0.88296","0.03235","-0.00001"
"8.91000","0.88478","0.03472","-0.00001"
"8.92800","0.88660","0.01839","-0.00001"
"8.94600","0.88840","-0.00485","0.00000"
"8.96400","0.89025","-0.02270","0.00000"
"8.98200","0.89208","0.00310","0.00000"
"9.00000","0.89383","0.00952","0.00000"
"9.01800","0.89556","0.00036","0.00000"
"9.03600","0.89734","0.06449","0.00000"
"9.05400","0.89914","0.10944","-0.00001"
"9.07200","0.90096","0.03068","-0.00001"
"9.09000","0.90277","-0.09962","-0.00001"
"9.10800","0.90452","-0.08882","-0.00001"
"9.12600","0.90625","0.00032","-0.00001"
"9.14400","0.90804","0.07159","-0.00001"
"9.16200","0.90984","0.06969","-0.00001"
"9.18000","0.91163","0.02713","0.00000"
"9.19800","0.91346","0.04603","0.00000"
"9.21600","0.91525","0.10687","0.00000"
"9.23400","0.91698","0.03791","0.00000"
"9.25200","0.91874","-0.01847","0.00000"
"9.27000","0.92058","-0.00944","-0.00001"
"9.28800","0.92245","0.01527","-0.00001"
"9.30600","0.92433","0.06464","-0.00001"
"9.32400","0.92615","0.02331","-0.00001"
"9.34200","0.92790","0.02834","-0.00001"
"9.36000","0.92968","0.03523","-0.00001"
"9.37800","0.93151","0.05351","-0.00001"
"9.39600","0.93333","0.01137","0.00000"
"9.41400","0.93517","-0.01680","0.00000"
"9.43200","0.93703","0.03899","0.00000"
"9.45000","0.93882","0.09105","0.00000"
"9.46800","0.94055","0.04291","0.00000"
"9.48600","0.94233","0.02783","-0.00001"
"9.50400","0.94417","-0.05709","-0.00001"
"9.52200","0.94602","-0.02157","-0.00001"
"9.54000","0.94786","0.01699","-0.00001"
"9.55800","0.94965","0.02442","-0.00001"
"9.57600","0.95141","-0.04044","-0.00001"
"9.59400","0.95318","-0.02677","-0.00001"
"9.61200","0.95496","-0.00134","-0.00001"
"9.63000","0.95674","0.04499","0.00000"
"9.64800","0.95857","0.03782","0.00000"
"9.66600","0.96038","0.04847","0.00000"
"9.68400","0.96210","0.11207","0.00000"
"9.70200","0.96380","0.08366","-0.00001"
"9.72000","0.96559","-0.00051","-0.00001"
"9.73800","0.96744","-0.00126","-0.00001"
"9.75600","0.96930","0.00074","-0.00001"
"9.77400","0.97114","0.00775","-0.00001"
"9.79200","0.97289","-0.06893","-0.00001"
"9.81000","0.97460","-0.07338","-0.00001"
"9.82800","0.97637","-0.03160","-0.00001"
"9.84600","0.97820","0.04896","0.00000"
"9.86400","0.98005","0.02617","0.00000"
"9.88200","0.98194","0.05179","0.00000"
"9.90000","0.98377","-0.01499","0.00000"
"9.91800","0.98551","0.00069","-0.00001"
"9.93600","0.98724","0.06936","-0.00001"
"9.95400","0.98905","0.12383","-0.00001"
"9.97200","0.99090","0.13026","-0.00001"
"9.99000","0.99276","0.08362","-0.00001"
"10.00800","0.99460","0.08185","-0.00001"
"10.02600","0.99638","-0.01995","-0.00001"
"10.04400","0.99814","-0.03719","-0.00001"
"10.06200","0.99994","0.06088","0.00000"
"10.08000","1.00176","0.13130","0.00000"
"10.09800","1.00363","0.10945","0.00000"
"10.11600","1.00550","0.08119","0.00000"
"10.13400","1.00726","0.05003","0.00000"
"10.15200","1.00894","-0.02088","-0.00001"
"10.17000","1.01069","-0.06524","-0.00001"
"10.18800","1.01252","0.02958","-0.00001"
"10.20600","1.01438","0.06377","-0.00001"
"10.22400","1.01622","0.06687","-0.00001"
"10.24200","1.01803","0.05605","-0.00001"
"10.26000","1.01977","0.10454","-0.00001"
"10.27800","1.02150","0.10595","-0.00001"
"10.29600","1.02328","-0.00058","0.00000"
"10.31400","1.02509","-0.09019","0.00000"
"10.33200","1.02694","-0.08674","0.00000"
"10.35000","1.02879","-0.03670","0.00000"
"10.36800","1.03054","0.04345","-0.00001"
"10.38600","1.03223","0.10040","-0.00001"
"10.40400","1.03398","0.09532","-0.00001"
"10.42200","1.03578","0.12308","-0.00001"
"10.44000","1.03761","0.11050","-0.00001"
"10.45800","1.03947","0.02732","-0.00001"
"10.47600","1.04130","0.03998","-0.00001"
"10.49400","1.04306","0.03861","-0.00001"
"10.51200","1.04482","-0.01316","0.00000"
"10.53000","1.04662","0.00944","0.00000"
"10.54800","1.04845","0.03267","0.00000"
"10.56600","1.05033","0.04665","-0.00001"
"10.58400","1.05218","0.09742","-0.00001"
"10.60200","1.05392","0.04704","-0.00001"
"10.62000","1.05565","0.04107","-0.00001"
"10.63800","1.05745","0.01549","-0.00001"
"10.65600","1.05930","-0.03864","-0.00001"
"10.67400","1.06116","-0.00810","-0.00001"
"10.69200","1.06304","0.02251","-0.00001"
"10.71000","1.06487","0.06253","-0.00001"
"10.72800","1.06662","0.06063","-0.00001"
"10.74600","1.06839","0.04415","0.00000"
"10.76400","1.07018","0.04405","0.00000"
"10.78200","1.07201","0.01567","0.00000"
"10.80000","1.07387","-0.01814","-0.00001"
"10.81800","1.07566","-0.00749","-0.00001"
"10.83600","1.07737","0.01728","-0.00001"
"10.85400","1.07909","0.08316","-0.00001"
"10.87200","1.08086","0.05233","-0.00001"
"10.89000","1.08265","0.01569","-0.00001"
"10.90800","1.08447","0.00378","-0.00001"
"10.92600","1.08631","-0.08301","-0.00001"
"10.94400","1.08809","-0.05966","0.00000"
"10.96200","1.08983","-0.01917","0.00000"
"10.98000","1.09162","0.03099","0.00000"
"10.99800","1.09343","0.02568","0.00000"
"11.01600","1.09526","0.00526","0.00000"
"11.03400","1.09711","-0.00963","-0.00001"
"11.05200","1.09891","0.00437","-0.00001"
"11.07000","1.10065","0.05372","-0.00001"
"11.08800","1.10243","0.07908","-0.00001"
"11.10600","1.10423","0.06461","-0.00001"
"11.12400","1.10603","0.00987","-0.00001"
"11.14200","1.10788","0.02254","-0.00001"
"11.16000","1.10974","0.05004","0.00000"
"11.17800","1.11154","0.12285","0.00000"
"11.19600","1.11330","0.10924","0.00000"
"11.21400","1.11508","0.06974","0.00000"
"11.23200","1.11690","0.04351","0.00000"
"11.25000","1.11876","0.01929","0.00000"
"11.26800","1.12062","-0.00541","-0.00001"
"11.28600","1.12241","-0.00253","-0.00001"
"11.30400","1.12417","0.01231","-0.00001"
"11.32200","1.12599","-0.07428","-0.00001"
"11.34000","1.12781","-0.16244","-0.00001"
"11.35800","1.12962","-0.09559","0.00000"
"11.37600","1.13147","-0.05187","0.00000"
"11.39400","1.13329","0.11483","0.00000"
"11.41200","1.13502","0.06284","0.00000"
"11.43000","1.13676","0.01586","0.00000"
"11.44800","1.13855","0.05961","0.00000"
"11.46600","1.14035","0.16251","0.00000"
"11.48400","1.14217","0.08930","0.00000"
"11.50200","1.14396","-0.01406","0.00000"
"11.52000","1.14570","0.04016","0.00000"
"11.53800","1.14745","0.03744","0.00000"
"11.55600","1.14925","0.00285","0.00000"
"11.57400","1.15106","-0.05480","0.00000"
"11.59200","1.15288","0.04011","0.00000"
"11.61000","1.15471","0.10101","0.00000"
"11.62800","1.15648","0.01780","0.00000"
"11.64600","1.15819","0.00366","0.00000"
"11.66400","1.15996","0.04034","0.00000"
"11.68200","1.16180","0.05250","0.00000"
"11.70000","1.16368","0.08662","0.00000"
"11.71800","1.16556","0.11634","0.00000"
"11.73600","1.16737","0.03044","0.00000"
"11.75400","1.16910","-0.13109","0.00000"
"11.77200","1.17086","-0.11098","0.00000"
"11.79000","1.17268","-0.00830","0.00000"
"11.80800","1.17450","0.07620","0.00000"
"11.82600","1.17634","0.09923","0.00000"
"11.84400","1.17821","0.01901","0.00000"
"11.86200","1.18001","0.04145","0.00000"
"11.88000","1.18175","0.07322","0.00000"
"11.89800","1.18354","0.08881","0.00000"
"11.91600","1.18539","0.11945","0.00000"
"11.93400","1.18724","0.14213","0.00000"
"11.95200","1.18907","0.03916","0.00000"
"11.97000","1.19086","-0.06494","0.00000"
"11.98800","1.19261","0.04576","0.00000"
"12.00600","1.19437","0.14659","0.00000"
"12.02400","1.19615","0.07123","0.00000"
"12.04200","1.19793","0.01902","0.00000"
"12.06000","1.19976","-0.04048","0.00000"
"12.07800","1.20157","-0.03980","0.00000"
"12.09600","1.20331","-0.05300","0.00000"
"12.11400","1.20503","-0.06091","0.00000"
"12.13200","1.20683","-0.01735","0.00000"
"12.15000","1.20865","0.06789","0.00000"
"12.16800","1.21049","0.02297","0.00000"
"12.18600","1.21231","-0.07138","0.00000"
"12.20400","1.21406","-0.08625","0.00000"
"12.22200","1.21578","-0.01886","0.00000"
"12.24000","1.21755","0.02930","0.00000"
"12.25800","1.21936","0.04649","0.00000"
"12.27600","1.22121","0.12557","0.00000"
"12.29400","1.22309","0.12702","0.00000"
"12.31200","1.22492","0.07366","0.00000"
"12.33000","1.22666","0.13179","0.00000"
"12.34800","1.22840","0.15435","0.00000"
"12.36600","1.23022","0.11172","0.00000"
"12.38400","1.23208","0.07896","0.00000"
"12.40200","1.23394","0.08038","0.00000"
"12.42000","1.23577","0.06045","0.00000"
"12.43800","1.23753","0.02968","0.00000"
"12.45600","1.23929","0.06692","0.00000"
"12.47400","1.24110","0.04281","0.00000"
"12.49200","1.24294","-0.00154","0.00000"
"12.51000","1.24483","-0.00008","0.00000"
"12.52800","1.24671","0.07317","0.00000"
"12.54600","1.24849","0.07598","0.00000"
"12.56400","1.25018","0.03649","0.00000"
"12.58200","1.25195","-0.02911","0.00000"
"12.60000","1.25379","-0.03749","0.00000"
"12.61800","1.25563","0.00256","0.00000"
"12.63600","1.25747","-0.05852","0.00000"
"12.65400","1.25925","-0.05527","0.00000"
"12.67200","1.26096","-0.03707","0.00000"
"12.69000","1.26268","-0.04082","0.00000"
"12.70800","1.26446","-0.09048","0.00000"
"12.72600","1.26627","-0.01679","0.00000"
"12.74400","1.26812","0.05683","0.00000"
"12.76200","1.26996","0.01577","0.00000"
"12.78000","1.27171","0.05369","0.00000"
"12.79800","1.27341","0.11660","0.00000"
"12.81600","1.27518","0.00811","0.00000"
"12.83400","1.27700","-0.04674","-0.00001"
"12.85200","1.27884","-0.02069","-0.00001"
"12.87000","1.28070","-0.00047","-0.00001"
"12.88800","1.28252","0.02094","-0.00001"
"12.90600","1.28427","0.05084","0.00000"
"12.92400","1.28603","0.10449","0.00000"
"12.94200","1.28784","0.03355","0.00000"
"12.96000","1.28967","0.00261","0.00000"
"12.97800","1.29155","-0.07387","0.00000"
"12.99600","1.29339","-0.07342","0.00000"
"13.01400","1.29513","-0.04553","-0.00001"
"13.03200","1.29685","-0.03064","-0.00001"
"13.05000","1.29867","0.03204","-0.00001"
"13.06800","1.30053","0.02987","-0.00001"
"13.08600","1.30240","-0.01069","-0.00001"
"13.10400","1.30427","-0.07144","-0.00001"
"13.12200","1.30608","-0.06609","-0.00001"
"13.14000","1.30782","-0.08384","-0.00001"
"13.15800","1.30959","-0.05203","-0.00001"
"13.17600","1.31138","0.05341","0.00000"
"13.19400","1.31321","0.10383","0.00000"
"13.21200","1.31507","0.07111","-0.00001"
"13.23000","1.31686","0.00271","-0.00001"
"13.24800","1.31858","0.00108","-0.00001"
"13.26600","1.32030","0.04534","-0.00001"
"13.28400","1.32208","0.07265","-0.00001"
"13.30200","1.32386","0.06440","-0.00001"
"13.32000","1.32569","0.04690","-0.00001"
"13.33800","1.32753","0.08698","-0.00001"
"13.35600","1.32930","0.11927","-0.00001"
"13.37400","1.33104","0.01992","-0.00001"
"13.39200","1.33284","-0.03677","-0.00001"
"13.41000","1.33465","-0.00788","-0.00001"
"13.42800","1.33648","0.05575","-0.00001"
"13.44600","1.33832","0.05449","-0.00001"
"13.46400","1.34011","0.05601","-0.00001"
"13.48200","1.34186","0.09903","-0.00001"
"13.50000","1.34364","-0.00329","-0.00001"
"13.51800","1.34544","-0.02914","-0.00001"
"13.53600","1.34724","0.02447","-0.00001"
"13.55400","1.34908","0.03432","-0.00001"
"13.57200","1.35093","0.03224","-0.00001"
"13.59000","1.35273","0.07510","-0.00001"
"13.60800","1.35448","0.08781","0.00000"
"13.62600","1.35626","0.03686","0.00000"
"13.64400","1.35807","0.05078","0.00000"
"13.66200","1.35994","0.04682","-0.00001"
"13.68000","1.36181","-0.05667","-0.00001"
"13.69800","1.36360","-0.08496","-0.00001"
"13.71600","1.36537","0.00968","-0.00001"
"13.73400","1.36719","0.06725","-0.00001"
"13.75200","1.36899","0.09749","-0.00001"
"13.77000","1.37080","0.07253","-0.00001"
"13.78800","1.37265","0.10513","-0.00001"
"13.80600","1.37446","0.10417","-0.00001"
"13.82400","1.37619","0.04745","0.00000"
"13.84200","1.37794","0.01823","0.00000"
"13.86000","1.37974","0.02068","0.00000"
"13.87800","1.38155","0.02029","0.00000"
"13.89600","1.38336","-0.01254","-0.00001"
"13.91400","1.38515","-0.04729","-0.00001"
"13.93200","1.38690","0.00601","-0.00001"
"13.95000","1.38866","0.07002","-0.00001"
"13.96800","1.39047","0.12412","-0.00001"
"13.98600","1.39227","0.06138","0.00000"
"14.00400","1.39407","0.01624","0.00000"
"14.02200","1.39590","-0.04499","0.00000"
"14.04000","1.39766","0.05013","0.00000"
"14.05800","1.39937","0.08318","0.00000"
"14.07600","1.40114","0.02433","0.00000"
"14.09400","1.40298","0.01385","0.00000"
"14.11200","1.40487","-0.00130","0.00000"
"14.13000","1.40675","-0.07980","0.00000"
"14.14800","1.40855","-0.05931","0.00000"
"14.16600","1.41028","-0.01399","0.00000"
"14.18400","1.41205","0.07604","0.00000"
"14.20200","1.41386","0.11388","0.00000"
"14.22000","1.41568","0.03343","0.00000"
"14.23800","1.41751","0.01073","0.00000"
"14.25600","1.41936","-0.09975","0.00000"
"14.27400","1.42116","-0.04006","0.00000"
"14.29200","1.42292","0.01743","0.00000"
"14.31000","1.42473","-0.02949","0.00000"
"14.32800","1.42658","-0.02762","0.00000"
"14.34600","1.42843","0.08383","0.00000"
"14.36400","1.43027","0.08723","0.00000"
"14.38200","1.43206","0.03523","0.00000"
"14.40000","1.43381","0.08101","0.00000"
"14.41800","1.43558","0.12929","0.00000"
"14.43600","1.43735","0.03068","0.00000"
"14.45400","1.43913","0.10015","0.00000"
"14.47200","1.44097","0.17329","0.00000"
"14.49000","1.44278","0.15944","0.00000"
"14.50800","1.44450","0.03856","0.00000"
"14.52600","1.44622","-0.00643","0.00000"
"14.54400","1.44803","-0.00842","0.00000"
"14.56200","1.44988","-0.03873","0.00000"
"14.58000","1.45173","-0.00754","0.00000"
"14.59800","1.45354","0.01865","0.00000"
"14.61600","1.45528","0.00967","0.00000"
"14.63400","1.45699","0.03688","0.00000"
"14.65200","1.45877","0.05219","0.00000"
"14.67000","1.46059","0.05353","0.00000"
"14.68800","1.46243","0.07545","0.00001"
"14.70600","1.46431","0.09214","0.00001"
"14.72400","1.46615","0.08966","0.00001"
"14.74200","1.46789","0.06733","0.00001"
"14.76000","1.46965","0.06051","0.00001"
"14.77800","1.47146","0.03370","0.00001"
"14.79600","1.47331","0.05169","0.00001"
"14.81400","1.47517","0.01424","0.00001"
"14.83200","1.47699","-0.00692","0.00001"
"14.85000","1.47875","-0.03754","0.00001"
"14.86800","1.48050","0.03234","0.00001"
"14.88600","1.48230","0.04581","0.00001"
"14.90400","1.48414","0.02022","0.00001"
"14.92200","1.48602","-0.01372","0.00001"
"14.94000","1.48789","-0.02401","0.00001"
"14.95800","1.48965","0.00182","0.00001"
"14.97600","1.49135","0.02966","0.00001"
"14.99400","1.49313","-0.01391","0.00001"
"15.01200","1.49498","-0.05094","0.00001"
"15.03000","1.49683","-0.04258","0.00001"
"15.04800","1.49866","0.00793","0.00001"
"15.06600","1.50043","0.04623","0.00001"
"15.08400","1.50215","0.04508","0.00001"
"15.10200","1.50389","0.04333","0.00001"
"15.12000","1.50567","0.04833","0.00001"
"15.13800","1.50748","0.05894","0.00002"
"15.15600","1.50934","0.01457","0.00002"
"15.17400","1.51119","-0.00399","0.00002"
"15.19200","1.51294","-0.06182","0.00002"
"15.21000","1.51465","-0.04906","0.00002"
"15.22800","1.51642","0.04680","0.00001"
"15.24600","1.51823","0.04338","0.00001"
"15.26400","1.52007","0.03967","0.00001"
"15.28200","1.52192","-0.03854","0.00001"
"15.30000","1.52372","-0.05362","0.00001"
"15.31800","1.52546","0.03151","0.00002"
"15.33600","1.52722","0.01101","0.00002"
"15.35400","1.52903","-0.03102","0.00002"
"15.37200","1.53088","-0.01022","0.00002"
"15.39000","1.53278","-0.01545","0.00002"
"15.40800","1.53461","-0.02958","0.00002"
"15.42600","1.53633","0.03846","0.00002"
"15.44400","1.53805","0.09663","0.00002"
"15.46200","1.53987","0.03559","0.00002"
"15.48000","1.54173","-0.01273","0.00002"
"15.49800","1.54360","-0.08747","0.00002"
"15.51600","1.54546","-0.09997","0.00002"
"15.53400","1.54725","-0.03535","0.00002"
"15.55200","1.54899","0.10382","0.00002"
"15.57000","1.55074","0.05359","0.00002"
"15.58800","1.55253","0.09783","0.00002"
"15.60600","1.55437","0.08570","0.00002"
"15.62400","1.55624","0.09765","0.00002"
"15.64200","1.55805","0.05488","0.00002"
"15.66000","1.55979","0.04981","0.00002"
"15.67800","1.56153","0.03967","0.00002"
"15.69600","1.56330","-0.04967","0.00002"
"15.71400","1.56508","-0.05980","0.00001"
"15.73200","1.56690","0.02845","0.00002"
"15.75000","1.56873","0.07859","0.00002"
"15.76800","1.57050","0.06257","0.00002"
"15.78600","1.57224","0.07153","0.00002"
"15.80400","1.57403","0.08775","0.00002"
"15.82200","1.57584","0.02608","0.00002"
"15.84000","1.57768","-0.01014","0.00002"
"15.85800","1.57952","-0.00299","0.00002"
"15.87600","1.58130","-0.02179","0.00002"
"15.89400","1.58304","-0.01599","0.00002"
"15.91200","1.58484","0.04645","0.00001"
"15.93000","1.58666","-0.00611","0.00001"
"15.94800","1.58845","0.02746","0.00001"
"15.96600","1.59028","0.08406","0.00001"
"15.98400","1.59211","0.12716","0.00001"
"16.00200","1.59388","0.15216","0.00002"
"16.02000","1.59564","0.06058","0.00002"
"16.03800","1.59744","0.00290","0.00002"
"16.05600","1.59927","0.01862","0.00002"
"16.07400","1.60115","0.08466","0.00002"
"16.09200","1.60302","0.10885","0.00002"
"16.11000","1.60481","0.09441","0.00001"
"16.12800","1.60658","0.03538","0.00001"
"16.14600","1.60839","0.03231","0.00001"
"16.16400","1.61018","-0.02448","0.00001"
"16.18200","1.61197","-0.02520","0.00001"
"16.20000","1.61382","-0.00074","0.00001"
"16.21800","1.61562","0.05774","0.00001"
"16.23600","1.61735","0.08891","0.00001"
"16.25400","1.61912","0.05267","0.00002"
"16.27200","1.62093","0.07648","0.00001"
"16.29000","1.62274","0.09182","0.00001"
"16.30800","1.62456","0.07561","0.00001"
"16.32600","1.62635","-0.02922","0.00001"
"16.34400","1.62809","-0.10992","0.00001"
"16.36200","1.62984","-0.01883","0.00001"
"16.38000","1.63164","-0.01608","0.00000"
"16.39800","1.63345","-0.04656","-0.00002"
"16.41600","1.63526","-0.02090","-0.00006"
"16.43400","1.63708","0.00268","-0.00009"
"16.45200","1.63883","0.04872","-0.00014"
"16.47000","1.64054","0.07005","-0.00019"
"16.48800","1.64231","0.05372","-0.00023"
"16.50600","1.64417","0.02495","-0.00026"
"16.52400","1.64605","0.03762","-0.00026"
"16.54200","1.64794","-0.05518","-0.00026"
"16.56000","1.64974","-0.05979","-0.00026"
"16.57800","1.65148","0.03421","-0.00026"
"16.59600","1.65326","0.04349","-0.00026"
"16.61400","1.65509","0.02544","-0.00026"
"16.63200","1.65690","0.06087","-0.00026"
"16.65000","1.65874","0.07550","-0.00026"
"16.66800","1.66059","-0.03952","-0.00026"
"16.68600","1.66238","0.11935","-0.00026"
"16.70400","1.66413","-0.01525","-0.00026"
"16.72200","1.66594","-0.04269","-0.00027"
"16.74000","1.66779","0.08982","-0.00027"
"16.75800","1.66963","-0.03265","-0.00027"
"16.77600","1.67147","0.00686","-0.00027"
"16.79400","1.67324","0.07985","-0.00027"
"16.81200","1.67499","-0.02519","-0.00027"
"16.83000","1.67676","0.02286","-0.00026"
"16.84800","1.67853","0.09710","-0.00026"
"16.86600","1.68032","0.05358","-0.00026"
"16.88400","1.68215","0.11758","-0.00026"
"16.90200","1.68394","0.06986","-0.00026"
"16.92000","1.68566","0.05249","-0.00026"
"16.93800","1.68739","0.09355","-0.00026"
"16.95600","1.68921","0.02923","-0.00026"
"16.97400","1.69108","0.07734","-0.00026"
"16.99200","1.69294","0.02546","-0.00026"
"17.01000","1.69477","0.04609","-0.00026"
"17.02800","1.69650","0.11741","-0.00026"
"17.04600","1.69822","0.07065","-0.00027"
"17.06400","1.70000","0.00348","-0.00027"
"17.08200","1.70181","0.05437","-0.00026"
"17.10000","1.70365","0.04412","-0.00026"
"17.11800","1.70553","0.01787","-0.00026"
"17.13600","1.70734","-0.10090","-0.00026"
"17.15400","1.70907","-0.10646","-0.00026"
"17.17200","1.71083","0.00020","-0.00026"
"17.19000","1.71266","0.07528","-0.00026"
"17.20800","1.71450","0.03636","-0.00026"
"17.22600","1.71635","0.06696","-0.00026"
"17.24400","1.71816","0.04686","-0.00026"
"17.26200","1.71993","0.03551","-0.00027"
"17.28000","1.72170","0.04266","-0.00027"
"17.29800","1.72353","0.01585","-0.00026"
"17.31600","1.72537","0.04781","-0.00026"
"17.33400","1.72725","0.07151","-0.00026"
"17.35200","1.72911","0.10379","-0.00026"
"17.37000","1.73086","0.09710","-0.00026"
"17.38800","1.73255","0.05105","-0.00026"
"17.40600","1.73434","0.04299","-0.00026"
"17.42400","1.73619","-0.00899","-0.00026"
"17.44200","1.73805","-0.02207","-0.00026"
"17.46000","1.73988","-0.02224","-0.00026"
"17.47800","1.74166","0.04770","-0.00026"
"17.49600","1.74337","0.02996","-0.00026"
"17.51400","1.74510","0.04596","-0.00026"
"17.53200","1.74688","0.00400","-0.00026"
"17.55000","1.74869","0.03382","-0.00026"
"17.56800","1.75054","0.08785","-0.00026"
"17.58600","1.75238","0.07307","-0.00026"
"17.60400","1.75412","0.01209","-0.00026"
"17.62200","1.75582","-0.00992","-0.00026"
"17.64000","1.75758","-0.01980","-0.00026"
"17.65800","1.75939","0.02897","-0.00026"
"17.67600","1.76121","0.07362","-0.00026"
"17.69400","1.76307","0.18748","-0.00026"
"17.71200","1.76488","0.16166","-0.00026"
"17.73000","1.76664","0.11571","-0.00026"
"17.74800","1.76842","0.10434","-0.00026"
"17.76600","1.77024","0.08942","-0.00026"
"17.78400","1.77208","0.05531","-0.00026"
"17.80200","1.77396","0.02716","-0.00026"
"17.82000","1.77579","0.07859","-0.00026"
"17.83800","1.77752","0.09147","-0.00026"
"17.85600","1.77927","0.13543","-0.00026"
"17.87400","1.78111","0.12116","-0.00026"
"17.89200","1.78297","0.09275","-0.00026"
"17.91000","1.78483","0.11363","-0.00026"
"17.92800","1.78668","0.10472","-0.00026"
"17.94600","1.78847","0.14891","-0.00026"
"17.96400","1.79019","0.09664","-0.00026"
"17.98200","1.79194","0.00940","-0.00026"
"18.00000","1.79374","0.06811","-0.00026"
"18.01800","1.79559","0.01053","-0.00026"
"18.03600","1.79746","-0.01244","-0.00026"
"18.05400","1.79925","-0.00720","-0.00026"
"18.07200","1.80096","-0.04061","-0.00026"
"18.09000","1.80270","-0.02144","-0.00026"
"18.10800","1.80447","0.06713","-0.00026"
"18.12600","1.80627","0.04256","-0.00026"
"18.14400","1.80810","0.05247","-0.00026"
"18.16200","1.80993","-0.01601","-0.00026"
"18.18000","1.81169","-0.02176","-0.00026"
"18.19800","1.81343","-0.00921","-0.00026"
"18.21600","1.81521","0.06940","-0.00026"
"18.23400","1.81701","-0.00153","-0.00026"
"18.25200","1.81884","0.03105","-0.00026"
"18.27000","1.82070","0.03716","-0.00026"
"18.28800","1.82250","-0.03226","-0.00026"
"18.30600","1.82427","0.00581","-0.00026"
"18.32400","1.82608","-0.01767","-0.00026"
"18.34200","1.82789","-0.00839","-0.00026"
"18.36000","1.82969","0.06017","-0.00027"
"18.37800","1.83153","0.04172","-0.00027"
"18.39600","1.83335","0.03092","-0.00027"
"18.41400","1.83510","0.05486","-0.00027"
"18.43200","1.83684","0.04645","-0.00026"
"18.45000","1.83863","0.04075","-0.00026"
"18.46800","1.84047","0.01482","-0.00026"
"18.48600","1.84234","-0.01959","-0.00026"
"18.50400","1.84420","-0.01908","-0.00026"
"18.52200","1.84598","0.04008","-0.00027"
"18.54000","1.84776","0.08878","-0.00027"
"18.55800","1.84959","-0.00505","-0.00027"
"18.57600","1.85139","-0.06022","-0.00027"
"18.59400","1.85320","0.01844","-0.00027"
"18.61200","1.85506","0.08367","-0.00027"
"18.63000","1.85686","0.04111","-0.00027"
"18.64800","1.85859","0.02496","-0.00027"
"18.66600","1.86034","0.06106","-0.00027"
"18.68400","1.86214","0.03522","-0.00027"
"18.70200","1.86394","-0.00905","-0.00027"
"18.72000","1.86577","0.04721","-0.00027"
"18.73800","1.86755","0.14733","-0.00027"
"18.75600","1.86929","0.11218","-0.00027"
"18.77400","1.87106","0.08229","-0.00027"
"18.79200","1.87288","0.05721","-0.00027"
"18.81000","1.87469","0.01895","-0.00027"
"18.82800","1.87650","0.02734","-0.00027"
"18.84600","1.87831","0.04988","-0.00027"
"18.86400","1.88005","0.02234","-0.00027"
"18.88200","1.88176","-0.01426","-0.00027"
"18.90000","1.88354","-0.03544","-0.00027"
"18.91800","1.88540","-0.05683","-0.00027"
"18.93600","1.88727","0.00122","-0.00027"
"18.95400","1.88915","0.07597","-0.00027"
"18.97200","1.89094","0.04094","-0.00027"
"18.99000","1.89268","0.06535","-0.00027"
"19.00800","1.89446","0.08353","-0.00027"
"19.02600","1.89627","0.08145","-0.00027"
"19.04400","1.89809","0.04997","-0.00027"
"19.06200","1.89995","0.03975","-0.00027"
"19.08000","1.90180","0.00735","-0.00027"
"19.09800","1.90358","-0.10904","-0.00027"
"19.11600","1.90532","-0.07324","-0.00027"
"19.13400","1.90713","-0.04126","-0.00027"
"19.15200","1.90898","-0.04829","-0.00027"
"19.17000","1.91084","-0.02360","-0.00027"
"19.18800","1.91267","0.09322","-0.00027"
"19.20600","1.91445","0.02319","-0.00027"
"19.22400","1.91620","0.05571","-0.00027"
"19.24200","1.91798","0.10552","-0.00027"
"19.26000","1.91975","0.11545","-0.00027"
"19.27800","1.92153","0.10777","-0.00027"
"19.29600","1.92336","0.03529","-0.00027"
"19.31400","1.92514","0.00965","-0.00027"
"19.33200","1.92686","0.02799","-0.00027"
"19.35000","1.92860","0.03651","-0.00027"
"19.36800","1.93042","0.00298","-0.00027"
"19.38600","1.93226","-0.00916","-0.00027"
"19.40400","1.93412","0.02413","-0.00027"
"19.42200","1.93594","0.02956","-0.00027"
"19.44000","1.93768","0.01687","-0.00027"
"19.45800","1.93940","0.02290","-0.00027"
"19.47600","1.94118","-0.01722","-0.00027"
"19.49400","1.94299","-0.01859","-0.00027"
"19.51200","1.94484","0.02343","-0.00027"
"19.53000","1.94673","0.01716","-0.00027"
"19.54800","1.94854","0.04547","-0.00027"
"19.56600","1.95027","0.01384","-0.00027"
"19.58400","1.95202","-0.03230","-0.00027"
"19.60200","1.95384","0.00794","-0.00027"
"19.62000","1.95569","0.02334","-0.00027"
"19.63800","1.95755","0.04180","-0.00027"
"19.65600","1.95938","0.02278","-0.00027"
"19.67400","1.96116","-0.03176","-0.00027"
"19.69200","1.96294","-0.03285","-0.00027"
"19.71000","1.96475","0.02797","-0.00027"
"19.72800","1.96658","0.00447","-0.00027"
"19.74600","1.96845","0.00014","-0.00027"
"19.76400","1.97030","0.09054","-0.00027"
"19.78200","1.97204","0.05341","-0.00027"
"19.80000","1.97374","0.01446","-0.00027"
"19.81800","1.97553","-0.04474","-0.00027"
"19.83600","1.97738","0.05477","-0.00027"
"19.85400","1.97922","0.10771","-0.00027"
"19.87200","1.98107","0.08290","-0.00027"
"19.89000","1.98285","0.12174","-0.00027"
"19.90800","1.98456","0.16804","-0.00027"
"19.92600","1.98628","0.10706","-0.00027"
"19.94400","1.98806","0.12890","-0.00027"
"19.96200","1.98988","0.10939","-0.00027"
"19.98000","1.99175","0.04897","-0.00027"
"19.99800","1.99358","0.02854","-0.00027"
"20.01600","1.99531","-0.04830","-0.00027"
"20.03400","1.99700","-0.01567","-0.00027"
"20.05200","1.99878","0.03475","-0.00027"
"20.07000","2.00060","-0.01568","-0.00027"
"20.08800","2.00245","0.05551","-0.00027"
"20.10600","2.00431","-0.00991","-0.00027"
"20.12400","2.00612","-0.07770","-0.00027"
"20.14200","2.00788","-0.03017","-0.00027"
"20.16000","2.00965","-0.02515","-0.00027"
"20.17800","2.01145","0.02785","-0.00027"
"20.19600","2.01328","0.06685","-0.00027"
"20.21400","2.01516","0.05511","-0.00027"
"20.23200","2.01699","-0.03788","-0.00027"
"20.25000","2.01872","-0.01862","-0.00027"
"20.26800","2.02046","-0.00229","-0.00027"
"20.28600","2.02229","-0.01778","-0.00027"
"20.30400","2.02415","0.01697","-0.00027"
"20.32200","2.02602","-0.03192","-0.00027"
"20.34000","2.02789","-0.00323","-0.00028"
"20.35800","2.02968","0.03085","-0.00028"
"20.37600","2.03141","0.03171","-0.00028"
"20.39400","2.03317","0.01510","-0.00027"
"20.41200","2.03496","-0.03202","-0.00027"
"20.43000","2.03679","-0.10183","-0.00027"
"20.44800","2.03864","-0.03333","-0.00027"
"20.46600","2.04040","-0.00928","-0.00027"
"20.48400","2.04212","0.04760","-0.00027"
"20.50200","2.04387","0.04917","-0.00027"
"20.52000","2.04567","-0.00025","-0.00027"
"20.53800","2.04747","-0.06955","-0.00028"
"20.55600","2.04931","-0.01423","-0.00028"
"20.57400","2.05114","-0.00231","-0.00028"
"20.59200","2.05291","0.05555","-0.00028"
"20.61000","2.05466","0.10048","-0.00028"
"20.62800","2.05645","0.09588","-0.00028"
"20.64600","2.05825","0.07821","-0.00027"
"20.66400","2.06008","0.02400","-0.00027"
"20.68200","2.06191","-0.03417","-0.00027"
"20.70000","2.06368","-0.00978","-0.00027"
"20.71800","2.06543","0.09261","-0.00027"
"20.73600","2.06722","0.06850","-0.00027"
"20.75400","2.06904","0.03785","-0.00028"
"20.77200","2.07086","0.08036","-0.00028"
"20.79000","2.07272","0.03847","-0.00028"
"20.80800","2.07455","-0.00130","-0.00028"
"20.82600","2.07632","-0.01341","-0.00028"
"20.84400","2.07809","-0.03180","-0.00028"
"20.86200","2.07988","-0.04402","-0.00028"
"20.88000","2.08170","-0.00403","-0.00028"
"20.89800","2.08356","0.09241","-0.00027"
"20.91600","2.08539","0.10273","-0.00027"
"20.93400","2.08716","-0.00172","-0.00028"
"20.95200","2.08895","-0.10241","-0.00028"
"20.97000","2.09078","-0.05975","-0.00028"
"20.98800","2.09259","0.06098","-0.00028"
"21.00600","2.09441","0.05290","-0.00028"
"21.02400","2.09627","0.05735","-0.00028"
"21.04200","2.09807","0.01169","-0.00028"
"21.06000","2.09980","0.01322","-0.00028"
"21.07800","2.10156","0.04761","-0.00028"
"21.09600","2.10335","0.06460","-0.00028"
"21.11400","2.10515","0.09573","-0.00028"
"21.13200","2.10697","0.04383","-0.00028"
"21.15000","2.10875","-0.00335","-0.00028"
"21.16800","2.11049","0.03044","-0.00028"
"21.18600","2.11227","0.00817","-0.00028"
"21.20400","2.11409","-0.01759","-0.00028"
"21.22200","2.11590","-0.00642","-0.00028"
"21.24000","2.11771","0.03925","-0.00028"
"21.24900","2.11862","0.11256","-0.00028"