File: archive/undergrad/433/Pressure Vessel/Specimen_RawData_4.csv
Time,Extension,Load,Strain Gage18
(s),(mm),(N),(mm/mm)
"0.00000","0.00000","0.03529","0.00001"
"0.02200","0.00001","-0.02025","0.00001"
"0.04400","0.00018","-0.05731","0.00001"
"0.06600","0.00084","0.03609","0.00001"
"0.08800","0.00228","0.01898","0.00001"
"0.11000","0.00342","-0.02632","0.00001"
"0.13200","0.00434","0.01320","0.00001"
"0.15400","0.00615","-0.04507","0.00001"
"0.17600","0.00907","-0.06750","0.00001"
"0.19800","0.01229","-0.08014","0.00001"
"0.22000","0.01519","0.00148","0.00001"
"0.24200","0.01770","0.05893","0.00001"
"0.26400","0.02002","-0.02125","0.00001"
"0.28600","0.02221","0.09382","0.00001"
"0.30800","0.02436","0.07143","0.00001"
"0.33000","0.02661","0.01895","0.00001"
"0.35200","0.02883","-0.02164","0.00001"
"0.37400","0.03109","0.04016","0.00001"
"0.39600","0.03334","0.02354","0.00001"
"0.41800","0.03548","-0.01856","0.00001"
"0.44000","0.03762","-0.06232","0.00001"
"0.46200","0.03981","-0.03838","0.00001"
"0.48400","0.04200","0.03284","0.00001"
"0.50600","0.04421","-0.02097","0.00001"
"0.52800","0.04636","-0.03155","0.00001"
"0.55000","0.04854","0.01830","0.00001"
"0.57200","0.05077","0.02825","0.00001"
"0.59400","0.05298","0.03673","0.00001"
"0.61600","0.05520","0.00077","0.00001"
"0.63800","0.05732","-0.01059","0.00001"
"0.66000","0.05942","0.00869","0.00001"
"0.68200","0.06165","0.01679","0.00001"
"0.70400","0.06395","-0.03087","0.00001"
"0.72600","0.06624","-0.09116","0.00001"
"0.74800","0.06840","-0.04694","0.00001"
"0.77000","0.07053","-0.00638","0.00001"
"0.79200","0.07276","0.07860","0.00001"
"0.81400","0.07499","-0.00747","0.00001"
"0.83600","0.07726","-0.02561","0.00001"
"0.85800","0.07950","-0.02655","0.00001"
"0.88000","0.08164","0.00128","0.00001"
"0.90200","0.08382","0.01723","0.00001"
"0.92400","0.08606","-0.05227","0.00001"
"0.94600","0.08832","0.01208","0.00001"
"0.96800","0.09056","-0.02459","0.00001"
"0.99000","0.09273","-0.05256","0.00001"
"1.01200","0.09490","-0.05167","0.00001"
"1.03400","0.09707","0.00000","0.00001"
"1.05600","0.09927","-0.06767","0.00001"
"1.07800","0.10148","-0.03029","0.00001"
"1.10000","0.10359","0.01740","0.00001"
"1.12200","0.10570","0.03465","0.00001"
"1.14400","0.10794","-0.01173","0.00001"
"1.16600","0.11021","0.01069","0.00001"
"1.18800","0.11247","-0.04783","0.00001"
"1.21000","0.11461","-0.06026","0.00001"
"1.23200","0.11671","0.02429","0.00001"
"1.25400","0.11889","0.05015","0.00001"
"1.27600","0.12112","0.04777","0.00001"
"1.29800","0.12341","0.01741","0.00001"
"1.32000","0.12564","-0.02307","0.00001"
"1.34200","0.12775","-0.05179","0.00001"
"1.36400","0.12993","-0.11047","0.00001"
"1.38600","0.13218","-0.09425","0.00001"
"1.40800","0.13446","-0.05337","0.00001"
"1.43000","0.13667","-0.08241","0.00001"
"1.45200","0.13882","-0.06517","0.00001"
"1.47400","0.14102","-0.03834","0.00001"
"1.49600","0.14325","0.10336","0.00001"
"1.51800","0.14553","0.20708","0.00001"
"1.54000","0.14778","0.05912","0.00001"
"1.56200","0.14989","-0.02086","0.00001"
"1.58400","0.15204","-0.06295","0.00001"
"1.60600","0.15429","0.02112","0.00001"
"1.62800","0.15654","0.05369","0.00001"
"1.65000","0.15877","-0.03708","0.00001"
"1.67200","0.16089","-0.04642","0.00001"
"1.69400","0.16298","-0.04987","0.00001"
"1.71600","0.16515","0.02513","0.00001"
"1.73800","0.16740","-0.01760","0.00001"
"1.76000","0.16967","-0.04975","0.00001"
"1.78200","0.17183","0.00348","0.00001"
"1.80400","0.17390","-0.03522","0.00001"
"1.82600","0.17607","-0.03945","0.00001"
"1.84800","0.17831","-0.03211","0.00001"
"1.87000","0.18056","-0.07224","0.00001"
"1.89200","0.18279","-0.02943","0.00001"
"1.91400","0.18494","0.01089","0.00001"
"1.93600","0.18713","0.05639","0.00001"
"1.95800","0.18934","0.05495","0.00001"
"1.98000","0.19162","0.04821","0.00001"
"2.00200","0.19386","0.06442","0.00001"
"2.02400","0.19598","0.02854","0.00001"
"2.04600","0.19814","-0.05068","0.00001"
"2.06800","0.20039","0.00669","0.00001"
"2.09000","0.20266","0.07337","0.00001"
"2.11200","0.20494","0.03295","0.00001"
"2.13400","0.20710","-0.11927","0.00001"
"2.15600","0.20922","-0.16491","0.00001"
"2.17800","0.21139","-0.06672","0.00001"
"2.20000","0.21364","0.07065","0.00001"
"2.22200","0.21591","0.02148","0.00001"
"2.24400","0.21806","-0.08512","0.00001"
"2.26600","0.22017","-0.02219","0.00001"
"2.28800","0.22235","-0.00308","0.00001"
"2.31000","0.22456","-0.03088","0.00001"
"2.33200","0.22683","-0.01160","0.00001"
"2.35400","0.22904","-0.00638","0.00001"
"2.37600","0.23116","0.04812","0.00001"
"2.39800","0.23333","-0.07309","0.00001"
"2.42000","0.23553","-0.14318","0.00001"
"2.44200","0.23778","-0.07086","0.00001"
"2.46400","0.24000","-0.06925","0.00001"
"2.48600","0.24214","-0.04820","0.00001"
"2.50800","0.24434","-0.10030","0.00001"
"2.53000","0.24656","-0.14035","0.00001"
"2.55200","0.24878","-0.08986","0.00001"
"2.57400","0.25103","-0.02152","0.00001"
"2.59600","0.25320","0.00406","0.00001"
"2.61800","0.25536","-0.04373","0.00001"
"2.64000","0.25756","-0.08054","0.00001"
"2.66200","0.25982","-0.10162","0.00001"
"2.68400","0.26209","-0.07731","0.00001"
"2.70600","0.26426","-0.01790","0.00001"
"2.72800","0.26645","-0.01168","0.00001"
"2.75000","0.26867","-0.01830","0.00001"
"2.77200","0.27087","0.07740","0.00001"
"2.79400","0.27313","0.04371","0.00001"
"2.81600","0.27533","0.02237","0.00001"
"2.83800","0.27745","-0.01668","0.00001"
"2.86000","0.27964","-0.11447","0.00001"
"2.88200","0.28185","0.03571","0.00001"
"2.90400","0.28407","0.03516","0.00001"
"2.92600","0.28623","0.03972","0.00001"
"2.94800","0.28835","0.04108","0.00001"
"2.97000","0.29054","-0.02835","0.00001"
"2.99200","0.29276","-0.09416","0.00001"
"3.01400","0.29498","-0.09594","0.00001"
"3.03600","0.29718","-0.10654","0.00001"
"3.05800","0.29929","-0.07685","0.00001"
"3.08000","0.30145","0.05439","0.00001"
"3.10200","0.30371","-0.02782","0.00001"
"3.12400","0.30600","0.00572","0.00001"
"3.14600","0.30824","0.07504","0.00001"
"3.16800","0.31038","0.03715","0.00001"
"3.19000","0.31256","0.03286","0.00001"
"3.21200","0.31479","-0.05446","0.00001"
"3.23400","0.31702","-0.04286","0.00001"
"3.25600","0.31929","-0.00791","0.00001"
"3.27800","0.32148","-0.07188","0.00001"
"3.30000","0.32362","-0.02687","0.00001"
"3.32200","0.32585","-0.04613","0.00001"
"3.34400","0.32811","-0.08760","0.00001"
"3.36600","0.33036","-0.07235","0.00001"
"3.38800","0.33255","-0.00397","0.00001"
"3.41000","0.33471","0.07712","0.00001"
"3.43200","0.33688","0.03275","0.00001"
"3.45400","0.33904","-0.00366","0.00001"
"3.47600","0.34127","-0.01595","0.00001"
"3.49800","0.34345","-0.15085","0.00001"
"3.52000","0.34554","-0.09344","0.00001"
"3.54200","0.34770","-0.03258","0.00001"
"3.56400","0.34995","0.02628","0.00001"
"3.58600","0.35221","-0.03907","0.00001"
"3.60800","0.35442","-0.06704","0.00001"
"3.63000","0.35654","-0.02415","0.00001"
"3.65200","0.35869","0.02200","0.00001"
"3.67400","0.36091","0.05471","0.00001"
"3.69600","0.36318","0.03335","0.00001"
"3.71800","0.36547","-0.00235","0.00001"
"3.74000","0.36762","-0.05944","0.00001"
"3.76200","0.36973","-0.03307","0.00001"
"3.78400","0.37194","-0.11217","0.00001"
"3.80600","0.37420","0.01007","0.00001"
"3.82800","0.37646","0.00016","0.00001"
"3.85000","0.37865","-0.14869","0.00000"
"3.87200","0.38082","-0.14919","0.00001"
"3.89400","0.38304","-0.01809","0.00001"
"3.91600","0.38529","0.02034","0.00001"
"3.93800","0.38758","0.01819","0.00001"
"3.96000","0.38974","0.00951","0.00001"
"3.98200","0.39180","-0.01658","0.00001"
"4.00400","0.39400","-0.06600","0.00001"
"4.02600","0.39627","-0.01396","0.00000"
"4.04800","0.39853","-0.00598","0.00000"
"4.07000","0.40073","0.01421","0.00000"
"4.09200","0.40283","0.02051","0.00000"
"4.11400","0.40496","-0.04859","0.00000"
"4.13600","0.40716","-0.02488","0.00001"
"4.15800","0.40943","-0.01535","0.00001"
"4.18000","0.41167","0.09820","0.00001"
"4.20200","0.41378","0.08247","0.00001"
"4.22400","0.41588","0.03140","0.00001"
"4.24600","0.41809","-0.04184","0.00000"
"4.26800","0.42034","-0.11273","0.00000"
"4.29000","0.42261","-0.05659","0.00000"
"4.31200","0.42481","-0.00849","0.00000"
"4.33400","0.42695","-0.00695","0.00001"
"4.35600","0.42914","-0.11613","0.00001"
"4.37800","0.43137","-0.09664","0.00001"
"4.40000","0.43366","-0.03024","0.00001"
"4.42200","0.43586","-0.01551","0.00001"
"4.44400","0.43796","0.01474","0.00001"
"4.46600","0.44017","-0.02160","0.00000"
"4.48800","0.44242","0.05124","0.00000"
"4.51000","0.44470","0.03084","0.00000"
"4.53200","0.44696","0.06648","0.00000"
"4.55400","0.44911","0.05642","0.00001"
"4.57600","0.45127","-0.02582","0.00001"
"4.59800","0.45347","-0.02241","0.00001"
"4.62000","0.45573","0.03338","0.00001"
"4.64200","0.45794","0.05923","0.00001"
"4.66400","0.46004","0.12570","0.00001"
"4.68600","0.46217","0.06648","0.00001"
"4.70800","0.46436","-0.03964","0.00000"
"4.73000","0.46658","-0.01949","0.00000"
"4.75200","0.46884","-0.01498","0.00000"
"4.77400","0.47100","0.02848","0.00001"
"4.79600","0.47314","0.01689","0.00001"
"4.81800","0.47532","0.00773","0.00001"
"4.84000","0.47752","-0.01770","0.00001"
"4.86200","0.47977","0.02853","0.00001"
"4.88400","0.48194","0.06215","0.00001"
"4.90600","0.48411","0.03569","0.00001"
"4.92800","0.48633","0.02392","0.00000"
"4.95000","0.48854","-0.07271","0.00000"
"4.97200","0.49079","-0.01094","0.00000"
"4.99400","0.49303","0.00441","0.00001"
"5.01600","0.49521","-0.05277","0.00001"
"5.03800","0.49739","-0.12279","0.00001"
"5.06000","0.49960","-0.04682","0.00001"
"5.08200","0.50187","0.02035","0.00001"
"5.10400","0.50410","0.08422","0.00001"
"5.12600","0.50626","0.03838","0.00001"
"5.14800","0.50848","-0.10296","0.00000"
"5.17000","0.51069","-0.03392","0.00001"
"5.19200","0.51292","-0.00990","0.00001"
"5.21400","0.51517","0.01389","0.00001"
"5.23600","0.51729","-0.03141","0.00001"
"5.25800","0.51942","-0.02748","0.00001"
"5.28000","0.52162","-0.02463","0.00001"
"5.30200","0.52383","0.05719","0.00001"
"5.32400","0.52605","0.00195","0.00001"
"5.34600","0.52819","-0.06514","0.00001"
"5.36800","0.53034","-0.08576","0.00001"
"5.39000","0.53255","-0.06295","0.00001"
"5.41200","0.53475","-0.01119","0.00001"
"5.43400","0.53699","-0.02898","0.00001"
"5.45600","0.53916","-0.05538","0.00001"
"5.47800","0.54127","-0.06874","0.00001"
"5.50000","0.54348","-0.01980","0.00001"
"5.52200","0.54576","-0.11909","0.00001"
"5.54400","0.54805","-0.05506","0.00001"
"5.56600","0.55024","0.01131","0.00001"
"5.58800","0.55236","-0.04042","0.00001"
"5.61000","0.55456","-0.00291","0.00001"
"5.63200","0.55679","-0.05751","0.00001"
"5.65400","0.55905","-0.07828","0.00001"
"5.67600","0.56130","-0.02643","0.00001"
"5.69800","0.56344","-0.04432","0.00001"
"5.72000","0.56560","-0.06210","0.00001"
"5.74200","0.56786","0.05024","0.00001"
"5.76400","0.57012","0.03274","0.00001"
"5.78600","0.57234","0.09437","0.00001"
"5.80800","0.57449","0.10855","0.00001"
"5.83000","0.57665","-0.01641","0.00001"
"5.85200","0.57883","-0.05346","0.00001"
"5.87400","0.58104","0.02281","0.00001"
"5.89600","0.58329","-0.08141","0.00001"
"5.91800","0.58544","-0.01552","0.00001"
"5.94000","0.58755","-0.00660","0.00001"
"5.96200","0.58975","0.03617","0.00001"
"5.98400","0.59199","0.03962","0.00001"
"6.00600","0.59423","-0.00816","0.00001"
"6.02800","0.59637","-0.02406","0.00001"
"6.05000","0.59847","-0.05888","0.00001"
"6.07200","0.60066","-0.12978","0.00001"
"6.09400","0.60290","-0.10150","0.00001"
"6.11600","0.60521","0.01300","0.00001"
"6.13800","0.60746","0.05994","0.00001"
"6.16000","0.60956","0.08615","0.00001"
"6.18200","0.61171","0.07105","0.00001"
"6.20400","0.61395","0.00567","0.00001"
"6.22600","0.61621","-0.03082","0.00001"
"6.24800","0.61844","-0.05218","0.00001"
"6.27000","0.62058","-0.02331","0.00001"
"6.29200","0.62277","-0.02539","0.00001"
"6.31400","0.62501","0.02155","0.00001"
"6.33600","0.62731","-0.02185","0.00001"
"6.35800","0.62960","0.03340","0.00001"
"6.38000","0.63172","-0.02398","0.00001"
"6.40200","0.63383","-0.01772","0.00001"
"6.42400","0.63606","-0.01774","0.00001"
"6.44600","0.63830","0.01729","0.00001"
"6.46800","0.64053","0.04812","0.00000"
"6.49000","0.64268","0.01275","0.00000"
"6.51200","0.64479","-0.05321","0.00001"
"6.53400","0.64696","-0.01895","0.00001"
"6.55600","0.64919","0.01310","0.00001"
"6.57800","0.65145","-0.10750","0.00001"
"6.60000","0.65363","-0.07034","0.00001"
"6.62200","0.65570","0.00082","0.00001"
"6.64400","0.65785","0.02172","0.00001"
"6.66600","0.66007","0.04015","0.00001"
"6.68800","0.66233","0.00641","0.00001"
"6.71000","0.66457","0.09585","0.00001"
"6.73200","0.66672","-0.00707","0.00001"
"6.75400","0.66891","-0.07747","0.00001"
"6.77600","0.67116","-0.05902","0.00001"
"6.79800","0.67347","-0.04070","0.00001"
"6.82000","0.67574","-0.04475","0.00001"
"6.84200","0.67786","0.04763","0.00001"
"6.86400","0.67999","-0.06664","0.00001"
"6.88600","0.68222","0.02075","0.00001"
"6.90800","0.68448","0.04691","0.00000"
"6.93000","0.68674","-0.01331","0.00000"
"6.95200","0.68893","-0.08167","0.00000"
"6.97400","0.69107","-0.02024","0.00001"
"6.99600","0.69325","0.00509","0.00001"
"7.01800","0.69548","0.02410","0.00001"
"7.04000","0.69774","-0.05217","0.00001"
"7.06200","0.69990","-0.02171","0.00001"
"7.08400","0.70200","-0.06343","0.00001"
"7.10600","0.70416","-0.13255","0.00001"
"7.12800","0.70635","-0.11526","0.00000"
"7.15000","0.70860","-0.04345","0.00000"
"7.17200","0.71083","-0.05719","0.00001"
"7.19400","0.71296","-0.01255","0.00001"
"7.21600","0.71514","0.01576","0.00001"
"7.23800","0.71736","-0.01197","0.00001"
"7.26000","0.71960","0.03145","0.00001"
"7.28200","0.72181","0.00624","0.00001"
"7.30400","0.72393","0.01683","0.00001"
"7.32600","0.72612","-0.04773","0.00001"
"7.34800","0.72834","-0.02294","0.00001"
"7.37000","0.73056","-0.02389","0.00000"
"7.39200","0.73282","-0.10266","0.00000"
"7.41400","0.73503","-0.07032","0.00001"
"7.43600","0.73719","0.01098","0.00001"
"7.45800","0.73937","0.04584","0.00001"
"7.48000","0.74159","-0.00690","0.00001"
"7.50200","0.74387","-0.12692","0.00001"
"7.52400","0.74606","-0.17392","0.00001"
"7.54600","0.74824","-0.05682","0.00001"
"7.56800","0.75046","-0.02122","0.00000"
"7.59000","0.75267","0.02926","0.00000"
"7.61200","0.75493","0.10073","0.00000"
"7.63400","0.75713","0.08033","0.00001"
"7.65600","0.75924","0.05465","0.00001"
"7.67800","0.76143","-0.06412","0.00001"
"7.70000","0.76364","-0.01689","0.00001"
"7.72200","0.76586","-0.00168","0.00001"
"7.74400","0.76803","0.01575","0.00001"
"7.76600","0.77016","-0.02106","0.00001"
"7.78800","0.77235","-0.13646","0.00000"
"7.81000","0.77455","-0.05166","0.00000"
"7.83200","0.77677","0.00508","0.00001"
"7.85400","0.77899","-0.06716","0.00001"
"7.87600","0.78110","-0.06774","0.00001"
"7.89800","0.78323","-0.05131","0.00001"
"7.92000","0.78547","-0.05854","0.00001"
"7.94200","0.78778","-0.08903","0.00001"
"7.96400","0.79006","-0.07671","0.00001"
"7.98600","0.79219","-0.05247","0.00001"
"8.00800","0.79433","-0.00379","0.00000"
"8.03000","0.79656","0.04652","0.00000"
"8.05200","0.79878","-0.05747","0.00000"
"8.07400","0.80105","-0.02272","0.00001"
"8.09600","0.80326","0.00923","0.00001"
"8.11800","0.80542","0.01719","0.00001"
"8.14000","0.80765","0.09004","0.00001"
"8.16200","0.80992","-0.00637","0.00001"
"8.18400","0.81218","0.00587","0.00001"
"8.20600","0.81436","-0.00722","0.00000"
"8.22800","0.81649","-0.07126","0.00000"
"8.25000","0.81865","-0.07227","0.00000"
"8.27200","0.82083","-0.06654","0.00000"
"8.29400","0.82306","-0.05830","0.00000"
"8.31600","0.82527","-0.08536","0.00000"
"8.33800","0.82735","-0.09148","0.00001"
"8.36000","0.82949","-0.03846","0.00001"
"8.38200","0.83174","-0.02092","0.00001"
"8.40400","0.83400","0.03917","0.00001"
"8.42600","0.83622","0.05471","0.00000"
"8.44800","0.83831","0.10053","0.00000"
"8.47000","0.84043","0.02391","0.00000"
"8.49200","0.84265","-0.02033","0.00000"
"8.51400","0.84491","-0.03555","0.00000"
"8.53600","0.84723","-0.05689","0.00000"
"8.55800","0.84943","0.03298","0.00000"
"8.58000","0.85156","0.02546","0.00001"
"8.60200","0.85377","0.00717","0.00001"
"8.62400","0.85603","-0.02255","0.00000"
"8.64600","0.85829","0.00121","0.00000"
"8.66800","0.86046","0.01097","0.00000"
"8.69000","0.86259","0.04965","0.00000"
"8.71200","0.86480","0.05270","0.00000"
"8.73400","0.86706","-0.05380","0.00000"
"8.75600","0.86937","-0.07831","0.00000"
"8.77800","0.87158","-0.11156","0.00000"
"8.80000","0.87365","-0.01745","0.00001"
"8.82200","0.87583","-0.04619","0.00000"
"8.84400","0.87808","-0.04957","0.00000"
"8.86600","0.88033","-0.00168","0.00000"
"8.88800","0.88253","-0.01043","0.00000"
"8.91000","0.88463","0.06016","0.00000"
"8.93200","0.88675","0.06924","0.00000"
"8.95400","0.88894","-0.04656","0.00000"
"8.97600","0.89120","-0.10606","0.00000"
"8.99800","0.89347","-0.06823","0.00000"
"9.02000","0.89561","-0.08882","0.00000"
"9.04200","0.89771","-0.04527","0.00000"
"9.06400","0.89990","0.05166","0.00000"
"9.08600","0.90214","0.05104","0.00000"
"9.10800","0.90439","-0.00977","0.00000"
"9.13000","0.90659","-0.11143","0.00000"
"9.15200","0.90872","-0.06423","0.00000"
"9.17400","0.91092","0.07109","0.00000"
"9.19600","0.91316","0.09168","0.00000"
"9.21800","0.91547","0.03914","0.00000"
"9.24000","0.91767","0.04646","0.00000"
"9.26200","0.91976","0.00388","0.00000"
"9.28400","0.92195","-0.01423","0.00000"
"9.30600","0.92422","-0.05998","0.00000"
"9.32800","0.92651","0.01928","0.00000"
"9.35000","0.92876","-0.04395","0.00000"
"9.37200","0.93089","-0.06256","0.00000"
"9.39400","0.93302","-0.12499","0.00000"
"9.41600","0.93522","-0.16808","0.00000"
"9.43800","0.93749","-0.05604","0.00000"
"9.46000","0.93974","0.01691","0.00000"
"9.48200","0.94187","-0.02909","0.00000"
"9.50400","0.94400","-0.03065","0.00000"
"9.52600","0.94618","0.04150","0.00000"
"9.54800","0.94839","0.12804","0.00000"
"9.57000","0.95064","0.06214","0.00000"
"9.59200","0.95280","-0.03844","0.00000"
"9.61400","0.95494","-0.00457","0.00000"
"9.63600","0.95713","0.07034","0.00000"
"9.65800","0.95935","0.02233","0.00000"
"9.68000","0.96160","-0.04805","0.00000"
"9.70200","0.96378","-0.04412","0.00000"
"9.72400","0.96591","-0.04925","0.00000"
"9.74600","0.96811","-0.06957","0.00000"
"9.76800","0.97033","-0.10743","0.00000"
"9.79000","0.97257","-0.10564","0.00000"
"9.81200","0.97482","-0.09147","0.00000"
"9.83400","0.97698","-0.10070","0.00000"
"9.85600","0.97915","0.02046","0.00000"
"9.87800","0.98136","0.07705","0.00000"
"9.90000","0.98364","0.00350","0.00000"
"9.92200","0.98590","-0.01057","0.00000"
"9.94400","0.98807","0.03032","0.00000"
"9.96600","0.99029","-0.01066","0.00000"
"9.98800","0.99250","0.01163","0.00000"
"10.01000","0.99469","-0.03112","0.00000"
"10.03200","0.99694","-0.13356","0.00000"
"10.05400","0.99910","-0.07120","0.00000"
"10.07600","1.00123","-0.01534","0.00000"
"10.09800","1.00343","0.02229","0.00000"
"10.12000","1.00564","-0.00209","0.00000"
"10.14200","1.00786","-0.05831","0.00000"
"10.16400","1.01001","-0.07365","0.00000"
"10.18600","1.01215","-0.02090","0.00000"
"10.20800","1.01436","0.02901","0.00000"
"10.23000","1.01657","0.00409","0.00000"
"10.25200","1.01879","-0.03864","0.00000"
"10.27400","1.02094","-0.10859","0.00000"
"10.29600","1.02303","-0.03886","0.00000"
"10.31800","1.02521","0.00024","0.00000"
"10.34000","1.02750","-0.08623","0.00000"
"10.36200","1.02981","-0.17977","0.00000"
"10.38400","1.03204","-0.11897","0.00000"
"10.40600","1.03417","0.00561","0.00000"
"10.42800","1.03637","-0.03321","0.00000"
"10.45000","1.03860","-0.07099","0.00000"
"10.47200","1.04084","-0.07105","0.00000"
"10.49400","1.04310","-0.05963","0.00000"
"10.51600","1.04527","-0.04472","0.00000"
"10.53800","1.04741","-0.02880","0.00000"
"10.56000","1.04965","-0.05190","0.00001"
"10.58200","1.05191","-0.02264","0.00001"
"10.60400","1.05415","-0.00088","0.00000"
"10.62600","1.05631","-0.01779","0.00000"
"10.64800","1.05846","0.04012","0.00000"
"10.67000","1.06065","-0.00346","0.00000"
"10.69200","1.06284","-0.08075","0.00000"
"10.71400","1.06506","-0.03753","0.00000"
"10.73600","1.06720","-0.05026","0.00000"
"10.75800","1.06929","-0.06772","0.00001"
"10.78000","1.07150","0.00321","0.00001"
"10.80200","1.07377","0.07173","0.00001"
"10.82400","1.07605","0.01525","0.00001"
"10.84600","1.07823","-0.06438","0.00001"
"10.86800","1.08032","-0.04630","0.00000"
"10.89000","1.08248","-0.02760","0.00000"
"10.91200","1.08470","0.01997","0.00000"
"10.93400","1.08699","-0.05165","0.00000"
"10.95600","1.08926","-0.05390","0.00001"
"10.97800","1.09138","0.00696","0.00001"
"11.00000","1.09352","0.07814","0.00001"
"11.02200","1.09576","0.13363","0.00001"
"11.04400","1.09802","0.10552","0.00001"
"11.06600","1.10026","-0.00179","0.00001"
"11.08800","1.10241","-0.02811","0.00000"
"11.11000","1.10458","-0.06321","0.00000"
"11.13200","1.10680","-0.09440","0.00000"
"11.15400","1.10906","0.04712","0.00000"
"11.17600","1.11134","0.10596","0.00001"
"11.19800","1.11349","0.13340","0.00001"
"11.22000","1.11561","0.12571","0.00001"
"11.24200","1.11787","0.00042","0.00001"
"11.26400","1.12015","0.01803","0.00001"
"11.28600","1.12241","0.06007","0.00001"
"11.30800","1.12456","0.04790","0.00000"
"11.33000","1.12663","0.04403","0.00000"
"11.35200","1.12876","0.04857","0.00000"
"11.37400","1.13096","-0.01246","0.00000"
"11.39600","1.13324","-0.15011","0.00001"
"11.41800","1.13547","-0.04204","0.00001"
"11.44000","1.13756","-0.04221","0.00001"
"11.46200","1.13969","-0.03610","0.00001"
"11.48400","1.14190","0.00480","0.00001"
"11.50600","1.14416","0.01359","0.00000"
"11.52800","1.14641","-0.04920","0.00000"
"11.55000","1.14858","-0.04602","0.00000"
"11.57200","1.15074","-0.07166","0.00000"
"11.59400","1.15293","-0.07145","0.00000"
"11.61600","1.15517","0.00117","0.00000"
"11.63800","1.15746","-0.02104","0.00001"
"11.66000","1.15963","-0.02800","0.00001"
"11.68200","1.16177","-0.05429","0.00001"
"11.70400","1.16402","0.03934","0.00001"
"11.72600","1.16630","0.05100","0.00000"
"11.74800","1.16859","0.00524","0.00000"
"11.77000","1.17078","-0.08437","0.00000"
"11.79200","1.17288","-0.05436","0.00000"
"11.81400","1.17504","-0.07740","0.00000"
"11.83600","1.17726","0.03067","0.00000"
"11.85800","1.17952","0.02322","0.00001"
"11.88000","1.18170","-0.05548","0.00001"
"11.90200","1.18380","-0.06198","0.00001"
"11.92400","1.18597","0.04123","0.00001"
"11.94600","1.18815","0.01739","0.00000"
"11.96800","1.19038","-0.01252","0.00000"
"11.99000","1.19261","-0.08304","0.00000"
"12.01200","1.19477","-0.07226","0.00000"
"12.03400","1.19694","-0.00345","0.00000"
"12.05600","1.19912","-0.08702","0.00000"
"12.07800","1.20134","-0.10071","0.00001"
"12.10000","1.20357","-0.08898","0.00001"
"12.12200","1.20573","-0.02122","0.00001"
"12.14400","1.20790","0.00205","0.00001"
"12.16600","1.21013","-0.02833","0.00000"
"12.18800","1.21237","-0.08951","0.00000"
"12.21000","1.21464","-0.05519","0.00000"
"12.23200","1.21682","-0.07566","0.00000"
"12.25400","1.21895","-0.06486","0.00000"
"12.27600","1.22115","-0.00100","0.00000"
"12.29800","1.22340","0.05826","0.00001"
"12.32000","1.22570","0.00346","0.00001"
"12.34200","1.22790","0.03605","0.00001"
"12.36400","1.23007","-0.01323","0.00001"
"12.38600","1.23229","-0.10210","0.00000"
"12.40800","1.23447","-0.03873","0.00000"
"12.43000","1.23669","0.05568","0.00000"
"12.45200","1.23893","-0.04072","0.00000"
"12.47400","1.24106","-0.08869","0.00000"
"12.49600","1.24322","0.01701","0.00000"
"12.51800","1.24542","0.06083","0.00000"
"12.54000","1.24764","0.00461","0.00001"
"12.56200","1.24984","0.07751","0.00001"
"12.58400","1.25197","0.03718","0.00000"
"12.60600","1.25415","-0.02812","0.00000"
"12.62800","1.25638","-0.00947","0.00000"
"12.65000","1.25860","-0.00229","0.00000"
"12.67200","1.26083","-0.04943","0.00000"
"12.69400","1.26294","-0.13815","0.00000"
"12.71600","1.26503","-0.18704","0.00000"
"12.73800","1.26726","-0.00404","0.00000"
"12.76000","1.26954","0.06896","0.00000"
"12.78200","1.27182","0.08743","0.00001"
"12.80400","1.27399","-0.00936","0.00000"
"12.82600","1.27613","-0.04174","0.00000"
"12.84800","1.27836","0.02743","0.00000"
"12.87000","1.28058","0.03292","0.00000"
"12.89200","1.28285","-0.06477","0.00000"
"12.91400","1.28508","-0.14562","0.00000"
"12.93600","1.28722","-0.10610","0.00000"
"12.95800","1.28942","-0.08057","0.00000"
"12.98000","1.29168","-0.08605","0.00000"
"13.00200","1.29393","0.01133","0.00000"
"13.02400","1.29614","0.02181","0.00000"
"13.04600","1.29830","0.08092","0.00000"
"13.06800","1.30048","0.05700","0.00000"
"13.09000","1.30267","0.00124","0.00000"
"13.11200","1.30489","-0.04095","0.00000"
"13.13400","1.30710","-0.10061","0.00000"
"13.15600","1.30918","-0.09000","0.00000"
"13.17800","1.31129","-0.05067","0.00000"
"13.20000","1.31351","-0.05839","0.00000"
"13.22200","1.31578","-0.04740","0.00000"
"13.24400","1.31802","-0.04107","0.00000"
"13.26600","1.32013","-0.07907","0.00000"
"13.28800","1.32226","-0.04758","0.00000"
"13.31000","1.32448","0.02641","0.00000"
"13.33200","1.32676","0.02831","0.00000"
"13.35400","1.32907","-0.00352","0.00000"
"13.37600","1.33125","-0.05652","0.00000"
"13.39800","1.33334","0.00801","0.00000"
"13.42000","1.33552","-0.05909","0.00000"
"13.44200","1.33778","-0.07093","0.00000"
"13.46400","1.34006","0.07768","0.00000"
"13.48600","1.34227","0.08210","0.00000"
"13.50800","1.34441","0.09006","0.00000"
"13.53000","1.34661","-0.00115","0.00000"
"13.55200","1.34885","-0.03593","0.00000"
"13.57400","1.35115","-0.05336","0.00000"
"13.59600","1.35337","-0.05502","0.00000"
"13.61800","1.35544","-0.03270","0.00000"
"13.64000","1.35758","-0.04261","0.00000"
"13.66200","1.35984","-0.00719","0.00000"
"13.68400","1.36211","-0.08694","0.00000"
"13.70600","1.36434","0.01785","0.00000"
"13.72800","1.36646","-0.07194","0.00000"
"13.75000","1.36856","0.05756","0.00000"
"13.77200","1.37074","0.09373","0.00000"
"13.79400","1.37299","-0.00503","0.00000"
"13.81600","1.37526","-0.02788","0.00000"
"13.83800","1.37741","-0.03440","0.00000"
"13.86000","1.37948","0.06120","0.00000"
"13.88200","1.38166","0.10055","0.00000"
"13.90400","1.38391","-0.01108","0.00000"
"13.92600","1.38619","-0.07867","0.00000"
"13.94800","1.38843","-0.13207","0.00000"
"13.97000","1.39058","-0.06063","0.00000"
"13.99200","1.39277","-0.01380","0.00000"
"14.01400","1.39498","-0.03080","0.00000"
"14.03600","1.39725","-0.00120","0.00000"
"14.05800","1.39947","-0.01860","0.00000"
"14.08000","1.40158","-0.01431","0.00000"
"14.10200","1.40377","0.03318","0.00000"
"14.12400","1.40604","0.07136","0.00000"
"14.14600","1.40832","0.08976","0.00000"
"14.16800","1.41060","0.03376","0.00000"
"14.19000","1.41275","-0.10575","0.00000"
"14.21200","1.41487","-0.09706","0.00000"
"14.23400","1.41704","-0.00624","0.00000"
"14.25600","1.41929","-0.03129","0.00000"
"14.27800","1.42155","-0.08338","0.00000"
"14.30000","1.42368","-0.10393","0.00000"
"14.32200","1.42578","0.00436","0.00000"
"14.34400","1.42795","0.06436","0.00000"
"14.36600","1.43015","-0.02114","0.00000"
"14.38800","1.43241","-0.11989","0.00000"
"14.41000","1.43462","-0.05913","0.00000"
"14.43200","1.43676","-0.13244","0.00000"
"14.45400","1.43894","-0.07657","0.00000"
"14.47600","1.44113","0.03204","0.00000"
"14.49800","1.44336","-0.02022","0.00000"
"14.52000","1.44557","-0.01882","0.00000"
"14.54200","1.44771","-0.01493","0.00000"
"14.56400","1.44992","-0.01783","0.00000"
"14.58600","1.45214","0.04384","0.00000"
"14.60800","1.45439","0.01240","0.00000"
"14.63000","1.45665","0.02924","0.00000"
"14.65200","1.45881","0.10611","0.00000"
"14.67400","1.46097","0.04056","0.00000"
"14.69600","1.46317","0.02160","0.00000"
"14.71800","1.46544","0.06642","0.00000"
"14.74000","1.46769","-0.02328","0.00001"
"14.76200","1.46985","-0.05048","0.00001"
"14.78400","1.47206","-0.08736","0.00001"
"14.80600","1.47429","0.01659","0.00000"
"14.82800","1.47650","-0.05432","0.00000"
"14.85000","1.47877","0.01191","0.00000"
"14.87200","1.48094","0.03889","0.00000"
"14.89400","1.48305","0.06119","0.00000"
"14.91600","1.48522","-0.06674","0.00000"
"14.93800","1.48742","-0.09583","0.00000"
"14.96000","1.48964","0.00562","0.00001"
"14.98200","1.49181","0.00851","0.00001"
"15.00400","1.49394","-0.07541","0.00001"
"15.02600","1.49615","-0.06017","0.00001"
"15.04800","1.49835","-0.00333","0.00000"
"15.07000","1.50058","-0.01148","0.00000"
"15.09200","1.50278","-0.00724","0.00000"
"15.11400","1.50487","0.05639","0.00000"
"15.13600","1.50702","-0.01530","0.00000"
"15.15800","1.50929","-0.03079","0.00001"
"15.18000","1.51160","-0.04878","0.00001"
"15.20200","1.51385","-0.01551","0.00001"
"15.22400","1.51599","-0.03589","0.00001"
"15.24600","1.51818","-0.04916","0.00001"
"15.26800","1.52042","-0.09446","0.00000"
"15.29000","1.52267","-0.07923","0.00000"
"15.31200","1.52493","-0.06139","0.00000"
"15.33400","1.52709","-0.07036","0.00001"
"15.35600","1.52921","0.00935","0.00001"
"15.37800","1.53144","0.00302","0.00001"
"15.40000","1.53370","0.02768","0.00001"
"15.42200","1.53595","-0.04659","0.00001"
"15.44400","1.53813","-0.02302","0.00001"
"15.46600","1.54029","0.02741","0.00001"
"15.48800","1.54246","0.02177","0.00001"
"15.51000","1.54464","-0.02404","0.00001"
"15.53200","1.54687","-0.05369","0.00001"
"15.55400","1.54904","-0.01699","0.00001"
"15.57600","1.55111","-0.01557","0.00001"
"15.59800","1.55329","-0.07599","0.00001"
"15.62000","1.55554","-0.05460","0.00001"
"15.64200","1.55781","-0.05341","0.00001"
"15.66400","1.56000","0.00299","0.00001"
"15.68600","1.56210","0.01781","0.00001"
"15.70800","1.56426","-0.02235","0.00001"
"15.73000","1.56649","0.00101","0.00001"
"15.75200","1.56876","-0.00800","0.00001"
"15.77400","1.57104","0.01625","0.00001"
"15.79600","1.57319","0.03297","0.00001"
"15.81800","1.57532","0.02529","0.00001"
"15.84000","1.57755","0.01076","0.00001"
"15.86200","1.57982","0.04054","0.00001"
"15.88400","1.58208","-0.03467","0.00001"
"15.90600","1.58424","-0.03349","0.00001"
"15.92800","1.58639","0.01635","0.00001"
"15.95000","1.58862","0.02238","0.00001"
"15.97200","1.59091","0.05490","0.00001"
"15.99400","1.59322","0.04644","0.00001"
"16.01600","1.59537","0.05276","0.00001"
"16.03800","1.59743","0.03099","0.00001"
"16.06000","1.59963","0.02831","0.00001"
"16.08200","1.60188","-0.06046","0.00001"
"16.10400","1.60413","-0.01505","0.00001"
"16.12600","1.60629","-0.09750","0.00001"
"16.14800","1.60839","-0.08652","0.00001"
"16.17000","1.61054","-0.00165","0.00001"
"16.19200","1.61275","0.05824","0.00001"
"16.21400","1.61500","0.08117","0.00001"
"16.23600","1.61724","0.01372","0.00001"
"16.25800","1.61933","0.13482","0.00001"
"16.28000","1.62144","0.11179","0.00001"
"16.30200","1.62365","0.08030","0.00001"
"16.32400","1.62590","-0.00366","0.00001"
"16.34600","1.62816","-0.02489","0.00001"
"16.36800","1.63033","-0.02202","0.00001"
"16.39000","1.63247","0.01015","0.00001"
"16.41200","1.63467","0.01272","0.00001"
"16.43400","1.63693","-0.04805","0.00001"
"16.45600","1.63923","-0.07740","0.00001"
"16.47800","1.64141","-0.04121","0.00001"
"16.50000","1.64355","0.05012","0.00001"
"16.52200","1.64579","-0.07435","0.00001"
"16.54400","1.64804","-0.14221","0.00001"
"16.56600","1.65031","-0.11836","0.00001"
"16.58800","1.65254","-0.02933","0.00001"
"16.61000","1.65469","0.06764","0.00001"
"16.63200","1.65685","0.05921","0.00001"
"16.65400","1.65907","-0.00611","0.00001"
"16.67600","1.66135","0.01407","0.00001"
"16.69800","1.66355","-0.01183","0.00001"
"16.72000","1.66563","0.01577","0.00001"
"16.74200","1.66776","-0.01664","0.00001"
"16.76400","1.66995","-0.08662","0.00001"
"16.78600","1.67219","-0.03655","0.00001"
"16.80800","1.67443","-0.04129","0.00001"
"16.83000","1.67657","-0.07840","0.00000"
"16.85200","1.67871","-0.02256","0.00000"
"16.87400","1.68091","-0.04622","0.00001"
"16.89600","1.68314","0.03230","0.00001"
"16.91800","1.68540","0.00759","0.00001"
"16.94000","1.68756","0.03859","0.00001"
"16.96200","1.68973","-0.07410","0.00001"
"16.98400","1.69194","-0.15932","0.00001"
"17.00600","1.69414","-0.14818","0.00001"
"17.02800","1.69641","-0.09925","0.00000"
"17.05000","1.69864","-0.04407","0.00000"
"17.07200","1.70080","0.01794","0.00000"
"17.09400","1.70299","0.01734","0.00000"
"17.11600","1.70522","0.04028","0.00001"
"17.13800","1.70750","-0.09325","0.00001"
"17.16000","1.70970","-0.15599","0.00001"
"17.18200","1.71185","-0.08326","0.00001"
"17.20400","1.71407","0.00048","0.00001"
"17.22600","1.71629","0.00477","0.00001"
"17.24800","1.71854","0.01926","0.00001"
"17.27000","1.72078","-0.05752","0.00001"
"17.29200","1.72290","-0.04109","0.00001"
"17.31400","1.72505","-0.00648","0.00001"
"17.33600","1.72725","-0.09279","0.00001"
"17.35800","1.72945","-0.06347","0.00001"
"17.38000","1.73164","-0.03167","0.00001"
"17.40200","1.73377","-0.03469","0.00001"
"17.42400","1.73593","-0.02920","0.00001"
"17.44600","1.73815","-0.08695","0.00001"
"17.46800","1.74036","0.01302","0.00001"
"17.49000","1.74260","0.08745","0.00001"
"17.51200","1.74474","-0.02061","0.00000"
"17.53400","1.74685","-0.00591","0.00000"
"17.55600","1.74907","-0.02840","0.00001"
"17.57800","1.75136","0.00873","0.00001"
"17.60000","1.75365","0.06983","0.00001"
"17.62200","1.75583","0.04445","0.00001"
"17.64400","1.75795","-0.03240","0.00001"
"17.66600","1.76016","-0.11923","0.00001"
"17.68800","1.76239","-0.14423","0.00000"
"17.71000","1.76466","-0.02505","0.00000"
"17.73200","1.76691","0.01483","0.00000"
"17.75400","1.76906","-0.03737","0.00000"
"17.77600","1.77125","-0.11275","0.00000"
"17.79800","1.77350","-0.05830","0.00000"
"17.82000","1.77574","0.03585","0.00001"
"17.84200","1.77795","0.00024","0.00001"
"17.86400","1.78009","-0.04320","0.00001"
"17.88600","1.78226","-0.07844","0.00001"
"17.90800","1.78443","0.01825","0.00000"
"17.93000","1.78664","0.05030","0.00000"
"17.95200","1.78888","0.04913","0.00000"
"17.97400","1.79101","0.03255","0.00000"
"17.99600","1.79311","-0.06760","0.00000"
"18.01800","1.79532","-0.03893","0.00000"
"18.04000","1.79757","-0.01404","0.00000"
"18.06200","1.79981","0.00871","0.00001"
"18.08400","1.80194","-0.02622","0.00001"
"18.10600","1.80405","0.00197","0.00000"
"18.12800","1.80624","-0.06102","0.00000"
"18.15000","1.80849","-0.01115","0.00000"
"18.17200","1.81080","0.03033","0.00000"
"18.19400","1.81302","0.06846","0.00000"
"18.21600","1.81512","0.01550","0.00000"
"18.23800","1.81729","-0.00311","0.00000"
"18.26000","1.81955","-0.04465","0.00000"
"18.28200","1.82182","-0.08534","0.00000"
"18.30400","1.82404","-0.00225","0.00000"
"18.32600","1.82619","0.07580","0.00000"
"18.34800","1.82840","0.02597","0.00000"
"18.37000","1.83065","0.00966","0.00000"
"18.39200","1.83295","-0.03277","0.00000"
"18.41400","1.83520","-0.04114","0.00000"
"18.43600","1.83728","-0.03574","0.00000"
"18.45800","1.83939","-0.10367","0.00000"
"18.48000","1.84164","-0.04315","-0.00001"
"18.50200","1.84390","-0.08150","-0.00001"
"18.52400","1.84612","-0.13980","-0.00001"
"18.54600","1.84825","0.01753","-0.00002"
"18.56800","1.85034","0.02937","-0.00002"
"18.59000","1.85251","0.01165","-0.00003"
"18.61200","1.85474","0.01140","-0.00003"
"18.63400","1.85703","0.07163","-0.00003"
"18.65600","1.85924","0.03914","-0.00003"
"18.67800","1.86134","0.05692","-0.00003"
"18.70000","1.86353","0.11654","-0.00002"
"18.72200","1.86574","0.06148","-0.00002"
"18.74400","1.86799","-0.03009","-0.00003"
"18.76600","1.87020","-0.13049","-0.00003"
"18.78800","1.87234","0.00002","-0.00004"
"18.81000","1.87452","0.08219","-0.00004"
"18.83200","1.87676","0.12894","-0.00004"
"18.85400","1.87905","0.04016","-0.00004"
"18.87600","1.88130","0.07395","-0.00004"
"18.89800","1.88342","0.14547","-0.00004"
"18.92000","1.88557","-0.00421","-0.00004"
"18.94200","1.88781","0.04533","-0.00004"
"18.96400","1.89006","-0.07281","-0.00007"
"18.98600","1.89232","-0.01572","-0.00021"
"19.00800","1.89450","-0.04227","-0.00032"
"19.03000","1.89663","0.04367","-0.00035"
"19.05200","1.89881","-0.14587","-0.00035"
"19.07400","1.90106","0.03267","-0.00034"
"19.09600","1.90334","-0.06540","-0.00034"
"19.11800","1.90551","-0.04401","-0.00033"
"19.14000","1.90761","-0.10769","-0.00032"
"19.16200","1.90978","0.02739","-0.00032"
"19.18400","1.91197","-0.04039","-0.00033"
"19.20600","1.91423","-0.03011","-0.00033"
"19.22800","1.91646","-0.02913","-0.00034"
"19.25000","1.91859","-0.12943","-0.00034"
"19.27200","1.92076","-0.11384","-0.00034"
"19.29400","1.92296","-0.01900","-0.00033"
"19.31600","1.92520","0.00739","-0.00033"
"19.33800","1.92741","-0.03330","-0.00033"
"19.36000","1.92955","-0.00647","-0.00033"
"19.38200","1.93174","-0.05889","-0.00033"
"19.40400","1.93394","-0.00312","-0.00033"
"19.42600","1.93615","0.01322","-0.00033"
"19.44800","1.93842","0.03570","-0.00033"
"19.47000","1.94061","-0.08500","-0.00033"
"19.49200","1.94277","-0.05015","-0.00033"
"19.51400","1.94497","0.02907","-0.00033"
"19.53600","1.94723","-0.05769","-0.00033"
"19.55800","1.94950","-0.08104","-0.00032"
"19.58000","1.95166","-0.03232","-0.00032"
"19.60200","1.95384","-0.04603","-0.00032"
"19.62400","1.95606","-0.01491","-0.00032"
"19.64600","1.95827","-0.01802","-0.00032"
"19.66800","1.96053","-0.00301","-0.00032"
"19.69000","1.96272","-0.03196","-0.00033"
"19.71200","1.96484","0.04161","-0.00033"
"19.73400","1.96702","0.11425","-0.00033"
"19.75600","1.96924","0.05851","-0.00033"
"19.77800","1.97147","-0.02152","-0.00032"
"19.80000","1.97365","-0.00321","-0.00032"
"19.82200","1.97577","0.05804","-0.00032"
"19.84400","1.97796","-0.00395","-0.00032"
"19.86600","1.98017","-0.05425","-0.00032"
"19.88800","1.98238","-0.08903","-0.00033"
"19.91000","1.98458","-0.06996","-0.00033"
"19.93200","1.98668","-0.06952","-0.00033"
"19.95400","1.98883","-0.05153","-0.00033"
"19.97600","1.99109","-0.01400","-0.00033"
"19.99800","1.99338","-0.05076","-0.00033"
"20.02000","1.99564","-0.00643","-0.00033"
"20.04200","1.99778","-0.00269","-0.00033"
"20.06400","1.99995","-0.02813","-0.00033"
"20.08600","2.00218","0.04871","-0.00033"
"20.10800","2.00439","0.01077","-0.00033"
"20.13000","2.00666","0.00652","-0.00033"
"20.15200","2.00886","-0.00137","-0.00033"
"20.17400","2.01100","-0.05043","-0.00033"
"20.19600","2.01324","-0.07993","-0.00033"
"20.21800","2.01551","-0.06823","-0.00033"
"20.24000","2.01778","-0.07044","-0.00033"
"20.26200","2.01996","-0.04704","-0.00033"
"20.28400","2.02211","0.02464","-0.00033"
"20.30600","2.02427","-0.01476","-0.00033"
"20.32800","2.02645","-0.06915","-0.00033"
"20.35000","2.02867","-0.13306","-0.00033"
"20.37200","2.03086","-0.09255","-0.00033"
"20.39400","2.03294","-0.00108","-0.00033"
"20.41600","2.03510","-0.05100","-0.00033"
"20.43800","2.03736","-0.06504","-0.00033"
"20.46000","2.03962","-0.08982","-0.00033"
"20.48200","2.04183","-0.03114","-0.00033"
"20.50400","2.04394","0.02809","-0.00033"
"20.52600","2.04608","0.04923","-0.00033"
"20.54800","2.04828","0.01519","-0.00033"
"20.57000","2.05054","-0.06326","-0.00033"
"20.59200","2.05283","-0.06386","-0.00033"
"20.61400","2.05501","-0.04867","-0.00033"
"20.63600","2.05713","-0.06584","-0.00033"
"20.65800","2.05934","0.00816","-0.00033"
"20.68000","2.06160","0.06095","-0.00033"
"20.70200","2.06386","0.04598","-0.00033"
"20.72400","2.06604","0.04114","-0.00033"
"20.74600","2.06820","-0.02583","-0.00033"
"20.76800","2.07041","-0.04690","-0.00033"
"20.79000","2.07266","-0.05021","-0.00034"
"20.81200","2.07496","0.03220","-0.00034"
"20.83400","2.07715","-0.02399","-0.00034"
"20.85600","2.07923","-0.06320","-0.00034"
"20.87800","2.08143","-0.08132","-0.00034"
"20.90000","2.08369","-0.08607","-0.00033"
"20.92200","2.08594","-0.09448","-0.00033"
"20.94400","2.08813","-0.03495","-0.00033"
"20.96600","2.09022","-0.04876","-0.00033"
"20.98800","2.09235","-0.02022","-0.00034"
"21.01000","2.09454","-0.00518","-0.00034"
"21.03200","2.09681","-0.03298","-0.00034"
"21.05400","2.09907","-0.05615","-0.00034"
"21.07600","2.10119","-0.07115","-0.00034"
"21.09800","2.10330","-0.05581","-0.00034"
"21.12000","2.10549","-0.02896","-0.00033"
"21.14200","2.10772","-0.00781","-0.00033"
"21.16400","2.10996","-0.04689","-0.00033"
"21.18600","2.11214","0.02636","-0.00033"
"21.20800","2.11430","0.00188","-0.00034"
"21.23000","2.11651","0.08763","-0.00034"
"21.25200","2.11875","0.06934","-0.00034"
"21.27400","2.12104","0.02335","-0.00034"
"21.29600","2.12324","-0.04258","-0.00034"
"21.31800","2.12535","0.04115","-0.00034"
"21.34000","2.12758","0.02646","-0.00033"
"21.36200","2.12985","-0.00950","-0.00033"
"21.38400","2.13214","0.01472","-0.00033"
"21.40600","2.13439","0.04636","-0.00033"
"21.42800","2.13653","0.06608","-0.00034"
"21.45000","2.13868","-0.10874","-0.00034"
"21.47200","2.14088","-0.06095","-0.00034"
"21.49400","2.14315","-0.06185","-0.00034"
"21.51600","2.14538","-0.06851","-0.00034"
"21.53800","2.14749","-0.01185","-0.00034"
"21.56000","2.14962","0.00795","-0.00034"
"21.58200","2.15178","0.05566","-0.00034"
"21.60400","2.15396","-0.03689","-0.00034"
"21.62600","2.15619","-0.13541","-0.00034"
"21.64800","2.15837","-0.09786","-0.00034"
"21.67000","2.16051","-0.05241","-0.00034"
"21.69200","2.16269","-0.04747","-0.00034"
"21.71400","2.16490","-0.01600","-0.00034"
"21.73600","2.16715","-0.05318","-0.00034"
"21.75800","2.16935","-0.07356","-0.00034"
"21.78000","2.17151","0.00084","-0.00034"
"21.80200","2.17374","-0.06071","-0.00034"
"21.82400","2.17595","0.00521","-0.00034"
"21.84600","2.17820","-0.00975","-0.00034"
"21.86800","2.18042","-0.03418","-0.00034"
"21.89000","2.18257","-0.05048","-0.00034"
"21.91200","2.18477","0.01134","-0.00034"
"21.93400","2.18701","-0.00003","-0.00034"
"21.95600","2.18929","-0.07904","-0.00034"
"21.97800","2.19152","-0.10031","-0.00034"
"22.00000","2.19368","0.01040","-0.00034"
"22.02200","2.19589","0.02161","-0.00034"
"22.04400","2.19809","0.03246","-0.00034"
"22.06600","2.20030","-0.03953","-0.00034"
"22.08800","2.20255","-0.00305","-0.00034"
"22.11000","2.20470","-0.10332","-0.00034"
"22.13200","2.20683","-0.15468","-0.00034"
"22.15400","2.20903","-0.08334","-0.00034"
"22.17600","2.21124","-0.05351","-0.00034"
"22.19800","2.21345","-0.08890","-0.00034"
"22.22000","2.21558","-0.09740","-0.00034"
"22.24200","2.21771","0.01141","-0.00034"
"22.26400","2.21993","0.07955","-0.00034"
"22.28600","2.22214","0.10307","-0.00034"
"22.30800","2.22438","0.06729","-0.00034"
"22.33000","2.22653","-0.02128","-0.00034"
"22.35200","2.22863","-0.05549","-0.00034"
"22.37400","2.23084","-0.05855","-0.00034"
"22.39600","2.23314","-0.06071","-0.00034"
"22.41800","2.23544","-0.02391","-0.00034"
"22.44000","2.23764","-0.03380","-0.00034"
"22.46200","2.23976","-0.09920","-0.00034"
"22.48400","2.24196","-0.11193","-0.00034"
"22.50600","2.24417","-0.07609","-0.00034"
"22.52800","2.24642","-0.00889","-0.00034"
"22.55000","2.24869","0.00782","-0.00034"
"22.57200","2.25085","0.00279","-0.00034"
"22.59400","2.25301","-0.00215","-0.00034"
"22.61600","2.25527","0.02566","-0.00034"
"22.63800","2.25753","-0.00666","-0.00034"
"22.66000","2.25976","0.06224","-0.00034"
"22.68200","2.26191","-0.00415","-0.00034"
"22.70400","2.26407","-0.06317","-0.00034"
"22.72600","2.26624","-0.10110","-0.00034"
"22.74800","2.26843","-0.07518","-0.00034"
"22.77000","2.27065","-0.04918","-0.00034"
"22.79200","2.27279","-0.03173","-0.00034"
"22.81400","2.27490","-0.01436","-0.00034"
"22.83600","2.27712","-0.03211","-0.00034"
"22.85800","2.27939","-0.10451","-0.00034"
"22.88000","2.28166","-0.08083","-0.00034"
"22.90200","2.28382","-0.09744","-0.00034"
"22.92400","2.28592","-0.03105","-0.00034"
"22.94600","2.28809","-0.03422","-0.00034"
"22.96800","2.29031","-0.07268","-0.00034"
"22.99000","2.29260","-0.12841","-0.00034"
"23.01200","2.29485","-0.05404","-0.00034"
"23.03400","2.29697","-0.05208","-0.00034"
"23.05600","2.29913","-0.10054","-0.00034"
"23.07800","2.30138","-0.10242","-0.00034"
"23.10000","2.30365","-0.08959","-0.00034"
"23.12200","2.30587","-0.06865","-0.00033"
"23.14400","2.30802","-0.05075","-0.00033"
"23.16600","2.31021","-0.06857","-0.00033"
"23.18800","2.31243","-0.03858","-0.00034"
"23.21000","2.31470","0.03196","-0.00034"
"23.23200","2.31698","0.07045","-0.00034"
"23.25400","2.31911","0.03737","-0.00034"
"23.27600","2.32123","-0.09684","-0.00034"
"23.29800","2.32348","-0.05414","-0.00034"
"23.32000","2.32574","-0.00168","-0.00033"
"23.34200","2.32798","-0.02355","-0.00033"
"23.36400","2.33012","0.01885","-0.00033"
"23.38600","2.33221","-0.00679","-0.00033"
"23.40800","2.33437","-0.04405","-0.00033"
"23.43000","2.33658","-0.00899","-0.00034"
"23.45200","2.33885","-0.01841","-0.00034"
"23.47400","2.34104","0.02676","-0.00034"
"23.49600","2.34312","-0.06748","-0.00034"
"23.51800","2.34526","-0.16156","-0.00034"
"23.54000","2.34747","-0.07804","-0.00033"
"23.56200","2.34973","-0.00497","-0.00033"
"23.58400","2.35200","-0.04605","-0.00033"
"23.60600","2.35417","-0.00787","-0.00033"
"23.62800","2.35634","0.01854","-0.00033"
"23.65000","2.35854","-0.01801","-0.00033"
"23.67200","2.36080","-0.04453","-0.00034"
"23.69400","2.36306","-0.07434","-0.00034"
"23.71600","2.36520","-0.11108","-0.00034"
"23.73800","2.36735","-0.18324","-0.00033"
"23.76000","2.36961","-0.05458","-0.00033"
"23.78200","2.37187","-0.03179","-0.00033"
"23.80400","2.37414","0.08664","-0.00033"
"23.82600","2.37633","0.13784","-0.00033"
"23.84800","2.37844","0.01507","-0.00033"
"23.87000","2.38060","0.05761","-0.00033"
"23.89200","2.38283","-0.01200","-0.00034"
"23.91400","2.38511","-0.05110","-0.00034"
"23.93600","2.38729","0.05821","-0.00034"
"23.95800","2.38940","0.04966","-0.00033"
"23.98000","2.39157","-0.00314","-0.00033"
"24.00200","2.39377","-0.02539","-0.00033"
"24.02400","2.39601","-0.00828","-0.00033"
"24.04600","2.39824","-0.00832","-0.00033"
"24.06800","2.40036","0.00701","-0.00033"
"24.09000","2.40252","-0.07499","-0.00033"
"24.11200","2.40472","-0.06041","-0.00034"
"24.13400","2.40697","-0.03426","-0.00034"
"24.15600","2.40921","-0.06179","-0.00033"
"24.17800","2.41137","-0.04776","-0.00033"
"24.20000","2.41356","-0.08617","-0.00033"
"24.22200","2.41578","-0.03821","-0.00033"
"24.24400","2.41800","0.06148","-0.00033"
"24.26600","2.42024","0.06683","-0.00033"
"24.28800","2.42241","0.03029","-0.00033"
"24.31000","2.42454","0.00341","-0.00033"
"24.33200","2.42672","0.00691","-0.00033"
"24.35400","2.42897","0.02014","-0.00033"
"24.37600","2.43127","-0.00369","-0.00033"
"24.39800","2.43346","-0.01874","-0.00033"
"24.42000","2.43563","-0.00598","-0.00033"
"24.44200","2.43786","0.01834","-0.00033"
"24.46400","2.44006","-0.01577","-0.00033"
"24.48600","2.44231","-0.01329","-0.00033"
"24.50800","2.44453","-0.02164","-0.00033"
"24.53000","2.44666","-0.06130","-0.00033"
"24.55200","2.44883","-0.11679","-0.00033"
"24.57400","2.45104","-0.12389","-0.00034"
"24.59600","2.45328","-0.07886","-0.00033"
"24.61800","2.45547","-0.05750","-0.00033"
"24.64000","2.45760","-0.05757","-0.00033"
"24.66200","2.45978","-0.09808","-0.00033"
"24.68400","2.46199","-0.07827","-0.00033"
"24.70600","2.46419","0.00709","-0.00033"
"24.72800","2.46639","-0.02898","-0.00033"
"24.75000","2.46850","-0.07893","-0.00033"
"24.77200","2.47063","0.01684","-0.00034"
"24.79400","2.47288","-0.10985","-0.00034"
"24.81600","2.47518","-0.08002","-0.00034"
"24.83800","2.47745","0.05360","-0.00033"
"24.86000","2.47959","0.00663","-0.00033"
"24.88200","2.48174","-0.10419","-0.00033"
"24.90400","2.48396","-0.09779","-0.00033"
"24.92600","2.48619","-0.04572","-0.00033"
"24.94800","2.48847","-0.16613","-0.00033"
"24.97000","2.49070","-0.05321","-0.00033"
"24.99200","2.49283","-0.01484","-0.00034"
"25.01400","2.49503","-0.07098","-0.00034"
"25.03600","2.49729","-0.09586","-0.00034"
"25.05800","2.49954","-0.14057","-0.00034"
"25.08000","2.50174","-0.18881","-0.00034"
"25.10200","2.50389","-0.10314","-0.00033"
"25.12400","2.50607","0.03722","-0.00033"
"25.14600","2.50825","0.01650","-0.00033"
"25.16800","2.51046","-0.00716","-0.00034"
"25.19000","2.51266","-0.06354","-0.00034"
"25.21200","2.51475","-0.02816","-0.00034"
"25.23400","2.51689","-0.03662","-0.00034"
"25.25600","2.51913","-0.10168","-0.00034"
"25.27800","2.52139","-0.06105","-0.00034"
"25.30000","2.52362","-0.04735","-0.00034"
"25.32200","2.52573","-0.06574","-0.00034"
"25.34400","2.52787","-0.06544","-0.00034"
"25.36600","2.53009","-0.05360","-0.00034"
"25.38800","2.53233","0.00296","-0.00034"
"25.41000","2.53462","-0.09166","-0.00034"
"25.43200","2.53680","-0.09856","-0.00034"
"25.45400","2.53891","-0.04540","-0.00034"
"25.47600","2.54112","-0.11989","-0.00034"
"25.49800","2.54338","-0.03410","-0.00034"
"25.52000","2.54565","0.06786","-0.00034"
"25.54200","2.54785","0.05021","-0.00034"
"25.56400","2.55000","-0.00628","-0.00034"
"25.58600","2.55222","-0.01304","-0.00034"
"25.60800","2.55447","0.05885","-0.00034"
"25.63000","2.55677","0.03959","-0.00034"
"25.65200","2.55897","-0.11555","-0.00034"
"25.67400","2.56105","-0.00933","-0.00034"
"25.69600","2.56322","-0.00641","-0.00034"
"25.71800","2.56548","-0.04273","-0.00034"
"25.74000","2.56773","-0.05237","-0.00034"
"25.76200","2.56994","0.07670","-0.00034"
"25.78400","2.57205","0.09162","-0.00034"
"25.80600","2.57416","-0.01169","-0.00034"
"25.82800","2.57634","-0.03898","-0.00034"
"25.85000","2.57860","-0.02932","-0.00034"
"25.87200","2.58087","0.03150","-0.00034"
"25.89400","2.58300","-0.04185","-0.00034"
"25.91600","2.58508","0.01351","-0.00034"
"25.93800","2.58728","0.02265","-0.00034"
"25.96000","2.58953","-0.00481","-0.00034"
"25.98200","2.59180","-0.04394","-0.00034"
"25.99000","2.59262","-0.04856","-0.00034"