File: archive/undergrad/433/Pressure Vessel/Specimen_RawData_7.csv
Time,Extension,Load,Strain Gage18
(s),(mm),(N),(mm/mm)
"0.00000","0.00000","-0.01011","0.00000"
"0.01600","0.00000","-0.04546","0.00000"
"0.03200","0.00006","0.04253","0.00000"
"0.04800","0.00030","0.07884","0.00000"
"0.06400","0.00087","0.05196","0.00000"
"0.08000","0.00189","-0.00416","0.00000"
"0.09600","0.00299","-0.00744","0.00000"
"0.11200","0.00378","0.04057","0.00000"
"0.12800","0.00451","0.09003","0.00000"
"0.14400","0.00559","0.11326","0.00000"
"0.16000","0.00722","0.09640","0.00000"
"0.17600","0.00931","-0.00311","0.00000"
"0.19200","0.01161","-0.01079","0.00000"
"0.20800","0.01385","0.00558","0.00000"
"0.22400","0.01589","0.01615","0.00000"
"0.24000","0.01770","-0.00171","0.00000"
"0.25600","0.01934","-0.04361","0.00000"
"0.27200","0.02094","-0.06230","0.00000"
"0.28800","0.02254","0.01607","0.00000"
"0.30400","0.02414","-0.03151","0.00000"
"0.32000","0.02575","-0.04649","0.00000"
"0.33600","0.02738","0.00692","0.00000"
"0.35200","0.02896","0.01770","0.00000"
"0.36800","0.03049","-0.04246","0.00000"
"0.38400","0.03206","-0.09298","0.00000"
"0.40000","0.03368","-0.03145","0.00000"
"0.41600","0.03534","-0.02906","0.00000"
"0.43200","0.03700","-0.01997","0.00000"
"0.44800","0.03864","-0.07693","0.00000"
"0.46400","0.04021","-0.07815","0.00000"
"0.48000","0.04176","-0.01720","0.00000"
"0.49600","0.04334","0.06837","0.00000"
"0.51200","0.04497","0.09739","0.00000"
"0.52800","0.04661","0.07798","0.00000"
"0.54400","0.04825","0.05773","0.00000"
"0.56000","0.04991","0.01873","0.00000"
"0.57600","0.05153","0.00235","0.00000"
"0.59200","0.05309","0.04275","0.00000"
"0.60800","0.05465","0.08353","0.00000"
"0.62400","0.05626","0.11929","0.00000"
"0.64000","0.05789","0.11498","0.00000"
"0.65600","0.05953","0.04629","0.00000"
"0.67200","0.06117","0.11015","0.00000"
"0.68800","0.06277","0.18581","0.00000"
"0.70400","0.06434","0.09261","0.00000"
"0.72000","0.06591","0.02428","0.00000"
"0.73600","0.06749","0.03288","0.00000"
"0.75200","0.06907","0.03632","0.00000"
"0.76800","0.07067","0.00671","0.00000"
"0.78400","0.07231","-0.00956","0.00000"
"0.80000","0.07392","-0.00266","0.00000"
"0.81600","0.07546","-0.08230","0.00000"
"0.83200","0.07698","-0.12934","0.00000"
"0.84800","0.07855","-0.10711","0.00000"
"0.86400","0.08017","-0.01654","0.00000"
"0.88000","0.08181","0.03407","0.00000"
"0.89600","0.08345","0.09944","0.00000"
"0.91200","0.08505","0.06773","0.00000"
"0.92800","0.08659","0.07412","0.00000"
"0.94400","0.08811","0.09390","0.00000"
"0.96000","0.08970","0.08451","0.00000"
"0.97600","0.09133","-0.00964","0.00000"
"0.99200","0.09298","-0.01707","0.00000"
"1.00800","0.09465","-0.01932","0.00000"
"1.02400","0.09631","0.03989","0.00000"
"1.04000","0.09789","0.05710","0.00000"
"1.05600","0.09941","0.05769","0.00000"
"1.07200","0.10096","0.02640","0.00000"
"1.08800","0.10257","0.03548","0.00000"
"1.10400","0.10422","0.04887","0.00000"
"1.12000","0.10589","0.01711","0.00000"
"1.13600","0.10754","0.06704","0.00000"
"1.15200","0.10913","0.07703","0.00000"
"1.16800","0.11068","0.03697","0.00000"
"1.18400","0.11224","-0.00886","0.00000"
"1.20000","0.11384","-0.00941","0.00000"
"1.21600","0.11547","0.00655","0.00000"
"1.23200","0.11714","0.00328","0.00000"
"1.24800","0.11881","-0.00858","0.00000"
"1.26400","0.12040","-0.08447","0.00000"
"1.28000","0.12192","-0.19306","0.00000"
"1.29600","0.12345","-0.17623","0.00000"
"1.31200","0.12507","-0.09382","0.00000"
"1.32800","0.12671","-0.02244","0.00000"
"1.34400","0.12835","0.01528","0.00000"
"1.36000","0.12998","0.03035","0.00000"
"1.37600","0.13156","0.00929","0.00000"
"1.39200","0.13310","-0.01002","0.00000"
"1.40800","0.13462","-0.03108","0.00000"
"1.42400","0.13619","0.01495","0.00000"
"1.44000","0.13779","0.00817","0.00000"
"1.45600","0.13941","0.01973","0.00000"
"1.47200","0.14108","-0.01217","0.00000"
"1.48800","0.14270","-0.05694","0.00000"
"1.50400","0.14425","-0.04654","0.00000"
"1.52000","0.14575","0.01389","0.00000"
"1.53600","0.14731","0.03639","0.00000"
"1.55200","0.14891","-0.00483","0.00000"
"1.56800","0.15055","-0.01716","0.00000"
"1.58400","0.15220","0.00833","0.00000"
"1.60000","0.15385","0.05547","0.00000"
"1.61600","0.15545","0.04806","0.00000"
"1.63200","0.15701","0.04374","0.00000"
"1.64800","0.15859","0.00512","0.00000"
"1.66400","0.16019","0.02492","0.00000"
"1.68000","0.16180","0.02169","0.00000"
"1.69600","0.16345","0.00311","0.00000"
"1.71200","0.16510","-0.03818","0.00000"
"1.72800","0.16668","-0.07267","0.00000"
"1.74400","0.16821","-0.05051","0.00000"
"1.76000","0.16978","-0.01902","0.00000"
"1.77600","0.17141","0.05899","0.00000"
"1.79200","0.17305","0.14249","0.00000"
"1.80800","0.17471","0.08137","0.00000"
"1.82400","0.17638","0.01761","0.00000"
"1.84000","0.17801","0.05361","0.00000"
"1.85600","0.17958","0.12487","0.00000"
"1.87200","0.18111","0.06533","0.00000"
"1.88800","0.18267","-0.00093","0.00000"
"1.90400","0.18427","-0.00863","0.00000"
"1.92000","0.18590","-0.00158","0.00000"
"1.93600","0.18756","-0.04248","0.00000"
"1.95200","0.18916","-0.03372","0.00000"
"1.96800","0.19070","-0.00844","0.00000"
"1.98400","0.19223","0.05413","0.00000"
"2.00000","0.19381","0.00502","0.00000"
"2.01600","0.19541","0.04774","0.00000"
"2.03200","0.19701","0.07446","0.00000"
"2.04800","0.19866","-0.04937","0.00000"
"2.06400","0.20028","-0.07748","0.00000"
"2.08000","0.20184","-0.03470","0.00000"
"2.09600","0.20339","-0.03830","0.00000"
"2.11200","0.20497","-0.02073","0.00000"
"2.12800","0.20656","-0.00088","0.00000"
"2.14400","0.20817","-0.01555","0.00000"
"2.16000","0.20980","-0.00857","0.00000"
"2.17600","0.21143","0.05687","0.00000"
"2.19200","0.21301","0.07140","0.00000"
"2.20800","0.21457","0.07321","0.00000"
"2.22400","0.21618","-0.00164","0.00000"
"2.24000","0.21780","0.01421","0.00000"
"2.25600","0.21940","0.06570","0.00000"
"2.27200","0.22102","0.05595","0.00000"
"2.28800","0.22267","0.03835","0.00000"
"2.30400","0.22427","-0.03751","0.00000"
"2.32000","0.22583","-0.02418","0.00000"
"2.33600","0.22740","0.04880","0.00000"
"2.35200","0.22899","0.05068","0.00000"
"2.36800","0.23061","0.06591","0.00000"
"2.38400","0.23227","0.03132","0.00000"
"2.40000","0.23392","-0.02662","0.00000"
"2.41600","0.23552","0.01842","0.00000"
"2.43200","0.23709","0.07307","0.00000"
"2.44800","0.23870","0.08910","0.00000"
"2.46400","0.24033","0.09699","0.00000"
"2.48000","0.24194","0.09861","0.00000"
"2.49600","0.24355","0.12443","0.00000"
"2.51200","0.24520","0.07174","0.00000"
"2.52800","0.24681","0.07502","0.00000"
"2.54400","0.24834","0.06941","0.00000"
"2.56000","0.24987","-0.02558","0.00000"
"2.57600","0.25145","-0.06368","0.00000"
"2.59200","0.25305","0.04090","0.00000"
"2.60800","0.25465","0.09142","0.00000"
"2.62400","0.25627","0.05474","0.00000"
"2.64000","0.25785","0.03696","0.00000"
"2.65600","0.25940","-0.00586","0.00000"
"2.67200","0.26095","-0.00603","0.00000"
"2.68800","0.26255","0.06140","0.00000"
"2.70400","0.26417","0.07769","0.00000"
"2.72000","0.26578","0.03958","0.00000"
"2.73600","0.26740","0.03551","0.00000"
"2.75200","0.26901","0.06270","0.00000"
"2.76800","0.27056","0.10011","0.00000"
"2.78400","0.27209","0.03008","0.00000"
"2.80000","0.27368","-0.00273","0.00000"
"2.81600","0.27533","0.05548","0.00000"
"2.83200","0.27699","0.11732","0.00000"
"2.84800","0.27866","0.06941","0.00000"
"2.86400","0.28029","0.01488","0.00000"
"2.88000","0.28185","0.00616","0.00000"
"2.89600","0.28340","-0.01859","0.00000"
"2.91200","0.28501","-0.01019","0.00000"
"2.92800","0.28664","-0.00726","0.00000"
"2.94400","0.28827","0.02291","0.00000"
"2.96000","0.28990","0.00028","0.00000"
"2.97600","0.29154","-0.03527","0.00000"
"2.99200","0.29313","0.01415","0.00000"
"3.00800","0.29466","0.10413","0.00000"
"3.02400","0.29622","0.09860","0.00000"
"3.04000","0.29785","0.05230","0.00000"
"3.05600","0.29950","-0.02618","0.00000"
"3.07200","0.30116","-0.12404","0.00000"
"3.08800","0.30280","-0.10321","0.00000"
"3.10400","0.30438","-0.05231","0.00000"
"3.12000","0.30593","-0.03807","0.00000"
"3.13600","0.30749","-0.00852","0.00000"
"3.15200","0.30906","0.00889","0.00000"
"3.16800","0.31064","0.10721","0.00000"
"3.18400","0.31225","0.10721","0.00000"
"3.20000","0.31388","0.05219","0.00000"
"3.21600","0.31547","-0.00933","0.00000"
"3.23200","0.31699","-0.02513","0.00000"
"3.24800","0.31852","-0.01821","0.00000"
"3.26400","0.32013","0.05125","0.00000"
"3.28000","0.32177","0.10492","0.00000"
"3.29600","0.32342","0.09772","0.00000"
"3.31200","0.32507","0.09198","0.00000"
"3.32800","0.32665","0.01246","0.00000"
"3.34400","0.32818","0.01059","0.00000"
"3.36000","0.32972","0.00769","0.00000"
"3.37600","0.33131","0.04841","0.00000"
"3.39200","0.33293","0.09290","0.00000"
"3.40800","0.33458","0.07411","0.00000"
"3.42400","0.33625","0.01962","0.00000"
"3.44000","0.33789","0.03767","0.00000"
"3.45600","0.33946","0.00983","0.00000"
"3.47200","0.34098","-0.01603","0.00000"
"3.48800","0.34255","0.04360","0.00000"
"3.50400","0.34418","0.04509","0.00000"
"3.52000","0.34583","0.01420","0.00000"
"3.53600","0.34749","0.06932","0.00000"
"3.55200","0.34912","0.05634","0.00000"
"3.56800","0.35071","0.02102","0.00000"
"3.58400","0.35227","0.03520","0.00000"
"3.60000","0.35387","0.01428","0.00000"
"3.61600","0.35548","0.01845","0.00000"
"3.63200","0.35712","0.02484","0.00000"
"3.64800","0.35879","-0.03639","0.00000"
"3.66400","0.36043","-0.04069","0.00000"
"3.68000","0.36197","0.00592","0.00000"
"3.69600","0.36347","0.04806","0.00000"
"3.71200","0.36503","0.10293","0.00000"
"3.72800","0.36666","0.17684","0.00000"
"3.74400","0.36831","0.10462","0.00000"
"3.76000","0.36994","0.04155","0.00000"
"3.77600","0.37156","0.00423","0.00000"
"3.79200","0.37313","-0.03611","0.00000"
"3.80800","0.37466","-0.00727","0.00000"
"3.82400","0.37621","0.03001","0.00000"
"3.84000","0.37779","0.03460","0.00000"
"3.85600","0.37940","-0.00222","0.00000"
"3.87200","0.38104","-0.00869","0.00000"
"3.88800","0.38269","0.00963","0.00000"
"3.90400","0.38429","0.03591","0.00000"
"3.92000","0.38582","0.05034","0.00000"
"3.93600","0.38733","-0.02968","0.00000"
"3.95200","0.38890","-0.06267","0.00000"
"3.96800","0.39051","-0.06262","0.00000"
"3.98400","0.39215","-0.06058","0.00000"
"4.00000","0.39380","-0.05012","0.00000"
"4.01600","0.39543","0.02219","0.00000"
"4.03200","0.39702","0.02198","0.00000"
"4.04800","0.39858","0.04017","0.00000"
"4.06400","0.40016","0.04935","0.00000"
"4.08000","0.40177","-0.00165","0.00000"
"4.09600","0.40340","-0.02633","0.00000"
"4.11200","0.40507","-0.02968","0.00000"
"4.12800","0.40671","-0.04807","0.00000"
"4.14400","0.40827","-0.05145","0.00000"
"4.16000","0.40980","-0.01639","0.00000"
"4.17600","0.41139","-0.01192","0.00000"
"4.19200","0.41302","-0.02122","0.00000"
"4.20800","0.41466","0.06053","0.00000"
"4.22400","0.41631","0.09610","0.00000"
"4.24000","0.41796","0.05508","0.00000"
"4.25600","0.41957","0.03160","0.00000"
"4.27200","0.42113","0.04642","0.00000"
"4.28800","0.42270","0.06925","0.00000"
"4.30400","0.42429","0.07215","0.00000"
"4.32000","0.42591","0.08105","0.00000"
"4.33600","0.42755","0.07021","0.00000"
"4.35200","0.42919","0.05164","0.00000"
"4.36800","0.43075","0.01039","0.00000"
"4.38400","0.43226","-0.06625","0.00000"
"4.40000","0.43380","-0.10071","0.00000"
"4.41600","0.43538","-0.07100","0.00000"
"4.43200","0.43698","0.03869","0.00000"
"4.44800","0.43859","0.07198","0.00000"
"4.46400","0.44023","0.07734","0.00000"
"4.48000","0.44184","0.07531","0.00000"
"4.49600","0.44340","-0.06939","0.00000"
"4.51200","0.44496","-0.09467","0.00000"
"4.52800","0.44655","-0.06689","0.00000"
"4.54400","0.44815","-0.01454","0.00000"
"4.56000","0.44977","0.00216","0.00000"
"4.57600","0.45141","0.04617","0.00000"
"4.59200","0.45302","0.06876","0.00000"
"4.60800","0.45459","0.11469","0.00000"
"4.62400","0.45615","0.10696","0.00000"
"4.64000","0.45775","0.00736","0.00000"
"4.65600","0.45936","-0.06622","0.00000"
"4.67200","0.46097","-0.04676","0.00000"
"4.68800","0.46262","-0.03508","0.00000"
"4.70400","0.46428","0.07984","0.00000"
"4.72000","0.46587","0.11895","0.00000"
"4.73600","0.46744","0.04634","0.00001"
"4.75200","0.46901","-0.04735","0.00001"
"4.76800","0.47061","-0.01627","0.00001"
"4.78400","0.47224","0.04415","0.00000"
"4.80000","0.47391","0.06988","0.00000"
"4.81600","0.47554","0.05828","0.00000"
"4.83200","0.47711","0.03260","0.00000"
"4.84800","0.47869","0.08629","0.00000"
"4.86400","0.48031","0.08896","0.00000"
"4.88000","0.48193","0.10790","0.00000"
"4.89600","0.48353","0.11996","0.00000"
"4.91200","0.48515","0.03002","0.00000"
"4.92800","0.48680","-0.04901","0.00000"
"4.94400","0.48838","-0.05813","0.00001"
"4.96000","0.48991","-0.00019","0.00001"
"4.97600","0.49146","0.05335","0.00001"
"4.99200","0.49305","0.04585","0.00001"
"5.00800","0.49465","0.01358","0.00001"
"5.02400","0.49626","0.07159","0.00000"
"5.04000","0.49787","0.10388","0.00000"
"5.05600","0.49944","0.11032","0.00000"
"5.07200","0.50098","0.04619","0.00000"
"5.08800","0.50256","0.01019","0.00000"
"5.10400","0.50417","0.04299","0.00000"
"5.12000","0.50579","0.06519","0.00000"
"5.13600","0.50741","0.03786","0.00000"
"5.15200","0.50904","0.00824","0.00001"
"5.16800","0.51062","-0.00613","0.00001"
"5.18400","0.51215","0.02182","0.00001"
"5.20000","0.51369","-0.09116","0.00001"
"5.21600","0.51531","-0.07569","0.00001"
"5.23200","0.51696","-0.05191","0.00001"
"5.24800","0.51862","0.02936","0.00001"
"5.26400","0.52027","0.05278","0.00000"
"5.28000","0.52187","0.03340","0.00000"
"5.29600","0.52342","0.02258","0.00000"
"5.31200","0.52499","0.04347","0.00000"
"5.32800","0.52660","0.10328","0.00000"
"5.34400","0.52822","0.08305","0.00000"
"5.36000","0.52985","0.02621","0.00001"
"5.37600","0.53151","-0.02214","0.00001"
"5.39200","0.53315","-0.01811","0.00001"
"5.40800","0.53473","0.02188","0.00001"
"5.42400","0.53627","0.05808","0.00001"
"5.44000","0.53785","0.07528","0.00001"
"5.45600","0.53949","0.08052","0.00001"
"5.47200","0.54114","0.06978","0.00001"
"5.48800","0.54279","0.11283","0.00001"
"5.50400","0.54441","0.06382","0.00000"
"5.52000","0.54598","-0.04332","0.00000"
"5.53600","0.54753","-0.11975","0.00000"
"5.55200","0.54910","-0.07694","0.00001"
"5.56800","0.55069","0.01972","0.00001"
"5.58400","0.55227","0.08214","0.00001"
"5.60000","0.55389","0.07618","0.00001"
"5.61600","0.55551","0.02672","0.00001"
"5.63200","0.55707","0.03445","0.00001"
"5.64800","0.55859","0.08282","0.00001"
"5.66400","0.56016","0.07840","0.00001"
"5.68000","0.56177","0.02575","0.00001"
"5.69600","0.56341","-0.01288","0.00001"
"5.71200","0.56504","-0.03070","0.00001"
"5.72800","0.56667","-0.12142","0.00001"
"5.74400","0.56823","-0.11433","0.00000"
"5.76000","0.56975","-0.07278","0.00001"
"5.77600","0.57129","-0.02638","0.00001"
"5.79200","0.57289","-0.01662","0.00001"
"5.80800","0.57451","0.01575","0.00001"
"5.82400","0.57617","0.08535","0.00001"
"5.84000","0.57785","0.07442","0.00001"
"5.85600","0.57947","0.08049","0.00001"
"5.87200","0.58101","0.03371","0.00001"
"5.88800","0.58253","0.01434","0.00001"
"5.90400","0.58412","-0.03841","0.00001"
"5.92000","0.58576","-0.08630","0.00001"
"5.93600","0.58741","-0.01570","0.00001"
"5.95200","0.58907","0.04737","0.00001"
"5.96800","0.59067","0.10443","0.00001"
"5.98400","0.59224","0.05125","0.00001"
"6.00000","0.59381","0.03091","0.00001"
"6.01600","0.59544","0.06470","0.00001"
"6.03200","0.59707","0.10438","0.00001"
"6.04800","0.59873","0.08613","0.00001"
"6.06400","0.60041","0.06663","0.00001"
"6.08000","0.60203","0.05425","0.00001"
"6.09600","0.60356","0.00856","0.00001"
"6.11200","0.60506","-0.04829","0.00001"
"6.12800","0.60665","-0.06365","0.00001"
"6.14400","0.60829","-0.02841","0.00001"
"6.16000","0.60994","0.02473","0.00001"
"6.17600","0.61158","0.04458","0.00001"
"6.19200","0.61318","0.03920","0.00001"
"6.20800","0.61472","0.04199","0.00001"
"6.22400","0.61624","-0.06732","0.00001"
"6.24000","0.61778","-0.13412","0.00001"
"6.25600","0.61938","-0.10106","0.00001"
"6.27200","0.62100","-0.02032","0.00001"
"6.28800","0.62266","0.01893","0.00001"
"6.30400","0.62430","0.01555","0.00001"
"6.32000","0.62587","0.00744","0.00001"
"6.33600","0.62737","0.03209","0.00001"
"6.35200","0.62890","0.05454","0.00001"
"6.36800","0.63050","0.08698","0.00001"
"6.38400","0.63213","0.06444","0.00001"
"6.40000","0.63377","0.00304","0.00000"
"6.41600","0.63542","-0.02726","0.00000"
"6.43200","0.63703","0.00619","0.00000"
"6.44800","0.63859","0.06610","0.00001"
"6.46400","0.64016","0.11840","0.00001"
"6.48000","0.64175","0.01929","0.00001"
"6.49600","0.64337","-0.07261","0.00001"
"6.51200","0.64503","-0.07130","0.00001"
"6.52800","0.64671","-0.03843","0.00001"
"6.54400","0.64833","0.05056","0.00001"
"6.56000","0.64986","0.04773","0.00001"
"6.57600","0.65140","-0.00824","0.00001"
"6.59200","0.65300","-0.00726","0.00000"
"6.60800","0.65464","0.01802","0.00000"
"6.62400","0.65629","0.03536","0.00000"
"6.64000","0.65794","-0.06595","0.00000"
"6.65600","0.65958","-0.09002","0.00000"
"6.67200","0.66116","-0.03230","0.00001"
"6.68800","0.66271","0.01976","0.00001"
"6.70400","0.66427","0.07517","0.00001"
"6.72000","0.66587","0.02527","0.00001"
"6.73600","0.66751","-0.02597","0.00001"
"6.75200","0.66917","-0.02681","0.00001"
"6.76800","0.67080","-0.02375","0.00001"
"6.78400","0.67236","-0.02203","0.00001"
"6.80000","0.67389","0.00143","0.00001"
"6.81600","0.67546","0.02760","0.00000"
"6.83200","0.67704","0.00027","0.00000"
"6.84800","0.67863","0.00550","0.00000"
"6.86400","0.68024","0.01349","0.00000"
"6.88000","0.68187","0.00112","0.00000"
"6.89600","0.68345","0.01865","0.00000"
"6.91200","0.68499","0.06988","0.00001"
"6.92800","0.68656","0.02755","0.00001"
"6.94400","0.68815","-0.05014","0.00001"
"6.96000","0.68976","-0.10407","0.00001"
"6.97600","0.69140","-0.04762","0.00001"
"6.99200","0.69304","0.04124","0.00001"
"7.00800","0.69463","0.05429","0.00001"
"7.02400","0.69619","0.06147","0.00000"
"7.04000","0.69777","0.00666","0.00000"
"7.05600","0.69938","-0.02443","0.00000"
"7.07200","0.70097","-0.01680","0.00000"
"7.08800","0.70258","0.00227","0.00000"
"7.10400","0.70422","0.02304","0.00000"
"7.12000","0.70586","0.04579","0.00000"
"7.13600","0.70744","0.07875","0.00001"
"7.15200","0.70901","0.06837","0.00001"
"7.16800","0.71060","0.03724","0.00001"
"7.18400","0.71220","0.00393","0.00001"
"7.20000","0.71384","-0.01173","0.00001"
"7.21600","0.71551","0.03156","0.00001"
"7.23200","0.71713","0.09029","0.00001"
"7.24800","0.71869","0.12527","0.00000"
"7.26400","0.72027","0.09296","0.00000"
"7.28000","0.72189","0.04562","0.00000"
"7.29600","0.72349","0.03590","0.00000"
"7.31200","0.72509","0.00614","0.00000"
"7.32800","0.72674","-0.02666","0.00000"
"7.34400","0.72838","-0.02567","0.00000"
"7.36000","0.72996","-0.02213","0.00000"
"7.37600","0.73151","0.02012","0.00001"
"7.39200","0.73308","0.10940","0.00001"
"7.40800","0.73468","0.06019","0.00001"
"7.42400","0.73628","-0.01472","0.00001"
"7.44000","0.73789","0.00782","0.00001"
"7.45600","0.73948","0.04196","0.00000"
"7.47200","0.74104","0.01700","0.00000"
"7.48800","0.74258","-0.00984","0.00000"
"7.50400","0.74417","0.00376","0.00000"
"7.52000","0.74578","0.04128","0.00000"
"7.53600","0.74739","0.04784","0.00000"
"7.55200","0.74900","0.03206","0.00000"
"7.56800","0.75062","-0.01737","0.00000"
"7.58400","0.75219","-0.04989","0.00001"
"7.60000","0.75371","-0.04628","0.00001"
"7.61600","0.75528","0.02885","0.00001"
"7.63200","0.75691","0.05354","0.00001"
"7.64800","0.75857","-0.03795","0.00001"
"7.66400","0.76023","-0.01236","0.00001"
"7.68000","0.76188","0.03306","0.00000"
"7.69600","0.76345","0.13305","0.00000"
"7.71200","0.76498","0.17439","0.00000"
"7.72800","0.76655","0.08059","0.00000"
"7.74400","0.76817","0.00271","0.00000"
"7.76000","0.76978","-0.02958","0.00000"
"7.77600","0.77141","-0.03202","0.00000"
"7.79200","0.77307","-0.00214","0.00000"
"7.80800","0.77471","0.04153","0.00001"
"7.82400","0.77629","0.08088","0.00001"
"7.84000","0.77785","0.10454","0.00001"
"7.85600","0.77947","0.05974","0.00001"
"7.87200","0.78112","0.06263","0.00001"
"7.88800","0.78277","0.05482","0.00000"
"7.90400","0.78441","-0.00995","0.00000"
"7.92000","0.78601","-0.04686","0.00000"
"7.93600","0.78757","-0.00659","0.00000"
"7.95200","0.78913","-0.03426","0.00000"
"7.96800","0.79070","-0.01733","0.00000"
"7.98400","0.79228","-0.02811","0.00000"
"8.00000","0.79386","-0.03007","0.00000"
"8.01600","0.79549","0.00069","0.00001"
"8.03200","0.79709","0.04627","0.00001"
"8.04800","0.79862","0.09365","0.00001"
"8.06400","0.80015","0.01311","0.00001"
"8.08000","0.80173","0.01748","0.00001"
"8.09600","0.80337","0.06352","0.00001"
"8.11200","0.80502","0.02618","0.00000"
"8.12800","0.80667","-0.00319","0.00000"
"8.14400","0.80828","-0.06008","0.00000"
"8.16000","0.80982","-0.01057","0.00000"
"8.17600","0.81134","0.03043","0.00000"
"8.19200","0.81290","0.04807","0.00000"
"8.20800","0.81450","0.03715","0.00000"
"8.22400","0.81613","0.03328","0.00000"
"8.24000","0.81779","0.05041","0.00000"
"8.25600","0.81946","0.08055","0.00001"
"8.27200","0.82107","0.08941","0.00001"
"8.28800","0.82261","0.06184","0.00001"
"8.30400","0.82416","0.07862","0.00001"
"8.32000","0.82578","0.08980","0.00001"
"8.33600","0.82741","0.09268","0.00001"
"8.35200","0.82906","0.09492","0.00000"
"8.36800","0.83069","0.06020","0.00000"
"8.38400","0.83227","0.02869","0.00000"
"8.40000","0.83383","0.01840","0.00000"
"8.41600","0.83542","0.03152","0.00000"
"8.43200","0.83704","0.03644","0.00000"
"8.44800","0.83868","0.03224","0.00000"
"8.46400","0.84035","0.05454","0.00001"
"8.48000","0.84202","0.03966","0.00001"
"8.49600","0.84361","0.05165","0.00001"
"8.51200","0.84512","0.07774","0.00001"
"8.52800","0.84665","0.10688","0.00001"
"8.54400","0.84826","0.03478","0.00001"
"8.56000","0.84991","-0.03575","0.00001"
"8.57600","0.85155","0.01442","0.00001"
"8.59200","0.85318","0.03937","0.00000"
"8.60800","0.85477","0.13070","0.00000"
"8.62400","0.85630","0.14442","0.00000"
"8.64000","0.85782","0.06562","0.00000"
"8.65600","0.85938","0.02197","0.00000"
"8.67200","0.86097","0.07717","0.00000"
"8.68800","0.86260","0.03752","0.00001"
"8.70400","0.86426","-0.01586","0.00001"
"8.72000","0.86590","0.02314","0.00001"
"8.73600","0.86745","0.12758","0.00001"
"8.75200","0.86897","0.14236","0.00001"
"8.76800","0.87053","0.09475","0.00001"
"8.78400","0.87213","0.00033","0.00001"
"8.80000","0.87376","0.01541","0.00000"
"8.81600","0.87540","0.03085","0.00000"
"8.83200","0.87705","-0.00381","0.00000"
"8.84800","0.87864","-0.00642","0.00000"
"8.86400","0.88019","-0.00553","0.00000"
"8.88000","0.88176","-0.00502","0.00000"
"8.89600","0.88336","0.05845","0.00001"
"8.91200","0.88498","0.05920","0.00001"
"8.92800","0.88664","0.06293","0.00001"
"8.94400","0.88830","-0.03418","0.00001"
"8.96000","0.88989","0.00579","0.00001"
"8.97600","0.89141","0.07233","0.00000"
"8.99200","0.89297","0.04821","0.00000"
"9.00800","0.89460","0.02114","0.00000"
"9.02400","0.89625","0.04395","0.00000"
"9.04000","0.89790","0.06918","0.00000"
"9.05600","0.89957","0.04731","0.00000"
"9.07200","0.90120","0.05940","0.00000"
"9.08800","0.90276","0.15183","0.00000"
"9.10400","0.90430","0.14157","0.00000"
"9.12000","0.90586","0.05383","0.00000"
"9.13600","0.90746","0.03002","0.00001"
"9.15200","0.90910","-0.02740","0.00001"
"9.16800","0.91077","0.00554","0.00001"
"9.18400","0.91238","0.05025","0.00001"
"9.20000","0.91393","0.01560","0.00000"
"9.21600","0.91547","-0.03545","0.00000"
"9.23200","0.91704","-0.04612","0.00000"
"9.24800","0.91862","-0.02812","0.00000"
"9.26400","0.92020","-0.01450","0.00000"
"9.28000","0.92183","0.06596","0.00000"
"9.29600","0.92345","0.06158","0.00000"
"9.31200","0.92502","0.05148","0.00000"
"9.32800","0.92657","0.06734","0.00000"
"9.34400","0.92815","0.07702","0.00001"
"9.36000","0.92976","0.02347","0.00001"
"9.37600","0.93138","-0.03999","0.00001"
"9.39200","0.93302","-0.07801","0.00001"
"9.40800","0.93464","-0.04950","0.00001"
"9.42400","0.93622","-0.00939","0.00000"
"9.44000","0.93778","0.05830","0.00000"
"9.45600","0.93938","0.01706","0.00000"
"9.47200","0.94099","-0.02627","0.00000"
"9.48800","0.94258","-0.04164","0.00000"
"9.50400","0.94419","0.01230","0.00000"
"9.52000","0.94582","0.04593","0.00000"
"9.53600","0.94743","0.10252","0.00000"
"9.55200","0.94900","0.09900","0.00000"
"9.56800","0.95057","0.04318","0.00000"
"9.58400","0.95218","-0.02991","0.00001"
"9.60000","0.95381","-0.03545","0.00001"
"9.61600","0.95548","0.01550","0.00001"
"9.63200","0.95715","0.09631","0.00000"
"9.64800","0.95875","0.11716","0.00000"
"9.66400","0.96032","0.06564","0.00000"
"9.68000","0.96192","-0.00798","0.00000"
"9.69600","0.96354","0.00695","0.00000"
"9.71200","0.96513","0.02879","0.00000"
"9.72800","0.96673","0.10029","0.00001"
"9.74400","0.96837","0.05314","0.00000"
"9.76000","0.96997","-0.02151","0.00000"
"9.77600","0.97152","0.00185","0.00001"
"9.79200","0.97306","0.11237","0.00001"
"9.80800","0.97465","0.14936","0.00001"
"9.82400","0.97626","0.14762","0.00001"
"9.84000","0.97787","0.06259","0.00001"
"9.85600","0.97949","-0.00944","0.00001"
"9.87200","0.98107","-0.08363","0.00001"
"9.88800","0.98261","-0.07659","0.00001"
"9.90400","0.98417","-0.01121","0.00001"
"9.92000","0.98577","-0.01631","0.00000"
"9.93600","0.98739","-0.02080","0.00000"
"9.95200","0.98899","0.07832","0.00000"
"9.96800","0.99061","0.10577","0.00000"
"9.98400","0.99220","0.06288","0.00001"
"10.00000","0.99374","0.06226","0.00001"
"10.01600","0.99526","0.04140","0.00001"
"10.03200","0.99685","-0.00400","0.00001"
"10.04800","0.99851","0.03698","0.00001"
"10.06400","1.00018","0.03646","0.00001"
"10.08000","1.00187","0.09035","0.00001"
"10.09600","1.00349","0.09564","0.00001"
"10.11200","1.00505","0.08375","0.00001"
"10.12800","1.00658","0.14314","0.00001"
"10.14400","1.00817","0.16524","0.00001"
"10.16000","1.00979","0.14546","0.00001"
"10.17600","1.01141","0.08242","0.00001"
"10.19200","1.01305","0.03545","0.00001"
"10.20800","1.01470","-0.03549","0.00001"
"10.22400","1.01631","-0.02988","0.00001"
"10.24000","1.01786","-0.02240","0.00001"
"10.25600","1.01943","-0.00026","0.00001"
"10.27200","1.02106","0.05284","0.00001"
"10.28800","1.02272","0.05706","0.00001"
"10.30400","1.02436","0.04983","0.00001"
"10.32000","1.02599","0.09518","0.00001"
"10.33600","1.02758","0.07644","0.00001"
"10.35200","1.02913","0.03714","0.00000"
"10.36800","1.03069","-0.01179","0.00000"
"10.38400","1.03227","-0.09054","0.00000"
"10.40000","1.03385","-0.04690","0.00000"
"10.41600","1.03546","0.12170","0.00000"
"10.43200","1.03709","0.14493","0.00000"
"10.44800","1.03867","0.11795","0.00001"
"10.46400","1.04019","0.08428","0.00001"
"10.48000","1.04173","0.05661","0.00001"
"10.49600","1.04333","-0.01670","0.00001"
"10.51200","1.04498","0.00736","0.00001"
"10.52800","1.04664","0.01201","0.00001"
"10.54400","1.04828","-0.01750","0.00000"
"10.56000","1.04987","-0.07141","0.00000"
"10.57600","1.05140","0.01318","0.00000"
"10.59200","1.05293","0.13832","0.00000"
"10.60800","1.05451","0.16049","0.00000"
"10.62400","1.05612","0.08373","0.00000"
"10.64000","1.05775","0.05457","0.00000"
"10.65600","1.05943","0.02738","0.00001"
"10.67200","1.06108","0.05154","0.00001"
"10.68800","1.06265","0.03244","0.00001"
"10.70400","1.06418","0.05040","0.00001"
"10.72000","1.06575","0.06236","0.00001"
"10.73600","1.06737","0.04973","0.00001"
"10.75200","1.06901","0.04238","0.00001"
"10.76800","1.07066","0.02122","0.00001"
"10.78400","1.07228","0.04120","0.00001"
"10.80000","1.07385","0.03655","0.00001"
"10.81600","1.07542","-0.05198","0.00000"
"10.83200","1.07703","0.05222","0.00000"
"10.84800","1.07866","0.13824","0.00001"
"10.86400","1.08030","0.15219","0.00001"
"10.88000","1.08198","0.12782","0.00001"
"10.89600","1.08363","0.01616","0.00001"
"10.91200","1.08519","-0.05809","0.00001"
"10.92800","1.08669","-0.02967","0.00001"
"10.94400","1.08827","0.01255","0.00001"
"10.96000","1.08991","0.06675","0.00001"
"10.97600","1.09157","0.08013","0.00001"
"10.99200","1.09321","0.09485","0.00001"
"11.00800","1.09483","0.05665","0.00001"
"11.02400","1.09638","0.13366","0.00001"
"11.04000","1.09789","0.12727","0.00001"
"11.05600","1.09941","0.06354","0.00001"
"11.07200","1.10097","0.06004","0.00001"
"11.08800","1.10257","0.01200","0.00001"
"11.10400","1.10420","0.04273","0.00001"
"11.12000","1.10587","0.05991","0.00001"
"11.13600","1.10748","-0.00592","0.00001"
"11.15200","1.10902","-0.00390","0.00001"
"11.16800","1.11054","0.06192","0.00001"
"11.18400","1.11211","0.04828","0.00001"
"11.20000","1.11371","0.00647","0.00001"
"11.21600","1.11533","0.02269","0.00001"
"11.23200","1.11698","0.04084","0.00001"
"11.24800","1.11861","0.07486","0.00001"
"11.26400","1.12020","0.02355","0.00001"
"11.28000","1.12177","0.02257","0.00001"
"11.29600","1.12337","-0.00860","0.00001"
"11.31200","1.12498","0.03337","0.00001"
"11.32800","1.12662","0.06459","0.00001"
"11.34400","1.12828","0.02645","0.00001"
"11.36000","1.12991","-0.06125","0.00001"
"11.37600","1.13147","-0.12446","0.00001"
"11.39200","1.13299","-0.12853","0.00001"
"11.40800","1.13459","-0.08178","0.00001"
"11.42400","1.13623","0.00506","0.00000"
"11.44000","1.13788","0.07521","0.00000"
"11.45600","1.13954","0.13268","0.00000"
"11.47200","1.14119","0.14763","0.00000"
"11.48800","1.14279","0.06381","-0.00002"
"11.50400","1.14435","0.03510","-0.00005"
"11.52000","1.14590","0.07437","-0.00011"
"11.53600","1.14748","0.05103","-0.00016"
"11.55200","1.14909","0.07941","-0.00021"
"11.56800","1.15074","0.14622","-0.00025"
"11.58400","1.15239","0.11549","-0.00026"
"11.60000","1.15396","0.04467","-0.00026"
"11.61600","1.15548","0.13261","-0.00027"
"11.63200","1.15703","0.15069","-0.00027"
"11.64800","1.15861","0.05514","-0.00028"
"11.66400","1.16020","0.03992","-0.00027"
"11.68000","1.16181","-0.05022","-0.00027"
"11.69600","1.16344","-0.05153","-0.00026"
"11.71200","1.16504","-0.04484","-0.00026"
"11.72800","1.16659","0.01401","-0.00025"
"11.74400","1.16815","0.01263","-0.00025"
"11.76000","1.16974","0.03491","-0.00025"
"11.77600","1.17135","0.07892","-0.00025"
"11.79200","1.17297","0.04115","-0.00025"
"11.80800","1.17462","0.03576","-0.00025"
"11.82400","1.17623","0.08543","-0.00025"
"11.84000","1.17780","0.00842","-0.00026"
"11.85600","1.17938","-0.02994","-0.00026"
"11.87200","1.18099","-0.00049","-0.00026"
"11.88800","1.18260","0.02297","-0.00026"
"11.90400","1.18420","0.04573","-0.00026"
"11.92000","1.18584","0.01620","-0.00026"
"11.93600","1.18747","0.08281","-0.00025"
"11.95200","1.18905","0.10749","-0.00025"
"11.96800","1.19060","0.09523","-0.00025"
"11.98400","1.19218","-0.00010","-0.00025"
"12.00000","1.19378","-0.01632","-0.00025"
"12.01600","1.19542","-0.06328","-0.00025"
"12.03200","1.19709","-0.09775","-0.00025"
"12.04800","1.19873","-0.02070","-0.00026"
"12.06400","1.20031","0.07752","-0.00026"
"12.08000","1.20188","0.10340","-0.00026"
"12.09600","1.20350","0.10130","-0.00026"
"12.11200","1.20511","0.03990","-0.00026"
"12.12800","1.20671","-0.00061","-0.00026"
"12.14400","1.20834","-0.04452","-0.00026"
"12.16000","1.20998","-0.04029","-0.00026"
"12.17600","1.21157","-0.02196","-0.00026"
"12.19200","1.21310","-0.05570","-0.00026"
"12.20800","1.21465","-0.08019","-0.00025"
"12.22400","1.21624","-0.08557","-0.00025"
"12.24000","1.21784","0.00876","-0.00025"
"12.25600","1.21946","0.02106","-0.00025"
"12.27200","1.22107","0.05292","-0.00025"
"12.28800","1.22265","0.04828","-0.00025"
"12.30400","1.22420","0.05193","-0.00025"
"12.32000","1.22578","0.01125","-0.00025"
"12.33600","1.22740","0.00690","-0.00026"
"12.35200","1.22902","-0.02087","-0.00026"
"12.36800","1.23064","-0.03702","-0.00026"
"12.38400","1.23226","-0.10009","-0.00026"
"12.40000","1.23383","-0.10018","-0.00026"
"12.41600","1.23535","-0.00194","-0.00026"
"12.43200","1.23689","0.09582","-0.00025"
"12.44800","1.23849","0.08882","-0.00025"
"12.46400","1.24014","0.14406","-0.00025"
"12.48000","1.24180","0.14859","-0.00025"
"12.49600","1.24346","0.08032","-0.00025"
"12.51200","1.24507","0.00467","-0.00025"
"12.52800","1.24662","-0.00599","-0.00025"
"12.54400","1.24818","-0.06790","-0.00026"
"12.56000","1.24978","-0.00288","-0.00026"
"12.57600","1.25140","0.08925","-0.00026"
"12.59200","1.25302","0.11364","-0.00026"
"12.60800","1.25468","0.10776","-0.00026"
"12.62400","1.25633","0.09522","-0.00026"
"12.64000","1.25791","0.03213","-0.00026"
"12.65600","1.25945","0.00332","-0.00026"
"12.67200","1.26103","0.00884","-0.00025"
"12.68800","1.26267","0.05280","-0.00025"
"12.70400","1.26433","0.09764","-0.00025"
"12.72000","1.26599","0.07501","-0.00025"
"12.73600","1.26763","0.03866","-0.00026"
"12.75200","1.26921","-0.07308","-0.00026"
"12.76800","1.27078","-0.10535","-0.00026"
"12.78400","1.27235","-0.07145","-0.00026"
"12.80000","1.27392","-0.00299","-0.00026"
"12.81600","1.27549","0.03654","-0.00026"
"12.83200","1.27710","0.06743","-0.00026"
"12.84800","1.27871","0.10566","-0.00026"
"12.86400","1.28027","0.05378","-0.00026"
"12.88000","1.28178","0.05738","-0.00026"
"12.89600","1.28333","0.04264","-0.00026"
"12.91200","1.28495","0.05972","-0.00026"
"12.92800","1.28659","0.08890","-0.00025"
"12.94400","1.28824","0.05230","-0.00026"
"12.96000","1.28987","0.06021","-0.00026"
"12.97600","1.29143","0.04696","-0.00026"
"12.99200","1.29295","0.05624","-0.00026"
"13.00800","1.29449","0.07601","-0.00026"
"13.02400","1.29608","0.03250","-0.00026"
"13.04000","1.29771","0.04035","-0.00026"
"13.05600","1.29937","0.04925","-0.00026"
"13.07200","1.30106","0.02710","-0.00026"
"13.08800","1.30269","0.00644","-0.00026"
"13.10400","1.30423","0.06891","-0.00026"
"13.12000","1.30576","0.05517","-0.00026"
"13.13600","1.30735","0.04095","-0.00026"
"13.15200","1.30898","0.09553","-0.00026"
"13.16800","1.31063","0.12980","-0.00026"
"13.18400","1.31228","0.16274","-0.00026"
"13.20000","1.31389","0.13669","-0.00026"
"13.21600","1.31546","0.06055","-0.00026"
"13.23200","1.31705","0.00800","-0.00026"
"13.24800","1.31866","0.00407","-0.00026"
"13.26400","1.32029","0.04578","-0.00026"
"13.28000","1.32194","0.11845","-0.00026"
"13.29600","1.32361","0.09867","-0.00026"
"13.31200","1.32522","0.06148","-0.00026"
"13.32800","1.32674","0.01877","-0.00026"
"13.34400","1.32825","0.03266","-0.00026"
"13.36000","1.32984","0.07409","-0.00026"
"13.37600","1.33148","0.08798","-0.00026"
"13.39200","1.33313","0.05535","-0.00026"
"13.40800","1.33478","0.03076","-0.00026"
"13.42400","1.33640","0.00434","-0.00026"
"13.44000","1.33795","0.00928","-0.00026"
"13.45600","1.33945","0.03709","-0.00026"
"13.47200","1.34098","0.02309","-0.00026"
"13.48800","1.34256","0.03583","-0.00026"
"13.50400","1.34418","-0.00895","-0.00026"
"13.52000","1.34584","-0.05313","-0.00026"
"13.53600","1.34750","-0.06852","-0.00026"
"13.55200","1.34907","-0.04679","-0.00026"
"13.56800","1.35058","-0.00733","-0.00026"
"13.58400","1.35212","0.03499","-0.00026"
"13.60000","1.35371","0.07689","-0.00026"
"13.61600","1.35533","0.07691","-0.00026"
"13.63200","1.35697","0.06825","-0.00026"
"13.64800","1.35861","0.07829","-0.00026"
"13.66400","1.36023","0.02331","-0.00026"
"13.68000","1.36180","0.01692","-0.00026"
"13.69600","1.36336","0.01236","-0.00026"
"13.71200","1.36495","0.02761","-0.00026"
"13.72800","1.36653","0.00636","-0.00026"
"13.74400","1.36814","0.02029","-0.00026"
"13.76000","1.36980","0.04379","-0.00026"
"13.77600","1.37142","0.06205","-0.00026"
"13.79200","1.37297","0.05080","-0.00025"
"13.80800","1.37452","0.02907","-0.00025"
"13.82400","1.37614","0.07955","-0.00026"
"13.84000","1.37780","0.10716","-0.00026"
"13.85600","1.37946","0.05777","-0.00026"
"13.87200","1.38114","0.10890","-0.00026"
"13.88800","1.38279","0.10297","-0.00026"
"13.90400","1.38438","0.03895","-0.00026"
"13.92000","1.38592","0.00662","-0.00026"
"13.93600","1.38747","0.01703","-0.00026"
"13.95200","1.38906","0.06871","-0.00026"
"13.96800","1.39069","0.04986","-0.00026"
"13.98400","1.39236","0.01828","-0.00026"
"14.00000","1.39398","-0.00543","-0.00026"
"14.01600","1.39553","0.09904","-0.00025"
"14.03200","1.39705","0.15529","-0.00026"
"14.04800","1.39862","0.05790","-0.00026"
"14.06400","1.40020","0.06073","-0.00026"
"14.08000","1.40179","0.06105","-0.00026"
"14.09600","1.40340","0.04426","-0.00026"
"14.11200","1.40504","0.05137","-0.00026"
"14.12800","1.40663","0.04887","-0.00026"
"14.14400","1.40819","0.04197","-0.00026"
"14.16000","1.40977","0.02158","-0.00026"
"14.17600","1.41137","-0.00412","-0.00026"
"14.19200","1.41297","0.02624","-0.00026"
"14.20800","1.41460","0.07347","-0.00026"
"14.22400","1.41624","0.05242","-0.00026"
"14.24000","1.41784","0.02022","-0.00025"
"14.25600","1.41940","0.02014","-0.00025"
"14.27200","1.42098","0.00190","-0.00026"
"14.28800","1.42258","-0.04697","-0.00026"
"14.30400","1.42418","0.01946","-0.00026"
"14.32000","1.42579","0.00834","-0.00026"
"14.33600","1.42743","-0.03731","-0.00026"
"14.35200","1.42905","0.03975","-0.00026"
"14.36800","1.43063","0.11587","-0.00026"
"14.38400","1.43219","0.17980","-0.00026"
"14.40000","1.43379","0.06598","-0.00026"
"14.41600","1.43540","-0.01709","-0.00026"
"14.43200","1.43704","-0.08326","-0.00026"
"14.44800","1.43870","-0.06445","-0.00025"
"14.46400","1.44030","0.01262","-0.00025"
"14.48000","1.44188","0.02558","-0.00025"
"14.49600","1.44348","0.00814","-0.00026"
"14.51200","1.44511","0.00179","-0.00026"
"14.52800","1.44672","-0.03141","-0.00026"
"14.54400","1.44832","-0.01854","-0.00026"
"14.56000","1.44997","0.05153","-0.00026"
"14.57600","1.45161","0.08113","-0.00026"
"14.59200","1.45318","0.08156","-0.00026"
"14.60800","1.45470","0.04812","-0.00026"
"14.62400","1.45626","0.12342","-0.00026"
"14.64000","1.45785","0.10971","-0.00026"
"14.65600","1.45946","0.03418","-0.00025"
"14.67200","1.46108","0.04225","-0.00025"
"14.68800","1.46268","0.01304","-0.00025"
"14.70400","1.46425","-0.01802","-0.00025"
"14.72000","1.46580","0.02105","-0.00026"
"14.73600","1.46740","0.06733","-0.00026"
"14.75200","1.46903","0.07985","-0.00026"
"14.76800","1.47065","0.06300","-0.00026"
"14.78400","1.47227","0.02485","-0.00026"
"14.80000","1.47387","-0.04283","-0.00026"
"14.81600","1.47542","-0.00159","-0.00026"
"14.83200","1.47693","0.04309","-0.00026"
"14.84800","1.47848","0.00973","-0.00026"
"14.86400","1.48011","0.01699","-0.00026"
"14.88000","1.48175","-0.00564","-0.00025"
"14.89600","1.48340","0.04530","-0.00025"
"14.91200","1.48504","0.00143","-0.00025"
"14.92800","1.48662","-0.00012","-0.00025"
"14.94400","1.48818","0.06601","-0.00026"
"14.96000","1.48978","0.06868","-0.00026"
"14.97600","1.49141","0.06030","-0.00026"
"14.99200","1.49303","0.08754","-0.00026"
"15.00800","1.49466","0.09024","-0.00026"
"15.02400","1.49632","0.07082","-0.00026"
"15.04000","1.49794","0.00252","-0.00026"
"15.05600","1.49950","0.01417","-0.00026"
"15.07200","1.50104","-0.00565","-0.00026"
"15.08800","1.50265","-0.02756","-0.00026"
"15.10400","1.50430","0.00262","-0.00026"
"15.12000","1.50596","0.04643","-0.00025"
"15.13600","1.50761","0.03491","-0.00025"
"15.15200","1.50921","0.02087","-0.00025"
"15.16800","1.51077","-0.03330","-0.00025"
"15.18400","1.51233","-0.04798","-0.00026"
"15.20000","1.51391","-0.01818","-0.00026"
"15.21600","1.51550","-0.00014","-0.00026"
"15.23200","1.51710","0.07590","-0.00026"
"15.24800","1.51873","0.13751","-0.00026"
"15.26400","1.52033","0.11385","-0.00026"
"15.28000","1.52187","0.04047","-0.00026"
"15.29600","1.52340","0.05373","-0.00026"
"15.31200","1.52497","0.09721","-0.00026"
"15.32800","1.52658","0.09164","-0.00025"
"15.34400","1.52819","0.04810","-0.00025"
"15.36000","1.52982","0.06958","-0.00025"
"15.37600","1.53143","0.08404","-0.00026"
"15.39200","1.53297","0.06298","-0.00026"
"15.40800","1.53450","0.07479","-0.00026"
"15.42400","1.53607","0.09784","-0.00026"
"15.44000","1.53769","0.12917","-0.00026"
"15.45600","1.53934","0.12054","-0.00026"
"15.47200","1.54102","0.10622","-0.00026"
"15.48800","1.54270","0.07717","-0.00026"
"15.50400","1.54429","0.02301","-0.00026"
"15.52000","1.54581","0.02886","-0.00026"
"15.53600","1.54735","-0.01318","-0.00025"
"15.55200","1.54896","0.00754","-0.00025"
"15.56800","1.55060","0.07375","-0.00025"
"15.58400","1.55225","0.04148","-0.00025"
"15.60000","1.55388","0.02617","-0.00026"
"15.61600","1.55547","0.00219","-0.00026"
"15.63200","1.55703","0.01719","-0.00026"
"15.64800","1.55863","-0.03541","-0.00026"
"15.66400","1.56026","-0.05479","-0.00026"
"15.68000","1.56188","0.00971","-0.00026"
"15.69600","1.56354","0.04940","-0.00026"
"15.71200","1.56521","0.00483","-0.00026"
"15.72800","1.56681","0.00013","-0.00026"
"15.74400","1.56834","0.00237","-0.00026"
"15.76000","1.56987","-0.04814","-0.00026"
"15.77600","1.57148","-0.06462","-0.00026"
"15.79200","1.57311","0.03060","-0.00026"
"15.80800","1.57475","0.11507","-0.00026"
"15.82400","1.57639","0.07062","-0.00026"
"15.84000","1.57799","0.06119","-0.00026"
"15.85600","1.57952","0.03604","-0.00026"
"15.87200","1.58104","0.05242","-0.00026"
"15.88800","1.58259","0.01635","-0.00026"
"15.90400","1.58419","0.01735","-0.00026"
"15.92000","1.58583","0.02086","-0.00026"
"15.93600","1.58749","-0.03053","-0.00026"
"15.95200","1.58911","-0.05443","-0.00026"
"15.96800","1.59063","-0.04046","-0.00026"
"15.98400","1.59212","-0.04869","-0.00026"
"16.00000","1.59368","-0.04085","-0.00025"
"16.01600","1.59529","0.03533","-0.00026"
"16.03200","1.59693","0.09103","-0.00026"
"16.04800","1.59858","0.06871","-0.00026"
"16.06400","1.60023","0.03944","-0.00026"
"16.08000","1.60184","0.01521","-0.00026"
"16.09600","1.60341","0.03883","-0.00026"
"16.11200","1.60499","0.08745","-0.00026"
"16.12800","1.60657","0.10864","-0.00026"
"16.14400","1.60818","0.07210","-0.00026"
"16.16000","1.60982","0.03566","-0.00026"
"16.17600","1.61148","0.07055","-0.00026"
"16.19200","1.61307","0.06453","-0.00026"
"16.20800","1.61461","0.09724","-0.00026"
"16.22400","1.61617","0.08528","-0.00026"
"16.24000","1.61779","0.04861","-0.00026"
"16.25600","1.61943","0.05171","-0.00026"
"16.27200","1.62108","0.01822","-0.00026"
"16.28800","1.62275","-0.03662","-0.00026"
"16.30400","1.62438","-0.02962","-0.00026"
"16.32000","1.62595","-0.00997","-0.00026"
"16.33600","1.62751","0.02919","-0.00026"
"16.35200","1.62909","-0.01704","-0.00026"
"16.36800","1.63071","-0.02758","-0.00026"
"16.38400","1.63236","0.06316","-0.00026"
"16.40000","1.63401","0.05597","-0.00026"
"16.41600","1.63560","0.00593","-0.00026"
"16.43200","1.63713","0.04291","-0.00026"
"16.44800","1.63865","0.05504","-0.00025"
"16.46400","1.64022","0.08110","-0.00026"
"16.48000","1.64179","0.12252","-0.00026"
"16.49600","1.64337","0.07369","-0.00026"
"16.51200","1.64499","0.05704","-0.00026"
"16.52800","1.64661","0.03496","-0.00026"
"16.54400","1.64818","-0.04149","-0.00026"
"16.56000","1.64973","-0.03935","-0.00026"
"16.57600","1.65133","-0.02128","-0.00026"
"16.59200","1.65294","-0.07092","-0.00026"
"16.60800","1.65456","0.01532","-0.00026"
"16.62400","1.65621","0.04483","-0.00026"
"16.64000","1.65783","0.11702","-0.00026"
"16.65600","1.65941","0.10524","-0.00026"
"16.67200","1.66096","0.06614","-0.00026"
"16.68800","1.66255","0.05942","-0.00026"
"16.70400","1.66415","0.05813","-0.00026"
"16.72000","1.66576","0.11245","-0.00026"
"16.73600","1.66739","0.12829","-0.00026"
"16.75200","1.66904","0.04477","-0.00026"
"16.76800","1.67066","0.08491","-0.00026"
"16.78400","1.67223","0.12067","-0.00026"
"16.80000","1.67381","0.12923","-0.00026"
"16.81600","1.67540","0.08632","-0.00026"
"16.83200","1.67703","0.06425","-0.00026"
"16.84800","1.67868","0.03065","-0.00026"
"16.86400","1.68034","-0.06985","-0.00026"
"16.88000","1.68194","-0.06097","-0.00026"
"16.89600","1.68350","0.00230","-0.00026"
"16.91200","1.68510","0.04183","-0.00026"
"16.92800","1.68672","0.08084","-0.00026"
"16.94400","1.68832","0.04229","-0.00026"
"16.96000","1.68993","0.03704","-0.00026"
"16.97600","1.69158","0.02101","-0.00026"
"16.99200","1.69318","0.04476","-0.00026"
"17.00800","1.69472","0.07523","-0.00026"
"17.02400","1.69627","0.06582","-0.00026"
"17.04000","1.69786","0.06221","-0.00026"
"17.05600","1.69948","0.10097","-0.00026"
"17.07200","1.70110","0.10663","-0.00026"
"17.08800","1.70272","0.00848","-0.00026"
"17.10400","1.70429","0.00267","-0.00026"
"17.12000","1.70582","0.07368","-0.00026"
"17.13600","1.70737","0.13216","-0.00026"
"17.15200","1.70896","0.05160","-0.00026"
"17.16800","1.71057","0.05821","-0.00026"
"17.18400","1.71219","0.08385","-0.00026"
"17.20000","1.71382","0.05756","-0.00026"
"17.21600","1.71543","0.02195","-0.00026"
"17.23200","1.71698","0.01475","-0.00026"
"17.24800","1.71851","-0.00584","-0.00026"
"17.26400","1.72009","0.04748","-0.00026"
"17.28000","1.72173","0.03481","-0.00026"
"17.29600","1.72338","0.04944","-0.00026"
"17.31200","1.72505","0.05997","-0.00026"
"17.32800","1.72667","0.02607","-0.00026"
"17.34400","1.72823","0.08469","-0.00026"
"17.36000","1.72978","0.09564","-0.00026"
"17.37600","1.73138","0.10913","-0.00026"
"17.39200","1.73300","0.06963","-0.00026"
"17.40800","1.73461","0.09598","-0.00026"
"17.42400","1.73625","0.06120","-0.00026"
"17.44000","1.73791","0.03821","-0.00026"
"17.45600","1.73952","0.09911","-0.00026"
"17.47200","1.74108","0.08515","-0.00026"
"17.48800","1.74266","0.08498","-0.00026"
"17.50400","1.74428","0.03587","-0.00026"
"17.52000","1.74593","-0.00207","-0.00026"
"17.53600","1.74757","0.03622","-0.00026"
"17.55200","1.74919","0.03141","-0.00026"
"17.56800","1.75077","-0.03794","-0.00026"
"17.58400","1.75232","0.01312","-0.00026"
"17.60000","1.75388","0.09274","-0.00026"
"17.61600","1.75546","0.02281","-0.00026"
"17.63200","1.75706","0.02348","-0.00026"
"17.64800","1.75868","0.05087","-0.00026"
"17.66400","1.76033","0.10629","-0.00026"
"17.68000","1.76191","0.03209","-0.00026"
"17.69600","1.76343","0.01817","-0.00026"
"17.71200","1.76496","0.03373","-0.00026"
"17.72800","1.76656","0.08372","-0.00026"
"17.74400","1.76819","0.16310","-0.00026"
"17.76000","1.76983","0.09897","-0.00026"
"17.77600","1.77145","0.07923","-0.00026"
"17.79200","1.77303","0.02645","-0.00026"
"17.80800","1.77456","0.01513","-0.00026"
"17.82400","1.77610","0.04119","-0.00026"
"17.84000","1.77769","0.08217","-0.00026"
"17.85600","1.77931","0.13527","-0.00026"
"17.87200","1.78095","0.07695","-0.00026"
"17.88800","1.78263","0.05792","-0.00026"
"17.90400","1.78430","0.04902","-0.00026"
"17.92000","1.78588","0.10318","-0.00026"
"17.93600","1.78741","0.09686","-0.00026"
"17.95200","1.78898","0.04934","-0.00026"
"17.96800","1.79059","0.08984","-0.00026"
"17.98400","1.79222","0.06734","-0.00026"
"18.00000","1.79386","-0.02225","-0.00026"
"18.01600","1.79548","-0.00296","-0.00026"
"18.03200","1.79704","0.11611","-0.00026"
"18.04800","1.79860","0.10546","-0.00026"
"18.06400","1.80021","0.04483","-0.00026"
"18.08000","1.80183","0.02994","-0.00026"
"18.09600","1.80348","0.08755","-0.00027"
"18.11200","1.80516","0.08288","-0.00026"
"18.12800","1.80682","0.01861","-0.00026"
"18.14400","1.80839","0.04076","-0.00026"
"18.16000","1.80990","0.09730","-0.00026"
"18.17600","1.81147","0.08239","-0.00026"
"18.19200","1.81310","0.06131","-0.00026"
"18.20800","1.81474","0.00537","-0.00026"
"18.22400","1.81637","-0.02753","-0.00026"
"18.24000","1.81799","0.10532","-0.00026"
"18.25600","1.81956","0.14545","-0.00026"
"18.27200","1.82108","0.06594","-0.00026"
"18.28800","1.82262","0.05707","-0.00026"
"18.30400","1.82419","0.15425","-0.00027"
"18.32000","1.82579","0.12477","-0.00027"
"18.33600","1.82743","0.15098","-0.00027"
"18.35200","1.82909","0.08353","-0.00027"
"18.36800","1.83068","0.10038","-0.00026"
"18.38400","1.83221","0.09311","-0.00026"
"18.40000","1.83372","0.06543","-0.00026"
"18.41600","1.83530","0.10043","-0.00026"
"18.43200","1.83692","0.08212","-0.00026"
"18.44800","1.83855","0.00865","-0.00026"
"18.46400","1.84020","-0.01902","-0.00026"
"18.48000","1.84183","-0.00267","-0.00026"
"18.49600","1.84342","0.06160","-0.00026"
"18.51200","1.84498","0.03240","-0.00026"
"18.52800","1.84657","0.08757","-0.00027"
"18.54400","1.84818","0.09808","-0.00027"
"18.56000","1.84981","0.09420","-0.00027"
"18.57600","1.85148","0.03396","-0.00026"
"18.59200","1.85312","0.01743","-0.00026"
"18.60800","1.85469","0.15153","-0.00026"
"18.62400","1.85621","0.18446","-0.00026"
"18.64000","1.85780","0.17010","-0.00026"
"18.65600","1.85943","0.11655","-0.00026"
"18.67200","1.86108","0.07342","-0.00026"
"18.68800","1.86274","0.11625","-0.00026"
"18.70400","1.86439","0.11783","-0.00026"
"18.72000","1.86599","0.06952","-0.00026"
"18.73600","1.86752","0.01459","-0.00026"
"18.75200","1.86906","0.01418","-0.00026"
"18.76800","1.87064","0.00456","-0.00026"
"18.78400","1.87226","0.01980","-0.00026"
"18.80000","1.87392","0.04300","-0.00026"
"18.81600","1.87557","0.05366","-0.00026"
"18.83200","1.87716","0.08774","-0.00026"
"18.84800","1.87869","0.14090","-0.00026"
"18.86400","1.88024","0.06674","-0.00026"
"18.88000","1.88182","0.03764","-0.00026"
"18.89600","1.88341","0.07414","-0.00026"
"18.91200","1.88502","0.08660","-0.00026"
"18.92800","1.88665","0.08894","-0.00026"
"18.94400","1.88826","-0.00562","-0.00026"
"18.96000","1.88981","-0.02776","-0.00026"
"18.97600","1.89137","-0.01148","-0.00026"
"18.99200","1.89297","-0.02044","-0.00026"
"19.00800","1.89458","-0.03555","-0.00026"
"19.02400","1.89621","-0.03082","-0.00026"
"19.04000","1.89785","0.00655","-0.00026"
"19.05600","1.89945","0.11075","-0.00026"
"19.07200","1.90100","0.21802","-0.00026"
"19.08800","1.90256","0.13434","-0.00026"
"19.10400","1.90416","0.01653","-0.00026"
"19.12000","1.90577","-0.07243","-0.00026"
"19.13600","1.90737","0.00634","-0.00026"
"19.15200","1.90901","0.05470","-0.00026"
"19.16800","1.91065","0.10793","-0.00026"
"19.18400","1.91224","0.06985","-0.00026"
"19.20000","1.91381","0.05638","-0.00026"
"19.21600","1.91539","0.05445","-0.00026"
"19.23200","1.91699","0.09703","-0.00026"
"19.24800","1.91862","0.07544","-0.00026"
"19.26400","1.92029","0.09505","-0.00026"
"19.28000","1.92192","0.09346","-0.00026"
"19.29600","1.92350","0.11879","-0.00026"
"19.31200","1.92506","0.11178","-0.00026"
"19.32800","1.92667","0.10045","-0.00026"
"19.34400","1.92829","0.04043","-0.00026"
"19.36000","1.92990","0.02640","-0.00026"
"19.37600","1.93153","0.05338","-0.00026"
"19.39200","1.93318","0.00472","-0.00026"
"19.40800","1.93477","0.03893","-0.00026"
"19.42000","1.93592","0.10507","-0.00026"