File: archive/undergrad/433/Pressure Vessel/Specimen_RawData_5.csv
Time,Extension,Load,Strain Gage18
(s),(mm),(N),(mm/mm)
"0.00000","0.00000","-0.00437","0.00001"
"0.01500","0.00000","-0.00210","0.00001"
"0.03000","0.00005","0.01930","0.00001"
"0.04500","0.00023","0.01055","0.00001"
"0.06000","0.00065","0.02722","0.00001"
"0.07500","0.00145","0.06241","0.00001"
"0.09000","0.00248","0.01324","0.00001"
"0.10500","0.00322","-0.03790","0.00001"
"0.12000","0.00371","-0.00804","0.00001"
"0.13500","0.00437","0.06899","0.00001"
"0.15000","0.00557","0.06539","0.00001"
"0.16500","0.00733","0.03495","0.00001"
"0.18000","0.00942","0.03678","0.00001"
"0.19500","0.01163","-0.01039","0.00000"
"0.21000","0.01377","0.01120","0.00000"
"0.22500","0.01575","0.14055","0.00001"
"0.24000","0.01758","0.14677","0.00001"
"0.25500","0.01925","0.10050","0.00001"
"0.27000","0.02079","0.05981","0.00001"
"0.28500","0.02226","0.03791","0.00001"
"0.30000","0.02372","0.02297","0.00001"
"0.31500","0.02521","0.04839","0.00001"
"0.33000","0.02673","0.06518","0.00001"
"0.34500","0.02828","0.10569","0.00001"
"0.36000","0.02980","0.10503","0.00001"
"0.37500","0.03127","0.08256","0.00001"
"0.39000","0.03270","0.07472","0.00000"
"0.40500","0.03417","0.06359","0.00000"
"0.42000","0.03567","0.07549","0.00000"
"0.43500","0.03717","0.02343","0.00000"
"0.45000","0.03868","0.01055","0.00001"
"0.46500","0.04021","0.07124","0.00001"
"0.48000","0.04172","0.07541","0.00001"
"0.49500","0.04319","0.01085","0.00001"
"0.51000","0.04464","-0.01225","0.00001"
"0.52500","0.04612","-0.03305","0.00001"
"0.54000","0.04761","-0.04848","0.00001"
"0.55500","0.04909","-0.01915","0.00001"
"0.57000","0.05060","0.07843","0.00001"
"0.58500","0.05212","0.18131","0.00001"
"0.60000","0.05362","0.18263","0.00000"
"0.61500","0.05509","0.09959","0.00000"
"0.63000","0.05656","0.01954","0.00000"
"0.64500","0.05807","0.00640","0.00000"
"0.66000","0.05959","0.06519","0.00000"
"0.67500","0.06111","0.10157","0.00000"
"0.69000","0.06266","0.09124","0.00001"
"0.70500","0.06423","0.07330","0.00001"
"0.72000","0.06575","0.02028","0.00001"
"0.73500","0.06722","-0.00530","0.00001"
"0.75000","0.06868","-0.02660","0.00001"
"0.76500","0.07016","-0.06687","0.00001"
"0.78000","0.07167","-0.07641","0.00001"
"0.79500","0.07320","-0.04400","0.00001"
"0.81000","0.07477","-0.04482","0.00000"
"0.82500","0.07630","-0.01951","0.00000"
"0.84000","0.07778","-0.04409","0.00000"
"0.85500","0.07927","-0.00999","0.00000"
"0.87000","0.08080","-0.00506","0.00000"
"0.88500","0.08231","0.02798","0.00000"
"0.90000","0.08379","0.07189","0.00001"
"0.91500","0.08530","0.08996","0.00001"
"0.93000","0.08684","0.06060","0.00001"
"0.94500","0.08834","0.04585","0.00001"
"0.96000","0.08979","0.06131","0.00001"
"0.97500","0.09124","-0.04742","0.00001"
"0.99000","0.09272","-0.10851","0.00001"
"1.00500","0.09422","-0.06147","0.00001"
"1.02000","0.09572","0.07954","0.00001"
"1.03500","0.09724","0.13186","0.00000"
"1.05000","0.09875","0.10561","0.00000"
"1.06500","0.10022","0.02206","0.00000"
"1.08000","0.10167","0.00081","0.00000"
"1.09500","0.10316","0.06213","0.00000"
"1.11000","0.10467","0.08136","0.00000"
"1.12500","0.10617","0.08705","0.00000"
"1.14000","0.10767","0.07427","0.00001"
"1.15500","0.10918","-0.01191","0.00001"
"1.17000","0.11067","-0.01559","0.00001"
"1.18500","0.11211","0.06277","0.00001"
"1.20000","0.11353","0.11218","0.00001"
"1.21500","0.11501","0.11156","0.00001"
"1.23000","0.11654","0.05100","0.00001"
"1.24500","0.11810","-0.03336","0.00001"
"1.26000","0.11966","-0.06005","0.00000"
"1.27500","0.12121","-0.06339","0.00000"
"1.29000","0.12270","-0.07026","0.00000"
"1.30500","0.12416","-0.10443","0.00000"
"1.32000","0.12564","-0.04929","0.00000"
"1.33500","0.12718","-0.05594","0.00000"
"1.35000","0.12871","-0.06343","0.00001"
"1.36500","0.13025","-0.02017","0.00001"
"1.38000","0.13180","0.05192","0.00001"
"1.39500","0.13333","0.09189","0.00001"
"1.41000","0.13481","0.09333","0.00001"
"1.42500","0.13624","0.10712","0.00001"
"1.44000","0.13769","0.06332","0.00001"
"1.45500","0.13919","0.03498","0.00001"
"1.47000","0.14072","0.06214","0.00000"
"1.48500","0.14226","-0.00394","0.00000"
"1.50000","0.14380","-0.02573","0.00000"
"1.51500","0.14532","0.06711","0.00000"
"1.53000","0.14680","0.16329","0.00000"
"1.54500","0.14827","0.17173","0.00000"
"1.56000","0.14976","0.08079","0.00000"
"1.57500","0.15125","0.02056","0.00000"
"1.59000","0.15274","0.00877","0.00001"
"1.60500","0.15425","0.01058","0.00001"
"1.62000","0.15577","0.03377","0.00001"
"1.63500","0.15725","0.06952","0.00001"
"1.65000","0.15868","0.08009","0.00001"
"1.66500","0.16012","0.08818","0.00001"
"1.68000","0.16162","0.10601","0.00000"
"1.69500","0.16313","0.02618","0.00000"
"1.71000","0.16465","-0.01615","0.00000"
"1.72500","0.16618","-0.02968","0.00000"
"1.74000","0.16769","-0.07927","0.00000"
"1.75500","0.16915","-0.09277","0.00000"
"1.77000","0.17060","-0.04801","0.00000"
"1.78500","0.17207","-0.01399","0.00000"
"1.80000","0.17358","-0.06251","0.00001"
"1.81500","0.17511","-0.03519","0.00001"
"1.83000","0.17665","0.02619","0.00001"
"1.84500","0.17822","0.07869","0.00001"
"1.86000","0.17975","0.07338","0.00001"
"1.87500","0.18120","0.09497","0.00001"
"1.89000","0.18263","0.05483","0.00001"
"1.90500","0.18410","0.03938","0.00000"
"1.92000","0.18563","0.05711","0.00000"
"1.93500","0.18719","0.02716","0.00000"
"1.95000","0.18874","-0.03611","0.00000"
"1.96500","0.19026","-0.07055","0.00000"
"1.98000","0.19173","-0.04102","0.00000"
"1.99500","0.19318","0.04447","0.00000"
"2.01000","0.19466","0.03204","0.00000"
"2.02500","0.19617","0.00365","0.00000"
"2.04000","0.19770","0.07041","0.00001"
"2.05500","0.19926","0.05695","0.00001"
"2.07000","0.20084","0.03276","0.00001"
"2.08500","0.20238","0.03016","0.00001"
"2.10000","0.20384","0.07319","0.00001"
"2.11500","0.20526","0.10573","0.00001"
"2.13000","0.20673","0.05303","0.00000"
"2.14500","0.20824","0.00397","0.00000"
"2.16000","0.20976","-0.00759","0.00000"
"2.17500","0.21129","-0.02250","0.00000"
"2.19000","0.21282","0.01083","0.00000"
"2.20500","0.21431","0.04159","0.00000"
"2.22000","0.21576","0.05491","0.00000"
"2.23500","0.21718","0.01023","0.00000"
"2.25000","0.21864","-0.00045","0.00001"
"2.26500","0.22013","0.04962","0.00001"
"2.28000","0.22165","0.04605","0.00001"
"2.29500","0.22321","0.06968","0.00001"
"2.31000","0.22475","0.07482","0.00001"
"2.32500","0.22623","0.10313","0.00000"
"2.34000","0.22764","0.11657","0.00000"
"2.35500","0.22907","0.09589","0.00000"
"2.37000","0.23055","0.05787","0.00000"
"2.38500","0.23207","0.05539","0.00000"
"2.40000","0.23361","0.06285","0.00000"
"2.41500","0.23516","0.07215","0.00000"
"2.43000","0.23669","0.04282","0.00000"
"2.44500","0.23819","0.08933","0.00000"
"2.46000","0.23966","0.16271","0.00000"
"2.47500","0.24114","0.08732","0.00001"
"2.49000","0.24263","0.05286","0.00001"
"2.50500","0.24414","0.02810","0.00001"
"2.52000","0.24567","-0.00141","0.00001"
"2.53500","0.24724","-0.03198","0.00001"
"2.55000","0.24876","-0.02932","0.00001"
"2.56500","0.25022","0.01322","0.00000"
"2.58000","0.25166","0.03027","0.00000"
"2.59500","0.25315","0.02222","0.00000"
"2.61000","0.25467","-0.03235","0.00000"
"2.62500","0.25620","-0.03680","0.00000"
"2.64000","0.25776","-0.02509","0.00000"
"2.65500","0.25931","0.01751","0.00000"
"2.67000","0.26083","-0.03020","0.00000"
"2.68500","0.26229","-0.03439","0.00000"
"2.70000","0.26375","0.00253","0.00001"
"2.71500","0.26524","-0.05863","0.00001"
"2.73000","0.26675","-0.04310","0.00001"
"2.74500","0.26829","-0.04789","0.00001"
"2.76000","0.26984","-0.04587","0.00001"
"2.77500","0.27135","0.00943","0.00000"
"2.79000","0.27279","0.05205","0.00000"
"2.80500","0.27421","0.00445","0.00000"
"2.82000","0.27566","-0.03786","0.00000"
"2.83500","0.27714","-0.05610","0.00000"
"2.85000","0.27863","-0.02518","0.00000"
"2.86500","0.28013","-0.00482","0.00000"
"2.88000","0.28166","-0.00207","0.00000"
"2.89500","0.28317","0.03812","0.00000"
"2.91000","0.28465","0.02534","0.00000"
"2.92500","0.28611","-0.01558","0.00001"
"2.94000","0.28760","-0.01607","0.00001"
"2.95500","0.28910","0.00520","0.00001"
"2.97000","0.29060","0.00472","0.00001"
"2.98500","0.29213","-0.06202","0.00001"
"3.00000","0.29365","-0.06745","0.00000"
"3.01500","0.29514","0.02129","0.00000"
"3.03000","0.29660","0.01997","0.00000"
"3.04500","0.29808","-0.03372","0.00000"
"3.06000","0.29960","0.01040","0.00000"
"3.07500","0.30111","0.02143","0.00000"
"3.09000","0.30262","0.04160","0.00000"
"3.10500","0.30417","0.03795","0.00000"
"3.12000","0.30571","0.08495","0.00000"
"3.13500","0.30722","0.05668","0.00000"
"3.15000","0.30869","-0.00710","0.00001"
"3.16500","0.31017","0.06173","0.00001"
"3.18000","0.31167","0.13662","0.00001"
"3.19500","0.31318","0.13950","0.00001"
"3.21000","0.31471","0.04568","0.00000"
"3.22500","0.31626","0.01980","0.00000"
"3.24000","0.31776","0.05245","0.00000"
"3.25500","0.31923","0.07357","0.00000"
"3.27000","0.32072","0.03762","0.00000"
"3.28500","0.32224","0.01218","0.00000"
"3.30000","0.32375","0.01421","0.00000"
"3.31500","0.32524","-0.01729","0.00000"
"3.33000","0.32677","-0.05884","0.00000"
"3.34500","0.32831","-0.05973","0.00000"
"3.36000","0.32980","-0.04619","0.00000"
"3.37500","0.33125","-0.00178","0.00000"
"3.39000","0.33271","0.03128","0.00001"
"3.40500","0.33422","0.05148","0.00001"
"3.42000","0.33574","0.02100","0.00001"
"3.43500","0.33726","-0.05720","0.00000"
"3.45000","0.33877","-0.09354","0.00000"
"3.46500","0.34025","0.00017","0.00000"
"3.48000","0.34169","0.09456","0.00000"
"3.49500","0.34313","0.08447","0.00000"
"3.51000","0.34462","0.03296","0.00000"
"3.52500","0.34613","-0.03925","0.00000"
"3.54000","0.34765","-0.06663","0.00000"
"3.55500","0.34917","-0.08333","0.00000"
"3.57000","0.35070","-0.08568","0.00000"
"3.58500","0.35219","0.00371","0.00000"
"3.60000","0.35363","0.04209","0.00000"
"3.61500","0.35507","0.07024","0.00000"
"3.63000","0.35657","0.06738","0.00000"
"3.64500","0.35810","0.06604","0.00000"
"3.66000","0.35965","0.09268","0.00000"
"3.67500","0.36121","0.05472","0.00000"
"3.69000","0.36273","-0.03961","0.00000"
"3.70500","0.36419","-0.05965","0.00000"
"3.72000","0.36562","-0.04379","0.00000"
"3.73500","0.36711","-0.06915","0.00000"
"3.75000","0.36863","-0.01685","0.00000"
"3.76500","0.37016","-0.00450","0.00000"
"3.78000","0.37169","0.05845","0.00000"
"3.79500","0.37325","0.02278","0.00000"
"3.81000","0.37478","0.01236","0.00000"
"3.82500","0.37626","0.02095","0.00001"
"3.84000","0.37770","0.04833","0.00001"
"3.85500","0.37918","0.03315","0.00001"
"3.87000","0.38071","0.02982","0.00000"
"3.88500","0.38225","0.00903","0.00000"
"3.90000","0.38379","-0.00883","0.00000"
"3.91500","0.38531","0.04600","0.00000"
"3.93000","0.38681","0.05070","0.00000"
"3.94500","0.38828","0.06304","0.00000"
"3.96000","0.38975","0.09828","0.00000"
"3.97500","0.39124","0.10232","0.00000"
"3.99000","0.39274","0.05518","0.00000"
"4.00500","0.39424","-0.00082","0.00000"
"4.02000","0.39577","-0.08107","0.00000"
"4.03500","0.39729","-0.12049","0.00000"
"4.05000","0.39875","-0.07249","0.00000"
"4.06500","0.40018","-0.02907","0.00000"
"4.08000","0.40163","0.04509","0.00000"
"4.09500","0.40313","0.04915","0.00000"
"4.11000","0.40465","0.06041","0.00000"
"4.12500","0.40616","0.06572","0.00000"
"4.14000","0.40769","0.08387","0.00000"
"4.15500","0.40917","0.05073","0.00000"
"4.17000","0.41062","0.00329","0.00000"
"4.18500","0.41207","0.00576","0.00000"
"4.20000","0.41356","-0.00326","0.00000"
"4.21500","0.41507","-0.03301","0.00000"
"4.23000","0.41661","0.01406","0.00000"
"4.24500","0.41816","0.01118","0.00000"
"4.26000","0.41973","-0.00447","0.00001"
"4.27500","0.42124","0.00868","0.00001"
"4.29000","0.42269","0.09576","0.00000"
"4.30500","0.42413","0.08864","0.00000"
"4.32000","0.42563","0.09596","0.00000"
"4.33500","0.42716","0.08685","0.00000"
"4.35000","0.42871","0.10152","0.00000"
"4.36500","0.43025","0.10523","0.00000"
"4.38000","0.43175","0.06061","0.00000"
"4.39500","0.43322","0.02410","0.00000"
"4.41000","0.43467","-0.02166","0.00000"
"4.42500","0.43617","-0.04361","0.00000"
"4.44000","0.43769","0.00065","0.00000"
"4.45500","0.43922","0.04326","0.00000"
"4.47000","0.44079","0.00721","0.00000"
"4.48500","0.44237","-0.04056","0.00001"
"4.50000","0.44388","-0.04917","0.00001"
"4.51500","0.44532","0.00025","0.00001"
"4.53000","0.44674","-0.01140","0.00000"
"4.54500","0.44822","-0.02480","0.00000"
"4.56000","0.44975","0.03711","0.00000"
"4.57500","0.45128","0.05076","0.00000"
"4.59000","0.45281","0.07309","0.00000"
"4.60500","0.45434","0.05116","0.00000"
"4.62000","0.45582","0.06945","0.00000"
"4.63500","0.45725","0.02584","0.00000"
"4.65000","0.45868","-0.06671","0.00000"
"4.66500","0.46015","-0.07178","0.00000"
"4.68000","0.46164","-0.00423","0.00000"
"4.69500","0.46317","-0.01420","0.00000"
"4.71000","0.46473","-0.01588","0.00001"
"4.72500","0.46626","0.00328","0.00001"
"4.74000","0.46772","-0.02299","0.00000"
"4.75500","0.46913","-0.00586","0.00000"
"4.77000","0.47058","0.01232","0.00000"
"4.78500","0.47208","-0.01866","0.00000"
"4.80000","0.47359","0.00968","0.00000"
"4.81500","0.47512","0.07059","0.00000"
"4.83000","0.47667","0.05902","0.00000"
"4.84500","0.47819","0.03084","0.00000"
"4.86000","0.47967","0.00225","0.00000"
"4.87500","0.48114","-0.01186","0.00000"
"4.89000","0.48263","-0.02608","0.00000"
"4.90500","0.48413","0.00156","0.00000"
"4.92000","0.48565","-0.00924","0.00000"
"4.93500","0.48721","0.06193","0.00001"
"4.95000","0.48878","0.15898","0.00001"
"4.96500","0.49028","0.11398","0.00001"
"4.98000","0.49173","0.06845","0.00001"
"4.99500","0.49317","0.02313","0.00000"
"5.01000","0.49467","-0.03328","0.00000"
"5.02500","0.49620","-0.00093","0.00000"
"5.04000","0.49774","0.02740","0.00000"
"5.05500","0.49930","0.03127","0.00000"
"5.07000","0.50085","0.00540","0.00000"
"5.08500","0.50235","0.03579","0.00000"
"5.10000","0.50379","0.05484","0.00000"
"5.11500","0.50524","0.02604","0.00000"
"5.13000","0.50672","-0.03481","0.00001"
"5.14500","0.50823","-0.05197","0.00001"
"5.16000","0.50977","-0.00644","0.00000"
"5.17500","0.51131","0.03870","0.00000"
"5.19000","0.51281","0.08565","0.00000"
"5.20500","0.51425","0.10891","0.00000"
"5.22000","0.51569","0.10777","0.00000"
"5.23500","0.51717","0.09556","0.00000"
"5.25000","0.51866","0.10745","0.00000"
"5.26500","0.52016","0.06888","0.00000"
"5.28000","0.52169","0.05126","0.00000"
"5.29500","0.52322","0.05529","0.00000"
"5.31000","0.52473","0.06566","0.00000"
"5.32500","0.52619","0.03903","0.00000"
"5.34000","0.52765","-0.03159","0.00000"
"5.35500","0.52914","-0.06660","0.00000"
"5.37000","0.53064","-0.00880","0.00001"
"5.38500","0.53215","0.04868","0.00001"
"5.40000","0.53368","0.05681","0.00001"
"5.41500","0.53519","0.04403","0.00000"
"5.43000","0.53666","0.12920","0.00000"
"5.44500","0.53810","0.16139","0.00000"
"5.46000","0.53958","0.17084","0.00000"
"5.47500","0.54109","0.06864","0.00000"
"5.49000","0.54260","0.01748","0.00000"
"5.50500","0.54412","-0.03378","0.00000"
"5.52000","0.54568","-0.03114","0.00000"
"5.53500","0.54722","-0.08249","0.00000"
"5.55000","0.54871","-0.03525","0.00000"
"5.56500","0.55018","0.01948","0.00000"
"5.58000","0.55166","0.06409","0.00000"
"5.59500","0.55315","0.04275","0.00001"
"5.61000","0.55467","0.00512","0.00001"
"5.62500","0.55622","-0.03200","0.00001"
"5.64000","0.55776","0.00504","0.00000"
"5.65500","0.55926","0.08841","0.00000"
"5.67000","0.56072","0.08077","0.00000"
"5.68500","0.56221","0.06021","0.00000"
"5.70000","0.56373","0.01596","0.00000"
"5.71500","0.56523","0.01329","0.00000"
"5.73000","0.56673","0.00308","0.00000"
"5.74500","0.56827","-0.07038","0.00000"
"5.76000","0.56981","-0.07872","0.00000"
"5.77500","0.57129","-0.04986","0.00000"
"5.79000","0.57273","-0.01514","0.00000"
"5.80500","0.57420","-0.03509","0.00000"
"5.82000","0.57570","-0.00763","0.00000"
"5.83500","0.57722","0.03403","0.00000"
"5.85000","0.57874","0.01385","0.00000"
"5.86500","0.58025","-0.01529","0.00000"
"5.88000","0.58173","-0.04284","0.00000"
"5.89500","0.58317","-0.08345","0.00000"
"5.91000","0.58462","-0.06160","0.00000"
"5.92500","0.58612","0.02966","0.00000"
"5.94000","0.58764","0.05865","0.00000"
"5.95500","0.58914","0.03671","0.00000"
"5.97000","0.59067","0.08101","0.00000"
"5.98500","0.59219","0.04844","0.00000"
"6.00000","0.59366","0.01858","0.00000"
"6.01500","0.59509","-0.03429","0.00000"
"6.03000","0.59654","-0.03907","0.00000"
"6.04500","0.59805","-0.02276","0.00000"
"6.06000","0.59959","0.02648","0.00000"
"6.07500","0.60114","0.05254","0.00000"
"6.09000","0.60270","0.08098","0.00000"
"6.10500","0.60421","0.08720","0.00000"
"6.12000","0.60566","0.08966","0.00000"
"6.13500","0.60711","0.04544","0.00000"
"6.15000","0.60861","0.05688","0.00000"
"6.16500","0.61013","0.06289","0.00000"
"6.18000","0.61165","0.09109","0.00000"
"6.19500","0.61318","0.11133","0.00000"
"6.21000","0.61473","0.10286","0.00000"
"6.22500","0.61626","0.04198","0.00000"
"6.24000","0.61774","0.02404","0.00000"
"6.25500","0.61920","0.07083","0.00001"
"6.27000","0.62071","0.06296","0.00001"
"6.28500","0.62225","0.00657","0.00001"
"6.30000","0.62379","0.05017","0.00000"
"6.31500","0.62534","0.05749","0.00000"
"6.33000","0.62686","0.00477","0.00000"
"6.34500","0.62835","-0.07174","0.00000"
"6.36000","0.62981","-0.01868","0.00000"
"6.37500","0.63128","0.03925","0.00000"
"6.39000","0.63276","0.07671","0.00000"
"6.40500","0.63423","0.06777","0.00000"
"6.42000","0.63573","0.03163","0.00000"
"6.43500","0.63725","0.03751","0.00000"
"6.45000","0.63875","-0.00613","0.00000"
"6.46500","0.64019","-0.00332","0.00000"
"6.48000","0.64161","0.03284","0.00000"
"6.49500","0.64307","0.06596","0.00000"
"6.51000","0.64459","0.04814","0.00000"
"6.52500","0.64613","0.03126","0.00000"
"6.54000","0.64767","0.03484","0.00000"
"6.55500","0.64919","-0.01972","0.00000"
"6.57000","0.65066","-0.04661","0.00000"
"6.58500","0.65209","0.01753","0.00000"
"6.60000","0.65354","0.04868","0.00000"
"6.61500","0.65503","0.02200","0.00000"
"6.63000","0.65655","-0.00418","0.00000"
"6.64500","0.65808","0.05732","0.00000"
"6.66000","0.65964","0.09043","0.00000"
"6.67500","0.66120","0.03004","0.00000"
"6.69000","0.66270","0.02688","0.00000"
"6.70500","0.66416","0.05472","0.00000"
"6.72000","0.66564","0.05807","0.00000"
"6.73500","0.66716","0.03995","0.00000"
"6.75000","0.66870","0.02408","0.00000"
"6.76500","0.67023","0.01375","0.00000"
"6.78000","0.67176","0.01137","0.00000"
"6.79500","0.67325","0.00482","0.00000"
"6.81000","0.67470","0.02342","0.00000"
"6.82500","0.67616","0.01970","0.00000"
"6.84000","0.67766","0.04338","0.00000"
"6.85500","0.67919","0.04941","0.00000"
"6.87000","0.68073","0.01966","0.00000"
"6.88500","0.68230","-0.02398","0.00000"
"6.90000","0.68386","-0.12660","0.00000"
"6.91500","0.68533","-0.16312","0.00000"
"6.93000","0.68675","-0.05046","0.00000"
"6.94500","0.68818","0.00118","0.00000"
"6.96000","0.68970","0.04674","0.00000"
"6.97500","0.69125","0.05078","0.00000"
"6.99000","0.69279","0.04194","0.00000"
"7.00500","0.69433","-0.00011","0.00000"
"7.02000","0.69583","-0.00625","0.00000"
"7.03500","0.69728","0.01753","0.00000"
"7.05000","0.69869","0.02935","0.00000"
"7.06500","0.70013","0.02229","0.00000"
"7.08000","0.70160","-0.02186","0.00000"
"7.09500","0.70310","0.02156","0.00000"
"7.11000","0.70464","0.04074","0.00000"
"7.12500","0.70620","0.04404","0.00000"
"7.14000","0.70773","0.06181","0.00000"
"7.15500","0.70919","0.01467","0.00000"
"7.17000","0.71062","-0.08244","0.00000"
"7.18500","0.71208","-0.12910","0.00000"
"7.20000","0.71359","-0.05634","0.00000"
"7.21500","0.71511","0.01001","0.00000"
"7.23000","0.71665","0.02897","0.00000"
"7.24500","0.71819","0.05020","0.00000"
"7.26000","0.71969","0.01911","0.00000"
"7.27500","0.72115","-0.00317","0.00000"
"7.29000","0.72262","0.01214","0.00000"
"7.30500","0.72412","-0.00187","0.00000"
"7.32000","0.72564","0.03566","0.00000"
"7.33500","0.72718","0.02206","0.00000"
"7.35000","0.72875","-0.01162","0.00001"
"7.36500","0.73028","0.04590","0.00001"
"7.38000","0.73175","0.04182","0.00001"
"7.39500","0.73317","0.03115","0.00000"
"7.41000","0.73464","-0.02559","0.00000"
"7.42500","0.73616","-0.09777","0.00000"
"7.44000","0.73770","-0.08728","0.00000"
"7.45500","0.73924","-0.09683","0.00000"
"7.47000","0.74080","-0.06102","0.00000"
"7.48500","0.74233","-0.01172","0.00000"
"7.50000","0.74381","0.13489","0.00000"
"7.51500","0.74525","0.15317","0.00000"
"7.53000","0.74671","0.09801","0.00000"
"7.54500","0.74819","-0.00544","0.00000"
"7.56000","0.74971","-0.01326","0.00000"
"7.57500","0.75127","-0.02021","0.00000"
"7.59000","0.75282","0.00354","0.00000"
"7.60500","0.75431","0.03048","0.00000"
"7.62000","0.75575","-0.02949","0.00000"
"7.63500","0.75720","-0.07760","0.00000"
"7.65000","0.75868","-0.08896","0.00000"
"7.66500","0.76017","-0.06153","0.00000"
"7.68000","0.76167","-0.02882","0.00000"
"7.69500","0.76319","-0.02716","0.00000"
"7.71000","0.76472","-0.04766","0.00000"
"7.72500","0.76620","-0.05176","0.00000"
"7.74000","0.76764","0.01120","0.00000"
"7.75500","0.76911","0.02358","0.00000"
"7.77000","0.77060","0.05793","0.00000"
"7.78500","0.77210","0.03390","0.00000"
"7.80000","0.77363","-0.02690","0.00000"
"7.81500","0.77518","-0.05875","0.00000"
"7.83000","0.77670","-0.06716","0.00000"
"7.84500","0.77817","-0.02579","0.00000"
"7.86000","0.77963","0.05491","0.00000"
"7.87500","0.78113","0.06648","0.00000"
"7.89000","0.78264","0.03505","0.00000"
"7.90500","0.78413","-0.01851","0.00000"
"7.92000","0.78564","-0.04725","0.00000"
"7.93500","0.78719","-0.03223","0.00000"
"7.95000","0.78870","-0.02971","0.00000"
"7.96500","0.79018","-0.02307","0.00000"
"7.98000","0.79165","0.03446","0.00000"
"7.99500","0.79314","-0.00198","0.00000"
"8.01000","0.79464","-0.10441","0.00000"
"8.02500","0.79617","-0.14050","0.00000"
"8.04000","0.79773","-0.12138","0.00000"
"8.05500","0.79927","-0.12604","0.00000"
"8.07000","0.80076","-0.02332","0.00000"
"8.08500","0.80224","0.03278","0.00000"
"8.10000","0.80376","0.03623","0.00000"
"8.11500","0.80528","0.04254","0.00000"
"8.13000","0.80678","0.03912","0.00000"
"8.14500","0.80829","0.06272","0.00000"
"8.16000","0.80983","0.05725","0.00000"
"8.17500","0.81134","0.03069","0.00000"
"8.19000","0.81279","0.05600","0.00000"
"8.20500","0.81422","0.00544","0.00000"
"8.22000","0.81569","0.00527","0.00000"
"8.23500","0.81719","0.04288","0.00000"
"8.25000","0.81870","0.00644","0.00000"
"8.26500","0.82021","-0.04674","0.00000"
"8.28000","0.82172","-0.04721","0.00000"
"8.29500","0.82319","-0.02725","0.00000"
"8.31000","0.82463","-0.00300","0.00000"
"8.32500","0.82610","0.03299","0.00000"
"8.34000","0.82760","0.01383","0.00000"
"8.35500","0.82910","0.08565","0.00000"
"8.37000","0.83060","0.07001","0.00000"
"8.38500","0.83212","0.06991","0.00000"
"8.40000","0.83364","0.05091","0.00000"
"8.41500","0.83511","-0.02004","0.00000"
"8.43000","0.83655","-0.03175","0.00000"
"8.44500","0.83802","-0.02237","0.00000"
"8.46000","0.83955","-0.00806","0.00000"
"8.47500","0.84110","-0.03319","0.00000"
"8.49000","0.84266","-0.01895","0.00000"
"8.50500","0.84422","0.03968","0.00000"
"8.52000","0.84571","0.05183","0.00000"
"8.53500","0.84716","0.01104","0.00000"
"8.55000","0.84863","0.02070","0.00000"
"8.56500","0.85014","0.05128","0.00000"
"8.58000","0.85167","0.00736","0.00000"
"8.59500","0.85318","0.00789","0.00000"
"8.61000","0.85472","-0.00213","0.00000"
"8.62500","0.85626","-0.00634","0.00000"
"8.64000","0.85776","0.00461","0.00000"
"8.65500","0.85922","-0.03391","0.00000"
"8.67000","0.86069","-0.06585","0.00000"
"8.68500","0.86221","-0.07674","0.00000"
"8.70000","0.86375","-0.09208","0.00000"
"8.71500","0.86528","-0.04194","0.00000"
"8.73000","0.86682","0.02943","0.00000"
"8.74500","0.86833","0.04668","0.00000"
"8.76000","0.86982","0.07506","0.00000"
"8.77500","0.87128","0.10124","0.00000"
"8.79000","0.87276","0.01302","0.00000"
"8.80500","0.87424","-0.02718","0.00000"
"8.82000","0.87571","-0.02730","0.00000"
"8.83500","0.87722","-0.00216","0.00000"
"8.85000","0.87875","0.05157","0.00000"
"8.86500","0.88023","0.10134","0.00000"
"8.88000","0.88166","0.09109","0.00000"
"8.89500","0.88309","0.05469","0.00001"
"8.91000","0.88457","0.04919","0.00001"
"8.92500","0.88610","0.00705","0.00000"
"8.94000","0.88765","0.00208","0.00000"
"8.95500","0.88920","-0.03180","0.00000"
"8.97000","0.89072","0.01106","0.00000"
"8.98500","0.89217","0.04365","0.00000"
"9.00000","0.89360","0.05043","0.00000"
"9.01500","0.89507","0.04750","0.00000"
"9.03000","0.89657","-0.02343","0.00000"
"9.04500","0.89809","-0.02179","0.00000"
"9.06000","0.89964","-0.02774","0.00000"
"9.07500","0.90120","0.01776","0.00000"
"9.09000","0.90273","0.06164","0.00000"
"9.10500","0.90420","0.03978","0.00000"
"9.12000","0.90564","-0.01304","0.00000"
"9.13500","0.90711","-0.03006","0.00001"
"9.15000","0.90863","-0.01528","0.00001"
"9.16500","0.91018","-0.01340","0.00000"
"9.18000","0.91173","-0.00684","0.00000"
"9.19500","0.91327","0.01058","0.00000"
"9.21000","0.91476","0.06723","0.00000"
"9.22500","0.91622","0.03951","0.00000"
"9.24000","0.91769","0.04671","0.00000"
"9.25500","0.91919","0.05079","0.00000"
"9.27000","0.92070","0.01663","0.00000"
"9.28500","0.92224","0.02720","0.00000"
"9.30000","0.92382","0.08912","0.00000"
"9.31500","0.92535","0.08777","0.00000"
"9.33000","0.92680","0.04938","0.00000"
"9.34500","0.92821","0.05647","0.00000"
"9.36000","0.92967","0.10446","0.00000"
"9.37500","0.93121","0.07913","0.00000"
"9.39000","0.93277","0.03816","0.00000"
"9.40500","0.93432","-0.00842","0.00000"
"9.42000","0.93586","-0.05350","0.00000"
"9.43500","0.93735","-0.04809","0.00000"
"9.45000","0.93878","-0.02818","0.00000"
"9.46500","0.94020","-0.01319","0.00000"
"9.48000","0.94165","-0.05086","0.00000"
"9.49500","0.94312","0.03235","0.00000"
"9.51000","0.94462","-0.01426","0.00000"
"9.52500","0.94617","0.03426","0.00000"
"9.54000","0.94773","0.05017","0.00000"
"9.55500","0.94923","0.03255","0.00000"
"9.57000","0.95067","-0.02290","0.00000"
"9.58500","0.95210","-0.04756","0.00000"
"9.60000","0.95357","-0.03465","0.00000"
"9.61500","0.95507","-0.00299","0.00000"
"9.63000","0.95660","-0.00284","0.00000"
"9.64500","0.95815","-0.01519","0.00000"
"9.66000","0.95969","-0.03856","0.00000"
"9.67500","0.96119","-0.04124","0.00000"
"9.69000","0.96264","-0.02749","0.00000"
"9.70500","0.96411","-0.00203","0.00000"
"9.72000","0.96560","0.07954","0.00000"
"9.73500","0.96712","0.10239","0.00000"
"9.75000","0.96865","0.08230","0.00000"
"9.76500","0.97021","0.06240","0.00000"
"9.78000","0.97173","0.11324","0.00000"
"9.79500","0.97319","0.02335","0.00000"
"9.81000","0.97463","-0.00255","0.00000"
"9.82500","0.97614","0.02742","0.00000"
"9.84000","0.97768","-0.01971","0.00000"
"9.85500","0.97923","0.02615","0.00000"
"9.87000","0.98078","0.02033","0.00000"
"9.88500","0.98233","-0.04135","0.00000"
"9.90000","0.98386","-0.02217","0.00000"
"9.91500","0.98532","0.02494","0.00000"
"9.93000","0.98677","0.09188","0.00000"
"9.94500","0.98823","0.11532","0.00000"
"9.96000","0.98972","0.02099","0.00000"
"9.97500","0.99125","-0.03966","0.00000"
"9.99000","0.99281","-0.01776","0.00000"
"10.00500","0.99434","-0.00860","0.00000"
"10.02000","0.99581","-0.04354","0.00000"
"10.03500","0.99723","-0.07118","0.00000"
"10.05000","0.99868","-0.07805","0.00000"
"10.06500","1.00015","-0.03678","0.00000"
"10.08000","1.00163","-0.02295","0.00000"
"10.09500","1.00313","0.02500","0.00000"
"10.11000","1.00466","0.06470","0.00000"
"10.12500","1.00617","0.01091","0.00000"
"10.14000","1.00765","-0.03625","0.00000"
"10.15500","1.00910","0.01809","0.00000"
"10.17000","1.01058","0.09243","0.00000"
"10.18500","1.01207","0.06951","0.00000"
"10.20000","1.01357","0.08048","0.00000"
"10.21500","1.01510","0.05070","0.00000"
"10.23000","1.01664","0.00172","0.00000"
"10.24500","1.01815","-0.01496","0.00000"
"10.26000","1.01962","-0.03014","0.00000"
"10.27500","1.02111","-0.01048","0.00000"
"10.29000","1.02263","0.00148","0.00000"
"10.30500","1.02414","0.04508","0.00000"
"10.32000","1.02564","0.07320","0.00000"
"10.33500","1.02717","0.05591","-0.00001"
"10.35000","1.02871","0.01836","-0.00001"
"10.36500","1.03021","-0.01314","0.00000"
"10.38000","1.03167","0.03076","0.00000"
"10.39500","1.03315","0.13096","0.00000"
"10.41000","1.03464","0.18165","0.00000"
"10.42500","1.03616","0.08016","0.00000"
"10.44000","1.03771","0.01911","0.00000"
"10.45500","1.03927","-0.01141","0.00000"
"10.47000","1.04079","0.01911","0.00000"
"10.48500","1.04225","0.00138","0.00000"
"10.50000","1.04373","0.03686","0.00000"
"10.51500","1.04525","0.05886","0.00000"
"10.53000","1.04676","0.03622","0.00000"
"10.54500","1.04826","0.01103","0.00000"
"10.56000","1.04978","0.00148","0.00000"
"10.57500","1.05132","-0.00521","0.00000"
"10.59000","1.05282","0.00502","0.00000"
"10.60500","1.05427","0.00113","0.00000"
"10.62000","1.05572","-0.00059","0.00000"
"10.63500","1.05720","0.06213","0.00000"
"10.65000","1.05869","0.09755","0.00000"
"10.66500","1.06019","0.02828","0.00000"
"10.68000","1.06170","-0.06007","0.00000"
"10.69500","1.06320","-0.05116","0.00000"
"10.71000","1.06467","-0.04296","0.00000"
"10.72500","1.06613","-0.03435","0.00000"
"10.74000","1.06764","0.00910","0.00000"
"10.75500","1.06916","0.02003","0.00000"
"10.77000","1.07067","0.07618","0.00000"
"10.78500","1.07217","0.03255","0.00000"
"10.80000","1.07369","0.02458","0.00000"
"10.81500","1.07517","-0.00746","0.00000"
"10.83000","1.07661","0.02514","0.00000"
"10.84500","1.07803","0.01932","0.00000"
"10.86000","1.07952","0.03766","0.00000"
"10.87500","1.08106","0.06737","0.00000"
"10.89000","1.08263","0.07675","0.00000"
"10.90500","1.08420","0.03768","0.00000"
"10.92000","1.08574","-0.01839","0.00000"
"10.93500","1.08722","-0.02106","0.00000"
"10.95000","1.08866","-0.00470","0.00000"
"10.96500","1.09013","0.03124","0.00000"
"10.98000","1.09165","0.01239","0.00000"
"10.99500","1.09316","-0.05249","0.00000"
"11.01000","1.09468","-0.07553","0.00000"
"11.02500","1.09621","-0.02705","-0.00001"
"11.04000","1.09774","-0.00161","0.00000"
"11.05500","1.09923","0.01177","0.00000"
"11.07000","1.10069","0.06237","0.00000"
"11.08500","1.10218","0.05008","0.00000"
"11.10000","1.10371","0.04298","0.00000"
"11.11500","1.10526","0.02681","0.00000"
"11.13000","1.10680","0.01978","0.00000"
"11.14500","1.10833","-0.04848","-0.00001"
"11.16000","1.10984","-0.07666","-0.00004"
"11.17500","1.11132","0.00791","-0.00010"
"11.19000","1.11279","0.03437","-0.00017"
"11.20500","1.11429","-0.03145","-0.00023"
"11.22000","1.11577","-0.06184","-0.00026"
"11.23500","1.11727","-0.03231","-0.00027"
"11.25000","1.11878","-0.03112","-0.00028"
"11.26500","1.12029","-0.04335","-0.00028"
"11.28000","1.12174","-0.05210","-0.00028"
"11.29500","1.12315","0.03867","-0.00028"
"11.31000","1.12459","-0.19461","-0.00028"
"11.32500","1.12610","-0.13431","-0.00028"
"11.34000","1.12764","-0.00236","-0.00028"
"11.35500","1.12917","-0.06173","-0.00028"
"11.37000","1.13071","-0.15349","-0.00027"
"11.38500","1.13221","-0.02876","-0.00027"
"11.40000","1.13365","-0.08211","-0.00027"
"11.41500","1.13508","-0.11727","-0.00027"
"11.43000","1.13655","0.04719","-0.00027"
"11.44500","1.13805","0.04557","-0.00027"
"11.46000","1.13958","-0.03617","-0.00027"
"11.47500","1.14113","-0.07036","-0.00027"
"11.49000","1.14270","-0.02510","-0.00027"
"11.50500","1.14422","-0.10251","-0.00027"
"11.52000","1.14567","-0.05914","-0.00026"
"11.53500","1.14710","-0.00325","-0.00026"
"11.55000","1.14858","0.03861","-0.00026"
"11.56500","1.15011","0.00994","-0.00026"
"11.58000","1.15166","0.00403","-0.00026"
"11.59500","1.15322","-0.05135","-0.00026"
"11.61000","1.15475","-0.03943","-0.00026"
"11.62500","1.15623","0.05089","-0.00026"
"11.64000","1.15770","0.02360","-0.00026"
"11.65500","1.15920","-0.00938","-0.00026"
"11.67000","1.16072","0.08068","-0.00027"
"11.68500","1.16224","0.17063","-0.00027"
"11.70000","1.16378","0.02682","-0.00026"
"11.71500","1.16534","0.00641","-0.00026"
"11.73000","1.16685","-0.00339","-0.00026"
"11.74500","1.16829","-0.04201","-0.00026"
"11.76000","1.16971","-0.01031","-0.00026"
"11.77500","1.17120","-0.04915","-0.00026"
"11.79000","1.17273","-0.05785","-0.00026"
"11.80500","1.17427","-0.06009","-0.00026"
"11.82000","1.17581","0.00841","-0.00026"
"11.83500","1.17734","-0.03728","-0.00026"
"11.85000","1.17882","-0.03147","-0.00026"
"11.86500","1.18025","-0.04526","-0.00026"
"11.88000","1.18167","-0.01069","-0.00026"
"11.89500","1.18314","0.00533","-0.00026"
"11.91000","1.18464","-0.05534","-0.00026"
"11.92500","1.18617","-0.06734","-0.00026"
"11.94000","1.18772","-0.00668","-0.00026"
"11.95500","1.18925","0.00271","-0.00026"
"11.97000","1.19070","0.03000","-0.00025"
"11.98500","1.19211","0.01921","-0.00025"
"12.00000","1.19353","0.00966","-0.00025"
"12.01500","1.19503","0.00774","-0.00025"
"12.03000","1.19655","-0.02539","-0.00025"
"12.04500","1.19809","-0.00250","-0.00025"
"12.06000","1.19965","-0.01581","-0.00025"
"12.07500","1.20120","0.05258","-0.00026"
"12.09000","1.20269","0.01635","-0.00026"
"12.10500","1.20416","0.01609","-0.00026"
"12.12000","1.20566","-0.02896","-0.00026"
"12.13500","1.20716","-0.06921","-0.00026"
"12.15000","1.20867","-0.04567","-0.00026"
"12.16500","1.21021","-0.03465","-0.00026"
"12.18000","1.21177","-0.02546","-0.00025"
"12.19500","1.21327","-0.00599","-0.00025"
"12.21000","1.21470","-0.02469","-0.00025"
"12.22500","1.21615","0.01468","-0.00025"
"12.24000","1.21765","0.05291","-0.00025"
"12.25500","1.21918","0.08022","-0.00025"
"12.27000","1.22072","0.11934","-0.00025"
"12.28500","1.22227","0.08722","-0.00025"
"12.30000","1.22382","0.05653","-0.00026"
"12.31500","1.22533","-0.00403","-0.00026"
"12.33000","1.22678","-0.05936","-0.00026"
"12.34500","1.22823","-0.10789","-0.00026"
"12.36000","1.22971","-0.05907","-0.00026"
"12.37500","1.23122","-0.02741","-0.00026"
"12.39000","1.23277","-0.01402","-0.00025"
"12.40500","1.23432","0.00090","-0.00025"
"12.42000","1.23581","-0.00944","-0.00025"
"12.43500","1.23725","-0.00229","-0.00025"
"12.45000","1.23868","0.02384","-0.00025"
"12.46500","1.24015","-0.01026","-0.00025"
"12.48000","1.24164","0.03251","-0.00025"
"12.49500","1.24314","0.03749","-0.00025"
"12.51000","1.24466","0.11578","-0.00026"
"12.52500","1.24620","0.06589","-0.00026"
"12.54000","1.24771","0.04879","-0.00026"
"12.55500","1.24918","0.02472","-0.00026"
"12.57000","1.25063","-0.00692","-0.00026"
"12.58500","1.25211","-0.05162","-0.00026"
"12.60000","1.25361","-0.05150","-0.00026"
"12.61500","1.25511","0.03286","-0.00025"
"12.63000","1.25665","0.02060","-0.00025"
"12.64500","1.25819","0.07347","-0.00025"
"12.66000","1.25968","0.08234","-0.00025"
"12.67500","1.26114","0.09875","-0.00025"
"12.69000","1.26262","0.10618","-0.00025"
"12.70500","1.26414","0.03910","-0.00025"
"12.72000","1.26564","-0.00853","-0.00025"
"12.73500","1.26715","-0.06512","-0.00026"
"12.75000","1.26869","-0.14475","-0.00026"
"12.76500","1.27022","-0.12852","-0.00026"
"12.78000","1.27170","-0.07685","-0.00026"
"12.79500","1.27316","-0.03463","-0.00026"
"12.81000","1.27463","-0.02555","-0.00026"
"12.82500","1.27612","-0.01268","-0.00026"
"12.84000","1.27763","0.01210","-0.00025"
"12.85500","1.27918","0.04121","-0.00025"
"12.87000","1.28072","0.05560","-0.00025"
"12.88500","1.28223","-0.01001","-0.00025"
"12.90000","1.28371","-0.02311","-0.00025"
"12.91500","1.28522","0.07240","-0.00025"
"12.93000","1.28676","0.02682","-0.00025"
"12.94500","1.28827","-0.03942","-0.00026"
"12.96000","1.28977","-0.06632","-0.00026"
"12.97500","1.29131","-0.12140","-0.00026"
"12.99000","1.29285","-0.11400","-0.00026"
"13.00500","1.29434","-0.02187","-0.00026"
"13.02000","1.29578","0.06429","-0.00026"
"13.03500","1.29723","0.07806","-0.00026"
"13.05000","1.29871","0.06569","-0.00025"
"13.06500","1.30021","0.00802","-0.00025"
"13.08000","1.30172","-0.00304","-0.00025"
"13.09500","1.30324","-0.01580","-0.00025"
"13.11000","1.30473","0.00215","-0.00025"
"13.12500","1.30619","0.03839","-0.00025"
"13.14000","1.30764","0.01306","-0.00025"
"13.15500","1.30914","-0.02345","-0.00025"
"13.17000","1.31065","-0.01569","-0.00025"
"13.18500","1.31215","0.00683","-0.00026"
"13.20000","1.31366","0.06063","-0.00026"
"13.21500","1.31516","-0.00932","-0.00026"
"13.23000","1.31663","-0.07081","-0.00026"
"13.24500","1.31806","-0.04348","-0.00026"
"13.26000","1.31951","-0.01534","-0.00026"
"13.27500","1.32102","0.00056","-0.00025"
"13.29000","1.32258","-0.04124","-0.00025"
"13.30500","1.32414","-0.02290","-0.00025"
"13.32000","1.32571","-0.02894","-0.00025"
"13.33500","1.32723","-0.00983","-0.00025"
"13.35000","1.32869","-0.06885","-0.00025"
"13.36500","1.33015","-0.06848","-0.00025"
"13.38000","1.33165","-0.01916","-0.00025"
"13.39500","1.33317","-0.04761","-0.00025"
"13.41000","1.33468","-0.03619","-0.00026"
"13.42500","1.33620","-0.06170","-0.00026"
"13.44000","1.33775","-0.03015","-0.00026"
"13.45500","1.33928","-0.00248","-0.00026"
"13.47000","1.34075","0.04411","-0.00025"
"13.48500","1.34221","0.06084","-0.00025"
"13.50000","1.34371","0.04048","-0.00025"
"13.51500","1.34526","-0.00596","-0.00025"
"13.53000","1.34681","0.00103","-0.00025"
"13.54500","1.34836","0.02162","-0.00025"
"13.56000","1.34988","0.01584","-0.00025"
"13.57500","1.35135","-0.00153","-0.00025"
"13.59000","1.35280","0.00013","-0.00025"
"13.60500","1.35426","-0.00047","-0.00025"
"13.62000","1.35574","0.04702","-0.00026"
"13.63500","1.35721","0.02232","-0.00026"
"13.65000","1.35870","-0.02344","-0.00026"
"13.66500","1.36023","-0.00540","-0.00026"
"13.68000","1.36173","0.00957","-0.00026"
"13.69500","1.36318","-0.05182","-0.00026"
"13.71000","1.36460","-0.05615","-0.00025"
"13.72500","1.36607","-0.02379","-0.00025"
"13.74000","1.36758","-0.00558","-0.00025"
"13.75500","1.36911","-0.06373","-0.00025"
"13.77000","1.37064","-0.07898","-0.00025"
"13.78500","1.37217","-0.06113","-0.00025"
"13.80000","1.37366","-0.03988","-0.00025"
"13.81500","1.37511","0.02705","-0.00025"
"13.83000","1.37656","0.08657","-0.00025"
"13.84500","1.37806","0.03051","-0.00026"
"13.86000","1.37959","-0.10582","-0.00026"
"13.87500","1.38112","-0.11746","-0.00026"
"13.89000","1.38269","-0.07256","-0.00026"
"13.90500","1.38424","-0.04008","-0.00026"
"13.92000","1.38574","0.05435","-0.00025"
"13.93500","1.38717","0.05305","-0.00025"
"13.95000","1.38861","0.03494","-0.00025"
"13.96500","1.39011","0.07661","-0.00025"
"13.98000","1.39165","0.10954","-0.00025"
"13.99500","1.39320","0.12807","-0.00025"
"14.01000","1.39475","0.08000","-0.00025"
"14.02500","1.39626","-0.00854","-0.00025"
"14.04000","1.39772","-0.05706","-0.00025"
"14.05500","1.39919","-0.01896","-0.00025"
"14.07000","1.40069","-0.01164","-0.00026"
"14.08500","1.40221","0.00491","-0.00026"
"14.10000","1.40374","0.01569","-0.00026"
"14.11500","1.40530","0.04613","-0.00026"
"14.13000","1.40686","-0.00384","-0.00026"
"14.14500","1.40835","0.01304","-0.00025"
"14.16000","1.40977","0.06415","-0.00025"
"14.17500","1.41120","0.08732","-0.00025"
"14.19000","1.41270","-0.03932","-0.00025"
"14.20500","1.41423","-0.09008","-0.00025"
"14.22000","1.41577","-0.07758","-0.00025"
"14.23500","1.41731","-0.05354","-0.00025"
"14.25000","1.41883","-0.07092","-0.00025"
"14.26500","1.42030","-0.08733","-0.00025"
"14.28000","1.42173","-0.03812","-0.00025"
"14.29500","1.42317","-0.02518","-0.00025"
"14.31000","1.42465","-0.01451","-0.00026"
"14.32500","1.42615","0.01507","-0.00026"
"14.34000","1.42769","-0.02421","-0.00026"
"14.35500","1.42924","-0.04107","-0.00025"
"14.37000","1.43076","-0.06235","-0.00025"
"14.38500","1.43220","-0.06828","-0.00025"
"14.40000","1.43360","-0.12462","-0.00025"
"14.41500","1.43505","-0.10455","-0.00025"
"14.43000","1.43655","-0.05787","-0.00025"
"14.44500","1.43808","0.00420","-0.00025"
"14.46000","1.43962","-0.00707","-0.00025"
"14.47500","1.44117","0.00472","-0.00025"
"14.49000","1.44268","-0.04285","-0.00025"
"14.50500","1.44416","-0.04975","-0.00025"
"14.52000","1.44563","-0.01944","-0.00025"
"14.53500","1.44712","-0.00366","-0.00026"
"14.55000","1.44863","-0.03731","-0.00025"
"14.56500","1.45015","-0.12864","-0.00025"
"14.58000","1.45171","-0.08796","-0.00025"
"14.59500","1.45325","-0.00395","-0.00025"
"14.61000","1.45474","0.04677","-0.00025"
"14.62500","1.45617","0.04490","-0.00025"
"14.64000","1.45763","-0.00321","-0.00025"
"14.65500","1.45914","-0.06545","-0.00025"
"14.67000","1.46068","-0.06458","-0.00025"
"14.68500","1.46222","-0.05749","-0.00025"
"14.70000","1.46379","0.00173","-0.00025"
"14.71500","1.46533","0.01046","-0.00025"
"14.73000","1.46682","-0.03981","-0.00025"
"14.74500","1.46828","-0.03098","-0.00026"
"14.76000","1.46975","-0.09500","-0.00026"
"14.77500","1.47125","-0.07259","-0.00025"
"14.79000","1.47278","-0.01386","-0.00025"
"14.80500","1.47432","-0.00165","-0.00025"
"14.82000","1.47586","-0.00245","-0.00025"
"14.83500","1.47733","-0.04624","-0.00025"
"14.85000","1.47876","-0.05514","-0.00025"
"14.86500","1.48020","-0.05881","-0.00025"
"14.88000","1.48167","-0.05945","-0.00025"
"14.89500","1.48316","-0.03853","-0.00025"
"14.91000","1.48465","-0.03579","-0.00025"
"14.92500","1.48617","-0.01912","-0.00025"
"14.94000","1.48770","0.05155","-0.00025"
"14.95500","1.48920","0.02987","-0.00026"
"14.97000","1.49066","-0.04080","-0.00026"
"14.98500","1.49213","-0.06757","-0.00026"
"15.00000","1.49361","-0.06366","-0.00026"
"15.01500","1.49510","-0.04447","-0.00025"
"15.03000","1.49662","0.01016","-0.00025"
"15.04500","1.49816","0.03423","-0.00025"
"15.06000","1.49969","-0.06591","-0.00025"
"15.07500","1.50116","-0.10717","-0.00025"
"15.09000","1.50262","-0.11673","-0.00025"
"15.10500","1.50412","-0.04253","-0.00025"
"15.12000","1.50563","-0.00314","-0.00025"
"15.13500","1.50714","-0.00390","-0.00025"
"15.15000","1.50865","0.03113","-0.00025"
"15.16500","1.51020","0.01428","-0.00025"
"15.18000","1.51173","0.04662","-0.00025"
"15.19500","1.51323","-0.00532","-0.00025"
"15.21000","1.51470","-0.03158","-0.00025"
"15.22500","1.51619","-0.08571","-0.00025"
"15.24000","1.51769","-0.08668","-0.00025"
"15.25500","1.51921","-0.06459","-0.00025"
"15.27000","1.52076","-0.00763","-0.00025"
"15.28500","1.52229","-0.07720","-0.00025"
"15.30000","1.52378","-0.06937","-0.00025"
"15.31500","1.52525","-0.04855","-0.00025"
"15.33000","1.52676","-0.01876","-0.00025"
"15.34500","1.52827","-0.01849","-0.00025"
"15.36000","1.52977","-0.00474","-0.00025"
"15.37500","1.53127","0.01429","-0.00025"
"15.39000","1.53281","-0.01149","-0.00025"
"15.40500","1.53434","-0.05278","-0.00025"
"15.42000","1.53581","-0.06436","-0.00025"
"15.43500","1.53724","-0.08805","-0.00025"
"15.45000","1.53871","-0.01189","-0.00025"
"15.46500","1.54021","0.02288","-0.00025"
"15.48000","1.54172","0.01845","-0.00025"
"15.49500","1.54322","0.01216","-0.00025"
"15.51000","1.54472","-0.04502","-0.00025"
"15.52500","1.54619","-0.12819","-0.00025"
"15.54000","1.54763","-0.11705","-0.00025"
"15.55500","1.54910","-0.06937","-0.00025"
"15.57000","1.55061","-0.00524","-0.00025"
"15.58500","1.55213","0.03865","-0.00025"
"15.60000","1.55364","0.07928","-0.00025"
"15.61500","1.55516","0.09470","-0.00025"
"15.63000","1.55668","0.09334","-0.00026"
"15.64500","1.55815","0.07962","-0.00026"
"15.66000","1.55958","-0.01549","-0.00025"
"15.67500","1.56105","-0.09427","-0.00025"
"15.69000","1.56256","-0.02732","-0.00025"
"15.70500","1.56411","0.03427","-0.00025"
"15.72000","1.56567","0.00606","-0.00025"
"15.73500","1.56723","-0.04509","-0.00025"
"15.75000","1.56873","-0.06179","-0.00025"
"15.76500","1.57017","-0.03408","-0.00025"
"15.78000","1.57162","-0.00395","-0.00025"
"15.79500","1.57313","0.00440","-0.00025"
"15.81000","1.57465","0.00796","-0.00025"
"15.82500","1.57617","0.03573","-0.00025"
"15.84000","1.57771","0.00566","-0.00025"
"15.85500","1.57927","0.01340","-0.00025"
"15.87000","1.58078","0.01656","-0.00025"
"15.88500","1.58224","-0.03012","-0.00025"
"15.90000","1.58369","-0.02262","-0.00025"
"15.91500","1.58519","-0.00059","-0.00025"
"15.93000","1.58673","0.01489","-0.00025"
"15.94500","1.58827","-0.01701","-0.00025"
"15.96000","1.58982","-0.05458","-0.00025"
"15.97500","1.59133","-0.06328","-0.00025"
"15.99000","1.59281","-0.00659","-0.00025"
"16.00500","1.59427","-0.05620","-0.00025"
"16.02000","1.59575","-0.07960","-0.00025"
"16.03500","1.59723","-0.07354","-0.00025"
"16.05000","1.59872","-0.03293","-0.00025"
"16.06500","1.60023","0.01500","-0.00025"
"16.08000","1.60176","0.02965","-0.00025"
"16.09500","1.60325","-0.01357","-0.00026"
"16.11000","1.60468","-0.01288","-0.00025"
"16.12500","1.60609","-0.05398","-0.00025"
"16.14000","1.60755","-0.07692","-0.00025"
"16.15500","1.60904","-0.07750","-0.00025"
"16.17000","1.61055","-0.01604","-0.00025"
"16.18500","1.61207","0.04900","-0.00025"
"16.20000","1.61358","0.02250","-0.00025"
"16.21500","1.61506","-0.05777","-0.00025"
"16.23000","1.61652","-0.07353","-0.00025"
"16.24500","1.61800","-0.06524","-0.00025"
"16.26000","1.61951","-0.11669","-0.00025"
"16.27500","1.62104","-0.08317","-0.00025"
"16.29000","1.62259","-0.01443","-0.00025"
"16.30500","1.62416","0.02016","-0.00026"
"16.32000","1.62572","-0.03976","-0.00025"
"16.33500","1.62721","-0.04306","-0.00025"
"16.35000","1.62864","-0.01750","-0.00025"
"16.36500","1.63010","-0.04401","-0.00025"
"16.38000","1.63160","-0.06335","-0.00025"
"16.39500","1.63314","-0.06360","-0.00025"
"16.41000","1.63469","-0.02585","-0.00025"
"16.42500","1.63623","-0.04243","-0.00025"
"16.44000","1.63772","-0.04361","-0.00025"
"16.45500","1.63919","-0.11094","-0.00025"
"16.47000","1.64066","-0.04301","-0.00025"
"16.48500","1.64218","0.02024","-0.00025"
"16.50000","1.64370","0.03291","-0.00025"
"16.51500","1.64525","0.04324","-0.00025"
"16.53000","1.64682","0.00556","-0.00025"
"16.54500","1.64836","-0.04426","-0.00026"
"16.56000","1.64983","-0.01697","-0.00026"
"16.57500","1.65125","-0.04484","-0.00025"
"16.59000","1.65271","-0.06854","-0.00025"
"16.60500","1.65423","-0.06899","-0.00025"
"16.62000","1.65577","-0.02467","-0.00025"
"16.63500","1.65731","-0.01191","-0.00025"
"16.65000","1.65884","-0.04883","-0.00025"
"16.66500","1.66033","-0.12260","-0.00025"
"16.68000","1.66177","-0.07143","-0.00025"
"16.69500","1.66318","-0.01045","-0.00025"
"16.71000","1.66462","0.03114","-0.00025"
"16.72500","1.66610","0.07319","-0.00025"
"16.74000","1.66761","0.03479","-0.00026"
"16.75500","1.66916","0.04512","-0.00026"
"16.77000","1.67072","0.03184","-0.00026"
"16.78500","1.67224","-0.00641","-0.00025"
"16.80000","1.67368","-0.02699","-0.00025"
"16.81500","1.67511","-0.04823","-0.00025"
"16.83000","1.67658","-0.04762","-0.00025"
"16.84500","1.67808","-0.06373","-0.00025"
"16.86000","1.67960","-0.10305","-0.00025"
"16.87500","1.68114","-0.09246","-0.00025"
"16.89000","1.68267","-0.04988","-0.00025"
"16.90500","1.68417","-0.05122","-0.00025"
"16.92000","1.68563","-0.03000","-0.00025"
"16.93500","1.68711","-0.02342","-0.00025"
"16.95000","1.68862","-0.01110","-0.00026"
"16.96500","1.69014","-0.08706","-0.00026"
"16.98000","1.69167","-0.16511","-0.00026"
"16.99500","1.69324","-0.08911","-0.00026"
"17.01000","1.69477","-0.02371","-0.00025"
"17.02500","1.69624","-0.01637","-0.00025"
"17.04000","1.69767","0.00399","-0.00025"
"17.05500","1.69915","0.02259","-0.00025"
"17.07000","1.70068","-0.06386","-0.00025"
"17.08500","1.70222","-0.10443","-0.00025"
"17.10000","1.70376","-0.14241","-0.00025"
"17.11500","1.70533","-0.17551","-0.00025"
"17.13000","1.70686","-0.14455","-0.00025"
"17.14500","1.70835","-0.09800","-0.00025"
"17.16000","1.70980","0.00223","-0.00026"
"17.17500","1.71128","0.02882","-0.00026"
"17.19000","1.71277","-0.02766","-0.00026"
"17.20500","1.71431","-0.08999","-0.00026"
"17.22000","1.71586","-0.09919","-0.00026"
"17.23500","1.71738","-0.10862","-0.00025"
"17.25000","1.71883","-0.03145","-0.00025"
"17.26500","1.72024","-0.02925","-0.00025"
"17.28000","1.72167","-0.07577","-0.00025"
"17.29500","1.72314","-0.06114","-0.00025"
"17.31000","1.72462","-0.01269","-0.00025"
"17.32500","1.72611","0.03990","-0.00025"
"17.34000","1.72763","0.04183","-0.00025"
"17.35500","1.72914","0.02205","-0.00025"
"17.37000","1.73062","0.06139","-0.00025"
"17.38500","1.73208","-0.00206","-0.00026"
"17.40000","1.73357","-0.09855","-0.00026"
"17.41500","1.73509","-0.10830","-0.00026"
"17.43000","1.73661","-0.09952","-0.00026"
"17.44500","1.73816","-0.04840","-0.00026"
"17.46000","1.73971","-0.00016","-0.00026"
"17.47500","1.74122","-0.04998","-0.00025"
"17.49000","1.74268","-0.14787","-0.00025"
"17.50500","1.74414","-0.13150","-0.00025"
"17.52000","1.74564","-0.10238","-0.00025"
"17.53500","1.74713","-0.02909","-0.00025"
"17.55000","1.74863","0.03586","-0.00025"
"17.56500","1.75016","0.01091","-0.00025"
"17.58000","1.75170","-0.06821","-0.00026"
"17.59500","1.75322","-0.06009","-0.00026"
"17.61000","1.75469","-0.01508","-0.00026"
"17.62500","1.75616","-0.05766","-0.00026"
"17.64000","1.75765","-0.05552","-0.00026"
"17.65500","1.75916","-0.06341","-0.00026"
"17.67000","1.76070","-0.06463","-0.00026"
"17.68500","1.76226","-0.05199","-0.00026"
"17.70000","1.76378","-0.09381","-0.00025"
"17.71500","1.76525","-0.12373","-0.00025"
"17.73000","1.76673","-0.08871","-0.00025"
"17.74500","1.76825","-0.12065","-0.00025"
"17.76000","1.76976","-0.16454","-0.00025"
"17.77500","1.77126","-0.08300","-0.00025"
"17.79000","1.77277","0.01255","-0.00025"
"17.80000","1.77379","0.04427","-0.00026"