File: archive/undergrad/433/Pressure Vessel/Specimen_RawData_8.csv
Time,Extension,Load,Strain Gage18
(s),(mm),(N),(mm/mm)
"0.00000","1.80062","0.13280","0.00000"
"0.01400","1.80062","0.06120","0.00000"
"0.02800","1.80065","-0.02680","0.00000"
"0.04200","1.80078","-0.07657","0.00000"
"0.05600","1.80109","-0.05104","0.00000"
"0.07000","1.80171","0.03346","0.00000"
"0.08400","1.80266","0.09582","0.00000"
"0.09800","1.80355","0.06817","0.00000"
"0.11200","1.80418","0.02895","0.00000"
"0.12600","1.80475","-0.00068","0.00000"
"0.14000","1.80560","0.02375","0.00000"
"0.15400","1.80693","0.00334","0.00000"
"0.16800","1.80873","0.01986","0.00000"
"0.18200","1.81076","0.00334","0.00001"
"0.19600","1.81277","0.01117","0.00001"
"0.21000","1.81466","0.02346","0.00000"
"0.22400","1.81637","0.04410","0.00000"
"0.23800","1.81794","0.05918","0.00000"
"0.25200","1.81942","0.11980","0.00000"
"0.26600","1.82088","0.06017","0.00000"
"0.28000","1.82231","0.00609","0.00000"
"0.29400","1.82371","-0.04894","0.00000"
"0.30800","1.82507","-0.02425","0.00000"
"0.32200","1.82645","0.06820","0.00000"
"0.33600","1.82786","0.07598","0.00000"
"0.35000","1.82929","0.09637","0.00000"
"0.36400","1.83073","0.05769","0.00000"
"0.37800","1.83218","0.04374","0.00000"
"0.39200","1.83359","0.04091","0.00000"
"0.40600","1.83495","0.07007","0.00001"
"0.42000","1.83629","0.07378","0.00001"
"0.43400","1.83765","0.04944","0.00000"
"0.44800","1.83905","-0.00016","0.00000"
"0.46200","1.84044","-0.05389","0.00000"
"0.47600","1.84184","-0.03684","0.00000"
"0.49000","1.84326","-0.00595","0.00000"
"0.50400","1.84469","-0.00354","0.00000"
"0.51800","1.84608","-0.00902","0.00000"
"0.53200","1.84745","-0.01356","0.00000"
"0.54600","1.84882","0.01345","0.00000"
"0.56000","1.85021","0.01385","0.00000"
"0.57400","1.85159","0.01747","0.00000"
"0.58800","1.85299","-0.00850","0.00000"
"0.60200","1.85442","-0.03659","0.00000"
"0.61600","1.85585","-0.01359","0.00000"
"0.63000","1.85724","0.02882","0.00000"
"0.64400","1.85860","0.00523","0.00000"
"0.65800","1.85997","-0.06378","0.00000"
"0.67200","1.86137","-0.06445","0.00000"
"0.68600","1.86279","-0.00586","0.00000"
"0.70000","1.86420","0.06009","0.00000"
"0.71400","1.86563","0.06112","0.00000"
"0.72800","1.86707","0.04598","0.00000"
"0.74200","1.86849","0.04798","0.00000"
"0.75600","1.86986","-0.03932","0.00000"
"0.77000","1.87122","-0.02926","0.00000"
"0.78400","1.87261","-0.00318","0.00000"
"0.79800","1.87401","-0.00011","0.00000"
"0.81200","1.87544","0.02498","0.00000"
"0.82600","1.87689","0.00270","0.00000"
"0.84000","1.87834","-0.00690","0.00000"
"0.85400","1.87976","-0.00025","0.00000"
"0.86800","1.88114","0.02806","0.00000"
"0.88200","1.88253","0.12962","0.00000"
"0.89600","1.88395","0.12340","0.00000"
"0.91000","1.88537","0.14234","0.00000"
"0.92400","1.88676","0.13165","0.00000"
"0.93800","1.88815","0.10430","0.00000"
"0.95200","1.88959","0.09550","0.00000"
"0.96600","1.89102","0.06971","0.00000"
"0.98000","1.89240","0.03081","0.00000"
"0.99400","1.89374","0.08277","0.00000"
"1.00800","1.89509","0.06048","0.00000"
"1.02200","1.89647","0.03439","0.00000"
"1.03600","1.89787","0.04632","0.00000"
"1.05000","1.89926","0.06978","0.00000"
"1.06400","1.90068","0.07472","0.00000"
"1.07800","1.90208","0.02893","0.00000"
"1.09200","1.90346","0.05875","0.00000"
"1.10600","1.90482","0.11754","0.00000"
"1.12000","1.90620","0.09956","0.00000"
"1.13400","1.90762","0.01271","0.00000"
"1.14800","1.90903","-0.04507","0.00000"
"1.16200","1.91043","-0.08057","0.00000"
"1.17600","1.91185","-0.11880","0.00000"
"1.19000","1.91326","-0.08826","0.00000"
"1.20400","1.91462","-0.05494","0.00000"
"1.21800","1.91595","-0.06837","0.00000"
"1.23200","1.91729","-0.06070","0.00000"
"1.24600","1.91868","0.00005","0.00000"
"1.26000","1.92012","0.09961","0.00000"
"1.27400","1.92158","0.13182","0.00000"
"1.28800","1.92304","0.07099","0.00000"
"1.30200","1.92449","0.02240","0.00000"
"1.31600","1.92588","-0.02791","0.00000"
"1.33000","1.92723","0.03899","0.00000"
"1.34400","1.92859","0.05917","0.00000"
"1.35800","1.93000","0.04853","0.00000"
"1.37200","1.93142","0.00668","0.00000"
"1.38600","1.93283","-0.02318","0.00000"
"1.40000","1.93426","0.02650","0.00000"
"1.41400","1.93572","-0.00901","0.00000"
"1.42800","1.93716","-0.02417","0.00000"
"1.44200","1.93855","-0.05123","0.00000"
"1.45600","1.93990","-0.07026","0.00000"
"1.47000","1.94129","-0.01589","0.00000"
"1.48400","1.94270","0.00499","0.00000"
"1.49800","1.94414","-0.00800","0.00000"
"1.51200","1.94557","0.00853","0.00000"
"1.52600","1.94699","-0.03598","0.00000"
"1.54000","1.94839","-0.05710","0.00000"
"1.55400","1.94977","-0.03926","0.00000"
"1.56800","1.95114","-0.01161","0.00000"
"1.58200","1.95252","0.01633","0.00000"
"1.59600","1.95391","0.02036","0.00000"
"1.61000","1.95530","0.03230","0.00000"
"1.62400","1.95670","0.02437","0.00000"
"1.63800","1.95813","-0.00504","0.00000"
"1.65200","1.95955","-0.01758","0.00000"
"1.66600","1.96091","-0.00553","0.00000"
"1.68000","1.96224","0.02985","0.00000"
"1.69400","1.96358","0.04469","0.00000"
"1.70800","1.96498","0.01571","0.00000"
"1.72200","1.96640","0.02437","0.00000"
"1.73600","1.96784","0.03687","0.00000"
"1.75000","1.96928","0.00462","0.00000"
"1.76400","1.97069","-0.02667","0.00000"
"1.77800","1.97204","-0.02176","0.00000"
"1.79200","1.97337","0.01393","0.00000"
"1.80600","1.97472","0.02728","0.00000"
"1.82000","1.97613","0.02584","0.00000"
"1.83400","1.97755","0.01954","0.00000"
"1.84800","1.97900","-0.00890","0.00000"
"1.86200","1.98047","-0.00281","0.00000"
"1.87600","1.98194","-0.01147","0.00000"
"1.89000","1.98334","0.01990","0.00000"
"1.90400","1.98468","0.01274","0.00000"
"1.91800","1.98599","-0.01081","0.00000"
"1.93200","1.98736","0.00068","0.00000"
"1.94600","1.98878","-0.00852","0.00000"
"1.96000","1.99022","-0.04791","0.00000"
"1.97400","1.99168","-0.03728","0.00000"
"1.98800","1.99313","-0.03886","0.00000"
"2.00200","1.99454","0.01519","0.00000"
"2.01600","1.99591","0.01527","0.00000"
"2.03000","1.99727","-0.03501","0.00000"
"2.04400","1.99866","0.01757","0.00000"
"2.05800","2.00007","0.06801","0.00000"
"2.07200","2.00149","0.11368","0.00000"
"2.08600","2.00295","0.12726","0.00000"
"2.10000","2.00441","0.07481","0.00000"
"2.11400","2.00583","0.03165","0.00000"
"2.12800","2.00717","0.00973","0.00000"
"2.14200","2.00849","0.02472","0.00000"
"2.15600","2.00986","-0.02836","0.00000"
"2.17000","2.01129","-0.07282","0.00001"
"2.18400","2.01273","0.00294","0.00001"
"2.19800","2.01416","0.00682","0.00000"
"2.21200","2.01560","0.01065","0.00000"
"2.22600","2.01701","0.02148","0.00000"
"2.24000","2.01837","0.05086","0.00000"
"2.25400","2.01969","0.04576","0.00000"
"2.26800","2.02104","0.05982","0.00000"
"2.28200","2.02242","0.04295","0.00000"
"2.29600","2.02383","0.00660","0.00000"
"2.31000","2.02526","0.02455","0.00000"
"2.32400","2.02672","-0.02790","0.00000"
"2.33800","2.02815","-0.03702","0.00000"
"2.35200","2.02952","0.00130","0.00000"
"2.36600","2.03083","-0.02708","0.00000"
"2.38000","2.03215","0.01036","0.00000"
"2.39400","2.03352","0.01312","0.00000"
"2.40800","2.03493","-0.03957","0.00000"
"2.42200","2.03636","-0.06708","0.00000"
"2.43600","2.03781","-0.05381","0.00000"
"2.45000","2.03926","-0.02487","0.00000"
"2.46400","2.04068","-0.00074","0.00000"
"2.47800","2.04206","0.04616","0.00000"
"2.49200","2.04343","0.05318","0.00000"
"2.50600","2.04481","0.08045","0.00000"
"2.52000","2.04620","0.06310","0.00000"
"2.53400","2.04761","0.02431","0.00000"
"2.54800","2.04904","-0.01238","0.00000"
"2.56200","2.05050","-0.01297","0.00000"
"2.57600","2.05191","-0.04862","0.00000"
"2.59000","2.05327","-0.05504","0.00000"
"2.60400","2.05461","-0.02643","0.00000"
"2.61800","2.05599","-0.05262","0.00000"
"2.63200","2.05743","-0.08660","0.00000"
"2.64600","2.05888","-0.06798","0.00000"
"2.66000","2.06034","-0.05320","0.00000"
"2.67400","2.06181","-0.03367","0.00000"
"2.68800","2.06326","-0.00385","0.00000"
"2.70200","2.06465","0.03765","0.00000"
"2.71600","2.06600","0.05894","0.00000"
"2.73000","2.06734","0.08903","0.00000"
"2.74400","2.06871","0.08449","0.00000"
"2.75800","2.07010","0.06363","0.00000"
"2.77200","2.07152","0.05297","0.00000"
"2.78600","2.07296","0.04140","0.00000"
"2.80000","2.07438","-0.02116","0.00000"
"2.81400","2.07575","-0.06475","0.00000"
"2.82800","2.07708","-0.01480","0.00000"
"2.84200","2.07843","0.01334","0.00000"
"2.85600","2.07981","0.05448","0.00000"
"2.87000","2.08120","0.08392","0.00000"
"2.88400","2.08260","0.11558","0.00000"
"2.89800","2.08402","0.04445","0.00000"
"2.91200","2.08546","0.01018","0.00000"
"2.92600","2.08686","0.02488","0.00000"
"2.94000","2.08822","0.03676","0.00000"
"2.95400","2.08959","0.06280","0.00000"
"2.96800","2.09097","0.06446","0.00000"
"2.98200","2.09237","0.04404","0.00000"
"2.99600","2.09377","-0.02463","0.00000"
"3.01000","2.09519","-0.06254","0.00000"
"3.02400","2.09662","-0.00157","0.00000"
"3.03800","2.09803","-0.00150","0.00000"
"3.05200","2.09939","0.03519","0.00000"
"3.06600","2.10076","0.04498","0.00000"
"3.08000","2.10217","0.01394","0.00000"
"3.09400","2.10359","0.06859","0.00000"
"3.10800","2.10501","0.09535","0.00000"
"3.12200","2.10644","0.07109","0.00000"
"3.13600","2.10788","0.05185","0.00000"
"3.15000","2.10931","0.04069","0.00000"
"3.16400","2.11069","0.04301","0.00000"
"3.17800","2.11205","0.04188","0.00000"
"3.19200","2.11342","0.07788","0.00000"
"3.20600","2.11482","0.12520","0.00000"
"3.22000","2.11623","0.11685","0.00000"
"3.23400","2.11766","0.09392","0.00000"
"3.24800","2.11911","0.01102","0.00000"
"3.26200","2.12053","-0.04333","0.00000"
"3.27600","2.12192","-0.08606","0.00000"
"3.29000","2.12330","-0.06088","0.00000"
"3.30400","2.12472","0.02755","0.00000"
"3.31800","2.12615","-0.02206","0.00000"
"3.33200","2.12756","-0.07293","0.00000"
"3.34600","2.12896","-0.04349","0.00000"
"3.36000","2.13040","0.04525","0.00000"
"3.37400","2.13184","0.05720","0.00000"
"3.38800","2.13323","0.09315","0.00000"
"3.40200","2.13457","0.08214","0.00000"
"3.41600","2.13591","0.00891","0.00000"
"3.43000","2.13728","-0.04363","0.00000"
"3.44400","2.13868","-0.02908","0.00000"
"3.45800","2.14008","-0.03787","0.00000"
"3.47200","2.14149","-0.04427","0.00000"
"3.48600","2.14290","-0.05034","0.00000"
"3.50000","2.14427","0.04280","0.00000"
"3.51400","2.14562","0.11059","0.00000"
"3.52800","2.14698","0.10984","0.00000"
"3.54200","2.14838","0.04778","0.00000"
"3.55600","2.14980","-0.02714","0.00000"
"3.57000","2.15120","-0.05378","0.00000"
"3.58400","2.15262","-0.02897","0.00000"
"3.59800","2.15404","-0.01285","0.00000"
"3.61200","2.15542","0.02659","0.00000"
"3.62600","2.15677","0.03017","0.00000"
"3.64000","2.15811","0.00124","0.00000"
"3.65400","2.15951","-0.02900","0.00000"
"3.66800","2.16095","0.00258","0.00000"
"3.68200","2.16240","0.06208","0.00000"
"3.69600","2.16386","0.07201","0.00000"
"3.71000","2.16531","0.08104","0.00000"
"3.72400","2.16671","0.08523","0.00000"
"3.73800","2.16806","0.07970","0.00000"
"3.75200","2.16942","0.08468","0.00000"
"3.76600","2.17083","0.04310","0.00000"
"3.78000","2.17226","-0.00749","0.00000"
"3.79400","2.17368","0.00488","0.00000"
"3.80800","2.17511","0.02548","0.00000"
"3.82200","2.17656","0.07514","0.00000"
"3.83600","2.17799","0.09068","0.00000"
"3.85000","2.17937","0.08373","0.00000"
"3.86400","2.18070","0.05357","0.00000"
"3.87800","2.18206","-0.03370","0.00000"
"3.89200","2.18347","-0.02123","0.00000"
"3.90600","2.18490","-0.00016","0.00000"
"3.92000","2.18635","-0.03311","0.00000"
"3.93400","2.18779","0.00128","0.00000"
"3.94800","2.18921","0.02576","0.00000"
"3.96200","2.19059","0.02667","0.00000"
"3.97600","2.19195","0.00280","0.00000"
"3.99000","2.19333","-0.04289","0.00000"
"4.00400","2.19471","-0.06624","0.00000"
"4.01800","2.19609","-0.07566","0.00000"
"4.03200","2.19748","-0.12696","0.00000"
"4.04600","2.19889","-0.11286","0.00000"
"4.06000","2.20030","-0.01844","0.00000"
"4.07400","2.20167","0.04173","0.00000"
"4.08800","2.20300","0.00080","0.00000"
"4.10200","2.20434","0.03310","0.00000"
"4.11600","2.20574","0.03065","0.00000"
"4.13000","2.20718","0.05618","0.00000"
"4.14400","2.20863","0.02635","0.00000"
"4.15800","2.21008","0.02730","0.00000"
"4.17200","2.21150","0.05926","0.00000"
"4.18600","2.21287","0.10586","0.00000"
"4.20000","2.21419","0.04019","0.00000"
"4.21400","2.21553","0.00004","0.00000"
"4.22800","2.21691","0.01101","0.00000"
"4.24200","2.21832","0.02251","0.00000"
"4.25600","2.21976","0.03958","0.00000"
"4.27000","2.22122","-0.01214","0.00000"
"4.28400","2.22269","0.03740","0.00000"
"4.29800","2.22412","0.10710","0.00000"
"4.31200","2.22548","0.09309","0.00000"
"4.32600","2.22681","0.03519","0.00000"
"4.34000","2.22818","-0.03414","0.00000"
"4.35400","2.22959","-0.03717","0.00000"
"4.36800","2.23103","0.00931","0.00000"
"4.38200","2.23248","0.10070","0.00000"
"4.39600","2.23392","0.11232","0.00000"
"4.41000","2.23533","0.07244","0.00000"
"4.42400","2.23671","0.07661","0.00000"
"4.43800","2.23808","0.05053","0.00000"
"4.45200","2.23947","0.03383","0.00000"
"4.46600","2.24089","0.01060","0.00000"
"4.48000","2.24232","-0.00977","0.00000"
"4.49400","2.24377","-0.00966","0.00000"
"4.50800","2.24524","0.02343","0.00000"
"4.52200","2.24665","0.09244","0.00000"
"4.53600","2.24799","0.09732","0.00000"
"4.55000","2.24929","0.03314","0.00000"
"4.56400","2.25064","-0.01844","0.00000"
"4.57800","2.25205","-0.02869","0.00000"
"4.59200","2.25350","-0.04335","0.00000"
"4.60600","2.25494","0.00436","0.00000"
"4.62000","2.25638","-0.02214","0.00000"
"4.63400","2.25779","-0.03434","0.00000"
"4.64800","2.25916","0.00250","0.00000"
"4.66200","2.26048","0.02887","0.00000"
"4.67600","2.26182","0.04732","0.00000"
"4.69000","2.26320","-0.00344","0.00000"
"4.70400","2.26461","-0.01573","0.00000"
"4.71800","2.26605","-0.04071","0.00000"
"4.73200","2.26751","0.01075","0.00000"
"4.74600","2.26895","0.05114","0.00000"
"4.76000","2.27034","0.00238","0.00000"
"4.77400","2.27167","-0.02012","0.00000"
"4.78800","2.27299","-0.00565","0.00000"
"4.80200","2.27435","0.01117","0.00000"
"4.81600","2.27575","-0.06912","0.00000"
"4.83000","2.27716","-0.12273","0.00000"
"4.84400","2.27860","-0.07948","0.00000"
"4.85800","2.28004","-0.03828","0.00000"
"4.87200","2.28147","-0.01551","0.00000"
"4.88600","2.28285","-0.00550","0.00000"
"4.90000","2.28421","-0.02699","0.00000"
"4.91400","2.28559","-0.02243","0.00000"
"4.92800","2.28698","0.01876","0.00000"
"4.94200","2.28839","0.01802","0.00000"
"4.95600","2.28983","0.00404","0.00000"
"4.97000","2.29129","0.02586","0.00000"
"4.98400","2.29272","0.05364","0.00000"
"4.99800","2.29409","0.04755","0.00000"
"5.01200","2.29543","-0.01407","0.00000"
"5.02600","2.29680","-0.02981","0.00000"
"5.04000","2.29822","0.03892","0.00000"
"5.05400","2.29965","0.05290","0.00000"
"5.06800","2.30108","-0.00109","0.00000"
"5.08200","2.30253","-0.04132","0.00000"
"5.09600","2.30398","-0.05611","0.00000"
"5.11000","2.30539","-0.02626","0.00000"
"5.12400","2.30677","0.01431","0.00000"
"5.13800","2.30813","0.05388","0.00000"
"5.15200","2.30952","0.05227","0.00000"
"5.16600","2.31092","0.04761","0.00000"
"5.18000","2.31235","0.03762","0.00000"
"5.19400","2.31380","0.03127","0.00000"
"5.20800","2.31522","-0.06488","0.00000"
"5.22200","2.31659","-0.13699","0.00000"
"5.23600","2.31791","-0.13184","0.00000"
"5.25000","2.31925","-0.10529","0.00001"
"5.26400","2.32062","-0.01061","0.00001"
"5.27800","2.32201","0.03967","0.00001"
"5.29200","2.32342","0.07815","0.00000"
"5.30600","2.32486","0.01551","0.00000"
"5.32000","2.32630","-0.01927","0.00000"
"5.33400","2.32770","-0.03240","0.00000"
"5.34800","2.32906","-0.02362","0.00000"
"5.36200","2.33040","0.02696","0.00000"
"5.37600","2.33178","-0.01112","0.00000"
"5.39000","2.33316","-0.02049","0.00000"
"5.40400","2.33457","-0.01162","0.00000"
"5.41800","2.33599","0.00650","0.00000"
"5.43200","2.33742","-0.00404","0.00000"
"5.44600","2.33883","0.05317","0.00000"
"5.46000","2.34021","0.11038","0.00001"
"5.47400","2.34157","0.13586","0.00001"
"5.48800","2.34297","0.12262","0.00001"
"5.50200","2.34438","0.10202","0.00001"
"5.51600","2.34579","0.05950","0.00001"
"5.53000","2.34720","0.04983","0.00000"
"5.54400","2.34865","0.09087","0.00000"
"5.55800","2.35010","0.08820","0.00000"
"5.57200","2.35151","0.11076","0.00000"
"5.58600","2.35288","0.07141","0.00000"
"5.60000","2.35425","0.09422","0.00000"
"5.61400","2.35563","0.10545","0.00000"
"5.62800","2.35704","0.12305","0.00000"
"5.64200","2.35847","0.09108","0.00000"
"5.65600","2.35992","0.03085","0.00000"
"5.67000","2.36135","-0.01747","0.00001"
"5.68400","2.36273","0.01613","0.00001"
"5.69800","2.36410","0.04019","0.00001"
"5.71200","2.36550","-0.00473","0.00001"
"5.72600","2.36693","-0.00898","0.00001"
"5.74000","2.36835","0.05990","0.00001"
"5.75400","2.36976","0.07018","0.00000"
"5.76800","2.37119","0.08682","0.00000"
"5.78200","2.37263","0.06873","0.00000"
"5.79600","2.37403","-0.00091","0.00000"
"5.81000","2.37537","-0.03088","0.00000"
"5.82400","2.37671","0.00016","0.00000"
"5.83800","2.37809","0.09156","0.00000"
"5.85200","2.37948","0.11834","0.00000"
"5.86600","2.38088","0.06640","0.00000"
"5.88000","2.38229","-0.02773","0.00000"
"5.89400","2.38370","-0.08040","0.00001"
"5.90800","2.38508","0.00053","0.00001"
"5.92200","2.38643","0.02444","0.00001"
"5.93600","2.38779","-0.00312","0.00001"
"5.95000","2.38918","-0.05214","0.00001"
"5.96400","2.39060","-0.03564","0.00001"
"5.97800","2.39201","-0.03573","0.00001"
"5.99200","2.39343","-0.05000","0.00000"
"6.00600","2.39486","-0.04368","0.00000"
"6.02000","2.39626","-0.04274","0.00000"
"6.03400","2.39761","-0.06521","0.00000"
"6.04800","2.39894","-0.03958","0.00000"
"6.06200","2.40031","-0.07460","0.00000"
"6.07600","2.40173","-0.05645","0.00000"
"6.09000","2.40317","0.01799","0.00000"
"6.10400","2.40462","0.06125","0.00001"
"6.11800","2.40608","0.02683","0.00001"
"6.13200","2.40749","0.01222","0.00001"
"6.14600","2.40885","-0.02828","0.00001"
"6.16000","2.41021","0.01519","0.00001"
"6.17400","2.41159","0.02696","0.00001"
"6.18800","2.41301","0.04469","0.00001"
"6.20200","2.41442","0.05820","0.00000"
"6.21600","2.41585","0.01830","0.00000"
"6.23000","2.41731","0.03500","0.00000"
"6.24400","2.41876","0.02520","0.00000"
"6.25800","2.42016","0.00103","0.00000"
"6.27200","2.42152","-0.05281","0.00000"
"6.28600","2.42288","-0.09043","0.00000"
"6.30000","2.42430","-0.07735","0.00000"
"6.31400","2.42574","-0.10271","0.00001"
"6.32800","2.42718","-0.13835","0.00001"
"6.34200","2.42861","-0.11883","0.00001"
"6.35600","2.43002","-0.05458","0.00001"
"6.37000","2.43140","-0.02569","0.00001"
"6.38400","2.43276","-0.00625","0.00001"
"6.39800","2.43413","-0.04088","0.00001"
"6.41200","2.43551","-0.05087","0.00001"
"6.42600","2.43690","-0.10144","0.00000"
"6.44000","2.43830","-0.09827","0.00000"
"6.45400","2.43972","-0.07281","0.00000"
"6.46800","2.44115","-0.11042","0.00000"
"6.48200","2.44253","-0.10878","0.00000"
"6.49600","2.44387","-0.05293","0.00000"
"6.51000","2.44521","-0.02439","0.00000"
"6.52400","2.44659","-0.04171","0.00000"
"6.53800","2.44801","-0.03504","0.00000"
"6.55200","2.44945","0.06291","0.00000"
"6.56600","2.45088","0.10969","0.00001"
"6.58000","2.45231","0.09273","0.00001"
"6.59400","2.45368","0.08126","0.00001"
"6.60800","2.45501","0.02320","0.00000"
"6.62200","2.45634","0.00874","0.00000"
"6.63600","2.45771","0.00071","0.00000"
"6.65000","2.45911","-0.04763","0.00000"
"6.66400","2.46054","-0.08105","0.00000"
"6.67800","2.46198","-0.07480","0.00000"
"6.69200","2.46345","-0.02334","0.00000"
"6.70600","2.46488","-0.05273","0.00000"
"6.72000","2.46625","-0.06919","0.00000"
"6.73400","2.46758","-0.06613","0.00000"
"6.74800","2.46893","-0.01801","0.00000"
"6.76200","2.47034","0.03809","0.00001"
"6.77600","2.47178","0.07463","0.00001"
"6.79000","2.47324","0.03553","0.00001"
"6.80400","2.47469","0.00178","0.00001"
"6.81800","2.47611","0.06514","0.00000"
"6.83200","2.47749","0.08964","0.00000"
"6.84600","2.47885","0.08482","0.00000"
"6.86000","2.48024","0.04566","-0.00001"
"6.87400","2.48166","-0.01473","-0.00001"
"6.88800","2.48310","0.01276","-0.00001"
"6.90200","2.48455","-0.01935","-0.00001"
"6.91600","2.48603","-0.06367","-0.00002"
"6.93000","2.48747","-0.03447","-0.00002"
"6.94400","2.48883","-0.05156","-0.00002"
"6.95800","2.49014","-0.03074","-0.00001"
"6.97200","2.49147","-0.01295","-0.00001"
"6.98600","2.49288","-0.04925","-0.00001"
"7.00000","2.49432","-0.05896","0.00000"
"7.01400","2.49576","-0.02546","0.00000"
"7.02800","2.49720","0.02058","0.00001"
"7.04200","2.49861","0.09874","0.00001"
"7.05600","2.49997","0.06875","0.00001"
"7.07000","2.50129","0.00795","0.00000"
"7.08400","2.50262","-0.03290","0.00000"
"7.09800","2.50399","-0.05708","0.00000"
"7.11200","2.50540","-0.05708","-0.00001"
"7.12600","2.50683","-0.03810","-0.00001"
"7.14000","2.50829","0.00933","-0.00001"
"7.15400","2.50974","-0.01120","-0.00001"
"7.16800","2.51114","-0.00052","-0.00001"
"7.18200","2.51248","-0.01549","-0.00001"
"7.19600","2.51379","-0.01272","-0.00001"
"7.21000","2.51514","0.00973","-0.00001"
"7.22400","2.51654","0.00354","-0.00001"
"7.23800","2.51795","-0.03629","-0.00001"
"7.25200","2.51938","-0.03741","-0.00001"
"7.26600","2.52083","0.01432","-0.00001"
"7.28000","2.52226","-0.00075","-0.00001"
"7.29400","2.52364","0.00868","-0.00001"
"7.30800","2.52501","0.04282","-0.00001"
"7.32200","2.52639","0.10243","-0.00001"
"7.33600","2.52779","0.08040","-0.00002"
"7.35000","2.52921","0.07919","-0.00002"
"7.36400","2.53065","0.06572","-0.00001"
"7.37800","2.53211","0.01541","-0.00001"
"7.39200","2.53355","-0.01503","-0.00001"
"7.40600","2.53491","-0.03580","-0.00001"
"7.42000","2.53624","-0.09573","-0.00001"
"7.43400","2.53760","-0.12574","-0.00001"
"7.44800","2.53901","-0.13906","-0.00001"
"7.46200","2.54046","-0.07636","-0.00001"
"7.47600","2.54191","-0.03566","-0.00001"
"7.49000","2.54336","0.01410","-0.00001"
"7.50400","2.54481","0.08682","-0.00001"
"7.51800","2.54622","0.10758","-0.00002"
"7.53200","2.54759","0.06173","-0.00002"
"7.54600","2.54894","0.03647","-0.00002"
"7.56000","2.55031","0.08906","-0.00002"
"7.57400","2.55171","0.04318","-0.00002"
"7.58800","2.55313","-0.04322","-0.00002"
"7.60200","2.55457","-0.07185","-0.00002"
"7.61600","2.55601","-0.02580","-0.00002"
"7.63000","2.55740","-0.00042","-0.00001"
"7.64400","2.55875","-0.00569","-0.00001"
"7.65800","2.56008","0.00795","-0.00001"
"7.67200","2.56145","0.04077","-0.00001"
"7.68600","2.56283","0.10685","-0.00001"
"7.70000","2.56423","0.11470","0.00000"
"7.71400","2.56564","0.08832","-0.00001"
"7.72800","2.56708","0.06585","-0.00001"
"7.74200","2.56848","0.00794","-0.00001"
"7.75600","2.56984","-0.01721","-0.00002"
"7.77000","2.57119","-0.02012","-0.00002"
"7.78400","2.57256","-0.01307","-0.00002"
"7.79800","2.57397","-0.01076","-0.00003"
"7.81200","2.57539","-0.00351","-0.00003"
"7.82600","2.57681","-0.00305","-0.00003"
"7.84000","2.57826","0.00933","-0.00003"
"7.85400","2.57967","-0.02647","-0.00002"
"7.86800","2.58105","-0.00022","-0.00002"
"7.88200","2.58241","0.03876","-0.00002"
"7.89600","2.58380","0.02083","-0.00002"
"7.91000","2.58521","0.03453","-0.00002"
"7.92400","2.58661","0.01718","-0.00002"
"7.93800","2.58801","-0.01671","-0.00002"
"7.95200","2.58945","-0.01065","-0.00001"
"7.96600","2.59089","-0.02103","-0.00001"
"7.98000","2.59230","-0.01721","-0.00001"
"7.99400","2.59367","0.01891","-0.00002"
"8.00800","2.59504","-0.00637","-0.00002"
"8.02200","2.59642","-0.02082","-0.00002"
"8.03600","2.59782","0.02532","-0.00002"
"8.05000","2.59924","-0.03227","-0.00002"
"8.06400","2.60070","-0.10040","-0.00002"
"8.07800","2.60214","-0.10952","-0.00002"
"8.09200","2.60354","-0.07463","-0.00002"
"8.10600","2.60491","-0.03404","-0.00002"
"8.12000","2.60630","-0.02554","-0.00002"
"8.13400","2.60772","-0.01824","-0.00002"
"8.14800","2.60914","-0.01149","-0.00002"
"8.16200","2.61053","-0.01826","-0.00002"
"8.17600","2.61195","-0.01435","-0.00002"
"8.19000","2.61339","-0.03034","-0.00002"
"8.20400","2.61479","-0.02855","-0.00003"
"8.21800","2.61615","0.02322","-0.00003"
"8.23200","2.61751","0.08505","-0.00003"
"8.24600","2.61889","0.06210","-0.00003"
"8.26000","2.62031","0.04824","-0.00003"
"8.27400","2.62172","0.03435","-0.00003"
"8.28800","2.62312","0.01437","-0.00003"
"8.30200","2.62453","-0.03953","-0.00002"
"8.31600","2.62591","-0.05176","-0.00002"
"8.33000","2.62726","-0.09225","-0.00002"
"8.34400","2.62860","-0.04575","-0.00002"
"8.35800","2.62999","0.00434","-0.00002"
"8.37200","2.63139","0.01650","-0.00002"
"8.38600","2.63279","-0.06384","-0.00002"
"8.40000","2.63420","-0.09904","-0.00002"
"8.41400","2.63563","-0.03592","-0.00003"
"8.42800","2.63704","-0.01812","-0.00003"
"8.44200","2.63840","0.01433","-0.00003"
"8.45600","2.63974","0.00223","-0.00003"
"8.47000","2.64110","0.03518","-0.00003"
"8.48400","2.64251","0.02376","-0.00003"
"8.49800","2.64395","0.02737","-0.00003"
"8.51200","2.64541","0.05667","-0.00003"
"8.52600","2.64686","0.06361","-0.00003"
"8.54000","2.64828","0.08777","-0.00003"
"8.55400","2.64965","0.04808","-0.00002"
"8.56800","2.65101","0.00257","-0.00002"
"8.58200","2.65240","-0.03325","-0.00002"
"8.59600","2.65382","0.01724","-0.00003"
"8.61000","2.65523","0.02944","-0.00004"
"8.62400","2.65664","-0.05447","-0.00008"
"8.63800","2.65808","-0.03295","-0.00013"
"8.65200","2.65952","0.02279","-0.00019"
"8.66600","2.66092","-0.02563","-0.00025"
"8.68000","2.66229","-0.03990","-0.00030"
"8.69400","2.66366","-0.04782","-0.00034"
"8.70800","2.66507","-0.00243","-0.00036"
"8.72200","2.66651","-0.00248","-0.00037"
"8.73600","2.66795","0.00798","-0.00037"
"8.75000","2.66940","0.01868","-0.00036"
"8.76400","2.67082","-0.02943","-0.00036"
"8.77800","2.67221","-0.12660","-0.00035"
"8.79200","2.67358","-0.16277","-0.00034"
"8.80600","2.67494","-0.07858","-0.00034"
"8.82000","2.67632","0.01347","-0.00034"
"8.83400","2.67771","-0.00545","-0.00034"
"8.84800","2.67910","0.02795","-0.00035"
"8.86200","2.68052","0.05189","-0.00035"
"8.87600","2.68195","0.01335","-0.00035"
"8.89000","2.68334","0.03629","-0.00035"
"8.90400","2.68467","0.02958","-0.00035"
"8.91800","2.68600","0.00544","-0.00035"
"8.93200","2.68737","0.01917","-0.00035"
"8.94600","2.68879","-0.00123","-0.00035"
"8.96000","2.69022","0.02758","-0.00033"
"8.97400","2.69165","0.00314","-0.00032"
"8.98800","2.69308","0.04842","-0.00031"
"9.00200","2.69447","0.06754","-0.00030"
"9.01600","2.69582","-0.05647","-0.00029"
"9.03000","2.69716","0.00593","-0.00028"
"9.04400","2.69853","0.03722","-0.00028"
"9.05800","2.69993","0.04294","-0.00028"
"9.07200","2.70135","-0.02273","-0.00029"
"9.08600","2.70278","0.00576","-0.00030"
"9.10000","2.70424","0.06687","-0.00032"
"9.11400","2.70569","0.01117","-0.00033"
"9.12800","2.70708","0.02331","-0.00033"
"9.14200","2.70843","-0.01874","-0.00034"
"9.15600","2.70979","-0.00679","-0.00034"
"9.17000","2.71120","-0.07738","-0.00035"
"9.18400","2.71263","-0.06503","-0.00035"
"9.19800","2.71408","0.02924","-0.00035"
"9.21200","2.71552","-0.05603","-0.00035"
"9.22600","2.71695","-0.11653","-0.00035"
"9.24000","2.71833","-0.06052","-0.00035"
"9.25400","2.71969","-0.07236","-0.00034"
"9.26800","2.72106","-0.04878","-0.00033"
"9.28200","2.72247","0.02342","-0.00034"
"9.29600","2.72389","0.09232","-0.00035"
"9.31000","2.72533","0.04749","-0.00035"
"9.32400","2.72680","-0.05414","-0.00035"
"9.33800","2.72824","-0.10899","-0.00035"
"9.35200","2.72962","-0.16001","-0.00036"
"9.36600","2.73094","-0.08438","-0.00036"
"9.38000","2.73227","0.01789","-0.00037"
"9.39400","2.73367","0.05651","-0.00037"
"9.40800","2.73511","-0.04889","-0.00037"
"9.42200","2.73656","-0.07059","-0.00037"
"9.43600","2.73799","-0.08699","-0.00037"
"9.45000","2.73941","-0.08190","-0.00037"
"9.46400","2.74078","-0.03601","-0.00037"
"9.47800","2.74211","-0.00663","-0.00037"
"9.49200","2.74343","-0.03106","-0.00037"
"9.50600","2.74479","-0.04594","-0.00037"
"9.52000","2.74619","-0.04456","-0.00038"
"9.53400","2.74761","-0.06398","-0.00038"
"9.54800","2.74906","-0.10965","-0.00038"
"9.56200","2.75052","-0.08691","-0.00039"
"9.57600","2.75194","-0.06786","-0.00039"
"9.59000","2.75330","-0.04510","-0.00038"
"9.60400","2.75461","-0.04976","-0.00038"
"9.61800","2.75596","-0.03168","-0.00038"
"9.63200","2.75736","0.01887","-0.00038"
"9.64600","2.75878","0.01412","-0.00037"
"9.66000","2.76021","0.05367","-0.00037"
"9.67400","2.76165","0.02288","-0.00037"
"9.68800","2.76308","0.02416","-0.00037"
"9.70200","2.76448","0.02357","-0.00037"
"9.71600","2.76584","-0.00648","-0.00038"
"9.73000","2.76720","-0.02892","-0.00038"
"9.74400","2.76860","-0.08446","-0.00038"
"9.75800","2.77001","-0.09545","-0.00039"
"9.77200","2.77144","-0.07394","-0.00039"
"9.78600","2.77290","-0.03116","-0.00039"
"9.80000","2.77435","-0.03724","-0.00039"
"9.81400","2.77573","-0.00609","-0.00039"
"9.82800","2.77706","-0.01929","-0.00039"
"9.84200","2.77840","-0.00314","-0.00038"
"9.85600","2.77980","-0.06339","-0.00038"
"9.87000","2.78124","-0.02876","-0.00038"
"9.88400","2.78268","0.03073","-0.00038"
"9.89800","2.78413","0.02771","-0.00038"
"9.91200","2.78559","0.04743","-0.00039"
"9.92600","2.78701","0.07081","-0.00039"
"9.94000","2.78838","0.05324","-0.00039"
"9.95400","2.78973","0.02614","-0.00039"
"9.96800","2.79109","-0.01761","-0.00039"
"9.98200","2.79248","-0.05327","-0.00039"
"9.99600","2.79390","-0.08581","-0.00039"
"10.01000","2.79535","-0.07321","-0.00039"
"10.02400","2.79681","-0.08207","-0.00039"
"10.03800","2.79821","-0.04979","-0.00039"
"10.05200","2.79957","-0.03295","-0.00039"
"10.06600","2.80092","0.00291","-0.00039"
"10.08000","2.80228","0.02068","-0.00039"
"10.09400","2.80366","-0.01611","-0.00039"
"10.10800","2.80504","-0.03359","-0.00039"
"10.12200","2.80644","-0.01546","-0.00038"
"10.13600","2.80787","-0.00117","-0.00038"
"10.15000","2.80929","0.05138","-0.00039"
"10.16400","2.81068","0.02466","-0.00039"
"10.17800","2.81203","0.00967","-0.00039"
"10.19200","2.81340","0.09201","-0.00039"
"10.20600","2.81479","0.11903","-0.00039"
"10.22000","2.81618","0.00248","-0.00039"
"10.23400","2.81760","-0.04501","-0.00039"
"10.24800","2.81904","-0.06202","-0.00039"
"10.26200","2.82047","-0.09267","-0.00039"
"10.27600","2.82185","-0.05861","-0.00039"
"10.29000","2.82321","0.02518","-0.00039"
"10.30400","2.82458","0.12199","-0.00038"
"10.31800","2.82598","0.11253","-0.00038"
"10.33200","2.82739","0.02953","-0.00038"
"10.34600","2.82879","-0.01910","-0.00038"
"10.36000","2.83022","-0.05720","-0.00038"
"10.37400","2.83166","-0.14716","-0.00039"
"10.38800","2.83307","-0.08764","-0.00039"
"10.40200","2.83444","-0.01787","-0.00039"
"10.41600","2.83581","-0.00124","-0.00039"
"10.43000","2.83720","0.02182","-0.00039"
"10.44400","2.83860","0.05671","-0.00039"
"10.45800","2.84004","0.03462","-0.00039"
"10.47200","2.84149","0.04300","-0.00039"
"10.48600","2.84295","0.06733","-0.00039"
"10.50000","2.84436","0.04011","-0.00039"
"10.51400","2.84574","0.04952","-0.00039"
"10.52800","2.84713","0.04904","-0.00038"
"10.54200","2.84855","0.00043","-0.00038"
"10.55600","2.84995","-0.03159","-0.00038"
"10.57000","2.85134","0.01562","-0.00038"
"10.58400","2.85275","0.07411","-0.00038"
"10.59800","2.85419","0.13076","-0.00039"
"10.61200","2.85561","0.10195","-0.00039"
"10.62600","2.85698","0.01544","-0.00039"
"10.64000","2.85833","-0.07573","-0.00039"
"10.65400","2.85970","-0.09509","-0.00039"
"10.66800","2.86109","-0.04690","-0.00039"
"10.68200","2.86250","-0.04334","-0.00039"
"10.69600","2.86390","-0.01590","-0.00039"
"10.71000","2.86531","-0.03305","-0.00039"
"10.72400","2.86670","-0.04561","-0.00039"
"10.73800","2.86805","-0.05435","-0.00039"
"10.75200","2.86939","0.01649","-0.00038"
"10.76600","2.87077","0.00991","-0.00038"
"10.78000","2.87218","-0.01419","-0.00038"
"10.79400","2.87359","0.03003","-0.00038"
"10.80800","2.87500","0.03393","-0.00038"
"10.82200","2.87642","0.03540","-0.00039"
"10.83600","2.87783","0.04416","-0.00039"
"10.85000","2.87919","0.00843","-0.00039"
"10.86400","2.88053","-0.04553","-0.00039"
"10.87800","2.88189","-0.00588","-0.00039"
"10.89200","2.88331","0.01306","-0.00039"
"10.90600","2.88476","0.04005","-0.00039"
"10.92000","2.88622","0.06942","-0.00039"
"10.93400","2.88768","0.06073","-0.00039"
"10.94800","2.88911","0.05871","-0.00039"
"10.96200","2.89048","0.02282","-0.00039"
"10.97600","2.89183","-0.03182","-0.00039"
"10.99000","2.89321","-0.06064","-0.00039"
"11.00400","2.89462","-0.03592","-0.00039"
"11.01800","2.89603","-0.05216","-0.00039"
"11.03200","2.89745","-0.03622","-0.00039"
"11.04600","2.89889","-0.02261","-0.00039"
"11.06000","2.90034","-0.04263","-0.00039"
"11.07400","2.90176","-0.01314","-0.00039"
"11.08800","2.90312","0.02237","-0.00039"
"11.10200","2.90447","0.05294","-0.00039"
"11.11600","2.90586","0.05710","-0.00039"
"11.13000","2.90729","-0.01491","-0.00039"
"11.14400","2.90874","0.00044","-0.00039"
"11.15800","2.91019","0.02629","-0.00039"
"11.17200","2.91162","0.05777","-0.00039"
"11.18600","2.91301","0.01185","-0.00039"
"11.20000","2.91436","0.00837","-0.00039"
"11.21400","2.91572","0.00692","-0.00039"
"11.22800","2.91709","0.00660","-0.00039"
"11.24200","2.91849","-0.03689","-0.00039"
"11.25600","2.91989","-0.05537","-0.00039"
"11.27000","2.92130","-0.04699","-0.00039"
"11.28400","2.92273","-0.04162","-0.00039"
"11.29800","2.92412","0.00673","-0.00039"
"11.31200","2.92546","0.00113","-0.00039"
"11.32600","2.92678","-0.02945","-0.00039"
"11.34000","2.92815","-0.04008","-0.00039"
"11.35400","2.92957","0.03193","-0.00039"
"11.36800","2.93102","0.07945","-0.00039"
"11.38200","2.93247","0.03277","-0.00039"
"11.39600","2.93392","0.01957","-0.00039"
"11.41000","2.93533","-0.00175","-0.00039"
"11.42400","2.93669","0.04982","-0.00039"
"11.43800","2.93801","0.07465","-0.00039"
"11.45200","2.93936","-0.02361","-0.00039"
"11.46600","2.94074","-0.07241","-0.00039"
"11.48000","2.94215","-0.10349","-0.00039"
"11.49400","2.94358","-0.09800","-0.00039"
"11.50800","2.94505","-0.01755","-0.00039"
"11.52200","2.94650","0.03136","-0.00039"
"11.53600","2.94790","0.01296","-0.00039"
"11.55000","2.94924","0.03029","-0.00040"
"11.56400","2.95059","0.08020","-0.00039"
"11.57800","2.95198","0.07338","-0.00039"
"11.59200","2.95341","0.04099","-0.00039"
"11.60600","2.95486","0.02950","-0.00039"
"11.62000","2.95630","-0.02319","-0.00039"
"11.63400","2.95772","-0.02296","-0.00039"
"11.64800","2.95910","0.00527","-0.00039"
"11.66200","2.96046","0.06768","-0.00039"
"11.67600","2.96184","0.06900","-0.00039"
"11.69000","2.96326","-0.02582","-0.00039"
"11.70400","2.96469","-0.03428","-0.00039"
"11.71800","2.96613","-0.01400","-0.00039"
"11.73200","2.96759","0.01493","-0.00039"
"11.74600","2.96904","-0.01365","-0.00039"
"11.76000","2.97043","-0.11898","-0.00040"
"11.77400","2.97176","-0.15018","-0.00040"
"11.78800","2.97309","-0.10027","-0.00040"
"11.80200","2.97448","0.00235","-0.00039"
"11.81600","2.97592","0.02093","-0.00039"
"11.83000","2.97737","0.00677","-0.00039"
"11.84400","2.97880","0.01767","-0.00039"
"11.85800","2.98023","0.07342","-0.00039"
"11.87200","2.98162","0.09211","-0.00039"
"11.88600","2.98295","0.04538","-0.00039"
"11.90000","2.98427","-0.01763","-0.00039"
"11.91400","2.98562","-0.05642","-0.00039"
"11.92800","2.98702","-0.04450","-0.00039"
"11.94200","2.98844","-0.02031","-0.00039"
"11.95600","2.98988","-0.02474","-0.00039"
"11.97000","2.99133","-0.07909","-0.00040"
"11.98400","2.99276","-0.13371","-0.00040"
"11.99800","2.99411","-0.11498","-0.00040"
"12.01200","2.99542","-0.07350","-0.00040"
"12.02600","2.99674","-0.01207","-0.00040"
"12.04000","2.99812","-0.05048","-0.00039"
"12.05400","2.99952","-0.03067","-0.00039"
"12.06800","3.00094","-0.02396","-0.00039"
"12.08200","3.00238","-0.05770","-0.00039"
"12.09600","3.00382","-0.05757","-0.00039"
"12.11000","3.00523","-0.07367","-0.00039"
"12.12400","3.00661","0.00457","-0.00039"
"12.13800","3.00798","0.04360","-0.00039"
"12.15200","3.00938","0.01751","-0.00039"
"12.16600","3.01079","-0.04167","-0.00039"
"12.18000","3.01221","-0.04437","-0.00040"
"12.19400","3.01366","-0.00225","-0.00040"
"12.20800","3.01511","0.04334","-0.00040"
"12.22200","3.01652","-0.01068","-0.00040"
"12.23600","3.01787","-0.03351","-0.00040"
"12.25000","3.01922","-0.03244","-0.00040"
"12.26400","3.02062","-0.04501","-0.00039"
"12.27800","3.02206","-0.07825","-0.00039"
"12.29200","3.02350","-0.02012","-0.00039"
"12.30600","3.02496","-0.00681","-0.00039"
"12.32000","3.02641","-0.05957","-0.00039"
"12.33400","3.02784","-0.10130","-0.00039"
"12.34800","3.02921","-0.09841","-0.00039"
"12.36200","3.03055","-0.06993","-0.00039"
"12.37600","3.03191","-0.01305","-0.00039"
"12.39000","3.03330","0.03317","-0.00039"
"12.40400","3.03472","0.06678","-0.00040"
"12.41800","3.03617","0.04976","-0.00040"
"12.43200","3.03762","-0.03145","-0.00040"
"12.44600","3.03902","-0.08942","-0.00040"
"12.46000","3.04037","-0.06767","-0.00040"
"12.47400","3.04169","-0.07163","-0.00040"
"12.48800","3.04304","-0.10777","-0.00039"
"12.50200","3.04442","-0.15119","-0.00039"
"12.51600","3.04581","-0.13014","-0.00039"
"12.53000","3.04721","-0.10246","-0.00039"
"12.54400","3.04865","-0.02860","-0.00039"
"12.55800","3.05008","-0.02130","-0.00039"
"12.57200","3.05147","-0.02914","-0.00039"
"12.58600","3.05283","-0.01089","-0.00039"
"12.60000","3.05419","0.00140","-0.00039"
"12.61400","3.05558","-0.01763","-0.00039"
"12.62800","3.05697","-0.06862","-0.00040"
"12.64200","3.05837","-0.01370","-0.00040"
"12.65600","3.05981","-0.03450","-0.00040"
"12.67000","3.06124","-0.03365","-0.00040"
"12.68400","3.06265","-0.04779","-0.00040"
"12.69800","3.06403","-0.01251","-0.00040"
"12.71200","3.06542","-0.01303","-0.00039"
"12.72600","3.06684","-0.01796","-0.00039"
"12.74000","3.06825","-0.00715","-0.00039"
"12.75400","3.06965","-0.05336","-0.00039"
"12.76800","3.07107","-0.01985","-0.00039"
"12.78200","3.07250","0.01324","-0.00039"
"12.79600","3.07390","0.04222","-0.00039"
"12.81000","3.07526","0.02137","-0.00039"
"12.82400","3.07662","-0.00256","-0.00039"
"12.83800","3.07800","0.01515","-0.00040"
"12.85200","3.07940","-0.02865","-0.00040"
"12.86600","3.08083","-0.03502","-0.00040"
"12.88000","3.08228","-0.05619","-0.00040"
"12.89400","3.08374","-0.09681","-0.00040"
"12.90800","3.08515","-0.10435","-0.00040"
"12.92200","3.08652","-0.05732","-0.00040"
"12.93600","3.08790","-0.01043","-0.00039"
"12.95000","3.08932","-0.02454","-0.00039"
"12.96400","3.09074","-0.00545","-0.00039"
"12.97800","3.09213","-0.01946","-0.00039"
"12.99200","3.09354","-0.03469","-0.00039"
"13.00600","3.09499","-0.03371","-0.00039"
"13.02000","3.09642","0.00920","-0.00039"
"13.03400","3.09779","-0.00106","-0.00039"
"13.04800","3.09913","0.00713","-0.00039"
"13.06200","3.10048","-0.02063","-0.00040"
"13.07600","3.10187","0.00072","-0.00040"
"13.09000","3.10327","0.02785","-0.00040"
"13.10400","3.10468","-0.00383","-0.00040"
"13.11800","3.10610","0.01124","-0.00040"
"13.13200","3.10750","-0.00419","-0.00040"
"13.14600","3.10887","-0.02079","-0.00040"
"13.16000","3.11022","-0.03450","-0.00039"
"13.17400","3.11161","-0.03607","-0.00039"
"13.18800","3.11302","-0.04845","-0.00039"
"13.20200","3.11444","-0.06079","-0.00039"
"13.21600","3.11585","-0.07354","-0.00039"
"13.23000","3.11726","-0.10259","-0.00039"
"13.24400","3.11866","-0.07351","-0.00039"
"13.25800","3.12002","-0.06167","-0.00039"
"13.27200","3.12135","-0.09962","-0.00039"
"13.28600","3.12269","-0.08458","-0.00040"
"13.30000","3.12409","-0.09406","-0.00040"
"13.31400","3.12554","-0.11703","-0.00040"
"13.32800","3.12700","-0.11855","-0.00040"
"13.34200","3.12847","-0.09725","-0.00040"
"13.35600","3.12992","0.00121","-0.00040"
"13.37000","3.13131","0.06101","-0.00040"
"13.38400","3.13266","0.04494","-0.00039"
"13.39800","3.13402","0.00023","-0.00039"
"13.41200","3.13542","-0.06735","-0.00039"
"13.42600","3.13683","-0.08410","-0.00039"
"13.44000","3.13824","-0.02452","-0.00039"
"13.45400","3.13967","0.04080","-0.00039"
"13.46800","3.14112","0.02423","-0.00039"
"13.48200","3.14255","0.00868","-0.00039"
"13.49600","3.14393","0.08302","-0.00040"
"13.51000","3.14527","0.08431","-0.00040"
"13.52400","3.14666","-0.05185","-0.00040"
"13.53800","3.14809","-0.09581","-0.00040"
"13.55200","3.14954","-0.12951","-0.00040"
"13.56600","3.15099","-0.08860","-0.00040"
"13.58000","3.15243","-0.08346","-0.00040"
"13.59400","3.15383","-0.02701","-0.00040"
"13.60800","3.15521","0.03355","-0.00039"
"13.62200","3.15658","0.03836","-0.00039"
"13.63600","3.15796","-0.02713","-0.00039"
"13.65000","3.15935","-0.09152","-0.00039"
"13.66400","3.16073","-0.04461","-0.00039"
"13.67800","3.16212","-0.01358","-0.00039"
"13.69200","3.16353","-0.02419","-0.00039"
"13.70600","3.16493","0.04562","-0.00039"
"13.72000","3.16629","0.11725","-0.00040"
"13.73400","3.16762","0.07616","-0.00040"
"13.74800","3.16898","0.05418","-0.00040"
"13.76200","3.17038","0.00782","-0.00040"
"13.77600","3.17181","-0.02703","-0.00040"
"13.79000","3.17325","-0.02143","-0.00040"
"13.80400","3.17469","-0.04780","-0.00040"
"13.81800","3.17610","-0.06078","-0.00039"
"13.83200","3.17745","-0.04229","-0.00039"
"13.84600","3.17878","-0.02134","-0.00039"
"13.86000","3.18012","0.03370","-0.00039"
"13.87400","3.18151","0.05954","-0.00039"
"13.88800","3.18292","0.06013","-0.00039"
"13.90200","3.18436","0.07143","-0.00039"
"13.91600","3.18582","0.05549","-0.00039"
"13.93000","3.18729","0.04520","-0.00039"
"13.94400","3.18871","0.05781","-0.00039"
"13.95800","3.19006","0.04354","-0.00039"
"13.97200","3.19139","-0.03718","-0.00039"
"13.98600","3.19277","-0.06316","-0.00039"
"14.00000","3.19418","-0.02049","-0.00039"
"14.01400","3.19562","-0.03125","-0.00039"
"14.02800","3.19706","-0.05543","-0.00039"
"14.04200","3.19850","-0.11303","-0.00039"
"14.05600","3.19991","-0.10322","-0.00038"
"14.07000","3.20128","-0.04955","-0.00038"
"14.08400","3.20265","-0.03681","-0.00038"
"14.09800","3.20406","-0.05201","-0.00038"
"14.11200","3.20548","-0.09430","-0.00038"
"14.12600","3.20692","-0.10617","-0.00038"
"14.14000","3.20838","-0.09059","-0.00038"
"14.15400","3.20985","-0.10121","-0.00038"
"14.16800","3.21125","-0.09070","-0.00038"
"14.18200","3.21259","-0.07943","-0.00037"
"14.19600","3.21390","-0.06245","-0.00037"
"14.21000","3.21527","-0.01293","-0.00037"
"14.22400","3.21669","0.00742","-0.00037"
"14.23800","3.21813","0.00074","-0.00037"
"14.25200","3.21957","0.00233","-0.00036"
"14.26600","3.22100","0.00414","-0.00036"
"14.28000","3.22240","0.00149","-0.00036"
"14.29400","3.22375","-0.04790","-0.00036"
"14.30800","3.22507","-0.04279","-0.00036"
"14.32200","3.22641","-0.01034","-0.00036"
"14.33600","3.22779","0.00728","-0.00036"
"14.35000","3.22920","-0.04020","-0.00036"
"14.36400","3.23063","-0.05321","-0.00037"
"14.37800","3.23209","0.00491","-0.00037"
"14.39200","3.23353","0.03693","-0.00037"
"14.40600","3.23490","0.06876","-0.00037"
"14.42000","3.23622","0.02800","-0.00037"
"14.43400","3.23755","-0.02684","-0.00037"
"14.44800","3.23892","-0.05550","-0.00037"
"14.46200","3.24034","-0.09315","-0.00037"
"14.47600","3.24176","-0.08916","-0.00037"
"14.49000","3.24320","-0.10408","-0.00037"
"14.50400","3.24464","-0.06620","-0.00037"
"14.51800","3.24605","0.00604","-0.00036"
"14.53200","3.24743","0.00596","-0.00036"
"14.54600","3.24879","0.02207","-0.00036"
"14.56000","3.25017","0.00891","-0.00036"
"14.57400","3.25156","0.00704","-0.00037"
"14.58800","3.25296","-0.02985","-0.00037"
"14.60200","3.25439","-0.03242","-0.00037"
"14.61600","3.25584","-0.08046","-0.00037"
"14.63000","3.25726","-0.03637","-0.00037"
"14.64400","3.25863","-0.01234","-0.00037"
"14.65800","3.25998","-0.02021","-0.00037"
"14.67200","3.26138","-0.01914","-0.00037"
"14.68600","3.26281","-0.02419","-0.00037"
"14.70000","3.26426","0.00998","-0.00037"
"14.71400","3.26570","0.01789","-0.00037"
"14.72800","3.26717","-0.05531","-0.00037"
"14.74200","3.26861","-0.07923","-0.00036"
"14.75600","3.27001","-0.03902","-0.00036"
"14.77000","3.27137","-0.04192","-0.00036"
"14.78400","3.27272","-0.09510","-0.00037"
"14.79800","3.27410","-0.05746","-0.00037"
"14.81200","3.27550","0.01115","-0.00037"
"14.82600","3.27693","-0.00469","-0.00037"
"14.84000","3.27838","-0.10996","-0.00037"
"14.85400","3.27979","-0.16499","-0.00037"
"14.86800","3.28115","-0.12205","-0.00037"
"14.88200","3.28248","-0.08819","-0.00037"
"14.89600","3.28382","-0.02624","-0.00037"
"14.91000","3.28521","0.00256","-0.00037"
"14.92400","3.28661","-0.00724","-0.00037"
"14.93800","3.28802","0.00373","-0.00037"
"14.95200","3.28945","0.01358","-0.00037"
"14.96600","3.29089","-0.04705","-0.00037"
"14.98000","3.29229","-0.05043","-0.00037"
"14.99400","3.29365","-0.00941","-0.00037"
"15.00800","3.29501","-0.00036","-0.00037"
"15.02200","3.29640","-0.05126","-0.00037"
"15.03600","3.29780","-0.04439","-0.00038"
"15.05000","3.29920","-0.02452","-0.00038"
"15.06400","3.30063","-0.02120","-0.00038"
"15.07800","3.30206","-0.00314","-0.00038"
"15.09200","3.30347","0.03793","-0.00038"
"15.10600","3.30483","0.03330","-0.00038"
"15.12000","3.30620","0.00265","-0.00038"
"15.13400","3.30761","0.04542","-0.00038"
"15.14800","3.30901","-0.00964","-0.00038"
"15.16200","3.31041","-0.08614","-0.00038"
"15.17600","3.31181","-0.10099","-0.00037"
"15.19000","3.31325","-0.07142","-0.00037"
"15.20400","3.31467","-0.06623","-0.00037"
"15.21800","3.31607","-0.10755","-0.00037"
"15.23200","3.31744","-0.10590","-0.00038"
"15.24600","3.31882","-0.04452","-0.00038"
"15.26000","3.32022","-0.00692","-0.00038"
"15.27400","3.32164","-0.03004","-0.00038"
"15.28800","3.32307","-0.07220","-0.00038"
"15.30200","3.32452","-0.08358","-0.00038"
"15.31600","3.32594","-0.03871","-0.00038"
"15.33000","3.32731","-0.08406","-0.00038"
"15.34400","3.32869","-0.09649","-0.00038"
"15.35800","3.33011","-0.08025","-0.00038"
"15.37200","3.33154","-0.00288","-0.00038"
"15.38600","3.33294","0.02180","-0.00038"
"15.40000","3.33435","0.05689","-0.00038"
"15.41400","3.33578","0.08203","-0.00038"
"15.42800","3.33722","0.03323","-0.00038"
"15.44200","3.33860","0.02347","-0.00038"
"15.45600","3.33995","0.04440","-0.00038"
"15.47000","3.34131","-0.01840","-0.00038"
"15.48400","3.34270","-0.06518","-0.00038"
"15.49800","3.34410","-0.01700","-0.00039"
"15.51200","3.34551","-0.01541","-0.00039"
"15.52600","3.34692","-0.04729","-0.00039"
"15.54000","3.34833","-0.10425","-0.00039"
"15.55400","3.34970","-0.10726","-0.00039"
"15.56800","3.35105","-0.10776","-0.00039"
"15.58200","3.35242","-0.07481","-0.00038"
"15.59600","3.35383","-0.08185","-0.00038"
"15.61000","3.35524","-0.04959","-0.00038"
"15.62400","3.35665","-0.06519","-0.00038"
"15.63800","3.35807","-0.14420","-0.00038"
"15.65200","3.35948","-0.08252","-0.00038"
"15.66600","3.36084","0.00731","-0.00038"
"15.68000","3.36216","0.04714","-0.00038"
"15.69400","3.36349","0.05963","-0.00038"
"15.70800","3.36487","0.04214","-0.00039"
"15.72200","3.36631","0.00435","-0.00039"
"15.73600","3.36777","0.02812","-0.00039"
"15.75000","3.36923","0.04151","-0.00039"
"15.76400","3.37067","0.04012","-0.00039"
"15.77800","3.37206","-0.02972","-0.00039"
"15.79200","3.37342","-0.03502","-0.00039"
"15.80600","3.37478","0.02186","-0.00038"
"15.82000","3.37619","-0.00682","-0.00038"
"15.83400","3.37762","-0.00954","-0.00038"
"15.84800","3.37905","0.05052","-0.00038"
"15.86200","3.38048","0.05683","-0.00038"
"15.87600","3.38194","0.04970","-0.00038"
"15.89000","3.38337","0.00003","-0.00038"
"15.90400","3.38476","-0.02861","-0.00038"
"15.91800","3.38611","-0.12334","-0.00039"
"15.93200","3.38748","-0.10848","-0.00039"
"15.94600","3.38889","-0.04887","-0.00039"
"15.96000","3.39033","0.01237","-0.00039"
"15.97400","3.39177","0.01179","-0.00039"
"15.98800","3.39321","-0.00533","-0.00039"
"16.00200","3.39463","0.01346","-0.00039"
"16.01600","3.39601","0.01949","-0.00039"
"16.03000","3.39738","0.01438","-0.00039"
"16.04400","3.39875","-0.03441","-0.00038"
"16.05800","3.40014","-0.05323","-0.00038"
"16.07200","3.40151","-0.05543","-0.00038"
"16.08600","3.40290","-0.05247","-0.00038"
"16.10000","3.40432","-0.03818","-0.00038"
"16.11400","3.40573","-0.00394","-0.00038"
"16.12800","3.40709","0.00225","-0.00039"
"16.14200","3.40842","0.02861","-0.00039"
"16.15600","3.40976","-0.00354","-0.00039"
"16.17000","3.41115","-0.01468","-0.00039"
"16.18400","3.41258","-0.07743","-0.00039"
"16.19800","3.41401","-0.09728","-0.00039"
"16.21200","3.41545","-0.10293","-0.00039"
"16.22600","3.41687","-0.10026","-0.00039"
"16.24000","3.41824","-0.04975","-0.00039"
"16.25400","3.41958","-0.03356","-0.00039"
"16.26800","3.42093","0.02392","-0.00039"
"16.28200","3.42232","0.07002","-0.00038"
"16.29600","3.42373","0.09804","-0.00038"
"16.31000","3.42516","0.09809","-0.00038"
"16.32400","3.42662","0.04268","-0.00038"
"16.33800","3.42810","0.02912","-0.00038"
"16.35200","3.42953","0.01052","-0.00039"
"16.36600","3.43090","-0.01600","-0.00039"
"16.38000","3.43223","-0.02474","-0.00039"
"16.39400","3.43361","0.00497","-0.00039"
"16.40800","3.43502","0.07351","-0.00039"
"16.42200","3.43645","0.04186","-0.00039"
"16.43600","3.43789","0.02685","-0.00039"
"16.45000","3.43932","0.04791","-0.00039"
"16.46400","3.44071","0.01470","-0.00039"
"16.47800","3.44208","0.02185","-0.00039"
"16.49200","3.44346","0.00130","-0.00039"
"16.50600","3.44487","-0.04629","-0.00038"
"16.52000","3.44630","-0.00041","-0.00038"
"16.53400","3.44773","0.00907","-0.00038"
"16.54800","3.44918","0.00402","-0.00038"
"16.56200","3.45064","0.01544","-0.00039"
"16.57600","3.45206","0.03179","-0.00039"
"16.59000","3.45341","-0.01814","-0.00039"
"16.60400","3.45472","-0.00681","-0.00039"
"16.61800","3.45607","0.01739","-0.00039"
"16.63200","3.45748","0.02468","-0.00039"
"16.64600","3.45892","-0.00119","-0.00039"
"16.66000","3.46034","-0.01418","-0.00039"
"16.67400","3.46178","0.05644","-0.00039"
"16.68800","3.46318","0.14350","-0.00039"
"16.70200","3.46455","0.11426","-0.00039"
"16.71600","3.46587","0.06448","-0.00039"
"16.73000","3.46720","0.09505","-0.00039"
"16.74400","3.46858","0.05220","-0.00038"
"16.75800","3.46999","0.01922","-0.00038"
"16.77200","3.47143","-0.00060","-0.00039"
"16.78600","3.47289","-0.02259","-0.00039"
"16.80000","3.47434","-0.04351","-0.00039"
"16.80500","3.47485","-0.02505","-0.00039"