File: archive/undergrad/433/Pressure Vessel/Specimen_RawData_6.csv
Time,Extension,Load,Strain Gage18
(s),(mm),(N),(mm/mm)
"0.00000","0.00000","-0.07855","0.00001"
"0.01400","0.00000","-0.06658","0.00001"
"0.02800","0.00004","-0.04902","0.00001"
"0.04200","0.00019","0.01062","0.00001"
"0.05600","0.00057","0.06659","0.00001"
"0.07000","0.00129","0.05697","0.00000"
"0.08400","0.00228","0.03678","0.00000"
"0.09800","0.00315","0.01682","0.00000"
"0.11200","0.00375","0.02219","0.00000"
"0.12600","0.00436","0.05598","0.00000"
"0.14000","0.00530","0.07639","0.00000"
"0.15400","0.00671","0.08768","0.00000"
"0.16800","0.00851","0.05627","0.00000"
"0.18200","0.01048","-0.01911","0.00000"
"0.19600","0.01247","-0.07523","0.00000"
"0.21000","0.01434","-0.04808","0.00001"
"0.22400","0.01604","-0.07356","0.00001"
"0.23800","0.01761","-0.11934","0.00001"
"0.25200","0.01909","-0.05737","0.00001"
"0.26600","0.02047","-0.01958","0.00001"
"0.28000","0.02181","0.00678","0.00000"
"0.29400","0.02315","-0.02885","0.00000"
"0.30800","0.02456","-0.01482","0.00000"
"0.32200","0.02602","-0.01693","0.00000"
"0.33600","0.02749","0.01821","0.00000"
"0.35000","0.02896","0.01023","0.00000"
"0.36400","0.03041","0.03354","0.00000"
"0.37800","0.03180","0.05260","0.00000"
"0.39200","0.03316","0.06260","0.00000"
"0.40600","0.03452","0.00534","0.00000"
"0.42000","0.03593","-0.01617","0.00001"
"0.43400","0.03733","-0.02116","0.00001"
"0.44800","0.03873","-0.01366","0.00001"
"0.46200","0.04016","0.08516","0.00001"
"0.47600","0.04161","0.06455","0.00001"
"0.49000","0.04304","-0.00493","0.00001"
"0.50400","0.04443","-0.04382","0.00001"
"0.51800","0.04579","-0.07072","0.00000"
"0.53200","0.04718","-0.07119","0.00000"
"0.54600","0.04861","-0.11253","0.00000"
"0.56000","0.05006","-0.07466","0.00000"
"0.57400","0.05150","-0.09023","0.00000"
"0.58800","0.05295","-0.11424","0.00000"
"0.60200","0.05435","-0.10089","0.00000"
"0.61600","0.05572","-0.07379","0.00000"
"0.63000","0.05707","-0.07463","0.00001"
"0.64400","0.05844","0.01718","0.00001"
"0.65800","0.05983","0.06300","0.00001"
"0.67200","0.06122","0.00206","0.00001"
"0.68600","0.06263","-0.02632","0.00001"
"0.70000","0.06406","-0.00355","0.00001"
"0.71400","0.06547","0.04760","0.00001"
"0.72800","0.06683","0.01596","0.00001"
"0.74200","0.06816","-0.00659","0.00000"
"0.75600","0.06951","0.04367","0.00000"
"0.77000","0.07091","0.08603","0.00000"
"0.78400","0.07233","0.08513","0.00000"
"0.79800","0.07376","0.07206","0.00000"
"0.81200","0.07518","0.08022","0.00000"
"0.82600","0.07659","0.04998","0.00000"
"0.84000","0.07796","-0.03102","0.00001"
"0.85400","0.07930","-0.06162","0.00001"
"0.86800","0.08066","-0.03929","0.00001"
"0.88200","0.08205","-0.02205","0.00001"
"0.89600","0.08346","-0.09976","0.00001"
"0.91000","0.08489","-0.05680","0.00001"
"0.92400","0.08634","0.02187","0.00001"
"0.93800","0.08781","0.05017","0.00001"
"0.95200","0.08922","0.03548","0.00001"
"0.96600","0.09058","0.04929","0.00001"
"0.98000","0.09193","0.02664","0.00000"
"0.99400","0.09331","-0.02574","0.00000"
"1.00800","0.09474","-0.01166","0.00000"
"1.02200","0.09619","0.04380","0.00000"
"1.03600","0.09763","0.02626","0.00001"
"1.05000","0.09907","0.01817","0.00001"
"1.06400","0.10046","0.03742","0.00001"
"1.07800","0.10183","0.01326","0.00001"
"1.09200","0.10320","-0.02573","0.00001"
"1.10600","0.10460","-0.09157","0.00001"
"1.12000","0.10602","-0.11685","0.00001"
"1.13400","0.10744","-0.07275","0.00001"
"1.14800","0.10889","-0.03216","0.00001"
"1.16200","0.11035","0.03698","0.00001"
"1.17600","0.11176","0.04148","0.00001"
"1.19000","0.11310","0.00930","0.00001"
"1.20400","0.11442","0.02263","0.00000"
"1.21800","0.11579","0.04857","0.00000"
"1.23200","0.11722","0.02852","0.00000"
"1.24600","0.11865","-0.03117","0.00001"
"1.26000","0.12008","-0.06284","0.00001"
"1.27400","0.12151","-0.07496","0.00001"
"1.28800","0.12291","-0.06968","0.00001"
"1.30200","0.12427","-0.07670","0.00001"
"1.31600","0.12559","-0.08943","0.00001"
"1.33000","0.12694","-0.02047","0.00001"
"1.34400","0.12832","0.00380","0.00001"
"1.35800","0.12971","-0.00729","0.00001"
"1.37200","0.13114","-0.05753","0.00001"
"1.38600","0.13259","-0.01514","0.00001"
"1.40000","0.13403","0.09137","0.00001"
"1.41400","0.13542","0.10694","0.00001"
"1.42800","0.13676","0.06757","0.00001"
"1.44200","0.13810","0.00033","0.00001"
"1.45600","0.13948","-0.02535","0.00001"
"1.47000","0.14088","-0.05843","0.00001"
"1.48400","0.14230","-0.00390","0.00001"
"1.49800","0.14374","0.03806","0.00001"
"1.51200","0.14518","0.07282","0.00001"
"1.52600","0.14659","0.03531","0.00001"
"1.54000","0.14797","0.04940","0.00001"
"1.55400","0.14933","0.08185","0.00001"
"1.56800","0.15072","0.05257","0.00001"
"1.58200","0.15212","0.03539","0.00001"
"1.59600","0.15354","0.06754","0.00001"
"1.61000","0.15499","0.03702","0.00001"
"1.62400","0.15645","-0.07775","0.00001"
"1.63800","0.15785","-0.16365","0.00001"
"1.65200","0.15921","-0.14041","0.00001"
"1.66600","0.16055","-0.04219","0.00001"
"1.68000","0.16194","-0.05832","0.00001"
"1.69400","0.16338","-0.02436","0.00001"
"1.70800","0.16483","0.01832","0.00001"
"1.72200","0.16627","-0.05574","0.00001"
"1.73600","0.16772","-0.05180","0.00001"
"1.75000","0.16915","-0.04940","0.00001"
"1.76400","0.17053","-0.01297","0.00001"
"1.77800","0.17186","0.02646","0.00001"
"1.79200","0.17320","0.04684","0.00001"
"1.80600","0.17458","0.08919","0.00001"
"1.82000","0.17599","0.04652","0.00001"
"1.83400","0.17744","-0.02829","0.00001"
"1.84800","0.17891","-0.03246","0.00001"
"1.86200","0.18034","0.01757","0.00001"
"1.87600","0.18171","0.08737","0.00001"
"1.89000","0.18305","0.11593","0.00001"
"1.90400","0.18439","0.11335","0.00001"
"1.91800","0.18577","0.06232","0.00001"
"1.93200","0.18715","-0.01288","0.00001"
"1.94600","0.18855","-0.00273","0.00001"
"1.96000","0.18997","0.02783","0.00001"
"1.97400","0.19140","0.08651","0.00001"
"1.98800","0.19279","0.12253","0.00001"
"2.00200","0.19415","0.06558","0.00001"
"2.01600","0.19550","0.02787","0.00001"
"2.03000","0.19689","-0.02034","0.00001"
"2.04400","0.19828","-0.05347","0.00001"
"2.05800","0.19969","-0.13448","0.00001"
"2.07200","0.20112","-0.07799","0.00001"
"2.08600","0.20256","-0.00352","0.00001"
"2.10000","0.20397","-0.01085","0.00001"
"2.11400","0.20534","-0.07998","0.00001"
"2.12800","0.20672","-0.07180","0.00001"
"2.14200","0.20812","0.03439","0.00001"
"2.15600","0.20953","0.07119","0.00001"
"2.17000","0.21092","0.11114","0.00001"
"2.18400","0.21233","0.07837","0.00001"
"2.19800","0.21377","0.05555","0.00001"
"2.21200","0.21520","0.05199","0.00002"
"2.22600","0.21659","0.05056","0.00002"
"2.24000","0.21795","0.03200","0.00002"
"2.25400","0.21933","0.03999","0.00001"
"2.26800","0.22073","-0.02295","0.00001"
"2.28200","0.22215","-0.03763","0.00001"
"2.29600","0.22360","-0.07261","0.00001"
"2.31000","0.22506","-0.03079","0.00001"
"2.32400","0.22649","0.00782","0.00001"
"2.33800","0.22787","-0.00833","0.00001"
"2.35200","0.22924","-0.07263","0.00001"
"2.36600","0.23065","-0.06444","0.00001"
"2.38000","0.23207","-0.03686","0.00001"
"2.39400","0.23346","-0.04411","0.00001"
"2.40800","0.23485","0.01360","0.00002"
"2.42200","0.23628","0.00528","0.00002"
"2.43600","0.23771","-0.06691","0.00002"
"2.45000","0.23910","-0.05478","0.00002"
"2.46400","0.24046","0.00866","0.00001"
"2.47800","0.24183","0.07124","0.00001"
"2.49200","0.24322","0.06015","0.00001"
"2.50600","0.24462","-0.01075","0.00001"
"2.52000","0.24603","-0.04745","0.00001"
"2.53400","0.24744","-0.08638","0.00001"
"2.54800","0.24885","-0.03990","0.00001"
"2.56200","0.25022","-0.06948","0.00001"
"2.57600","0.25156","-0.03105","0.00001"
"2.59000","0.25292","-0.00170","0.00001"
"2.60400","0.25431","0.02953","0.00001"
"2.61800","0.25572","0.00540","0.00002"
"2.63200","0.25711","0.02366","0.00002"
"2.64600","0.25852","0.05756","0.00002"
"2.66000","0.25994","0.06195","0.00002"
"2.67400","0.26133","0.07854","0.00002"
"2.68800","0.26267","0.01764","0.00002"
"2.70200","0.26402","-0.07387","0.00001"
"2.71600","0.26541","-0.08502","0.00001"
"2.73000","0.26684","-0.01780","0.00001"
"2.74400","0.26830","0.00865","0.00001"
"2.75800","0.26977","-0.03966","0.00001"
"2.77200","0.27122","-0.06037","0.00001"
"2.78600","0.27262","-0.06275","0.00001"
"2.80000","0.27398","-0.06875","0.00001"
"2.81400","0.27534","-0.01735","0.00001"
"2.82800","0.27674","-0.04429","0.00001"
"2.84200","0.27816","-0.03995","0.00002"
"2.85600","0.27956","0.00009","0.00002"
"2.87000","0.28098","0.05895","0.00002"
"2.88400","0.28243","0.09409","0.00002"
"2.89800","0.28387","0.10004","0.00002"
"2.91200","0.28526","0.07124","0.00002"
"2.92600","0.28662","-0.00797","0.00001"
"2.94000","0.28800","-0.06290","0.00001"
"2.95400","0.28942","-0.02431","0.00001"
"2.96800","0.29086","0.04494","0.00001"
"2.98200","0.29230","0.04323","0.00001"
"2.99600","0.29374","-0.00553","0.00001"
"3.01000","0.29515","0.01998","0.00001"
"3.02400","0.29653","0.00568","0.00001"
"3.03800","0.29789","0.00822","0.00001"
"3.05200","0.29927","0.06086","0.00001"
"3.06600","0.30065","0.09945","0.00002"
"3.08000","0.30204","0.03083","0.00002"
"3.09400","0.30343","-0.05144","0.00002"
"3.10800","0.30485","-0.00179","0.00002"
"3.12200","0.30626","0.05374","0.00002"
"3.13600","0.30762","0.09128","0.00002"
"3.15000","0.30895","0.09498","0.00002"
"3.16400","0.31029","0.04922","0.00001"
"3.17800","0.31169","0.05453","0.00001"
"3.19200","0.31311","0.02362","0.00001"
"3.20600","0.31455","-0.00070","0.00001"
"3.22000","0.31600","-0.02039","0.00001"
"3.23400","0.31743","-0.04867","0.00001"
"3.24800","0.31881","-0.06859","0.00001"
"3.26200","0.32015","-0.04108","0.00001"
"3.27600","0.32149","0.00652","0.00002"
"3.29000","0.32286","0.05521","0.00002"
"3.30400","0.32426","0.01457","0.00002"
"3.31800","0.32568","-0.01203","0.00002"
"3.33200","0.32714","0.00510","0.00002"
"3.34600","0.32861","0.00498","0.00002"
"3.36000","0.33003","0.02468","0.00002"
"3.37400","0.33139","0.00554","0.00002"
"3.38800","0.33272","0.00873","0.00001"
"3.40200","0.33409","0.03194","0.00001"
"3.41600","0.33550","-0.00304","0.00001"
"3.43000","0.33694","-0.04037","0.00001"
"3.44400","0.33838","-0.00332","0.00001"
"3.45800","0.33982","0.03978","0.00001"
"3.47200","0.34123","0.07331","0.00001"
"3.48600","0.34260","0.00485","0.00001"
"3.50000","0.34398","-0.02189","0.00002"
"3.51400","0.34538","-0.03222","0.00002"
"3.52800","0.34680","-0.00485","0.00002"
"3.54200","0.34823","-0.02543","0.00002"
"3.55600","0.34969","0.02094","0.00002"
"3.57000","0.35115","0.07146","0.00002"
"3.58400","0.35258","0.00570","0.00002"
"3.59800","0.35393","-0.02426","0.00002"
"3.61200","0.35525","0.03129","0.00001"
"3.62600","0.35662","0.03955","0.00001"
"3.64000","0.35805","0.02764","0.00001"
"3.65400","0.35949","0.00542","0.00001"
"3.66800","0.36093","0.02113","0.00001"
"3.68200","0.36236","-0.01988","0.00001"
"3.69600","0.36377","-0.05353","0.00001"
"3.71000","0.36512","-0.05292","0.00001"
"3.72400","0.36644","-0.01672","0.00001"
"3.73800","0.36776","0.05120","0.00002"
"3.75200","0.36912","0.00431","0.00002"
"3.76600","0.37050","-0.01953","0.00002"
"3.78000","0.37193","-0.04911","0.00002"
"3.79400","0.37338","-0.10516","0.00002"
"3.80800","0.37484","-0.08300","0.00002"
"3.82200","0.37624","-0.01740","0.00002"
"3.83600","0.37757","0.00152","0.00001"
"3.85000","0.37890","0.06032","0.00001"
"3.86400","0.38026","0.06229","0.00001"
"3.87800","0.38166","0.01928","0.00001"
"3.89200","0.38307","0.02674","0.00001"
"3.90600","0.38451","0.00996","0.00001"
"3.92000","0.38596","0.03589","0.00001"
"3.93400","0.38738","0.09713","0.00001"
"3.94800","0.38876","0.09931","0.00002"
"3.96200","0.39012","0.09276","0.00002"
"3.97600","0.39150","0.03993","0.00002"
"3.99000","0.39290","0.02643","0.00002"
"4.00400","0.39432","0.06725","0.00002"
"4.01800","0.39576","0.05843","0.00002"
"4.03200","0.39723","0.07549","0.00002"
"4.04600","0.39865","0.07945","0.00001"
"4.06000","0.40002","0.04459","0.00001"
"4.07400","0.40135","-0.02062","0.00001"
"4.08800","0.40272","-0.02572","0.00001"
"4.10200","0.40414","0.00084","0.00001"
"4.11600","0.40558","0.00713","0.00001"
"4.13000","0.40703","0.08052","0.00001"
"4.14400","0.40849","0.09197","0.00002"
"4.15800","0.40993","0.05818","0.00002"
"4.17200","0.41133","0.04683","0.00002"
"4.18600","0.41268","0.06113","0.00002"
"4.20000","0.41403","-0.01222","0.00002"
"4.21400","0.41540","-0.02907","0.00002"
"4.22800","0.41682","-0.03192","0.00002"
"4.24200","0.41826","-0.02900","0.00002"
"4.25600","0.41973","-0.01948","0.00001"
"4.27000","0.42118","-0.04275","0.00001"
"4.28400","0.42255","-0.01901","0.00001"
"4.29800","0.42389","0.01164","0.00001"
"4.31200","0.42522","-0.01248","0.00001"
"4.32600","0.42659","-0.00363","0.00001"
"4.34000","0.42797","-0.00695","0.00001"
"4.35400","0.42935","0.01752","0.00001"
"4.36800","0.43076","0.01522","0.00001"
"4.38200","0.43219","-0.03184","0.00002"
"4.39600","0.43360","-0.07144","0.00002"
"4.41000","0.43496","-0.06372","0.00002"
"4.42400","0.43631","0.00246","0.00002"
"4.43800","0.43768","0.01158","0.00002"
"4.45200","0.43907","0.05997","0.00002"
"4.46600","0.44047","0.06569","0.00002"
"4.48000","0.44189","0.01570","0.00001"
"4.49400","0.44332","0.00091","0.00001"
"4.50800","0.44474","-0.00886","0.00001"
"4.52200","0.44612","-0.03259","0.00001"
"4.53600","0.44750","-0.03746","0.00001"
"4.55000","0.44891","-0.01834","0.00001"
"4.56400","0.45033","-0.01819","0.00001"
"4.57800","0.45173","-0.05608","0.00001"
"4.59200","0.45314","-0.05716","0.00002"
"4.60600","0.45458","0.01300","0.00002"
"4.62000","0.45601","0.03183","0.00002"
"4.63400","0.45741","0.03711","0.00002"
"4.64800","0.45877","-0.04115","0.00002"
"4.66200","0.46014","-0.10175","0.00002"
"4.67600","0.46152","-0.15071","0.00002"
"4.69000","0.46293","-0.13672","0.00002"
"4.70400","0.46437","-0.05876","0.00002"
"4.71800","0.46583","-0.02908","0.00001"
"4.73200","0.46727","-0.05729","0.00001"
"4.74600","0.46866","-0.02473","0.00001"
"4.76000","0.47004","0.02212","0.00001"
"4.77400","0.47145","0.01260","0.00001"
"4.78800","0.47287","0.00535","0.00001"
"4.80200","0.47428","0.03639","0.00001"
"4.81600","0.47567","0.04434","0.00001"
"4.83000","0.47710","0.04042","0.00002"
"4.84400","0.47853","0.06485","0.00002"
"4.85800","0.47992","0.01151","0.00002"
"4.87200","0.48127","-0.00550","0.00002"
"4.88600","0.48262","-0.00667","0.00002"
"4.90000","0.48401","-0.05573","0.00002"
"4.91400","0.48541","-0.09587","0.00002"
"4.92800","0.48681","-0.05156","0.00001"
"4.94200","0.48822","-0.02321","0.00001"
"4.95600","0.48962","-0.02564","0.00001"
"4.97000","0.49100","-0.07033","0.00001"
"4.98400","0.49235","-0.05634","0.00001"
"4.99800","0.49371","0.00621","0.00001"
"5.01200","0.49512","0.04204","0.00001"
"5.02600","0.49653","0.07902","0.00001"
"5.04000","0.49794","0.08109","0.00002"
"5.05400","0.49935","0.11698","0.00002"
"5.06800","0.50077","0.08822","0.00002"
"5.08200","0.50216","0.09973","0.00002"
"5.09600","0.50350","0.10090","0.00002"
"5.11000","0.50482","0.08273","0.00002"
"5.12400","0.50620","0.07038","0.00002"
"5.13800","0.50763","0.02826","0.00002"
"5.15200","0.50908","0.01223","0.00001"
"5.16600","0.51055","0.03124","0.00001"
"5.18000","0.51200","0.03073","0.00001"
"5.19400","0.51341","0.03147","0.00001"
"5.20800","0.51476","0.00840","0.00001"
"5.22200","0.51612","0.06674","0.00001"
"5.23600","0.51751","0.08883","0.00001"
"5.25000","0.51892","0.07831","0.00002"
"5.26400","0.52034","0.01383","0.00002"
"5.27800","0.52175","-0.01693","0.00002"
"5.29200","0.52320","0.00832","0.00002"
"5.30600","0.52465","0.01402","0.00002"
"5.32000","0.52605","0.01063","0.00002"
"5.33400","0.52740","-0.04467","0.00002"
"5.34800","0.52877","-0.09811","0.00002"
"5.36200","0.53018","-0.07334","0.00002"
"5.37600","0.53162","-0.05338","0.00002"
"5.39000","0.53306","-0.06979","0.00002"
"5.40400","0.53451","-0.03429","0.00001"
"5.41800","0.53594","0.02439","0.00001"
"5.43200","0.53733","0.03952","0.00001"
"5.44600","0.53870","-0.02491","0.00001"
"5.46000","0.54006","-0.04222","0.00002"
"5.47400","0.54144","-0.11721","0.00002"
"5.48800","0.54282","-0.14636","0.00002"
"5.50200","0.54421","-0.10370","0.00002"
"5.51600","0.54562","-0.08910","0.00002"
"5.53000","0.54704","-0.07939","0.00002"
"5.54400","0.54842","0.00710","0.00002"
"5.55800","0.54976","0.00352","0.00002"
"5.57200","0.55110","0.00344","0.00002"
"5.58600","0.55249","0.00301","0.00002"
"5.60000","0.55393","-0.05529","0.00002"
"5.61400","0.55538","-0.10431","0.00002"
"5.62800","0.55682","-0.17999","0.00001"
"5.64200","0.55826","-0.13638","0.00001"
"5.65600","0.55965","-0.08501","0.00002"
"5.67000","0.56098","-0.04884","0.00002"
"5.68400","0.56231","-0.05620","0.00002"
"5.69800","0.56368","-0.03144","0.00002"
"5.71200","0.56507","-0.01170","0.00002"
"5.72600","0.56649","0.05520","0.00002"
"5.74000","0.56793","0.03049","0.00002"
"5.75400","0.56940","0.04476","0.00002"
"5.76800","0.57084","0.06058","0.00002"
"5.78200","0.57221","0.04576","0.00002"
"5.79600","0.57354","0.08022","0.00002"
"5.81000","0.57490","-0.01126","0.00002"
"5.82400","0.57630","-0.08215","0.00002"
"5.83800","0.57774","-0.05650","0.00001"
"5.85200","0.57918","-0.03607","0.00001"
"5.86600","0.58062","-0.06133","0.00002"
"5.88000","0.58203","-0.08042","0.00002"
"5.89400","0.58340","-0.08532","0.00002"
"5.90800","0.58477","-0.08501","0.00002"
"5.92200","0.58617","-0.05196","0.00002"
"5.93600","0.58759","0.05067","0.00002"
"5.95000","0.58902","0.11192","0.00002"
"5.96400","0.59046","0.04204","0.00002"
"5.97800","0.59193","0.00349","0.00002"
"5.99200","0.59337","0.02318","0.00002"
"6.00600","0.59475","-0.00698","0.00002"
"6.02000","0.59607","-0.05902","0.00002"
"6.03400","0.59743","-0.07414","0.00002"
"6.04800","0.59884","-0.07344","0.00001"
"6.06200","0.60028","-0.02628","0.00001"
"6.07600","0.60171","-0.03069","0.00002"
"6.09000","0.60315","-0.10218","0.00002"
"6.10400","0.60457","-0.09228","0.00002"
"6.11800","0.60595","-0.07573","0.00002"
"6.13200","0.60727","-0.08633","0.00002"
"6.14600","0.60859","-0.05941","0.00002"
"6.16000","0.60995","0.00045","0.00002"
"6.17400","0.61134","0.08260","0.00002"
"6.18800","0.61276","0.10891","0.00002"
"6.20200","0.61421","0.05919","0.00002"
"6.21600","0.61567","0.03512","0.00002"
"6.23000","0.61707","-0.02310","0.00002"
"6.24400","0.61840","-0.03839","0.00002"
"6.25800","0.61971","-0.08061","0.00002"
"6.27200","0.62106","-0.09093","0.00002"
"6.28600","0.62245","-0.06292","0.00001"
"6.30000","0.62386","-0.07079","0.00001"
"6.31400","0.62528","-0.05742","0.00002"
"6.32800","0.62673","-0.10491","0.00002"
"6.34200","0.62816","-0.13577","0.00002"
"6.35600","0.62956","-0.10924","0.00002"
"6.37000","0.63093","-0.01643","0.00002"
"6.38400","0.63232","-0.00317","0.00002"
"6.39800","0.63372","-0.00089","0.00002"
"6.41200","0.63512","-0.00775","0.00002"
"6.42600","0.63655","0.02089","0.00002"
"6.44000","0.63802","0.02311","0.00002"
"6.45400","0.63946","0.00607","0.00002"
"6.46800","0.64083","0.02074","0.00002"
"6.48200","0.64217","0.07799","0.00002"
"6.49600","0.64353","0.05267","0.00002"
"6.51000","0.64493","0.02522","0.00001"
"6.52400","0.64637","-0.00611","0.00001"
"6.53800","0.64781","0.03365","0.00002"
"6.55200","0.64926","0.04270","0.00001"
"6.56600","0.65070","-0.05530","0.00002"
"6.58000","0.65210","-0.02511","0.00002"
"6.59400","0.65344","-0.03228","0.00002"
"6.60800","0.65478","-0.02691","0.00002"
"6.62200","0.65614","0.01548","0.00002"
"6.63600","0.65755","-0.01407","0.00002"
"6.65000","0.65898","-0.05861","0.00002"
"6.66400","0.66045","-0.04954","0.00002"
"6.67800","0.66190","-0.03083","0.00002"
"6.69200","0.66329","-0.01998","0.00002"
"6.70600","0.66463","0.00983","0.00002"
"6.72000","0.66597","0.05906","0.00002"
"6.73400","0.66734","0.03907","0.00002"
"6.74800","0.66874","0.00930","0.00002"
"6.76200","0.67013","-0.04052","0.00002"
"6.77600","0.67155","-0.01620","0.00002"
"6.79000","0.67298","-0.02731","0.00002"
"6.80400","0.67440","-0.01969","0.00002"
"6.81800","0.67576","-0.02116","0.00002"
"6.83200","0.67712","-0.01853","0.00002"
"6.84600","0.67849","0.01627","0.00002"
"6.86000","0.67989","0.00854","0.00002"
"6.87400","0.68131","-0.05849","0.00002"
"6.88800","0.68273","-0.00777","0.00002"
"6.90200","0.68417","0.04972","0.00002"
"6.91600","0.68559","0.05313","0.00002"
"6.93000","0.68696","0.02518","0.00002"
"6.94400","0.68833","0.04214","0.00002"
"6.95800","0.68972","-0.00934","0.00002"
"6.97200","0.69113","-0.01741","0.00002"
"6.98600","0.69254","-0.00623","0.00002"
"7.00000","0.69393","0.01585","0.00001"
"7.01400","0.69535","0.03433","0.00001"
"7.02800","0.69678","0.05104","0.00002"
"7.04200","0.69818","0.01387","0.00002"
"7.05600","0.69956","-0.00237","0.00002"
"7.07000","0.70094","-0.03435","0.00002"
"7.08400","0.70234","-0.02358","0.00002"
"7.09800","0.70375","0.00576","0.00002"
"7.11200","0.70518","0.02225","0.00002"
"7.12600","0.70663","-0.00298","0.00002"
"7.14000","0.70807","-0.01088","0.00002"
"7.15400","0.70946","0.05183","0.00001"
"7.16800","0.71083","0.06343","0.00001"
"7.18200","0.71222","0.06580","0.00001"
"7.19600","0.71364","0.05807","0.00001"
"7.21000","0.71505","-0.01148","0.00001"
"7.22400","0.71645","-0.11330","0.00001"
"7.23800","0.71788","-0.13608","0.00002"
"7.25200","0.71933","-0.05696","0.00002"
"7.26600","0.72074","0.03990","0.00002"
"7.28000","0.72209","0.10693","0.00002"
"7.29400","0.72344","0.08688","0.00002"
"7.30800","0.72481","0.06660","0.00002"
"7.32200","0.72622","0.00490","0.00002"
"7.33600","0.72763","-0.00654","0.00002"
"7.35000","0.72904","0.01397","0.00002"
"7.36400","0.73045","-0.00515","0.00001"
"7.37800","0.73183","0.01929","0.00001"
"7.39200","0.73318","0.00249","0.00001"
"7.40600","0.73453","0.03106","0.00001"
"7.42000","0.73592","0.03272","0.00001"
"7.43400","0.73734","0.05353","0.00001"
"7.44800","0.73874","0.00368","0.00001"
"7.46200","0.74015","-0.00956","0.00002"
"7.47600","0.74158","0.00886","0.00002"
"7.49000","0.74298","-0.05952","0.00002"
"7.50400","0.74434","-0.04378","0.00002"
"7.51800","0.74567","0.01827","0.00002"
"7.53200","0.74703","0.01401","0.00002"
"7.54600","0.74844","0.00611","0.00002"
"7.56000","0.74989","0.04175","0.00002"
"7.57400","0.75134","0.03702","0.00001"
"7.58800","0.75280","0.02516","0.00001"
"7.60200","0.75422","-0.01422","0.00001"
"7.61600","0.75558","-0.00410","0.00001"
"7.63000","0.75692","-0.00688","0.00001"
"7.64400","0.75831","0.01032","0.00001"
"7.65800","0.75974","0.02686","0.00001"
"7.67200","0.76116","-0.03225","0.00001"
"7.68600","0.76259","-0.10579","0.00002"
"7.70000","0.76403","-0.09691","0.00002"
"7.71400","0.76547","-0.07805","0.00002"
"7.72800","0.76688","-0.01718","0.00002"
"7.74200","0.76824","0.05812","0.00002"
"7.75600","0.76960","0.08178","0.00002"
"7.77000","0.77100","0.07060","0.00002"
"7.78400","0.77243","0.04710","0.00002"
"7.79800","0.77387","-0.02344","0.00002"
"7.81200","0.77530","-0.02930","0.00002"
"7.82600","0.77673","-0.03004","0.00001"
"7.84000","0.77813","-0.08483","0.00001"
"7.85400","0.77950","-0.10462","0.00002"
"7.86800","0.78087","-0.07746","0.00002"
"7.88200","0.78225","-0.04730","0.00002"
"7.89600","0.78363","-0.07094","0.00002"
"7.91000","0.78502","-0.02698","0.00002"
"7.92400","0.78642","0.01624","0.00002"
"7.93800","0.78784","0.00719","0.00002"
"7.95200","0.78923","-0.00290","0.00002"
"7.96600","0.79057","-0.00470","0.00002"
"7.98000","0.79190","0.07271","0.00002"
"7.99400","0.79328","0.10327","0.00002"
"8.00800","0.79470","0.06733","0.00002"
"8.02200","0.79614","0.01445","0.00002"
"8.03600","0.79758","-0.03444","0.00002"
"8.05000","0.79901","-0.07693","0.00002"
"8.06400","0.80040","-0.05442","0.00002"
"8.07800","0.80174","0.00214","0.00002"
"8.09200","0.80307","0.06822","0.00002"
"8.10600","0.80445","0.03602","0.00002"
"8.12000","0.80586","0.04070","0.00002"
"8.13400","0.80729","0.00050","0.00002"
"8.14800","0.80873","-0.01802","0.00002"
"8.16200","0.81019","-0.04848","0.00002"
"8.17600","0.81164","-0.00754","-0.00003"
"8.19000","0.81302","0.04131","-0.00016"
"8.20400","0.81436","0.03981","-0.00038"
"8.21800","0.81571","0.00416","-0.00066"
"8.23200","0.81711","-0.00504","-0.00094"
"8.24600","0.81853","0.01992","-0.00120"
"8.26000","0.81998","0.01560","-0.00137"
"8.27400","0.82143","0.06257","-0.00145"
"8.28800","0.82285","0.09874","-0.00147"
"8.30200","0.82423","0.10415","-0.00147"
"8.31600","0.82560","0.07344","-0.00146"
"8.33000","0.82698","0.08204","-0.00145"
"8.34400","0.82839","0.04213","-0.00144"
"8.35800","0.82980","-0.07342","-0.00144"
"8.37200","0.83123","-0.09796","-0.00144"
"8.38600","0.83269","-0.15570","-0.00144"
"8.40000","0.83413","-0.20228","-0.00144"
"8.41400","0.83551","-0.05614","-0.00145"
"8.42800","0.83683","0.01197","-0.00145"
"8.44200","0.83817","0.10016","-0.00145"
"8.45600","0.83957","0.04651","-0.00145"
"8.47000","0.84102","0.01623","-0.00145"
"8.48400","0.84246","-0.00635","-0.00145"
"8.49800","0.84389","-0.08229","-0.00145"
"8.51200","0.84532","-0.06684","-0.00145"
"8.52600","0.84670","-0.10008","-0.00145"
"8.54000","0.84804","-0.07721","-0.00145"
"8.55400","0.84937","-0.06941","-0.00144"
"8.56800","0.85074","0.02868","-0.00144"
"8.58200","0.85213","0.06316","-0.00144"
"8.59600","0.85354","0.01602","-0.00144"
"8.61000","0.85498","-0.01778","-0.00144"
"8.62400","0.85644","-0.04297","-0.00144"
"8.63800","0.85786","-0.03568","-0.00144"
"8.65200","0.85922","-0.04886","-0.00144"
"8.66600","0.86053","-0.10999","-0.00145"
"8.68000","0.86188","-0.04818","-0.00145"
"8.69400","0.86327","-0.02469","-0.00145"
"8.70800","0.86468","-0.03816","-0.00145"
"8.72200","0.86611","-0.07385","-0.00145"
"8.73600","0.86756","-0.04893","-0.00145"
"8.75000","0.86899","-0.04632","-0.00145"
"8.76400","0.87039","-0.06350","-0.00145"
"8.77800","0.87175","-0.08061","-0.00145"
"8.79200","0.87312","-0.09200","-0.00145"
"8.80600","0.87451","-0.01293","-0.00145"
"8.82000","0.87592","0.00605","-0.00144"
"8.83400","0.87735","-0.00345","-0.00145"
"8.84800","0.87881","0.00147","-0.00145"
"8.86200","0.88025","0.03032","-0.00145"
"8.87600","0.88164","0.05320","-0.00145"
"8.89000","0.88298","0.02942","-0.00145"
"8.90400","0.88433","-0.02383","-0.00145"
"8.91800","0.88574","-0.06811","-0.00145"
"8.93200","0.88717","-0.12887","-0.00145"
"8.94600","0.88861","-0.11225","-0.00145"
"8.96000","0.89005","-0.04420","-0.00145"
"8.97400","0.89150","0.01731","-0.00145"
"8.98800","0.89293","0.01908","-0.00145"
"9.00200","0.89431","0.04481","-0.00145"
"9.01600","0.89567","0.02876","-0.00145"
"9.03000","0.89704","0.03830","-0.00145"
"9.04400","0.89843","0.09608","-0.00145"
"9.05800","0.89985","0.09920","-0.00145"
"9.07200","0.90130","0.05939","-0.00145"
"9.08600","0.90274","0.01765","-0.00145"
"9.10000","0.90413","-0.04964","-0.00145"
"9.11400","0.90547","-0.06649","-0.00145"
"9.12800","0.90680","-0.07030","-0.00145"
"9.14200","0.90816","-0.07224","-0.00145"
"9.15600","0.90955","-0.03619","-0.00145"
"9.17000","0.91094","-0.09224","-0.00145"
"9.18400","0.91235","-0.08783","-0.00145"
"9.19800","0.91379","-0.06888","-0.00145"
"9.21200","0.91521","-0.05768","-0.00145"
"9.22600","0.91659","0.01480","-0.00145"
"9.24000","0.91794","0.01384","-0.00145"
"9.25400","0.91931","-0.08305","-0.00145"
"9.26800","0.92071","-0.13413","-0.00145"
"9.28200","0.92211","-0.09469","-0.00145"
"9.29600","0.92352","-0.03017","-0.00145"
"9.31000","0.92495","-0.02129","-0.00145"
"9.32400","0.92637","-0.03167","-0.00145"
"9.33800","0.92775","-0.00673","-0.00145"
"9.35200","0.92911","0.03415","-0.00145"
"9.36600","0.93050","0.03879","-0.00145"
"9.38000","0.93191","0.02811","-0.00145"
"9.39400","0.93332","0.00811","-0.00146"
"9.40800","0.93472","0.01240","-0.00145"
"9.42200","0.93614","0.03062","-0.00145"
"9.43600","0.93758","0.02690","-0.00145"
"9.45000","0.93900","0.06608","-0.00145"
"9.46400","0.94039","0.07436","-0.00145"
"9.47800","0.94177","0.08846","-0.00145"
"9.49200","0.94316","0.01025","-0.00145"
"9.50600","0.94456","-0.06068","-0.00145"
"9.52000","0.94598","0.01624","-0.00145"
"9.53400","0.94743","0.05896","-0.00145"
"9.54800","0.94888","0.05419","-0.00145"
"9.56200","0.95028","-0.03496","-0.00145"
"9.57600","0.95165","-0.08354","-0.00145"
"9.59000","0.95303","-0.05215","-0.00145"
"9.60400","0.95445","-0.03987","-0.00146"
"9.61800","0.95586","-0.05331","-0.00146"
"9.63200","0.95726","-0.01848","-0.00146"
"9.64600","0.95868","-0.06093","-0.00146"
"9.66000","0.96012","-0.07626","-0.00145"
"9.67400","0.96153","-0.11038","-0.00145"
"9.68800","0.96289","-0.09522","-0.00145"
"9.70200","0.96423","-0.06432","-0.00145"
"9.71600","0.96560","-0.08136","-0.00145"
"9.73000","0.96700","-0.08710","-0.00145"
"9.74400","0.96841","-0.02394","-0.00145"
"9.75800","0.96981","0.01623","-0.00145"
"9.77200","0.97122","-0.03226","-0.00145"
"9.78600","0.97261","-0.07007","-0.00145"
"9.80000","0.97396","-0.13544","-0.00146"
"9.81400","0.97531","-0.19200","-0.00146"
"9.82800","0.97669","-0.15398","-0.00146"
"9.84200","0.97810","-0.07817","-0.00146"
"9.85600","0.97951","-0.06878","-0.00146"
"9.87000","0.98092","-0.05818","-0.00146"
"9.88400","0.98235","-0.04044","-0.00145"
"9.89800","0.98377","-0.00756","-0.00145"
"9.91200","0.98515","-0.00967","-0.00145"
"9.92600","0.98649","-0.02963","-0.00145"
"9.94000","0.98786","-0.07418","-0.00145"
"9.95400","0.98926","-0.05309","-0.00145"
"9.96800","0.99070","0.00391","-0.00145"
"9.98200","0.99215","0.06070","-0.00145"
"9.99600","0.99361","0.07790","-0.00145"
"10.01000","0.99504","0.08255","-0.00146"
"10.02400","0.99641","0.04775","-0.00146"
"10.03800","0.99776","0.11260","-0.00146"
"10.05200","0.99913","0.10670","-0.00146"
"10.06600","1.00054","-0.00422","-0.00146"
"10.08000","1.00196","-0.05128","-0.00146"
"10.09400","1.00337","-0.09037","-0.00146"
"10.10800","1.00481","-0.08656","-0.00146"
"10.12200","1.00626","-0.11021","-0.00145"
"10.13600","1.00768","-0.04510","-0.00145"
"10.15000","1.00905","0.03052","-0.00145"
"10.16400","1.01041","0.07245","-0.00145"
"10.17800","1.01180","0.11650","-0.00145"
"10.19200","1.01323","0.11243","-0.00145"
"10.20600","1.01467","0.03167","-0.00145"
"10.22000","1.01610","-0.04186","-0.00145"
"10.23400","1.01753","-0.01959","-0.00146"
"10.24800","1.01891","0.02632","-0.00146"
"10.26200","1.02028","0.02299","-0.00146"
"10.27600","1.02164","0.01268","-0.00146"
"10.29000","1.02302","-0.02101","-0.00146"
"10.30400","1.02441","-0.05199","-0.00146"
"10.31800","1.02581","-0.04311","-0.00146"
"10.33200","1.02723","-0.01146","-0.00145"
"10.34600","1.02866","0.04630","-0.00145"
"10.36000","1.03006","0.06047","-0.00145"
"10.37400","1.03141","0.03365","-0.00145"
"10.38800","1.03274","0.02100","-0.00145"
"10.40200","1.03410","-0.01177","-0.00145"
"10.41600","1.03551","-0.04488","-0.00145"
"10.43000","1.03694","-0.01051","-0.00145"
"10.44400","1.03837","-0.02384","-0.00146"
"10.45800","1.03981","-0.06929","-0.00146"
"10.47200","1.04121","-0.06620","-0.00146"
"10.48600","1.04255","-0.00010","-0.00146"
"10.50000","1.04388","0.00620","-0.00146"
"10.51400","1.04524","-0.06905","-0.00146"
"10.52800","1.04663","-0.08224","-0.00146"
"10.54200","1.04805","-0.05289","-0.00146"
"10.55600","1.04949","0.00498","-0.00145"
"10.57000","1.05096","0.02053","-0.00145"
"10.58400","1.05242","-0.02253","-0.00145"
"10.59800","1.05382","-0.04966","-0.00145"
"10.61200","1.05516","0.01311","-0.00145"
"10.62600","1.05650","0.01819","-0.00145"
"10.64000","1.05790","-0.03356","-0.00145"
"10.65400","1.05933","-0.10204","-0.00145"
"10.66800","1.06077","-0.12174","-0.00145"
"10.68200","1.06221","-0.11809","-0.00146"
"10.69600","1.06363","-0.05322","-0.00146"
"10.71000","1.06501","-0.01988","-0.00146"
"10.72400","1.06637","0.00427","-0.00146"
"10.73800","1.06775","0.02329","-0.00146"
"10.75200","1.06916","0.07768","-0.00146"
"10.76600","1.07058","0.08950","-0.00146"
"10.78000","1.07202","0.02318","-0.00145"
"10.79400","1.07349","-0.05652","-0.00145"
"10.80800","1.07496","-0.12473","-0.00145"
"10.82200","1.07636","-0.13055","-0.00145"
"10.83600","1.07770","-0.09947","-0.00145"
"10.85000","1.07903","-0.06824","-0.00145"
"10.86400","1.08042","-0.08662","-0.00145"
"10.87800","1.08184","-0.08140","-0.00145"
"10.89200","1.08327","-0.05488","-0.00146"
"10.90600","1.08470","-0.07654","-0.00146"
"10.92000","1.08613","-0.07220","-0.00146"
"10.93400","1.08752","-0.04425","-0.00146"
"10.94800","1.08887","0.00239","-0.00146"
"10.96200","1.09020","-0.00414","-0.00146"
"10.97600","1.09155","-0.04559","-0.00146"
"10.99000","1.09293","-0.02000","-0.00146"
"11.00400","1.09434","-0.01051","-0.00146"
"11.01800","1.09577","-0.00966","-0.00145"
"11.03200","1.09722","-0.00894","-0.00145"
"11.04600","1.09864","-0.02213","-0.00145"
"11.06000","1.10000","0.02290","-0.00145"
"11.07400","1.10132","-0.01593","-0.00145"
"11.08800","1.10265","-0.01653","-0.00145"
"11.10200","1.10404","0.00191","-0.00145"
"11.11600","1.10546","0.05397","-0.00146"
"11.13000","1.10689","0.00768","-0.00146"
"11.14400","1.10833","-0.06435","-0.00146"
"11.15800","1.10977","-0.11126","-0.00146"
"11.17200","1.11117","-0.11595","-0.00146"
"11.18600","1.11254","-0.03294","-0.00146"
"11.20000","1.11391","-0.00719","-0.00146"
"11.21400","1.11531","-0.01842","-0.00145"
"11.22800","1.11673","0.00620","-0.00145"
"11.24200","1.11816","-0.00260","-0.00145"
"11.25600","1.11962","-0.02801","-0.00145"
"11.27000","1.12108","-0.01857","-0.00145"
"11.28400","1.12248","-0.00796","-0.00145"
"11.29800","1.12382","-0.01321","-0.00145"
"11.31200","1.12516","0.02386","-0.00145"
"11.32600","1.12655","0.04545","-0.00145"
"11.34000","1.12798","-0.04838","-0.00146"
"11.35400","1.12941","-0.01422","-0.00146"
"11.36800","1.13086","0.04163","-0.00146"
"11.38200","1.13231","0.05719","-0.00146"
"11.39600","1.13374","0.02789","-0.00146"
"11.41000","1.13511","0.02896","-0.00146"
"11.42400","1.13646","-0.00786","-0.00146"
"11.43800","1.13783","-0.02044","-0.00145"
"11.45200","1.13922","0.00654","-0.00145"
"11.46600","1.14063","0.01008","-0.00145"
"11.48000","1.14208","0.00666","-0.00145"
"11.49400","1.14352","0.02500","-0.00145"
"11.50800","1.14492","0.03185","-0.00145"
"11.52200","1.14627","-0.02480","-0.00145"
"11.53600","1.14760","-0.04387","-0.00145"
"11.55000","1.14895","0.02412","-0.00145"
"11.56400","1.15034","0.05715","-0.00146"
"11.57800","1.15174","0.02718","-0.00146"
"11.59200","1.15315","0.00724","-0.00146"
"11.60600","1.15458","0.00358","-0.00146"
"11.62000","1.15601","-0.07971","-0.00146"
"11.63400","1.15739","-0.10115","-0.00146"
"11.64800","1.15875","-0.05975","-0.00145"
"11.66200","1.16012","-0.06044","-0.00145"
"11.67600","1.16151","-0.02740","-0.00145"
"11.69000","1.16292","0.02220","-0.00145"
"11.70400","1.16434","0.07366","-0.00145"
"11.71800","1.16577","0.06013","-0.00145"
"11.73200","1.16720","0.05289","-0.00145"
"11.74600","1.16859","0.06435","-0.00145"
"11.76000","1.16994","0.09505","-0.00145"
"11.77400","1.17132","0.10371","-0.00145"
"11.78800","1.17273","0.10829","-0.00145"
"11.80200","1.17413","0.09045","-0.00145"
"11.81600","1.17553","0.02396","-0.00146"
"11.83000","1.17694","-0.04065","-0.00146"
"11.84400","1.17838","-0.01163","-0.00146"
"11.85800","1.17980","-0.00189","-0.00146"
"11.87200","1.18119","-0.04232","-0.00145"
"11.88600","1.18256","-0.01458","-0.00145"
"11.90000","1.18394","0.00252","-0.00145"
"11.91400","1.18534","0.03958","-0.00145"
"11.92800","1.18675","0.03278","-0.00145"
"11.94200","1.18819","0.04774","-0.00145"
"11.95600","1.18965","-0.02427","-0.00145"
"11.97000","1.19106","-0.01824","-0.00145"
"11.98400","1.19244","0.03364","-0.00145"
"11.99800","1.19382","0.08371","-0.00145"
"12.01200","1.19523","0.06231","-0.00146"
"12.02600","1.19665","0.01497","-0.00146"
"12.04000","1.19805","0.01132","-0.00146"
"12.05400","1.19946","-0.03994","-0.00146"
"12.06800","1.20090","-0.04341","-0.00146"
"12.08200","1.20232","-0.03451","-0.00145"
"12.09600","1.20370","-0.06593","-0.00145"
"12.11000","1.20504","-0.04549","-0.00145"
"12.12400","1.20641","0.03244","-0.00145"
"12.13800","1.20780","0.01859","-0.00145"
"12.15200","1.20921","0.02589","-0.00145"
"12.16600","1.21062","0.03777","-0.00145"
"12.18000","1.21204","0.08296","-0.00145"
"12.19400","1.21343","0.07827","-0.00145"
"12.20800","1.21479","0.07367","-0.00145"
"12.22200","1.21614","0.00666","-0.00145"
"12.23600","1.21751","-0.07665","-0.00145"
"12.25000","1.21892","-0.15418","-0.00145"
"12.26400","1.22033","-0.11029","-0.00145"
"12.27800","1.22174","0.00010","-0.00146"
"12.29200","1.22316","-0.01516","-0.00145"
"12.30600","1.22458","-0.02286","-0.00145"
"12.32000","1.22595","-0.02272","-0.00145"
"12.33400","1.22729","0.02913","-0.00145"
"12.34800","1.22863","0.05830","-0.00145"
"12.36200","1.23004","0.01233","-0.00145"
"12.37600","1.23147","-0.03448","-0.00145"
"12.39000","1.23292","0.01390","-0.00145"
"12.40400","1.23437","-0.00477","-0.00145"
"12.41800","1.23581","-0.00920","-0.00145"
"12.43200","1.23719","0.04050","-0.00145"
"12.44600","1.23854","0.08330","-0.00145"
"12.46000","1.23990","0.13913","-0.00145"
"12.47400","1.24131","0.14930","-0.00145"
"12.48800","1.24273","0.06508","-0.00145"
"12.50200","1.24414","-0.04625","-0.00145"
"12.51600","1.24557","-0.07238","-0.00145"
"12.53000","1.24703","-0.05000","-0.00145"
"12.54400","1.24847","-0.04023","-0.00145"
"12.55800","1.24986","-0.05324","-0.00145"
"12.57200","1.25122","-0.08782","-0.00145"
"12.58600","1.25262","-0.07552","-0.00145"
"12.60000","1.25405","-0.05189","-0.00145"
"12.61400","1.25550","-0.00134","-0.00145"
"12.62800","1.25694","0.06085","-0.00145"
"12.64200","1.25837","0.06413","-0.00145"
"12.65600","1.25976","0.03943","-0.00145"
"12.67000","1.26112","-0.01270","-0.00145"
"12.68400","1.26247","0.01637","-0.00145"
"12.69800","1.26384","-0.00219","-0.00146"
"12.71200","1.26522","-0.02310","-0.00145"
"12.72600","1.26662","-0.04753","-0.00145"
"12.74000","1.26802","-0.03548","-0.00145"
"12.75400","1.26945","-0.07510","-0.00145"
"12.76800","1.27085","-0.13292","-0.00145"
"12.78200","1.27220","-0.12512","-0.00145"
"12.79600","1.27353","-0.08747","-0.00145"
"12.81000","1.27488","0.01116","-0.00145"
"12.82400","1.27629","0.01941","-0.00145"
"12.83800","1.27772","-0.02521","-0.00145"
"12.85200","1.27916","-0.04429","-0.00145"
"12.86600","1.28060","-0.04797","-0.00145"
"12.88000","1.28201","-0.03436","-0.00145"
"12.89400","1.28337","-0.02830","-0.00145"
"12.90800","1.28470","-0.02635","-0.00146"
"12.92200","1.28604","0.03384","-0.00146"
"12.93600","1.28743","0.04367","-0.00145"
"12.95000","1.28884","0.02717","-0.00145"
"12.96400","1.29028","0.01085","-0.00145"
"12.97800","1.29174","-0.05388","-0.00145"
"12.99200","1.29322","-0.02017","-0.00145"
"13.00600","1.29463","0.02893","-0.00145"
"13.02000","1.29599","0.06379","-0.00145"
"13.03400","1.29733","-0.01177","-0.00145"
"13.04800","1.29872","-0.03567","-0.00145"
"13.06200","1.30014","-0.06152","-0.00145"
"13.07600","1.30159","-0.09607","-0.00145"
"13.09000","1.30303","-0.03323","-0.00145"
"13.10400","1.30445","-0.04454","-0.00145"
"13.11800","1.30584","-0.04606","-0.00145"
"13.13200","1.30720","-0.01852","-0.00146"
"13.14600","1.30857","-0.05647","-0.00146"
"13.16000","1.30998","-0.05953","-0.00145"
"13.17400","1.31140","-0.02096","-0.00145"
"13.18800","1.31283","0.05796","-0.00145"
"13.20200","1.31428","0.15343","-0.00145"
"13.21600","1.31575","0.09255","-0.00145"
"13.23000","1.31717","0.02324","-0.00145"
"13.24400","1.31852","0.05081","-0.00145"
"13.25800","1.31985","0.09613","-0.00145"
"13.27200","1.32122","0.13924","-0.00145"
"13.28600","1.32263","0.07572","-0.00145"
"13.30000","1.32406","0.00119","-0.00145"
"13.31400","1.32548","-0.02505","-0.00145"
"13.32800","1.32692","0.01642","-0.00145"
"13.34200","1.32833","0.01240","-0.00146"
"13.35600","1.32969","-0.05769","-0.00146"
"13.37000","1.33102","-0.03252","-0.00146"
"13.38400","1.33236","0.08717","-0.00146"
"13.39800","1.33373","0.14483","-0.00145"
"13.41200","1.33514","0.01616","-0.00145"
"13.42600","1.33656","-0.09552","-0.00145"
"13.44000","1.33802","-0.08279","-0.00145"
"13.45400","1.33945","-0.05981","-0.00145"
"13.46800","1.34084","-0.00595","-0.00145"
"13.48200","1.34217","0.00861","-0.00145"
"13.49600","1.34350","0.04364","-0.00145"
"13.51000","1.34488","0.06785","-0.00145"
"13.52400","1.34629","0.05295","-0.00145"
"13.53800","1.34771","0.02321","-0.00145"
"13.55200","1.34914","-0.02797","-0.00145"
"13.56600","1.35058","-0.02937","-0.00146"
"13.58000","1.35198","-0.04524","-0.00146"
"13.59400","1.35336","-0.02177","-0.00146"
"13.60800","1.35473","0.01257","-0.00146"
"13.62200","1.35611","0.01502","-0.00145"
"13.63600","1.35752","0.01250","-0.00145"
"13.65000","1.35894","0.01910","-0.00145"
"13.66400","1.36039","0.01186","-0.00145"
"13.67800","1.36186","-0.01125","-0.00145"
"13.69200","1.36327","-0.06779","-0.00145"
"13.70600","1.36462","-0.09414","-0.00145"
"13.72000","1.36595","-0.04852","-0.00145"
"13.73400","1.36733","0.02620","-0.00145"
"13.74800","1.36875","0.03078","-0.00145"
"13.76200","1.37020","0.02154","-0.00145"
"13.77600","1.37165","0.00155","-0.00145"
"13.79000","1.37311","-0.03955","-0.00146"
"13.80400","1.37454","-0.01247","-0.00146"
"13.81800","1.37592","0.00166","-0.00146"
"13.83200","1.37727","-0.00441","-0.00146"
"13.84600","1.37862","-0.00126","-0.00145"
"13.86000","1.38000","-0.01010","-0.00145"
"13.87400","1.38141","-0.05229","-0.00145"
"13.88800","1.38285","-0.06457","-0.00145"
"13.90200","1.38430","-0.08267","-0.00145"
"13.91600","1.38572","-0.08767","-0.00145"
"13.93000","1.38710","-0.09534","-0.00145"
"13.94400","1.38844","-0.08251","-0.00145"
"13.95800","1.38981","0.01164","-0.00145"
"13.97200","1.39119","0.08779","-0.00145"
"13.98600","1.39257","0.13500","-0.00145"
"14.00000","1.39396","0.07951","-0.00145"
"14.01400","1.39537","-0.00800","-0.00146"
"14.02800","1.39680","-0.04892","-0.00146"
"14.04200","1.39819","-0.08663","-0.00146"
"14.05600","1.39955","-0.08675","-0.00145"
"14.07000","1.40091","-0.00414","-0.00145"
"14.08400","1.40230","0.00295","-0.00145"
"14.09800","1.40370","0.04025","-0.00145"
"14.11200","1.40511","0.03804","-0.00145"
"14.12600","1.40654","0.00623","-0.00145"
"14.14000","1.40798","-0.02476","-0.00145"
"14.15400","1.40937","0.01841","-0.00145"
"14.16800","1.41073","0.04238","-0.00145"
"14.18200","1.41209","0.01449","-0.00145"
"14.19600","1.41349","-0.04335","-0.00145"
"14.21000","1.41491","-0.05695","-0.00145"
"14.22400","1.41632","0.01017","-0.00146"
"14.23800","1.41773","0.03300","-0.00145"
"14.25200","1.41917","0.02699","-0.00145"
"14.26600","1.42060","0.02706","-0.00146"
"14.28000","1.42199","-0.04777","-0.00146"
"14.29400","1.42335","-0.04815","-0.00145"
"14.30800","1.42473","0.00697","-0.00145"
"14.32200","1.42613","0.05700","-0.00145"
"14.33600","1.42755","0.08454","-0.00145"
"14.35000","1.42900","0.10876","-0.00145"
"14.36400","1.43046","0.07480","-0.00145"
"14.37800","1.43188","-0.02983","-0.00145"
"14.39200","1.43326","-0.14332","-0.00145"
"14.40600","1.43463","-0.13412","-0.00145"
"14.42000","1.43603","-0.10649","-0.00145"
"14.43400","1.43743","-0.09743","-0.00145"
"14.44800","1.43880","-0.07921","-0.00145"
"14.46200","1.44018","-0.06821","-0.00146"
"14.47600","1.44160","0.01012","-0.00146"
"14.49000","1.44304","0.12963","-0.00146"
"14.50400","1.44444","0.17926","-0.00145"
"14.51800","1.44581","0.19813","-0.00145"
"14.53200","1.44717","0.13135","-0.00145"
"14.54600","1.44857","0.09574","-0.00145"
"14.56000","1.44997","0.01053","-0.00145"
"14.57400","1.45138","-0.05844","-0.00145"
"14.58800","1.45280","-0.07874","-0.00145"
"14.60200","1.45422","-0.08589","-0.00145"
"14.61600","1.45560","-0.12565","-0.00145"
"14.63000","1.45695","-0.09697","-0.00145"
"14.64400","1.45832","-0.05017","-0.00145"
"14.65800","1.45972","-0.05549","-0.00146"
"14.67200","1.46113","-0.02590","-0.00146"
"14.68600","1.46253","0.05662","-0.00146"
"14.70000","1.46394","0.04823","-0.00146"
"14.71400","1.46535","-0.05572","-0.00146"
"14.72800","1.46673","-0.11925","-0.00145"
"14.74200","1.46808","-0.10196","-0.00145"
"14.75600","1.46942","-0.05670","-0.00145"
"14.77000","1.47082","-0.07411","-0.00144"
"14.78400","1.47226","-0.03332","-0.00144"
"14.79800","1.47372","-0.00326","-0.00144"
"14.81200","1.47518","-0.02227","-0.00144"
"14.82600","1.47663","-0.04736","-0.00143"
"14.84000","1.47802","-0.03065","-0.00143"
"14.85400","1.47937","0.01677","-0.00143"
"14.86800","1.48073","0.07773","-0.00143"
"14.88200","1.48213","-0.00168","-0.00144"
"14.89600","1.48355","-0.05693","-0.00144"
"14.91000","1.48496","-0.01860","-0.00145"
"14.92400","1.48638","0.03452","-0.00146"
"14.93800","1.48783","0.04295","-0.00146"
"14.95200","1.48927","0.11901","-0.00147"
"14.96600","1.49066","0.08985","-0.00147"
"14.98000","1.49202","0.01692","-0.00148"
"14.99400","1.49339","-0.07046","-0.00148"
"15.00800","1.49481","-0.11384","-0.00148"
"15.02200","1.49625","-0.07439","-0.00149"
"15.03600","1.49769","-0.02776","-0.00149"
"15.05000","1.49912","-0.05192","-0.00149"
"15.06400","1.50053","-0.02500","-0.00150"
"15.07800","1.50191","-0.01223","-0.00151"
"15.09200","1.50327","0.04415","-0.00152"
"15.10600","1.50465","0.06591","-0.00153"
"15.12000","1.50604","-0.00930","-0.00154"
"15.13400","1.50743","-0.02942","-0.00155"
"15.14800","1.50882","-0.01367","-0.00156"
"15.16200","1.51024","-0.00355","-0.00157"
"15.17600","1.51165","-0.02887","-0.00157"
"15.19000","1.51300","-0.04027","-0.00158"
"15.20400","1.51433","-0.03243","-0.00159"
"15.21800","1.51568","-0.00185","-0.00159"
"15.23200","1.51709","0.05806","-0.00158"
"15.24600","1.51852","0.06282","-0.00156"
"15.26000","1.51996","0.00970","-0.00155"
"15.27400","1.52140","0.05033","-0.00155"
"15.28800","1.52283","0.05759","-0.00156"
"15.30200","1.52420","-0.00710","-0.00158"
"15.31600","1.52554","-0.02851","-0.00159"
"15.33000","1.52688","-0.05889","-0.00161"
"15.34400","1.52827","-0.08486","-0.00162"
"15.35800","1.52968","-0.07984","-0.00163"
"15.37200","1.53111","0.01261","-0.00164"
"15.38600","1.53257","0.02129","-0.00165"
"15.40000","1.53404","0.02448","-0.00165"
"15.41400","1.53546","0.00968","-0.00165"
"15.42800","1.53682","-0.00731","-0.00165"
"15.44200","1.53815","0.00389","-0.00165"
"15.45600","1.53952","-0.02012","-0.00165"
"15.47000","1.54094","-0.03402","-0.00166"
"15.48400","1.54238","-0.04272","-0.00166"
"15.49800","1.54382","-0.06744","-0.00166"
"15.51200","1.54526","-0.18142","-0.00167"
"15.52600","1.54665","-0.17376","-0.00167"
"15.54000","1.54802","-0.11461","-0.00167"
"15.55400","1.54938","-0.05464","-0.00167"
"15.56800","1.55078","-0.02422","-0.00167"
"15.58200","1.55219","-0.00445","-0.00168"
"15.59600","1.55361","0.02015","-0.00168"
"15.61000","1.55505","0.01255","-0.00168"
"15.62400","1.55652","-0.06951","-0.00169"
"15.63800","1.55794","-0.08531","-0.00169"
"15.65200","1.55930","-0.06426","-0.00169"
"15.66600","1.56063","-0.01777","-0.00169"
"15.68000","1.56200","0.00522","-0.00169"
"15.69400","1.56343","0.00706","-0.00169"
"15.70800","1.56487","0.03949","-0.00169"
"15.72200","1.56632","0.09305","-0.00169"
"15.73600","1.56776","0.05819","-0.00169"
"15.75000","1.56917","0.03139","-0.00169"
"15.76400","1.57053","0.03070","-0.00169"
"15.77800","1.57185","-0.02182","-0.00170"
"15.79200","1.57317","-0.04119","-0.00170"
"15.80600","1.57452","-0.03159","-0.00170"
"15.82000","1.57591","0.00853","-0.00170"
"15.83400","1.57733","0.01253","-0.00171"
"15.84800","1.57879","-0.03278","-0.00171"
"15.86200","1.58024","-0.11216","-0.00171"
"15.87600","1.58164","-0.08943","-0.00171"
"15.89000","1.58298","-0.03846","-0.00171"
"15.90400","1.58430","0.04260","-0.00171"
"15.91800","1.58567","0.07383","-0.00171"
"15.93200","1.58708","0.01174","-0.00171"
"15.94600","1.58850","-0.04758","-0.00171"
"15.96000","1.58993","0.03011","-0.00170"
"15.97400","1.59138","0.06026","-0.00170"
"15.98800","1.59279","0.07144","-0.00170"
"16.00200","1.59417","0.04478","-0.00170"
"16.01600","1.59553","0.02222","-0.00170"
"16.03000","1.59691","-0.01090","-0.00171"
"16.04400","1.59830","-0.00216","-0.00171"
"16.05800","1.59970","0.05377","-0.00170"
"16.07200","1.60113","0.08356","-0.00170"
"16.08600","1.60260","0.01249","-0.00170"
"16.10000","1.60403","-0.00649","-0.00170"
"16.11400","1.60540","-0.01215","-0.00170"
"16.12800","1.60675","-0.06989","-0.00170"
"16.14200","1.60813","-0.04583","-0.00170"
"16.15600","1.60955","0.01665","-0.00171"
"16.17000","1.61099","0.05262","-0.00171"
"16.18400","1.61244","0.01248","-0.00171"
"16.19800","1.61390","-0.03017","-0.00172"
"16.21200","1.61534","-0.02843","-0.00172"
"16.22600","1.61673","0.03294","-0.00172"
"16.24000","1.61808","0.05137","-0.00172"
"16.25400","1.61943","0.02098","-0.00172"
"16.26800","1.62081","0.02886","-0.00172"
"16.28200","1.62222","0.04074","-0.00172"
"16.29600","1.62366","0.01374","-0.00171"
"16.31000","1.62511","-0.03329","-0.00171"
"16.32400","1.62654","-0.10932","-0.00171"
"16.33800","1.62790","-0.12919","-0.00171"
"16.35200","1.62924","-0.09776","-0.00171"
"16.36600","1.63059","-0.08812","-0.00171"
"16.38000","1.63197","-0.08057","-0.00171"
"16.39400","1.63336","-0.07069","-0.00172"
"16.40800","1.63475","-0.05184","-0.00172"
"16.42200","1.63616","-0.08360","-0.00173"
"16.43600","1.63759","-0.09091","-0.00173"
"16.45000","1.63900","-0.05665","-0.00173"
"16.46400","1.64037","-0.03456","-0.00174"
"16.47800","1.64173","0.02547","-0.00174"
"16.49200","1.64311","0.14559","-0.00173"
"16.50600","1.64450","0.13145","-0.00173"
"16.52000","1.64590","0.02948","-0.00172"
"16.53400","1.64732","0.00327","-0.00172"
"16.54800","1.64876","0.00646","-0.00172"
"16.56200","1.65017","0.00464","-0.00172"
"16.57600","1.65154","-0.05358","-0.00172"
"16.59000","1.65291","-0.05904","-0.00172"
"16.60400","1.65431","-0.07866","-0.00172"
"16.61800","1.65573","-0.07293","-0.00171"
"16.63200","1.65713","-0.09792","-0.00171"
"16.64600","1.65854","-0.05414","-0.00171"
"16.66000","1.65998","-0.04366","-0.00171"
"16.67400","1.66140","-0.05239","-0.00171"
"16.68800","1.66279","-0.03130","-0.00171"
"16.70200","1.66415","0.01656","-0.00171"
"16.71600","1.66553","0.06843","-0.00171"
"16.73000","1.66693","0.06104","-0.00171"
"16.74400","1.66835","0.01820","-0.00171"
"16.75800","1.66979","-0.02008","-0.00171"
"16.77200","1.67126","-0.09704","-0.00171"
"16.78600","1.67269","-0.07134","-0.00171"
"16.80000","1.67407","0.02801","-0.00171"
"16.81000","1.67505","0.06445","-0.00171"