File: archive/undergrad/433/Pressure Vessel/Specimen_RawData_3.csv
Time,Extension,Load,Strain Gage18
(s),(mm),(N),(mm/mm)
"0.00000","0.00000","-0.05907","0.00002"
"0.01800","0.00000","-0.01267","0.00001"
"0.03600","0.00010","0.06774","0.00001"
"0.05400","0.00048","0.07266","0.00002"
"0.07200","0.00137","0.03001","0.00002"
"0.09000","0.00268","-0.02005","0.00002"
"0.10800","0.00364","-0.00227","0.00002"
"0.12600","0.00436","-0.02711","0.00002"
"0.14400","0.00554","-0.02688","0.00002"
"0.16200","0.00748","-0.00481","0.00002"
"0.18000","0.00993","0.04116","0.00002"
"0.19800","0.01251","0.00488","0.00002"
"0.21600","0.01493","-0.00895","0.00002"
"0.23400","0.01710","-0.00815","0.00001"
"0.25200","0.01910","-0.02596","0.00001"
"0.27000","0.02093","0.05246","0.00001"
"0.28800","0.02267","0.07049","0.00002"
"0.30600","0.02445","0.02003","0.00002"
"0.32400","0.02630","-0.02638","0.00002"
"0.34200","0.02817","-0.07727","0.00002"
"0.36000","0.03004","-0.13154","0.00002"
"0.37800","0.03184","-0.07228","0.00002"
"0.39600","0.03360","-0.03269","0.00002"
"0.41400","0.03537","0.08999","0.00002"
"0.43200","0.03715","0.03376","0.00002"
"0.45000","0.03894","0.02531","0.00002"
"0.46800","0.04077","0.02669","0.00002"
"0.48600","0.04257","-0.03902","0.00002"
"0.50400","0.04430","-0.13466","0.00002"
"0.52200","0.04601","-0.06948","0.00002"
"0.54000","0.04780","-0.04850","0.00002"
"0.55800","0.04963","-0.03099","0.00002"
"0.57600","0.05147","-0.00024","0.00002"
"0.59400","0.05330","-0.00438","0.00002"
"0.61200","0.05505","0.01839","0.00002"
"0.63000","0.05679","0.01907","0.00002"
"0.64800","0.05858","0.02704","0.00002"
"0.66600","0.06041","0.04988","0.00002"
"0.68400","0.06226","0.05635","0.00002"
"0.70200","0.06414","-0.05285","0.00002"
"0.72000","0.06596","-0.10513","0.00002"
"0.73800","0.06769","-0.06725","0.00002"
"0.75600","0.06942","-0.01179","0.00002"
"0.77400","0.07122","0.06296","0.00002"
"0.79200","0.07306","-0.00929","0.00002"
"0.81000","0.07491","-0.05522","0.00002"
"0.82800","0.07672","-0.11852","0.00002"
"0.84600","0.07849","-0.12141","0.00002"
"0.86400","0.08026","-0.04868","0.00002"
"0.88200","0.08208","-0.02166","0.00002"
"0.90000","0.08393","-0.02687","0.00002"
"0.91800","0.08581","0.01579","0.00002"
"0.93600","0.08769","0.02805","0.00002"
"0.95400","0.08946","0.01670","0.00002"
"0.97200","0.09115","-0.01018","0.00002"
"0.99000","0.09292","-0.09591","0.00002"
"1.00800","0.09475","-0.12694","0.00002"
"1.02600","0.09659","-0.12153","0.00002"
"1.04400","0.09843","-0.07589","0.00002"
"1.06200","0.10023","-0.09650","0.00002"
"1.08000","0.10196","-0.01887","0.00002"
"1.09800","0.10369","0.08069","0.00002"
"1.11600","0.10546","-0.01807","0.00002"
"1.13400","0.10726","-0.06168","0.00002"
"1.15200","0.10912","-0.03092","0.00002"
"1.17000","0.11096","0.00253","0.00002"
"1.18800","0.11271","-0.02066","0.00002"
"1.20600","0.11440","-0.16711","0.00002"
"1.22400","0.11616","-0.11931","0.00002"
"1.24200","0.11798","-0.03120","0.00002"
"1.26000","0.11982","-0.00619","0.00002"
"1.27800","0.12168","-0.04063","0.00002"
"1.29600","0.12350","-0.07531","0.00002"
"1.31400","0.12526","-0.05874","0.00002"
"1.33200","0.12703","-0.08109","0.00002"
"1.35000","0.12883","-0.13339","0.00002"
"1.36800","0.13066","-0.07144","0.00002"
"1.38600","0.13253","-0.05184","0.00002"
"1.40400","0.13437","-0.06803","0.00002"
"1.42200","0.13611","-0.04544","0.00002"
"1.44000","0.13784","-0.05654","0.00002"
"1.45800","0.13965","-0.08713","0.00002"
"1.47600","0.14149","-0.04765","0.00002"
"1.49400","0.14335","-0.07351","0.00002"
"1.51200","0.14523","-0.09878","0.00002"
"1.53000","0.14705","-0.05933","0.00002"
"1.54800","0.14880","-0.05932","0.00002"
"1.56600","0.15055","-0.00202","0.00002"
"1.58400","0.15235","0.00382","0.00002"
"1.60200","0.15420","-0.04083","0.00002"
"1.62000","0.15607","-0.00805","0.00002"
"1.63800","0.15786","-0.04150","0.00002"
"1.65600","0.15956","-0.02590","0.00002"
"1.67400","0.16127","-0.04619","0.00002"
"1.69200","0.16305","0.00399","0.00002"
"1.71000","0.16484","0.02922","0.00002"
"1.72800","0.16667","0.02648","0.00002"
"1.74600","0.16850","-0.00645","0.00002"
"1.76400","0.17027","0.07140","0.00002"
"1.78200","0.17201","0.06942","0.00002"
"1.80000","0.17380","0.04525","0.00002"
"1.81800","0.17560","-0.05002","0.00002"
"1.83600","0.17742","-0.01222","0.00002"
"1.85400","0.17927","0.01003","0.00002"
"1.87200","0.18106","0.04613","0.00002"
"1.89000","0.18281","0.02783","0.00002"
"1.90800","0.18461","0.00370","0.00002"
"1.92600","0.18643","0.00631","0.00002"
"1.94400","0.18823","0.02149","0.00002"
"1.96200","0.19007","-0.03035","0.00002"
"1.98000","0.19192","-0.08137","0.00002"
"1.99800","0.19371","-0.09104","0.00002"
"2.01600","0.19547","-0.05546","0.00002"
"2.03400","0.19726","0.02996","0.00002"
"2.05200","0.19908","0.04227","0.00002"
"2.07000","0.20095","-0.01271","0.00002"
"2.08800","0.20281","-0.03816","0.00002"
"2.10600","0.20458","-0.00527","0.00002"
"2.12400","0.20634","-0.03185","0.00002"
"2.14200","0.20815","-0.02862","0.00002"
"2.16000","0.20996","-0.04761","0.00002"
"2.17800","0.21177","0.00006","0.00002"
"2.19600","0.21362","-0.01198","0.00002"
"2.21400","0.21543","-0.07148","0.00002"
"2.23200","0.21717","-0.03975","0.00002"
"2.25000","0.21893","-0.03563","0.00002"
"2.26800","0.22074","-0.05769","0.00002"
"2.28600","0.22256","-0.01190","0.00002"
"2.30400","0.22438","0.00164","0.00002"
"2.32200","0.22616","0.00272","0.00002"
"2.34000","0.22789","-0.03004","0.00002"
"2.35800","0.22961","-0.05365","0.00002"
"2.37600","0.23141","-0.08708","0.00002"
"2.39400","0.23322","-0.02806","0.00002"
"2.41200","0.23505","-0.01413","0.00002"
"2.43000","0.23689","-0.01325","0.00002"
"2.44800","0.23866","-0.02724","0.00002"
"2.46600","0.24037","-0.04851","0.00002"
"2.48400","0.24214","-0.15236","0.00002"
"2.50200","0.24398","-0.12095","0.00002"
"2.52000","0.24584","-0.07204","0.00002"
"2.53800","0.24771","-0.05902","0.00002"
"2.55600","0.24951","-0.04111","0.00002"
"2.57400","0.25125","-0.07153","0.00002"
"2.59200","0.25303","-0.08656","0.00002"
"2.61000","0.25486","-0.11321","0.00002"
"2.62800","0.25668","-0.06416","0.00002"
"2.64600","0.25852","-0.05970","0.00002"
"2.66400","0.26037","-0.11066","0.00002"
"2.68200","0.26217","-0.05324","0.00002"
"2.70000","0.26393","-0.02069","0.00002"
"2.71800","0.26572","0.06486","0.00002"
"2.73600","0.26756","0.04074","0.00002"
"2.75400","0.26941","-0.00316","0.00002"
"2.77200","0.27124","-0.03761","0.00002"
"2.79000","0.27302","-0.09302","0.00002"
"2.80800","0.27477","-0.01918","0.00002"
"2.82600","0.27654","-0.04876","0.00002"
"2.84400","0.27832","-0.15838","0.00002"
"2.86200","0.28013","-0.11250","0.00002"
"2.88000","0.28198","0.01665","0.00002"
"2.89800","0.28378","0.06854","0.00002"
"2.91600","0.28550","0.13069","0.00002"
"2.93400","0.28721","0.06580","0.00002"
"2.95200","0.28901","0.03824","0.00002"
"2.97000","0.29085","0.07681","0.00002"
"2.98800","0.29269","0.05742","0.00002"
"3.00600","0.29450","0.02832","0.00002"
"3.02400","0.29624","-0.01142","0.00002"
"3.04200","0.29797","-0.05980","0.00002"
"3.06000","0.29976","-0.10029","0.00002"
"3.07800","0.30158","-0.09533","0.00002"
"3.09600","0.30343","-0.06463","0.00002"
"3.11400","0.30533","-0.08371","0.00002"
"3.13200","0.30716","-0.05216","0.00002"
"3.15000","0.30890","-0.10534","0.00002"
"3.16800","0.31064","-0.13417","0.00002"
"3.18600","0.31244","-0.03304","0.00002"
"3.20400","0.31427","0.05978","0.00002"
"3.22200","0.31611","0.03798","0.00002"
"3.24000","0.31793","-0.05804","0.00002"
"3.25800","0.31969","-0.14117","0.00002"
"3.27600","0.32145","-0.15793","0.00002"
"3.29400","0.32327","-0.21001","0.00002"
"3.31200","0.32512","-0.16567","0.00002"
"3.33000","0.32701","-0.03430","0.00002"
"3.34800","0.32889","-0.02965","0.00002"
"3.36600","0.33065","-0.06458","0.00002"
"3.38400","0.33235","-0.05612","0.00002"
"3.40200","0.33413","-0.08817","0.00002"
"3.42000","0.33597","-0.02409","0.00002"
"3.43800","0.33781","0.01226","0.00002"
"3.45600","0.33964","0.06826","0.00002"
"3.47400","0.34143","0.13907","0.00002"
"3.49200","0.34316","0.01865","0.00002"
"3.51000","0.34489","-0.04996","0.00002"
"3.52800","0.34666","-0.01771","0.00002"
"3.54600","0.34846","0.00162","0.00002"
"3.56400","0.35031","0.02919","0.00002"
"3.58200","0.35216","0.02657","0.00002"
"3.60000","0.35391","0.03793","0.00002"
"3.61800","0.35561","0.05940","0.00002"
"3.63600","0.35738","0.03439","0.00002"
"3.65400","0.35920","0.07622","0.00002"
"3.67200","0.36103","0.07608","0.00003"
"3.69000","0.36288","-0.00592","0.00003"
"3.70800","0.36469","-0.00711","0.00002"
"3.72600","0.36644","-0.03744","0.00002"
"3.74400","0.36821","-0.08411","0.00002"
"3.76200","0.37003","-0.07453","0.00002"
"3.78000","0.37188","0.01446","0.00002"
"3.79800","0.37377","0.06179","0.00002"
"3.81600","0.37560","0.13177","0.00002"
"3.83400","0.37732","0.12313","0.00002"
"3.85200","0.37904","0.07274","0.00003"
"3.87000","0.38084","-0.02687","0.00003"
"3.88800","0.38269","-0.04011","0.00003"
"3.90600","0.38455","0.01580","0.00003"
"3.92400","0.38642","0.01689","0.00003"
"3.94200","0.38823","0.01643","0.00002"
"3.96000","0.38997","0.09084","0.00002"
"3.97800","0.39172","0.04561","0.00002"
"3.99600","0.39351","0.01054","0.00002"
"4.01400","0.39535","0.02484","0.00002"
"4.03200","0.39722","0.03166","0.00002"
"4.05000","0.39902","0.00550","0.00002"
"4.06800","0.40075","-0.03459","0.00003"
"4.08600","0.40249","-0.07583","0.00003"
"4.10400","0.40427","-0.06581","0.00003"
"4.12200","0.40607","-0.08664","0.00003"
"4.14000","0.40790","-0.03968","0.00003"
"4.15800","0.40973","-0.03000","0.00002"
"4.17600","0.41149","-0.04400","0.00002"
"4.19400","0.41324","-0.01401","0.00002"
"4.21200","0.41503","-0.02325","0.00002"
"4.23000","0.41684","-0.02190","0.00002"
"4.24800","0.41868","-0.07921","0.00002"
"4.26600","0.42052","-0.03114","0.00002"
"4.28400","0.42230","0.01545","0.00003"
"4.30200","0.42403","-0.02011","0.00003"
"4.32000","0.42581","-0.10008","0.00003"
"4.33800","0.42762","-0.12387","0.00003"
"4.35600","0.42943","-0.13889","0.00003"
"4.37400","0.43127","-0.03866","0.00003"
"4.39200","0.43311","-0.01650","0.00002"
"4.41000","0.43489","0.00358","0.00002"
"4.42800","0.43666","-0.04959","0.00002"
"4.44600","0.43845","-0.04414","0.00002"
"4.46400","0.44026","0.10442","0.00002"
"4.48200","0.44213","0.13052","0.00002"
"4.50000","0.44398","0.06547","0.00002"
"4.51800","0.44576","0.06499","0.00002"
"4.53600","0.44753","0.01272","0.00002"
"4.55400","0.44935","-0.00054","0.00002"
"4.57200","0.45116","-0.02654","0.00002"
"4.59000","0.45297","-0.03475","0.00002"
"4.60800","0.45482","0.02516","0.00002"
"4.62600","0.45663","-0.01739","0.00002"
"4.64400","0.45837","0.01569","0.00002"
"4.66200","0.46013","-0.00115","0.00002"
"4.68000","0.46193","-0.02263","0.00002"
"4.69800","0.46374","-0.05034","0.00002"
"4.71600","0.46556","-0.03369","0.00002"
"4.73400","0.46735","-0.08022","0.00002"
"4.75200","0.46908","-0.03231","0.00003"
"4.77000","0.47083","0.00236","0.00003"
"4.78800","0.47263","-0.07583","0.00003"
"4.80600","0.47444","-0.06160","0.00002"
"4.82400","0.47626","-0.03765","0.00002"
"4.84200","0.47809","-0.05394","0.00002"
"4.86000","0.47986","-0.04265","0.00002"
"4.87800","0.48157","-0.05638","0.00002"
"4.89600","0.48335","-0.03620","0.00002"
"4.91400","0.48520","0.00341","0.00002"
"4.93200","0.48707","0.00107","0.00002"
"4.95000","0.48894","-0.03423","0.00002"
"4.96800","0.49073","-0.07211","0.00002"
"4.98600","0.49246","-0.11320","0.00002"
"5.00400","0.49423","-0.11533","0.00002"
"5.02200","0.49605","-0.11450","0.00002"
"5.04000","0.49786","-0.08229","0.00002"
"5.05800","0.49971","-0.07902","0.00002"
"5.07600","0.50156","-0.08564","0.00002"
"5.09400","0.50335","-0.11319","0.00002"
"5.11200","0.50511","-0.13104","0.00002"
"5.13000","0.50693","-0.13875","0.00002"
"5.14800","0.50879","-0.09390","0.00002"
"5.16600","0.51064","-0.07675","0.00002"
"5.18400","0.51248","-0.07022","0.00002"
"5.20200","0.51425","-0.07577","0.00002"
"5.22000","0.51600","-0.08894","0.00002"
"5.23800","0.51776","-0.04905","0.00002"
"5.25600","0.51953","-0.01841","0.00002"
"5.27400","0.52131","0.00926","0.00002"
"5.29200","0.52314","-0.01614","0.00002"
"5.31000","0.52494","-0.07341","0.00002"
"5.32800","0.52666","-0.09322","0.00002"
"5.34600","0.52838","-0.08857","0.00002"
"5.36400","0.53019","-0.08816","0.00002"
"5.38200","0.53204","-0.06088","0.00002"
"5.40000","0.53390","-0.00589","0.00002"
"5.41800","0.53571","-0.03443","0.00002"
"5.43600","0.53744","-0.10195","0.00002"
"5.45400","0.53917","-0.08105","0.00002"
"5.47200","0.54095","-0.03644","0.00002"
"5.49000","0.54278","0.00746","0.00002"
"5.50800","0.54462","0.02229","0.00002"
"5.52600","0.54650","0.00427","0.00002"
"5.54400","0.54832","-0.07898","0.00002"
"5.56200","0.55007","-0.11969","0.00002"
"5.58000","0.55183","-0.14550","0.00002"
"5.59800","0.55365","-0.09376","0.00002"
"5.61600","0.55549","-0.00593","0.00002"
"5.63400","0.55734","-0.02732","0.00002"
"5.65200","0.55914","-0.04051","0.00002"
"5.67000","0.56090","0.00618","0.00002"
"5.68800","0.56267","-0.00019","0.00002"
"5.70600","0.56448","-0.01166","0.00002"
"5.72400","0.56632","-0.08531","0.00002"
"5.74200","0.56820","-0.03902","0.00002"
"5.76000","0.57006","-0.02997","0.00002"
"5.77800","0.57182","-0.01613","0.00002"
"5.79600","0.57352","-0.02921","0.00002"
"5.81400","0.57532","-0.04977","0.00002"
"5.83200","0.57717","-0.05193","0.00002"
"5.85000","0.57901","-0.07010","0.00002"
"5.86800","0.58085","-0.00168","0.00002"
"5.88600","0.58263","-0.03518","0.00002"
"5.90400","0.58434","-0.03762","0.00002"
"5.92200","0.58607","-0.03051","0.00002"
"5.94000","0.58783","0.01564","0.00002"
"5.95800","0.58964","-0.01564","0.00002"
"5.97600","0.59150","-0.05285","0.00002"
"5.99400","0.59335","-0.13252","0.00002"
"6.01200","0.59510","-0.07639","0.00002"
"6.03000","0.59681","-0.01294","0.00002"
"6.04800","0.59858","0.04559","0.00002"
"6.06600","0.60039","0.02673","0.00002"
"6.08400","0.60223","-0.01893","0.00002"
"6.10200","0.60408","-0.03745","0.00002"
"6.12000","0.60588","-0.06908","0.00002"
"6.13800","0.60763","-0.09878","0.00002"
"6.15600","0.60941","-0.04201","0.00002"
"6.17400","0.61123","-0.04157","0.00002"
"6.19200","0.61308","-0.03281","0.00002"
"6.21000","0.61497","-0.02018","0.00002"
"6.22800","0.61680","-0.01019","0.00002"
"6.24600","0.61854","-0.00058","0.00002"
"6.26400","0.62027","0.01209","0.00002"
"6.28200","0.62208","-0.00661","0.00002"
"6.30000","0.62393","-0.05331","0.00002"
"6.31800","0.62579","0.00805","0.00002"
"6.33600","0.62766","0.02349","0.00002"
"6.35400","0.62945","-0.01395","0.00002"
"6.37200","0.63117","-0.04694","0.00002"
"6.39000","0.63292","-0.11600","0.00002"
"6.40800","0.63472","-0.11210","0.00002"
"6.42600","0.63657","-0.06419","0.00002"
"6.44400","0.63844","-0.00134","0.00002"
"6.46200","0.64024","0.03319","0.00002"
"6.48000","0.64196","0.07478","0.00002"
"6.49800","0.64371","0.02382","0.00002"
"6.51600","0.64548","-0.02966","0.00003"
"6.53400","0.64726","-0.01933","0.00003"
"6.55200","0.64907","0.00519","0.00003"
"6.57000","0.65090","-0.03652","0.00002"
"6.58800","0.65268","-0.04882","0.00002"
"6.60600","0.65443","-0.05010","0.00002"
"6.62400","0.65622","-0.05398","0.00002"
"6.64200","0.65802","-0.02535","0.00002"
"6.66000","0.65986","-0.01240","0.00002"
"6.67800","0.66171","0.00586","0.00002"
"6.69600","0.66350","0.03121","0.00003"
"6.71400","0.66524","0.06412","0.00003"
"6.73200","0.66703","0.07930","0.00003"
"6.75000","0.66885","0.04318","0.00003"
"6.76800","0.67065","0.00834","0.00003"
"6.78600","0.67249","-0.01348","0.00003"
"6.80400","0.67432","-0.02728","0.00003"
"6.82200","0.67610","-0.07418","0.00002"
"6.84000","0.67786","-0.03782","0.00002"
"6.85800","0.67965","-0.03617","0.00002"
"6.87600","0.68146","-0.03135","0.00002"
"6.89400","0.68332","0.00598","0.00003"
"6.91200","0.68517","0.00369","0.00003"
"6.93000","0.68696","-0.04005","0.00003"
"6.94800","0.68875","-0.03631","0.00003"
"6.96600","0.69058","-0.08521","0.00003"
"6.98400","0.69237","-0.01794","0.00003"
"7.00200","0.69416","0.01310","0.00003"
"7.02000","0.69601","0.03566","0.00003"
"7.03800","0.69783","0.04785","0.00003"
"7.05600","0.69956","0.01520","0.00003"
"7.07400","0.70132","-0.00745","0.00002"
"7.09200","0.70312","-0.04697","0.00002"
"7.11000","0.70492","-0.03630","0.00002"
"7.12800","0.70674","-0.03324","0.00003"
"7.14600","0.70851","-0.02123","0.00003"
"7.16400","0.71024","0.01417","0.00003"
"7.18200","0.71199","0.02970","0.00003"
"7.20000","0.71380","0.01810","0.00003"
"7.21800","0.71561","0.01133","0.00003"
"7.23600","0.71743","0.05236","0.00003"
"7.25400","0.71925","0.04354","0.00003"
"7.27200","0.72101","0.04930","0.00003"
"7.29000","0.72273","-0.00188","0.00002"
"7.30800","0.72452","-0.01670","0.00002"
"7.32600","0.72638","-0.05514","0.00002"
"7.34400","0.72827","-0.10510","0.00002"
"7.36200","0.73014","-0.11052","0.00002"
"7.38000","0.73193","-0.01400","0.00003"
"7.39800","0.73367","0.01562","0.00003"
"7.41600","0.73545","0.00074","0.00003"
"7.43400","0.73727","-0.01102","0.00003"
"7.45200","0.73909","-0.02724","0.00003"
"7.47000","0.74095","-0.03033","0.00003"
"7.48800","0.74280","-0.00795","0.00002"
"7.50600","0.74458","0.02303","0.00002"
"7.52400","0.74632","-0.01574","0.00002"
"7.54200","0.74812","-0.05540","0.00002"
"7.56000","0.74997","-0.04634","0.00002"
"7.57800","0.75183","-0.01747","0.00002"
"7.59600","0.75366","-0.00564","0.00003"
"7.61400","0.75544","-0.03911","0.00003"
"7.63200","0.75719","-0.03166","0.00003"
"7.65000","0.75897","-0.01145","0.00003"
"7.66800","0.76074","0.02180","0.00003"
"7.68600","0.76252","0.05863","0.00003"
"7.70400","0.76434","-0.00272","0.00002"
"7.72200","0.76613","-0.06590","0.00002"
"7.74000","0.76784","-0.04179","0.00002"
"7.75800","0.76957","0.06753","0.00002"
"7.77600","0.77139","0.02574","0.00002"
"7.79400","0.77324","0.02564","0.00002"
"7.81200","0.77510","-0.03046","0.00002"
"7.83000","0.77692","-0.07482","0.00003"
"7.84800","0.77866","-0.02232","0.00003"
"7.86600","0.78039","0.09283","0.00003"
"7.88400","0.78218","0.07611","0.00003"
"7.90200","0.78399","-0.02922","0.00003"
"7.92000","0.78584","-0.11742","0.00002"
"7.93800","0.78771","-0.12888","0.00002"
"7.95600","0.78952","-0.06194","0.00002"
"7.97400","0.79124","0.02338","0.00002"
"7.99200","0.79301","0.05314","0.00002"
"8.01000","0.79484","-0.02880","0.00002"
"8.02800","0.79670","-0.00574","0.00002"
"8.04600","0.79856","0.09638","0.00002"
"8.06400","0.80038","0.09086","0.00002"
"8.08200","0.80215","0.05804","0.00002"
"8.10000","0.80392","0.00923","0.00002"
"8.11800","0.80573","0.00561","0.00002"
"8.13600","0.80755","0.00938","0.00002"
"8.15400","0.80942","0.02886","0.00002"
"8.17200","0.81128","0.03116","0.00002"
"8.19000","0.81302","-0.07289","0.00002"
"8.20800","0.81473","-0.10399","0.00002"
"8.22600","0.81653","-0.15029","0.00002"
"8.24400","0.81839","-0.13832","0.00002"
"8.26200","0.82023","-0.04919","0.00002"
"8.28000","0.82207","-0.03018","0.00002"
"8.29800","0.82384","-0.03212","0.00002"
"8.31600","0.82555","0.01504","0.00002"
"8.33400","0.82727","0.02173","0.00002"
"8.35200","0.82904","-0.02155","0.00002"
"8.37000","0.83085","0.06079","0.00002"
"8.38800","0.83271","0.02116","0.00002"
"8.40600","0.83455","-0.07218","0.00002"
"8.42400","0.83629","-0.02797","0.00002"
"8.44200","0.83799","0.10008","0.00002"
"8.46000","0.83976","0.06872","0.00002"
"8.47800","0.84158","-0.09029","0.00002"
"8.49600","0.84342","-0.05649","0.00002"
"8.51400","0.84528","-0.00958","0.00002"
"8.53200","0.84709","0.02521","0.00002"
"8.55000","0.84884","0.06957","0.00002"
"8.56800","0.85062","0.01638","0.00002"
"8.58600","0.85243","0.00040","0.00002"
"8.60400","0.85427","0.05031","0.00002"
"8.62200","0.85615","0.00337","0.00002"
"8.64000","0.85797","-0.04424","0.00002"
"8.65800","0.85969","0.00128","0.00002"
"8.67600","0.86143","0.02063","0.00002"
"8.69400","0.86326","-0.02654","0.00002"
"8.71200","0.86512","-0.07891","0.00002"
"8.73000","0.86699","-0.09772","0.00002"
"8.74800","0.86886","-0.09449","0.00002"
"8.76600","0.87065","-0.04050","0.00002"
"8.78400","0.87238","0.00186","0.00002"
"8.80200","0.87413","-0.01197","0.00002"
"8.82000","0.87593","-0.01090","0.00002"
"8.83800","0.87778","-0.00060","0.00002"
"8.85600","0.87965","0.02498","0.00002"
"8.87400","0.88143","0.04749","0.00002"
"8.89200","0.88315","0.00390","0.00002"
"8.91000","0.88489","-0.10734","0.00002"
"8.92800","0.88667","-0.07943","0.00002"
"8.94600","0.88845","-0.06033","0.00002"
"8.96400","0.89028","0.00351","0.00002"
"8.98200","0.89211","-0.01912","0.00002"
"9.00000","0.89387","-0.01126","0.00002"
"9.01800","0.89561","0.00780","0.00002"
"9.03600","0.89740","-0.05401","0.00002"
"9.05400","0.89920","-0.09455","0.00002"
"9.07200","0.90103","-0.05699","0.00002"
"9.09000","0.90287","-0.08397","0.00002"
"9.10800","0.90466","-0.09485","0.00002"
"9.12600","0.90642","0.03074","0.00002"
"9.14400","0.90823","0.08101","0.00002"
"9.16200","0.91005","0.02852","0.00002"
"9.18000","0.91185","-0.00826","0.00002"
"9.19800","0.91369","-0.02670","0.00002"
"9.21600","0.91553","-0.10392","0.00002"
"9.23400","0.91730","-0.08219","0.00002"
"9.25200","0.91906","-0.11929","0.00002"
"9.27000","0.92084","-0.10199","0.00002"
"9.28800","0.92267","-0.11250","0.00001"
"9.30600","0.92455","-0.11236","0.00001"
"9.32400","0.92640","-0.04570","0.00002"
"9.34200","0.92817","-0.04759","0.00002"
"9.36000","0.92995","-0.02007","0.00002"
"9.37800","0.93177","0.03425","0.00002"
"9.39600","0.93357","0.04490","0.00002"
"9.41400","0.93539","0.05685","0.00002"
"9.43200","0.93725","-0.02470","0.00002"
"9.45000","0.93904","0.01428","0.00002"
"9.46800","0.94076","-0.04091","0.00002"
"9.48600","0.94252","-0.03331","0.00002"
"9.50400","0.94432","0.03502","0.00001"
"9.52200","0.94612","0.11394","0.00001"
"9.54000","0.94794","0.08712","0.00001"
"9.55800","0.94973","0.01951","0.00002"
"9.57600","0.95148","0.00952","0.00002"
"9.59400","0.95326","-0.05806","0.00002"
"9.61200","0.95507","-0.17423","0.00002"
"9.63000","0.95687","-0.10459","0.00002"
"9.64800","0.95868","-0.11267","0.00002"
"9.66600","0.96049","-0.08538","0.00002"
"9.68400","0.96222","-0.02971","0.00002"
"9.70200","0.96392","-0.03823","0.00001"
"9.72000","0.96570","-0.01654","0.00001"
"9.73800","0.96756","0.04154","0.00001"
"9.75600","0.96945","0.02964","0.00001"
"9.77400","0.97133","0.03442","0.00001"
"9.79200","0.97312","0.10409","0.00001"
"9.81000","0.97486","0.06116","0.00002"
"9.82800","0.97665","-0.02471","0.00002"
"9.84600","0.97848","-0.00017","0.00002"
"9.86400","0.98030","-0.05588","0.00002"
"9.88200","0.98215","-0.11714","0.00002"
"9.90000","0.98399","-0.13443","0.00001"
"9.91800","0.98576","-0.04376","0.00001"
"9.93600","0.98750","0.02008","0.00001"
"9.95400","0.98932","0.02650","0.00001"
"9.97200","0.99117","-0.00993","0.00001"
"9.99000","0.99301","-0.04638","0.00001"
"10.00800","0.99484","-0.07286","0.00001"
"10.02600","0.99663","-0.07668","0.00001"
"10.04400","0.99839","0.04891","0.00002"
"10.06200","1.00018","0.09319","0.00002"
"10.08000","1.00196","0.01948","0.00002"
"10.09800","1.00375","0.00592","0.00001"
"10.11600","1.00558","-0.00425","0.00001"
"10.13400","1.00736","0.03113","0.00001"
"10.15200","1.00906","0.00518","0.00001"
"10.17000","1.01079","-0.11969","0.00001"
"10.18800","1.01261","-0.13238","0.00001"
"10.20600","1.01446","-0.12235","0.00001"
"10.22400","1.01632","-0.08517","0.00001"
"10.24200","1.01812","-0.10782","0.00001"
"10.26000","1.01984","-0.05314","0.00001"
"10.27800","1.02156","-0.06582","0.00001"
"10.29600","1.02335","-0.03955","0.00001"
"10.31400","1.02517","-0.06611","0.00001"
"10.33200","1.02703","-0.10333","0.00001"
"10.35000","1.02891","-0.11486","0.00001"
"10.36800","1.03073","-0.04443","0.00001"
"10.38600","1.03246","-0.00413","0.00001"
"10.40400","1.03422","0.02576","0.00001"
"10.42200","1.03603","-0.01110","0.00001"
"10.44000","1.03788","-0.04592","0.00001"
"10.45800","1.03974","-0.05026","0.00001"
"10.47600","1.04155","0.03551","0.00001"
"10.49400","1.04332","0.04857","0.00001"
"10.51200","1.04509","-0.03576","0.00001"
"10.53000","1.04690","-0.05866","0.00001"
"10.54800","1.04873","0.02004","0.00001"
"10.56600","1.05061","0.02898","0.00001"
"10.58400","1.05246","0.01084","0.00001"
"10.60200","1.05420","0.00377","0.00001"
"10.62000","1.05591","0.00631","0.00001"
"10.63800","1.05772","0.00932","0.00001"
"10.65600","1.05958","-0.03413","0.00001"
"10.67400","1.06144","-0.15508","0.00001"
"10.69200","1.06327","-0.12202","0.00001"
"10.71000","1.06503","-0.10838","0.00001"
"10.72800","1.06674","-0.10578","0.00001"
"10.74600","1.06847","-0.08094","0.00001"
"10.76400","1.07025","-0.02642","0.00001"
"10.78200","1.07206","-0.02647","0.00001"
"10.80000","1.07392","-0.05894","0.00001"
"10.81800","1.07573","-0.00961","0.00001"
"10.83600","1.07745","0.02701","0.00001"
"10.85400","1.07915","-0.06325","0.00001"
"10.87200","1.08092","-0.10495","0.00001"
"10.89000","1.08274","-0.08355","0.00001"
"10.90800","1.08460","0.01326","0.00001"
"10.92600","1.08648","0.01499","0.00001"
"10.94400","1.08830","-0.06612","0.00001"
"10.96200","1.09007","-0.06045","0.00001"
"10.98000","1.09185","0.02199","0.00001"
"10.99800","1.09366","0.05298","0.00001"
"11.01600","1.09550","0.00641","0.00001"
"11.03400","1.09737","-0.10297","0.00001"
"11.05200","1.09916","-0.13830","0.00000"
"11.07000","1.10087","-0.11120","0.00000"
"11.08800","1.10262","-0.09514","0.00000"
"11.10600","1.10445","-0.03122","0.00000"
"11.12400","1.10630","-0.01459","0.00001"
"11.14200","1.10816","0.01954","0.00001"
"11.16000","1.11002","-0.03977","0.00001"
"11.17800","1.11181","-0.07774","0.00001"
"11.19600","1.11355","-0.00566","0.00001"
"11.21400","1.11532","0.04400","0.00001"
"11.23200","1.11713","0.05335","0.00000"
"11.25000","1.11898","0.04454","0.00000"
"11.26800","1.12084","0.03918","0.00000"
"11.28600","1.12261","0.12732","0.00000"
"11.30400","1.12432","0.08904","0.00000"
"11.32200","1.12606","0.00304","0.00000"
"11.34000","1.12785","-0.01297","0.00000"
"11.35800","1.12966","-0.02162","0.00000"
"11.37600","1.13151","-0.02526","0.00001"
"11.39400","1.13334","0.00511","0.00001"
"11.41200","1.13510","0.05149","0.00000"
"11.43000","1.13684","0.04456","0.00000"
"11.44800","1.13863","0.00516","0.00000"
"11.46600","1.14043","-0.03175","0.00000"
"11.48400","1.14225","-0.02619","0.00000"
"11.50200","1.14408","-0.00046","0.00000"
"11.52000","1.14585","0.04375","0.00000"
"11.53800","1.14761","0.02937","0.00000"
"11.55600","1.14942","-0.02922","0.00000"
"11.57400","1.15124","-0.05754","0.00000"
"11.59200","1.15304","-0.00831","0.00000"
"11.61000","1.15488","-0.02547","0.00000"
"11.62800","1.15671","-0.00137","0.00000"
"11.64600","1.15848","0.01647","0.00000"
"11.66400","1.16025","0.00432","0.00000"
"11.68200","1.16205","-0.03768","0.00000"
"11.70000","1.16388","-0.05204","0.00000"
"11.71800","1.16575","-0.12074","0.00000"
"11.73600","1.16759","-0.10521","0.00000"
"11.75400","1.16935","-0.03878","0.00000"
"11.77200","1.17113","0.01258","0.00000"
"11.79000","1.17297","-0.03650","0.00000"
"11.80800","1.17479","-0.03607","0.00000"
"11.82600","1.17663","-0.00463","0.00000"
"11.84400","1.17848","-0.07599","0.00000"
"11.86200","1.18026","-0.03086","0.00000"
"11.88000","1.18198","0.09182","0.00000"
"11.89800","1.18373","0.09399","0.00000"
"11.91600","1.18553","0.01850","0.00000"
"11.93400","1.18733","-0.05739","-0.00001"
"11.95200","1.18914","-0.17577","-0.00001"
"11.97000","1.19092","-0.12508","-0.00001"
"11.98800","1.19266","-0.00776","0.00000"
"12.00600","1.19443","0.05132","0.00000"
"12.02400","1.19625","-0.01297","0.00000"
"12.04200","1.19806","-0.01498","0.00000"
"12.06000","1.19988","-0.02962","0.00000"
"12.07800","1.20169","-0.12305","0.00000"
"12.09600","1.20343","-0.06527","0.00000"
"12.11400","1.20515","0.00969","-0.00001"
"12.13200","1.20693","-0.03017","-0.00001"
"12.15000","1.20879","-0.02770","-0.00001"
"12.16800","1.21066","-0.06967","-0.00001"
"12.18600","1.21253","-0.03580","-0.00001"
"12.20400","1.21431","-0.03540","-0.00001"
"12.22200","1.21605","-0.01155","0.00000"
"12.24000","1.21785","0.03663","0.00000"
"12.25800","1.21970","-0.07502","0.00000"
"12.27600","1.22152","-0.14179","0.00000"
"12.29400","1.22337","-0.12643","0.00000"
"12.31200","1.22520","-0.15250","0.00000"
"12.33000","1.22697","-0.12548","-0.00001"
"12.34800","1.22873","-0.13196","-0.00001"
"12.36600","1.23055","-0.13702","-0.00001"
"12.38400","1.23239","-0.12728","-0.00001"
"12.40200","1.23423","-0.07803","-0.00001"
"12.42000","1.23605","-0.01037","-0.00001"
"12.43800","1.23783","0.00880","-0.00001"
"12.45600","1.23958","0.02715","-0.00001"
"12.47400","1.24136","0.01421","-0.00001"
"12.49200","1.24313","0.00296","-0.00001"
"12.51000","1.24492","-0.00744","0.00000"
"12.52800","1.24675","-0.01725","-0.00001"
"12.54600","1.24854","0.02767","-0.00001"
"12.56400","1.25025","0.03388","-0.00001"
"12.58200","1.25198","0.06956","-0.00001"
"12.60000","1.25380","0.07313","-0.00001"
"12.61800","1.25565","0.00758","-0.00001"
"12.63600","1.25750","-0.06589","-0.00001"
"12.65400","1.25930","-0.06093","-0.00001"
"12.67200","1.26102","-0.08811","-0.00001"
"12.69000","1.26276","-0.01620","0.00000"
"12.70800","1.26456","-0.00712","0.00000"
"12.72600","1.26639","0.02483","0.00000"
"12.74400","1.26825","0.02520","0.00000"
"12.76200","1.27013","-0.01023","0.00000"
"12.78000","1.27193","-0.03799","-0.00001"
"12.79800","1.27365","-0.01408","-0.00001"
"12.81600","1.27542","0.02074","-0.00001"
"12.83400","1.27724","0.05381","-0.00001"
"12.85200","1.27909","0.00093","-0.00001"
"12.87000","1.28094","-0.01057","-0.00001"
"12.88800","1.28274","-0.00699","-0.00001"
"12.90600","1.28450","0.02208","0.00000"
"12.92400","1.28628","0.02092","0.00000"
"12.94200","1.28810","0.03623","0.00000"
"12.96000","1.28996","0.03978","0.00000"
"12.97800","1.29186","-0.01185","0.00000"
"12.99600","1.29371","-0.01263","-0.00001"
"13.01400","1.29543","-0.05078","-0.00001"
"13.03200","1.29713","-0.12233","-0.00001"
"13.05000","1.29893","-0.03450","-0.00001"
"13.06800","1.30077","0.00479","-0.00001"
"13.08600","1.30261","0.02879","-0.00001"
"13.10400","1.30444","-0.03741","-0.00001"
"13.12200","1.30622","-0.01638","-0.00001"
"13.14000","1.30794","-0.01202","-0.00001"
"13.15800","1.30969","0.07329","-0.00001"
"13.17600","1.31147","0.03336","-0.00001"
"13.19400","1.31328","-0.04072","-0.00001"
"13.21200","1.31513","-0.00179","-0.00001"
"13.23000","1.31694","-0.02384","-0.00001"
"13.24800","1.31866","-0.08950","-0.00001"
"13.26600","1.32036","-0.12743","-0.00001"
"13.28400","1.32214","-0.12599","-0.00001"
"13.30200","1.32397","-0.06050","-0.00001"
"13.32000","1.32583","-0.02114","-0.00001"
"13.33800","1.32768","-0.02906","-0.00001"
"13.35600","1.32947","0.00223","-0.00001"
"13.37400","1.33122","0.05617","-0.00001"
"13.39200","1.33300","0.06972","-0.00001"
"13.41000","1.33482","-0.00586","-0.00001"
"13.42800","1.33667","-0.05655","-0.00001"
"13.44600","1.33855","-0.05841","-0.00001"
"13.46400","1.34036","-0.03989","-0.00001"
"13.48200","1.34208","0.01645","-0.00001"
"13.50000","1.34385","-0.07047","-0.00001"
"13.51800","1.34568","0.03505","-0.00001"
"13.53600","1.34753","0.04893","-0.00001"
"13.55400","1.34939","-0.03312","-0.00001"
"13.57200","1.35124","-0.14304","-0.00001"
"13.59000","1.35302","-0.15667","-0.00001"
"13.60800","1.35477","-0.03095","-0.00001"
"13.62600","1.35655","-0.01102","-0.00001"
"13.64400","1.35837","-0.02168","-0.00001"
"13.66200","1.36022","0.02059","-0.00001"
"13.68000","1.36207","-0.06349","-0.00001"
"13.69800","1.36383","-0.07578","-0.00001"
"13.71600","1.36554","-0.06035","-0.00001"
"13.73400","1.36729","-0.11353","-0.00001"
"13.75200","1.36907","-0.05132","-0.00001"
"13.77000","1.37086","0.02715","-0.00001"
"13.78800","1.37269","0.04737","-0.00001"
"13.80600","1.37451","0.07742","-0.00001"
"13.82400","1.37625","0.05601","-0.00001"
"13.84200","1.37800","0.05710","-0.00001"
"13.86000","1.37978","-0.03110","-0.00001"
"13.87800","1.38158","-0.01719","-0.00001"
"13.89600","1.38342","-0.00186","-0.00001"
"13.91400","1.38525","-0.06407","-0.00001"
"13.93200","1.38703","-0.09513","-0.00001"
"13.95000","1.38878","-0.03788","-0.00001"
"13.96800","1.39059","-0.01052","-0.00001"
"13.98600","1.39242","0.02538","-0.00001"
"14.00400","1.39424","0.05101","-0.00001"
"14.02200","1.39610","0.01299","-0.00001"
"14.04000","1.39792","-0.00538","-0.00001"
"14.05800","1.39969","-0.05706","-0.00001"
"14.07600","1.40147","0.00953","-0.00001"
"14.09400","1.40327","0.08803","-0.00001"
"14.11200","1.40510","0.04481","-0.00001"
"14.13000","1.40696","0.01679","-0.00001"
"14.14800","1.40879","0.03467","-0.00001"
"14.16600","1.41056","0.05918","-0.00001"
"14.18400","1.41234","-0.04892","-0.00001"
"14.20200","1.41417","-0.05442","-0.00001"
"14.22000","1.41597","-0.10964","-0.00001"
"14.23800","1.41779","-0.12832","-0.00001"
"14.25600","1.41966","-0.10582","-0.00001"
"14.27400","1.42145","-0.05048","-0.00001"
"14.29200","1.42318","0.04020","-0.00001"
"14.31000","1.42494","0.05478","-0.00001"
"14.32800","1.42673","-0.02757","-0.00001"
"14.34600","1.42852","-0.06948","-0.00001"
"14.36400","1.43032","-0.11310","-0.00001"
"14.38200","1.43209","-0.04192","-0.00001"
"14.40000","1.43383","0.06816","-0.00001"
"14.41800","1.43561","0.02826","-0.00001"
"14.43600","1.43743","0.06224","-0.00001"
"14.45400","1.43924","0.01346","-0.00001"
"14.47200","1.44107","-0.00736","-0.00001"
"14.49000","1.44290","-0.07247","-0.00001"
"14.50800","1.44465","-0.08646","-0.00001"
"14.52600","1.44637","-0.03929","-0.00001"
"14.54400","1.44817","-0.04830","-0.00001"
"14.56200","1.45002","-0.12324","-0.00001"
"14.58000","1.45188","-0.13129","-0.00001"
"14.59800","1.45371","-0.07781","-0.00001"
"14.61600","1.45548","-0.15405","-0.00001"
"14.63400","1.45723","-0.13553","-0.00001"
"14.65200","1.45903","-0.04255","-0.00001"
"14.67000","1.46085","0.01351","-0.00001"
"14.68800","1.46266","-0.04361","-0.00001"
"14.70600","1.46452","-0.08533","-0.00001"
"14.72400","1.46636","-0.14276","-0.00001"
"14.74200","1.46813","-0.10192","-0.00001"
"14.76000","1.46990","-0.03419","-0.00001"
"14.77800","1.47174","0.07991","-0.00001"
"14.79600","1.47360","0.05367","-0.00001"
"14.81400","1.47546","-0.06263","-0.00001"
"14.83200","1.47728","-0.09615","-0.00001"
"14.85000","1.47904","-0.10467","-0.00001"
"14.86800","1.48079","-0.08305","-0.00001"
"14.88600","1.48257","-0.05920","-0.00001"
"14.90400","1.48435","0.02407","-0.00001"
"14.92200","1.48615","0.05155","-0.00001"
"14.94000","1.48798","-0.01290","-0.00001"
"14.95800","1.48975","-0.08866","-0.00001"
"14.97600","1.49146","-0.00820","-0.00001"
"14.99400","1.49321","-0.00644","-0.00001"
"15.01200","1.49503","-0.05956","-0.00001"
"15.03000","1.49686","-0.00693","-0.00001"
"15.04800","1.49871","0.00088","-0.00001"
"15.06600","1.50051","-0.08353","-0.00001"
"15.08400","1.50223","-0.08820","-0.00001"
"15.10200","1.50397","-0.02291","-0.00001"
"15.12000","1.50576","0.03841","-0.00001"
"15.13800","1.50759","0.03994","-0.00001"
"15.15600","1.50946","0.03692","-0.00001"
"15.17400","1.51134","0.04716","-0.00001"
"15.19200","1.51314","-0.03226","-0.00001"
"15.21000","1.51486","-0.14018","-0.00001"
"15.22800","1.51663","-0.15531","-0.00001"
"15.24600","1.51846","-0.13283","-0.00001"
"15.26400","1.52031","-0.16312","-0.00001"
"15.28200","1.52215","-0.07730","-0.00001"
"15.30000","1.52394","0.03424","-0.00001"
"15.31800","1.52569","-0.05569","-0.00001"
"15.33600","1.52748","-0.10802","-0.00001"
"15.35400","1.52930","-0.15941","0.00000"
"15.37200","1.53115","-0.10248","0.00000"
"15.39000","1.53304","0.00608","0.00000"
"15.40800","1.53489","0.01206","0.00000"
"15.42600","1.53662","-0.00966","-0.00001"
"15.44400","1.53834","0.02349","-0.00001"
"15.46200","1.54014","-0.10175","-0.00001"
"15.48000","1.54199","-0.11781","-0.00001"
"15.49800","1.54383","-0.04206","-0.00001"
"15.51600","1.54566","-0.07073","0.00000"
"15.53400","1.54741","-0.13006","0.00000"
"15.55200","1.54911","-0.09885","0.00000"
"15.57000","1.55084","-0.03407","0.00000"
"15.58800","1.55263","0.00617","0.00000"
"15.60600","1.55446","0.00348","0.00000"
"15.62400","1.55633","0.02627","0.00000"
"15.64200","1.55814","0.01152","0.00000"
"15.66000","1.55985","0.02452","0.00000"
"15.67800","1.56156","0.05806","0.00000"
"15.69600","1.56336","0.01819","0.00000"
"15.71400","1.56519","-0.07519","0.00000"
"15.73200","1.56703","-0.03588","0.00000"
"15.75000","1.56887","0.01512","0.00000"
"15.76800","1.57066","0.02328","0.00000"
"15.78600","1.57243","0.01499","0.00000"
"15.80400","1.57423","0.01119","0.00000"
"15.82200","1.57605","-0.05697","0.00000"
"15.84000","1.57791","-0.03661","0.00000"
"15.85800","1.57980","0.08077","0.00000"
"15.87600","1.58159","0.10276","0.00000"
"15.89400","1.58330","0.12966","0.00000"
"15.91200","1.58504","0.04678","0.00000"
"15.93000","1.58687","-0.06466","0.00000"
"15.94800","1.58872","-0.05742","0.00000"
"15.96600","1.59060","-0.05424","0.00000"
"15.98400","1.59245","-0.05881","0.00000"
"16.00200","1.59423","-0.10507","0.00000"
"16.02000","1.59596","-0.03504","0.00001"
"16.03800","1.59774","-0.02957","0.00001"
"16.05600","1.59957","0.05806","0.00000"
"16.07400","1.60143","0.03077","0.00000"
"16.09200","1.60327","-0.06812","0.00000"
"16.11000","1.60501","-0.12240","0.00000"
"16.12800","1.60671","-0.10026","0.00000"
"16.14600","1.60846","-0.06115","0.00000"
"16.16400","1.61023","-0.06567","0.00000"
"16.18200","1.61200","-0.03680","0.00000"
"16.20000","1.61382","-0.00476","0.00000"
"16.21800","1.61565","0.03692","0.00001"
"16.23600","1.61742","-0.02652","0.00001"
"16.25400","1.61920","-0.04303","0.00001"
"16.27200","1.62102","-0.06562","0.00001"
"16.29000","1.62284","-0.06083","0.00000"
"16.30800","1.62469","0.13253","0.00000"
"16.32600","1.62653","0.09566","0.00000"
"16.34400","1.62829","0.06235","0.00000"
"16.36200","1.63003","0.01233","0.00000"
"16.38000","1.63183","-0.06204","0.00000"
"16.39800","1.63364","-0.10063","0.00000"
"16.41600","1.63545","-0.03873","0.00001"
"16.43400","1.63730","-0.05185","0.00001"
"16.45200","1.63912","-0.06940","0.00001"
"16.47000","1.64088","-0.10086","0.00001"
"16.48800","1.64266","-0.04859","0.00000"
"16.50600","1.64446","0.03440","-0.00006"
"16.52400","1.64630","0.04926","-0.00023"
"16.54200","1.64817","0.06562","-0.00048"
"16.56000","1.65000","-0.05108","-0.00072"
"16.57800","1.65177","-0.10721","-0.00092"
"16.59600","1.65357","-0.03715","-0.00102"
"16.61400","1.65538","0.01482","-0.00105"
"16.63200","1.65715","0.03057","-0.00104"
"16.65000","1.65896","-0.02694","-0.00103"
"16.66800","1.66082","0.05660","-0.00103"
"16.68600","1.66262","0.08759","-0.00103"
"16.70400","1.66437","0.06186","-0.00103"
"16.72200","1.66615","-0.04274","-0.00103"
"16.74000","1.66796","-0.10714","-0.00103"
"16.75800","1.66977","-0.06498","-0.00103"
"16.77600","1.67158","-0.02518","-0.00103"
"16.79400","1.67333","0.05298","-0.00104"
"16.81200","1.67506","0.20305","-0.00103"
"16.83000","1.67683","0.06730","-0.00103"
"16.84800","1.67865","0.03769","-0.00102"
"16.86600","1.68046","0.10941","-0.00101"
"16.88400","1.68228","0.04807","-0.00100"
"16.90200","1.68406","0.06511","-0.00101"
"16.92000","1.68578","-0.09272","-0.00102"
"16.93800","1.68750","-0.06943","-0.00102"
"16.95600","1.68931","0.12523","-0.00102"
"16.97400","1.69118","-0.00597","-0.00101"
"16.99200","1.69306","-0.02315","-0.00102"
"17.01000","1.69491","-0.02536","-0.00103"
"17.02800","1.69668","-0.09728","-0.00104"
"17.04600","1.69843","-0.05254","-0.00104"
"17.06400","1.70023","-0.12916","-0.00104"
"17.08200","1.70205","-0.13446","-0.00103"
"17.10000","1.70388","-0.04154","-0.00102"
"17.11800","1.70575","-0.11548","-0.00101"
"17.13600","1.70760","-0.09533","-0.00102"
"17.15400","1.70936","-0.05670","-0.00103"
"17.17200","1.71111","-0.17171","-0.00103"
"17.19000","1.71293","-0.07205","-0.00102"
"17.20800","1.71479","-0.02311","-0.00102"
"17.22600","1.71665","-0.01074","-0.00103"
"17.24400","1.71847","-0.05268","-0.00104"
"17.26200","1.72023","-0.18368","-0.00104"
"17.28000","1.72197","-0.14642","-0.00104"
"17.29800","1.72375","-0.11538","-0.00103"
"17.31600","1.72553","-0.10646","-0.00103"
"17.33400","1.72733","-0.04384","-0.00103"
"17.35200","1.72917","-0.03095","-0.00103"
"17.37000","1.73093","-0.09729","-0.00103"
"17.38800","1.73264","-0.02927","-0.00103"
"17.40600","1.73441","-0.02102","-0.00104"
"17.42400","1.73623","-0.02176","-0.00104"
"17.44200","1.73808","-0.03009","-0.00104"
"17.46000","1.73992","-0.04870","-0.00104"
"17.47800","1.74171","0.00772","-0.00104"
"17.49600","1.74343","0.10032","-0.00104"
"17.51400","1.74515","0.02693","-0.00104"
"17.53200","1.74694","0.02818","-0.00104"
"17.55000","1.74877","-0.00789","-0.00104"
"17.56800","1.75064","0.03698","-0.00104"
"17.58600","1.75253","-0.01780","-0.00104"
"17.60400","1.75432","-0.06923","-0.00104"
"17.62200","1.75605","-0.06142","-0.00104"
"17.64000","1.75783","0.00099","-0.00104"
"17.65800","1.75967","-0.00152","-0.00104"
"17.67600","1.76152","0.00170","-0.00104"
"17.69400","1.76337","-0.00652","-0.00104"
"17.71200","1.76515","0.00746","-0.00104"
"17.73000","1.76689","0.01530","-0.00104"
"17.74800","1.76867","0.03849","-0.00104"
"17.76600","1.77050","-0.00065","-0.00103"
"17.78400","1.77235","-0.06491","-0.00103"
"17.80200","1.77425","-0.14957","-0.00103"
"17.82000","1.77608","-0.10373","-0.00103"
"17.83800","1.77780","-0.08125","-0.00104"
"17.85600","1.77951","-0.07263","-0.00104"
"17.87400","1.78132","-0.06541","-0.00104"
"17.89200","1.78317","-0.09779","-0.00104"
"17.91000","1.78502","-0.13378","-0.00104"
"17.92800","1.78683","-0.08680","-0.00104"
"17.94600","1.78858","-0.02781","-0.00104"
"17.96400","1.79028","0.00755","-0.00104"
"17.98200","1.79202","0.00493","-0.00104"
"18.00000","1.79382","0.01177","-0.00104"
"18.01800","1.79565","0.03869","-0.00104"
"18.03600","1.79752","0.07536","-0.00104"
"18.05400","1.79934","0.04511","-0.00104"
"18.07200","1.80107","-0.03953","-0.00104"
"18.09000","1.80280","-0.07066","-0.00104"
"18.10800","1.80459","-0.06916","-0.00104"
"18.12600","1.80640","0.04675","-0.00104"
"18.14400","1.80825","0.00302","-0.00104"
"18.16200","1.81010","0.09332","-0.00104"
"18.18000","1.81190","0.14982","-0.00104"
"18.19800","1.81365","0.07719","-0.00104"
"18.21600","1.81544","-0.04650","-0.00104"
"18.23400","1.81726","-0.07289","-0.00104"
"18.25200","1.81912","-0.04709","-0.00104"
"18.27000","1.82099","0.01012","-0.00104"
"18.28800","1.82277","0.04289","-0.00104"
"18.30600","1.82447","0.02372","-0.00104"
"18.32400","1.82624","0.00462","-0.00104"
"18.34200","1.82809","-0.04307","-0.00104"
"18.36000","1.82996","0.00007","-0.00104"
"18.37800","1.83184","0.02093","-0.00104"
"18.39600","1.83368","0.07416","-0.00104"
"18.41400","1.83543","0.08060","-0.00104"
"18.43200","1.83716","-0.03053","-0.00104"
"18.45000","1.83892","-0.04450","-0.00104"
"18.46800","1.84074","-0.02357","-0.00104"
"18.48600","1.84261","0.04546","-0.00104"
"18.50400","1.84446","0.07751","-0.00104"
"18.52200","1.84621","0.02276","-0.00104"
"18.54000","1.84792","0.00459","-0.00104"
"18.55800","1.84967","0.00616","-0.00104"
"18.57600","1.85145","0.03155","-0.00104"
"18.59400","1.85325","0.04018","-0.00104"
"18.61200","1.85510","0.02833","-0.00104"
"18.63000","1.85690","-0.01242","-0.00104"
"18.64800","1.85865","-0.04904","-0.00104"
"18.66600","1.86041","-0.07942","-0.00103"
"18.68400","1.86222","-0.07961","-0.00103"
"18.70200","1.86403","-0.00077","-0.00103"
"18.72000","1.86587","0.04059","-0.00104"
"18.73800","1.86769","-0.01317","-0.00104"
"18.75600","1.86945","-0.09096","-0.00104"
"18.77400","1.87121","-0.09994","-0.00104"
"18.79200","1.87302","-0.08329","-0.00104"
"18.81000","1.87482","-0.06027","-0.00104"
"18.82800","1.87663","-0.00997","-0.00103"
"18.84600","1.87849","0.06649","-0.00103"
"18.86400","1.88031","-0.00394","-0.00103"
"18.88200","1.88206","-0.06633","-0.00103"
"18.90000","1.88383","0.03299","-0.00103"
"18.91800","1.88564","0.01501","-0.00103"
"18.93600","1.88750","-0.00813","-0.00103"
"18.95400","1.88939","0.01980","-0.00103"
"18.97200","1.89122","-0.02498","-0.00103"
"18.99000","1.89298","0.00105","-0.00103"
"19.00800","1.89477","0.04175","-0.00103"
"19.02600","1.89659","-0.02184","-0.00103"
"19.04400","1.89838","-0.02122","-0.00100"
"19.06200","1.90020","-0.05414","-0.00098"
"19.08000","1.90204","-0.10097","-0.00097"
"19.09800","1.90381","-0.09981","-0.00097"
"19.11600","1.90554","-0.11784","-0.00099"
"19.13400","1.90732","-0.07470","-0.00101"
"19.15200","1.90912","-0.04149","-0.00097"
"19.17000","1.91093","-0.03374","-0.00093"
"19.18800","1.91276","0.00329","-0.00090"
"19.20600","1.91454","-0.06400","-0.00088"
"19.22400","1.91629","-0.07655","-0.00087"
"19.24200","1.91806","-0.04192","-0.00085"
"19.26000","1.91986","-0.04989","-0.00084"
"19.27800","1.92166","-0.01053","-0.00084"
"19.29600","1.92347","-0.01208","-0.00083"
"19.31400","1.92527","0.02957","-0.00083"
"19.33200","1.92699","-0.00990","-0.00082"
"19.35000","1.92871","-0.03318","-0.00082"
"19.36800","1.93052","-0.04433","-0.00082"
"19.38600","1.93239","-0.01579","-0.00083"
"19.40400","1.93428","-0.12955","-0.00083"
"19.42200","1.93613","-0.17744","-0.00083"
"19.44000","1.93789","-0.05696","-0.00082"
"19.45800","1.93964","-0.01230","-0.00081"
"19.47600","1.94144","0.04033","-0.00080"
"19.49400","1.94327","0.04765","-0.00080"
"19.51200","1.94509","0.07715","-0.00080"
"19.53000","1.94695","-0.00047","-0.00078"
"19.54800","1.94879","-0.05936","-0.00077"
"19.56600","1.95055","-0.05530","-0.00077"
"19.58400","1.95231","0.06875","-0.00076"
"19.60200","1.95414","0.07277","-0.00076"
"19.62000","1.95599","0.00789","-0.00076"
"19.63800","1.95784","0.03378","-0.00075"
"19.65600","1.95965","0.01940","-0.00074"
"19.67400","1.96141","0.00695","-0.00073"
"19.69200","1.96316","0.05191","-0.00072"
"19.71000","1.96494","0.00589","-0.00071"
"19.72800","1.96672","-0.01010","-0.00070"
"19.74600","1.96854","0.02296","-0.00069"
"19.76400","1.97037","0.00428","-0.00068"
"19.78200","1.97213","0.03099","-0.00067"
"19.80000","1.97383","-0.02453","-0.00067"
"19.81800","1.97559","-0.01203","-0.00067"
"19.83600","1.97742","0.01366","-0.00067"
"19.85400","1.97928","0.00108","-0.00067"
"19.87200","1.98114","-0.00602","-0.00067"
"19.89000","1.98293","-0.03176","-0.00067"
"19.90800","1.98464","-0.09702","-0.00067"
"19.92600","1.98637","0.02005","-0.00066"
"19.94400","1.98817","0.09739","-0.00066"
"19.96200","1.98999","0.04896","-0.00066"
"19.98000","1.99186","-0.01100","-0.00066"
"19.99800","1.99373","0.03806","-0.00066"
"20.01600","1.99550","0.05073","-0.00065"
"20.03400","1.99722","0.09365","-0.00065"
"20.05200","1.99899","0.08273","-0.00066"
"20.07000","2.00083","0.08283","-0.00066"
"20.08800","2.00268","-0.01926","-0.00066"
"20.10600","2.00454","-0.03446","-0.00065"
"20.12400","2.00633","-0.08042","-0.00065"
"20.14200","2.00809","-0.05256","-0.00065"
"20.16000","2.00988","-0.01896","-0.00064"
"20.17800","2.01170","-0.02741","-0.00064"
"20.19600","2.01356","-0.10667","-0.00064"
"20.21400","2.01545","-0.16148","-0.00064"
"20.23200","2.01728","-0.15061","-0.00064"
"20.25000","2.01899","-0.08427","-0.00064"
"20.26800","2.02073","-0.01049","-0.00064"
"20.28600","2.02256","0.04575","-0.00064"
"20.30400","2.02443","0.06851","-0.00064"
"20.32200","2.02627","0.02919","-0.00065"
"20.34000","2.02808","-0.05248","-0.00065"
"20.35800","2.02982","-0.08513","-0.00064"
"20.37600","2.03151","-0.04476","-0.00064"
"20.39400","2.03325","-0.02940","-0.00064"
"20.41200","2.03503","0.03044","-0.00064"
"20.43000","2.03686","0.08403","-0.00064"
"20.44800","2.03872","0.04534","-0.00064"
"20.46600","2.04052","-0.04477","-0.00064"
"20.48400","2.04224","-0.04755","-0.00064"
"20.50200","2.04397","-0.00281","-0.00064"
"20.52000","2.04576","0.04319","-0.00064"
"20.53800","2.04759","0.00191","-0.00064"
"20.55600","2.04945","-0.09707","-0.00064"
"20.57400","2.05129","-0.06274","-0.00064"
"20.59200","2.05307","-0.00582","-0.00064"
"20.61000","2.05481","0.06195","-0.00063"
"20.62800","2.05659","0.08680","-0.00063"
"20.64600","2.05842","0.13142","-0.00063"
"20.66400","2.06028","0.06225","-0.00063"
"20.68200","2.06216","0.07160","-0.00063"
"20.70000","2.06395","0.04841","-0.00063"
"20.71800","2.06566","-0.06738","-0.00063"
"20.73600","2.06744","-0.04008","-0.00063"
"20.75400","2.06929","0.00389","-0.00063"
"20.77200","2.07115","-0.03082","-0.00064"
"20.79000","2.07303","0.03776","-0.00064"
"20.80800","2.07487","0.00832","-0.00063"
"20.82600","2.07663","-0.02787","-0.00063"
"20.84400","2.07837","-0.03502","-0.00063"
"20.86200","2.08015","-0.04023","-0.00063"
"20.88000","2.08196","0.07963","-0.00063"
"20.89800","2.08382","0.04153","-0.00063"
"20.91600","2.08566","0.00886","-0.00063"
"20.93400","2.08741","-0.00303","-0.00063"
"20.95200","2.08912","0.01932","-0.00063"
"20.97000","2.09088","-0.00109","-0.00063"
"20.98800","2.09266","-0.01751","-0.00063"
"21.00600","2.09446","-0.04954","-0.00063"
"21.02400","2.09630","-0.03608","-0.00063"
"21.04200","2.09810","-0.01846","-0.00063"
"21.06000","2.09984","-0.05059","-0.00063"
"21.07800","2.10160","-0.08954","-0.00063"
"21.09600","2.10340","-0.05342","-0.00063"
"21.10000","2.10380","-0.02806","-0.00063"