File: archive/undergrad/433/Pressure Vessel/Specimen_RawData_9.csv
Time,Extension,Load,Strain Gage18
(s),(mm),(N),(mm/mm)
"0.00000","0.00000","-0.02560","0.00000"
"0.01700","0.00000","-0.08740","0.00000"
"0.03400","0.00008","-0.07225","-0.00001"
"0.05100","0.00038","-0.02287","-0.00001"
"0.06800","0.00108","-0.02408","0.00000"
"0.08500","0.00224","-0.03495","0.00000"
"0.10200","0.00324","-0.06355","0.00000"
"0.11900","0.00395","0.04855","0.00000"
"0.13600","0.00485","0.05836","0.00000"
"0.15300","0.00635","0.05469","0.00000"
"0.17000","0.00844","0.01428","0.00000"
"0.18700","0.01086","-0.04639","0.00000"
"0.20400","0.01332","0.02449","0.00000"
"0.22100","0.01560","0.14467","0.00000"
"0.23800","0.01758","0.15142","-0.00001"
"0.25500","0.01932","0.09726","-0.00001"
"0.27200","0.02098","0.02541","0.00000"
"0.28900","0.02264","-0.01293","0.00000"
"0.30600","0.02431","0.02991","0.00000"
"0.32300","0.02604","0.04927","0.00000"
"0.34000","0.02779","-0.00111","0.00000"
"0.35700","0.02948","-0.02618","0.00000"
"0.37400","0.03114","0.00912","0.00000"
"0.39100","0.03282","0.08053","0.00000"
"0.40800","0.03452","0.07413","0.00000"
"0.42500","0.03623","-0.03557","0.00000"
"0.44200","0.03797","-0.04384","0.00000"
"0.45900","0.03968","-0.04856","0.00000"
"0.47600","0.04136","-0.05433","0.00000"
"0.49300","0.04305","-0.03663","-0.00001"
"0.51000","0.04477","-0.04800","-0.00001"
"0.52700","0.04648","0.01219","-0.00001"
"0.54400","0.04819","0.01089","-0.00001"
"0.56100","0.04994","0.00842","0.00000"
"0.57800","0.05165","0.02215","0.00000"
"0.59500","0.05331","0.03495","0.00000"
"0.61200","0.05498","0.05909","0.00000"
"0.62900","0.05667","0.01119","0.00000"
"0.64600","0.05841","-0.01998","0.00000"
"0.66300","0.06019","-0.09352","0.00000"
"0.68000","0.06195","-0.08963","0.00000"
"0.69700","0.06363","-0.06106","-0.00001"
"0.71400","0.06529","-0.06833","-0.00001"
"0.73100","0.06699","0.00434","-0.00001"
"0.74800","0.06870","0.05287","-0.00001"
"0.76500","0.07039","0.00362","-0.00001"
"0.78200","0.07213","0.01310","0.00000"
"0.79900","0.07387","-0.01898","0.00000"
"0.81600","0.07554","-0.09211","0.00000"
"0.83300","0.07717","-0.15011","0.00000"
"0.85000","0.07884","-0.15103","0.00000"
"0.86700","0.08054","-0.12294","0.00000"
"0.88400","0.08223","-0.01588","0.00000"
"0.90100","0.08394","0.01747","0.00000"
"0.91800","0.08564","0.07298","-0.00001"
"0.93500","0.08730","0.04242","-0.00001"
"0.95200","0.08899","-0.01146","-0.00001"
"0.96900","0.09070","-0.08455","0.00000"
"0.98600","0.09241","-0.14327","0.00000"
"1.00300","0.09412","-0.08484","0.00000"
"1.02000","0.09584","-0.05799","0.00000"
"1.03700","0.09751","-0.05952","0.00000"
"1.05400","0.09912","-0.04444","0.00000"
"1.07100","0.10076","-0.01163","0.00000"
"1.08800","0.10248","-0.03240","0.00000"
"1.10500","0.10425","-0.01813","0.00000"
"1.12200","0.10602","-0.00628","-0.00001"
"1.13900","0.10776","-0.02621","-0.00001"
"1.15600","0.10943","-0.01612","-0.00001"
"1.17300","0.11107","-0.03099","-0.00001"
"1.19000","0.11277","-0.03876","-0.00001"
"1.20700","0.11450","-0.01562","-0.00001"
"1.22400","0.11622","0.01025","0.00000"
"1.24100","0.11796","-0.00129","0.00000"
"1.25800","0.11971","-0.02051","0.00000"
"1.27500","0.12139","-0.00202","0.00000"
"1.29200","0.12304","0.03923","0.00000"
"1.30900","0.12473","0.00390","0.00000"
"1.32600","0.12647","-0.00426","0.00000"
"1.34300","0.12821","-0.01264","0.00000"
"1.36000","0.12997","-0.07368","0.00000"
"1.37700","0.13168","-0.02851","-0.00001"
"1.39400","0.13336","0.01190","-0.00001"
"1.41100","0.13503","-0.03349","-0.00001"
"1.42800","0.13670","-0.05293","-0.00001"
"1.44500","0.13838","0.01671","0.00000"
"1.46200","0.14008","0.01668","0.00000"
"1.47900","0.14180","0.03819","0.00000"
"1.49600","0.14347","0.11159","0.00000"
"1.51300","0.14508","0.08497","0.00000"
"1.53000","0.14674","0.01037","0.00000"
"1.54700","0.14846","0.04246","0.00000"
"1.56400","0.15020","0.09335","-0.00001"
"1.58100","0.15195","0.03001","-0.00001"
"1.59800","0.15367","-0.10495","-0.00001"
"1.61500","0.15532","-0.05442","-0.00001"
"1.63200","0.15693","0.00765","-0.00001"
"1.64900","0.15860","0.02082","0.00000"
"1.66600","0.16030","-0.02577","0.00000"
"1.68300","0.16204","-0.05256","0.00000"
"1.70000","0.16381","-0.01665","0.00000"
"1.71700","0.16557","0.01287","0.00000"
"1.73400","0.16724","0.06808","0.00000"
"1.75100","0.16886","0.05388","0.00000"
"1.76800","0.17054","0.10252","-0.00001"
"1.78500","0.17229","0.08934","-0.00001"
"1.80200","0.17404","-0.00857","-0.00001"
"1.81900","0.17579","-0.05710","-0.00001"
"1.83600","0.17749","-0.01054","-0.00001"
"1.85300","0.17915","0.09014","-0.00001"
"1.87000","0.18083","0.10508","-0.00001"
"1.88700","0.18255","0.01901","0.00000"
"1.90400","0.18428","-0.02470","0.00000"
"1.92100","0.18604","0.01696","0.00000"
"1.93800","0.18780","0.05652","0.00000"
"1.95500","0.18948","0.01794","0.00001"
"1.97200","0.19110","-0.01897","0.00000"
"1.98900","0.19276","-0.01192","0.00000"
"2.00600","0.19449","-0.06892","0.00000"
"2.02300","0.19624","-0.08749","0.00000"
"2.04000","0.19799","-0.03428","-0.00001"
"2.05700","0.19970","0.02036","-0.00001"
"2.07400","0.20134","0.02631","0.00000"
"2.09100","0.20293","-0.02245","0.00000"
"2.10800","0.20456","-0.04030","0.00000"
"2.12500","0.20626","0.02956","0.00000"
"2.14200","0.20800","0.09707","0.00000"
"2.15900","0.20977","0.09960","0.00000"
"2.17600","0.21151","0.10234","0.00000"
"2.19300","0.21314","0.14898","0.00000"
"2.21000","0.21474","0.12281","0.00000"
"2.22700","0.21640","0.04912","0.00000"
"2.24400","0.21810","-0.01184","-0.00001"
"2.26100","0.21982","0.01653","-0.00001"
"2.27800","0.22158","0.02164","-0.00001"
"2.29500","0.22332","0.02117","0.00000"
"2.31200","0.22501","0.06360","0.00000"
"2.32900","0.22669","0.10937","0.00000"
"2.34600","0.22838","0.12629","0.00000"
"2.36300","0.23007","0.06604","0.00000"
"2.38000","0.23180","0.02400","0.00000"
"2.39700","0.23357","-0.01659","0.00000"
"2.41400","0.23528","0.03077","0.00000"
"2.43100","0.23692","0.09622","0.00000"
"2.44800","0.23857","0.12171","0.00000"
"2.46500","0.24029","0.10718","-0.00001"
"2.48200","0.24203","-0.01537","-0.00001"
"2.49900","0.24379","-0.06043","0.00000"
"2.51600","0.24556","-0.02896","0.00000"
"2.53300","0.24726","-0.02747","0.00000"
"2.55000","0.24888","0.00337","0.00000"
"2.56700","0.25053","0.03273","0.00000"
"2.58400","0.25222","0.01516","0.00000"
"2.60100","0.25396","0.01369","0.00000"
"2.61800","0.25573","0.04400","0.00000"
"2.63500","0.25746","0.04803","0.00000"
"2.65200","0.25911","0.05975","0.00000"
"2.66900","0.26073","0.05396","0.00000"
"2.68600","0.26239","0.00181","-0.00001"
"2.70300","0.26408","-0.05846","-0.00001"
"2.72000","0.26578","-0.04914","-0.00001"
"2.73700","0.26753","-0.03036","0.00000"
"2.75400","0.26925","-0.00228","0.00000"
"2.77100","0.27092","0.06621","0.00000"
"2.78800","0.27256","0.05245","0.00000"
"2.80500","0.27425","-0.00864","0.00000"
"2.82200","0.27595","0.00059","0.00001"
"2.83900","0.27768","0.06250","0.00000"
"2.85600","0.27942","0.02150","0.00000"
"2.87300","0.28112","0.00280","0.00000"
"2.89000","0.28277","0.02072","-0.00001"
"2.90700","0.28445","-0.02106","-0.00001"
"2.92400","0.28617","-0.00417","-0.00001"
"2.94100","0.28787","-0.01480","-0.00001"
"2.95800","0.28959","-0.06727","-0.00001"
"2.97500","0.29133","0.00335","0.00000"
"2.99200","0.29303","-0.03027","0.00000"
"3.00900","0.29469","-0.00008","0.00000"
"3.02600","0.29637","0.00011","0.00000"
"3.04300","0.29808","-0.02056","0.00000"
"3.06000","0.29981","-0.02047","0.00000"
"3.07700","0.30158","0.06621","0.00000"
"3.09400","0.30332","0.00852","0.00000"
"3.11100","0.30499","-0.01812","0.00000"
"3.12800","0.30667","0.03172","-0.00001"
"3.14500","0.30839","-0.01235","-0.00001"
"3.16200","0.31010","-0.02458","-0.00001"
"3.17900","0.31181","-0.06549","-0.00001"
"3.19600","0.31356","-0.03641","0.00000"
"3.21300","0.31529","-0.06747","0.00000"
"3.23000","0.31694","-0.03821","0.00000"
"3.24700","0.31857","0.01163","0.00000"
"3.26400","0.32025","-0.00174","0.00000"
"3.28100","0.32195","-0.04136","0.00000"
"3.29800","0.32366","-0.03635","0.00000"
"3.31500","0.32538","-0.04156","0.00000"
"3.33200","0.32706","-0.01712","-0.00001"
"3.34900","0.32870","0.01239","-0.00001"
"3.36600","0.33038","0.09237","-0.00001"
"3.38300","0.33210","0.12025","-0.00001"
"3.40000","0.33380","0.10018","-0.00001"
"3.41700","0.33551","0.04196","0.00000"
"3.43400","0.33723","-0.08093","0.00000"
"3.45100","0.33889","-0.08268","0.00000"
"3.46800","0.34052","-0.01957","0.00000"
"3.48500","0.34219","0.08180","0.00000"
"3.50200","0.34392","0.07363","0.00000"
"3.51900","0.34568","0.03619","0.00000"
"3.53600","0.34744","0.00462","0.00000"
"3.55300","0.34916","-0.04845","-0.00001"
"3.57000","0.35081","0.00662","-0.00001"
"3.58700","0.35247","0.04496","-0.00001"
"3.60400","0.35419","0.02729","-0.00001"
"3.62100","0.35592","0.01439","-0.00001"
"3.63800","0.35764","-0.01035","-0.00001"
"3.65500","0.35940","-0.08228","0.00000"
"3.67200","0.36114","-0.06144","0.00000"
"3.68900","0.36281","-0.04738","0.00000"
"3.70600","0.36445","-0.00062","0.00000"
"3.72300","0.36615","0.07022","0.00000"
"3.74000","0.36789","0.07391","0.00000"
"3.75700","0.36963","-0.00467","0.00000"
"3.77400","0.37137","-0.05089","-0.00001"
"3.79100","0.37307","-0.02086","-0.00001"
"3.80800","0.37474","0.04066","-0.00001"
"3.82500","0.37641","0.10693","-0.00001"
"3.84200","0.37809","0.10176","-0.00001"
"3.85900","0.37976","0.01784","0.00000"
"3.87600","0.38146","0.00939","0.00000"
"3.89300","0.38317","0.01857","0.00000"
"3.91000","0.38482","0.05630","0.00000"
"3.92700","0.38643","0.07383","0.00000"
"3.94400","0.38809","0.12692","0.00000"
"3.96100","0.38982","0.09374","0.00000"
"3.97800","0.39158","0.05082","0.00000"
"3.99500","0.39333","0.05224","0.00000"
"4.01200","0.39504","0.09097","0.00000"
"4.02900","0.39668","0.04646","-0.00001"
"4.04600","0.39831","-0.00194","-0.00001"
"4.06300","0.40000","0.01152","-0.00001"
"4.08000","0.40172","0.01680","-0.00001"
"4.09700","0.40347","0.04190","0.00000"
"4.11400","0.40525","0.03397","0.00000"
"4.13100","0.40699","0.00972","0.00000"
"4.14800","0.40864","-0.00341","0.00000"
"4.16500","0.41026","-0.01801","0.00000"
"4.18200","0.41195","-0.07645","0.00000"
"4.19900","0.41369","-0.03495","0.00000"
"4.21600","0.41544","-0.00718","-0.00001"
"4.23300","0.41719","0.04141","-0.00001"
"4.25000","0.41888","0.04192","-0.00001"
"4.26700","0.42054","0.06231","-0.00001"
"4.28400","0.42223","0.03770","-0.00001"
"4.30100","0.42395","-0.04520","0.00000"
"4.31800","0.42568","-0.02282","0.00000"
"4.33500","0.42743","-0.04828","0.00000"
"4.35200","0.42918","-0.06455","0.00000"
"4.36900","0.43083","-0.01844","0.00000"
"4.38600","0.43244","0.02571","0.00000"
"4.40300","0.43412","0.01950","0.00000"
"4.42000","0.43587","-0.05285","-0.00001"
"4.43700","0.43762","-0.07255","-0.00001"
"4.45400","0.43936","-0.06331","-0.00001"
"4.47100","0.44107","-0.01877","-0.00001"
"4.48800","0.44270","-0.03509","-0.00001"
"4.50500","0.44430","-0.03205","-0.00001"
"4.52200","0.44595","-0.02315","-0.00001"
"4.53900","0.44766","-0.07227","0.00000"
"4.55600","0.44941","-0.05491","0.00000"
"4.57300","0.45118","-0.01170","0.00000"
"4.59000","0.45290","-0.01315","0.00000"
"4.60700","0.45453","-0.00046","0.00000"
"4.62400","0.45613","0.01908","0.00000"
"4.64100","0.45781","0.04909","-0.00001"
"4.65800","0.45952","0.04703","-0.00001"
"4.67500","0.46126","0.00937","-0.00001"
"4.69200","0.46302","-0.04316","-0.00001"
"4.70900","0.46474","-0.04042","-0.00001"
"4.72600","0.46641","0.02181","-0.00001"
"4.74300","0.46808","0.01699","0.00000"
"4.76000","0.46977","0.01641","0.00000"
"4.77700","0.47149","0.06699","0.00000"
"4.79400","0.47324","0.07036","0.00000"
"4.81100","0.47500","-0.00186","0.00000"
"4.82800","0.47669","-0.06615","0.00000"
"4.84500","0.47831","-0.02261","0.00000"
"4.86200","0.47999","0.00718","-0.00001"
"4.87900","0.48171","-0.02521","-0.00001"
"4.89600","0.48345","-0.03813","0.00000"
"4.91300","0.48521","0.01108","0.00000"
"4.93000","0.48696","0.05667","0.00000"
"4.94700","0.48866","0.06223","0.00000"
"4.96400","0.49031","0.09890","0.00000"
"4.98100","0.49197","0.06186","0.00000"
"4.99800","0.49367","0.00470","0.00000"
"5.01500","0.49541","0.02185","0.00000"
"5.03200","0.49717","-0.00247","0.00000"
"5.04900","0.49888","-0.00031","0.00000"
"5.06600","0.50050","0.08106","0.00000"
"5.08300","0.50212","0.07608","0.00000"
"5.10000","0.50379","0.08056","-0.00001"
"5.11700","0.50548","0.02562","-0.00001"
"5.13400","0.50721","-0.01620","-0.00001"
"5.15100","0.50896","0.00170","-0.00001"
"5.16800","0.51067","0.05401","-0.00001"
"5.18500","0.51231","-0.01744","0.00000"
"5.20200","0.51396","-0.06617","0.00000"
"5.21900","0.51564","-0.04495","0.00000"
"5.23600","0.51734","-0.00967","0.00000"
"5.25300","0.51907","-0.02456","0.00000"
"5.27000","0.52080","-0.09301","0.00000"
"5.28700","0.52249","-0.13972","0.00000"
"5.30400","0.52413","-0.05500","0.00000"
"5.32100","0.52583","-0.04394","-0.00001"
"5.33800","0.52755","-0.02975","-0.00001"
"5.35500","0.52927","-0.01285","-0.00001"
"5.37200","0.53101","0.04397","-0.00001"
"5.38900","0.53276","-0.04211","0.00000"
"5.40600","0.53447","-0.11433","0.00000"
"5.42300","0.53613","-0.09975","0.00000"
"5.44000","0.53780","-0.12025","0.00000"
"5.45700","0.53950","-0.10152","0.00000"
"5.47400","0.54123","-0.06023","0.00000"
"5.49100","0.54301","0.01206","0.00000"
"5.50800","0.54474","-0.01308","0.00000"
"5.52500","0.54640","-0.00122","-0.00001"
"5.54200","0.54808","0.04125","-0.00001"
"5.55900","0.54980","0.09413","-0.00001"
"5.57600","0.55151","0.13346","0.00000"
"5.59300","0.55322","0.08891","0.00000"
"5.61000","0.55498","-0.01314","0.00000"
"5.62700","0.55669","-0.01669","0.00000"
"5.64400","0.55832","0.02851","0.00000"
"5.66100","0.55995","0.08272","0.00000"
"5.67800","0.56164","0.02377","0.00000"
"5.69500","0.56334","0.04518","0.00000"
"5.71200","0.56505","0.07345","0.00000"
"5.72900","0.56676","0.06952","0.00000"
"5.74600","0.56843","0.03200","0.00000"
"5.76300","0.57007","-0.02795","0.00000"
"5.78000","0.57176","-0.04275","0.00000"
"5.79700","0.57347","-0.02161","-0.00001"
"5.81400","0.57518","0.03346","0.00000"
"5.83100","0.57690","0.01407","0.00000"
"5.84800","0.57862","-0.01903","0.00000"
"5.86500","0.58029","-0.03398","0.00000"
"5.88200","0.58191","-0.03970","0.00000"
"5.89900","0.58359","-0.04807","0.00001"
"5.91600","0.58533","-0.04211","0.00000"
"5.93300","0.58709","-0.00439","0.00000"
"5.95000","0.58885","-0.02823","0.00000"
"5.96700","0.59056","-0.00412","0.00000"
"5.98400","0.59221","0.03107","-0.00001"
"6.00100","0.59387","-0.04921","0.00000"
"6.01800","0.59559","0.01755","0.00000"
"6.03500","0.59731","-0.05220","0.00000"
"6.05200","0.59904","-0.08202","0.00000"
"6.06900","0.60079","-0.02834","0.00000"
"6.08600","0.60251","0.02875","0.00000"
"6.10300","0.60416","0.03729","0.00000"
"6.12000","0.60582","0.04304","0.00000"
"6.13700","0.60754","0.01069","0.00000"
"6.15400","0.60930","-0.01000","0.00000"
"6.17100","0.61105","-0.01241","0.00000"
"6.18800","0.61278","0.00352","0.00000"
"6.20500","0.61446","0.01192","0.00000"
"6.22200","0.61611","0.04637","-0.00001"
"6.23900","0.61777","-0.02276","0.00000"
"6.25600","0.61945","-0.03697","0.00000"
"6.27300","0.62114","-0.04017","0.00000"
"6.29000","0.62287","-0.03415","0.00000"
"6.30700","0.62459","-0.01757","0.00000"
"6.32400","0.62624","-0.03374","0.00001"
"6.34100","0.62786","-0.00841","0.00000"
"6.35800","0.62953","-0.02433","0.00000"
"6.37500","0.63127","-0.04376","0.00000"
"6.39200","0.63301","-0.06805","0.00000"
"6.40900","0.63476","-0.00675","0.00000"
"6.42600","0.63645","-0.00376","0.00000"
"6.44300","0.63807","-0.07718","0.00000"
"6.46000","0.63970","-0.04112","0.00000"
"6.47700","0.64139","-0.01371","0.00000"
"6.49400","0.64311","0.09351","0.00000"
"6.51100","0.64486","0.07023","0.00000"
"6.52800","0.64664","0.03198","0.00000"
"6.54500","0.64836","0.02178","0.00000"
"6.56200","0.65000","0.05684","0.00000"
"6.57900","0.65164","0.02197","0.00000"
"6.59600","0.65334","-0.03443","0.00000"
"6.61300","0.65508","-0.01383","0.00000"
"6.63000","0.65683","0.00394","0.00000"
"6.64700","0.65857","-0.03869","0.00000"
"6.66400","0.66024","-0.07387","0.00000"
"6.68100","0.66191","0.00084","0.00000"
"6.69800","0.66361","-0.00334","0.00000"
"6.71500","0.66535","-0.01681","0.00000"
"6.73200","0.66710","-0.00509","0.00000"
"6.74900","0.66888","0.02527","0.00000"
"6.76600","0.67062","-0.01542","0.00001"
"6.78300","0.67225","0.02476","0.00000"
"6.80000","0.67385","-0.04763","0.00000"
"6.81700","0.67555","-0.08623","0.00001"
"6.83400","0.67729","-0.01926","0.00000"
"6.85100","0.67903","0.02809","0.00000"
"6.86800","0.68077","0.04293","0.00000"
"6.88500","0.68246","0.05364","0.00000"
"6.90200","0.68408","0.00973","0.00000"
"6.91900","0.68569","-0.02566","0.00000"
"6.93600","0.68737","-0.05548","0.00000"
"6.95300","0.68908","-0.02639","0.00001"
"6.97000","0.69083","-0.02265","0.00001"
"6.98700","0.69259","0.01448","0.00001"
"7.00400","0.69428","-0.09150","0.00001"
"7.02100","0.69589","-0.05928","0.00001"
"7.03800","0.69750","0.00719","0.00001"
"7.05500","0.69918","0.08048","0.00001"
"7.07200","0.70090","0.04730","0.00000"
"7.08900","0.70264","-0.06645","0.00000"
"7.10600","0.70438","-0.13629","0.00000"
"7.12300","0.70609","-0.12070","0.00000"
"7.14000","0.70775","-0.08466","0.00000"
"7.15700","0.70944","-0.07204","0.00000"
"7.17400","0.71116","-0.04208","0.00000"
"7.19100","0.71290","-0.05610","0.00001"
"7.20800","0.71468","0.01027","0.00001"
"7.22500","0.71644","0.06994","0.00001"
"7.24200","0.71809","0.02406","0.00001"
"7.25900","0.71971","-0.02213","0.00001"
"7.27600","0.72139","-0.00921","0.00001"
"7.29300","0.72313","-0.01302","0.00000"
"7.31000","0.72487","-0.03041","0.00000"
"7.32700","0.72663","-0.08660","0.00000"
"7.34400","0.72837","-0.05229","0.00000"
"7.36100","0.73005","-0.01076","0.00000"
"7.37800","0.73169","-0.01963","0.00000"
"7.39500","0.73336","0.02274","0.00000"
"7.41200","0.73506","0.04850","0.00000"
"7.42900","0.73681","0.13521","0.00001"
"7.44600","0.73856","0.08671","0.00001"
"7.46300","0.74025","-0.02312","0.00001"
"7.48000","0.74187","-0.08985","0.00001"
"7.49700","0.74350","-0.04694","0.00001"
"7.51400","0.74518","-0.06377","0.00000"
"7.53100","0.74688","-0.12152","0.00000"
"7.54800","0.74860","-0.08415","0.00000"
"7.56500","0.75035","-0.07134","0.00000"
"7.58200","0.75204","-0.05632","0.00000"
"7.59900","0.75368","0.00332","0.00000"
"7.61600","0.75535","-0.05462","0.00001"
"7.63300","0.75706","-0.00009","0.00001"
"7.65000","0.75878","0.00942","0.00001"
"7.66700","0.76052","0.01118","0.00001"
"7.68400","0.76225","0.00267","0.00001"
"7.70100","0.76391","0.03725","0.00001"
"7.71800","0.76556","0.13745","0.00001"
"7.73500","0.76726","0.08041","0.00001"
"7.75200","0.76898","0.05511","0.00001"
"7.76900","0.77068","0.06814","0.00000"
"7.78600","0.77241","0.08229","0.00000"
"7.80300","0.77415","0.02324","0.00000"
"7.82000","0.77585","-0.02816","0.00000"
"7.83700","0.77751","-0.00424","0.00001"
"7.85400","0.77918","0.01882","0.00001"
"7.87100","0.78088","0.01844","0.00001"
"7.88800","0.78262","0.03191","0.00001"
"7.90500","0.78440","0.04138","0.00001"
"7.92200","0.78612","0.11756","0.00001"
"7.93900","0.78778","0.05302","0.00001"
"7.95600","0.78948","-0.04246","0.00000"
"7.97300","0.79120","-0.05112","0.00000"
"7.99000","0.79291","-0.06030","0.00001"
"8.00700","0.79463","-0.02963","0.00001"
"8.02400","0.79638","-0.00135","0.00001"
"8.04100","0.79807","0.00617","0.00001"
"8.05800","0.79970","-0.02833","0.00001"
"8.07500","0.80135","0.01171","0.00001"
"8.09200","0.80305","0.03677","0.00001"
"8.10900","0.80476","0.05817","0.00001"
"8.12600","0.80646","0.00390","0.00001"
"8.14300","0.80816","0.02832","0.00001"
"8.16000","0.80982","0.07202","0.00001"
"8.17700","0.81146","-0.04323","0.00001"
"8.19400","0.81315","-0.08015","0.00001"
"8.21100","0.81485","-0.07379","0.00001"
"8.22800","0.81654","-0.05020","0.00001"
"8.24500","0.81827","-0.07702","0.00001"
"8.26200","0.81998","-0.09367","0.00001"
"8.27900","0.82163","-0.01710","0.00001"
"8.29600","0.82326","0.03097","0.00001"
"8.31300","0.82495","-0.03831","0.00001"
"8.33000","0.82670","-0.05965","0.00001"
"8.34700","0.82847","-0.04984","0.00002"
"8.36400","0.83024","-0.03355","0.00002"
"8.38100","0.83194","-0.02711","0.00001"
"8.39800","0.83359","-0.10515","0.00001"
"8.41500","0.83527","-0.10506","0.00001"
"8.43200","0.83699","-0.07314","0.00001"
"8.44900","0.83871","0.07106","0.00001"
"8.46600","0.84044","0.09992","0.00001"
"8.48300","0.84220","0.04163","0.00001"
"8.50000","0.84391","0.02853","0.00001"
"8.51700","0.84557","0.00549","0.00002"
"8.53400","0.84725","0.01784","0.00002"
"8.55100","0.84899","0.01725","0.00002"
"8.56800","0.85074","-0.02559","0.00002"
"8.58500","0.85249","-0.05157","0.00002"
"8.60200","0.85420","-0.05538","0.00001"
"8.61900","0.85587","-0.03616","0.00001"
"8.63600","0.85751","0.02380","0.00001"
"8.65300","0.85918","0.04103","0.00001"
"8.67000","0.86086","0.07316","0.00001"
"8.68700","0.86255","-0.00339","0.00001"
"8.70400","0.86429","-0.01946","0.00001"
"8.72100","0.86599","-0.00367","0.00001"
"8.73800","0.86762","-0.04442","0.00001"
"8.75500","0.86923","-0.09515","0.00001"
"8.77200","0.87092","-0.16961","0.00002"
"8.78900","0.87266","-0.17825","0.00002"
"8.80600","0.87441","-0.09660","0.00002"
"8.82300","0.87616","-0.03706","0.00002"
"8.84000","0.87783","0.00984","0.00001"
"8.85700","0.87945","0.08235","0.00001"
"8.87400","0.88109","0.08618","0.00001"
"8.89100","0.88278","0.01794","0.00001"
"8.90800","0.88451","-0.04354","0.00001"
"8.92500","0.88628","-0.06616","0.00001"
"8.94200","0.88807","-0.02579","0.00001"
"8.95900","0.88978","-0.02559","0.00001"
"8.97600","0.89141","-0.08362","0.00002"
"8.99300","0.89307","-0.05788","0.00002"
"9.01000","0.89479","0.00139","0.00002"
"9.02700","0.89654","0.03994","0.00002"
"9.04400","0.89829","0.02996","0.00001"
"9.06100","0.90000","0.02545","0.00001"
"9.07800","0.90166","0.04911","0.00001"
"9.09500","0.90332","0.01371","0.00001"
"9.11200","0.90503","-0.01150","0.00001"
"9.12900","0.90677","-0.07140","0.00001"
"9.14600","0.90852","-0.02161","0.00001"
"9.16300","0.91030","-0.04809","0.00002"
"9.18000","0.91201","0.02737","0.00002"
"9.19700","0.91363","0.02285","0.00002"
"9.21400","0.91525","0.02262","0.00002"
"9.23100","0.91695","0.02784","0.00002"
"9.24800","0.91869","0.03948","0.00002"
"9.26500","0.92044","-0.06272","0.00002"
"9.28200","0.92218","-0.12444","0.00002"
"9.29900","0.92386","-0.07209","0.00001"
"9.31600","0.92546","0.01721","0.00001"
"9.33300","0.92708","0.04631","0.00001"
"9.35000","0.92875","0.02229","0.00001"
"9.36700","0.93048","-0.00831","0.00001"
"9.38400","0.93224","0.02059","0.00002"
"9.40100","0.93402","0.04656","0.00002"
"9.41800","0.93571","-0.04200","0.00002"
"9.43500","0.93732","-0.08863","0.00002"
"9.45200","0.93895","-0.06832","0.00002"
"9.46900","0.94064","-0.10919","0.00002"
"9.48600","0.94235","-0.10169","0.00001"
"9.50300","0.94408","-0.00438","0.00001"
"9.52000","0.94582","-0.04620","0.00001"
"9.53700","0.94751","-0.09994","0.00001"
"9.55400","0.94917","-0.02461","0.00001"
"9.57100","0.95085","0.05145","0.00001"
"9.58800","0.95255","0.05127","0.00001"
"9.60500","0.95429","0.06007","0.00002"
"9.62200","0.95606","0.09650","0.00002"
"9.63900","0.95780","0.02383","0.00002"
"9.65600","0.95944","0.02421","0.00002"
"9.67300","0.96106","-0.07252","0.00002"
"9.69000","0.96276","-0.03470","0.00002"
"9.70700","0.96452","0.08147","0.00001"
"9.72400","0.96629","0.06517","0.00001"
"9.74100","0.96807","0.04312","0.00001"
"9.75800","0.96980","0.01627","0.00001"
"9.77500","0.97145","0.00083","0.00001"
"9.79200","0.97308","-0.04856","0.00001"
"9.80900","0.97474","-0.03438","0.00002"
"9.82600","0.97645","-0.03071","0.00002"
"9.84300","0.97820","-0.06030","0.00002"
"9.86000","0.97996","-0.08654","0.00002"
"9.87700","0.98165","-0.07341","0.00002"
"9.89400","0.98328","-0.04649","0.00002"
"9.91100","0.98494","-0.00858","0.00002"
"9.92800","0.98662","0.02319","0.00002"
"9.94500","0.98830","0.02451","0.00001"
"9.96200","0.99001","0.06267","0.00001"
"9.97900","0.99175","0.07406","0.00001"
"9.99600","0.99343","0.05868","0.00001"
"10.01300","0.99508","0.06400","0.00001"
"10.03000","0.99675","-0.00126","0.00001"
"10.04700","0.99844","-0.07216","0.00002"
"10.06400","1.00015","-0.09313","0.00002"
"10.08100","1.00189","-0.05405","0.00002"
"10.09800","1.00361","-0.05132","0.00002"
"10.11500","1.00527","0.01292","0.00002"
"10.13200","1.00692","0.07593","0.00002"
"10.14900","1.00863","0.06828","0.00001"
"10.16600","1.01035","0.04439","0.00001"
"10.18300","1.01207","0.03191","0.00001"
"10.20000","1.01382","0.02189","0.00001"
"10.21700","1.01554","-0.02336","0.00001"
"10.23400","1.01721","-0.04441","0.00002"
"10.25100","1.01887","-0.01634","0.00002"
"10.26800","1.02056","-0.03861","0.00002"
"10.28500","1.02229","-0.04321","0.00002"
"10.30200","1.02405","-0.04262","0.00002"
"10.31900","1.02583","-0.03783","0.00002"
"10.33600","1.02753","-0.06371","0.00001"
"10.35300","1.02919","0.01628","0.00001"
"10.37000","1.03088","0.11195","0.00001"
"10.38700","1.03257","0.08424","0.00001"
"10.40400","1.03424","0.00216","0.00001"
"10.42100","1.03594","-0.02595","0.00001"
"10.43800","1.03769","0.01292","0.00002"
"10.45500","1.03940","0.09358","0.00001"
"10.47200","1.04105","0.12328","0.00001"
"10.48900","1.04272","0.09152","0.00001"
"10.50600","1.04442","0.02187","0.00002"
"10.52300","1.04613","0.01123","0.00002"
"10.54000","1.04786","-0.00418","0.00002"
"10.55700","1.04956","-0.06780","0.00002"
"10.57400","1.05122","-0.08074","0.00002"
"10.59100","1.05287","-0.06961","0.00002"
"10.60800","1.05457","-0.00205","0.00001"
"10.62500","1.05627","0.05487","0.00001"
"10.64200","1.05797","0.09788","0.00001"
"10.65900","1.05969","0.07503","0.00001"
"10.67600","1.06137","-0.00041","0.00001"
"10.69300","1.06300","-0.05453","0.00001"
"10.71000","1.06464","-0.10509","0.00002"
"10.72700","1.06637","-0.01324","0.00002"
"10.74400","1.06814","0.01481","0.00002"
"10.76100","1.06992","0.11132","0.00002"
"10.77800","1.07168","0.06457","0.00002"
"10.79500","1.07337","0.10519","0.00002"
"10.81200","1.07501","0.11473","0.00002"
"10.82900","1.07670","0.03920","0.00002"
"10.84600","1.07841","-0.02162","0.00001"
"10.86300","1.08011","-0.05511","0.00001"
"10.88000","1.08185","-0.00378","0.00001"
"10.89700","1.08360","0.01973","0.00001"
"10.91400","1.08529","0.03702","0.00002"
"10.93100","1.08693","0.05194","0.00002"
"10.94800","1.08861","0.06795","0.00002"
"10.96500","1.09035","0.08430","0.00002"
"10.98200","1.09211","-0.01760","0.00002"
"10.99900","1.09387","-0.13114","0.00002"
"11.01600","1.09559","-0.09798","0.00002"
"11.03300","1.09725","-0.09880","0.00002"
"11.05000","1.09891","-0.03600","0.00001"
"11.06700","1.10059","0.00591","0.00001"
"11.08400","1.10228","-0.02601","0.00001"
"11.10100","1.10397","0.01450","0.00001"
"11.11800","1.10569","-0.04135","0.00001"
"11.13500","1.10737","-0.07466","0.00002"
"11.15200","1.10899","-0.01560","0.00002"
"11.16900","1.11062","0.05353","0.00002"
"11.18600","1.11233","0.08128","0.00002"
"11.20300","1.11408","0.03353","0.00002"
"11.22000","1.11583","0.00182","0.00002"
"11.23700","1.11758","-0.00103","0.00002"
"11.25400","1.11925","-0.00008","0.00002"
"11.27100","1.12087","0.08553","0.00001"
"11.28800","1.12252","0.09019","0.00001"
"11.30500","1.12421","0.02830","0.00001"
"11.32200","1.12593","-0.09434","0.00001"
"11.33900","1.12770","-0.14695","0.00001"
"11.35600","1.12947","-0.07482","0.00002"
"11.37300","1.13116","-0.03192","0.00002"
"11.39000","1.13278","0.00529","0.00002"
"11.40700","1.13445","-0.00229","0.00003"
"11.42400","1.13619","-0.01980","0.00002"
"11.44100","1.13795","0.00919","0.00002"
"11.45800","1.13970","-0.04327","0.00002"
"11.47500","1.14141","-0.01491","0.00002"
"11.49200","1.14306","0.02381","0.00001"
"11.50900","1.14473","0.08306","0.00001"
"11.52600","1.14644","0.14879","0.00001"
"11.54300","1.14816","0.15804","0.00001"
"11.56000","1.14990","0.11188","0.00002"
"11.57700","1.15166","0.05632","0.00002"
"11.59400","1.15336","-0.07165","-0.00006"
"11.61100","1.15497","-0.08448","-0.00029"
"11.62800","1.15661","-0.02731","-0.00062"
"11.64500","1.15834","0.05308","-0.00094"
"11.66200","1.16010","0.05463","-0.00116"
"11.67900","1.16186","0.05831","-0.00125"
"11.69600","1.16360","-0.01218","-0.00126"
"11.71300","1.16526","-0.09480","-0.00125"
"11.73000","1.16686","0.02129","-0.00124"
"11.74700","1.16848","0.02286","-0.00123"
"11.76400","1.17016","-0.06585","-0.00123"
"11.78100","1.17189","0.07338","-0.00123"
"11.79800","1.17366","0.08969","-0.00123"
"11.81500","1.17541","0.00405","-0.00123"
"11.83200","1.17707","0.05388","-0.00123"
"11.84900","1.17867","0.06498","-0.00123"
"11.86600","1.18033","-0.02146","-0.00123"
"11.88300","1.18203","-0.05303","-0.00123"
"11.90000","1.18376","-0.05191","-0.00123"
"11.91700","1.18549","-0.03311","-0.00123"
"11.93400","1.18722","0.02961","-0.00123"
"11.95100","1.18891","-0.01375","-0.00123"
"11.96800","1.19057","-0.09957","-0.00123"
"11.98500","1.19226","-0.10770","-0.00123"
"12.00200","1.19395","-0.16485","-0.00123"
"12.01900","1.19569","-0.05669","-0.00123"
"12.03600","1.19747","0.00570","-0.00123"
"12.05300","1.19921","0.01113","-0.00123"
"12.07000","1.20086","0.05777","-0.00123"
"12.08700","1.20251","0.03977","-0.00122"
"12.10400","1.20423","0.03889","-0.00123"
"12.12100","1.20598","0.05614","-0.00123"
"12.13800","1.20773","0.09306","-0.00123"
"12.15500","1.20949","0.03569","-0.00123"
"12.17200","1.21120","-0.00038","-0.00124"
"12.18900","1.21283","-0.05809","-0.00123"
"12.20600","1.21446","0.01945","-0.00123"
"12.22300","1.21614","0.11320","-0.00123"
"12.24000","1.21788","0.07375","-0.00123"
"12.25700","1.21964","0.02162","-0.00123"
"12.27400","1.22138","0.02032","-0.00123"
"12.29100","1.22304","0.00460","-0.00123"
"12.30800","1.22467","-0.06352","-0.00123"
"12.32500","1.22633","-0.00030","-0.00123"
"12.34200","1.22801","0.04524","-0.00123"
"12.35900","1.22969","0.07809","-0.00123"
"12.37600","1.23141","0.03593","-0.00123"
"12.39300","1.23314","0.00700","-0.00123"
"12.41000","1.23483","-0.08145","-0.00123"
"12.42700","1.23648","-0.03532","-0.00123"
"12.44400","1.23815","0.02833","-0.00123"
"12.46100","1.23982","0.00820","-0.00123"
"12.47800","1.24152","-0.05163","-0.00123"
"12.49500","1.24326","-0.02358","-0.00123"
"12.51200","1.24499","0.05652","-0.00123"
"12.52900","1.24666","0.04280","-0.00123"
"12.54600","1.24833","0.03476","-0.00123"
"12.56300","1.25006","0.02993","-0.00123"
"12.58000","1.25178","0.01364","-0.00123"
"12.59700","1.25350","-0.05747","-0.00123"
"12.61400","1.25525","-0.09631","-0.00123"
"12.63100","1.25695","-0.08542","-0.00123"
"12.64800","1.25861","-0.04184","-0.00123"
"12.66500","1.26027","-0.06016","-0.00123"
"12.68200","1.26198","0.01790","-0.00123"
"12.69900","1.26372","0.07388","-0.00123"
"12.71600","1.26549","0.11718","-0.00123"
"12.73300","1.26724","-0.00852","-0.00123"
"12.75000","1.26892","-0.07491","-0.00123"
"12.76700","1.27058","-0.07471","-0.00123"
"12.78400","1.27228","-0.06235","-0.00123"
"12.80100","1.27399","0.00190","-0.00123"
"12.81800","1.27567","0.04925","-0.00123"
"12.83500","1.27741","0.01656","-0.00124"
"12.85200","1.27917","-0.06622","-0.00124"
"12.86900","1.28085","-0.06790","-0.00123"
"12.88600","1.28248","-0.04354","-0.00124"
"12.90300","1.28414","0.00114","-0.00123"
"12.92000","1.28583","0.10474","-0.00123"
"12.93700","1.28753","0.10704","-0.00123"
"12.95400","1.28926","0.04472","-0.00123"
"12.97100","1.29095","0.01005","-0.00123"
"12.98800","1.29261","-0.03096","-0.00123"
"13.00500","1.29427","-0.01282","-0.00123"
"13.02200","1.29599","-0.00388","-0.00123"
"13.03900","1.29770","0.03873","-0.00123"
"13.05600","1.29941","0.04807","-0.00123"
"13.07300","1.30113","0.00002","-0.00123"
"13.09000","1.30279","-0.03737","-0.00124"
"13.10700","1.30440","-0.01177","-0.00124"
"13.12400","1.30604","-0.02752","-0.00124"
"13.14100","1.30776","-0.01805","-0.00123"
"13.15800","1.30953","-0.01482","-0.00123"
"13.17500","1.31130","0.00861","-0.00123"
"13.19200","1.31305","0.00382","-0.00123"
"13.20900","1.31473","-0.01344","-0.00123"
"13.22600","1.31637","-0.01679","-0.00123"
"13.24300","1.31807","-0.04215","-0.00123"
"13.26000","1.31978","-0.04289","-0.00123"
"13.27700","1.32150","-0.01936","-0.00124"
"13.29400","1.32325","0.02988","-0.00124"
"13.31100","1.32500","-0.03298","-0.00124"
"13.32800","1.32669","-0.06009","-0.00123"
"13.34500","1.32832","-0.00397","-0.00124"
"13.36200","1.33001","0.06552","-0.00123"
"13.37900","1.33176","0.08485","-0.00123"
"13.39600","1.33352","0.08411","-0.00123"
"13.41300","1.33527","-0.01174","-0.00123"
"13.43000","1.33698","-0.01829","-0.00123"
"13.44700","1.33865","0.02544","-0.00123"
"13.46400","1.34033","-0.03487","-0.00123"
"13.48100","1.34201","0.01962","-0.00124"
"13.49800","1.34368","0.11514","-0.00124"
"13.51500","1.34539","0.07381","-0.00124"
"13.53200","1.34712","0.01714","-0.00124"
"13.54900","1.34878","-0.01905","-0.00124"
"13.56600","1.35039","-0.06969","-0.00124"
"13.58300","1.35202","-0.01742","-0.00124"
"13.60000","1.35373","0.05244","-0.00123"
"13.61700","1.35548","0.08927","-0.00123"
"13.63400","1.35724","0.13860","-0.00123"
"13.65100","1.35896","0.06943","-0.00123"
"13.66800","1.36060","-0.05170","-0.00123"
"13.68500","1.36220","-0.01303","-0.00123"
"13.70200","1.36388","0.09486","-0.00124"
"13.71900","1.36561","0.12794","-0.00124"
"13.73600","1.36736","0.06160","-0.00124"
"13.75300","1.36913","-0.00780","-0.00124"
"13.77000","1.37088","-0.03467","-0.00124"
"13.78700","1.37253","-0.00644","-0.00124"
"13.80400","1.37415","0.02191","-0.00123"
"13.82100","1.37582","-0.00987","-0.00123"
"13.83800","1.37756","-0.04320","-0.00123"
"13.85500","1.37932","-0.08372","-0.00123"
"13.87200","1.38108","-0.04361","-0.00123"
"13.88900","1.38280","-0.02689","-0.00123"
"13.90600","1.38446","-0.09473","-0.00123"
"13.92300","1.38613","0.00186","-0.00123"
"13.94000","1.38783","0.09756","-0.00124"
"13.95700","1.38955","0.10089","-0.00124"
"13.97400","1.39132","0.12684","-0.00124"
"13.99100","1.39309","0.09121","-0.00124"
"14.00800","1.39477","0.04266","-0.00123"
"14.02500","1.39637","-0.02378","-0.00124"
"14.04200","1.39802","-0.03805","-0.00123"
"14.05900","1.39975","0.00443","-0.00123"
"14.07600","1.40150","0.01301","-0.00123"
"14.09300","1.40325","-0.01260","-0.00123"
"14.11000","1.40497","-0.04175","-0.00123"
"14.12700","1.40662","-0.00316","-0.00123"
"14.14400","1.40823","-0.02206","-0.00123"
"14.16100","1.40987","0.04158","-0.00124"
"14.17800","1.41156","0.12285","-0.00124"
"14.19500","1.41329","0.09155","-0.00124"
"14.21200","1.41506","0.04948","-0.00124"
"14.22900","1.41679","0.09316","-0.00123"
"14.24600","1.41843","0.06280","-0.00123"
"14.26300","1.42003","0.02218","-0.00123"
"14.28000","1.42170","-0.06019","-0.00123"
"14.29700","1.42342","-0.09176","-0.00123"
"14.31400","1.42518","0.00157","-0.00123"
"14.33100","1.42694","-0.03473","-0.00123"
"14.34800","1.42867","-0.09528","-0.00123"
"14.36500","1.43033","-0.06774","-0.00123"
"14.38200","1.43197","-0.01364","-0.00124"
"14.39900","1.43366","0.00682","-0.00123"
"14.41600","1.43536","0.03871","-0.00123"
"14.43300","1.43709","0.05640","-0.00124"
"14.45000","1.43886","0.02983","-0.00124"
"14.46700","1.44058","0.03149","-0.00123"
"14.48400","1.44222","0.03645","-0.00123"
"14.50100","1.44388","-0.00624","-0.00122"
"14.51800","1.44561","-0.10620","-0.00122"
"14.53500","1.44736","-0.08978","-0.00123"
"14.55200","1.44913","-0.01229","-0.00123"
"14.56900","1.45089","0.05041","-0.00123"
"14.58600","1.45260","0.06149","-0.00123"
"14.60300","1.45424","0.01925","-0.00123"
"14.62000","1.45588","-0.02123","-0.00123"
"14.63700","1.45755","-0.00120","-0.00123"
"14.65400","1.45928","-0.01204","-0.00123"
"14.67100","1.46105","0.05914","-0.00123"
"14.68800","1.46278","0.04587","-0.00123"
"14.70500","1.46442","0.07984","-0.00123"
"14.72200","1.46603","0.06509","-0.00122"
"14.73900","1.46769","0.02535","-0.00122"
"14.75600","1.46939","0.06657","-0.00122"
"14.77300","1.47110","0.01921","-0.00123"
"14.79000","1.47284","0.00010","-0.00123"
"14.80700","1.47456","-0.03403","-0.00123"
"14.82400","1.47622","0.00396","-0.00123"
"14.84100","1.47787","0.02865","-0.00123"
"14.85800","1.47956","0.03930","-0.00123"
"14.87500","1.48126","0.00903","-0.00123"
"14.89200","1.48297","-0.00404","-0.00123"
"14.90900","1.48471","-0.03985","-0.00122"
"14.92600","1.48641","-0.00578","-0.00122"
"14.94300","1.48806","0.02964","-0.00122"
"14.96000","1.48975","0.08924","-0.00122"
"14.97700","1.49147","0.01444","-0.00122"
"14.99400","1.49318","-0.02425","-0.00122"
"15.01100","1.49490","-0.08311","-0.00123"
"15.02800","1.49664","-0.05461","-0.00123"
"15.04500","1.49835","-0.03242","-0.00123"
"15.06200","1.50000","0.04228","-0.00123"
"15.07900","1.50167","0.08688","-0.00123"
"15.09600","1.50338","0.09828","-0.00123"
"15.11300","1.50512","0.06168","-0.00123"
"15.13000","1.50690","0.06253","-0.00123"
"15.14700","1.50864","0.01850","-0.00123"
"15.16400","1.51030","0.04136","-0.00123"
"15.18100","1.51197","0.10045","-0.00122"
"15.19800","1.51369","0.04290","-0.00122"
"15.21500","1.51542","0.01156","-0.00122"
"15.23200","1.51713","-0.00305","-0.00123"
"15.24900","1.51889","-0.00978","-0.00123"
"15.26600","1.52062","-0.07745","-0.00123"
"15.28300","1.52226","-0.08931","-0.00123"
"15.30000","1.52388","-0.03727","-0.00123"
"15.31700","1.52555","0.02743","-0.00123"
"15.33400","1.52724","0.07753","-0.00123"
"15.35100","1.52895","0.05493","-0.00123"
"15.36800","1.53067","-0.00337","-0.00122"
"15.38500","1.53235","-0.03434","-0.00122"
"15.40200","1.53400","-0.03321","-0.00122"
"15.41900","1.53566","-0.11239","-0.00122"
"15.43600","1.53737","-0.10808","-0.00122"
"15.45300","1.53907","-0.06405","-0.00122"
"15.47000","1.54077","0.05563","-0.00122"
"15.48700","1.54249","0.04911","-0.00122"
"15.50400","1.54416","0.05053","-0.00123"
"15.52100","1.54577","-0.00102","-0.00123"
"15.53800","1.54744","-0.10060","-0.00123"
"15.55500","1.54917","-0.07849","-0.00123"
"15.57200","1.55096","-0.02047","-0.00122"
"15.58900","1.55275","0.00517","-0.00122"
"15.60600","1.55449","0.03182","-0.00122"
"15.62300","1.55615","-0.00859","-0.00122"
"15.64000","1.55779","0.00824","-0.00122"
"15.65700","1.55950","-0.00298","-0.00122"
"15.67400","1.56123","0.07333","-0.00122"
"15.69100","1.56296","0.12437","-0.00122"
"15.70800","1.56472","0.05562","-0.00123"
"15.72500","1.56646","0.03164","-0.00123"
"15.74200","1.56812","0.03906","-0.00123"
"15.75900","1.56975","-0.01816","-0.00122"
"15.77600","1.57145","-0.03196","-0.00122"
"15.79300","1.57319","-0.04055","-0.00122"
"15.81000","1.57493","-0.06084","-0.00122"
"15.82700","1.57666","0.00379","-0.00122"
"15.84400","1.57835","0.14764","-0.00122"
"15.86100","1.58001","0.14988","-0.00122"
"15.87800","1.58169","0.03309","-0.00122"
"15.89500","1.58338","-0.00344","-0.00122"
"15.91200","1.58506","0.07758","-0.00123"
"15.92900","1.58678","0.14667","-0.00123"
"15.94600","1.58850","0.08686","-0.00123"
"15.96300","1.59015","0.05754","-0.00123"
"15.98000","1.59174","0.11132","-0.00123"
"15.99700","1.59339","0.09383","-0.00123"
"16.01400","1.59512","0.09773","-0.00122"
"16.03100","1.59688","0.08357","-0.00122"
"16.04800","1.59865","0.05971","-0.00122"
"16.06500","1.60036","0.05688","-0.00122"
"16.08200","1.60199","0.00603","-0.00122"
"16.09900","1.60360","0.00738","-0.00122"
"16.11600","1.60528","-0.08516","-0.00122"
"16.13300","1.60700","-0.02297","-0.00122"
"16.15000","1.60874","0.08566","-0.00122"
"16.16700","1.61052","0.08204","-0.00122"
"16.18400","1.61225","0.07838","-0.00123"
"16.20100","1.61390","0.09099","-0.00123"
"16.21800","1.61553","0.09193","-0.00122"
"16.23500","1.61723","0.07821","-0.00122"
"16.25200","1.61898","0.06405","-0.00122"
"16.26900","1.62074","0.04337","-0.00122"
"16.28600","1.62251","0.02205","-0.00121"
"16.30300","1.62421","0.01887","-0.00122"
"16.32000","1.62586","0.03062","-0.00122"
"16.33700","1.62753","0.05875","-0.00122"
"16.35400","1.62924","-0.02439","-0.00122"
"16.37100","1.63097","-0.04690","-0.00122"
"16.38800","1.63275","-0.00225","-0.00123"
"16.40500","1.63450","-0.03718","-0.00122"
"16.42200","1.63615","-0.01881","-0.00123"
"16.43900","1.63774","0.02903","-0.00123"
"16.45600","1.63941","0.04769","-0.00122"
"16.47300","1.64115","0.01950","-0.00122"
"16.49000","1.64290","0.11653","-0.00122"
"16.50700","1.64464","0.08215","-0.00122"
"16.52400","1.64633","0.10302","-0.00122"
"16.54100","1.64797","0.12537","-0.00122"
"16.55800","1.64960","0.08458","-0.00122"
"16.57500","1.65127","-0.02003","-0.00123"
"16.59200","1.65299","-0.10692","-0.00123"
"16.60900","1.65473","-0.09775","-0.00123"
"16.62600","1.65650","-0.07282","-0.00123"
"16.64300","1.65821","-0.12628","-0.00123"
"16.66000","1.65983","-0.07481","-0.00123"
"16.67700","1.66143","-0.08157","-0.00122"
"16.69400","1.66310","-0.07872","-0.00122"
"16.71100","1.66481","-0.04243","-0.00122"
"16.72800","1.66654","0.03885","-0.00122"
"16.74500","1.66830","-0.00475","-0.00122"
"16.76200","1.67003","-0.00989","-0.00122"
"16.77900","1.67169","-0.01540","-0.00122"
"16.79600","1.67335","0.00061","-0.00123"
"16.81300","1.67504","0.00897","-0.00123"
"16.83000","1.67676","0.01053","-0.00123"
"16.84700","1.67851","0.06220","-0.00123"
"16.86400","1.68027","0.02032","-0.00123"
"16.88100","1.68196","-0.04094","-0.00122"
"16.89800","1.68358","-0.03095","-0.00122"
"16.91500","1.68526","-0.00259","-0.00122"
"16.93200","1.68700","-0.01001","-0.00122"
"16.94900","1.68876","0.00441","-0.00122"
"16.96600","1.69052","0.01712","-0.00122"
"16.98300","1.69228","0.01424","-0.00122"
"17.00000","1.69398","-0.07747","-0.00122"
"17.01700","1.69563","-0.06400","-0.00123"
"17.03400","1.69729","-0.02560","-0.00123"
"17.05100","1.69898","0.01798","-0.00123"
"17.06800","1.70070","0.05112","-0.00123"
"17.08500","1.70245","0.00832","-0.00123"
"17.10200","1.70415","-0.01380","-0.00123"
"17.11900","1.70578","-0.03861","-0.00122"
"17.13600","1.70740","0.03458","-0.00122"
"17.15300","1.70907","0.06391","-0.00122"
"17.17000","1.71077","0.07326","-0.00122"
"17.18700","1.71250","0.05842","-0.00122"
"17.20400","1.71425","0.06793","-0.00122"
"17.22100","1.71595","0.08977","-0.00123"
"17.23800","1.71759","0.09058","-0.00123"
"17.25500","1.71924","-0.02003","-0.00123"
"17.27200","1.72094","-0.05420","-0.00123"
"17.28900","1.72265","-0.09768","-0.00123"
"17.30600","1.72438","-0.09526","-0.00123"
"17.32300","1.72612","-0.11008","-0.00123"
"17.34000","1.72780","-0.07189","-0.00122"
"17.35700","1.72945","-0.02239","-0.00122"
"17.37400","1.73113","0.07510","-0.00122"
"17.39100","1.73284","0.07204","-0.00122"
"17.40800","1.73454","0.04387","-0.00122"
"17.42500","1.73628","-0.03477","-0.00122"
"17.44200","1.73803","-0.07686","-0.00123"
"17.45900","1.73975","0.01399","-0.00123"
"17.47600","1.74142","-0.02734","-0.00123"
"17.49300","1.74310","-0.07652","-0.00123"
"17.51000","1.74480","-0.04462","-0.00123"
"17.52700","1.74654","-0.09762","-0.00123"
"17.54400","1.74831","-0.04090","-0.00123"
"17.56100","1.75002","0.02496","-0.00123"
"17.57800","1.75168","-0.00599","-0.00122"
"17.59500","1.75336","0.01288","-0.00122"
"17.61200","1.75508","-0.01998","-0.00123"
"17.62900","1.75679","-0.04209","-0.00123"
"17.64600","1.75850","0.10084","-0.00123"
"17.66300","1.76026","0.09209","-0.00123"
"17.68000","1.76198","-0.01329","-0.00124"
"17.69700","1.76363","-0.01279","-0.00124"
"17.71400","1.76527","0.01857","-0.00124"
"17.73100","1.76696","-0.01011","-0.00124"
"17.74800","1.76867","-0.04935","-0.00124"
"17.76500","1.77037","-0.03662","-0.00123"
"17.78200","1.77207","0.01152","-0.00123"
"17.79900","1.77374","0.03671","-0.00123"
"17.81600","1.77537","-0.00463","-0.00123"
"17.83300","1.77705","-0.00299","-0.00123"
"17.85000","1.77876","0.02936","-0.00123"
"17.86700","1.78047","0.02764","-0.00123"
"17.88400","1.78219","0.05078","-0.00124"
"17.90100","1.78391","0.05098","-0.00124"
"17.91800","1.78556","0.05527","-0.00124"
"17.93500","1.78717","0.07800","-0.00124"
"17.95200","1.78886","0.04904","-0.00124"
"17.96900","1.79061","0.00234","-0.00124"
"17.98600","1.79239","0.05576","-0.00124"
"18.00300","1.79416","0.02828","-0.00123"
"18.02000","1.79588","-0.02251","-0.00123"
"18.03700","1.79753","-0.02231","-0.00123"
"18.05400","1.79919","0.01158","-0.00123"
"18.07100","1.80090","0.00762","-0.00123"
"18.08800","1.80262","0.06737","-0.00124"
"18.10500","1.80434","0.01910","-0.00124"
"18.12200","1.80611","-0.12184","-0.00124"
"18.13900","1.80783","-0.07454","-0.00124"
"18.15600","1.80948","0.03480","-0.00124"
"18.17300","1.81113","0.00492","-0.00124"
"18.19000","1.81285","-0.01843","-0.00124"
"18.20700","1.81461","0.01665","-0.00124"
"18.22400","1.81636","0.06573","-0.00123"
"18.24100","1.81809","0.01488","-0.00123"
"18.25800","1.81977","-0.04411","-0.00123"
"18.27500","1.82141","-0.01631","-0.00123"
"18.29200","1.82309","-0.01824","-0.00123"
"18.30900","1.82477","-0.00663","-0.00123"
"18.32600","1.82646","-0.04178","-0.00123"
"18.34300","1.82818","-0.04189","-0.00124"
"18.36000","1.82989","-0.05072","-0.00124"
"18.37700","1.83154","-0.07733","-0.00123"
"18.39400","1.83316","-0.03925","-0.00122"
"18.41100","1.83483","-0.03922","-0.00122"
"18.42800","1.83656","-0.08591","-0.00122"
"18.44500","1.83830","-0.13757","-0.00122"
"18.46200","1.84005","-0.10555","-0.00122"
"18.47900","1.84175","-0.05776","-0.00122"
"18.49600","1.84339","0.02626","-0.00122"
"18.51300","1.84501","-0.00004","-0.00122"
"18.53000","1.84668","-0.06972","-0.00123"
"18.54700","1.84839","-0.07138","-0.00122"
"18.56400","1.85013","0.00760","-0.00121"
"18.58100","1.85191","0.07423","0.01228"
"18.59800","1.85363","0.20964","0.06491"
"18.61500","1.85527","0.25615","0.10299"
"18.63200","1.85690","0.22524","0.11741"
"18.64900","1.85861","0.22642","0.11886"
"18.66600","1.86037","0.19783","0.11668"
"18.68300","1.86213","0.20488","0.11486"
"18.70000","1.86388","0.17237","0.11410"
"18.71700","1.86556","0.17923","0.11398"
"18.73400","1.86722","0.12465","0.11407"
"18.75100","1.86893","0.16083","0.11415"
"18.76800","1.87066","0.25002","0.11419"
"18.78500","1.87241","0.27382","0.11420"
"18.80200","1.87419","0.42781","0.11419"
"18.81900","1.87592","0.45012","0.11419"
"18.83600","1.87754","0.37230","0.11419"
"18.85300","1.87914","0.38017","0.11419"
"18.87000","1.88082","0.36563","0.11419"
"18.88700","1.88257","0.31641","0.11419"
"18.90400","1.88433","0.26104","0.11419"
"18.92100","1.88607","0.23949","0.11419"
"18.93800","1.88776","0.22353","0.11419"
"18.95500","1.88938","0.17343","0.11419"
"18.97200","1.89098","0.23622","0.11419"
"18.98900","1.89265","0.26188","0.11419"
"19.00600","1.89437","0.26332","0.11419"
"19.02300","1.89612","0.27110","0.11419"
"19.04000","1.89790","0.29093","0.11419"
"19.05700","1.89959","0.24349","0.11419"
"19.07400","1.90120","0.28398","0.11419"
"19.09100","1.90282","0.30500","0.11419"
"19.10800","1.90450","0.39527","0.11419"
"19.12500","1.90622","0.33678","0.11419"
"19.14200","1.90796","0.25445","0.11419"
"19.15900","1.90971","0.22905","0.11419"
"19.17600","1.91141","0.22013","0.11419"
"19.19300","1.91307","0.18552","0.11419"
"19.21000","1.91474","0.12934","0.11419"
"19.22700","1.91644","0.20335","0.11419"
"19.24400","1.91817","0.27791","0.11419"
"19.26100","1.91995","0.26914","0.11419"
"19.27800","1.92171","0.30271","0.11419"
"19.29500","1.92338","0.28924","0.11419"
"19.31200","1.92500","0.31624","0.11419"
"19.32900","1.92669","0.31444","0.11419"
"19.34600","1.92843","0.28153","0.11419"
"19.36300","1.93017","0.31560","0.11419"
"19.38000","1.93193","0.22560","0.11419"
"19.39700","1.93368","0.17194","0.11419"
"19.41400","1.93536","0.21785","0.11419"
"19.43100","1.93700","0.21816","0.11419"
"19.44800","1.93867","0.23992","0.11419"
"19.46500","1.94038","0.26180","0.11419"
"19.48200","1.94213","0.22929","0.11419"
"19.49900","1.94388","0.25313","0.11419"
"19.51600","1.94557","0.26121","0.11419"
"19.53300","1.94719","0.29889","0.11419"
"19.55000","1.94883","0.35192","0.11419"
"19.56700","1.95051","0.28129","0.11419"
"19.58400","1.95219","0.28912","0.11419"
"19.60100","1.95390","0.34931","0.11419"
"19.61800","1.95563","0.40643","0.11419"
"19.63500","1.95733","0.34016","0.10216"
"19.65200","1.95897","0.27140","0.07320"
"19.66900","1.96064","0.23177","0.05754"
"19.68600","1.96234","0.20266","0.03586"
"19.70300","1.96406","0.00822","0.01542"
"19.72000","1.96580","-0.02450","0.00634"
"19.73700","1.96754","0.01914","0.01013"
"19.75400","1.96922","0.03012","0.01123"
"19.77100","1.97086","0.08577","0.00671"
"19.78800","1.97255","0.02699","0.00348"
"19.80500","1.97425","-0.03817","0.00451"
"19.82200","1.97596","0.03364","0.00593"
"19.83900","1.97770","0.07714","0.01078"
"19.85600","1.97944","0.18587","0.03605"
"19.87300","1.98114","0.24686","0.07090"
"19.89000","1.98280","0.24814","0.07726"
"19.90700","1.98448","0.14674","0.04623"
"19.92400","1.98619","0.03243","0.01748"
"19.94100","1.98793","0.00329","0.00534"
"19.95800","1.98969","-0.00376","0.00340"
"19.97500","1.99141","-0.04405","0.00487"
"19.99200","1.99308","-0.08006","0.00636"
"20.00900","1.99477","-0.05316","0.00691"
"20.02600","1.99649","0.04222","0.00692"
"20.04300","1.99819","-0.05773","0.00693"
"20.06000","1.99990","-0.11399","0.00699"
"20.07700","2.00165","-0.10021","0.00701"
"20.09400","2.00336","-0.01441","0.00700"
"20.11100","2.00500","0.01212","0.00696"
"20.12300","2.00616","0.00003","0.00691"