File: archive/undergrad/433/Pressure Vessel/Specimen_RawData_1.csv
Time,Extension,Load,Strain Gage18
(s),(mm),(N),(mm/mm)
"0.00000","0.00000","-0.04002","-0.00003"
"0.01900","0.00000","0.02101","-0.00003"
"0.03800","0.00012","0.09362","-0.00004"
"0.05700","0.00051","0.07709","-0.00004"
"0.07600","0.00144","0.01053","-0.00004"
"0.09500","0.00278","-0.08478","-0.00004"
"0.11400","0.00369","-0.10046","-0.00004"
"0.13300","0.00443","-0.04588","-0.00003"
"0.15200","0.00585","-0.05226","-0.00003"
"0.17100","0.00817","-0.06523","-0.00003"
"0.19000","0.01096","-0.08144","-0.00003"
"0.20900","0.01365","-0.09634","-0.00003"
"0.22800","0.01599","-0.09174","-0.00003"
"0.24700","0.01806","-0.09451","-0.00004"
"0.26600","0.01999","-0.07688","-0.00004"
"0.28500","0.02191","-0.04197","-0.00004"
"0.30400","0.02388","-0.04753","-0.00004"
"0.32300","0.02581","-0.13930","-0.00004"
"0.34200","0.02767","-0.15668","-0.00003"
"0.36100","0.02956","-0.13506","-0.00003"
"0.38000","0.03151","-0.23049","-0.00003"
"0.39900","0.03347","-0.18719","-0.00003"
"0.41800","0.03542","-0.18881","-0.00003"
"0.43700","0.03730","-0.11435","-0.00003"
"0.45600","0.03915","-0.11652","-0.00003"
"0.47500","0.04104","-0.03295","-0.00004"
"0.49400","0.04296","-0.06653","-0.00004"
"0.51300","0.04492","-0.10018","-0.00004"
"0.53200","0.04690","-0.05013","-0.00004"
"0.55100","0.04878","-0.09730","-0.00004"
"0.57000","0.05059","-0.12879","-0.00003"
"0.58900","0.05248","-0.10413","-0.00003"
"0.60800","0.05444","-0.04991","-0.00003"
"0.62700","0.05638","-0.05792","-0.00003"
"0.64600","0.05830","-0.06573","-0.00003"
"0.66500","0.06017","-0.07934","-0.00003"
"0.68400","0.06198","-0.08308","-0.00003"
"0.70300","0.06381","-0.07757","-0.00004"
"0.72200","0.06569","-0.08134","-0.00004"
"0.74100","0.06761","-0.05961","-0.00004"
"0.76000","0.06959","-0.05330","-0.00004"
"0.77900","0.07150","-0.01245","-0.00003"
"0.79800","0.07332","-0.03390","-0.00003"
"0.81700","0.07515","-0.08628","-0.00003"
"0.83600","0.07705","-0.07991","-0.00003"
"0.85500","0.07898","-0.06010","-0.00003"
"0.87400","0.08094","-0.01856","-0.00003"
"0.89300","0.08285","-0.05694","-0.00003"
"0.91200","0.08470","-0.03768","-0.00003"
"0.93100","0.08658","-0.09159","-0.00004"
"0.95000","0.08850","-0.05161","-0.00004"
"0.96900","0.09046","0.02019","-0.00004"
"0.98800","0.09244","0.00151","-0.00003"
"1.00700","0.09435","-0.01112","-0.00003"
"1.02600","0.09618","0.00816","-0.00003"
"1.04500","0.09804","-0.07272","-0.00003"
"1.06400","0.09997","-0.16303","-0.00003"
"1.08300","0.10191","-0.14038","-0.00003"
"1.10200","0.10388","-0.05036","-0.00003"
"1.12100","0.10582","-0.09370","-0.00003"
"1.14000","0.10768","-0.13931","-0.00003"
"1.15900","0.10952","-0.12521","-0.00004"
"1.17800","0.11140","-0.10716","-0.00004"
"1.19700","0.11334","-0.12979","-0.00004"
"1.21600","0.11531","-0.12196","-0.00003"
"1.23500","0.11721","-0.04436","-0.00003"
"1.25400","0.11901","-0.06372","-0.00003"
"1.27300","0.12083","-0.03417","-0.00003"
"1.29200","0.12271","-0.09783","-0.00003"
"1.31100","0.12461","-0.09855","-0.00003"
"1.33000","0.12655","-0.08425","-0.00003"
"1.34900","0.12848","-0.08786","-0.00003"
"1.36800","0.13034","-0.17259","-0.00003"
"1.38700","0.13219","-0.16736","-0.00004"
"1.40600","0.13408","-0.09490","-0.00004"
"1.42500","0.13598","-0.12583","-0.00003"
"1.44400","0.13793","-0.11814","-0.00003"
"1.46300","0.13985","-0.09001","-0.00003"
"1.48200","0.14171","-0.05098","-0.00003"
"1.50100","0.14359","-0.05618","-0.00003"
"1.52000","0.14551","-0.06952","-0.00003"
"1.53900","0.14741","-0.16231","-0.00003"
"1.55800","0.14934","-0.16608","-0.00003"
"1.57700","0.15128","-0.11635","-0.00003"
"1.59600","0.15316","-0.09394","-0.00004"
"1.61500","0.15502","-0.09262","-0.00004"
"1.63400","0.15690","-0.09491","-0.00004"
"1.65300","0.15882","-0.06332","-0.00003"
"1.67200","0.16080","-0.11606","-0.00003"
"1.69100","0.16275","-0.12347","-0.00003"
"1.71000","0.16463","-0.11970","-0.00003"
"1.72900","0.16651","-0.18102","-0.00003"
"1.74800","0.16842","-0.17268","-0.00003"
"1.76700","0.17031","-0.14585","-0.00003"
"1.78600","0.17225","-0.12460","-0.00003"
"1.80500","0.17419","-0.06476","-0.00003"
"1.82400","0.17604","-0.09623","-0.00003"
"1.84300","0.17786","-0.00901","-0.00004"
"1.86200","0.17974","-0.02523","-0.00003"
"1.88100","0.18164","0.01618","-0.00003"
"1.90000","0.18356","0.05479","-0.00003"
"1.91900","0.18547","0.00537","-0.00003"
"1.93800","0.18730","-0.09895","-0.00003"
"1.95700","0.18915","-0.17988","-0.00003"
"1.97600","0.19106","-0.15162","-0.00003"
"1.99500","0.19297","-0.04478","-0.00003"
"2.01400","0.19489","-0.01897","-0.00003"
"2.03300","0.19682","-0.02149","-0.00003"
"2.05200","0.19867","-0.06563","-0.00004"
"2.07100","0.20049","-0.09568","-0.00004"
"2.09000","0.20239","-0.03432","-0.00003"
"2.10900","0.20436","-0.09229","-0.00003"
"2.12800","0.20635","-0.09608","-0.00003"
"2.14700","0.20830","-0.05494","-0.00003"
"2.16600","0.21015","-0.07836","-0.00003"
"2.18500","0.21200","-0.05698","-0.00003"
"2.20400","0.21392","-0.08386","-0.00003"
"2.22300","0.21584","-0.20165","-0.00003"
"2.24200","0.21778","-0.21769","-0.00003"
"2.26100","0.21974","-0.18116","-0.00004"
"2.28000","0.22162","-0.17776","-0.00004"
"2.29900","0.22347","-0.12828","-0.00004"
"2.31800","0.22538","-0.14026","-0.00003"
"2.33700","0.22733","-0.13382","-0.00003"
"2.35600","0.22927","0.00545","-0.00003"
"2.37500","0.23120","-0.04139","-0.00003"
"2.39400","0.23307","-0.07212","-0.00003"
"2.41300","0.23491","-0.07979","-0.00003"
"2.43200","0.23678","-0.10975","-0.00003"
"2.45100","0.23866","-0.02752","-0.00003"
"2.47000","0.24058","-0.09152","-0.00004"
"2.48900","0.24251","-0.08924","-0.00004"
"2.50800","0.24437","-0.08370","-0.00004"
"2.52700","0.24617","-0.22267","-0.00004"
"2.54600","0.24806","-0.19399","-0.00003"
"2.56500","0.24999","-0.19490","-0.00003"
"2.58400","0.25194","-0.19879","-0.00003"
"2.60300","0.25387","-0.19769","-0.00003"
"2.62200","0.25572","-0.07465","-0.00003"
"2.64100","0.25755","-0.00536","-0.00003"
"2.66000","0.25944","-0.01954","-0.00003"
"2.67900","0.26136","-0.06900","-0.00004"
"2.69800","0.26331","-0.01518","-0.00004"
"2.71700","0.26528","-0.05935","-0.00004"
"2.73600","0.26716","-0.10622","-0.00004"
"2.75500","0.26899","-0.05467","-0.00004"
"2.77400","0.27087","-0.08659","-0.00003"
"2.79300","0.27281","-0.06218","-0.00003"
"2.81200","0.27478","-0.08098","-0.00003"
"2.83100","0.27673","-0.10205","-0.00003"
"2.85000","0.27862","-0.08863","-0.00003"
"2.86900","0.28048","0.00310","-0.00003"
"2.88800","0.28239","-0.02585","-0.00004"
"2.90700","0.28430","-0.06124","-0.00004"
"2.92600","0.28626","-0.07469","-0.00004"
"2.94500","0.28822","-0.05221","-0.00004"
"2.96400","0.29007","-0.02333","-0.00004"
"2.98300","0.29187","-0.07694","-0.00004"
"3.00200","0.29377","-0.15301","-0.00003"
"3.02100","0.29573","-0.12310","-0.00003"
"3.04000","0.29768","-0.07540","-0.00003"
"3.05900","0.29961","-0.04542","-0.00003"
"3.07800","0.30146","-0.11373","-0.00003"
"3.09700","0.30326","-0.11991","-0.00003"
"3.11600","0.30510","-0.10887","-0.00004"
"3.13500","0.30698","-0.09528","-0.00004"
"3.15400","0.30891","-0.11606","-0.00004"
"3.17300","0.31089","-0.04537","-0.00004"
"3.19200","0.31279","-0.07549","-0.00004"
"3.21100","0.31460","-0.07586","-0.00003"
"3.23000","0.31644","-0.11698","-0.00003"
"3.24900","0.31834","-0.12962","-0.00003"
"3.26800","0.32027","-0.11275","-0.00003"
"3.28700","0.32223","-0.13560","-0.00003"
"3.30600","0.32415","-0.13275","-0.00003"
"3.32500","0.32600","-0.08427","-0.00003"
"3.34400","0.32787","-0.04161","-0.00004"
"3.36300","0.32978","-0.09091","-0.00004"
"3.38200","0.33172","-0.02271","-0.00004"
"3.40100","0.33371","-0.06993","-0.00004"
"3.42000","0.33562","-0.09690","-0.00004"
"3.43900","0.33744","-0.12748","-0.00003"
"3.45800","0.33933","-0.14816","-0.00003"
"3.47700","0.34127","-0.20080","-0.00003"
"3.49600","0.34321","-0.17084","-0.00003"
"3.51500","0.34517","-0.13550","-0.00003"
"3.53400","0.34711","-0.10093","-0.00003"
"3.55300","0.34897","-0.01977","-0.00004"
"3.57200","0.35082","0.02142","-0.00004"
"3.59100","0.35270","0.01548","-0.00004"
"3.61000","0.35464","-0.05596","-0.00004"
"3.62900","0.35661","-0.14820","-0.00004"
"3.64800","0.35849","-0.12393","-0.00004"
"3.66700","0.36029","-0.07214","-0.00003"
"3.68600","0.36213","-0.07384","-0.00003"
"3.70500","0.36401","-0.08828","-0.00003"
"3.72400","0.36591","-0.05852","-0.00003"
"3.74300","0.36784","-0.05609","-0.00003"
"3.76200","0.36976","-0.11887","-0.00003"
"3.78100","0.37161","-0.14847","-0.00004"
"3.80000","0.37348","-0.12403","-0.00004"
"3.81900","0.37537","-0.12884","-0.00004"
"3.83800","0.37727","-0.14445","-0.00004"
"3.85700","0.37922","-0.08669","-0.00004"
"3.87600","0.38113","-0.08891","-0.00003"
"3.89500","0.38299","-0.08898","-0.00003"
"3.91400","0.38488","-0.05349","-0.00003"
"3.93300","0.38680","0.00028","-0.00003"
"3.95200","0.38870","-0.05224","-0.00003"
"3.97100","0.39064","-0.11948","-0.00003"
"3.99000","0.39258","-0.14436","-0.00004"
"4.00900","0.39446","-0.08980","-0.00004"
"4.02800","0.39632","-0.06966","-0.00004"
"4.04700","0.39821","-0.05521","-0.00004"
"4.06600","0.40014","-0.07169","-0.00004"
"4.08500","0.40212","-0.17108","-0.00004"
"4.10400","0.40405","-0.20229","-0.00003"
"4.12300","0.40592","-0.16871","-0.00003"
"4.14200","0.40783","-0.14266","-0.00003"
"4.16100","0.40974","-0.09057","-0.00003"
"4.18000","0.41163","-0.07850","-0.00003"
"4.19900","0.41357","-0.07944","-0.00003"
"4.21800","0.41550","-0.06029","-0.00004"
"4.23700","0.41735","-0.02838","-0.00004"
"4.25600","0.41918","-0.08803","-0.00004"
"4.27500","0.42107","-0.14865","-0.00004"
"4.29400","0.42297","-0.11924","-0.00004"
"4.31300","0.42488","-0.07120","-0.00004"
"4.33200","0.42678","-0.11284","-0.00003"
"4.35100","0.42862","-0.12365","-0.00003"
"4.37000","0.43049","-0.12770","-0.00003"
"4.38900","0.43240","-0.15145","-0.00003"
"4.40800","0.43431","-0.12486","-0.00003"
"4.42700","0.43623","-0.06235","-0.00004"
"4.44600","0.43814","-0.10499","-0.00004"
"4.46500","0.43997","-0.13754","-0.00004"
"4.48400","0.44180","-0.07587","-0.00004"
"4.50300","0.44371","-0.08547","-0.00004"
"4.52200","0.44568","-0.14503","-0.00004"
"4.54100","0.44766","-0.02878","-0.00003"
"4.56000","0.44959","-0.02348","-0.00003"
"4.57900","0.45145","-0.10877","-0.00003"
"4.59800","0.45332","-0.05798","-0.00003"
"4.61700","0.45524","-0.04041","-0.00003"
"4.63600","0.45716","-0.03173","-0.00003"
"4.65500","0.45910","-0.02638","-0.00004"
"4.67400","0.46105","-0.10965","-0.00004"
"4.69300","0.46292","-0.06430","-0.00004"
"4.71200","0.46476","-0.02705","-0.00004"
"4.73100","0.46667","-0.13000","-0.00004"
"4.75000","0.46861","-0.15093","-0.00004"
"4.76900","0.47057","-0.08078","-0.00003"
"4.78800","0.47250","-0.07978","-0.00003"
"4.80700","0.47438","-0.07204","-0.00003"
"4.82600","0.47625","-0.08099","-0.00003"
"4.84500","0.47813","-0.11291","-0.00003"
"4.86400","0.48001","-0.08562","-0.00003"
"4.88300","0.48192","-0.10910","-0.00004"
"4.90200","0.48384","-0.10966","-0.00004"
"4.92100","0.48567","-0.15484","-0.00004"
"4.94000","0.48748","-0.14530","-0.00004"
"4.95900","0.48937","-0.15045","-0.00004"
"4.97800","0.49131","-0.22662","-0.00003"
"4.99700","0.49327","-0.18962","-0.00003"
"5.01600","0.49519","-0.04760","-0.00003"
"5.03500","0.49702","-0.02907","-0.00003"
"5.05400","0.49884","-0.01427","-0.00003"
"5.07300","0.50073","0.02558","-0.00003"
"5.09200","0.50265","-0.04607","-0.00003"
"5.11100","0.50462","-0.15591","-0.00004"
"5.13000","0.50660","-0.21873","-0.00004"
"5.14900","0.50848","-0.18913","-0.00004"
"5.16800","0.51030","-0.16594","-0.00004"
"5.18700","0.51217","-0.12238","-0.00004"
"5.20600","0.51410","-0.08896","-0.00003"
"5.22500","0.51606","-0.08518","-0.00003"
"5.24400","0.51802","-0.08174","-0.00003"
"5.26300","0.51991","-0.12123","-0.00003"
"5.28200","0.52179","-0.11904","-0.00003"
"5.30100","0.52371","-0.13870","-0.00003"
"5.32000","0.52563","-0.15067","-0.00004"
"5.33900","0.52759","-0.17983","-0.00004"
"5.35800","0.52954","-0.15122","-0.00004"
"5.37700","0.53138","-0.10729","-0.00004"
"5.39600","0.53318","-0.05035","-0.00004"
"5.41500","0.53509","-0.06619","-0.00004"
"5.43400","0.53704","-0.10834","-0.00003"
"5.45300","0.53899","-0.17115","-0.00003"
"5.47200","0.54092","-0.17520","-0.00003"
"5.49100","0.54277","-0.19471","-0.00003"
"5.51000","0.54457","-0.15541","-0.00003"
"5.52900","0.54640","-0.04652","-0.00003"
"5.54800","0.54829","0.04792","-0.00003"
"5.56700","0.55023","-0.06078","-0.00004"
"5.58600","0.55219","-0.17537","-0.00004"
"5.60500","0.55406","-0.15687","-0.00003"
"5.62400","0.55584","-0.10101","-0.00003"
"5.64300","0.55769","-0.09596","-0.00003"
"5.66200","0.55961","-0.17468","-0.00003"
"5.68100","0.56156","-0.16118","-0.00002"
"5.70000","0.56352","-0.10287","-0.00002"
"5.71900","0.56544","-0.12048","-0.00002"
"5.73800","0.56730","-0.04050","-0.00002"
"5.75700","0.56919","-0.00569","-0.00003"
"5.77600","0.57110","-0.03057","-0.00003"
"5.79500","0.57305","-0.09097","-0.00003"
"5.81400","0.57503","-0.14732","-0.00003"
"5.83300","0.57692","-0.15671","-0.00003"
"5.85200","0.57873","-0.07419","-0.00002"
"5.87100","0.58060","-0.04561","-0.00002"
"5.89000","0.58255","-0.02590","-0.00002"
"5.90900","0.58451","-0.09656","-0.00002"
"5.92800","0.58649","-0.11446","-0.00001"
"5.94700","0.58841","-0.08415","-0.00001"
"5.96600","0.59026","-0.07895","-0.00002"
"5.98500","0.59211","-0.04196","-0.00002"
"6.00400","0.59400","-0.05746","-0.00002"
"6.02300","0.59594","-0.07908","-0.00002"
"6.04200","0.59789","-0.05354","-0.00002"
"6.06100","0.59974","-0.11119","-0.00002"
"6.08000","0.60154","-0.07149","-0.00001"
"6.09900","0.60339","-0.07264","-0.00001"
"6.11800","0.60530","-0.06957","-0.00001"
"6.13700","0.60722","-0.08674","-0.00001"
"6.15600","0.60917","-0.16097","-0.00001"
"6.17500","0.61108","-0.15296","-0.00001"
"6.19400","0.61292","-0.18360","-0.00001"
"6.21300","0.61477","-0.15117","-0.00001"
"6.23200","0.61666","-0.07709","-0.00001"
"6.25100","0.61856","-0.08204","-0.00001"
"6.27000","0.62051","-0.08952","-0.00001"
"6.28900","0.62243","-0.10501","-0.00001"
"6.30800","0.62429","-0.14185","0.00000"
"6.32700","0.62618","-0.06312","0.00000"
"6.34600","0.62809","-0.04489","0.00000"
"6.36500","0.62999","-0.01389","0.00000"
"6.38400","0.63194","-0.11961","0.00000"
"6.40300","0.63387","-0.15400","0.00000"
"6.42200","0.63573","-0.11850","0.00000"
"6.44100","0.63760","-0.08678","0.00000"
"6.46000","0.63949","-0.14149","0.00000"
"6.47900","0.64142","-0.21170","0.00000"
"6.49800","0.64340","-0.12444","0.00000"
"6.51700","0.64531","-0.09309","0.00000"
"6.53600","0.64718","-0.07923","0.00000"
"6.55500","0.64910","-0.10008","0.00001"
"6.57400","0.65103","-0.04223","0.00001"
"6.59300","0.65294","0.01876","0.00001"
"6.61200","0.65491","-0.16213","0.00001"
"6.63100","0.65684","-0.18594","0.00000"
"6.65000","0.65866","-0.13080","0.00000"
"6.66900","0.66049","-0.09098","0.00000"
"6.68800","0.66237","-0.11442","0.00000"
"6.70700","0.66427","-0.11441","0.00000"
"6.72600","0.66620","-0.10644","0.00000"
"6.74500","0.66810","-0.06124","0.00001"
"6.76400","0.66993","-0.07519","0.00001"
"6.78300","0.67181","-0.11849","0.00001"
"6.80200","0.67372","-0.08211","0.00001"
"6.82100","0.67562","-0.05020","0.00001"
"6.84000","0.67753","-0.08395","0.00001"
"6.85900","0.67943","-0.13904","0.00001"
"6.87800","0.68124","-0.14160","0.00001"
"6.89700","0.68308","-0.14041","0.00001"
"6.91600","0.68500","-0.18268","0.00001"
"6.93500","0.68697","-0.13625","0.00001"
"6.95400","0.68896","-0.07315","0.00001"
"6.97300","0.69088","-0.06187","0.00002"
"6.99200","0.69273","-0.03441","0.00002"
"7.01100","0.69461","-0.02995","0.00002"
"7.03000","0.69655","-0.02850","0.00002"
"7.04900","0.69847","-0.01567","0.00002"
"7.06800","0.70042","-0.08614","0.00002"
"7.08700","0.70236","-0.05111","0.00002"
"7.10600","0.70422","-0.08434","0.00002"
"7.12500","0.70607","-0.11003","0.00002"
"7.14400","0.70800","-0.10725","0.00002"
"7.16300","0.70996","-0.04113","0.00002"
"7.18200","0.71191","-0.01882","0.00002"
"7.20100","0.71382","-0.13696","0.00002"
"7.22000","0.71568","-0.12914","0.00002"
"7.23900","0.71752","-0.12440","0.00003"
"7.25800","0.71939","-0.10915","0.00003"
"7.27700","0.72125","-0.17197","0.00003"
"7.29600","0.72318","-0.08858","0.00002"
"7.31500","0.72510","-0.09032","0.00002"
"7.33400","0.72693","-0.09245","0.00002"
"7.35300","0.72875","-0.06814","0.00002"
"7.37200","0.73065","-0.10276","0.00002"
"7.39100","0.73259","-0.09154","0.00002"
"7.41000","0.73454","-0.14746","0.00002"
"7.42900","0.73645","-0.13737","0.00003"
"7.44800","0.73828","-0.12983","0.00003"
"7.46700","0.74013","-0.19154","0.00003"
"7.48600","0.74204","-0.16205","0.00003"
"7.50500","0.74397","-0.18169","0.00003"
"7.52400","0.74595","-0.13161","0.00003"
"7.54300","0.74791","-0.14820","0.00002"
"7.56200","0.74978","-0.13067","0.00002"
"7.58100","0.75160","-0.20931","0.00002"
"7.60000","0.75349","-0.15782","0.00003"
"7.61900","0.75543","-0.11738","0.00003"
"7.63800","0.75738","-0.14437","0.00003"
"7.65700","0.75932","-0.13996","0.00003"
"7.67600","0.76118","-0.13290","0.00003"
"7.69500","0.76305","-0.11775","0.00003"
"7.71400","0.76496","-0.11123","0.00003"
"7.73300","0.76690","-0.07843","0.00003"
"7.75200","0.76888","-0.04523","0.00003"
"7.77100","0.77084","-0.00060","0.00003"
"7.79000","0.77266","-0.03069","0.00003"
"7.80900","0.77447","-0.06914","0.00003"
"7.82800","0.77638","-0.08175","0.00003"
"7.84700","0.77833","-0.09236","0.00003"
"7.86600","0.78027","-0.13433","0.00003"
"7.88500","0.78218","-0.04636","0.00003"
"7.90400","0.78403","-0.10018","0.00003"
"7.92300","0.78585","-0.09977","0.00003"
"7.94200","0.78773","-0.17207","0.00003"
"7.96100","0.78964","-0.11763","0.00003"
"7.98000","0.79159","-0.16748","0.00003"
"7.99900","0.79354","-0.14796","0.00003"
"8.01800","0.79538","-0.13665","0.00003"
"8.03700","0.79715","-0.08133","0.00003"
"8.05600","0.79900","-0.05537","0.00003"
"8.07500","0.80091","-0.05838","0.00003"
"8.09400","0.80286","-0.08453","0.00003"
"8.11300","0.80483","-0.10966","0.00003"
"8.13200","0.80673","-0.14894","0.00003"
"8.15100","0.80858","-0.12844","0.00003"
"8.17000","0.81047","-0.14457","0.00003"
"8.18900","0.81239","-0.17785","0.00003"
"8.20800","0.81435","-0.20126","0.00003"
"8.22700","0.81633","-0.19559","0.00002"
"8.24600","0.81820","-0.11310","0.00002"
"8.26500","0.82002","-0.00025","0.00002"
"8.28400","0.82191","0.00780","0.00003"
"8.30300","0.82385","-0.01901","0.00003"
"8.32200","0.82581","-0.02464","0.00003"
"8.34100","0.82779","0.01034","0.00003"
"8.36000","0.82971","-0.00821","0.00003"
"8.37900","0.83157","-0.03164","0.00003"
"8.39800","0.83343","-0.08969","0.00003"
"8.41700","0.83533","-0.14354","0.00003"
"8.43600","0.83727","-0.19896","0.00002"
"8.45500","0.83921","-0.10329","0.00002"
"8.47400","0.84105","-0.06302","0.00002"
"8.49300","0.84285","-0.08486","0.00003"
"8.51200","0.84470","-0.09699","0.00003"
"8.53100","0.84659","-0.10179","0.00003"
"8.55000","0.84851","-0.09468","0.00003"
"8.56900","0.85046","-0.08966","0.00003"
"8.58800","0.85237","-0.10349","0.00003"
"8.60700","0.85420","-0.11636","0.00003"
"8.62600","0.85607","-0.07357","0.00003"
"8.64500","0.85797","-0.09376","0.00003"
"8.66400","0.85989","-0.14593","0.00003"
"8.68300","0.86185","-0.16390","0.00003"
"8.70200","0.86374","-0.16209","0.00003"
"8.72100","0.86559","-0.11353","0.00003"
"8.74000","0.86748","-0.18077","0.00003"
"8.75900","0.86938","-0.17243","0.00003"
"8.77800","0.87127","-0.11411","0.00003"
"8.79700","0.87323","-0.01705","0.00003"
"8.81600","0.87517","0.04049","0.00003"
"8.83500","0.87706","-0.09181","0.00003"
"8.85400","0.87894","-0.09221","0.00003"
"8.87300","0.88084","-0.08563","0.00003"
"8.89200","0.88277","-0.08650","0.00003"
"8.91100","0.88473","-0.12001","0.00003"
"8.93000","0.88664","-0.21669","0.00003"
"8.94900","0.88850","-0.11984","0.00003"
"8.96800","0.89041","-0.13993","0.00003"
"8.98700","0.89233","-0.12459","0.00003"
"9.00600","0.89425","-0.07187","0.00004"
"9.02500","0.89620","-0.06905","0.00004"
"9.04400","0.89811","-0.16421","0.00003"
"9.06300","0.89993","-0.14612","0.00003"
"9.08200","0.90177","-0.11206","0.00003"
"9.10100","0.90366","-0.07120","0.00003"
"9.12000","0.90557","-0.07681","0.00003"
"9.13900","0.90748","-0.12731","0.00003"
"9.15800","0.90935","-0.08078","0.00003"
"9.17700","0.91119","-0.06331","0.00003"
"9.19600","0.91306","-0.03313","0.00004"
"9.21500","0.91498","-0.08353","0.00004"
"9.23400","0.91688","-0.17931","0.00004"
"9.25300","0.91881","-0.16602","0.00004"
"9.27200","0.92072","-0.10936","0.00004"
"9.29100","0.92255","-0.04584","0.00003"
"9.31000","0.92441","-0.08497","0.00003"
"9.32900","0.92634","-0.11290","0.00003"
"9.34800","0.92831","-0.10007","0.00003"
"9.36700","0.93028","-0.14409","0.00003"
"9.38600","0.93218","-0.12528","0.00003"
"9.40500","0.93401","-0.07358","0.00004"
"9.42400","0.93590","-0.14668","0.00004"
"9.44300","0.93783","-0.09959","0.00004"
"9.46200","0.93975","-0.03215","0.00004"
"9.48100","0.94170","-0.04677","0.00004"
"9.50000","0.94364","-0.02129","0.00004"
"9.51900","0.94551","-0.01101","0.00004"
"9.53800","0.94737","-0.11770","0.00003"
"9.55700","0.94931","-0.13410","0.00003"
"9.57600","0.95127","-0.12263","0.00003"
"9.59500","0.95322","-0.17785","0.00004"
"9.61400","0.95512","-0.16752","0.00004"
"9.63300","0.95696","-0.13266","0.00004"
"9.65200","0.95880","-0.06821","0.00004"
"9.67100","0.96067","-0.06559","0.00004"
"9.69000","0.96257","0.02053","0.00004"
"9.70900","0.96452","0.02566","0.00004"
"9.72800","0.96643","-0.03876","0.00004"
"9.74700","0.96825","-0.09040","0.00004"
"9.76600","0.97007","-0.08222","0.00004"
"9.78500","0.97198","-0.10404","0.00004"
"9.80400","0.97392","-0.05810","0.00004"
"9.82300","0.97587","-0.03250","0.00004"
"9.84200","0.97776","-0.11365","0.00004"
"9.86100","0.97957","-0.03728","0.00004"
"9.88000","0.98141","-0.01892","0.00004"
"9.89900","0.98332","-0.10003","0.00004"
"9.91800","0.98525","-0.15802","0.00005"
"9.93700","0.98723","-0.16214","0.00004"
"9.95600","0.98920","-0.19810","0.00004"
"9.97500","0.99107","-0.14175","0.00004"
"9.99400","0.99290","-0.11128","0.00004"
"10.01300","0.99481","-0.02141","0.00004"
"10.03200","0.99674","-0.04275","0.00004"
"10.05100","0.99869","-0.07754","0.00004"
"10.07000","1.00059","-0.12506","0.00004"
"10.08900","1.00244","-0.17585","0.00004"
"10.10800","1.00431","-0.19446","0.00005"
"10.12700","1.00623","-0.12952","0.00005"
"10.14600","1.00818","-0.05108","0.00005"
"10.16500","1.01018","-0.11446","0.00004"
"10.18400","1.01213","-0.11792","0.00004"
"10.20300","1.01395","-0.07585","0.00004"
"10.22200","1.01577","-0.07556","0.00004"
"10.24100","1.01770","-0.07422","0.00004"
"10.26000","1.01965","-0.06260","0.00004"
"10.27900","1.02159","-0.11390","0.00004"
"10.29800","1.02350","-0.09530","0.00005"
"10.31700","1.02533","-0.09737","0.00005"
"10.33600","1.02715","-0.11767","0.00005"
"10.35500","1.02900","-0.13643","0.00005"
"10.37400","1.03090","-0.17255","0.00005"
"10.39300","1.03286","-0.17951","0.00004"
"10.41200","1.03481","-0.12211","0.00004"
"10.43100","1.03665","-0.09300","0.00004"
"10.45000","1.03845","-0.16109","0.00004"
"10.46900","1.04033","-0.14605","0.00004"
"10.48800","1.04225","-0.12545","0.00004"
"10.50700","1.04419","-0.09384","0.00005"
"10.52600","1.04614","-0.03834","0.00005"
"10.54500","1.04802","-0.00139","0.00005"
"10.56400","1.04987","0.01381","0.00005"
"10.58300","1.05177","-0.01435","0.00005"
"10.60200","1.05370","-0.13604","0.00005"
"10.62100","1.05568","-0.16287","0.00005"
"10.64000","1.05765","-0.17980","0.00004"
"10.65900","1.05951","-0.08881","0.00004"
"10.67800","1.06133","-0.10288","0.00004"
"10.69700","1.06323","-0.16299","0.00004"
"10.71600","1.06518","-0.07931","0.00005"
"10.73500","1.06714","-0.17475","0.00005"
"10.75400","1.06910","-0.17776","0.00005"
"10.77300","1.07100","-0.10275","0.00005"
"10.79200","1.07284","-0.12227","0.00005"
"10.81100","1.07471","-0.06295","0.00005"
"10.83000","1.07663","-0.09251","0.00005"
"10.84900","1.07858","-0.14240","0.00005"
"10.86800","1.08052","-0.19465","0.00004"
"10.88700","1.08235","-0.17930","0.00004"
"10.90600","1.08414","-0.15942","0.00004"
"10.92500","1.08600","-0.18936","0.00005"
"10.94400","1.08789","-0.15269","0.00005"
"10.96300","1.08981","-0.15740","0.00005"
"10.98200","1.09175","-0.22032","0.00005"
"11.00100","1.09364","-0.14682","0.00005"
"11.02000","1.09548","-0.11958","0.00005"
"11.03900","1.09737","-0.08493","0.00005"
"11.05800","1.09930","-0.05378","0.00005"
"11.07700","1.10124","-0.06140","0.00005"
"11.09600","1.10319","-0.05883","0.00005"
"11.11500","1.10507","-0.11297","0.00005"
"11.13400","1.10689","-0.14712","0.00005"
"11.15300","1.10878","-0.15671","0.00005"
"11.17200","1.11068","-0.16083","0.00005"
"11.19100","1.11259","-0.08656","0.00005"
"11.21000","1.11456","-0.10379","0.00005"
"11.22900","1.11649","-0.08273","0.00005"
"11.24800","1.11836","-0.12212","0.00005"
"11.26700","1.12023","-0.16444","0.00005"
"11.28600","1.12213","-0.16790","0.00005"
"11.30500","1.12408","-0.13646","0.00005"
"11.32400","1.12606","-0.12863","0.00005"
"11.34300","1.12796","-0.12605","0.00005"
"11.36200","1.12982","-0.08464","0.00005"
"11.38100","1.13173","-0.02777","0.00005"
"11.40000","1.13362","-0.06615","0.00005"
"11.41900","1.13550","-0.08407","0.00005"
"11.43800","1.13744","-0.14032","0.00005"
"11.45700","1.13936","-0.20055","0.00005"
"11.47600","1.14121","-0.07611","0.00005"
"11.49500","1.14309","-0.07741","0.00005"
"11.51400","1.14500","-0.02850","0.00005"
"11.53300","1.14692","-0.00351","0.00005"
"11.55200","1.14883","-0.12738","0.00005"
"11.57100","1.15070","-0.12795","0.00005"
"11.59000","1.15253","-0.08770","0.00005"
"11.60900","1.15441","-0.03621","0.00005"
"11.62800","1.15631","-0.03074","0.00006"
"11.64700","1.15821","-0.04361","0.00006"
"11.66600","1.16012","-0.08188","0.00006"
"11.68500","1.16198","-0.13368","0.00006"
"11.70400","1.16379","-0.11136","0.00005"
"11.72300","1.16565","-0.14517","0.00005"
"11.74200","1.16761","-0.15493","0.00005"
"11.76100","1.16958","-0.17543","0.00005"
"11.78000","1.17156","-0.24043","0.00005"
"11.79900","1.17345","-0.27673","0.00005"
"11.81800","1.17530","-0.19963","0.00005"
"11.83700","1.17719","-0.17158","0.00005"
"11.85600","1.17911","-0.08093","0.00006"
"11.87500","1.18102","-0.15323","0.00006"
"11.89400","1.18298","-0.17208","0.00006"
"11.91300","1.18493","-0.16754","0.00006"
"11.93200","1.18679","-0.08363","0.00005"
"11.95100","1.18867","-0.06303","0.00005"
"11.97000","1.19060","-0.09237","0.00005"
"11.98900","1.19256","-0.15912","0.00005"
"12.00800","1.19451","-0.18745","0.00005"
"12.02700","1.19640","-0.16540","0.00005"
"12.04600","1.19824","-0.14649","0.00005"
"12.06500","1.20010","-0.17941","0.00006"
"12.08400","1.20199","-0.20187","0.00006"
"12.10300","1.20389","-0.17739","0.00006"
"12.12200","1.20583","-0.10845","0.00006"
"12.14100","1.20772","-0.08094","0.00006"
"12.16000","1.20953","-0.13577","0.00005"
"12.17900","1.21136","-0.14893","0.00005"
"12.19800","1.21327","-0.21757","0.00005"
"12.21700","1.21520","-0.22491","0.00005"
"12.23600","1.21715","-0.13349","0.00005"
"12.25500","1.21904","-0.11443","0.00005"
"12.27400","1.22086","-0.17129","0.00006"
"12.29300","1.22272","-0.14588","0.00006"
"12.31200","1.22462","-0.12038","0.00006"
"12.33100","1.22656","-0.10763","0.00006"
"12.35000","1.22854","-0.14918","0.00006"
"12.36900","1.23050","-0.11913","0.00006"
"12.38800","1.23234","-0.15754","0.00005"
"12.40700","1.23419","-0.16374","0.00005"
"12.42600","1.23610","-0.11801","0.00005"
"12.44500","1.23805","-0.04757","0.00005"
"12.46400","1.24000","-0.10463","0.00005"
"12.48300","1.24191","-0.14471","0.00005"
"12.50200","1.24377","0.00257","0.00006"
"12.52100","1.24565","-0.05124","0.00006"
"12.54000","1.24758","-0.18554","0.00006"
"12.55900","1.24951","-0.20168","0.00006"
"12.57800","1.25150","-0.06997","0.00006"
"12.59700","1.25341","-0.00296","0.00006"
"12.61600","1.25522","-0.02901","0.00005"
"12.63500","1.25704","-0.05104","0.00005"
"12.65400","1.25897","-0.15684","0.00005"
"12.67300","1.26093","-0.18432","0.00005"
"12.69200","1.26288","-0.06417","0.00005"
"12.71100","1.26478","-0.10320","0.00006"
"12.73000","1.26661","-0.08683","0.00006"
"12.74900","1.26842","-0.10838","0.00006"
"12.76800","1.27029","-0.17638","0.00006"
"12.78700","1.27220","-0.14322","0.00006"
"12.80600","1.27416","-0.16757","0.00006"
"12.82500","1.27611","-0.14278","0.00006"
"12.84400","1.27795","-0.07311","0.00005"
"12.86300","1.27977","-0.03283","0.00005"
"12.88200","1.28165","-0.04796","0.00005"
"12.90100","1.28357","-0.03789","0.00005"
"12.92000","1.28552","-0.07521","0.00006"
"12.93900","1.28747","-0.11095","0.00006"
"12.95800","1.28935","-0.11612","0.00006"
"12.97700","1.29120","-0.13290","0.00006"
"12.99600","1.29310","-0.11299","0.00006"
"13.01500","1.29502","-0.12365","0.00006"
"13.03400","1.29699","-0.11110","0.00006"
"13.05300","1.29893","-0.10428","0.00006"
"13.07200","1.30077","-0.06894","0.00006"
"13.09100","1.30259","-0.05705","0.00005"
"13.11000","1.30452","-0.10151","0.00005"
"13.12900","1.30649","-0.16919","0.00006"
"13.14800","1.30846","-0.13479","0.00006"
"13.16700","1.31042","-0.09669","0.00006"
"13.18600","1.31229","-0.08465","0.00006"
"13.20500","1.31411","-0.09996","0.00006"
"13.22400","1.31596","-0.09174","0.00006"
"13.24300","1.31788","-0.12452","0.00006"
"13.26200","1.31986","-0.13646","0.00006"
"13.28100","1.32181","-0.12034","0.00005"
"13.30000","1.32366","-0.11565","0.00005"
"13.31900","1.32547","-0.14866","0.00005"
"13.33800","1.32734","-0.15925","0.00005"
"13.35700","1.32922","-0.19075","0.00006"
"13.37600","1.33113","-0.12598","0.00006"
"13.39500","1.33307","-0.07479","0.00006"
"13.41400","1.33495","-0.10164","0.00006"
"13.43300","1.33679","-0.20437","0.00006"
"13.45200","1.33867","-0.16975","0.00006"
"13.47100","1.34056","-0.11257","0.00006"
"13.49000","1.34249","-0.17321","0.00006"
"13.50900","1.34444","-0.15772","0.00005"
"13.52800","1.34632","-0.13589","0.00005"
"13.54700","1.34817","-0.12320","0.00005"
"13.56600","1.35008","-0.11570","0.00005"
"13.58500","1.35199","-0.03453","0.00006"
"13.60400","1.35390","-0.08101","0.00006"
"13.62300","1.35586","-0.17409","0.00006"
"13.64200","1.35777","-0.11884","0.00006"
"13.66100","1.35961","-0.08961","0.00006"
"13.68000","1.36148","-0.16837","0.00006"
"13.69900","1.36340","-0.05849","0.00006"
"13.71800","1.36537","-0.03651","0.00006"
"13.73700","1.36736","-0.06871","0.00006"
"13.75600","1.36927","-0.02018","0.00005"
"13.77500","1.37115","-0.06024","0.00006"
"13.79400","1.37307","-0.17077","0.00006"
"13.81300","1.37495","-0.16772","0.00006"
"13.83200","1.37683","-0.13080","0.00006"
"13.85100","1.37877","-0.13614","0.00006"
"13.87000","1.38068","-0.15692","0.00006"
"13.88900","1.38252","-0.12276","0.00006"
"13.90800","1.38439","-0.13519","0.00006"
"13.92700","1.38629","-0.16552","0.00006"
"13.94600","1.38820","-0.15554","0.00006"
"13.96500","1.39012","-0.15055","0.00006"
"13.98400","1.39198","-0.16082","0.00006"
"14.00300","1.39381","-0.27335","0.00006"
"14.02200","1.39570","-0.29546","0.00006"
"14.04100","1.39761","-0.21454","0.00006"
"14.06000","1.39951","-0.13261","0.00006"
"14.07900","1.40143","-0.13251","0.00006"
"14.09800","1.40329","-0.10347","0.00006"
"14.11700","1.40509","0.02111","0.00006"
"14.13600","1.40696","0.05487","0.00006"
"14.15500","1.40892","-0.00692","0.00006"
"14.17400","1.41091","-0.07988","0.00006"
"14.19300","1.41289","-0.01478","0.00006"
"14.21200","1.41478","-0.09413","0.00006"
"14.23100","1.41662","-0.01914","0.00006"
"14.25000","1.41851","-0.01833","0.00006"
"14.26900","1.42043","-0.12217","0.00006"
"14.28800","1.42235","-0.18921","0.00006"
"14.30700","1.42432","-0.22222","0.00006"
"14.32600","1.42626","-0.20781","0.00006"
"14.34500","1.42811","-0.09327","0.00006"
"14.36400","1.42998","-0.02966","0.00006"
"14.38300","1.43193","-0.06135","0.00006"
"14.40200","1.43388","-0.03498","0.00006"
"14.42100","1.43582","-0.06694","0.00006"
"14.44000","1.43770","-0.18159","0.00006"
"14.45900","1.43955","-0.16471","0.00006"
"14.47800","1.44142","-0.13245","0.00006"
"14.49700","1.44329","-0.12682","0.00006"
"14.51600","1.44518","-0.06669","0.00006"
"14.53500","1.44712","-0.11976","0.00006"
"14.55400","1.44900","-0.13592","0.00006"
"14.57300","1.45081","-0.10327","0.00006"
"14.59200","1.45266","-0.10811","0.00006"
"14.61100","1.45459","-0.18011","0.00006"
"14.63000","1.45654","-0.12101","0.00006"
"14.64900","1.45849","-0.12421","0.00006"
"14.66800","1.46038","-0.15078","0.00006"
"14.68700","1.46218","-0.08991","0.00006"
"14.70600","1.46402","-0.06627","0.00006"
"14.72500","1.46591","-0.12640","0.00007"
"14.74400","1.46786","-0.13258","0.00007"
"14.76300","1.46986","-0.13698","0.00007"
"14.78200","1.47180","-0.07440","0.00007"
"14.80100","1.47363","-0.07332","0.00007"
"14.82000","1.47546","-0.17037","0.00006"
"14.83900","1.47736","-0.28918","0.00006"
"14.85800","1.47931","-0.30097","0.00006"
"14.87700","1.48127","-0.25512","0.00006"
"14.89600","1.48318","-0.20643","0.00007"
"14.91500","1.48505","-0.10991","0.00007"
"14.93400","1.48695","-0.13126","-0.00005"
"14.95300","1.48887","-0.13198","-0.00035"
"14.97200","1.49083","-0.00856","-0.00072"
"14.99100","1.49283","-0.06087","-0.00101"
"15.01000","1.49474","-0.19240","-0.00112"
"15.02900","1.49654","-0.15892","-0.00114"
"15.04800","1.49839","-0.18614","-0.00113"
"15.06700","1.50034","-0.02130","-0.00112"
"15.08600","1.50230","-0.06177","-0.00112"
"15.10500","1.50425","-0.06920","-0.00112"
"15.12400","1.50614","-0.08338","-0.00111"
"15.14300","1.50795","-0.03314","-0.00111"
"15.16200","1.50975","-0.22060","-0.00111"
"15.18100","1.51161","-0.07714","-0.00112"
"15.20000","1.51352","-0.13989","-0.00112"
"15.21900","1.51549","-0.19048","-0.00111"
"15.23800","1.51741","-0.20108","-0.00111"
"15.25700","1.51923","-0.37885","-0.00111"
"15.27600","1.52105","-0.06686","-0.00112"
"15.29500","1.52294","-0.04687","-0.00112"
"15.31400","1.52485","-0.09287","-0.00112"
"15.33300","1.52680","0.01721","-0.00112"
"15.35200","1.52873","-0.11446","-0.00112"
"15.37100","1.53060","-0.02116","-0.00112"
"15.39000","1.53245","-0.16524","-0.00111"
"15.40900","1.53436","-0.13872","-0.00111"
"15.42800","1.53630","-0.08833","-0.00112"
"15.44700","1.53829","-0.10512","-0.00112"
"15.46600","1.54024","-0.08789","-0.00112"
"15.48500","1.54207","-0.11041","-0.00112"
"15.50400","1.54389","-0.20703","-0.00112"
"15.52300","1.54581","-0.25266","-0.00112"
"15.54200","1.54778","-0.11041","-0.00112"
"15.56100","1.54975","-0.02305","-0.00112"
"15.58000","1.55171","-0.07500","-0.00112"
"15.59900","1.55359","-0.08611","-0.00112"
"15.61800","1.55542","-0.07518","-0.00112"
"15.63700","1.55730","-0.10138","-0.00111"
"15.65600","1.55923","-0.09342","-0.00112"
"15.67500","1.56120","-0.06068","-0.00112"
"15.69400","1.56313","-0.23912","-0.00112"
"15.71300","1.56496","-0.13528","-0.00112"
"15.73200","1.56677","-0.12512","-0.00112"
"15.75100","1.56864","-0.02879","-0.00112"
"15.77000","1.57052","-0.01466","-0.00112"
"15.78900","1.57243","-0.13431","-0.00112"
"15.80800","1.57436","-0.02233","-0.00112"
"15.82700","1.57623","-0.08708","-0.00111"
"15.84600","1.57807","-0.18740","-0.00111"
"15.86500","1.57995","-0.19177","-0.00111"
"15.88400","1.58185","-0.17891","-0.00112"
"15.90300","1.58378","-0.22151","-0.00112"
"15.92200","1.58571","-0.16714","-0.00112"
"15.94100","1.58759","-0.19106","-0.00112"
"15.96000","1.58946","-0.14006","-0.00113"
"15.97900","1.59140","-0.13358","-0.00113"
"15.99800","1.59332","-0.12198","-0.00112"
"16.01700","1.59524","-0.10748","-0.00112"
"16.03600","1.59718","-0.10748","-0.00112"
"16.05500","1.59906","-0.13137","-0.00112"
"16.07400","1.60091","-0.19501","-0.00112"
"16.09300","1.60278","-0.18653","-0.00112"
"16.11200","1.60470","-0.15079","-0.00112"
"16.13100","1.60667","-0.10397","-0.00113"
"16.15000","1.60863","-0.13511","-0.00113"
"16.16900","1.61050","-0.04855","-0.00113"
"16.18800","1.61236","-0.03465","-0.00113"
"16.20700","1.61427","-0.11043","-0.00113"
"16.22600","1.61616","-0.18197","-0.00113"
"16.24500","1.61808","-0.14131","-0.00112"
"16.26400","1.62004","-0.18058","-0.00112"
"16.28300","1.62194","-0.15622","-0.00112"
"16.30200","1.62378","-0.09954","-0.00112"
"16.32100","1.62566","-0.09175","-0.00112"
"16.34000","1.62756","-0.11348","-0.00112"
"16.35900","1.62945","-0.15197","-0.00113"
"16.37800","1.63136","-0.15899","-0.00113"
"16.39700","1.63323","-0.10566","-0.00113"
"16.41600","1.63509","-0.08431","-0.00113"
"16.43500","1.63701","-0.02846","-0.00113"
"16.45400","1.63892","-0.01082","-0.00113"
"16.47300","1.64083","-0.05440","-0.00112"
"16.49200","1.64275","-0.10037","-0.00112"
"16.51100","1.64459","-0.09939","-0.00112"
"16.53000","1.64639","-0.13818","-0.00112"
"16.54900","1.64827","-0.11195","-0.00112"
"16.56800","1.65023","-0.09410","-0.00113"
"16.58700","1.65222","-0.07556","-0.00113"
"16.60600","1.65419","-0.10261","-0.00113"
"16.62500","1.65606","-0.10021","-0.00113"
"16.64400","1.65789","-0.09663","-0.00113"
"16.66300","1.65979","-0.07203","-0.00113"
"16.68200","1.66171","-0.09003","-0.00113"
"16.70100","1.66364","-0.12286","-0.00113"
"16.72000","1.66561","-0.10312","-0.00113"
"16.73900","1.66754","-0.08728","-0.00112"
"16.75800","1.66939","-0.13839","-0.00113"
"16.77700","1.67127","-0.20306","-0.00113"
"16.79600","1.67320","-0.25927","-0.00113"
"16.81500","1.67515","-0.18614","-0.00114"
"16.83400","1.67710","-0.11976","-0.00114"
"16.85300","1.67900","-0.11219","-0.00114"
"16.87200","1.68086","-0.14380","-0.00114"
"16.89100","1.68273","-0.03161","-0.00113"
"16.91000","1.68460","0.00297","-0.00113"
"16.92900","1.68650","-0.11911","-0.00113"
"16.94800","1.68843","-0.13886","-0.00113"
"16.96700","1.69029","-0.18835","-0.00113"
"16.98600","1.69209","-0.17892","-0.00113"
"17.00500","1.69395","-0.13224","-0.00114"
"17.02400","1.69589","-0.15678","-0.00114"
"17.04300","1.69786","-0.11120","-0.00114"
"17.06200","1.69981","-0.12274","-0.00114"
"17.08100","1.70168","-0.09511","-0.00114"
"17.10000","1.70349","-0.11600","-0.00114"
"17.11900","1.70534","-0.19411","-0.00114"
"17.13800","1.70724","-0.18737","-0.00114"
"17.15700","1.70918","-0.18222","-0.00114"
"17.17600","1.71117","-0.09004","-0.00114"
"17.19500","1.71310","-0.11405","-0.00114"
"17.21400","1.71493","-0.10937","-0.00114"
"17.23300","1.71678","-0.07888","-0.00115"
"17.25200","1.71870","-0.07700","-0.00115"
"17.27100","1.72066","-0.16703","-0.00115"
"17.29000","1.72262","-0.17321","-0.00115"
"17.30900","1.72453","-0.10323","-0.00115"
"17.32800","1.72638","-0.07562","-0.00115"
"17.34700","1.72828","-0.11836","-0.00115"
"17.36600","1.73020","-0.07892","-0.00115"
"17.38500","1.73216","-0.08318","-0.00115"
"17.40400","1.73414","-0.13289","-0.00115"
"17.42300","1.73602","-0.14839","-0.00115"
"17.44200","1.73781","-0.10621","-0.00115"
"17.46100","1.73967","-0.10023","-0.00116"
"17.48000","1.74161","-0.09274","-0.00116"
"17.49900","1.74356","-0.04559","-0.00116"
"17.51800","1.74551","-0.09225","-0.00116"
"17.53700","1.74739","-0.13105","-0.00116"
"17.55600","1.74920","-0.11299","-0.00116"
"17.57500","1.75103","-0.10727","-0.00116"
"17.59400","1.75290","-0.07004","-0.00115"
"17.61300","1.75482","-0.04007","-0.00115"
"17.63200","1.75678","-0.06318","-0.00116"
"17.65100","1.75870","-0.18840","-0.00116"
"17.67000","1.76051","-0.22668","-0.00116"
"17.68900","1.76233","-0.20426","-0.00117"
"17.70800","1.76423","-0.13680","-0.00117"
"17.72700","1.76616","-0.07893","-0.00117"
"17.74600","1.76812","-0.14613","-0.00117"
"17.76500","1.77006","-0.14400","-0.00117"
"17.78400","1.77192","-0.12712","-0.00116"
"17.80300","1.77377","-0.12546","-0.00116"
"17.82200","1.77567","-0.11500","-0.00116"
"17.84100","1.77761","-0.04987","-0.00116"
"17.86000","1.77959","-0.00071","-0.00116"
"17.87900","1.78152","0.01457","-0.00117"
"17.89800","1.78335","-0.08639","-0.00117"
"17.91700","1.78518","-0.11776","-0.00117"
"17.93600","1.78711","-0.10232","-0.00117"
"17.95500","1.78907","-0.07925","-0.00117"
"17.97400","1.79104","-0.07432","-0.00117"
"17.99300","1.79299","-0.15707","-0.00117"
"18.01200","1.79485","-0.16842","-0.00117"
"18.03100","1.79667","-0.21331","-0.00117"
"18.05000","1.79854","-0.17777","-0.00117"
"18.06900","1.80047","-0.12257","-0.00117"
"18.08800","1.80243","-0.13779","-0.00117"
"18.10700","1.80436","-0.09237","-0.00117"
"18.12600","1.80619","-0.11838","-0.00118"
"18.14500","1.80802","-0.08433","-0.00118"
"18.16400","1.80991","-0.07762","-0.00118"
"18.18300","1.81182","-0.06606","-0.00118"
"18.20200","1.81375","-0.03420","-0.00118"
"18.22100","1.81568","-0.02583","-0.00117"
"18.24000","1.81753","-0.04905","-0.00117"
"18.25900","1.81937","-0.09424","-0.00117"
"18.27800","1.82126","-0.14460","-0.00117"
"18.29700","1.82318","-0.18957","-0.00117"
"18.31600","1.82513","-0.15539","-0.00117"
"18.33500","1.82706","-0.05128","-0.00118"
"18.35400","1.82892","-0.01963","-0.00118"
"18.37300","1.83078","-0.05028","-0.00118"
"18.39200","1.83270","-0.09587","-0.00118"
"18.41100","1.83460","-0.11116","-0.00118"
"18.43000","1.83652","-0.11189","-0.00118"
"18.44900","1.83847","-0.11976","-0.00118"
"18.46800","1.84036","-0.08395","-0.00117"
"18.48700","1.84221","-0.01231","-0.00117"
"18.50600","1.84409","-0.01447","-0.00117"
"18.52500","1.84600","-0.10025","-0.00118"
"18.54400","1.84797","-0.16728","-0.00118"
"18.56300","1.84992","-0.13078","-0.00118"
"18.58200","1.85180","-0.14659","-0.00118"
"18.60100","1.85368","-0.07550","-0.00119"
"18.62000","1.85561","-0.09799","-0.00119"
"18.63900","1.85752","-0.10609","-0.00118"
"18.65800","1.85946","-0.06954","-0.00118"
"18.67700","1.86141","-0.00803","-0.00118"
"18.69600","1.86328","-0.02273","-0.00118"
"18.71500","1.86510","-0.09353","-0.00118"
"18.73400","1.86698","-0.15833","-0.00118"
"18.75300","1.86888","-0.10045","-0.00118"
"18.77200","1.87079","-0.15642","-0.00118"
"18.79100","1.87269","-0.18986","-0.00118"
"18.81000","1.87454","-0.17762","-0.00119"
"18.82900","1.87640","-0.16778","-0.00119"
"18.84800","1.87832","-0.17799","-0.00119"
"18.86700","1.88023","-0.16010","-0.00119"
"18.88600","1.88214","-0.18002","-0.00118"
"18.90500","1.88406","-0.23277","-0.00118"
"18.92400","1.88590","-0.14932","-0.00118"
"18.94300","1.88770","-0.04760","-0.00118"
"18.96200","1.88958","-0.04721","-0.00118"
"18.98100","1.89154","-0.18793","-0.00118"
"19.00000","1.89353","-0.13930","-0.00119"
"19.01900","1.89548","-0.05085","-0.00119"
"19.03800","1.89734","-0.07662","-0.00119"
"19.05700","1.89918","-0.09314","-0.00119"
"19.07600","1.90110","-0.10355","-0.00119"
"19.09500","1.90303","-0.08755","-0.00119"
"19.11400","1.90497","-0.14081","-0.00118"
"19.13300","1.90694","-0.06837","-0.00118"
"19.15200","1.90885","-0.04082","-0.00118"
"19.17100","1.91069","-0.08802","-0.00118"
"19.19000","1.91258","-0.11591","-0.00118"
"19.20900","1.91452","-0.18503","-0.00119"
"19.22800","1.91646","-0.08379","-0.00119"
"19.24700","1.91840","-0.07931","-0.00119"
"19.26600","1.92029","-0.13669","-0.00119"
"19.28500","1.92216","-0.21565","-0.00119"
"19.30400","1.92403","-0.19401","-0.00119"
"19.32300","1.92590","-0.06746","-0.00119"
"19.34200","1.92779","-0.15581","-0.00118"
"19.36100","1.92972","-0.18148","-0.00118"
"19.38000","1.93157","-0.13822","-0.00118"
"19.39900","1.93337","-0.12878","-0.00118"
"19.41800","1.93523","-0.16109","-0.00119"
"19.43700","1.93718","-0.19384","-0.00119"
"19.45600","1.93914","-0.19703","-0.00119"
"19.47500","1.94108","-0.19851","-0.00119"
"19.49400","1.94293","-0.18789","-0.00119"
"19.51300","1.94473","-0.18276","-0.00119"
"19.53200","1.94661","-0.20822","-0.00119"
"19.55100","1.94853","-0.16471","-0.00119"
"19.57000","1.95049","-0.10600","-0.00119"
"19.58900","1.95248","-0.07599","-0.00118"
"19.60800","1.95440","-0.12446","-0.00118"
"19.62700","1.95622","-0.16538","-0.00119"
"19.64600","1.95808","-0.10242","-0.00119"
"19.66500","1.96001","-0.09521","-0.00119"
"19.68400","1.96197","-0.13744","-0.00119"
"19.70300","1.96393","-0.14346","-0.00120"
"19.72200","1.96582","-0.20422","-0.00120"
"19.74100","1.96768","-0.10527","-0.00119"
"19.76000","1.96957","-0.05991","-0.00119"
"19.77900","1.97149","-0.14372","-0.00119"
"19.79800","1.97344","-0.13656","-0.00119"
"19.81700","1.97541","-0.14443","-0.00119"
"19.83600","1.97727","-0.11685","-0.00119"
"19.85500","1.97906","-0.05842","-0.00119"
"19.87400","1.98093","-0.09092","-0.00119"
"19.89300","1.98289","-0.10873","-0.00120"
"19.91200","1.98484","-0.05941","-0.00120"
"19.93100","1.98678","-0.07043","-0.00120"
"19.95000","1.98866","-0.17801","-0.00120"
"19.96900","1.99047","-0.19785","-0.00119"
"19.98800","1.99231","-0.20048","-0.00119"
"20.00700","1.99419","-0.14616","-0.00119"
"20.02600","1.99612","-0.05291","-0.00119"
"20.04500","1.99810","-0.00135","-0.00119"
"20.06400","2.00000","-0.03419","-0.00119"
"20.08300","2.00181","-0.09520","-0.00119"
"20.10200","2.00363","-0.10048","-0.00119"
"20.12100","2.00553","-0.10768","-0.00120"
"20.14000","2.00746","-0.11576","-0.00120"
"20.15900","2.00944","-0.11983","-0.00120"
"20.17800","2.01137","-0.08255","-0.00120"
"20.19700","2.01323","-0.04884","-0.00119"
"20.21600","2.01509","-0.04056","-0.00119"
"20.23500","2.01698","-0.08279","-0.00119"
"20.25400","2.01891","-0.14784","-0.00119"
"20.27300","2.02089","-0.18044","-0.00119"
"20.29200","2.02281","-0.19505","-0.00119"
"20.31100","2.02463","-0.10358","-0.00119"
"20.33000","2.02649","-0.12165","-0.00120"
"20.34900","2.02843","-0.08512","-0.00120"
"20.36800","2.03038","-0.08401","-0.00120"
"20.38700","2.03234","-0.04676","-0.00120"
"20.40600","2.03429","-0.01522","-0.00120"
"20.42500","2.03616","-0.08372","-0.00119"
"20.44400","2.03802","-0.16882","-0.00119"
"20.46300","2.03991","-0.17322","-0.00119"
"20.48200","2.04184","-0.11167","-0.00119"
"20.50100","2.04380","-0.07837","-0.00119"
"20.52000","2.04570","-0.08834","-0.00119"
"20.53900","2.04750","-0.12015","-0.00120"
"20.55800","2.04932","-0.14680","-0.00120"
"20.57700","2.05120","-0.19490","-0.00120"
"20.59600","2.05309","-0.14117","-0.00120"
"20.61500","2.05504","-0.18205","-0.00120"
"20.63400","2.05697","-0.18122","-0.00120"
"20.65300","2.05883","-0.13879","-0.00119"
"20.67200","2.06068","-0.17203","-0.00119"
"20.69100","2.06257","-0.19509","-0.00119"
"20.71000","2.06447","-0.20322","-0.00119"
"20.72900","2.06641","-0.13769","-0.00119"
"20.74800","2.06833","-0.08631","-0.00120"
"20.76700","2.07019","-0.02222","-0.00120"
"20.78600","2.07207","-0.10913","-0.00120"
"20.80500","2.07399","-0.13334","-0.00120"
"20.82400","2.07588","-0.01036","-0.00120"
"20.84300","2.07781","0.04865","-0.00120"
"20.86200","2.07976","0.02472","-0.00120"
"20.88100","2.08166","-0.03403","-0.00120"
"20.90000","2.08353","-0.07899","-0.00119"
"20.91900","2.08542","-0.08489","-0.00119"
"20.93800","2.08734","-0.01861","-0.00119"
"20.95700","2.08932","-0.09194","-0.00120"
"20.97600","2.09126","-0.12773","-0.00120"
"20.99500","2.09313","-0.10027","-0.00120"
"21.01400","2.09502","-0.18150","-0.00120"
"21.03300","2.09694","-0.20425","-0.00120"
"21.05200","2.09884","-0.17730","-0.00120"
"21.07100","2.10078","-0.15155","-0.00120"
"21.09000","2.10272","-0.17112","-0.00120"
"21.10900","2.10457","-0.12356","-0.00120"
"21.12800","2.10639","-0.09699","-0.00119"
"21.14700","2.10828","-0.18885","-0.00120"
"21.16600","2.11018","-0.11225","-0.00120"
"21.18500","2.11209","-0.05184","-0.00120"
"21.20400","2.11399","-0.05515","-0.00120"
"21.22300","2.11583","-0.03532","-0.00120"
"21.24200","2.11769","-0.11380","-0.00121"
"21.26100","2.11959","-0.12668","-0.00121"
"21.28000","2.12150","-0.15359","-0.00120"
"21.29900","2.12342","-0.13978","-0.00120"
"21.31800","2.12536","-0.03653","-0.00120"
"21.33700","2.12721","-0.04512","-0.00120"
"21.35600","2.12903","-0.05551","-0.00120"
"21.37500","2.13093","-0.11873","-0.00120"
"21.39400","2.13289","-0.10323","-0.00120"
"21.41300","2.13486","-0.15845","-0.00120"
"21.43200","2.13680","-0.12399","-0.00120"
"21.45100","2.13865","-0.10572","-0.00121"
"21.47000","2.14050","-0.10263","-0.00121"
"21.48900","2.14242","-0.09910","-0.00121"
"21.50800","2.14435","-0.08085","-0.00121"
"21.52700","2.14629","-0.09560","-0.00120"
"21.54600","2.14824","-0.15603","-0.00120"
"21.56500","2.15013","-0.15983","-0.00120"
"21.58400","2.15196","-0.13030","-0.00120"
"21.60300","2.15385","-0.08762","-0.00120"
"21.62200","2.15580","-0.14692","-0.00120"
"21.64100","2.15776","-0.16941","-0.00120"
"21.66000","2.15969","-0.14417","-0.00121"
"21.67900","2.16157","-0.21257","-0.00121"
"21.69800","2.16342","-0.18853","-0.00121"
"21.71700","2.16530","-0.11636","-0.00121"
"21.73600","2.16718","-0.15838","-0.00121"
"21.75500","2.16910","-0.09640","-0.00120"
"21.77400","2.17103","-0.10598","-0.00120"
"21.77500","2.17113","-0.10818","-0.00120"