File: archive/undergrad/433/Cantilever/Specimen_RawData_3.csv
Time,Extension,Load,Strain Gage18
(s),(mm),(N),(mm/mm)
"0.00000","0.00000","-0.05626","0.00000"
"0.50000","0.08980","-0.04689","0.00000"
"1.00000","0.18989","-0.00060","0.00000"
"1.50000","0.28972","0.02266","0.00000"
"2.00000","0.38987","0.06799","0.00000"
"2.50000","0.48986","-0.05098","0.00000"
"3.00000","0.58975","0.03261","0.00000"
"3.50000","0.68981","0.01079","0.00000"
"4.00000","0.78989","0.04108","0.00000"
"4.50000","0.88972","0.13642","0.00000"
"5.00000","0.98988","0.16431","-0.00001"
"5.50000","1.08981","0.13884","-0.00001"
"6.00000","1.18971","0.09328","-0.00001"
"6.50000","1.28994","0.05405","-0.00001"
"7.00000","1.38983","0.16690","-0.00001"
"7.50000","1.48969","0.15100","-0.00001"
"8.00000","1.58993","0.18470","-0.00001"
"8.50000","1.68980","0.24731","-0.00001"
"9.00000","1.78975","0.18958","-0.00001"
"9.50000","1.88991","0.16294","-0.00001"
"10.00000","1.98982","0.30192","-0.00001"
"10.50000","2.08969","0.36959","-0.00002"
"11.00000","2.18991","0.26269","-0.00002"
"11.50000","2.28979","0.29803","-0.00002"
"12.00000","2.38973","0.38726","-0.00002"
"12.50000","2.48995","0.41062","-0.00002"
"13.00000","2.58977","0.38702","-0.00002"
"13.50000","2.68978","0.36499","-0.00002"
"14.00000","2.78994","0.35110","-0.00002"
"14.50000","2.88975","0.35529","-0.00002"
"15.00000","2.98979","0.44945","-0.00002"
"15.50000","3.08992","0.45257","-0.00002"
"16.00000","3.18975","0.39447","-0.00003"
"16.50000","3.28978","0.53214","-0.00003"
"17.00000","3.38996","0.53589","-0.00003"
"17.50000","3.48973","0.47495","-0.00003"
"18.00000","3.58978","0.47512","-0.00003"
"18.50000","3.68998","0.50522","-0.00003"
"19.00000","3.78974","0.59804","-0.00003"
"19.50000","3.88980","0.52148","-0.00003"
"20.00000","3.98995","0.54221","-0.00003"
"20.50000","4.08973","0.48580","-0.00003"
"21.00000","4.18980","0.66555","-0.00003"
"21.50000","4.28992","0.54982","-0.00004"
"22.00000","4.38974","0.63247","-0.00004"
"22.50000","4.48983","0.73389","-0.00004"
"23.00000","4.58990","0.63218","-0.00004"
"23.50000","4.68964","0.74822","-0.00004"
"24.00000","4.78984","0.66965","-0.00004"
"24.50000","4.88992","0.69110","-0.00004"
"25.00000","4.98973","0.76845","-0.00004"
"25.50000","5.08983","0.67377","-0.00004"
"26.00000","5.18988","0.74479","-0.00004"
"26.50000","5.28970","0.80826","-0.00005"
"27.00000","5.38986","0.83808","-0.00005"
"27.50000","5.48985","0.86217","-0.00005"
"28.00000","5.58971","0.80447","-0.00005"
"28.50000","5.68987","1.02335","-0.00005"
"29.00000","5.78987","0.85431","-0.00005"
"29.50000","5.88970","0.84860","-0.00005"
"30.00000","5.98991","0.87009","-0.00005"
"30.50000","6.08978","0.93372","-0.00005"
"31.00000","6.18972","1.02137","-0.00005"
"31.50000","6.28981","0.88816","-0.00005"
"32.00000","6.38982","0.99725","-0.00006"
"32.50000","6.48970","1.05320","-0.00006"
"33.00000","6.58993","0.97540","-0.00006"
"33.50000","6.68975","1.04309","-0.00006"
"34.00000","6.78976","1.09561","-0.00006"
"34.50000","6.88993","1.13687","-0.00006"
"35.00000","6.98977","1.11975","-0.00006"
"35.50000","7.08976","1.07805","-0.00006"
"36.00000","7.18994","1.20914","-0.00006"
"36.50000","7.28975","1.08291","-0.00006"
"37.00000","7.38974","1.25876","-0.00006"
"37.50000","7.48991","1.13783","-0.00007"
"38.00000","7.58975","1.21350","-0.00007"
"38.50000","7.68972","1.14563","-0.00007"
"39.00000","7.79001","1.17242","-0.00007"
"39.50000","7.88972","1.30042","-0.00007"
"40.00000","7.98981","1.24571","-0.00007"
"40.50000","8.08995","1.31379","-0.00007"
"41.00000","8.18975","1.20342","-0.00007"
"41.50000","8.28978","1.31599","-0.00007"
"42.00000","8.38994","1.33186","-0.00007"
"42.50000","8.48975","1.28131","-0.00008"
"43.00000","8.58982","1.36566","-0.00008"
"43.50000","8.68994","1.26231","-0.00008"
"44.00000","8.78973","1.31424","-0.00008"
"44.50000","8.88981","1.28443","-0.00008"
"45.00000","8.98994","1.48267","-0.00008"
"45.50000","9.08972","1.23161","-0.00008"
"46.00000","9.18986","1.36236","-0.00008"
"46.50000","9.28991","1.41192","-0.00008"
"47.00000","9.38977","1.34341","-0.00008"
"47.50000","9.48979","1.44294","-0.00008"
"48.00000","9.58991","1.50591","-0.00009"
"48.50000","9.68972","1.46023","-0.00009"
"49.00000","9.78987","1.41964","-0.00009"
"49.50000","9.88983","1.47808","-0.00009"
"50.00000","9.98974","1.54908","-0.00009"
"50.50000","10.08985","1.54264","-0.00009"
"51.00000","10.18988","1.50077","-0.00009"
"51.50000","10.28967","1.55685","-0.00009"
"52.00000","10.38987","1.58192","-0.00009"
"52.50000","10.48979","1.55010","-0.00009"
"53.00000","10.58971","1.62446","-0.00009"
"53.50000","10.68993","1.67327","-0.00010"
"54.00000","10.78978","1.67750","-0.00010"
"54.50000","10.88974","1.84751","-0.00010"
"55.00000","10.98996","1.73142","-0.00010"
"55.50000","11.08976","1.80390","-0.00010"
"56.00000","11.18976","1.77591","-0.00010"
"56.50000","11.28994","1.69795","-0.00010"
"57.00000","11.38979","1.84339","-0.00010"
"57.50000","11.48975","1.73655","-0.00010"
"58.00000","11.58993","1.87432","-0.00010"
"58.50000","11.68974","1.84808","-0.00011"
"59.00000","11.78972","1.81532","-0.00011"
"59.50000","11.88996","1.89217","-0.00011"
"60.00000","11.98976","1.82511","-0.00011"
"60.50000","12.08978","1.87759","-0.00011"
"61.00000","12.18995","1.93020","-0.00011"
"61.50000","12.28977","1.84097","-0.00011"
"62.00000","12.38980","1.95501","-0.00011"
"62.50000","12.48997","1.92423","-0.00011"
"63.00000","12.58972","1.94409","-0.00011"
"63.50000","12.68977","2.08850","-0.00011"
"64.00000","12.78996","1.99385","-0.00012"
"64.50000","12.88974","2.05292","-0.00012"
"65.00000","12.98979","2.04981","-0.00012"
"65.50000","13.08997","2.11187","-0.00012"
"66.00000","13.18972","2.05500","-0.00012"
"66.50000","13.28983","2.13781","-0.00012"
"67.00000","13.38993","2.05308","-0.00012"
"67.50000","13.48975","2.04434","-0.00012"
"68.00000","13.58979","2.15701","-0.00012"
"68.50000","13.68992","2.19751","-0.00012"
"69.00000","13.78973","2.07318","-0.00012"
"69.50000","13.88985","2.19955","-0.00013"
"70.00000","13.98988","2.22520","-0.00013"
"70.50000","14.08975","2.27644","-0.00013"
"71.00000","14.18983","2.22360","-0.00013"
"71.50000","14.28989","2.18952","-0.00013"
"72.00000","14.38973","2.18338","-0.00013"
"72.50000","14.48985","2.22560","-0.00013"
"73.00000","14.58983","2.26587","-0.00013"
"73.50000","14.68971","2.33375","-0.00013"
"74.00000","14.78988","2.37452","-0.00013"
"74.50000","14.88982","2.25150","-0.00013"
"75.00000","14.98970","2.36176","-0.00014"
"75.50000","15.08992","2.32896","-0.00014"
"76.00000","15.18980","2.46738","-0.00014"
"76.50000","15.28971","2.30863","-0.00014"
"77.00000","15.38994","2.49171","-0.00014"
"77.50000","15.48982","2.43563","-0.00014"
"78.00000","15.58971","2.53768","-0.00014"
"78.50000","15.68989","2.46129","-0.00014"
"79.00000","15.78976","2.50088","-0.00014"
"79.50000","15.88973","2.48296","-0.00014"
"80.00000","15.98996","2.64433","-0.00014"
"80.50000","16.08972","2.64202","-0.00015"
"81.00000","16.18978","2.56706","-0.00015"
"81.50000","16.28994","2.63598","-0.00015"
"82.00000","16.38975","2.55987","-0.00015"
"82.50000","16.48978","2.58312","-0.00015"
"83.00000","16.58997","2.64904","-0.00015"
"83.50000","16.68974","2.64753","-0.00015"
"84.00000","16.78976","2.61096","-0.00015"
"84.50000","16.88997","2.75740","-0.00015"
"85.00000","16.98975","2.68403","-0.00015"
"85.50000","17.08977","2.83147","-0.00016"
"86.00000","17.18999","2.80411","-0.00016"
"86.50000","17.28972","2.84537","-0.00016"
"87.00000","17.38978","2.74146","-0.00016"
"87.50000","17.48995","2.76575","-0.00016"
"88.00000","17.58975","2.94933","-0.00016"
"88.50000","17.68977","2.76646","-0.00016"
"89.00000","17.78993","2.95302","-0.00016"
"89.50000","17.88975","2.83546","-0.00016"
"90.00000","17.98984","2.89891","-0.00016"
"90.50000","18.08991","2.79091","-0.00017"
"91.00000","18.18973","2.92732","-0.00017"
"91.50000","18.28981","2.82788","-0.00017"
"92.00000","18.38991","2.95678","-0.00017"
"92.50000","18.48976","2.98799","-0.00017"
"93.00000","18.58985","2.89894","-0.00017"
"93.50000","18.68987","2.87656","-0.00017"
"94.00000","18.78972","3.10409","-0.00017"
"94.50000","18.88984","2.96816","-0.00017"
"95.00000","18.98983","3.05620","-0.00017"
"95.50000","19.08972","3.09170","-0.00017"
"96.00000","19.18989","3.00277","-0.00018"
"96.50000","19.28979","3.07761","-0.00018"
"97.00000","19.38977","3.06623","-0.00018"
"97.50000","19.48987","3.11540","-0.00018"
"98.00000","19.58986","3.15032","-0.00018"
"98.50000","19.68972","3.29053","-0.00018"
"99.00000","19.78988","3.24880","-0.00018"
"99.50000","19.88976","3.19541","-0.00018"
"100.00000","19.98971","3.26050","-0.00018"
"100.50000","20.08994","3.27098","-0.00018"
"101.00000","20.18976","2.99325","-0.00019"
"101.50000","20.28973","3.09211","-0.00019"
"102.00000","20.38998","3.25234","-0.00019"
"102.50000","20.48973","3.38250","-0.00019"
"103.00000","20.58976","3.32279","-0.00019"
"103.50000","20.68999","3.39000","-0.00019"
"104.00000","20.78979","3.40147","-0.00019"
"104.50000","20.88968","3.39322","-0.00019"
"105.00000","20.98998","3.39225","-0.00019"
"105.50000","21.08973","3.43236","-0.00019"
"106.00000","21.18976","3.36780","-0.00019"
"106.50000","21.28999","3.44548","-0.00020"
"107.00000","21.38972","3.51306","-0.00020"
"107.50000","21.48979","3.42691","-0.00020"
"108.00000","21.58994","3.61410","-0.00020"
"108.50000","21.68975","3.59384","-0.00020"
"109.00000","21.78978","3.50968","-0.00020"
"109.50000","21.88994","3.59649","-0.00020"
"110.00000","21.98975","3.66317","-0.00020"
"110.50000","22.08979","3.67297","-0.00020"
"111.00000","22.18997","3.70484","-0.00020"
"111.50000","22.28974","3.61773","-0.00020"
"112.00000","22.38978","3.62921","-0.00021"
"112.50000","22.48992","3.72792","-0.00021"
"113.00000","22.58975","3.60252","-0.00021"
"113.50000","22.68985","3.70716","-0.00021"
"114.00000","22.78989","3.63525","-0.00021"
"114.50000","22.88974","3.69928","-0.00021"
"115.00000","22.98981","3.79407","-0.00021"
"115.50000","23.08989","3.75514","-0.00021"
"116.00000","23.18971","3.79828","-0.00021"
"116.50000","23.28988","3.79198","-0.00021"
"117.00000","23.38985","3.82392","-0.00021"
"117.50000","23.48975","3.84034","-0.00022"
"118.00000","23.58985","3.81794","-0.00022"
"118.50000","23.68985","3.83899","-0.00022"
"119.00000","23.78975","3.89082","-0.00022"
"119.50000","23.88990","3.82723","-0.00022"
"120.00000","23.98980","3.99699","-0.00022"
"120.50000","24.08972","4.00337","-0.00022"
"121.00000","24.18994","3.96274","-0.00022"
"121.50000","24.28980","3.89099","-0.00022"
"122.00000","24.38970","3.99470","-0.00022"
"122.50000","24.48996","3.97792","-0.00022"
"123.00000","24.58976","3.94896","-0.00023"
"123.50000","24.68972","4.14921","-0.00023"
"124.00000","24.78997","4.06237","-0.00023"
"124.50000","24.88979","4.08357","-0.00023"
"125.00000","24.98969","4.11855","-0.00023"
"125.50000","25.08996","4.07741","-0.00023"
"126.00000","25.18975","4.09236","-0.00023"
"126.50000","25.28972","4.07702","-0.00023"
"127.00000","25.38997","4.17017","-0.00023"
"127.50000","25.48976","4.16252","-0.00023"
"128.00000","25.58975","4.15964","-0.00023"
"128.50000","25.68996","4.16275","-0.00024"
"129.00000","25.78977","4.22534","-0.00024"
"129.50000","25.88976","4.18767","-0.00024"
"130.00000","25.98996","4.25838","-0.00024"
"130.50000","26.08976","4.35256","-0.00024"
"131.00000","26.18977","4.32081","-0.00024"
"131.50000","26.28994","4.34025","-0.00024"
"132.00000","26.38974","4.25096","-0.00024"
"132.50000","26.48979","4.26619","-0.00024"
"133.00000","26.58993","4.46244","-0.00024"
"133.50000","26.68975","4.42572","-0.00024"
"134.00000","26.78982","4.37127","-0.00025"
"134.50000","26.88992","4.40838","-0.00025"
"135.00000","26.98971","4.51329","-0.00025"
"135.50000","27.08981","4.47755","-0.00025"
"136.00000","27.18984","4.40191","-0.00025"
"136.50000","27.28975","4.58387","-0.00025"
"137.00000","27.38984","4.49434","-0.00025"
"137.50000","27.48988","4.58560","-0.00025"
"138.00000","27.58974","4.62331","-0.00025"
"138.50000","27.68987","4.50537","-0.00025"
"139.00000","27.78984","4.64667","-0.00025"
"139.50000","27.88972","4.65900","-0.00026"
"140.00000","27.98988","4.64905","-0.00026"
"140.50000","28.08984","4.69793","-0.00026"
"141.00000","28.18968","4.69285","-0.00026"
"141.50000","28.28992","4.71437","-0.00026"
"142.00000","28.38976","4.70266","-0.00026"
"142.50000","28.48972","4.72849","-0.00026"
"143.00000","28.58987","4.65764","-0.00026"
"143.50000","28.68984","4.67125","-0.00026"
"144.00000","28.78966","4.73806","-0.00026"
"144.50000","28.88994","4.74334","-0.00027"
"145.00000","28.98981","4.68302","-0.00027"
"145.50000","29.08970","4.79792","-0.00027"
"146.00000","29.18993","4.85793","-0.00027"
"146.50000","29.28977","4.77499","-0.00027"
"147.00000","29.38970","4.80761","-0.00027"
"147.50000","29.49003","4.84329","-0.00027"
"148.00000","29.58971","4.87837","-0.00027"
"148.50000","29.68975","4.81344","-0.00027"
"149.00000","29.78995","4.84161","-0.00027"
"149.50000","29.88976","4.85916","-0.00027"
"150.00000","29.98977","4.81952","-0.00028"
"150.50000","30.08997","4.92795","-0.00028"
"150.98400","30.18654","4.95907","-0.00028"