File: archive/undergrad/433/Cantilever/Specimen_RawData_11.csv
Time,Extension,Load,Strain Gage18
(s),(mm),(N),(mm/mm)
"0.00000","0.00000","-0.09613","0.00000"
"0.50000","0.08973","-0.08641","0.00000"
"1.00000","0.18981","-0.04431","0.00000"
"1.50000","0.28964","-0.05929","0.00000"
"2.00000","0.38979","-0.08806","0.00000"
"2.50000","0.48977","0.07006","0.00000"
"3.00000","0.58966","0.04283","0.00000"
"3.50000","0.68973","0.02742","0.00000"
"4.00000","0.78981","0.00210","0.00001"
"4.50000","0.88964","0.00093","0.00001"
"5.00000","0.98980","0.14295","0.00001"
"5.50000","1.08972","-0.03171","0.00001"
"6.00000","1.18964","0.13828","0.00001"
"6.50000","1.28985","0.20683","0.00001"
"7.00000","1.38975","0.13566","0.00001"
"7.50000","1.48962","0.10279","0.00002"
"8.00000","1.58984","0.12735","0.00002"
"8.50000","1.68973","0.10282","0.00002"
"9.00000","1.78965","0.25237","0.00002"
"9.50000","1.88983","0.31838","0.00002"
"10.00000","1.98973","0.18997","0.00002"
"10.50000","2.08959","0.17474","0.00002"
"11.00000","2.18984","0.22382","0.00002"
"11.50000","2.28970","0.23917","0.00002"
"12.00000","2.38964","0.40820","0.00003"
"12.50000","2.48986","0.19286","0.00003"
"13.00000","2.58970","0.39842","0.00003"
"13.50000","2.68969","0.28873","0.00003"
"14.00000","2.78986","0.32842","0.00003"
"14.50000","2.88966","0.43739","0.00003"
"15.00000","2.98969","0.40079","0.00003"
"15.50000","3.08984","0.37447","0.00003"
"16.00000","3.18965","0.36425","0.00004"
"16.50000","3.28969","0.44077","0.00004"
"17.00000","3.38987","0.42835","0.00004"
"17.50000","3.48965","0.41894","0.00004"
"18.00000","3.58970","0.46047","0.00004"
"18.50000","3.68990","0.55168","0.00004"
"19.00000","3.78965","0.54654","0.00004"
"19.50000","3.88972","0.52846","0.00004"
"20.00000","3.98986","0.50327","0.00005"
"20.50000","4.08965","0.53456","0.00005"
"21.00000","4.18973","0.55337","0.00005"
"21.50000","4.28983","0.53360","0.00005"
"22.00000","4.38964","0.57376","0.00005"
"22.50000","4.48977","0.57195","0.00005"
"23.00000","4.58980","0.57297","0.00005"
"23.50000","4.68958","0.63864","0.00005"
"24.00000","4.78976","0.72362","0.00006"
"24.50000","4.88982","0.71425","0.00006"
"25.00000","4.98964","0.70422","0.00006"
"25.50000","5.08976","0.60281","0.00006"
"26.00000","5.18980","0.72942","0.00006"
"26.50000","5.28960","0.76767","0.00006"
"27.00000","5.38979","0.75999","0.00006"
"27.50000","5.48978","0.83792","0.00007"
"28.00000","5.58963","0.89928","0.00007"
"28.50000","5.68979","0.79116","0.00007"
"29.00000","5.78978","0.80203","0.00007"
"29.50000","5.88961","0.89086","0.00007"
"30.00000","5.98982","0.91167","0.00007"
"30.50000","6.08969","0.90541","0.00007"
"31.00000","6.18964","0.92146","0.00007"
"31.50000","6.28974","0.96721","0.00008"
"32.00000","6.38973","1.08364","0.00008"
"32.50000","6.48962","1.03060","0.00008"
"33.00000","6.58987","1.05998","0.00008"
"33.50000","6.68968","0.91284","0.00008"
"34.00000","6.78968","1.02972","0.00008"
"34.50000","6.88983","1.04760","0.00008"
"35.00000","6.98969","1.14206","0.00008"
"35.50000","7.08967","1.18052","0.00009"
"36.00000","7.18986","1.10363","0.00009"
"36.50000","7.28967","1.13208","0.00009"
"37.00000","7.38964","1.16526","0.00009"
"37.50000","7.48983","1.16361","0.00009"
"38.00000","7.58968","1.30688","0.00009"
"38.50000","7.68964","1.22230","0.00009"
"39.00000","7.78993","1.20885","0.00009"
"39.50000","7.88966","1.10037","0.00009"
"40.00000","7.98972","1.22116","0.00010"
"40.50000","8.08986","1.33892","0.00010"
"41.00000","8.18965","1.19159","0.00010"
"41.50000","8.28969","1.39476","0.00010"
"42.00000","8.38986","1.37191","0.00010"
"42.50000","8.48966","1.42171","0.00010"
"43.00000","8.58974","1.33066","0.00010"
"43.50000","8.68984","1.30155","0.00011"
"44.00000","8.78963","1.37013","0.00011"
"44.50000","8.88974","1.37530","0.00011"
"45.00000","8.98985","1.38377","0.00011"
"45.50000","9.08962","1.32408","0.00011"
"46.00000","9.18981","1.45569","0.00011"
"46.50000","9.28981","1.31678","0.00011"
"47.00000","9.38967","1.37811","0.00011"
"47.50000","9.48972","1.42970","0.00012"
"48.00000","9.58982","1.41928","0.00012"
"48.50000","9.68962","1.39509","0.00012"
"49.00000","9.78979","1.43330","0.00012"
"49.50000","9.88975","1.55806","0.00012"
"50.00000","9.98967","1.48176","0.00012"
"50.50000","10.08977","1.52658","0.00012"
"51.00000","10.18979","1.53313","0.00012"
"51.50000","10.28959","1.66797","0.00013"
"52.00000","10.38980","1.65482","0.00013"
"52.50000","10.48973","1.67360","0.00013"
"53.00000","10.58963","1.52175","0.00013"
"53.50000","10.68985","1.63642","0.00013"
"54.00000","10.78971","1.89536","0.00013"
"54.50000","10.88965","1.77310","0.00013"
"55.00000","10.98987","1.86831","0.00013"
"55.50000","11.08968","1.83923","0.00014"
"56.00000","11.18968","1.84349","0.00014"
"56.50000","11.28985","1.85852","0.00014"
"57.00000","11.38971","1.84474","0.00014"
"57.50000","11.48963","1.82053","0.00014"
"58.00000","11.58985","1.77762","0.00014"
"58.50000","11.68967","1.82958","0.00014"
"59.00000","11.78964","1.79037","0.00015"
"59.50000","11.88990","1.94826","0.00015"
"60.00000","11.98969","1.88275","0.00015"
"60.50000","12.08972","1.89313","0.00015"
"61.00000","12.18985","1.87682","0.00015"
"61.50000","12.28968","1.89922","0.00015"
"62.00000","12.38971","2.00147","0.00015"
"62.50000","12.48988","2.03971","0.00015"
"63.00000","12.58964","2.07437","0.00015"
"63.50000","12.68971","2.04915","0.00016"
"64.00000","12.78987","1.95698","0.00016"
"64.50000","12.88964","2.02243","0.00016"
"65.00000","12.98971","1.98460","0.00016"
"65.50000","13.08989","2.04004","0.00016"
"66.00000","13.18965","2.10829","0.00016"
"66.50000","13.28974","2.08968","0.00016"
"67.00000","13.38983","2.22545","0.00016"
"67.50000","13.48966","2.04354","0.00017"
"68.00000","13.58972","2.06331","0.00017"
"68.50000","13.68983","2.08522","0.00017"
"69.00000","13.78967","2.18669","0.00017"
"69.50000","13.88978","2.15987","0.00017"
"70.00000","13.98979","2.15537","0.00017"
"70.50000","14.08967","2.21967","0.00017"
"71.00000","14.18974","2.28644","0.00017"
"71.50000","14.28981","2.20835","0.00018"
"72.00000","14.38964","2.29380","0.00018"
"72.50000","14.48977","2.28220","0.00018"
"73.00000","14.58976","2.20518","0.00018"
"73.50000","14.68963","2.33549","0.00018"
"74.00000","14.78981","2.34489","0.00018"
"74.50000","14.88974","2.34564","0.00018"
"75.00000","14.98961","2.38721","0.00019"
"75.50000","15.08985","2.40839","0.00019"
"76.00000","15.18973","2.36083","0.00019"
"76.50000","15.28963","2.35432","0.00019"
"77.00000","15.38984","2.35705","0.00019"
"77.50000","15.48972","2.47373","0.00019"
"78.00000","15.58962","2.53638","0.00019"
"78.50000","15.68984","2.47864","0.00019"
"79.00000","15.78968","2.58525","0.00020"
"79.50000","15.88965","2.46567","0.00020"
"80.00000","15.98988","2.46133","0.00020"
"80.50000","16.08961","2.70222","0.00020"
"81.00000","16.18970","2.59520","0.00020"
"81.50000","16.28986","2.68237","0.00020"
"82.00000","16.38966","2.75319","0.00020"
"82.50000","16.48969","2.72082","0.00020"
"83.00000","16.58987","2.68867","0.00021"
"83.50000","16.68967","2.65488","0.00021"
"84.00000","16.78967","2.78259","0.00021"
"84.50000","16.88989","2.71960","0.00021"
"85.00000","16.98966","2.76171","0.00021"
"85.50000","17.08970","2.79391","0.00021"
"86.00000","17.18991","2.77069","0.00021"
"86.50000","17.28965","2.70904","0.00021"
"87.00000","17.38970","2.86461","0.00022"
"87.50000","17.48987","2.81381","0.00022"
"88.00000","17.58967","2.81364","0.00022"
"88.50000","17.68967","2.86380","0.00022"
"89.00000","17.78987","2.88276","0.00022"
"89.50000","17.88966","2.92803","0.00022"
"90.00000","17.98975","2.93265","0.00022"
"90.50000","18.08983","2.85437","0.00023"
"91.00000","18.18965","2.85706","0.00023"
"91.50000","18.28972","2.94898","0.00023"
"92.00000","18.38982","2.94311","0.00023"
"92.50000","18.48968","3.03137","0.00023"
"93.00000","18.58982","3.08826","0.00023"
"93.50000","18.68977","2.98679","0.00023"
"94.00000","18.78966","3.05341","0.00023"
"94.50000","18.88976","2.99688","0.00023"
"95.00000","18.98976","3.07009","0.00024"
"95.50000","19.08962","3.10233","0.00024"
"96.00000","19.18983","3.10052","0.00024"
"96.50000","19.28971","3.19313","0.00024"
"97.00000","19.38968","3.07124","0.00024"
"97.50000","19.48979","3.11239","0.00024"
"98.00000","19.58978","3.05400","0.00024"
"98.50000","19.68965","3.14588","0.00024"
"99.00000","19.78981","3.20651","0.00025"
"99.50000","19.88967","3.29192","0.00025"
"100.00000","19.98964","3.16320","0.00025"
"100.50000","20.08984","3.25986","0.00025"
"101.00000","20.18971","3.37213","0.00025"
"101.50000","20.28965","3.32322","0.00025"
"102.00000","20.38990","3.30962","0.00025"
"102.50000","20.48964","3.35949","0.00026"
"103.00000","20.58968","3.42874","0.00026"
"103.50000","20.68989","3.33598","0.00026"
"104.00000","20.78969","3.38973","0.00026"
"104.50000","20.88960","3.48611","0.00026"
"105.00000","20.98992","3.41591","0.00026"
"105.50000","21.08965","3.44785","0.00026"
"106.00000","21.18968","3.43688","0.00026"
"106.50000","21.28991","3.50389","0.00027"
"107.00000","21.38966","3.51895","0.00027"
"107.50000","21.48969","3.59605","0.00027"
"108.00000","21.58986","3.43987","0.00027"
"108.50000","21.68967","3.51173","0.00027"
"109.00000","21.78970","3.44958","0.00027"
"109.50000","21.88985","3.59914","0.00027"
"110.00000","21.98967","3.56482","0.00027"
"110.50000","22.08974","3.60234","0.00028"
"111.00000","22.18988","3.65230","0.00028"
"111.50000","22.28966","3.56567","0.00028"
"112.00000","22.38970","3.64013","0.00028"
"112.50000","22.48983","3.71508","0.00028"
"113.00000","22.58966","3.74540","0.00028"
"113.50000","22.68977","3.80349","0.00028"
"114.00000","22.78979","3.75809","0.00029"
"114.50000","22.88966","3.67859","0.00029"
"115.00000","22.98973","3.66509","0.00029"
"115.50000","23.08981","3.85191","0.00029"
"116.00000","23.18964","3.86611","0.00029"
"116.50000","23.28979","3.83900","0.00029"
"117.00000","23.38976","3.86446","0.00029"
"117.50000","23.48966","3.84460","0.00029"
"118.00000","23.58976","3.86074","0.00030"
"118.50000","23.68978","3.90062","0.00030"
"119.00000","23.78966","3.81934","0.00030"
"119.50000","23.88982","3.84250","0.00030"
"120.00000","23.98969","3.93116","0.00030"
"120.50000","24.08962","3.92911","0.00030"
"121.00000","24.18985","3.84679","0.00030"
"121.50000","24.28973","3.85824","0.00030"
"122.00000","24.38962","3.87459","0.00031"
"122.50000","24.48986","3.84359","0.00031"
"123.00000","24.58969","3.89888","0.00031"
"123.50000","24.68965","3.99199","0.00031"
"124.00000","24.78988","3.98486","0.00031"
"124.50000","24.88972","4.07023","0.00031"
"125.00000","24.98960","4.02162","0.00031"
"125.50000","25.08988","4.02733","0.00031"
"126.00000","25.18968","4.09683","0.00032"
"126.50000","25.28964","4.17380","0.00032"
"127.00000","25.38988","4.14991","0.00032"
"127.50000","25.48967","4.18297","0.00032"
"128.00000","25.58967","4.22479","0.00032"
"128.50000","25.68987","4.25641","0.00032"
"129.00000","25.78968","4.35027","0.00032"
"129.50000","25.88969","4.33610","0.00032"
"130.00000","25.98988","4.31851","0.00033"
"130.50000","26.08967","4.38551","0.00033"
"131.00000","26.18969","4.23544","0.00033"
"131.50000","26.28986","4.23741","0.00033"
"132.00000","26.38967","4.36045","0.00033"
"132.50000","26.48969","4.35124","0.00033"
"133.00000","26.58985","4.29798","0.00033"
"133.50000","26.68967","4.34445","0.00033"
"134.00000","26.78975","4.37426","0.00034"
"134.50000","26.88983","4.38245","0.00034"
"135.00000","26.98965","4.38396","0.00034"
"135.50000","27.08973","4.52227","0.00034"
"136.00000","27.18979","4.48296","0.00034"
"136.50000","27.28967","4.46512","0.00034"
"137.00000","27.38977","4.57624","0.00034"
"137.50000","27.48978","4.43959","0.00035"
"138.00000","27.58967","4.55967","0.00035"
"138.50000","27.68977","4.43122","0.00035"
"139.00000","27.78978","4.50430","0.00035"
"139.50000","27.88965","4.52939","0.00035"
"140.00000","27.98979","4.60486","0.00035"
"140.50000","28.08973","4.60930","0.00035"
"141.00000","28.18962","4.64898","0.00035"
"141.50000","28.28983","4.81347","0.00036"
"142.00000","28.38971","4.60757","0.00036"
"142.50000","28.48964","4.58737","0.00036"
"143.00000","28.58980","4.62162","0.00036"
"143.50000","28.68974","4.71303","0.00036"
"144.00000","28.78956","4.69781","0.00036"
"144.50000","28.88986","4.76110","0.00036"
"145.00000","28.98973","4.80155","0.00036"
"145.50000","29.08962","4.79144","0.00037"
"146.00000","29.18982","4.72782","0.00037"
"146.50000","29.28966","4.84395","0.00037"
"147.00000","29.38963","4.79005","0.00037"
"147.50000","29.48990","4.69241","0.00037"
"148.00000","29.58964","4.85867","0.00037"
"148.50000","29.68968","4.94955","0.00037"
"149.00000","29.78984","4.92398","0.00037"
"149.50000","29.88970","4.92403","0.00038"
"150.00000","29.98965","4.78587","0.00038"
"150.50000","30.08989","4.93982","0.00038"
"151.00000","30.18965","4.90468","0.00038"
"151.02900","30.19550","4.97103","0.00038"