File: archive/undergrad/433/Cantilever/Specimen_RawData_13.csv
Time,Extension,Load,Strain Gage18
(s),(mm),(N),(mm/mm)
"0.00000","0.00000","-0.00081","0.00000"
"0.50000","0.08986","0.04252","0.00000"
"1.00000","0.18996","0.06740","0.00000"
"1.50000","0.28979","0.03186","0.00000"
"2.00000","0.38992","0.01510","0.00000"
"2.50000","0.48992","-0.05246","0.00000"
"3.00000","0.58981","-0.03253","0.00000"
"3.50000","0.68988","0.02359","0.00000"
"4.00000","0.78995","0.04672","0.00000"
"4.50000","0.88977","0.01915","0.00000"
"5.00000","0.98995","0.06211","0.00001"
"5.50000","1.08987","0.09483","0.00001"
"6.00000","1.18978","0.08083","0.00001"
"6.50000","1.29000","0.05239","0.00001"
"7.00000","1.38989","0.15376","0.00001"
"7.50000","1.48976","0.06707","0.00002"
"8.00000","1.58998","0.13292","0.00002"
"8.50000","1.68986","0.13145","0.00002"
"9.00000","1.78980","0.11721","0.00002"
"9.50000","1.88996","0.28187","0.00002"
"10.00000","1.98987","0.18968","0.00002"
"10.50000","2.08975","0.29809","0.00003"
"11.00000","2.18999","0.32163","0.00003"
"11.50000","2.28985","0.27306","0.00003"
"12.00000","2.38980","0.24446","0.00003"
"12.50000","2.49001","0.23019","0.00003"
"13.00000","2.58984","0.42715","0.00004"
"13.50000","2.68983","0.28537","0.00004"
"14.00000","2.79001","0.33379","0.00004"
"14.50000","2.88982","0.31250","0.00004"
"15.00000","2.98984","0.38108","0.00004"
"15.50000","3.09002","0.38260","0.00004"
"16.00000","3.18981","0.49104","0.00005"
"16.50000","3.28981","0.44354","0.00005"
"17.00000","3.39001","0.45070","0.00005"
"17.50000","3.48979","0.55570","0.00005"
"18.00000","3.58983","0.39474","0.00005"
"18.50000","3.69004","0.58493","0.00006"
"19.00000","3.78980","0.50227","0.00006"
"19.50000","3.88988","0.52405","0.00006"
"20.00000","3.99001","0.55496","0.00006"
"20.50000","4.08980","0.63776","0.00006"
"21.00000","4.18986","0.53293","0.00006"
"21.50000","4.28998","0.73755","0.00007"
"22.00000","4.38981","0.58580","0.00007"
"22.50000","4.48989","0.52300","0.00007"
"23.00000","4.58995","0.64558","0.00007"
"23.50000","4.68972","0.59763","0.00007"
"24.00000","4.78989","0.70972","0.00008"
"24.50000","4.88997","0.60110","0.00008"
"25.00000","4.98978","0.68437","0.00008"
"25.50000","5.08989","0.64948","0.00008"
"26.00000","5.18995","0.80186","0.00008"
"26.50000","5.28976","0.76224","0.00008"
"27.00000","5.38992","0.73764","0.00009"
"27.50000","5.48993","0.73990","0.00009"
"28.00000","5.58976","0.76361","0.00009"
"28.50000","5.68994","0.80569","0.00009"
"29.00000","5.78990","0.90046","0.00009"
"29.50000","5.88976","0.84060","0.00010"
"30.00000","5.98997","0.86610","0.00010"
"30.50000","6.08983","0.90982","0.00010"
"31.00000","6.18978","0.89307","0.00010"
"31.50000","6.28988","0.92775","0.00010"
"32.00000","6.38987","0.92058","0.00010"
"32.50000","6.48976","1.00217","0.00011"
"33.00000","6.58999","1.06323","0.00011"
"33.50000","6.68982","1.00618","0.00011"
"34.00000","6.78981","1.13518","0.00011"
"34.50000","6.88999","1.11675","0.00011"
"35.00000","6.98983","1.04693","0.00012"
"35.50000","7.08981","1.12480","0.00012"
"36.00000","7.19000","1.08841","0.00012"
"36.50000","7.28982","1.05096","0.00012"
"37.00000","7.38980","1.19419","0.00012"
"37.50000","7.48996","1.19174","0.00013"
"38.00000","7.58982","1.13804","0.00013"
"38.50000","7.68979","1.18615","0.00013"
"39.00000","7.79006","1.18318","0.00013"
"39.50000","7.88980","1.30286","0.00013"
"40.00000","7.98986","1.23787","0.00014"
"40.50000","8.09002","1.22674","0.00014"
"41.00000","8.18980","1.29902","0.00014"
"41.50000","8.28984","1.30348","0.00014"
"42.00000","8.39000","1.29152","0.00014"
"42.50000","8.48980","1.28378","0.00015"
"43.00000","8.58990","1.33096","0.00015"
"43.50000","8.68997","1.33681","0.00015"
"44.00000","8.78979","1.41312","0.00015"
"44.50000","8.88986","1.28702","0.00015"
"45.00000","8.99000","1.42292","0.00015"
"45.50000","9.08979","1.30609","0.00016"
"46.00000","9.18991","1.34407","0.00016"
"46.50000","9.28996","1.35727","0.00016"
"47.00000","9.38981","1.44579","0.00016"
"47.50000","9.48984","1.45421","0.00016"
"48.00000","9.58995","1.40197","0.00017"
"48.50000","9.68978","1.43071","0.00017"
"49.00000","9.78995","1.47955","0.00017"
"49.50000","9.88990","1.49122","0.00017"
"50.00000","9.98981","1.48601","0.00017"
"50.50000","10.08991","1.47108","0.00017"
"51.00000","10.18994","1.66687","0.00018"
"51.50000","10.28973","1.56981","0.00018"
"52.00000","10.38994","1.65701","0.00018"
"52.50000","10.48987","1.64477","0.00018"
"53.00000","10.58979","1.57218","0.00018"
"53.50000","10.68999","1.70391","0.00019"
"54.00000","10.78988","1.72928","0.00019"
"54.50000","10.88980","1.79298","0.00019"
"55.00000","10.99002","1.77412","0.00019"
"55.50000","11.08982","1.70052","0.00019"
"56.00000","11.18982","1.80923","0.00019"
"56.50000","11.28999","1.81865","0.00020"
"57.00000","11.38983","1.86920","0.00020"
"57.50000","11.48977","1.79269","0.00020"
"58.00000","11.58997","1.81634","0.00020"
"58.50000","11.68981","1.83992","0.00020"
"59.00000","11.78979","1.86770","0.00021"
"59.50000","11.89003","1.93098","0.00021"
"60.00000","11.98983","1.93159","0.00021"
"60.50000","12.08983","2.03312","0.00021"
"61.00000","12.18999","1.90784","0.00021"
"61.50000","12.28984","1.94243","0.00021"
"62.00000","12.38986","2.01181","0.00022"
"62.50000","12.49005","1.98969","0.00022"
"63.00000","12.58978","2.06747","0.00022"
"63.50000","12.68985","2.03805","0.00022"
"64.00000","12.79003","2.09540","0.00022"
"64.50000","12.88978","1.97143","0.00023"
"65.00000","12.98986","2.08115","0.00023"
"65.50000","13.09003","2.09501","0.00023"
"66.00000","13.18979","2.00760","0.00023"
"66.50000","13.28989","2.07841","0.00023"
"67.00000","13.38997","2.15888","0.00023"
"67.50000","13.48981","2.09754","0.00023"
"68.00000","13.58987","2.03824","0.00024"
"68.50000","13.68997","2.11116","0.00024"
"69.00000","13.78979","2.22014","0.00024"
"69.50000","13.88990","2.26029","0.00024"
"70.00000","13.98993","2.17479","0.00025"
"70.50000","14.08982","2.15131","0.00025"
"71.00000","14.18988","2.29482","0.00025"
"71.50000","14.28994","2.13687","0.00026"
"72.00000","14.38977","2.23509","0.00026"
"72.50000","14.48991","2.17331","0.00026"
"73.00000","14.58991","2.21955","0.00026"
"73.50000","14.68976","2.36825","0.00026"
"74.00000","14.78995","2.28927","0.00027"
"74.50000","14.88987","2.38670","0.00027"
"75.00000","14.98975","2.43884","0.00027"
"75.50000","15.08998","2.41290","0.00027"
"76.00000","15.18988","2.40258","0.00027"
"76.50000","15.28977","2.36991","0.00028"
"77.00000","15.38998","2.41232","0.00028"
"77.50000","15.48991","2.47460","0.00028"
"78.00000","15.58977","2.58456","0.00028"
"78.50000","15.68996","2.54525","0.00028"
"79.00000","15.78981","2.64376","0.00028"
"79.50000","15.88978","2.46715","0.00029"
"80.00000","15.99003","2.56740","0.00029"
"80.50000","16.08978","2.59334","0.00029"
"81.00000","16.18985","2.67707","0.00029"
"81.50000","16.28999","2.68482","0.00029"
"82.00000","16.38981","2.77943","0.00029"
"82.50000","16.48984","2.65305","0.00030"
"83.00000","16.59002","2.67805","0.00030"
"83.50000","16.68980","2.73264","0.00030"
"84.00000","16.78981","2.75571","0.00030"
"84.50000","16.89003","2.68124","0.00030"
"85.00000","16.98980","2.80729","0.00031"
"85.50000","17.08983","2.76928","0.00031"
"86.00000","17.19005","2.87140","0.00031"
"86.50000","17.28979","2.80161","0.00031"
"87.00000","17.38985","2.83459","0.00031"
"87.50000","17.49002","2.83560","0.00032"
"88.00000","17.58981","2.93403","0.00032"
"88.50000","17.68982","2.97133","0.00032"
"89.00000","17.79001","2.82353","0.00032"
"89.50000","17.88982","2.94735","0.00032"
"90.00000","17.98989","2.98111","0.00032"
"90.50000","18.08998","2.97734","0.00033"
"91.00000","18.18978","3.01358","0.00033"
"91.50000","18.28988","2.92932","0.00033"
"92.00000","18.38998","3.04639","0.00033"
"92.50000","18.48983","2.99854","0.00033"
"93.00000","18.58992","3.02075","0.00034"
"93.50000","18.68993","2.99506","0.00034"
"94.00000","18.78981","3.09222","0.00034"
"94.50000","18.88991","3.01750","0.00034"
"95.00000","18.98987","3.06244","0.00035"
"95.50000","19.08977","3.08801","0.00035"
"96.00000","19.18996","3.03805","0.00035"
"96.50000","19.28985","3.10971","0.00035"
"97.00000","19.38981","3.17028","0.00035"
"97.50000","19.48992","3.20999","0.00035"
"98.00000","19.58991","3.26903","0.00036"
"98.50000","19.68979","3.12381","0.00036"
"99.00000","19.78997","3.16428","0.00036"
"99.50000","19.88980","3.17835","0.00036"
"100.00000","19.98979","3.22734","0.00036"
"100.50000","20.09000","3.28531","0.00037"
"101.00000","20.18983","3.28187","0.00037"
"101.50000","20.28981","3.30742","0.00037"
"102.00000","20.39003","3.28492","0.00037"
"102.50000","20.48977","3.30421","0.00037"
"103.00000","20.58982","3.37320","0.00038"
"103.50000","20.69004","3.35451","0.00038"
"104.00000","20.78985","3.48121","0.00038"
"104.50000","20.88975","3.45142","0.00038"
"105.00000","20.99004","3.45002","0.00038"
"105.50000","21.08979","3.46229","0.00038"
"106.00000","21.18983","3.44861","0.00039"
"106.50000","21.29006","3.50960","0.00039"
"107.00000","21.38980","3.51555","0.00039"
"107.50000","21.48985","3.48414","0.00039"
"108.00000","21.59001","3.51160","0.00039"
"108.50000","21.68980","3.61511","0.00039"
"109.00000","21.78984","3.47286","0.00040"
"109.50000","21.89001","3.57313","0.00040"
"110.00000","21.98982","3.64883","0.00040"
"110.50000","22.08986","3.60146","0.00040"
"111.00000","22.19002","3.58074","0.00040"
"111.50000","22.28981","3.62882","0.00040"
"112.00000","22.38985","3.64406","0.00041"
"112.50000","22.48997","3.72378","0.00041"
"113.00000","22.58980","3.68795","0.00041"
"113.50000","22.68991","3.66609","0.00041"
"114.00000","22.78994","3.82431","0.00042"
"114.50000","22.88980","3.76410","0.00042"
"115.00000","22.98989","3.79000","0.00042"
"115.50000","23.08997","3.82360","0.00042"
"116.00000","23.18978","3.80082","0.00042"
"116.50000","23.28995","3.74547","0.00042"
"117.00000","23.38990","3.79834","0.00043"
"117.50000","23.48980","3.83088","0.00043"
"118.00000","23.58991","3.85280","0.00043"
"118.50000","23.68990","3.84067","0.00043"
"119.00000","23.78981","3.92360","0.00043"
"119.50000","23.88995","3.91387","0.00043"
"120.00000","23.98983","3.87141","0.00044"
"120.50000","24.08977","3.90462","0.00044"
"121.00000","24.19000","3.89197","0.00044"
"121.50000","24.28986","3.88416","0.00044"
"122.00000","24.38976","3.99570","0.00044"
"122.50000","24.49001","3.94265","0.00044"
"123.00000","24.58982","4.03627","0.00045"
"123.50000","24.68979","4.04916","0.00045"
"124.00000","24.79002","4.04735","0.00045"
"124.50000","24.88986","4.03788","0.00045"
"125.00000","24.98974","4.10034","0.00046"
"125.50000","25.09003","4.18403","0.00046"
"126.00000","25.18983","4.09205","0.00046"
"126.50000","25.28978","4.20960","0.00046"
"127.00000","25.39002","4.13634","0.00046"
"127.50000","25.48982","4.27305","0.00046"
"128.00000","25.58982","4.18623","0.00047"
"128.50000","25.69001","4.18204","0.00047"
"129.00000","25.78983","4.22237","0.00047"
"129.50000","25.88984","4.31236","0.00047"
"130.00000","25.99002","4.27543","0.00047"
"130.50000","26.08981","4.31015","0.00048"
"131.00000","26.18984","4.36937","0.00048"
"131.50000","26.28999","4.25085","0.00048"
"132.00000","26.38981","4.33562","0.00048"
"132.50000","26.48983","4.40754","0.00048"
"133.00000","26.59000","4.47990","0.00048"
"133.50000","26.68982","4.41203","0.00048"
"134.00000","26.78989","4.37474","0.00049"
"134.50000","26.88997","4.50344","0.00049"
"135.00000","26.98977","4.31664","0.00049"
"135.50000","27.08987","4.45901","0.00049"
"136.00000","27.18992","4.43176","0.00050"
"136.50000","27.28979","4.47854","0.00050"
"137.00000","27.38992","4.40035","0.00050"
"137.50000","27.48993","4.50186","0.00050"
"138.00000","27.58981","4.48938","0.00050"
"138.50000","27.68991","4.64323","0.00051"
"139.00000","27.78993","4.69966","0.00051"
"139.50000","27.88978","4.64039","0.00051"
"140.00000","27.98991","4.58304","0.00051"
"140.50000","28.08990","4.59118","0.00051"
"141.00000","28.18975","4.57359","0.00052"
"141.50000","28.28998","4.67819","0.00052"
"142.00000","28.38985","4.65532","0.00052"
"142.50000","28.48978","4.69709","0.00052"
"143.00000","28.58993","4.73225","0.00052"
"143.50000","28.68988","4.68948","0.00052"
"144.00000","28.78972","4.75632","0.00052"
"144.50000","28.89000","4.59711","0.00053"
"145.00000","28.98987","4.79934","0.00053"
"145.50000","29.08974","4.84359","0.00053"
"146.00000","29.18998","4.83456","0.00053"
"146.50000","29.28984","4.85593","0.00054"
"147.00000","29.38977","4.80103","0.00054"
"147.50000","29.49005","4.74599","0.00054"
"148.00000","29.58977","4.97022","0.00054"
"148.50000","29.68980","4.79832","0.00054"
"149.00000","29.78998","4.92314","0.00055"
"149.50000","29.88982","5.06636","0.00055"
"150.00000","29.98981","4.97777","0.00055"
"150.50000","30.09003","4.92903","0.00055"
"151.00000","30.18980","4.98369","0.00055"
"151.50000","30.28987","5.02154","0.00056"
"151.52400","30.29461","5.12323","0.00056"