File: archive/undergrad/433/Cantilever/Specimen_RawData_10.csv
Time,Extension,Load,Strain Gage18
(s),(mm),(N),(mm/mm)
"0.00000","0.00000","-0.03864","0.00000"
"0.50000","0.08980","0.11512","0.00000"
"1.00000","0.18992","0.01059","0.00000"
"1.50000","0.28974","-0.02080","0.00000"
"2.00000","0.38987","0.05097","0.00000"
"2.50000","0.48988","0.06174","0.00000"
"3.00000","0.58976","-0.04925","0.00000"
"3.50000","0.68983","0.14543","0.00000"
"4.00000","0.78990","0.02690","0.00000"
"4.50000","0.88973","0.08853","0.00000"
"5.00000","0.98992","0.12359","0.00001"
"5.50000","1.08983","0.02473","0.00001"
"6.00000","1.18973","0.26074","0.00001"
"6.50000","1.28995","0.06101","0.00001"
"7.00000","1.38984","0.13074","0.00001"
"7.50000","1.48970","0.13623","0.00001"
"8.00000","1.58992","0.09549","0.00001"
"8.50000","1.68982","0.10017","0.00001"
"9.00000","1.78974","0.17752","0.00001"
"9.50000","1.88992","0.29859","0.00001"
"10.00000","1.98981","0.23113","0.00001"
"10.50000","2.08970","0.23121","0.00002"
"11.00000","2.18993","0.32116","0.00002"
"11.50000","2.28980","0.33155","0.00002"
"12.00000","2.38974","0.30759","0.00002"
"12.50000","2.48997","0.38528","0.00002"
"13.00000","2.58979","0.31902","0.00002"
"13.50000","2.68977","0.28242","0.00002"
"14.00000","2.78997","0.31884","0.00002"
"14.50000","2.88976","0.30326","0.00002"
"15.00000","2.98980","0.50750","0.00002"
"15.50000","3.08997","0.40953","0.00002"
"16.00000","3.18975","0.43389","0.00003"
"16.50000","3.28979","0.51538","0.00003"
"17.00000","3.38997","0.35924","0.00003"
"17.50000","3.48975","0.37836","0.00003"
"18.00000","3.58978","0.51147","0.00003"
"18.50000","3.68999","0.63278","0.00003"
"19.00000","3.78975","0.55535","0.00003"
"19.50000","3.88981","0.50698","0.00003"
"20.00000","3.98997","0.57120","0.00003"
"20.50000","4.08975","0.56889","0.00003"
"21.00000","4.18983","0.71666","0.00003"
"21.50000","4.28993","0.56686","0.00004"
"22.00000","4.38976","0.60612","0.00004"
"22.50000","4.48984","0.63236","0.00004"
"23.00000","4.58991","0.73291","0.00004"
"23.50000","4.68968","0.60264","0.00004"
"24.00000","4.78985","0.64941","0.00004"
"24.50000","4.88993","0.71528","0.00004"
"25.00000","4.98974","0.73164","0.00004"
"25.50000","5.08985","0.72514","0.00004"
"26.00000","5.18990","0.73686","0.00004"
"26.50000","5.28972","0.82593","0.00004"
"27.00000","5.38987","0.71906","0.00005"
"27.50000","5.48987","0.77515","0.00005"
"28.00000","5.58973","0.96512","0.00005"
"28.50000","5.68989","0.79746","0.00005"
"29.00000","5.78988","0.78593","0.00005"
"29.50000","5.88972","0.76487","0.00005"
"30.00000","5.98990","0.80045","0.00005"
"30.50000","6.08980","0.88311","0.00005"
"31.00000","6.18975","0.85861","0.00005"
"31.50000","6.28985","1.00572","0.00005"
"32.00000","6.38983","0.89424","0.00005"
"32.50000","6.48973","0.83964","0.00006"
"33.00000","6.58996","1.04218","0.00006"
"33.50000","6.68978","1.18708","0.00006"
"34.00000","6.78978","1.08120","0.00006"
"34.50000","6.88994","1.03825","0.00006"
"35.00000","6.98979","0.98862","0.00006"
"35.50000","7.08978","1.21874","0.00006"
"36.00000","7.18997","1.04344","0.00006"
"36.50000","7.28977","1.10902","0.00006"
"37.00000","7.38975","1.07942","0.00006"
"37.50000","7.48993","1.11407","0.00006"
"38.00000","7.58978","1.15608","0.00007"
"38.50000","7.68974","1.21830","0.00007"
"39.00000","7.79002","1.11179","0.00007"
"39.50000","7.88973","1.17866","0.00007"
"40.00000","7.98982","1.29097","0.00007"
"40.50000","8.08996","1.19692","0.00007"
"41.00000","8.18975","1.17657","0.00007"
"41.50000","8.28979","1.31549","0.00007"
"42.00000","8.38995","1.35645","0.00007"
"42.50000","8.48975","1.31872","0.00007"
"43.00000","8.58984","1.31606","0.00007"
"43.50000","8.68995","1.31678","0.00008"
"44.00000","8.78975","1.39700","0.00008"
"44.50000","8.88981","1.42341","0.00008"
"45.00000","8.98996","1.30069","0.00008"
"45.50000","9.08974","1.48832","0.00008"
"46.00000","9.18988","1.28621","0.00008"
"46.50000","9.28989","1.44465","0.00008"
"47.00000","9.38977","1.44805","0.00008"
"47.50000","9.48980","1.47704","0.00008"
"48.00000","9.58992","1.42140","0.00008"
"48.50000","9.68973","1.47614","0.00008"
"49.00000","9.78989","1.42173","0.00009"
"49.50000","9.88985","1.51481","0.00009"
"50.00000","9.98975","1.59004","0.00009"
"50.50000","10.08987","1.63401","0.00009"
"51.00000","10.18987","1.56549","0.00009"
"51.50000","10.28971","1.59730","0.00009"
"52.00000","10.38990","1.63170","0.00009"
"52.50000","10.48981","1.67404","0.00009"
"53.00000","10.58973","1.69264","0.00009"
"53.50000","10.68995","1.57484","0.00009"
"54.00000","10.78983","1.61528","0.00009"
"54.50000","10.88975","1.77859","0.00010"
"55.00000","10.98998","1.77802","0.00010"
"55.50000","11.08978","1.73441","0.00010"
"56.00000","11.18979","1.74501","0.00010"
"56.50000","11.28994","1.79209","0.00010"
"57.00000","11.38982","1.76023","0.00010"
"57.50000","11.48973","1.82287","0.00010"
"58.00000","11.58995","1.81977","0.00010"
"58.50000","11.68977","1.91790","0.00010"
"59.00000","11.78974","1.84466","0.00010"
"59.50000","11.88997","1.83644","0.00010"
"60.00000","11.98978","1.84669","0.00011"
"60.50000","12.08979","1.90022","0.00011"
"61.00000","12.18996","1.92319","0.00011"
"61.50000","12.28977","1.82831","0.00011"
"62.00000","12.38983","1.86487","0.00011"
"62.50000","12.49000","1.87645","0.00011"
"63.00000","12.58974","1.94810","0.00011"
"63.50000","12.68980","1.95658","0.00011"
"64.00000","12.78998","1.91026","0.00011"
"64.50000","12.88974","2.05139","0.00011"
"65.00000","12.98981","2.03001","0.00011"
"65.50000","13.08999","2.05153","0.00012"
"66.00000","13.18974","2.08366","0.00012"
"66.50000","13.28984","2.09663","0.00012"
"67.00000","13.38994","2.21179","0.00012"
"67.50000","13.48977","2.13890","0.00012"
"68.00000","13.58982","2.09710","0.00012"
"68.50000","13.68992","2.25795","0.00012"
"69.00000","13.78976","2.11152","0.00012"
"69.50000","13.88987","2.25638","0.00012"
"70.00000","13.98988","2.17624","0.00012"
"70.50000","14.08977","2.18808","0.00012"
"71.00000","14.18984","2.15992","0.00013"
"71.50000","14.28992","2.21258","0.00013"
"72.00000","14.38973","2.34115","0.00013"
"72.50000","14.48986","2.36716","0.00013"
"73.00000","14.58985","2.33826","0.00013"
"73.50000","14.68972","2.36399","0.00013"
"74.00000","14.78990","2.40576","0.00013"
"74.50000","14.88982","2.31849","0.00013"
"75.00000","14.98971","2.40288","0.00013"
"75.50000","15.08994","2.44863","0.00013"
"76.00000","15.18981","2.45782","0.00013"
"76.50000","15.28973","2.36263","0.00014"
"77.00000","15.38994","2.45717","0.00014"
"77.50000","15.48984","2.46590","0.00014"
"78.00000","15.58974","2.43788","0.00014"
"78.50000","15.68992","2.51859","0.00014"
"79.00000","15.78978","2.58223","0.00014"
"79.50000","15.88973","2.60881","0.00014"
"80.00000","15.98998","2.66380","0.00014"
"80.50000","16.08974","2.70483","0.00014"
"81.00000","16.18980","2.79952","0.00014"
"81.50000","16.28995","2.75327","0.00014"
"82.00000","16.38976","2.70663","0.00015"
"82.50000","16.48980","2.74466","0.00015"
"83.00000","16.58997","2.68128","0.00015"
"83.50000","16.68975","2.68583","0.00015"
"84.00000","16.78976","2.81211","0.00015"
"84.50000","16.89000","2.78717","0.00015"
"85.00000","16.98976","2.74198","0.00015"
"85.50000","17.08979","2.85366","0.00015"
"86.00000","17.19002","2.74326","0.00015"
"86.50000","17.28974","2.97639","0.00015"
"87.00000","17.38980","2.75238","0.00015"
"87.50000","17.48996","2.81850","0.00016"
"88.00000","17.58977","2.79595","0.00016"
"88.50000","17.68978","2.92937","0.00016"
"89.00000","17.78995","2.88574","0.00016"
"89.50000","17.88976","2.88250","0.00016"
"90.00000","17.98984","3.03227","0.00016"
"90.50000","18.08994","2.99517","0.00016"
"91.00000","18.18975","2.96046","0.00016"
"91.50000","18.28982","2.88055","0.00016"
"92.00000","18.38990","2.99731","0.00016"
"92.50000","18.48977","2.97272","0.00017"
"93.00000","18.58988","3.08783","0.00017"
"93.50000","18.68988","3.02266","0.00017"
"94.00000","18.78976","3.06865","0.00017"
"94.50000","18.88985","3.01578","0.00017"
"95.00000","18.98985","3.14527","0.00017"
"95.50000","19.08974","3.05727","0.00017"
"96.00000","19.18990","3.11286","0.00017"
"96.50000","19.28982","3.21063","0.00017"
"97.00000","19.38976","3.21564","0.00017"
"97.50000","19.48986","3.22594","0.00017"
"98.00000","19.58987","3.30171","0.00017"
"98.50000","19.68974","3.26573","0.00018"
"99.00000","19.78991","3.22016","0.00018"
"99.50000","19.88979","3.18760","0.00018"
"100.00000","19.98973","3.30676","0.00018"
"100.50000","20.08995","3.34034","0.00018"
"101.00000","20.18979","3.30707","0.00018"
"101.50000","20.28976","3.34816","0.00018"
"102.00000","20.38998","3.36018","0.00018"
"102.50000","20.48973","3.47555","0.00018"
"103.00000","20.58977","3.36706","0.00018"
"103.50000","20.68999","3.45798","0.00019"
"104.00000","20.78980","3.50295","0.00019"
"104.50000","20.88969","3.38081","0.00019"
"105.00000","20.99000","3.31958","0.00019"
"105.50000","21.08976","3.55588","0.00019"
"106.00000","21.18978","3.56643","0.00019"
"106.50000","21.29000","3.48096","0.00019"
"107.00000","21.38974","3.65158","0.00019"
"107.50000","21.48979","3.40090","0.00019"
"108.00000","21.58996","3.62873","0.00019"
"108.50000","21.68975","3.50527","0.00020"
"109.00000","21.78979","3.58507","0.00020"
"109.50000","21.88998","3.66718","0.00020"
"110.00000","21.98977","3.63330","0.00020"
"110.50000","22.08981","3.58190","0.00020"
"111.00000","22.18998","3.67529","0.00020"
"111.50000","22.28976","3.72228","0.00020"
"112.00000","22.38980","3.61528","0.00020"
"112.50000","22.48993","3.72413","0.00020"
"113.00000","22.58977","3.73700","0.00020"
"113.50000","22.68986","3.50640","0.00021"
"114.00000","22.78989","3.63241","0.00021"
"114.50000","22.88976","3.75179","0.00021"
"115.00000","22.98982","3.88095","0.00021"
"115.50000","23.08990","3.78185","0.00021"
"116.00000","23.18974","3.82656","0.00021"
"116.50000","23.28990","3.80974","0.00021"
"117.00000","23.38986","3.93655","0.00021"
"117.50000","23.48975","3.89556","0.00021"
"118.00000","23.58987","3.97470","0.00021"
"118.50000","23.68987","3.90391","0.00021"
"119.00000","23.78977","3.88981","0.00022"
"119.50000","23.88992","3.88199","0.00022"
"120.00000","23.98980","3.81501","0.00022"
"120.50000","24.08973","3.82376","0.00022"
"121.00000","24.18996","4.03392","0.00022"
"121.50000","24.28982","4.02373","0.00022"
"122.00000","24.38972","4.05954","0.00022"
"122.50000","24.48996","4.12617","0.00022"
"123.00000","24.58979","4.07099","0.00022"
"123.50000","24.68975","4.03459","0.00022"
"124.00000","24.78998","4.16099","0.00022"
"124.50000","24.88981","4.18034","0.00022"
"125.00000","24.98971","4.17197","0.00023"
"125.50000","25.08998","4.24133","0.00023"
"126.00000","25.18979","4.25329","0.00023"
"126.50000","25.28974","4.16139","0.00023"
"127.00000","25.39000","4.23481","0.00023"
"127.50000","25.48977","4.34802","0.00023"
"128.00000","25.58976","4.14650","0.00023"
"128.50000","25.68997","4.15761","0.00023"
"129.00000","25.78979","4.26153","0.00023"
"129.50000","25.88979","4.18106","0.00023"
"130.00000","25.98997","4.13698","0.00024"
"130.50000","26.08976","4.35336","0.00024"
"131.00000","26.18979","4.43326","0.00024"
"131.50000","26.28996","4.37741","0.00024"
"132.00000","26.38975","4.38084","0.00024"
"132.50000","26.48980","4.53021","0.00024"
"133.00000","26.58996","4.37512","0.00024"
"133.50000","26.68978","4.48234","0.00024"
"134.00000","26.78986","4.52155","0.00024"
"134.50000","26.88992","4.47740","0.00024"
"135.00000","26.98973","4.37660","0.00024"
"135.50000","27.08984","4.45342","0.00025"
"136.00000","27.18987","4.56858","0.00025"
"136.50000","27.28977","4.54319","0.00025"
"137.00000","27.38987","4.56723","0.00025"
"137.50000","27.48987","4.55329","0.00025"
"138.00000","27.58977","4.46573","0.00025"
"138.50000","27.68989","4.60647","0.00025"
"139.00000","27.78987","4.62802","0.00025"
"139.50000","27.88975","4.62513","0.00025"
"140.00000","27.98989","4.56918","0.00025"
"140.50000","28.08981","4.63954","0.00025"
"141.00000","28.18970","4.72528","0.00026"
"141.50000","28.28994","4.73162","0.00026"
"142.00000","28.38981","4.67891","0.00026"
"142.50000","28.48975","4.60482","0.00026"
"143.00000","28.58989","4.77196","0.00026"
"143.50000","28.68983","4.79199","0.00026"
"144.00000","28.78964","4.76824","0.00026"
"144.50000","28.88998","4.74327","0.00026"
"145.00000","28.98982","4.70830","0.00026"
"145.50000","29.08969","4.88311","0.00026"
"146.00000","29.18999","4.80683","0.00027"
"146.50000","29.28979","4.88699","0.00027"
"147.00000","29.38971","4.91124","0.00027"
"147.50000","29.49001","4.85265","0.00027"
"148.00000","29.58973","4.95718","0.00027"
"148.50000","29.68973","4.84700","0.00027"
"149.00000","29.78994","4.97560","0.00027"
"149.50000","29.88978","4.99470","0.00027"
"150.00000","29.98975","4.93090","0.00027"
"150.50000","30.08999","4.98043","0.00027"
"151.00000","30.18974","5.05087","0.00027"
"151.49400","30.28864","4.98532","0.00027"